Workbook

Sheet Sheet1
A2: Exclude: Palestine, Bermuda, Puerto Rico, Greenland, Taiwan, American Samoa | N2: Delta
N3: =+K7-G7+M7-G7 -> 1.5e+08
F4: Ask the client for inputs? | H4: 30-79 NCDRisk?? | K4: =+K5-G5 -> 0.047655894 | W4: abs pp | X4: %change | Y4: growth_year
A5: Green Cells From updates source WHO or GBD 2023 | G5: =+G7/F7 -> 0.22792549 | I5: =+I7/F7 -> 0.50177138 | K5: =+K6/F7 -> 0.27558139 | M5: =+M6/F7 -> 0.25796942 | W5: =+I5-G5 -> 0.27384589 | X5: =+I5/G5-1 -> 1.2014711 | Y5: =((I7/G7)^(1/5))-1 -> 0.17096145
K6: =+G7+92000000 -> 5.3201158e+08 | M6: =+G7+58000000 -> 4.9801158e+08 | W6: =+K5-G5 -> 0.047655894 | X6: =+K5/G5-1 -> 0.20908541 | Y6: =((K5/G5)^(1/5))-1 -> 0.038703024
A7: Totals | B7: =+SUMPRODUCT(B10:B200,$E$10:$E$200)/SUM($E$10:$E$200) -> 0.33984296 | C7: =+SUMPRODUCT(C10:C200,$E$10:$E$200)/SUM($E$10:$E$200) -> 0.22339212 | D7: =+SUMPRODUCT(D10:D200,$E$10:$E$200)/SUM($E$10:$E$200) -> 0.055332931 | E7: =+SUM(E10:E200) -> 5.6805832e+09 | F7: =+SUM(F10:F200) -> 1.9305062e+09 | G7: =+SUM(G10:G200) -> 4.4001158e+08 | I7: =+SUM(I10:I200) -> 9.6867277e+08 | K7: =+SUM(K10:K200) -> 5.3201158e+08 | M7: =+SUM(M10:M200) -> 4.9801158e+08 | W7: =+M5-G5 -> 0.030043933 | X7: =+M5/G5-1 -> 0.13181471 | Y7: =((M5/G5)^(1/5))-1 -> 0.025073643
A9: location | B9: htnprev | C9: htncov2 | D9: raisedBP | E9: pop20_2025 | F9: prevalence_2025 | G9: controled_2025 | H9: htncov2_aspirational | I9: controlled_2030_aspirational | J9: htncov2_ambitious | K9: controlled_2030_ambitious | L9: htncov2_progress | M9: controlled_2030_equal | N9: diabetes | O9: htn_ctrl_diabetes | P9: diabetes_NCDRisk | Q9: htnprev_NCDRisk | R9: htncov2_NCDRisk | S9: raisedBP_NCDRisk | T9: htncov2_progress_who | V9: =SUM(V10:V200) -> 61492583 | W9: =SUM(W10:W200) -> 1.2246222e+08 | X9: =+W9-V9 -> 60969641
A10: Afghanistan | B10: =IFERROR(VLOOKUP(A10,HTN_targets!$D$1:$M$195,3,0),Q10) -> 0.37955967 | C10: =IFERROR(VLOOKUP(A10,HTN_targets!$D$1:$M$195,10,0),R10) -> 0.15960707 | D10: 0.085710088 | E10: 21241068 | F10: =+B10*E10 -> 8062253 | G10: =+F10*C10 -> 1286792.6 | H10: =+IF(C10>0.5,C10,0.5) -> 0.5 | I10: =+F10*H10 -> 4031126.5 | J10: =C10+($K$5-$G$5) -> 0.20726296 | K10: =+J10*F10 -> 1671006.4 | L10: =C10+($M$5-$G$5) -> 0.189651 | M10: =+F10*L10 -> 1529014.3 | N10: =+VLOOKUP(A10,Diabetes!$G$1:$S$206,12,0)/100000 -> 0.061569096 | O10: =+C10+0.15 -> 0.30960707 | P10: 0.05967259 | Q10: 0.35332145 | R10: 0.12488202 | S10: 0.085710088 | T10: =IFERROR(VLOOKUP(A10,HTN_targets!$R$9:$X$203,6,0),L10) -> 0.15960707 | U10: =IF(T10>C10,1,0) -> 1 | V10: =+E10*B10*N10*O10 -> 153684.5 | W10: =+E10*B10*N10*0.8 -> 397108.5
A11: Albania | B11: =IFERROR(VLOOKUP(A11,HTN_targets!$D$1:$M$195,3,0),Q11) -> 0.47361237 | C11: =IFERROR(VLOOKUP(A11,HTN_targets!$D$1:$M$195,10,0),R11) -> 0.10754282 | D11: 0.080804703 | E11: 2182816.5 | F11: =+B11*E11 -> 1033808.9 | G11: =+F11*C11 -> 111178.72 | H11: =+IF(C11>0.5,C11,0.5) -> 0.5 | I11: =+F11*H11 -> 516904.45 | J11: =C11+($K$5-$G$5) -> 0.15519871 | K11: =+J11*F11 -> 160445.81 | L11: =C11+($M$5-$G$5) -> 0.13758675 | M11: =+F11*L11 -> 142238.41 | N11: =+VLOOKUP(A11,Diabetes!$G$1:$S$206,12,0)/100000 -> 0.061050695 | O11: =+C11+0.15 -> 0.25754282 | P11: 0.02849345 | Q11: 0.4258326 | R11: 0.068413228 | S11: 0.080804703 | T11: =IFERROR(VLOOKUP(A11,HTN_targets!$R$9:$X$203,6,0),L11) -> 0.10754282 | U11: =IF(T11>C11,1,0) -> 1 | V11: =+E11*B11*N11*O11 -> 16254.751 | W11: =+E11*B11*N11*0.8 -> 50491.801
A12: Algeria | B12: =IFERROR(VLOOKUP(A12,HTN_targets!$D$1:$M$195,3,0),Q12) -> 0.34410548 | C12: =IFERROR(VLOOKUP(A12,HTN_targets!$D$1:$M$195,10,0),R12) -> 0.17358428 | D12: 0.062013212 | E12: 30080192 | F12: =+B12*E12 -> 10350759 | G12: =+F12*C12 -> 1796729 | H12: =+IF(C12>0.5,C12,0.5) -> 0.5 | I12: =+F12*H12 -> 5175379.4 | J12: =C12+($K$5-$G$5) -> 0.22124018 | K12: =+J12*F12 -> 2290003.7 | L12: =C12+($M$5-$G$5) -> 0.20362822 | M12: =+F12*L12 -> 2107706.5 | N12: =+VLOOKUP(A12,Diabetes!$G$1:$S$206,12,0)/100000 -> 0.11948162 | O12: =+C12+0.15 -> 0.32358428 | P12: 0.05273935 | Q12: 0.34954775 | R12: 0.13800483 | S12: 0.062013212 | T12: =IFERROR(VLOOKUP(A12,HTN_targets!$R$9:$X$203,6,0),L12) -> 0.17358428 | U12: =IF(T12>C12,1,0) -> 1 | V12: =+E12*B12*N12*O12 -> 400184.92 | W12: =+E12*B12*N12*0.8 -> 989380.37
A13: American Samoa | B13: =IFERROR(VLOOKUP(A13,HTN_targets!$D$1:$M$195,3,0),Q13) -> 0.4881284 | C13: =IFERROR(VLOOKUP(A13,HTN_targets!$D$1:$M$195,10,0),R13) -> 0.097576806 | D13: 0.05219546 | E13: 30619 | F13: =+B13*E13 -> 14946.004 | G13: =+F13*C13 -> 1458.3833 | H13: =+IF(C13>0.5,C13,0.5) -> 0.5 | I13: =+F13*H13 -> 7473.0018 | J13: =C13+($K$5-$G$5) -> 0.1452327 | K13: =+J13*F13 -> 2170.6485 | L13: =C13+($M$5-$G$5) -> 0.12762074 | M13: =+F13*L13 -> 1907.42 | N13: =+VLOOKUP(A13,Diabetes!$G$1:$S$206,12,0)/100000 -> 0.18703025 | O13: =+C13+0.15 -> 0.24757681 | P13: 0.055833428 | Q13: 0.4881284 | R13: 0.097576806 | S13: 0.05219546 | T13: =IFERROR(VLOOKUP(A13,HTN_targets!$R$9:$X$203,6,0),L13) -> 0.12762074 | U13: =IF(T13>C13,1,0) -> 1 | V13: =+E13*B13*N13*O13 -> 692.06501 | W13: =+E13*B13*N13*0.8 -> 2236.2838
A14: Andorra | B14: =IFERROR(VLOOKUP(A14,HTN_targets!$D$1:$M$195,3,0),Q14) -> 0.3673059 | C14: =IFERROR(VLOOKUP(A14,HTN_targets!$D$1:$M$195,10,0),R14) -> 0.37682921 | D14: 0.044482928 | E14: 69752 | F14: =+B14*E14 -> 25620.321 | G14: =+F14*C14 -> 9654.4853 | H14: =+IF(C14>0.5,C14,0.5) -> 0.5 | I14: =+F14*H14 -> 12810.161 | J14: =C14+($K$5-$G$5) -> 0.4244851 | K14: =+J14*F14 -> 10875.445 | L14: =C14+($M$5-$G$5) -> 0.40687314 | M14: =+F14*L14 -> 10424.221 | N14: =+VLOOKUP(A14,Diabetes!$G$1:$S$206,12,0)/100000 -> 0.05864314 | O14: =+C14+0.15 -> 0.52682921 | P14: 0.04890724 | Q14: 0.35732874 | R14: 0.30800619 | S14: 0.044482928 | T14: =IFERROR(VLOOKUP(A14,HTN_targets!$R$9:$X$203,6,0),L14) -> 0.37682921 | U14: =IF(T14>C14,1,0) -> 0 | V14: =+E14*B14*N14*O14 -> 791.53775 | W14: =+E14*B14*N14*0.8 -> 1201.9649
A15: Angola | B15: =IFERROR(VLOOKUP(A15,HTN_targets!$D$1:$M$195,3,0),Q15) -> 0.34542891 | C15: =IFERROR(VLOOKUP(A15,HTN_targets!$D$1:$M$195,10,0),R15) -> 0.13649409 | D15: 0.081140045 | E15: 18409009 | F15: =+B15*E15 -> 6359003.9 | G15: =+F15*C15 -> 867966.42 | H15: =+IF(C15>0.5,C15,0.5) -> 0.5 | I15: =+F15*H15 -> 3179502 | J15: =C15+($K$5-$G$5) -> 0.18414998 | K15: =+J15*F15 -> 1171010.4 | L15: =C15+($M$5-$G$5) -> 0.16653802 | M15: =+F15*L15 -> 1059015.9 | N15: =+VLOOKUP(A15,Diabetes!$G$1:$S$206,12,0)/100000 -> 0.044545008 | O15: =+C15+0.15 -> 0.28649409 | P15: 0.0699959 | Q15: 0.36489772 | R15: 0.10729056 | S15: 0.081140045 | T15: =IFERROR(VLOOKUP(A15,HTN_targets!$R$9:$X$203,6,0),L15) -> 0.13649409 | U15: =IF(T15>C15,1,0) -> 0 | V15: =+E15*B15*N15*O15 -> 81152.854 | W15: =+E15*B15*N15*0.8 -> 226609.51
A16: Antigua and Barbuda | B16: =IFERROR(VLOOKUP(A16,HTN_targets!$D$1:$M$195,3,0),Q16) -> 0.45622262 | C16: =IFERROR(VLOOKUP(A16,HTN_targets!$D$1:$M$195,10,0),R16) -> 0.25480822 | D16: 0.055943771 | E16: 72433.5 | F16: =+B16*E16 -> 33045.801 | G16: =+F16*C16 -> 8420.3417 | H16: =+IF(C16>0.5,C16,0.5) -> 0.5 | I16: =+F16*H16 -> 16522.901 | J16: =C16+($K$5-$G$5) -> 0.30246411 | K16: =+J16*F16 -> 9995.1689 | L16: =C16+($M$5-$G$5) -> 0.28485215 | M16: =+F16*L16 -> 9413.1675 | N16: =+VLOOKUP(A16,Diabetes!$G$1:$S$206,12,0)/100000 -> 0.12481961 | O16: =+C16+0.15 -> 0.40480822 | P16: 0.055833428 | Q16: 0.41943379 | R16: 0.20336407 | S16: 0.055943771 | T16: =IFERROR(VLOOKUP(A16,HTN_targets!$R$9:$X$203,6,0),L16) -> 0.25480822 | U16: =IF(T16>C16,1,0) -> 1 | V16: =+E16*B16*N16*O16 -> 1669.7384 | W16: =+E16*B16*N16*0.8 -> 3299.8112
A17: Argentina | B17: =IFERROR(VLOOKUP(A17,HTN_targets!$D$1:$M$195,3,0),Q17) -> 0.50844467 | C17: =IFERROR(VLOOKUP(A17,HTN_targets!$D$1:$M$195,10,0),R17) -> 0.16283064 | D17: 0.056253628 | E17: 33323446 | F17: =+B17*E17 -> 16943128 | G17: =+F17*C17 -> 2758860.3 | H17: =+IF(C17>0.5,C17,0.5) -> 0.5 | I17: =+F17*H17 -> 8471564.1 | J17: =C17+($K$5-$G$5) -> 0.21048653 | K17: =+J17*F17 -> 3566300.3 | L17: =C17+($M$5-$G$5) -> 0.19287457 | M17: =+F17*L17 -> 3267898.6 | N17: =+VLOOKUP(A17,Diabetes!$G$1:$S$206,12,0)/100000 -> 0.051307119 | O17: =+C17+0.15 -> 0.31283064 | P17: 0.03960288 | Q17: 0.54014376 | R17: 0.12363865 | S17: 0.056253628 | T17: =IFERROR(VLOOKUP(A17,HTN_targets!$R$9:$X$203,6,0),L17) -> 0.16283064 | U17: =IF(T17>C17,1,0) -> 1 | V17: =+E17*B17*N17*O17 -> 271944.64 | W17: =+E17*B17*N17*0.8 -> 695442.48
A18: Armenia | B18: =IFERROR(VLOOKUP(A18,HTN_targets!$D$1:$M$195,3,0),Q18) -> 0.50704086 | C18: =IFERROR(VLOOKUP(A18,HTN_targets!$D$1:$M$195,10,0),R18) -> 0.10214718 | D18: 0.061781734 | E18: 2236922.5 | F18: =+B18*E18 -> 1134211.1 | G18: =+F18*C18 -> 115856.47 | H18: =+IF(C18>0.5,C18,0.5) -> 0.5 | I18: =+F18*H18 -> 567105.55 | J18: =C18+($K$5-$G$5) -> 0.14980308 | K18: =+J18*F18 -> 169908.32 | L18: =C18+($M$5-$G$5) -> 0.13219112 | M18: =+F18*L18 -> 149932.63 | N18: =+VLOOKUP(A18,Diabetes!$G$1:$S$206,12,0)/100000 -> 0.07285414 | O18: =+C18+0.15 -> 0.25214718 | P18: 0.05040739 | Q18: 0.48463553 | R18: 0.080842912 | S18: 0.061781734 | T18: =IFERROR(VLOOKUP(A18,HTN_targets!$R$9:$X$203,6,0),L18) -> 0.10214718 | U18: =IF(T18>C18,1,0) -> 1 | V18: =+E18*B18*N18*O18 -> 20835.42 | W18: =+E18*B18*N18*0.8 -> 66105.58
A19: Australia | B19: =IFERROR(VLOOKUP(A19,HTN_targets!$D$1:$M$195,3,0),Q19) -> 0.34051824 | C19: =IFERROR(VLOOKUP(A19,HTN_targets!$D$1:$M$195,10,0),R19) -> 0.28334492 | D19: 0.030352476 | E19: 20873328 | F19: =+B19*E19 -> 7107748.9 | G19: =+F19*C19 -> 2013944.6 | H19: =+IF(C19>0.5,C19,0.5) -> 0.5 | I19: =+F19*H19 -> 3553874.5 | J19: =C19+($K$5-$G$5) -> 0.33100082 | K19: =+J19*F19 -> 2352670.7 | L19: =C19+($M$5-$G$5) -> 0.31338886 | M19: =+F19*L19 -> 2227489.3 | N19: =+VLOOKUP(A19,Diabetes!$G$1:$S$206,12,0)/100000 -> 0.04528884 | O19: =+C19+0.15 -> 0.43334492 | P19: 0.03122978 | Q19: 0.32253307 | R19: 0.25152593 | S19: 0.030352476 | T19: =IFERROR(VLOOKUP(A19,HTN_targets!$R$9:$X$203,6,0),L19) -> 0.28334492 | U19: =IF(T19>C19,1,0) -> 1 | V19: =+E19*B19*N19*O19 -> 139494.47 | W19: =+E19*B19*N19*0.8 -> 257521.36
A20: Austria | B20: =IFERROR(VLOOKUP(A20,HTN_targets!$D$1:$M$195,3,0),Q20) -> 0.37721261 | C20: =IFERROR(VLOOKUP(A20,HTN_targets!$D$1:$M$195,10,0),R20) -> 0.3139742 | D20: 0.050107476 | E20: 7476501.5 | F20: =+B20*E20 -> 2820230.6 | G20: =+F20*C20 -> 885479.67 | H20: =+IF(C20>0.5,C20,0.5) -> 0.5 | I20: =+F20*H20 -> 1410115.3 | J20: =C20+($K$5-$G$5) -> 0.3616301 | K20: =+J20*F20 -> 1019880.3 | L20: =C20+($M$5-$G$5) -> 0.34401814 | M20: =+F20*L20 -> 970210.49 | N20: =+VLOOKUP(A20,Diabetes!$G$1:$S$206,12,0)/100000 -> 0.051667703 | O20: =+C20+0.15 -> 0.4639742 | P20: 0.04354227 | Q20: 0.3747722 | R20: 0.27425232 | S20: 0.050107476 | T20: =IFERROR(VLOOKUP(A20,HTN_targets!$R$9:$X$203,6,0),L20) -> 0.3139742 | U20: =IF(T20>C20,1,0) -> 1 | V20: =+E20*B20*N20*O20 -> 67607.927 | W20: =+E20*B20*N20*0.8 -> 116571.87
A21: Azerbaijan | B21: =IFERROR(VLOOKUP(A21,HTN_targets!$D$1:$M$195,3,0),Q21) -> 0.42041826 | C21: =IFERROR(VLOOKUP(A21,HTN_targets!$D$1:$M$195,10,0),R21) -> 0.14830217 | D21: 0.058836393 | E21: 7550998 | F21: =+B21*E21 -> 3174577.4 | G21: =+F21*C21 -> 470796.72 | H21: =+IF(C21>0.5,C21,0.5) -> 0.5 | I21: =+F21*H21 -> 1587288.7 | J21: =C21+($K$5-$G$5) -> 0.19595806 | K21: =+J21*F21 -> 622084.04 | L21: =C21+($M$5-$G$5) -> 0.1783461 | M21: =+F21*L21 -> 566173.51 | N21: =+VLOOKUP(A21,Diabetes!$G$1:$S$206,12,0)/100000 -> 0.067644852 | O21: =+C21+0.15 -> 0.29830217 | P21: 0.04908308 | Q21: 0.39599679 | R21: 0.11381298 | S21: 0.058836393 | T21: =IFERROR(VLOOKUP(A21,HTN_targets!$R$9:$X$203,6,0),L21) -> 0.14830217 | U21: =IF(T21>C21,1,0) -> 1 | V21: =+E21*B21*N21*O21 -> 64058.548 | W21: =+E21*B21*N21*0.8 -> 171795.06
... A200: Zimbabwe | B200: =IFERROR(VLOOKUP(A200,HTN_targets!$D$1:$M$195,3,0),Q200) -> 0.37768167 | C200: =IFERROR(VLOOKUP(A200,HTN_targets!$D$1:$M$195,10,0),R200) -> 0.17734419 | D200: 0.071455299 | E200: 8524822.5 | F200: =+B200*E200 -> 3219669.2 | G200: =+F200*C200 -> 570989.62 | H200: =+IF(C200>0.5,C200,0.5) -> 0.5 | I200: =+F200*H200 -> 1609834.6 | J200: =C200+($K$5-$G$5) -> 0.22500008 | K200: =+J200*F200 -> 724425.83 | L200: =C200+($M$5-$G$5) -> 0.20738812 | M200: =+F200*L200 -> 667721.15 | N200: =+VLOOKUP(A200,Diabetes!$G$1:$S$206,12,0)/100000 -> 0.028570121 | O200: =+C200+0.15 -> 0.32734419 | P200: 0.06819287 | Q200: 0.36861002 | R200: 0.15091338 | S200: 0.071455299 | T200: =IFERROR(VLOOKUP(A200,HTN_targets!$R$9:$X$203,6,0),L200) -> 0.17734419 | U200: =IF(T200>C200,1,0) -> 0 | V200: =+E200*B200*N200*O200 -> 30111.193 | W200: =+E200*B200*N200*0.8 -> 73589.07

Sheet Diabetes
A1: population_group_id | B1: population_group_name | C1: measure_id | D1: measure_name | E1: location_id | F1: location_name | G1: loc_corrected | H1: sex_id | I1: sex_name | J1: age_id | K1: age_name | L1: cause_id | M1: cause_name | N1: metric_id | O1: metric_name | P1: year | Q1: val | R1: upper | S1: lower
A2: 1 | B2: All Population | C2: 5 | D2: Prevalence | E2: 160 | F2: Afghanistan | G2: Afghanistan | H2: 3 | I2: Both | J2: 22 | K2: All ages | L2: 587 | M2: Diabetes mellitus | N2: 3 | O2: Rate | P2: 2023 | Q2: 5613.1563 | R2: 6156.9096 | S2: 5122.2726
A3: 1 | B3: All Population | C3: 5 | D3: Prevalence | E3: 43 | F3: Albania | G3: Albania | H3: 3 | I3: Both | J3: 22 | K3: All ages | L3: 587 | M3: Diabetes mellitus | N3: 3 | O3: Rate | P3: 2023 | Q3: 5458.1354 | R3: 6105.0695 | S3: 4945.4141
A4: 1 | B4: All Population | C4: 5 | D4: Prevalence | E4: 139 | F4: Algeria | G4: Algeria | H4: 3 | I4: Both | J4: 22 | K4: All ages | L4: 587 | M4: Diabetes mellitus | N4: 3 | O4: Rate | P4: 2023 | Q4: 11003.903 | R4: 11948.162 | S4: 10156.58
A5: 1 | B5: All Population | C5: 5 | D5: Prevalence | E5: 298 | F5: American Samoa | G5: American Samoa | H5: 3 | I5: Both | J5: 22 | K5: All ages | L5: 587 | M5: Diabetes mellitus | N5: 3 | O5: Rate | P5: 2023 | Q5: 17340.534 | R5: 18703.025 | S5: 16005.811
A6: 1 | B6: All Population | C6: 5 | D6: Prevalence | E6: 74 | F6: Andorra | G6: Andorra | H6: 3 | I6: Both | J6: 22 | K6: All ages | L6: 587 | M6: Diabetes mellitus | N6: 3 | O6: Rate | P6: 2023 | Q6: 5277.0907 | R6: 5864.314 | S6: 4771.9099
A7: 1 | B7: All Population | C7: 5 | D7: Prevalence | E7: 168 | F7: Angola | G7: Angola | H7: 3 | I7: Both | J7: 22 | K7: All ages | L7: 587 | M7: Diabetes mellitus | N7: 3 | O7: Rate | P7: 2023 | Q7: 4053.73 | R7: 4454.5008 | S7: 3668.5738
A8: 1 | B8: All Population | C8: 5 | D8: Prevalence | E8: 105 | F8: Antigua and Barbuda | G8: Antigua and Barbuda | H8: 3 | I8: Both | J8: 22 | K8: All ages | L8: 587 | M8: Diabetes mellitus | N8: 3 | O8: Rate | P8: 2023 | Q8: 11343.179 | R8: 12481.961 | S8: 10591.15
A9: 1 | B9: All Population | C9: 5 | D9: Prevalence | E9: 97 | F9: Argentina | G9: Argentina | H9: 3 | I9: Both | J9: 22 | K9: All ages | L9: 587 | M9: Diabetes mellitus | N9: 3 | O9: Rate | P9: 2023 | Q9: 4739.8297 | R9: 5130.7119 | S9: 4309.4575
A10: 1 | B10: All Population | C10: 5 | D10: Prevalence | E10: 33 | F10: Armenia | G10: Armenia | H10: 3 | I10: Both | J10: 22 | K10: All ages | L10: 587 | M10: Diabetes mellitus | N10: 3 | O10: Rate | P10: 2023 | Q10: 6572.0767 | R10: 7285.414 | S10: 6130.0256
A11: 1 | B11: All Population | C11: 5 | D11: Prevalence | E11: 71 | F11: Australia | G11: Australia | H11: 3 | I11: Both | J11: 22 | K11: All ages | L11: 587 | M11: Diabetes mellitus | N11: 3 | O11: Rate | P11: 2023 | Q11: 4191.0437 | R11: 4528.884 | S11: 3845.0389
A12: 1 | B12: All Population | C12: 5 | D12: Prevalence | E12: 75 | F12: Austria | G12: Austria | H12: 3 | I12: Both | J12: 22 | K12: All ages | L12: 587 | M12: Diabetes mellitus | N12: 3 | O12: Rate | P12: 2023 | Q12: 4777.8121 | R12: 5166.7703 | S12: 4452.952
A13: 1 | B13: All Population | C13: 5 | D13: Prevalence | E13: 34 | F13: Azerbaijan | G13: Azerbaijan | H13: 3 | I13: Both | J13: 22 | K13: All ages | L13: 587 | M13: Diabetes mellitus | N13: 3 | O13: Rate | P13: 2023 | Q13: 6137.5204 | R13: 6764.4852 | S13: 5602.7726
... A206: 1 | B206: All Population | C206: 5 | D206: Prevalence | E206: 198 | F206: Zimbabwe | G206: Zimbabwe | H206: 3 | I206: Both | J206: 22 | K206: All ages | L206: 587 | M206: Diabetes mellitus | N206: 3 | O206: Rate | P206: 2023 | Q206: 2611.0335 | R206: 2857.0121 | S206: 2384.7868

Sheet HTN_targets
A1: iso | B1: region | C1: country | D1: LOCATION_NAME | E1: pop_rounded_2024 | F1: HTN_B_2024 | G1: HTN_M_2024 | H1: HTN_F_2024 | I1: NUM_HTN_B_rounded | J1: NUM_NOTCTRL_B_rounded | K1: PERC_DIAG_B | L1: PERC_TRTD_B | M1: PERC_CTRL_B | Q1: iso3 | R1: whoname | S1: sex | T1: metric | U1: type | V1: number_affected | W1: 2024 | X1: 2030 | Y1: improvement
A2: AFG | B2: EMR | C2: Afghanistan | D2: Afghanistan | E2: 42 650 000 | F2: 0.37955967 | G2: 0.31803739 | H2: 0.44444644 | I2: 4.8 million | J2: 4 million | K2: 0.5777325 | L2: 0.46509424 | M2: 0.15960707 | S2: 3 | T2: crude | U2: ctrl140 | V2: 70250136 | W2: 0.30056453 | X2: 0.15780576
A3: ALB | B3: EUR | C3: Albania | D3: Albania | E3: 2 792 000 | F3: 0.47361237 | G3: 0.46132031 | H3: 0.48597533 | I3: 797 000 | J3: 711 000 | K3: 0.48518428 | L3: 0.38384259 | M3: 0.10754282 | S3: 3 | T3: crude | U3: ctrl140 | V3: 48921100 | W3: 0.1789961 | X3: 0.18765149
A4: DZA | B4: AFR | C4: Algeria | D4: Algeria | E4: 46 810 000 | F4: 0.34410548 | G4: 0.33866921 | H4: 0.34956971 | I4: 7.7 million | J4: 6.4 million | K4: 0.51837742 | L4: 0.39900216 | M4: 0.17358428 | S4: 3 | T4: crude | U4: ctrl140 | V4: 85146072 | W4: 0.39468935 | X4: 0.21176809
A5: AND | B5: EUR | C5: Andorra | D5: Andorra | E5: 81 940 | F5: 0.3673059 | G5: 0.41399398 | H5: 0.31916377 | I5: 19 000 | J5: 12 000 | K5: 0.7079739 | L5: 0.61257422 | M5: 0.37682921 | S5: 3 | T5: crude | U5: ctrl140 | V5: 324145888 | W5: 0.23210214 | X5: 0.41985521
A6: AGO | B6: AFR | C6: Angola | D6: Angola | E6: 37 890 000 | F6: 0.34542891 | G6: 0.31410879 | H6: 0.3745172 | I6: 3.5 million | J6: 3 million | K6: 0.49009207 | L6: 0.26209638 | M6: 0.13649409 | S6: 3 | T6: crude | U6: ctrl140 | V6: 82420056 | W6: 0.19155692 | X6: 0.21478647
A7: ATG | B7: AMR | C7: Antigua and Barbuda | D7: Antigua and Barbuda | E7: 93 770 | F7: 0.45622262 | G7: 0.44210529 | H7: 0.46860048 | I7: 26 000 | J7: 19 000 | K7: 0.66413546 | L7: 0.53119254 | M7: 0.25480822 | S7: 3 | T7: crude | U7: ctrl140 | V7: 15995896 | W7: 0.13101666 | X7: 0.33325195
A8: ARG | B8: AMR | C8: Argentina | D8: Argentina | E8: 45 700 000 | F8: 0.50844467 | G8: 0.57147324 | H8: 0.45054114 | I8: 12.1 million | J8: 10.1 million | K8: 0.613832 | L8: 0.44066474 | M8: 0.16283064 | S8: 3 | T8: crude | U8: ctrl140 | V8: 19279208 | W8: 0.16505325 | X8: 0.25671268
A9: ARM | B9: EUR | C9: Armenia | D9: Armenia | E9: 2 974 000 | F9: 0.50704086 | G9: 0.51112437 | H9: 0.50383943 | I9: 894 000 | J9: 803 000 | K9: 0.44418496 | L9: 0.31800279 | M9: 0.10214718 | Q9: AFG | R9: Afghanistan | S9: 3 | T9: crude | U9: ctrl140 | V9: 766402.19 | W9: 0.15960707 | X9: 0.18319961 | Y9: =+X9-W9 -> 0.023592547
A10: AUS | B10: WPR | C10: Australia | D10: Australia | E10: 26 710 000 | F10: 0.34051824 | G10: 0.3632915 | H10: 0.31826234 | I10: 5.2 million | J10: 3.8 million | K10: 0.62795228 | L10: 0.51991534 | M10: 0.28334492 | Q10: AGO | R10: Angola | S10: 3 | T10: crude | U10: ctrl140 | V10: 474403.19 | W10: 0.13649409 | X10: 0.16322888 | Y10: =+X10-W10 -> 0.026734799
A11: AUT | B11: EUR | C11: Austria | D11: Austria | E11: 9 121 000 | F11: 0.37721261 | G11: 0.40785557 | H11: 0.34733573 | I11: 2.2 million | J11: 1.5 million | K11: 0.69541156 | L11: 0.61251521 | M11: 0.3139742 | Q11: ALB | R11: Albania | S11: 3 | T11: crude | U11: ctrl140 | V11: 85705.938 | W11: 0.10754282 | X11: 0.12572218 | Y11: =+X11-W11 -> 0.018179365
A12: AZE | B12: EUR | C12: Azerbaijan | D12: Azerbaijan | E12: 10 340 000 | F12: 0.42041826 | G12: 0.40530422 | H12: 0.43439779 | I12: 2.5 million | J12: 2.1 million | K12: 0.57690877 | L12: 0.43712997 | M12: 0.14830217 | Q12: AND | R12: Andorra | S12: 3 | T12: crude | U12: ctrl140 | V12: 7284.7407 | W12: 0.37682921 | X12: 0.42159513 | Y12: =+X12-W12 -> 0.044765919
A13: BHS | B13: AMR | C13: Bahamas | D13: Bahamas | E13: 401 300 | F13: 0.4681257 | G13: 0.46547452 | H13: 0.47050741 | I13: 103 000 | J13: 78 000 | K13: 0.68526411 | L13: 0.5565505 | M13: 0.24749425 | Q13: ARE | R13: United Arab Emirates | S13: 3 | T13: crude | U13: ctrl140 | V13: 376436.53 | W13: 0.176441 | X13: 0.22513947 | Y13: =+X13-W13 -> 0.04869847
A14: BHR | B14: EMR | C14: Bahrain | D14: Bahrain | E14: 1 607 000 | F14: 0.31960893 | G14: 0.33140814 | H14: 0.29303738 | I14: 347 000 | J14: 283 000 | K14: 0.46902308 | L14: 0.36816838 | M14: 0.18264845 | Q14: ARG | R14: Argentina | S14: 3 | T14: crude | U14: ctrl140 | V14: 1969649 | W14: 0.16283064 | X14: 0.17371769 | Y14: =+X14-W14 -> 0.010887057
A15: BGD | B15: SEAR | C15: Bangladesh | D15: Bangladesh | E15: 173 600 000 | F15: 0.28281882 | G15: 0.22130005 | H15: 0.34449816 | I15: 22.8 million | J15: 19.2 million | K15: 0.51564139 | L15: 0.39203113 | M15: 0.15759723 | Q15: ARM | R15: Armenia | S15: 3 | T15: crude | U15: ctrl140 | V15: 91326.812 | W15: 0.10214718 | X15: 0.11556184 | Y15: =+X15-W15 -> 0.013414651
A16: BRB | B16: AMR | C16: Barbados | D16: Barbados | E16: 282 500 | F16: 0.49306574 | G16: 0.45915464 | H16: 0.52397305 | I16: 86 000 | J16: 53 000 | K16: 0.75866687 | L16: 0.66573459 | M16: 0.37836894 | Q16: ATG | R16: Antigua and Barbuda | S16: 3 | T16: crude | U16: ctrl140 | V16: 6507.2856 | W16: 0.25480822 | X16: 0.28175312 | Y16: =+X16-W16 -> 0.026944906
A17: BLR | B17: EUR | C17: Belarus | D17: Belarus | E17: 9 057 000 | F17: 0.53998494 | G17: 0.52885288 | H17: 0.54939574 | I17: 3.2 million | J17: 2.8 million | K17: 0.74592501 | L17: 0.53739798 | M17: 0.12191955 | Q17: AUS | R17: Australia | S17: 3 | T17: crude | U17: ctrl140 | V17: 1485276.4 | W17: 0.28334492 | X17: 0.28700793 | Y17: =+X17-W17 -> 0.0036630034
A18: BEL | B18: EUR | C18: Belgium | D18: Belgium | E18: 11 740 000 | F18: 0.35070905 | G18: 0.37575898 | H18: 0.32591388 | I18: 2.5 million | J18: 1.4 million | K18: 0.73141915 | L18: 0.66941214 | M18: 0.42824572 | Q18: AUT | R18: Austria | S18: 3 | T18: crude | U18: ctrl140 | V18: 681557.69 | W18: 0.3139742 | X18: 0.35090956 | Y18: =+X18-W18 -> 0.036935359
A19: BLZ | B19: AMR | C19: Belize | D19: Belize | E19: 417 100 | F19: 0.37030411 | G19: 0.36937997 | H19: 0.37117913 | I19: 68 000 | J19: 53 000 | K19: 0.60574973 | L19: 0.45353037 | M19: 0.22931205 | Q19: AZE | R19: Azerbaijan | S19: 3 | T19: crude | U19: ctrl140 | V19: 364597.31 | W19: 0.14830217 | X19: 0.16252245 | Y19: =+X19-W19 -> 0.014220282
A20: BEN | B20: AFR | C20: Benin | D20: Benin | E20: 14 460 000 | F20: 0.25899792 | G20: 0.23451243 | H20: 0.28232104 | I20: 1.1 million | J20: 957 000 | K20: 0.41551059 | L20: 0.26470876 | M20: 0.1093098 | Q20: BDI | R20: Burundi | S20: 3 | T20: crude | U20: ctrl140 | V20: 132457.47 | W20: 0.12545674 | X20: 0.15454918 | Y20: =+X20-W20 -> 0.029092446
... A40: COG | B40: AFR | C40: Congo | D40: Congo | E40: 6 333 000 | F40: 0.36222741 | G40: 0.33715701 | H40: 0.38662389 | I40: 717 000 | J40: 636 000 | K40: 0.39301407 | L40: 0.24371909 | M40: 0.11282662 | Q40: CHL | R40: Chile | S40: 3 | T40: crude | U40: ctrl140 | V40: 1581763.2 | W40: 0.37391305 | X40: 0.41236633 | Y40: =+X40-W40 -> 0.038453281
A41: COK | B41: WPR | C41: Cook Islands | D41: Cook Islands | E41: 13 730 | F41: 0.48986831 | G41: 0.5004409 | H41: 0.48043373 | I41: 4800 | J41: 3900 | K41: 0.62803769 | L41: 0.47930694 | M41: 0.19560955 | Q41: CHN | R41: China | S41: 3 | T41: crude | U41: ctrl140 | V41: 50096176 | W41: 0.18453388 | X41: 0.21288836 | Y41: =+X41-W41 -> 0.028354481
A42: CRI | B42: AMR | C42: Costa Rica | D42: Costa Rica | E42: 5 130 000 | F42: 0.39033651 | G42: 0.36990809 | H42: 0.41026783 | I42: 1.2 million | J42: 512 000 | K42: 0.81704623 | L42: 0.75665319 | M42: 0.55520487 | Q42: CIV | R42: Ivory Coast | S42: 3 | T42: crude | U42: ctrl140 | V42: 293737.25 | W42: 0.10228874 | X42: 0.12691951 | Y42: =+X42-W42 -> 0.02463077
A43: HRV | B43: EUR | C43: Croatia | D43: Croatia | E43: 3 875 000 | F43: 0.57912576 | G43: 0.59248656 | H43: 0.56662953 | I43: 1.5 million | J43: 1.1 million | K43: 0.80653644 | L43: 0.61884409 | M43: 0.23284405 | Q43: CMR | R43: Cameroon | S43: 3 | T43: crude | U43: ctrl140 | V43: 242755.36 | W43: 0.082777984 | X43: 0.10055165 | Y43: =+X43-W43 -> 0.017773665
A44: CUB | B44: AMR | C44: Cuba | D44: Cuba | E44: 10 980 000 | F44: 0.46425918 | G44: 0.44801572 | H44: 0.4799912 | I44: 3.3 million | J44: 2.1 million | K44: 0.7490238 | L44: 0.65900528 | M44: 0.3651534 | Q44: COD | R44: Democratic Republic of the Congo | S44: 3 | T44: crude | U44: ctrl140 | V44: 1167100.2 | W44: 0.13204482 | X44: 0.1580267 | Y44: =+X44-W44 -> 0.025981873
A45: CYP | B45: EUR | C45: Cyprus | D45: Cyprus | E45: 1 358 000 | F45: 0.33332318 | G45: 0.37557802 | H45: 0.29221284 | I45: 248 000 | J45: 155 000 | K45: 0.69599271 | L45: 0.60275644 | M45: 0.37542126 | Q45: COG | R45: Congo | S45: 3 | T45: crude | U45: ctrl140 | V45: 80932.797 | W45: 0.11282662 | X45: 0.13862754 | Y45: =+X45-W45 -> 0.025800921
A46: CZE | B46: EUR | C46: Czechia | D46: Czechia | E46: 10 740 000 | F46: 0.48972061 | G46: 0.55697083 | H46: 0.42415977 | I46: 3.4 million | J46: 2 million | K46: 0.79615408 | L46: 0.7016384 | M46: 0.41031808 | Q46: COK | R46: Cook Islands | S46: 3 | T46: crude | U46: ctrl140 | V46: 938.39386 | W46: 0.19560955 | X46: 0.21539555 | Y46: =+X46-W46 -> 0.019786
A47: PRK | B47: SEAR | C47: Democratic People’s Republic of Korea | D47: Democratic People's Republic of Korea | E47: 26 500 000 | F47: 0.28730634 | G47: 0.29475933 | H47: 0.28034049 | I47: 4.3 million | J47: 3.2 million | K47: 0.57315534 | L47: 0.4676694 | M47: 0.25601324 | Q47: COL | R47: Colombia | S47: 3 | T47: crude | U47: ctrl140 | V47: 3245294.2 | W47: 0.36969075 | X47: 0.41953653 | Y47: =+X47-W47 -> 0.049845785
A48: COD | B48: AFR | C48: Democratic Republic of the Congo | D48: Democratic Republic of the Congo | E48: 109 300 000 | F48: 0.31483629 | G48: 0.28822213 | H48: 0.34049582 | I48: 8.8 million | J48: 7.7 million | K48: 0.40641773 | L48: 0.27249935 | M48: 0.13204482 | Q48: COM | R48: Comoros | S48: 3 | T48: crude | U48: ctrl140 | V48: 12171.088 | W48: 0.13255194 | X48: 0.16538861 | Y48: =+X48-W48 -> 0.032836676
A49: DNK | B49: EUR | C49: Denmark | D49: Denmark | E49: 5 977 000 | F49: 0.40491635 | G49: 0.47492266 | H49: 0.3359459 | I49: 1.4 million | J49: 1.2 million | K49: 0.64058214 | L49: 0.33866566 | M49: 0.12715143 | Q49: CPV | R49: Cabo Verde | S49: 3 | T49: crude | U49: ctrl140 | V49: 16192.491 | W49: 0.14735746 | X49: 0.18327707 | Y49: =+X49-W49 -> 0.035919607
A50: DJI | B50: EMR | C50: Djibouti | D50: Djibouti | E50: 1 169 000 | F50: 0.30559808 | G50: 0.28575978 | H50: 0.32714915 | I50: 145 000 | J50: 126 000 | K50: 0.41967076 | L50: 0.25681254 | M50: 0.13089179 | Q50: CRI | R50: Costa Rica | S50: 3 | T50: crude | U50: ctrl140 | V50: 639530.44 | W50: 0.55520487 | X50: 0.61629021 | Y50: =+X50-W50 -> 0.061085343
A51: DMA | B51: AMR | C51: Dominica | D51: Dominica | E51: 66 210 | F51: 0.48730233 | G51: 0.45953852 | H51: 0.51573861 | I51: 20 000 | J51: 16 000 | K51: 0.61533624 | L51: 0.4871518 | M51: 0.2012711 | Q51: CUB | R51: Cuba | S51: 3 | T51: crude | U51: ctrl140 | V51: 1202905 | W51: 0.3651534 | X51: 0.39527875 | Y51: =+X51-W51 -> 0.03012535
A52: DOM | B52: AMR | C52: Dominican Republic | D52: Dominican Republic | E52: 11 430 000 | F52: 0.4972364 | G52: 0.49285847 | H52: 0.50143719 | I52: 2.6 million | J52: 2 million | K52: 0.69677645 | L52: 0.55091512 | M52: 0.23310354 | Q52: CYP | R52: Cyprus | S52: 3 | T52: crude | U52: ctrl140 | V52: 93191.234 | W52: 0.37542126 | X52: 0.4133783 | Y52: =+X52-W52 -> 0.037957042
A53: ECU | B53: AMR | C53: Ecuador | D53: Ecuador | E53: 18 140 000 | F53: 0.28060457 | G53: 0.31355697 | H53: 0.24870723 | I53: 2.4 million | J53: 1.7 million | K53: 0.62635243 | L53: 0.50727069 | M53: 0.30289757 | Q53: CZE | R53: Czechia | S53: 3 | T53: crude | U53: ctrl140 | V53: 1408145.2 | W53: 0.41031808 | X53: 0.45508972 | Y53: =+X53-W53 -> 0.044771641
... A108: MLT | B108: EUR | C108: Malta | D108: Malta | E108: 539 600 | F108: 0.35987327 | G108: 0.39461651 | H108: 0.32437146 | I108: 104 000 | J108: 51 000 | K108: 0.78118974 | L108: 0.7406441 | M108: 0.50733453 | Q108: LBY | R108: Libya | S108: 3 | T108: crude | U108: ctrl140 | V108: 164192.41 | W108: 0.11820528 | X108: 0.14812113 | Y108: =+X108-W108 -> 0.029915854
A109: MHL | B109: WPR | C109: Marshall Islands | D109: Marshall Islands | E109: 37 550 | F109: 0.32036024 | G109: 0.30718675 | H109: 0.33393058 | I109: 6800 | J109: 5800 | K109: 0.47130409 | L109: 0.30182242 | M109: 0.15117688 | Q109: LCA | R109: Saint Lucia | S109: 3 | T109: crude | U109: ctrl140 | V109: 10812.04 | W109: 0.23869433 | X109: 0.26192454 | Y109: =+X109-W109 -> 0.02323021
A110: MRT | B110: AFR | C110: Mauritania | D110: Mauritania | E110: 5 169 000 | F110: 0.33440322 | G110: 0.30474409 | H110: 0.36348212 | I110: 584 000 | J110: 511 000 | K110: 0.45083874 | L110: 0.27045396 | M110: 0.12508741 | Q110: LKA | R110: Sri Lanka | S110: 3 | T110: crude | U110: ctrl140 | V110: 884961.75 | W110: 0.18705499 | X110: 0.2147132 | Y110: =+X110-W110 -> 0.027658209
A111: MUS | B111: AFR | C111: Mauritius | D111: Mauritius | E111: 1 271 000 | F111: 0.3571412 | G111: 0.35939005 | H111: 0.35500041 | I111: 276 000 | J111: 163 000 | K111: 0.73490518 | L111: 0.67747134 | M111: 0.41019771 | Q111: LSO | R111: Lesotho | S111: 3 | T111: crude | U111: ctrl140 | V111: 68039.297 | W111: 0.20699279 | X111: 0.24044284 | Y111: =+X111-W111 -> 0.033450052
A112: MEX | B112: AMR | C112: Mexico | D112: Mexico | E112: 130 900 000 | F112: 0.30612275 | G112: 0.30934817 | H112: 0.30323619 | I112: 20.2 million | J112: 13.8 million | K112: 0.62017584 | L112: 0.5387733 | M112: 0.31790951 | Q112: LTU | R112: Lithuania | S112: 3 | T112: crude | U112: ctrl140 | V112: 144791.23 | W112: 0.16224068 | X112: 0.19076239 | Y112: =+X112-W112 -> 0.028521702
A113: FSM | B113: WPR | C113: Micronesia (Federated States of) | D113: Micronesia (Federated States of) | E113: 113 200 | F113: 0.32580224 | G113: 0.29700014 | H113: 0.35478896 | I113: 16 000 | J113: 14 000 | K113: 0.53184873 | L113: 0.29146832 | M113: 0.15286335 | Q113: LUX | R113: Luxembourg | S113: 3 | T113: crude | U113: ctrl140 | V113: 43558.121 | W113: 0.34325638 | X113: 0.39746332 | Y113: =+X113-W113 -> 0.054206938
...
