Workbook

Sheet README
A1: Indonesia NCD FAIR Choices - cost & value workbook (formula edition)
A3: section | B3: detail
A4: Purpose | B4: Costing, budget impact and mortality-based cost-effectiveness for the FAIR Choices CVD interventions selected in indonesia_model_inputs.xlsx.
A5: How to read | B5: Grey cells are R-generated source values; light-blue cells are LIVE Excel formulas; pale-yellow cells on Calculation_Assumptions are editable controls. Change a yellow control and the blue results recompute. Calculation_Map lists every dependency.
A6: Scenarios | B6: Baseline + one scenario per selected valid intervention + a combined 'all' scenario. Membership derives only from the workbook selections (Model 04).
A7: Baseline pairing | B7: Deaths averted = baseline deaths - scenario deaths, matched at location x year x age x sex x cause (aggregated to year x cause here).
A8: CVD 40q30 | B8: CVD_40q30 / CVD_40q30_Age give the period probability of dying from the six CVD causes (ihd, istroke, hstroke, hhd, rhd, cmd) between exact ages 30 and 70, per scenario/HTN-target/year. The life table (m_x, q_x, l_x, l_{x+1}) is live Excel formula off grey CVD deaths and de-duplicated population; cvd_40q30 = 100*(1-l_70/l_30) reconciles to the Model 07 value. cvd_40q30 and the absolute reduction are PERCENT on a 0-100 scale (format 0.000), NOT Excel's fractional %.
A9: Model aggregates | B9: Annual_Mortality carries the R health aggregates (cases, deaths, baseline); Annual_Cost carries the full-precision R population quantity before the PIN fraction. The 157k-row state trace stays in the companion R workbook.
A10: Costing | B10: annual_cost = population_in_need x coverage(t) x frequency x unit_cost. PIN measure maps 'all'->eligible population, 'prevalence'->sick stock, 'incidence'->new cases.
A11: Shared costs | B11: Components flagged 'shared-count-once' (cost_join_key ...__C_SHARED) are counted once at intervention level, never once per affected cause (see Annual_Cost shared_duplicate_count and QA).
A12: Budget impact | B12: Budget impact reports UNDISCOUNTED baseline, scenario, incremental and cumulative incremental cost. Discounted costs are separate columns.
A13: Cost-effectiveness | B13: USD per death averted = cumulative discounted incremental cost / cumulative (undiscounted) deaths averted over the horizon. Not a DALY-based ICER.
A14: Economic value | B14: Reference-Case benefit-cost analysis (2019 Robinson et al. Guidelines): Health_Outcomes (Model 07 averted deaths/YLL/YLD/DALY & life-years gained), Economic_Value (Model 08 VSL/VSLY source with LIVE VSL-transfer, floor, VSLY, discount and PV-benefit formulas) and Benefit_Cost (PV benefits, PV costs converted to the benefit basis, net benefit and BCR). Preferred VSL = MAX(160xGNIpc_US x (GNIpc_IDN/GNIpc_US)^1.5, 20xGNIpc_IDN); 100x/160x GNI sensitivities. PARTIAL mortality-benefit BCA -- not a full societal BCA, and distinct from Cost_Effectiveness (USD per death averted).
... A18: Deferred | B18: Health outcomes (deaths averted, YLL/YLD/DALY averted, life-years gained) now come from Model 07 (Health_Outcomes); life-expectancy and disability-weight sources are documented via Model 07.

Sheet Run_Metadata
A1: item | B1: value
A2: Workbook title | B2: Indonesia NCD FAIR Choices - cost & value
A3: Run date | B3: 2026-08-27
A4: Model / pipeline | B4: CVD FAIR Choices (Models 00-06 -> 09)
A5: Input workbook | B5: C:/Users/wrgar/OneDrive - UW/02Work/WorldBank-Indonesia/uw-wb-indonesia-ncd//data/indonesia_70_30_30_to_70_70_70_inputs.xlsx
A6: Model output source | B6: output/out_model/model_output_*.rds (Model 06)
A7: Location | B7: Indonesia
A8: Analysis years | B8: =Calculation_Assumptions!B2&"-"&Calculation_Assumptions!B3 -> 2025-2050
A9: Baseline scenario | B9: =Calculation_Assumptions!B4 -> baseline
A10: Scenarios costed | B10: S_70_30_30_TO_70_70_70
A11: Cost discount rate | B11: =Calculation_Assumptions!B5 -> 0.03
A12: Cost price year | B12: =Calculation_Assumptions!B6 -> 2023
A13: Currency | B13: =Calculation_Assumptions!B7 -> USD
A14: Economic perspective | B14: =Calculation_Assumptions!B8 -> health_system
A15: Coverage scale-up shape | B15: =Calculation_Assumptions!B9 -> piecewise_linear
A16: Downstream cost offsets | B16: =Calculation_Assumptions!B10 -> 0
A17: Health outcomes (DALYs/YLL/YLD) | B17: Out of scope in this stage (deferred)
A18: R version | B18: R version 4.5.1 (2025-06-13 ucrt)
A19: openxlsx / data.table | B19: 4.2.8 / 1.17.8

Sheet Scenario_Catalog
A1: scenario | B1: scenario_label | C1: intervention_family | D1: scenario_level | E1: scenario_role | F1: parent_package_id | G1: intervention_ids | H1: n_interventions
A2: baseline | B2: Baseline (no new intervention) | C2: baseline | D2: baseline | H2: 0
A3: S_70_30_30_TO_70_70_70 | B3: 70-30-30 -> 70-70-70 hypertension/cholesterol + diabetes cascade | C3: cascade_70_30_30_to_70_70_70 | D3: combined | E3: combined | G3: I_CVD_PRIMARY; I_T2D_TREATMENT | H3: 2

Sheet Cascade_Assumptions
A1: parameter_id | B1: value | C1: unit | D1: description | E1: source | F1: source_workbook_cell
A2: analysis_start_year | B2: 2025 | C2: year | D2: First modeled year | E2: Agreed analysis horizon | F2: Assumptions![parameter_id=analysis_start_year]
A3: analysis_end_year | B3: 2050 | C3: year | D3: Last modeled year | E3: Agreed analysis horizon | F3: Assumptions![parameter_id=analysis_end_year]
A4: first_target_year | B4: 2030 | C4: year | D4: Year to achieve 70-30-30 | E4: World Bank/UW request, 27 Aug 2026 | F4: Assumptions![parameter_id=first_target_year]
A5: final_target_year | B5: 2040 | C5: year | D5: Year to achieve 70-70-70 | E5: World Bank/UW request, 27 Aug 2026 | F5: Assumptions![parameter_id=final_target_year]
A6: target_diagnosis_share | B6: 0.7 | C6: proportion | D6: Diagnosis step for both targets | E6: World Bank/UW request | F6: Assumptions![parameter_id=target_diagnosis_share]
A7: first_target_treatment_conditional | B7: 0.3 | C7: proportion | D7: Treated among diagnosed in 2030 | E7: 70-30-30 definition | F7: Assumptions![parameter_id=first_target_treatment_conditional]
A8: first_target_control_conditional | B8: 0.3 | C8: proportion | D8: Controlled among treated in 2030 | E8: 70-30-30 definition | F8: Assumptions![parameter_id=first_target_control_conditional]
A9: final_target_treatment_conditional | B9: 0.7 | C9: proportion | D9: Treated among diagnosed in 2040 | E9: 70-70-70 definition | F9: Assumptions![parameter_id=final_target_treatment_conditional]
A10: final_target_control_conditional | B10: 0.7 | C10: proportion | D10: Controlled among treated in 2040 | E10: 70-70-70 definition | F10: Assumptions![parameter_id=final_target_control_conditional]
A11: treated_uncontrolled_effect_fraction | B11: 0.5 | C11: share of full effect | D11: Effect received when treated but uncontrolled | E11: World Bank/UW request | F11: Assumptions![parameter_id=treated_uncontrolled_effect_fraction]
A12: first_target_effective_coverage_exact | B12: 0.1365 | C12: proportion | D12: Exact 70-30-30 effective coverage; no rounding override | E12: World Bank/UW cascade specification | F12: Assumptions![parameter_id=first_target_effective_coverage_exact]
A13: final_target_effective_coverage_exact | B13: 0.4165 | C13: proportion | D13: Exact 70-70-70 effective coverage; no rounding override | E13: World Bank/UW cascade specification | F13: Assumptions![parameter_id=final_target_effective_coverage_exact]
A14: diabetes_baseline_control_among_treated | B14: 0.34210526 | C14: proportion | D14: Derived as 6.5% controlled / 19.0% treated in the 2023 national diabetes cascade; editable | E14: Muharram et al. medRxiv 2026; peer-reviewed national estimate 32.0% HbA1c<7% | F14: Assumptions![parameter_id=diabetes_baseline_control_among_treated]
A15: diabetes_baseline_diagnosis_conditioning | B15: 1 | C15: proportion | D15: Conditions directly on all people with diabetes so reported treatment is reproduced | E15: Explicit modeling assumption | F15: Assumptions![parameter_id=diabetes_baseline_diagnosis_conditioning]
A16: cholesterol_coverage_proxy | B16: hypertension | C16: text | D16: Cholesterol coverage follows hypertension coverage | E16: World Bank/UW request | F16: Assumptions![parameter_id=cholesterol_coverage_proxy]
A17: scale_up_shape | B17: piecewise_linear | C17: text | D17: Linear to 2030, then linear to 2040 | E17: World Bank/UW request | F17: Assumptions![parameter_id=scale_up_shape]
A18: post_target_rule | B18: hold | C18: text | D18: Maintain achieved level after 2040 | E18: World Bank/UW request | F18: Assumptions![parameter_id=post_target_rule]
A19: prevent_coverage_backsliding | B19: 1 | C19: 0/1 | D19: When a measured baseline already exceeds a milestone, retain baseline rather than scale down | E19: Scale-up interpretation | F19: Assumptions![parameter_id=prevent_coverage_backsliding]
A20: scenario_id | B20: S_70_30_30_TO_70_70_70 | C20: text | D20: Stable scenario identifier | E20: This analysis | F20: Assumptions![parameter_id=scenario_id]
A21: cost_discount_rate | B21: 0.03 | C21: proportion/year | D21: Annual cost discount rate | E21: Supplied Indonesia input workbook | F21: Assumptions![parameter_id=cost_discount_rate]
A22: health_discount_rate | B22: 0.03 | C22: proportion/year | D22: Annual health discount rate | E22: Supplied Indonesia input workbook | F22: Assumptions![parameter_id=health_discount_rate]
A23: cost_price_year | B23: 2023 | C23: USD year | D23: Reporting price year | E23: Supplied Indonesia input workbook | F23: Assumptions![parameter_id=cost_price_year]
A24: currency | B24: USD | C24: currency | D24: Reporting currency | E24: Supplied Indonesia input workbook | F24: Assumptions![parameter_id=currency]

Sheet Cascade_Trajectory
A1: intervention_id | B1: risk_factor_id | C1: sex | D1: year | E1: phase | F1: baseline_effective_coverage | G1: target_2030_effective | H1: target_2040_effective | I1: controlled_share | J1: treated_uncontrolled_share | K1: half_effect_fraction | L1: scenario_effective_coverage | M1: effective_from_components | N1: model_effective_coverage_used
A2: I_CVD_PRIMARY | B2: RF_HTN | C2: Men | D2: 2025 | E2: Scale to 70-30-30 | F2: 0.094852977 | G2: 0.1365 | H2: 0.4165 | I2: 0.035834751 | J2: 0.11803645 | K2: 0.5 | L2: 0.094852977 | M2: =I2+Cascade_Assumptions!$B$11*J2 -> 0.094852977 | N2: =L2 -> 0.094852977
A3: I_CVD_PRIMARY | B3: RF_HTN | C3: Men | D3: 2026 | E3: Scale to 70-30-30 | F3: 0.094852977 | G3: 0.1365 | H3: 0.4165 | L3: 0.10318238 | N3: =L3 -> 0.10318238
A4: I_CVD_PRIMARY | B4: RF_HTN | C4: Men | D4: 2027 | E4: Scale to 70-30-30 | F4: 0.094852977 | G4: 0.1365 | H4: 0.4165 | L4: 0.11151179 | N4: =L4 -> 0.11151179
A5: I_CVD_PRIMARY | B5: RF_HTN | C5: Men | D5: 2028 | E5: Scale to 70-30-30 | F5: 0.094852977 | G5: 0.1365 | H5: 0.4165 | L5: 0.11984119 | N5: =L5 -> 0.11984119
A6: I_CVD_PRIMARY | B6: RF_HTN | C6: Men | D6: 2029 | E6: Scale to 70-30-30 | F6: 0.094852977 | G6: 0.1365 | H6: 0.4165 | L6: 0.1281706 | N6: =L6 -> 0.1281706
A7: I_CVD_PRIMARY | B7: RF_HTN | C7: Men | D7: 2030 | E7: Scale to 70-30-30 | F7: 0.094852977 | G7: 0.1365 | H7: 0.4165 | I7: 0.063 | J7: 0.147 | K7: 0.5 | L7: 0.1365 | M7: =I7+Cascade_Assumptions!$B$11*J7 -> 0.1365 | N7: =L7 -> 0.1365
A8: I_CVD_PRIMARY | B8: RF_HTN | C8: Men | D8: 2031 | E8: Scale to 70-70-70 | F8: 0.094852977 | G8: 0.1365 | H8: 0.4165 | L8: 0.1645 | N8: =L8 -> 0.1645
A9: I_CVD_PRIMARY | B9: RF_HTN | C9: Men | D9: 2032 | E9: Scale to 70-70-70 | F9: 0.094852977 | G9: 0.1365 | H9: 0.4165 | L9: 0.1925 | N9: =L9 -> 0.1925
A10: I_CVD_PRIMARY | B10: RF_HTN | C10: Men | D10: 2033 | E10: Scale to 70-70-70 | F10: 0.094852977 | G10: 0.1365 | H10: 0.4165 | L10: 0.2205 | N10: =L10 -> 0.2205
A11: I_CVD_PRIMARY | B11: RF_HTN | C11: Men | D11: 2034 | E11: Scale to 70-70-70 | F11: 0.094852977 | G11: 0.1365 | H11: 0.4165 | L11: 0.2485 | N11: =L11 -> 0.2485
A12: I_CVD_PRIMARY | B12: RF_HTN | C12: Men | D12: 2035 | E12: Scale to 70-70-70 | F12: 0.094852977 | G12: 0.1365 | H12: 0.4165 | L12: 0.2765 | N12: =L12 -> 0.2765
A13: I_CVD_PRIMARY | B13: RF_HTN | C13: Men | D13: 2036 | E13: Scale to 70-70-70 | F13: 0.094852977 | G13: 0.1365 | H13: 0.4165 | L13: 0.3045 | N13: =L13 -> 0.3045
A14: I_CVD_PRIMARY | B14: RF_HTN | C14: Men | D14: 2037 | E14: Scale to 70-70-70 | F14: 0.094852977 | G14: 0.1365 | H14: 0.4165 | L14: 0.3325 | N14: =L14 -> 0.3325
A15: I_CVD_PRIMARY | B15: RF_HTN | C15: Men | D15: 2038 | E15: Scale to 70-70-70 | F15: 0.094852977 | G15: 0.1365 | H15: 0.4165 | L15: 0.3605 | N15: =L15 -> 0.3605
A16: I_CVD_PRIMARY | B16: RF_HTN | C16: Men | D16: 2039 | E16: Scale to 70-70-70 | F16: 0.094852977 | G16: 0.1365 | H16: 0.4165 | L16: 0.3885 | N16: =L16 -> 0.3885
A17: I_CVD_PRIMARY | B17: RF_HTN | C17: Men | D17: 2040 | E17: Scale to 70-70-70 | F17: 0.094852977 | G17: 0.1365 | H17: 0.4165 | I17: 0.343 | J17: 0.147 | K17: 0.5 | L17: 0.4165 | M17: =I17+Cascade_Assumptions!$B$11*J17 -> 0.4165 | N17: =L17 -> 0.4165
A18: I_CVD_PRIMARY | B18: RF_HTN | C18: Men | D18: 2041 | E18: Maintain 70-70-70 | F18: 0.094852977 | G18: 0.1365 | H18: 0.4165 | L18: 0.4165 | N18: =L18 -> 0.4165
A19: I_CVD_PRIMARY | B19: RF_HTN | C19: Men | D19: 2042 | E19: Maintain 70-70-70 | F19: 0.094852977 | G19: 0.1365 | H19: 0.4165 | L19: 0.4165 | N19: =L19 -> 0.4165
A20: I_CVD_PRIMARY | B20: RF_HTN | C20: Men | D20: 2043 | E20: Maintain 70-70-70 | F20: 0.094852977 | G20: 0.1365 | H20: 0.4165 | L20: 0.4165 | N20: =L20 -> 0.4165
A21: I_CVD_PRIMARY | B21: RF_HTN | C21: Men | D21: 2044 | E21: Maintain 70-70-70 | F21: 0.094852977 | G21: 0.1365 | H21: 0.4165 | L21: 0.4165 | N21: =L21 -> 0.4165
A22: I_CVD_PRIMARY | B22: RF_HTN | C22: Men | D22: 2045 | E22: Maintain 70-70-70 | F22: 0.094852977 | G22: 0.1365 | H22: 0.4165 | L22: 0.4165 | N22: =L22 -> 0.4165
A23: I_CVD_PRIMARY | B23: RF_HTN | C23: Men | D23: 2046 | E23: Maintain 70-70-70 | F23: 0.094852977 | G23: 0.1365 | H23: 0.4165 | L23: 0.4165 | N23: =L23 -> 0.4165
A24: I_CVD_PRIMARY | B24: RF_HTN | C24: Men | D24: 2047 | E24: Maintain 70-70-70 | F24: 0.094852977 | G24: 0.1365 | H24: 0.4165 | L24: 0.4165 | N24: =L24 -> 0.4165
A25: I_CVD_PRIMARY | B25: RF_HTN | C25: Men | D25: 2048 | E25: Maintain 70-70-70 | F25: 0.094852977 | G25: 0.1365 | H25: 0.4165 | L25: 0.4165 | N25: =L25 -> 0.4165
A26: I_CVD_PRIMARY | B26: RF_HTN | C26: Men | D26: 2049 | E26: Maintain 70-70-70 | F26: 0.094852977 | G26: 0.1365 | H26: 0.4165 | L26: 0.4165 | N26: =L26 -> 0.4165
A27: I_CVD_PRIMARY | B27: RF_HTN | C27: Men | D27: 2050 | E27: Maintain 70-70-70 | F27: 0.094852977 | G27: 0.1365 | H27: 0.4165 | L27: 0.4165 | N27: =L27 -> 0.4165
A28: I_CVD_PRIMARY | B28: RF_HTN | C28: Women | D28: 2025 | E28: Scale to 70-30-30 | F28: 0.13268074 | G28: 0.1365 | H28: 0.4165 | I28: 0.051214394 | J28: 0.16293269 | K28: 0.5 | L28: 0.13268074 | M28: =I28+Cascade_Assumptions!$B$11*J28 -> 0.13268074 | N28: =L28 -> 0.13268074
A29: I_CVD_PRIMARY | B29: RF_HTN | C29: Women | D29: 2026 | E29: Scale to 70-30-30 | F29: 0.13268074 | G29: 0.1365 | H29: 0.4165 | L29: 0.13344459 | N29: =L29 -> 0.13344459
A30: I_CVD_PRIMARY | B30: RF_HTN | C30: Women | D30: 2027 | E30: Scale to 70-30-30 | F30: 0.13268074 | G30: 0.1365 | H30: 0.4165 | L30: 0.13420844 | N30: =L30 -> 0.13420844
A31: I_CVD_PRIMARY | B31: RF_HTN | C31: Women | D31: 2028 | E31: Scale to 70-30-30 | F31: 0.13268074 | G31: 0.1365 | H31: 0.4165 | L31: 0.1349723 | N31: =L31 -> 0.1349723
A32: I_CVD_PRIMARY | B32: RF_HTN | C32: Women | D32: 2029 | E32: Scale to 70-30-30 | F32: 0.13268074 | G32: 0.1365 | H32: 0.4165 | L32: 0.13573615 | N32: =L32 -> 0.13573615
A33: I_CVD_PRIMARY | B33: RF_HTN | C33: Women | D33: 2030 | E33: Scale to 70-30-30 | F33: 0.13268074 | G33: 0.1365 | H33: 0.4165 | I33: 0.063 | J33: 0.147 | K33: 0.5 | L33: 0.1365 | M33: =I33+Cascade_Assumptions!$B$11*J33 -> 0.1365 | N33: =L33 -> 0.1365
A34: I_CVD_PRIMARY | B34: RF_HTN | C34: Women | D34: 2031 | E34: Scale to 70-70-70 | F34: 0.13268074 | G34: 0.1365 | H34: 0.4165 | L34: 0.1645 | N34: =L34 -> 0.1645
A35: I_CVD_PRIMARY | B35: RF_HTN | C35: Women | D35: 2032 | E35: Scale to 70-70-70 | F35: 0.13268074 | G35: 0.1365 | H35: 0.4165 | L35: 0.1925 | N35: =L35 -> 0.1925
A36: I_CVD_PRIMARY | B36: RF_HTN | C36: Women | D36: 2033 | E36: Scale to 70-70-70 | F36: 0.13268074 | G36: 0.1365 | H36: 0.4165 | L36: 0.2205 | N36: =L36 -> 0.2205
A37: I_CVD_PRIMARY | B37: RF_HTN | C37: Women | D37: 2034 | E37: Scale to 70-70-70 | F37: 0.13268074 | G37: 0.1365 | H37: 0.4165 | L37: 0.2485 | N37: =L37 -> 0.2485
A38: I_CVD_PRIMARY | B38: RF_HTN | C38: Women | D38: 2035 | E38: Scale to 70-70-70 | F38: 0.13268074 | G38: 0.1365 | H38: 0.4165 | L38: 0.2765 | N38: =L38 -> 0.2765
A39: I_CVD_PRIMARY | B39: RF_HTN | C39: Women | D39: 2036 | E39: Scale to 70-70-70 | F39: 0.13268074 | G39: 0.1365 | H39: 0.4165 | L39: 0.3045 | N39: =L39 -> 0.3045
A40: I_CVD_PRIMARY | B40: RF_HTN | C40: Women | D40: 2037 | E40: Scale to 70-70-70 | F40: 0.13268074 | G40: 0.1365 | H40: 0.4165 | L40: 0.3325 | N40: =L40 -> 0.3325
...

Sheet Cascade_QA
A1: check_id | B1: check | C1: controlled_share | D1: treated_uncontrolled_share | E1: excel_effective | F1: expected_effective | G1: r_value | H1: status
A2: QAC01 | B2: 2030 effective coverage reconstructs to 0.1365 | C2: 0.063 | D2: 0.147 | E2: =C2+Cascade_Assumptions!$B$11*D2 -> 0.1365 | F2: 0.1365 | H2: =IF(ABS(E2-F2)<0.0000001,"PASS","CHECK") -> PASS
A3: QAC02 | B3: 2040 effective coverage reconstructs to 0.4165 | C3: 0.343 | D3: 0.147 | E3: =C3+Cascade_Assumptions!$B$11*D3 -> 0.4165 | F3: 0.4165 | H3: =IF(ABS(E3-F3)<0.0000001,"PASS","CHECK") -> PASS
A4: QAC03 | B4: Excel model_effective_coverage_used ties to R (by construction) | G4: 0 | H4: PASS
A5: QAC04 | B5: R adapter vs workbook Model_Input_View multipliers | G5: 0 | H5: =IF(G5<0.000001,"PASS","FAIL") -> PASS
A6: QAC05 | B6: Effective coverage is monotonic (no backsliding) | G6: 0 | H6: =IF(G6=0,"PASS","FAIL") -> PASS

Sheet Selected_Interventions
A1: intervention_id | B1: intervention_cause_key | C1: intervention_name | D1: cause_id | E1: cause_code | F1: model_name | G1: transition_from | H1: transition_to | I1: model_transition | J1: effect_value | K1: affected_fraction | L1: baseline_coverage | M1: target_coverage | N1: start_year | O1: target_year | P1: adjusted_effect_at_target | Q1: cost_join_key | R1: cost_scope | S1: effect_review | T1: coverage_review | U1: key_count | V1: formula_status
A2: I_CVD_PRIMARY | B2: I_CVD_PRIMARY__C_HHD | C2: Primary prevention of CVD | D2: C_HHD | E2: hhd | F2: Hypertensive heart disease | G2: well | H2: sick | I2: incidence | J2: 0.47 | K2: 1 | L2: 0.11376686 | M2: 0.4165 | N2: 2025 | O2: 2040 | P2: =IF(OR(J2="",K2="",L2="",M2=""),"",ROUND(K2*(J2*(M2-L2)/(1-J2*L2)),4)) -> 0.1503 | Q2: I_CVD_PRIMARY__C_SHARED | R2: shared-count-once | S2: Provisional | T2: OK (cascade trajectory) | U2: =COUNTIF($B$2:$B$7,B2) -> 1 | V2: =IF(U2=1,"OK","DUPLICATE KEY") -> OK
A3: I_CVD_PRIMARY | B3: I_CVD_PRIMARY__C_ICH | C3: Primary prevention of CVD | D3: C_ICH | E3: hstroke | F3: Intracerebral hemorrhage | G3: well | H3: sick | I3: incidence | J3: 0.49 | K3: 0.8 | L3: 0.11376686 | M3: 0.4165 | N3: 2025 | O3: 2040 | P3: =IF(OR(J3="",K3="",L3="",M3=""),"",ROUND(K3*(J3*(M3-L3)/(1-J3*L3)),4)) -> 0.1257 | Q3: I_CVD_PRIMARY__C_SHARED | R3: shared-count-once | S3: Provisional | T3: OK (cascade trajectory) | U3: =COUNTIF($B$2:$B$7,B3) -> 1 | V3: =IF(U3=1,"OK","DUPLICATE KEY") -> OK
A4: I_CVD_PRIMARY | B4: I_CVD_PRIMARY__C_IHD | C4: Primary prevention of CVD | D4: C_IHD | E4: ihd | F4: Ischemic heart disease | G4: well | H4: sick | I4: incidence | J4: 0.58 | K4: 0.8 | L4: 0.11376686 | M4: 0.4165 | N4: 2025 | O4: 2040 | P4: =IF(OR(J4="",K4="",L4="",M4=""),"",ROUND(K4*(J4*(M4-L4)/(1-J4*L4)),4)) -> 0.1504 | Q4: I_CVD_PRIMARY__C_SHARED | R4: shared-count-once | S4: Provisional | T4: OK (cascade trajectory) | U4: =COUNTIF($B$2:$B$7,B4) -> 1 | V4: =IF(U4=1,"OK","DUPLICATE KEY") -> OK
A5: I_CVD_PRIMARY | B5: I_CVD_PRIMARY__C_IS | C5: Primary prevention of CVD | D5: C_IS | E5: istroke | F5: Ischemic stroke | G5: well | H5: sick | I5: incidence | J5: 0.54 | K5: 0.8 | L5: 0.11376686 | M5: 0.4165 | N5: 2025 | O5: 2040 | P5: =IF(OR(J5="",K5="",L5="",M5=""),"",ROUND(K5*(J5*(M5-L5)/(1-J5*L5)),4)) -> 0.1393 | Q5: I_CVD_PRIMARY__C_SHARED | R5: shared-count-once | S5: Provisional | T5: OK (cascade trajectory) | U5: =COUNTIF($B$2:$B$7,B5) -> 1 | V5: =IF(U5=1,"OK","DUPLICATE KEY") -> OK
A6: I_T2D_TREATMENT | B6: I_T2D_TREATMENT__C_T2D | C6: Longitudinal treatment of type 2 diabetes | D6: C_T2D | E6: dm2 | F6: Type 2 diabetes | G6: sick | H6: dead_t2d | I6: case_fatality | J6: 0.28 | K6: 1 | L6: 0.14791461 | M6: 0.4165 | N6: 2025 | O6: 2040 | P6: =IF(OR(J6="",K6="",L6="",M6=""),"",ROUND(K6*(J6*(M6-L6)/(1-J6*L6)),4)) -> 0.0785 | Q6: I_T2D_TREATMENT__C_T2D | R6: cause-specific | S6: Provisional | T6: OK (cascade trajectory) | U6: =COUNTIF($B$2:$B$7,B6) -> 1 | V6: =IF(U6=1,"OK","DUPLICATE KEY") -> OK
A7: I_T2D_TREATMENT | B7: I_T2D_TREATMENT__C_IHD | C7: Longitudinal treatment of type 2 diabetes | D7: C_IHD | E7: ihd | F7: Ischemic heart disease | G7: sick | H7: dead_ihd | I7: case_fatality | J7: 0.15 | K7: 0.15 | L7: 0.14791461 | M7: 0.4165 | N7: 2025 | O7: 2040 | P7: =IF(OR(J7="",K7="",L7="",M7=""),"",ROUND(K7*(J7*(M7-L7)/(1-J7*L7)),4)) -> 0.0062 | Q7: I_T2D_TREATMENT__C_T2D | R7: shared-count-once | S7: Review | T7: OK (cascade trajectory) | U7: =COUNTIF($B$2:$B$7,B7) -> 1 | V7: =IF(U7=1,"OK","DUPLICATE KEY") -> OK

Sheet Cost_Components
A1: cost_record_id | B1: cost_component_key | C1: cost_option | D1: intervention_id | E1: cause_id | F1: cause_code | G1: cost_join_key | H1: cost_scope | I1: cost_component | J1: population_in_need_measure | K1: population_in_need_fraction | L1: frequency_per_year | M1: c_age_start | N1: c_age_stop | O1: c_sex | P1: unit_cost_usd | Q1: price_year | R1: indonesia_adjusted_flag | S1: cov_baseline | T1: cov_target | U1: cov_start_year | V1: cov_target_year | W1: cost_review | X1: cost_ready
A2: COST_PRIMARY_TX_A | B2: CC_PRIMARY_HTN_STATIN | C2: Option A (selected) | D2: I_CVD_PRIMARY | E2: C_SHARED | G2: I_CVD_PRIMARY__C_SHARED | H2: shared-count-once | I2: Antihypertensives and statins for absolute CVD risk >20% | J2: all | K2: 0.06 | L2: 1 | M2: 30 | N2: 95 | O2: Both | P2: 22.2296 | Q2: 2023 | R2: 1 | S2: =IFERROR(INDEX(Selected_Interventions!$L$2:$L$7,MATCH(G2,Selected_Interventions!$Q$2:$Q$7,0)),"") -> 0.11376686 | T2: =IFERROR(INDEX(Selected_Interventions!$M$2:$M$7,MATCH(G2,Selected_Interventions!$Q$2:$Q$7,0)),"") -> 0.4165 | U2: =IFERROR(INDEX(Selected_Interventions!$N$2:$N$7,MATCH(G2,Selected_Interventions!$Q$2:$Q$7,0)),"") -> 2025 | V2: =IFERROR(INDEX(Selected_Interventions!$O$2:$O$7,MATCH(G2,Selected_Interventions!$Q$2:$Q$7,0)),"") -> 2040 | W2: Review | X2: =IF(AND(P2<>"",P2>=0,S2<>"",K2<>"",K2>=0,K2<=1,OR(J2="all",J2="prevalence",J2="incidence")),1,0) -> 1
A3: COST_PRIMARY_SCREEN_A | B3: CC_PRIMARY_SCREENING | C3: Option A (selected) | D3: I_CVD_PRIMARY | E3: C_SHARED | G3: I_CVD_PRIMARY__C_SHARED | H3: shared-count-once | I3: CVD targeted screening | J3: all | K3: 0.2 | L3: 1 | M3: 30 | N3: 95 | O3: Both | P3: 1.291584 | Q3: 2023 | R3: 1 | S3: =IFERROR(INDEX(Selected_Interventions!$L$2:$L$7,MATCH(G3,Selected_Interventions!$Q$2:$Q$7,0)),"") -> 0.11376686 | T3: =IFERROR(INDEX(Selected_Interventions!$M$2:$M$7,MATCH(G3,Selected_Interventions!$Q$2:$Q$7,0)),"") -> 0.4165 | U3: =IFERROR(INDEX(Selected_Interventions!$N$2:$N$7,MATCH(G3,Selected_Interventions!$Q$2:$Q$7,0)),"") -> 2025 | V3: =IFERROR(INDEX(Selected_Interventions!$O$2:$O$7,MATCH(G3,Selected_Interventions!$Q$2:$Q$7,0)),"") -> 2040 | W3: Review | X3: =IF(AND(P3<>"",P3>=0,S3<>"",K3<>"",K3>=0,K3<=1,OR(J3="all",J3="prevalence",J3="incidence")),1,0) -> 1
A4: COST_T2D_INSULIN | B4: CC_T2D_INSULIN | C4: Base | D4: I_T2D_TREATMENT | E4: C_T2D | F4: dm2 | G4: I_T2D_TREATMENT__C_T2D | H4: cause-specific | I4: Diabetes management, insulin dependent | J4: prevalence | K4: 0.2 | L4: 1 | M4: 30 | N4: 95 | O4: Both | P4: 1154.0355 | Q4: 2023 | R4: 1 | S4: =IFERROR(INDEX(Selected_Interventions!$L$2:$L$7,MATCH(G4,Selected_Interventions!$Q$2:$Q$7,0)),"") -> 0.14791461 | T4: =IFERROR(INDEX(Selected_Interventions!$M$2:$M$7,MATCH(G4,Selected_Interventions!$Q$2:$Q$7,0)),"") -> 0.4165 | U4: =IFERROR(INDEX(Selected_Interventions!$N$2:$N$7,MATCH(G4,Selected_Interventions!$Q$2:$Q$7,0)),"") -> 2025 | V4: =IFERROR(INDEX(Selected_Interventions!$O$2:$O$7,MATCH(G4,Selected_Interventions!$Q$2:$Q$7,0)),"") -> 2040 | W4: Ready | X4: =IF(AND(P4<>"",P4>=0,S4<>"",K4<>"",K4>=0,K4<=1,OR(J4="all",J4="prevalence",J4="incidence")),1,0) -> 1
A5: COST_T2D_NONINSULIN | B5: CC_T2D_NONINSULIN | C5: Base | D5: I_T2D_TREATMENT | E5: C_T2D | F5: dm2 | G5: I_T2D_TREATMENT__C_T2D | H5: cause-specific | I5: Diabetes management, non insulin dependent | J5: prevalence | K5: 0.6 | L5: 1 | M5: 30 | N5: 95 | O5: Both | P5: 752.57623 | Q5: 2023 | R5: 1 | S5: =IFERROR(INDEX(Selected_Interventions!$L$2:$L$7,MATCH(G5,Selected_Interventions!$Q$2:$Q$7,0)),"") -> 0.14791461 | T5: =IFERROR(INDEX(Selected_Interventions!$M$2:$M$7,MATCH(G5,Selected_Interventions!$Q$2:$Q$7,0)),"") -> 0.4165 | U5: =IFERROR(INDEX(Selected_Interventions!$N$2:$N$7,MATCH(G5,Selected_Interventions!$Q$2:$Q$7,0)),"") -> 2025 | V5: =IFERROR(INDEX(Selected_Interventions!$O$2:$O$7,MATCH(G5,Selected_Interventions!$Q$2:$Q$7,0)),"") -> 2040 | W5: Ready | X5: =IF(AND(P5<>"",P5>=0,S5<>"",K5<>"",K5>=0,K5<=1,OR(J5="all",J5="prevalence",J5="incidence")),1,0) -> 1
A6: COST_T2D_SCREEN | B6: CC_T2D_SCREENING | C6: Base | D6: I_T2D_TREATMENT | E6: C_T2D | F6: dm2 | G6: I_T2D_TREATMENT__C_T2D | H6: cause-specific | I6: Diabetes opportunistic screening | J6: all | K6: 0.2 | L6: 1 | M6: 30 | N6: 95 | O6: Both | P6: 0.70495848 | Q6: 2023 | R6: 1 | S6: =IFERROR(INDEX(Selected_Interventions!$L$2:$L$7,MATCH(G6,Selected_Interventions!$Q$2:$Q$7,0)),"") -> 0.14791461 | T6: =IFERROR(INDEX(Selected_Interventions!$M$2:$M$7,MATCH(G6,Selected_Interventions!$Q$2:$Q$7,0)),"") -> 0.4165 | U6: =IFERROR(INDEX(Selected_Interventions!$N$2:$N$7,MATCH(G6,Selected_Interventions!$Q$2:$Q$7,0)),"") -> 2025 | V6: =IFERROR(INDEX(Selected_Interventions!$O$2:$O$7,MATCH(G6,Selected_Interventions!$Q$2:$Q$7,0)),"") -> 2040 | W6: Ready | X6: =IF(AND(P6<>"",P6>=0,S6<>"",K6<>"",K6>=0,K6<=1,OR(J6="all",J6="prevalence",J6="incidence")),1,0) -> 1

Sheet Annual_Mortality
A1: scenario | B1: scenario_label | C1: year | D1: cause | E1: cases | F1: cause_deaths | G1: base_deaths | H1: deaths_averted | I1: base_cases | J1: cases_averted
A2: S_70_30_30_TO_70_70_70 | B2: 70-30-30 -> 70-70-70 hypertension/cholesterol + diabetes cascade | C2: 2025 | D2: cmd | E2: 8428.906 | F2: 9668.8228 | G2: 9668.8228 | H2: =G2-F2 -> 0 | I2: 8428.906 | J2: =I2-E2 -> 0
A3: S_70_30_30_TO_70_70_70 | B3: 70-30-30 -> 70-70-70 hypertension/cholesterol + diabetes cascade | C3: 2025 | D3: dm2 | E3: 479897.33 | F3: 159105.61 | G3: 159105.61 | H3: =G3-F3 -> 0 | I3: 479897.33 | J3: =I3-E3 -> 0
A4: S_70_30_30_TO_70_70_70 | B4: 70-30-30 -> 70-70-70 hypertension/cholesterol + diabetes cascade | C4: 2025 | D4: hhd | E4: 76355.817 | F4: 63094.531 | G4: 63094.531 | H4: =G4-F4 -> 0 | I4: 76355.817 | J4: =I4-E4 -> 0
A5: S_70_30_30_TO_70_70_70 | B5: 70-30-30 -> 70-70-70 hypertension/cholesterol + diabetes cascade | C5: 2025 | D5: hstroke | E5: 207904.95 | F5: 240064.29 | G5: 240064.29 | H5: =G5-F5 -> 0 | I5: 207904.95 | J5: =I5-E5 -> 0
A6: S_70_30_30_TO_70_70_70 | B6: 70-30-30 -> 70-70-70 hypertension/cholesterol + diabetes cascade | C6: 2025 | D6: ihd | E6: 306292.01 | F6: 368786.79 | G6: 368786.79 | H6: =G6-F6 -> 0 | I6: 306292.01 | J6: =I6-E6 -> 0
A7: S_70_30_30_TO_70_70_70 | B7: 70-30-30 -> 70-70-70 hypertension/cholesterol + diabetes cascade | C7: 2025 | D7: istroke | E7: 197300.31 | F7: 222132.33 | G7: 222132.33 | H7: =G7-F7 -> 0 | I7: 197300.31 | J7: =I7-E7 -> 0
A8: S_70_30_30_TO_70_70_70 | B8: 70-30-30 -> 70-70-70 hypertension/cholesterol + diabetes cascade | C8: 2025 | D8: rhd | E8: 34256.139 | F8: 4628.4589 | G8: 4628.4589 | H8: =G8-F8 -> 0 | I8: 34256.139 | J8: =I8-E8 -> 0
A9: S_70_30_30_TO_70_70_70 | B9: 70-30-30 -> 70-70-70 hypertension/cholesterol + diabetes cascade | C9: 2026 | D9: cmd | E9: 8487.1725 | F9: 8630.3167 | G9: 8630.3167 | H9: =G9-F9 -> 0 | I9: 8487.1725 | J9: =I9-E9 -> 0
A10: S_70_30_30_TO_70_70_70 | B10: 70-30-30 -> 70-70-70 hypertension/cholesterol + diabetes cascade | C10: 2026 | D10: dm2 | E10: 487916.82 | F10: 158982.03 | G10: 159012.29 | H10: =G10-F10 -> 30.264394 | I10: 487916.82 | J10: =I10-E10 -> 0
A11: S_70_30_30_TO_70_70_70 | B11: 70-30-30 -> 70-70-70 hypertension/cholesterol + diabetes cascade | C11: 2026 | D11: hhd | E11: 77731.461 | F11: 59835.223 | G11: 59835.223 | H11: =G11-F11 -> 0 | I11: 77888.093 | J11: =I11-E11 -> 156.63199
A12: S_70_30_30_TO_70_70_70 | B12: 70-30-30 -> 70-70-70 hypertension/cholesterol + diabetes cascade | C12: 2026 | D12: hstroke | E12: 211661.78 | F12: 217295.45 | G12: 217295.45 | H12: =G12-F12 -> 0 | I12: 212035.13 | J12: =I12-E12 -> 373.34704
A13: S_70_30_30_TO_70_70_70 | B13: 70-30-30 -> 70-70-70 hypertension/cholesterol + diabetes cascade | C13: 2026 | D13: ihd | E13: 312510.74 | F13: 341944.06 | G13: 341949.4 | H13: =G13-F13 -> 5.3434396 | I13: 313184.01 | J13: =I13-E13 -> 673.26756
... A365: baseline | B365: Baseline (no new intervention) | C365: 2050 | D365: rhd | E365: 33050.354 | F365: 3414.3732 | G365: 3414.3732 | H365: =G365-F365 -> 0 | I365: 33050.354 | J365: =I365-E365 -> 0

Sheet Health_Outcomes
A1: scenario | B1: scenario_label | C1: year | D1: modeled_deaths | E1: baseline_deaths | F1: deaths_averted | G1: modeled_cases | H1: baseline_cases | I1: cases_averted | J1: yll | K1: base_yll | L1: yll_averted | M1: yld | N1: base_yld | O1: yld_averted | P1: daly | Q1: base_daly | R1: dalys_averted | S1: life_years_gained
A2: S_70_30_30_TO_70_70_70 | B2: 70-30-30 -> 70-70-70 hypertension/cholesterol + diabetes cascade | C2: 2025 | D2: 1067480.8 | E2: 1067480.8 | F2: =E2-D2 -> 0 | G2: 1310435.5 | H2: 1310435.5 | I2: =H2-G2 -> 0 | J2: 13787600 | K2: 13787600 | L2: =K2-J2 -> 0 | M2: 2532778.1 | N2: 2532778.1 | O2: =N2-M2 -> 0 | P2: 16320378 | Q2: 16320378 | R2: =Q2-P2 -> 0 | S2: =L2 -> 0
A3: S_70_30_30_TO_70_70_70 | B3: 70-30-30 -> 70-70-70 hypertension/cholesterol + diabetes cascade | C3: 2026 | D3: 988228.4 | E3: 988264.01 | F3: =E3-D3 -> 35.607834 | G3: 1333917.2 | H3: 1335499.8 | I3: =H3-G3 -> 1582.5916 | J3: 13277788 | K3: 13278266 | L3: =K3-J3 -> 478.73259 | M3: 2502931.9 | N3: 2503113.8 | O3: =N3-M3 -> 181.92052 | P3: 15780720 | Q3: 15781380 | R3: =Q3-P3 -> 660.65311 | S3: =L3 -> 478.73259
A4: S_70_30_30_TO_70_70_70 | B4: 70-30-30 -> 70-70-70 hypertension/cholesterol + diabetes cascade | C4: 2027 | D4: 949264.03 | E4: 949562.22 | F4: =E4-D4 -> 298.18274 | G4: 1359906.5 | H4: 1363154.3 | I4: =H4-G4 -> 3247.834 | J4: 12987806 | K4: 12992035 | L4: =K4-J4 -> 4229.0226 | M4: 2482891.1 | N4: 2483407.1 | O4: =N4-M4 -> 515.95624 | P4: 15470697 | Q4: 15475442 | R4: =Q4-P4 -> 4744.9789 | S4: =L4 -> 4229.0226
A5: S_70_30_30_TO_70_70_70 | B5: 70-30-30 -> 70-70-70 hypertension/cholesterol + diabetes cascade | C5: 2028 | D5: 926448.71 | E5: 927155.13 | F5: =E5-D5 -> 706.42037 | G5: 1387213.5 | H5: 1392211.2 | I5: =H5-G5 -> 4997.7491 | J5: 12802365 | K5: 12812694 | L5: =K5-J5 -> 10328.318 | M5: 2469844.7 | N5: 2470833.6 | O5: =N5-M5 -> 988.85715 | P5: 15272210 | Q5: 15283527 | R5: =Q5-P5 -> 11317.175 | S5: =L5 -> 10328.318
A6: S_70_30_30_TO_70_70_70 | B6: 70-30-30 -> 70-70-70 hypertension/cholesterol + diabetes cascade | C6: 2029 | D6: 913539.82 | E6: 914778.28 | F6: =E6-D6 -> 1238.4598 | G6: 1415376.7 | H6: 1422211.3 | I6: =H6-G6 -> 6834.6045 | J6: 12696432 | K6: 12714850 | L6: =K6-J6 -> 18417.507 | M6: 2462110.4 | N6: 2463702.1 | O6: =N6-M6 -> 1591.7739 | P6: 15158542 | Q6: 15178552 | R6: =Q6-P6 -> 20009.281 | S6: =L6 -> 18417.507
A7: S_70_30_30_TO_70_70_70 | B7: 70-30-30 -> 70-70-70 hypertension/cholesterol + diabetes cascade | C7: 2030 | D7: 907172.06 | E7: 909052.97 | F7: =E7-D7 -> 1880.9183 | G7: 1444111.1 | H7: 1452871.1 | I7: =H7-G7 -> 8760.0221 | J7: 12636399 | K7: 12664641 | L7: =K7-J7 -> 28241.963 | M7: 2458567.2 | N7: 2460885.7 | O7: =N7-M7 -> 2318.4214 | P7: 15094966 | Q7: 15125527 | R7: =Q7-P7 -> 30560.385 | S7: =L7 -> 28241.963
A8: S_70_30_30_TO_70_70_70 | B8: 70-30-30 -> 70-70-70 hypertension/cholesterol + diabetes cascade | C8: 2031 | D8: 902972.53 | E8: 907044.24 | F8: =E8-D8 -> 4071.7085 | G8: 1464851.5 | H8: 1483835.4 | I8: =H8-G8 -> 18983.872 | J8: 12598180 | K8: 12656050 | L8: =K8-J8 -> 57869.036 | M8: 2457757.4 | N8: 2461774.3 | O8: =N8-M8 -> 4016.8844 | P8: 15055938 | Q8: 15117824 | R8: =Q8-P8 -> 61885.92 | S8: =L8 -> 57869.036
A9: S_70_30_30_TO_70_70_70 | B9: 70-30-30 -> 70-70-70 hypertension/cholesterol + diabetes cascade | C9: 2032 | D9: 901420.28 | E9: 908870.88 | F9: =E9-D9 -> 7450.5935 | G9: 1485232.9 | H9: 1514938.3 | I9: =H9-G9 -> 29705.409 | J9: 12572523 | K9: 12676617 | L9: =K9-J9 -> 104094.46 | M9: 2459146.6 | N9: 2465693.1 | O9: =N9-M9 -> 6546.5329 | P9: 15031669 | Q9: 15142310 | R9: =Q9-P9 -> 110640.99 | S9: =L9 -> 104094.46
A10: S_70_30_30_TO_70_70_70 | B10: 70-30-30 -> 70-70-70 hypertension/cholesterol + diabetes cascade | C10: 2033 | D10: 901875.45 | E10: 913563.02 | F10: =E10-D10 -> 11687.569 | G10: 1505164.2 | H10: 1546062.3 | I10: =H10-G10 -> 40898.109 | J10: 12555272 | K10: 12718240 | L10: =K10-J10 -> 162967.44 | M10: 2462306.4 | N10: 2472136.3 | O10: =N10-M10 -> 9829.9476 | P10: 15017579 | Q10: 15190376 | R10: =Q10-P10 -> 172797.39 | S10: =L10 -> 162967.44
A11: S_70_30_30_TO_70_70_70 | B11: 70-30-30 -> 70-70-70 hypertension/cholesterol + diabetes cascade | C11: 2034 | D11: 904062.59 | E11: 920723.39 | F11: =E11-D11 -> 16660.797 | G11: 1524865.1 | H11: 1577410.5 | I11: =H11-G11 -> 52545.428 | J11: 12560562 | K11: 12793363 | L11: =K11-J11 -> 232801.26 | M11: 2466903.6 | N11: 2480715.2 | O11: =N11-M11 -> 13811.612 | P11: 15027466 | Q11: 15274079 | R11: =Q11-P11 -> 246612.87 | S11: =L11 -> 232801.26
A12: S_70_30_30_TO_70_70_70 | B12: 70-30-30 -> 70-70-70 hypertension/cholesterol + diabetes cascade | C12: 2035 | D12: 907779.26 | E12: 930075.42 | F12: =E12-D12 -> 22296.163 | G12: 1544452.3 | H12: 1609084.4 | I12: =H12-G12 -> 64632.029 | J12: 12572880 | K12: 12885098 | L12: =K12-J12 -> 312217.85 | M12: 2472636.6 | N12: 2491084.7 | O12: =N12-M12 -> 18448.107 | P12: 15045516 | Q12: 15376182 | R12: =Q12-P12 -> 330665.95 | S12: =L12 -> 312217.85
A13: S_70_30_30_TO_70_70_70 | B13: 70-30-30 -> 70-70-70 hypertension/cholesterol + diabetes cascade | C13: 2036 | D13: 913082.2 | E13: 941635.34 | F13: =E13-D13 -> 28553.139 | G13: 1563949.1 | H13: 1641090.6 | I13: =H13-G13 -> 77141.587 | J13: 12593721 | K13: 12994091 | L13: =K13-J13 -> 400370.5 | M13: 2479196.3 | N13: 2502898 | O13: =N13-M13 -> 23701.706 | P13: 15072917 | Q13: 15496989 | R13: =Q13-P13 -> 424072.21 | S13: =L13 -> 400370.5
... A27: S_70_30_30_TO_70_70_70 | B27: 70-30-30 -> 70-70-70 hypertension/cholesterol + diabetes cascade | C27: 2050 | D27: 1091622.8 | E27: 1189997.7 | F27: =E27-D27 -> 98374.925 | G27: 1951392.3 | H27: 2089872.9 | I27: =H27-G27 -> 138480.64 | J27: 13708939 | K27: 15111483 | L27: =K27-J27 -> 1402543.5 | M27: 2642063.5 | N27: 2736683.5 | O27: =N27-M27 -> 94620.016 | P27: 16351003 | Q27: 17848166 | R27: =Q27-P27 -> 1497163.5 | S27: =L27 -> 1402543.5

Sheet CVD_40q30
A1: location | B1: scenario | C1: scenario_label | D1: intervention_family | E1: scenario_role | F1: parent_package_id | G1: htn_target_scenario | H1: year | I1: cvd_40q30 | J1: baseline_cvd_40q30 | K1: absolute_reduction_pp | L1: percent_reduction | M1: cvd_40q30_r | N1: recon_status
A2: Indonesia | B2: S_70_30_30_TO_70_70_70 | C2: 70-30-30 -> 70-70-70 hypertension/cholesterol + diabetes cascade | D2: cascade_70_30_30_to_70_70_70 | E2: combined | G2: htncov2_aspirational | H2: 2025 | I2: =100*(1-(SUMIFS(CVD_40q30_Age!$M$2:$M$2081,CVD_40q30_Age!$A$2:$A$2081,A2,CVD_40q30_Age!$B$2:$B$2081,B2,CVD_40q30_Age!$E$2:$E$2081,G2,CVD_40q30_Age!$F$2:$F$2081,H2,CVD_40q30_Age!$G$2:$G$2081,69))/(SUMIFS(CVD_40q30_Age!$L$2:$L$2081,CVD_40q30_Age!$A$2:$A$2081,A2,CVD_40q30_Age!$B$2:$B$2081,B2,CVD_40q30_Age!$E$2:$E$2081,G2,CVD_40q30_Age!$F$2:$F$2081,H2,CVD_40q30_Age!$G$2:$G$2081,30))) -> 14.504478 | J2: =SUMIFS($I$2:$I$53,$A$2:$A$53,A2,$G$2:$G$53,G2,$H$2:$H$53,H2,$B$2:$B$53,"baseline") -> 14.504478 | K2: =J2-I2 -> 0 | L2: =IF(J2=0,"",100*(J2-I2)/J2) -> 0 | M2: 14.504478 | N2: =IF(ABS(I2-M2)<=0.001,"match","mismatch") -> match
A3: Indonesia | B3: S_70_30_30_TO_70_70_70 | C3: 70-30-30 -> 70-70-70 hypertension/cholesterol + diabetes cascade | D3: cascade_70_30_30_to_70_70_70 | E3: combined | G3: htncov2_aspirational | H3: 2026 | I3: =100*(1-(SUMIFS(CVD_40q30_Age!$M$2:$M$2081,CVD_40q30_Age!$A$2:$A$2081,A3,CVD_40q30_Age!$B$2:$B$2081,B3,CVD_40q30_Age!$E$2:$E$2081,G3,CVD_40q30_Age!$F$2:$F$2081,H3,CVD_40q30_Age!$G$2:$G$2081,69))/(SUMIFS(CVD_40q30_Age!$L$2:$L$2081,CVD_40q30_Age!$A$2:$A$2081,A3,CVD_40q30_Age!$B$2:$B$2081,B3,CVD_40q30_Age!$E$2:$E$2081,G3,CVD_40q30_Age!$F$2:$F$2081,H3,CVD_40q30_Age!$G$2:$G$2081,30))) -> 13.740436 | J3: =SUMIFS($I$2:$I$53,$A$2:$A$53,A3,$G$2:$G$53,G3,$H$2:$H$53,H3,$B$2:$B$53,"baseline") -> 13.740526 | K3: =J3-I3 -> 8.9519892e-05 | L3: =IF(J3=0,"",100*(J3-I3)/J3) -> 0.00065150267 | M3: 13.740436 | N3: =IF(ABS(I3-M3)<=0.001,"match","mismatch") -> match
A4: Indonesia | B4: S_70_30_30_TO_70_70_70 | C4: 70-30-30 -> 70-70-70 hypertension/cholesterol + diabetes cascade | D4: cascade_70_30_30_to_70_70_70 | E4: combined | G4: htncov2_aspirational | H4: 2027 | I4: =100*(1-(SUMIFS(CVD_40q30_Age!$M$2:$M$2081,CVD_40q30_Age!$A$2:$A$2081,A4,CVD_40q30_Age!$B$2:$B$2081,B4,CVD_40q30_Age!$E$2:$E$2081,G4,CVD_40q30_Age!$F$2:$F$2081,H4,CVD_40q30_Age!$G$2:$G$2081,69))/(SUMIFS(CVD_40q30_Age!$L$2:$L$2081,CVD_40q30_Age!$A$2:$A$2081,A4,CVD_40q30_Age!$B$2:$B$2081,B4,CVD_40q30_Age!$E$2:$E$2081,G4,CVD_40q30_Age!$F$2:$F$2081,H4,CVD_40q30_Age!$G$2:$G$2081,30))) -> 13.093748 | J4: =SUMIFS($I$2:$I$53,$A$2:$A$53,A4,$G$2:$G$53,G4,$H$2:$H$53,H4,$B$2:$B$53,"baseline") -> 13.098116 | K4: =J4-I4 -> 0.0043681399 | L4: =IF(J4=0,"",100*(J4-I4)/J4) -> 0.033349375 | M4: 13.093748 | N4: =IF(ABS(I4-M4)<=0.001,"match","mismatch") -> match
A5: Indonesia | B5: S_70_30_30_TO_70_70_70 | C5: 70-30-30 -> 70-70-70 hypertension/cholesterol + diabetes cascade | D5: cascade_70_30_30_to_70_70_70 | E5: combined | G5: htncov2_aspirational | H5: 2028 | I5: =100*(1-(SUMIFS(CVD_40q30_Age!$M$2:$M$2081,CVD_40q30_Age!$A$2:$A$2081,A5,CVD_40q30_Age!$B$2:$B$2081,B5,CVD_40q30_Age!$E$2:$E$2081,G5,CVD_40q30_Age!$F$2:$F$2081,H5,CVD_40q30_Age!$G$2:$G$2081,69))/(SUMIFS(CVD_40q30_Age!$L$2:$L$2081,CVD_40q30_Age!$A$2:$A$2081,A5,CVD_40q30_Age!$B$2:$B$2081,B5,CVD_40q30_Age!$E$2:$E$2081,G5,CVD_40q30_Age!$F$2:$F$2081,H5,CVD_40q30_Age!$G$2:$G$2081,30))) -> 12.551954 | J5: =SUMIFS($I$2:$I$53,$A$2:$A$53,A5,$G$2:$G$53,G5,$H$2:$H$53,H5,$B$2:$B$53,"baseline") -> 12.563551 | K5: =J5-I5 -> 0.011596595 | L5: =IF(J5=0,"",100*(J5-I5)/J5) -> 0.092303481 | M5: 12.551954 | N5: =IF(ABS(I5-M5)<=0.001,"match","mismatch") -> match
A6: Indonesia | B6: S_70_30_30_TO_70_70_70 | C6: 70-30-30 -> 70-70-70 hypertension/cholesterol + diabetes cascade | D6: cascade_70_30_30_to_70_70_70 | E6: combined | G6: htncov2_aspirational | H6: 2029 | I6: =100*(1-(SUMIFS(CVD_40q30_Age!$M$2:$M$2081,CVD_40q30_Age!$A$2:$A$2081,A6,CVD_40q30_Age!$B$2:$B$2081,B6,CVD_40q30_Age!$E$2:$E$2081,G6,CVD_40q30_Age!$F$2:$F$2081,H6,CVD_40q30_Age!$G$2:$G$2081,69))/(SUMIFS(CVD_40q30_Age!$L$2:$L$2081,CVD_40q30_Age!$A$2:$A$2081,A6,CVD_40q30_Age!$B$2:$B$2081,B6,CVD_40q30_Age!$E$2:$E$2081,G6,CVD_40q30_Age!$F$2:$F$2081,H6,CVD_40q30_Age!$G$2:$G$2081,30))) -> 12.09671 | J6: =SUMIFS($I$2:$I$53,$A$2:$A$53,A6,$G$2:$G$53,G6,$H$2:$H$53,H6,$B$2:$B$53,"baseline") -> 12.11775 | K6: =J6-I6 -> 0.021040036 | L6: =IF(J6=0,"",100*(J6-I6)/J6) -> 0.17362988 | M6: 12.09671 | N6: =IF(ABS(I6-M6)<=0.001,"match","mismatch") -> match
A7: Indonesia | B7: S_70_30_30_TO_70_70_70 | C7: 70-30-30 -> 70-70-70 hypertension/cholesterol + diabetes cascade | D7: cascade_70_30_30_to_70_70_70 | E7: combined | G7: htncov2_aspirational | H7: 2030 | I7: =100*(1-(SUMIFS(CVD_40q30_Age!$M$2:$M$2081,CVD_40q30_Age!$A$2:$A$2081,A7,CVD_40q30_Age!$B$2:$B$2081,B7,CVD_40q30_Age!$E$2:$E$2081,G7,CVD_40q30_Age!$F$2:$F$2081,H7,CVD_40q30_Age!$G$2:$G$2081,69))/(SUMIFS(CVD_40q30_Age!$L$2:$L$2081,CVD_40q30_Age!$A$2:$A$2081,A7,CVD_40q30_Age!$B$2:$B$2081,B7,CVD_40q30_Age!$E$2:$E$2081,G7,CVD_40q30_Age!$F$2:$F$2081,H7,CVD_40q30_Age!$G$2:$G$2081,30))) -> 11.714752 | J7: =SUMIFS($I$2:$I$53,$A$2:$A$53,A7,$G$2:$G$53,G7,$H$2:$H$53,H7,$B$2:$B$53,"baseline") -> 11.74693 | K7: =J7-I7 -> 0.032177915 | L7: =IF(J7=0,"",100*(J7-I7)/J7) -> 0.27392616 | M7: 11.714752 | N7: =IF(ABS(I7-M7)<=0.001,"match","mismatch") -> match
A8: Indonesia | B8: S_70_30_30_TO_70_70_70 | C8: 70-30-30 -> 70-70-70 hypertension/cholesterol + diabetes cascade | D8: cascade_70_30_30_to_70_70_70 | E8: combined | G8: htncov2_aspirational | H8: 2031 | I8: =100*(1-(SUMIFS(CVD_40q30_Age!$M$2:$M$2081,CVD_40q30_Age!$A$2:$A$2081,A8,CVD_40q30_Age!$B$2:$B$2081,B8,CVD_40q30_Age!$E$2:$E$2081,G8,CVD_40q30_Age!$F$2:$F$2081,H8,CVD_40q30_Age!$G$2:$G$2081,69))/(SUMIFS(CVD_40q30_Age!$L$2:$L$2081,CVD_40q30_Age!$A$2:$A$2081,A8,CVD_40q30_Age!$B$2:$B$2081,B8,CVD_40q30_Age!$E$2:$E$2081,G8,CVD_40q30_Age!$F$2:$F$2081,H8,CVD_40q30_Age!$G$2:$G$2081,30))) -> 11.365926 | J8: =SUMIFS($I$2:$I$53,$A$2:$A$53,A8,$G$2:$G$53,G8,$H$2:$H$53,H8,$B$2:$B$53,"baseline") -> 11.413097 | K8: =J8-I8 -> 0.047170649 | L8: =IF(J8=0,"",100*(J8-I8)/J8) -> 0.41330281 | M8: 11.365926 | N8: =IF(ABS(I8-M8)<=0.001,"match","mismatch") -> match
A9: Indonesia | B9: S_70_30_30_TO_70_70_70 | C9: 70-30-30 -> 70-70-70 hypertension/cholesterol + diabetes cascade | D9: cascade_70_30_30_to_70_70_70 | E9: combined | G9: htncov2_aspirational | H9: 2032 | I9: =100*(1-(SUMIFS(CVD_40q30_Age!$M$2:$M$2081,CVD_40q30_Age!$A$2:$A$2081,A9,CVD_40q30_Age!$B$2:$B$2081,B9,CVD_40q30_Age!$E$2:$E$2081,G9,CVD_40q30_Age!$F$2:$F$2081,H9,CVD_40q30_Age!$G$2:$G$2081,69))/(SUMIFS(CVD_40q30_Age!$L$2:$L$2081,CVD_40q30_Age!$A$2:$A$2081,A9,CVD_40q30_Age!$B$2:$B$2081,B9,CVD_40q30_Age!$E$2:$E$2081,G9,CVD_40q30_Age!$F$2:$F$2081,H9,CVD_40q30_Age!$G$2:$G$2081,30))) -> 11.035675 | J9: =SUMIFS($I$2:$I$53,$A$2:$A$53,A9,$G$2:$G$53,G9,$H$2:$H$53,H9,$B$2:$B$53,"baseline") -> 11.115398 | K9: =J9-I9 -> 0.079723741 | L9: =IF(J9=0,"",100*(J9-I9)/J9) -> 0.71723691 | M9: 11.035675 | N9: =IF(ABS(I9-M9)<=0.001,"match","mismatch") -> match
A10: Indonesia | B10: S_70_30_30_TO_70_70_70 | C10: 70-30-30 -> 70-70-70 hypertension/cholesterol + diabetes cascade | D10: cascade_70_30_30_to_70_70_70 | E10: combined | G10: htncov2_aspirational | H10: 2033 | I10: =100*(1-(SUMIFS(CVD_40q30_Age!$M$2:$M$2081,CVD_40q30_Age!$A$2:$A$2081,A10,CVD_40q30_Age!$B$2:$B$2081,B10,CVD_40q30_Age!$E$2:$E$2081,G10,CVD_40q30_Age!$F$2:$F$2081,H10,CVD_40q30_Age!$G$2:$G$2081,69))/(SUMIFS(CVD_40q30_Age!$L$2:$L$2081,CVD_40q30_Age!$A$2:$A$2081,A10,CVD_40q30_Age!$B$2:$B$2081,B10,CVD_40q30_Age!$E$2:$E$2081,G10,CVD_40q30_Age!$F$2:$F$2081,H10,CVD_40q30_Age!$G$2:$G$2081,30))) -> 10.726589 | J10: =SUMIFS($I$2:$I$53,$A$2:$A$53,A10,$G$2:$G$53,G10,$H$2:$H$53,H10,$B$2:$B$53,"baseline") -> 10.851472 | K10: =J10-I10 -> 0.1248834 | L10: =IF(J10=0,"",100*(J10-I10)/J10) -> 1.1508429 | M10: 10.726589 | N10: =IF(ABS(I10-M10)<=0.001,"match","mismatch") -> match
A11: Indonesia | B11: S_70_30_30_TO_70_70_70 | C11: 70-30-30 -> 70-70-70 hypertension/cholesterol + diabetes cascade | D11: cascade_70_30_30_to_70_70_70 | E11: combined | G11: htncov2_aspirational | H11: 2034 | I11: =100*(1-(SUMIFS(CVD_40q30_Age!$M$2:$M$2081,CVD_40q30_Age!$A$2:$A$2081,A11,CVD_40q30_Age!$B$2:$B$2081,B11,CVD_40q30_Age!$E$2:$E$2081,G11,CVD_40q30_Age!$F$2:$F$2081,H11,CVD_40q30_Age!$G$2:$G$2081,69))/(SUMIFS(CVD_40q30_Age!$L$2:$L$2081,CVD_40q30_Age!$A$2:$A$2081,A11,CVD_40q30_Age!$B$2:$B$2081,B11,CVD_40q30_Age!$E$2:$E$2081,G11,CVD_40q30_Age!$F$2:$F$2081,H11,CVD_40q30_Age!$G$2:$G$2081,30))) -> 10.446096 | J11: =SUMIFS($I$2:$I$53,$A$2:$A$53,A11,$G$2:$G$53,G11,$H$2:$H$53,H11,$B$2:$B$53,"baseline") -> 10.625758 | K11: =J11-I11 -> 0.17966279 | L11: =IF(J11=0,"",100*(J11-I11)/J11) -> 1.6908232 | M11: 10.446096 | N11: =IF(ABS(I11-M11)<=0.001,"match","mismatch") -> match
A12: Indonesia | B12: S_70_30_30_TO_70_70_70 | C12: 70-30-30 -> 70-70-70 hypertension/cholesterol + diabetes cascade | D12: cascade_70_30_30_to_70_70_70 | E12: combined | G12: htncov2_aspirational | H12: 2035 | I12: =100*(1-(SUMIFS(CVD_40q30_Age!$M$2:$M$2081,CVD_40q30_Age!$A$2:$A$2081,A12,CVD_40q30_Age!$B$2:$B$2081,B12,CVD_40q30_Age!$E$2:$E$2081,G12,CVD_40q30_Age!$F$2:$F$2081,H12,CVD_40q30_Age!$G$2:$G$2081,69))/(SUMIFS(CVD_40q30_Age!$L$2:$L$2081,CVD_40q30_Age!$A$2:$A$2081,A12,CVD_40q30_Age!$B$2:$B$2081,B12,CVD_40q30_Age!$E$2:$E$2081,G12,CVD_40q30_Age!$F$2:$F$2081,H12,CVD_40q30_Age!$G$2:$G$2081,30))) -> 10.189223 | J12: =SUMIFS($I$2:$I$53,$A$2:$A$53,A12,$G$2:$G$53,G12,$H$2:$H$53,H12,$B$2:$B$53,"baseline") -> 10.431088 | K12: =J12-I12 -> 0.24186518 | L12: =IF(J12=0,"",100*(J12-I12)/J12) -> 2.3186956 | M12: 10.189223 | N12: =IF(ABS(I12-M12)<=0.001,"match","mismatch") -> match
A13: Indonesia | B13: S_70_30_30_TO_70_70_70 | C13: 70-30-30 -> 70-70-70 hypertension/cholesterol + diabetes cascade | D13: cascade_70_30_30_to_70_70_70 | E13: combined | G13: htncov2_aspirational | H13: 2036 | I13: =100*(1-(SUMIFS(CVD_40q30_Age!$M$2:$M$2081,CVD_40q30_Age!$A$2:$A$2081,A13,CVD_40q30_Age!$B$2:$B$2081,B13,CVD_40q30_Age!$E$2:$E$2081,G13,CVD_40q30_Age!$F$2:$F$2081,H13,CVD_40q30_Age!$G$2:$G$2081,69))/(SUMIFS(CVD_40q30_Age!$L$2:$L$2081,CVD_40q30_Age!$A$2:$A$2081,A13,CVD_40q30_Age!$B$2:$B$2081,B13,CVD_40q30_Age!$E$2:$E$2081,G13,CVD_40q30_Age!$F$2:$F$2081,H13,CVD_40q30_Age!$G$2:$G$2081,30))) -> 9.9563929 | J13: =SUMIFS($I$2:$I$53,$A$2:$A$53,A13,$G$2:$G$53,G13,$H$2:$H$53,H13,$B$2:$B$53,"baseline") -> 10.266493 | K13: =J13-I13 -> 0.3101001 | L13: =IF(J13=0,"",100*(J13-I13)/J13) -> 3.0205066 | M13: 9.9563929 | N13: =IF(ABS(I13-M13)<=0.001,"match","mismatch") -> match
... A27: Indonesia | B27: S_70_30_30_TO_70_70_70 | C27: 70-30-30 -> 70-70-70 hypertension/cholesterol + diabetes cascade | D27: cascade_70_30_30_to_70_70_70 | E27: combined | G27: htncov2_aspirational | H27: 2050 | I27: =100*(1-(SUMIFS(CVD_40q30_Age!$M$2:$M$2081,CVD_40q30_Age!$A$2:$A$2081,A27,CVD_40q30_Age!$B$2:$B$2081,B27,CVD_40q30_Age!$E$2:$E$2081,G27,CVD_40q30_Age!$F$2:$F$2081,H27,CVD_40q30_Age!$G$2:$G$2081,69))/(SUMIFS(CVD_40q30_Age!$L$2:$L$2081,CVD_40q30_Age!$A$2:$A$2081,A27,CVD_40q30_Age!$B$2:$B$2081,B27,CVD_40q30_Age!$E$2:$E$2081,G27,CVD_40q30_Age!$F$2:$F$2081,H27,CVD_40q30_Age!$G$2:$G$2081,30))) -> 8.0775538 | J27: =SUMIFS($I$2:$I$53,$A$2:$A$53,A27,$G$2:$G$53,G27,$H$2:$H$53,H27,$B$2:$B$53,"baseline") -> 9.0836246 | K27: =J27-I27 -> 1.0060709 | L27: =IF(J27=0,"",100*(J27-I27)/J27) -> 11.075654 | M27: 8.0775538 | N27: =IF(ABS(I27-M27)<=0.001,"match","mismatch") -> match
A28: Indonesia | B28: baseline | C28: Baseline (no new intervention) | D28: baseline | G28: htncov2_aspirational | H28: 2025 | I28: =100*(1-(SUMIFS(CVD_40q30_Age!$M$2:$M$2081,CVD_40q30_Age!$A$2:$A$2081,A28,CVD_40q30_Age!$B$2:$B$2081,B28,CVD_40q30_Age!$E$2:$E$2081,G28,CVD_40q30_Age!$F$2:$F$2081,H28,CVD_40q30_Age!$G$2:$G$2081,69))/(SUMIFS(CVD_40q30_Age!$L$2:$L$2081,CVD_40q30_Age!$A$2:$A$2081,A28,CVD_40q30_Age!$B$2:$B$2081,B28,CVD_40q30_Age!$E$2:$E$2081,G28,CVD_40q30_Age!$F$2:$F$2081,H28,CVD_40q30_Age!$G$2:$G$2081,30))) -> 14.504478 | J28: =SUMIFS($I$2:$I$53,$A$2:$A$53,A28,$G$2:$G$53,G28,$H$2:$H$53,H28,$B$2:$B$53,"baseline") -> 14.504478 | K28: =J28-I28 -> 0 | L28: =IF(J28=0,"",100*(J28-I28)/J28) -> 0 | M28: 14.504478 | N28: =IF(ABS(I28-M28)<=0.001,"match","mismatch") -> match
A29: Indonesia | B29: baseline | C29: Baseline (no new intervention) | D29: baseline | G29: htncov2_aspirational | H29: 2026 | I29: =100*(1-(SUMIFS(CVD_40q30_Age!$M$2:$M$2081,CVD_40q30_Age!$A$2:$A$2081,A29,CVD_40q30_Age!$B$2:$B$2081,B29,CVD_40q30_Age!$E$2:$E$2081,G29,CVD_40q30_Age!$F$2:$F$2081,H29,CVD_40q30_Age!$G$2:$G$2081,69))/(SUMIFS(CVD_40q30_Age!$L$2:$L$2081,CVD_40q30_Age!$A$2:$A$2081,A29,CVD_40q30_Age!$B$2:$B$2081,B29,CVD_40q30_Age!$E$2:$E$2081,G29,CVD_40q30_Age!$F$2:$F$2081,H29,CVD_40q30_Age!$G$2:$G$2081,30))) -> 13.740526 | J29: =SUMIFS($I$2:$I$53,$A$2:$A$53,A29,$G$2:$G$53,G29,$H$2:$H$53,H29,$B$2:$B$53,"baseline") -> 13.740526 | K29: =J29-I29 -> 0 | L29: =IF(J29=0,"",100*(J29-I29)/J29) -> 0 | M29: 13.740526 | N29: =IF(ABS(I29-M29)<=0.001,"match","mismatch") -> match
A30: Indonesia | B30: baseline | C30: Baseline (no new intervention) | D30: baseline | G30: htncov2_aspirational | H30: 2027 | I30: =100*(1-(SUMIFS(CVD_40q30_Age!$M$2:$M$2081,CVD_40q30_Age!$A$2:$A$2081,A30,CVD_40q30_Age!$B$2:$B$2081,B30,CVD_40q30_Age!$E$2:$E$2081,G30,CVD_40q30_Age!$F$2:$F$2081,H30,CVD_40q30_Age!$G$2:$G$2081,69))/(SUMIFS(CVD_40q30_Age!$L$2:$L$2081,CVD_40q30_Age!$A$2:$A$2081,A30,CVD_40q30_Age!$B$2:$B$2081,B30,CVD_40q30_Age!$E$2:$E$2081,G30,CVD_40q30_Age!$F$2:$F$2081,H30,CVD_40q30_Age!$G$2:$G$2081,30))) -> 13.098116 | J30: =SUMIFS($I$2:$I$53,$A$2:$A$53,A30,$G$2:$G$53,G30,$H$2:$H$53,H30,$B$2:$B$53,"baseline") -> 13.098116 | K30: =J30-I30 -> 0 | L30: =IF(J30=0,"",100*(J30-I30)/J30) -> 0 | M30: 13.098116 | N30: =IF(ABS(I30-M30)<=0.001,"match","mismatch") -> match
A31: Indonesia | B31: baseline | C31: Baseline (no new intervention) | D31: baseline | G31: htncov2_aspirational | H31: 2028 | I31: =100*(1-(SUMIFS(CVD_40q30_Age!$M$2:$M$2081,CVD_40q30_Age!$A$2:$A$2081,A31,CVD_40q30_Age!$B$2:$B$2081,B31,CVD_40q30_Age!$E$2:$E$2081,G31,CVD_40q30_Age!$F$2:$F$2081,H31,CVD_40q30_Age!$G$2:$G$2081,69))/(SUMIFS(CVD_40q30_Age!$L$2:$L$2081,CVD_40q30_Age!$A$2:$A$2081,A31,CVD_40q30_Age!$B$2:$B$2081,B31,CVD_40q30_Age!$E$2:$E$2081,G31,CVD_40q30_Age!$F$2:$F$2081,H31,CVD_40q30_Age!$G$2:$G$2081,30))) -> 12.563551 | J31: =SUMIFS($I$2:$I$53,$A$2:$A$53,A31,$G$2:$G$53,G31,$H$2:$H$53,H31,$B$2:$B$53,"baseline") -> 12.563551 | K31: =J31-I31 -> 0 | L31: =IF(J31=0,"",100*(J31-I31)/J31) -> 0 | M31: 12.563551 | N31: =IF(ABS(I31-M31)<=0.001,"match","mismatch") -> match
A32: Indonesia | B32: baseline | C32: Baseline (no new intervention) | D32: baseline | G32: htncov2_aspirational | H32: 2029 | I32: =100*(1-(SUMIFS(CVD_40q30_Age!$M$2:$M$2081,CVD_40q30_Age!$A$2:$A$2081,A32,CVD_40q30_Age!$B$2:$B$2081,B32,CVD_40q30_Age!$E$2:$E$2081,G32,CVD_40q30_Age!$F$2:$F$2081,H32,CVD_40q30_Age!$G$2:$G$2081,69))/(SUMIFS(CVD_40q30_Age!$L$2:$L$2081,CVD_40q30_Age!$A$2:$A$2081,A32,CVD_40q30_Age!$B$2:$B$2081,B32,CVD_40q30_Age!$E$2:$E$2081,G32,CVD_40q30_Age!$F$2:$F$2081,H32,CVD_40q30_Age!$G$2:$G$2081,30))) -> 12.11775 | J32: =SUMIFS($I$2:$I$53,$A$2:$A$53,A32,$G$2:$G$53,G32,$H$2:$H$53,H32,$B$2:$B$53,"baseline") -> 12.11775 | K32: =J32-I32 -> 0 | L32: =IF(J32=0,"",100*(J32-I32)/J32) -> 0 | M32: 12.11775 | N32: =IF(ABS(I32-M32)<=0.001,"match","mismatch") -> match
A33: Indonesia | B33: baseline | C33: Baseline (no new intervention) | D33: baseline | G33: htncov2_aspirational | H33: 2030 | I33: =100*(1-(SUMIFS(CVD_40q30_Age!$M$2:$M$2081,CVD_40q30_Age!$A$2:$A$2081,A33,CVD_40q30_Age!$B$2:$B$2081,B33,CVD_40q30_Age!$E$2:$E$2081,G33,CVD_40q30_Age!$F$2:$F$2081,H33,CVD_40q30_Age!$G$2:$G$2081,69))/(SUMIFS(CVD_40q30_Age!$L$2:$L$2081,CVD_40q30_Age!$A$2:$A$2081,A33,CVD_40q30_Age!$B$2:$B$2081,B33,CVD_40q30_Age!$E$2:$E$2081,G33,CVD_40q30_Age!$F$2:$F$2081,H33,CVD_40q30_Age!$G$2:$G$2081,30))) -> 11.74693 | J33: =SUMIFS($I$2:$I$53,$A$2:$A$53,A33,$G$2:$G$53,G33,$H$2:$H$53,H33,$B$2:$B$53,"baseline") -> 11.74693 | K33: =J33-I33 -> 0 | L33: =IF(J33=0,"",100*(J33-I33)/J33) -> 0 | M33: 11.74693 | N33: =IF(ABS(I33-M33)<=0.001,"match","mismatch") -> match
A34: Indonesia | B34: baseline | C34: Baseline (no new intervention) | D34: baseline | G34: htncov2_aspirational | H34: 2031 | I34: =100*(1-(SUMIFS(CVD_40q30_Age!$M$2:$M$2081,CVD_40q30_Age!$A$2:$A$2081,A34,CVD_40q30_Age!$B$2:$B$2081,B34,CVD_40q30_Age!$E$2:$E$2081,G34,CVD_40q30_Age!$F$2:$F$2081,H34,CVD_40q30_Age!$G$2:$G$2081,69))/(SUMIFS(CVD_40q30_Age!$L$2:$L$2081,CVD_40q30_Age!$A$2:$A$2081,A34,CVD_40q30_Age!$B$2:$B$2081,B34,CVD_40q30_Age!$E$2:$E$2081,G34,CVD_40q30_Age!$F$2:$F$2081,H34,CVD_40q30_Age!$G$2:$G$2081,30))) -> 11.413097 | J34: =SUMIFS($I$2:$I$53,$A$2:$A$53,A34,$G$2:$G$53,G34,$H$2:$H$53,H34,$B$2:$B$53,"baseline") -> 11.413097 | K34: =J34-I34 -> 0 | L34: =IF(J34=0,"",100*(J34-I34)/J34) -> 0 | M34: 11.413097 | N34: =IF(ABS(I34-M34)<=0.001,"match","mismatch") -> match
A35: Indonesia | B35: baseline | C35: Baseline (no new intervention) | D35: baseline | G35: htncov2_aspirational | H35: 2032 | I35: =100*(1-(SUMIFS(CVD_40q30_Age!$M$2:$M$2081,CVD_40q30_Age!$A$2:$A$2081,A35,CVD_40q30_Age!$B$2:$B$2081,B35,CVD_40q30_Age!$E$2:$E$2081,G35,CVD_40q30_Age!$F$2:$F$2081,H35,CVD_40q30_Age!$G$2:$G$2081,69))/(SUMIFS(CVD_40q30_Age!$L$2:$L$2081,CVD_40q30_Age!$A$2:$A$2081,A35,CVD_40q30_Age!$B$2:$B$2081,B35,CVD_40q30_Age!$E$2:$E$2081,G35,CVD_40q30_Age!$F$2:$F$2081,H35,CVD_40q30_Age!$G$2:$G$2081,30))) -> 11.115398 | J35: =SUMIFS($I$2:$I$53,$A$2:$A$53,A35,$G$2:$G$53,G35,$H$2:$H$53,H35,$B$2:$B$53,"baseline") -> 11.115398 | K35: =J35-I35 -> 0 | L35: =IF(J35=0,"",100*(J35-I35)/J35) -> 0 | M35: 11.115398 | N35: =IF(ABS(I35-M35)<=0.001,"match","mismatch") -> match
A36: Indonesia | B36: baseline | C36: Baseline (no new intervention) | D36: baseline | G36: htncov2_aspirational | H36: 2033 | I36: =100*(1-(SUMIFS(CVD_40q30_Age!$M$2:$M$2081,CVD_40q30_Age!$A$2:$A$2081,A36,CVD_40q30_Age!$B$2:$B$2081,B36,CVD_40q30_Age!$E$2:$E$2081,G36,CVD_40q30_Age!$F$2:$F$2081,H36,CVD_40q30_Age!$G$2:$G$2081,69))/(SUMIFS(CVD_40q30_Age!$L$2:$L$2081,CVD_40q30_Age!$A$2:$A$2081,A36,CVD_40q30_Age!$B$2:$B$2081,B36,CVD_40q30_Age!$E$2:$E$2081,G36,CVD_40q30_Age!$F$2:$F$2081,H36,CVD_40q30_Age!$G$2:$G$2081,30))) -> 10.851472 | J36: =SUMIFS($I$2:$I$53,$A$2:$A$53,A36,$G$2:$G$53,G36,$H$2:$H$53,H36,$B$2:$B$53,"baseline") -> 10.851472 | K36: =J36-I36 -> 0 | L36: =IF(J36=0,"",100*(J36-I36)/J36) -> 0 | M36: 10.851472 | N36: =IF(ABS(I36-M36)<=0.001,"match","mismatch") -> match
A37: Indonesia | B37: baseline | C37: Baseline (no new intervention) | D37: baseline | G37: htncov2_aspirational | H37: 2034 | I37: =100*(1-(SUMIFS(CVD_40q30_Age!$M$2:$M$2081,CVD_40q30_Age!$A$2:$A$2081,A37,CVD_40q30_Age!$B$2:$B$2081,B37,CVD_40q30_Age!$E$2:$E$2081,G37,CVD_40q30_Age!$F$2:$F$2081,H37,CVD_40q30_Age!$G$2:$G$2081,69))/(SUMIFS(CVD_40q30_Age!$L$2:$L$2081,CVD_40q30_Age!$A$2:$A$2081,A37,CVD_40q30_Age!$B$2:$B$2081,B37,CVD_40q30_Age!$E$2:$E$2081,G37,CVD_40q30_Age!$F$2:$F$2081,H37,CVD_40q30_Age!$G$2:$G$2081,30))) -> 10.625758 | J37: =SUMIFS($I$2:$I$53,$A$2:$A$53,A37,$G$2:$G$53,G37,$H$2:$H$53,H37,$B$2:$B$53,"baseline") -> 10.625758 | K37: =J37-I37 -> 0 | L37: =IF(J37=0,"",100*(J37-I37)/J37) -> 0 | M37: 10.625758 | N37: =IF(ABS(I37-M37)<=0.001,"match","mismatch") -> match
A38: Indonesia | B38: baseline | C38: Baseline (no new intervention) | D38: baseline | G38: htncov2_aspirational | H38: 2035 | I38: =100*(1-(SUMIFS(CVD_40q30_Age!$M$2:$M$2081,CVD_40q30_Age!$A$2:$A$2081,A38,CVD_40q30_Age!$B$2:$B$2081,B38,CVD_40q30_Age!$E$2:$E$2081,G38,CVD_40q30_Age!$F$2:$F$2081,H38,CVD_40q30_Age!$G$2:$G$2081,69))/(SUMIFS(CVD_40q30_Age!$L$2:$L$2081,CVD_40q30_Age!$A$2:$A$2081,A38,CVD_40q30_Age!$B$2:$B$2081,B38,CVD_40q30_Age!$E$2:$E$2081,G38,CVD_40q30_Age!$F$2:$F$2081,H38,CVD_40q30_Age!$G$2:$G$2081,30))) -> 10.431088 | J38: =SUMIFS($I$2:$I$53,$A$2:$A$53,A38,$G$2:$G$53,G38,$H$2:$H$53,H38,$B$2:$B$53,"baseline") -> 10.431088 | K38: =J38-I38 -> 0 | L38: =IF(J38=0,"",100*(J38-I38)/J38) -> 0 | M38: 10.431088 | N38: =IF(ABS(I38-M38)<=0.001,"match","mismatch") -> match
A39: Indonesia | B39: baseline | C39: Baseline (no new intervention) | D39: baseline | G39: htncov2_aspirational | H39: 2036 | I39: =100*(1-(SUMIFS(CVD_40q30_Age!$M$2:$M$2081,CVD_40q30_Age!$A$2:$A$2081,A39,CVD_40q30_Age!$B$2:$B$2081,B39,CVD_40q30_Age!$E$2:$E$2081,G39,CVD_40q30_Age!$F$2:$F$2081,H39,CVD_40q30_Age!$G$2:$G$2081,69))/(SUMIFS(CVD_40q30_Age!$L$2:$L$2081,CVD_40q30_Age!$A$2:$A$2081,A39,CVD_40q30_Age!$B$2:$B$2081,B39,CVD_40q30_Age!$E$2:$E$2081,G39,CVD_40q30_Age!$F$2:$F$2081,H39,CVD_40q30_Age!$G$2:$G$2081,30))) -> 10.266493 | J39: =SUMIFS($I$2:$I$53,$A$2:$A$53,A39,$G$2:$G$53,G39,$H$2:$H$53,H39,$B$2:$B$53,"baseline") -> 10.266493 | K39: =J39-I39 -> 0 | L39: =IF(J39=0,"",100*(J39-I39)/J39) -> 0 | M39: 10.266493 | N39: =IF(ABS(I39-M39)<=0.001,"match","mismatch") -> match
... A53: Indonesia | B53: baseline | C53: Baseline (no new intervention) | D53: baseline | G53: htncov2_aspirational | H53: 2050 | I53: =100*(1-(SUMIFS(CVD_40q30_Age!$M$2:$M$2081,CVD_40q30_Age!$A$2:$A$2081,A53,CVD_40q30_Age!$B$2:$B$2081,B53,CVD_40q30_Age!$E$2:$E$2081,G53,CVD_40q30_Age!$F$2:$F$2081,H53,CVD_40q30_Age!$G$2:$G$2081,69))/(SUMIFS(CVD_40q30_Age!$L$2:$L$2081,CVD_40q30_Age!$A$2:$A$2081,A53,CVD_40q30_Age!$B$2:$B$2081,B53,CVD_40q30_Age!$E$2:$E$2081,G53,CVD_40q30_Age!$F$2:$F$2081,H53,CVD_40q30_Age!$G$2:$G$2081,30))) -> 9.0836246 | J53: =SUMIFS($I$2:$I$53,$A$2:$A$53,A53,$G$2:$G$53,G53,$H$2:$H$53,H53,$B$2:$B$53,"baseline") -> 9.0836246 | K53: =J53-I53 -> 0 | L53: =IF(J53=0,"",100*(J53-I53)/J53) -> 0 | M53: 9.0836246 | N53: =IF(ABS(I53-M53)<=0.001,"match","mismatch") -> match

Sheet CVD_40q30_Age
A1: location | B1: scenario | C1: scenario_label | D1: intervention_family | E1: htn_target_scenario | F1: year | G1: age | H1: cvd_deaths | I1: population | J1: m_x | K1: q_x | L1: l_x | M1: l_x_next
A2: Indonesia | B2: S_70_30_30_TO_70_70_70 | C2: 70-30-30 -> 70-70-70 hypertension/cholesterol + diabetes cascade | D2: cascade_70_30_30_to_70_70_70 | E2: htncov2_aspirational | F2: 2025 | G2: 30 | H2: 917.59069 | I2: 4325986.9 | J2: =IF(I2>0,H2/I2,0) -> 0.0002121113 | K2: =1-EXP(-J2) -> 0.0002120888 | L2: =IF(G2=30,1,M1) -> 1 | M2: =L2*(1-K2) -> 0.99978791
A3: Indonesia | B3: S_70_30_30_TO_70_70_70 | C3: 70-30-30 -> 70-70-70 hypertension/cholesterol + diabetes cascade | D3: cascade_70_30_30_to_70_70_70 | E3: htncov2_aspirational | F3: 2025 | G3: 31 | H3: 1309.867 | I3: 4272907.5 | J3: =IF(I3>0,H3/I3,0) -> 0.00030655169 | K3: =1-EXP(-J3) -> 0.00030650471 | L3: =IF(G3=30,1,M2) -> 0.99978791 | M3: =L3*(1-K3) -> 0.99948147
A4: Indonesia | B4: S_70_30_30_TO_70_70_70 | C4: 70-30-30 -> 70-70-70 hypertension/cholesterol + diabetes cascade | D4: cascade_70_30_30_to_70_70_70 | E4: htncov2_aspirational | F4: 2025 | G4: 32 | H4: 1349.7571 | I4: 4222809.1 | J4: =IF(I4>0,H4/I4,0) -> 0.00031963488 | K4: =1-EXP(-J4) -> 0.0003195838 | L4: =IF(G4=30,1,M3) -> 0.99948147 | M4: =L4*(1-K4) -> 0.99916205
A5: Indonesia | B5: S_70_30_30_TO_70_70_70 | C5: 70-30-30 -> 70-70-70 hypertension/cholesterol + diabetes cascade | D5: cascade_70_30_30_to_70_70_70 | E5: htncov2_aspirational | F5: 2025 | G5: 33 | H5: 1419.193 | I5: 4208311.5 | J5: =IF(I5>0,H5/I5,0) -> 0.00033723573 | K5: =1-EXP(-J5) -> 0.00033717887 | L5: =IF(G5=30,1,M4) -> 0.99916205 | M5: =L5*(1-K5) -> 0.99882516
A6: Indonesia | B6: S_70_30_30_TO_70_70_70 | C6: 70-30-30 -> 70-70-70 hypertension/cholesterol + diabetes cascade | D6: cascade_70_30_30_to_70_70_70 | E6: htncov2_aspirational | F6: 2025 | G6: 34 | H6: 1510.9799 | I6: 4188390.2 | J6: =IF(I6>0,H6/I6,0) -> 0.00036075432 | K6: =1-EXP(-J6) -> 0.00036068925 | L6: =IF(G6=30,1,M5) -> 0.99882516 | M6: =L6*(1-K6) -> 0.99846489
A7: Indonesia | B7: S_70_30_30_TO_70_70_70 | C7: 70-30-30 -> 70-70-70 hypertension/cholesterol + diabetes cascade | D7: cascade_70_30_30_to_70_70_70 | E7: htncov2_aspirational | F7: 2025 | G7: 35 | H7: 1631.109 | I7: 4172291.6 | J7: =IF(I7>0,H7/I7,0) -> 0.00039093841 | K7: =1-EXP(-J7) -> 0.000390862 | L7: =IF(G7=30,1,M6) -> 0.99846489 | M7: =L7*(1-K7) -> 0.99807463
A8: Indonesia | B8: S_70_30_30_TO_70_70_70 | C8: 70-30-30 -> 70-70-70 hypertension/cholesterol + diabetes cascade | D8: cascade_70_30_30_to_70_70_70 | E8: htncov2_aspirational | F8: 2025 | G8: 36 | H8: 2229.743 | I8: 4179862.9 | J8: =IF(I8>0,H8/I8,0) -> 0.00053344883 | K8: =1-EXP(-J8) -> 0.00053330657 | L8: =IF(G8=30,1,M7) -> 0.99807463 | M8: =L8*(1-K8) -> 0.99754235
