Workbook

Sheet README
A1: Indonesia NCD FAIR Choices - cost & value workbook (formula edition)
A3: section | B3: detail
A4: Purpose | B4: Costing, budget impact and mortality-based cost-effectiveness for the FAIR Choices CVD interventions selected in indonesia_model_inputs.xlsx.
A5: How to read | B5: Grey cells are R-generated source values; light-blue cells are LIVE Excel formulas; pale-yellow cells on Calculation_Assumptions are editable controls. Change a yellow control and the blue results recompute. Calculation_Map lists every dependency.
A6: Scenarios | B6: Baseline + one scenario per selected valid intervention + a combined 'all' scenario. Membership derives only from the workbook selections (Model 04).
A7: Baseline pairing | B7: Deaths averted = baseline deaths - scenario deaths, matched at location x year x age x sex x cause (aggregated to year x cause here).
A8: CVD 40q30 | B8: CVD_40q30 / CVD_40q30_Age give the period probability of dying from the six CVD causes (ihd, istroke, hstroke, hhd, rhd, cmd) between exact ages 30 and 70, per scenario/HTN-target/year. The life table (m_x, q_x, l_x, l_{x+1}) is live Excel formula off grey CVD deaths and de-duplicated population; cvd_40q30 = 100*(1-l_70/l_30) reconciles to the Model 07 value. cvd_40q30 and the absolute reduction are PERCENT on a 0-100 scale (format 0.000), NOT Excel's fractional %.
A9: Model aggregates | B9: Annual_Mortality carries the R health aggregates (cases, deaths, baseline); Annual_Cost carries the full-precision R population quantity before the PIN fraction. The 157k-row state trace stays in the companion R workbook.
A10: Costing | B10: annual_cost = population_in_need x coverage(t) x frequency x unit_cost. PIN measure maps 'all'->eligible population, 'prevalence'->sick stock, 'incidence'->new cases.
A11: Shared costs | B11: Components flagged 'shared-count-once' (cost_join_key ...__C_SHARED) are counted once at intervention level, never once per affected cause (see Annual_Cost shared_duplicate_count and QA).
A12: Budget impact | B12: Budget impact reports UNDISCOUNTED baseline, scenario, incremental and cumulative incremental cost. Discounted costs are separate columns. The four *_cost_per_capita columns are LIVE formulae (= that year's cost / national_population); national_population (grey R-source) is each year's national Indonesia population from out_model/model_output_Indonesia_htncov2_aspirational.rds (baseline series, de-duplicated across cause). Annual_Cost carries the matching per-component per-capita formulae, and Cost_Effectiveness carries the scenario mean annual incremental/discounted per-capita (2026-2050).
A13: Cost-effectiveness | B13: USD per death averted = cumulative discounted incremental cost / cumulative (undiscounted) deaths averted over the horizon. Not a DALY-based ICER.
A14: Economic value | B14: Reference-Case benefit-cost analysis (2019 Robinson et al. Guidelines): Health_Outcomes (Model 07 averted deaths/YLL/YLD/DALY & life-years gained), Economic_Value (Model 08 VSL/VSLY source with LIVE VSL-transfer, floor, VSLY, discount and PV-benefit formulas) and Benefit_Cost (PV benefits, PV costs converted to the benefit basis, net benefit and BCR). Preferred VSL = MAX(160xGNIpc_US x (GNIpc_IDN/GNIpc_US)^1.5, 20xGNIpc_IDN); 100x/160x GNI sensitivities. PARTIAL mortality-benefit BCA -- not a full societal BCA, and distinct from Cost_Effectiveness (USD per death averted).
... A18: Deferred | B18: Health outcomes (deaths averted, YLL/YLD/DALY averted, life-years gained) now come from Model 07 (Health_Outcomes); life-expectancy and disability-weight sources are documented via Model 07.

Sheet Run_Metadata
A1: item | B1: value
A2: Workbook title | B2: Indonesia NCD FAIR Choices - cost & value
A3: Run date | B3: 2026-08-30
A4: Model / pipeline | B4: CVD FAIR Choices (Models 00-06 -> 09)
A5: Input workbook | B5: C:/Users/wrgar/OneDrive - UW/02Work/WorldBank-Indonesia/uw-wb-indonesia-ncd/data/indonesia_model_inputs.xlsx
A6: Model output source | B6: output/out_model/model_output_*.rds (Model 06)
A7: Location | B7: Indonesia
A8: Analysis years | B8: ='Calculation_Assumptions'!B2&"-"&'Calculation_Assumptions'!B3
A9: Baseline scenario | B9: ='Calculation_Assumptions'!B4
A10: Scenarios costed | B10: I_CVD_PRIMARY, I_HF_ACUTE, I_HF_CHRONIC, I_IHD_ACUTE, I_IHD_SECONDARY, I_STROKE_SECONDARY, I_T2D_TREATMENT, all
A11: Cost discount rate | B11: ='Calculation_Assumptions'!B5
A12: Cost price year | B12: ='Calculation_Assumptions'!B6
A13: Currency | B13: ='Calculation_Assumptions'!B7
A14: Economic perspective | B14: ='Calculation_Assumptions'!B8
A15: Coverage scale-up shape | B15: ='Calculation_Assumptions'!B9
A16: Downstream cost offsets | B16: ='Calculation_Assumptions'!B10
A17: Health outcomes (DALYs/YLL/YLD) | B17: Out of scope in this stage (deferred)
A18: R version | B18: R version 4.5.1 (2025-06-13 ucrt)
A19: openxlsx / data.table | B19: 4.2.8 / 1.17.8

Sheet Scenario_Catalog
A1: scenario | B1: scenario_label | C1: intervention_family | D1: scenario_level | E1: scenario_role | F1: parent_package_id | G1: intervention_ids | H1: n_interventions
A2: baseline | B2: Baseline (no new intervention) | C2: clinical | D2: baseline | H2: 0
A3: I_CVD_PRIMARY | B3: Primary prevention of CVD | C3: clinical | D3: standalone | G3: I_CVD_PRIMARY | H3: 1
A4: I_HF_ACUTE | B4: Acute heart-failure management | C4: clinical | D4: standalone | G4: I_HF_ACUTE | H4: 1
A5: I_HF_CHRONIC | B5: Chronic heart-failure management | C5: clinical | D5: standalone | G5: I_HF_CHRONIC | H5: 1
A6: I_IHD_ACUTE | B6: Treatment of acute coronary syndromes | C6: clinical | D6: standalone | G6: I_IHD_ACUTE | H6: 1
A7: I_IHD_SECONDARY | B7: Secondary prevention of ischemic heart disease | C7: clinical | D7: standalone | G7: I_IHD_SECONDARY | H7: 1
A8: I_STROKE_SECONDARY | B8: Secondary prevention of stroke | C8: clinical | D8: standalone | G8: I_STROKE_SECONDARY | H8: 1
A9: I_T2D_TREATMENT | B9: Longitudinal treatment of type 2 diabetes | C9: clinical | D9: standalone | G9: I_T2D_TREATMENT | H9: 1
A10: all | B10: All selected interventions (combined) | C10: clinical | D10: combined | G10: I_CVD_PRIMARY; I_HF_ACUTE; I_HF_CHRONIC; I_IHD_ACUTE; I_IHD_SECONDARY; I_STROKE_SECONDARY; I_T2D_TREATMENT | H10: 7

Sheet Selected_Interventions
A1: intervention_id | B1: intervention_cause_key | C1: intervention_name | D1: cause_id | E1: cause_code | F1: model_name | G1: transition_from | H1: transition_to | I1: model_transition | J1: effect_value | K1: affected_fraction | L1: baseline_coverage | M1: target_coverage | N1: start_year | O1: target_year | P1: adjusted_effect_at_target | Q1: cost_join_key | R1: cost_scope | S1: effect_review | T1: coverage_review | U1: key_count | V1: formula_status
A2: I_CVD_PRIMARY | B2: I_CVD_PRIMARY__C_HHD | C2: Primary prevention of CVD | D2: C_HHD | E2: hhd | F2: Hypertensive heart disease | G2: well | H2: sick | I2: incidence | J2: 0.47 | K2: 1 | L2: 0.31 | M2: 0.8 | N2: 2025 | O2: 2050 | P2: =IF(OR(J2="",K2="",L2="",M2=""),"",ROUND(K2*(J2*(M2-L2)/(1-J2*L2)),4)) | Q2: I_CVD_PRIMARY__C_SHARED | R2: shared-count-once | S2: Provisional | T2: Provisional | U2: =COUNTIF($B$2:$B$17,B2) | V2: =IF(U2=1,"OK","DUPLICATE KEY")
A3: I_CVD_PRIMARY | B3: I_CVD_PRIMARY__C_ICH | C3: Primary prevention of CVD | D3: C_ICH | E3: hstroke | F3: Intracerebral hemorrhage | G3: well | H3: sick | I3: incidence | J3: 0.49 | K3: 0.8 | L3: 0.31 | M3: 0.8 | N3: 2025 | O3: 2050 | P3: =IF(OR(J3="",K3="",L3="",M3=""),"",ROUND(K3*(J3*(M3-L3)/(1-J3*L3)),4)) | Q3: I_CVD_PRIMARY__C_SHARED | R3: shared-count-once | S3: Provisional | T3: Provisional | U3: =COUNTIF($B$2:$B$17,B3) | V3: =IF(U3=1,"OK","DUPLICATE KEY")
A4: I_CVD_PRIMARY | B4: I_CVD_PRIMARY__C_IHD | C4: Primary prevention of CVD | D4: C_IHD | E4: ihd | F4: Ischemic heart disease | G4: well | H4: sick | I4: incidence | J4: 0.58 | K4: 0.8 | L4: 0.31 | M4: 0.8 | N4: 2025 | O4: 2050 | P4: =IF(OR(J4="",K4="",L4="",M4=""),"",ROUND(K4*(J4*(M4-L4)/(1-J4*L4)),4)) | Q4: I_CVD_PRIMARY__C_SHARED | R4: shared-count-once | S4: Provisional | T4: Provisional | U4: =COUNTIF($B$2:$B$17,B4) | V4: =IF(U4=1,"OK","DUPLICATE KEY")
A5: I_CVD_PRIMARY | B5: I_CVD_PRIMARY__C_IS | C5: Primary prevention of CVD | D5: C_IS | E5: istroke | F5: Ischemic stroke | G5: well | H5: sick | I5: incidence | J5: 0.54 | K5: 0.8 | L5: 0.31 | M5: 0.8 | N5: 2025 | O5: 2050 | P5: =IF(OR(J5="",K5="",L5="",M5=""),"",ROUND(K5*(J5*(M5-L5)/(1-J5*L5)),4)) | Q5: I_CVD_PRIMARY__C_SHARED | R5: shared-count-once | S5: Provisional | T5: Provisional | U5: =COUNTIF($B$2:$B$17,B5) | V5: =IF(U5=1,"OK","DUPLICATE KEY")
A6: I_HF_ACUTE | B6: I_HF_ACUTE__C_CMP | C6: Acute heart-failure management | D6: C_CMP | E6: cmd | F6: Cardiomyopathy and myocarditis | G6: sick_hf | H6: dead_cmp | I6: case_fatality | J6: 0.74 | K6: 0.2 | L6: 0.31 | M6: 0.8 | N6: 2025 | O6: 2050 | P6: =IF(OR(J6="",K6="",L6="",M6=""),"",ROUND(K6*(J6*(M6-L6)/(1-J6*L6)),4)) | Q6: I_HF_ACUTE__C_CMP | R6: cause-specific | S6: Provisional | T6: Provisional | U6: =COUNTIF($B$2:$B$17,B6) | V6: =IF(U6=1,"OK","DUPLICATE KEY")
A7: I_HF_ACUTE | B7: I_HF_ACUTE__C_HHD | C7: Acute heart-failure management | D7: C_HHD | E7: hhd | F7: Hypertensive heart disease | G7: sick_hf | H7: dead_hhd | I7: case_fatality | J7: 0.74 | K7: 0.2 | L7: 0.31 | M7: 0.8 | N7: 2025 | O7: 2050 | P7: =IF(OR(J7="",K7="",L7="",M7=""),"",ROUND(K7*(J7*(M7-L7)/(1-J7*L7)),4)) | Q7: I_HF_ACUTE__C_HHD | R7: cause-specific | S7: Provisional | T7: Provisional | U7: =COUNTIF($B$2:$B$17,B7) | V7: =IF(U7=1,"OK","DUPLICATE KEY")
A8: I_HF_ACUTE | B8: I_HF_ACUTE__C_IHD | C8: Acute heart-failure management | D8: C_IHD | E8: ihd | F8: Ischemic heart disease | G8: sick_hf | H8: dead_ihd | I8: case_fatality | J8: 0.18 | K8: 0.05 | L8: 0.31 | M8: 0.8 | N8: 2025 | O8: 2050 | P8: =IF(OR(J8="",K8="",L8="",M8=""),"",ROUND(K8*(J8*(M8-L8)/(1-J8*L8)),4)) | Q8: I_HF_ACUTE__C_IHD | R8: cause-specific | S8: Provisional | T8: Provisional | U8: =COUNTIF($B$2:$B$17,B8) | V8: =IF(U8=1,"OK","DUPLICATE KEY")
A9: I_HF_CHRONIC | B9: I_HF_CHRONIC__C_CMP | C9: Chronic heart-failure management | D9: C_CMP | E9: cmd | F9: Cardiomyopathy and myocarditis | G9: sick_hf | H9: dead_cmp | I9: case_fatality | J9: 0.536 | K9: 0.8 | L9: 0.31 | M9: 0.8 | N9: 2025 | O9: 2050 | P9: =IF(OR(J9="",K9="",L9="",M9=""),"",ROUND(K9*(J9*(M9-L9)/(1-J9*L9)),4)) | Q9: I_HF_CHRONIC__C_CMP | R9: cause-specific | S9: Provisional | T9: Provisional | U9: =COUNTIF($B$2:$B$17,B9) | V9: =IF(U9=1,"OK","DUPLICATE KEY")
A10: I_HF_CHRONIC | B10: I_HF_CHRONIC__C_HHD | C10: Chronic heart-failure management | D10: C_HHD | E10: hhd | F10: Hypertensive heart disease | G10: sick_hf | H10: dead_hhd | I10: case_fatality | J10: 0.275 | K10: 0.8 | L10: 0.31 | M10: 0.8 | N10: 2025 | O10: 2050 | P10: =IF(OR(J10="",K10="",L10="",M10=""),"",ROUND(K10*(J10*(M10-L10)/(1-J10*L10)),4)) | Q10: I_HF_CHRONIC__C_HHD | R10: cause-specific | S10: Provisional | T10: Provisional | U10: =COUNTIF($B$2:$B$17,B10) | V10: =IF(U10=1,"OK","DUPLICATE KEY")
A11: I_HF_CHRONIC | B11: I_HF_CHRONIC__C_IHD | C11: Chronic heart-failure management | D11: C_IHD | E11: ihd | F11: Ischemic heart disease | G11: sick_hf | H11: dead_ihd | I11: case_fatality | J11: 0.093 | K11: 0.2 | L11: 0.31 | M11: 0.8 | N11: 2025 | O11: 2050 | P11: =IF(OR(J11="",K11="",L11="",M11=""),"",ROUND(K11*(J11*(M11-L11)/(1-J11*L11)),4)) | Q11: I_HF_CHRONIC__C_IHD | R11: cause-specific | S11: Provisional | T11: Provisional | U11: =COUNTIF($B$2:$B$17,B11) | V11: =IF(U11=1,"OK","DUPLICATE KEY")
A12: I_IHD_ACUTE | B12: I_IHD_ACUTE__C_IHD | C12: Treatment of acute coronary syndromes | D12: C_IHD | E12: ihd | F12: Ischemic heart disease | G12: sick | H12: dead_ihd | I12: case_fatality | J12: 0.2812 | K12: 0.5 | L12: 0.2 | M12: 0.8 | N12: 2025 | O12: 2050 | P12: =IF(OR(J12="",K12="",L12="",M12=""),"",ROUND(K12*(J12*(M12-L12)/(1-J12*L12)),4)) | Q12: I_IHD_ACUTE__C_IHD | R12: cause-specific | S12: Provisional | T12: Provisional | U12: =COUNTIF($B$2:$B$17,B12) | V12: =IF(U12=1,"OK","DUPLICATE KEY")
A13: I_IHD_SECONDARY | B13: I_IHD_SECONDARY__C_IHD | C13: Secondary prevention of ischemic heart disease | D13: C_IHD | E13: ihd | F13: Ischemic heart disease | G13: sick | H13: dead_ihd | I13: case_fatality | J13: 0.5822 | K13: 0.2 | L13: 0.31 | M13: 0.8 | N13: 2025 | O13: 2050 | P13: =IF(OR(J13="",K13="",L13="",M13=""),"",ROUND(K13*(J13*(M13-L13)/(1-J13*L13)),4)) | Q13: I_IHD_SECONDARY__C_IHD | R13: cause-specific | S13: Provisional | T13: Provisional | U13: =COUNTIF($B$2:$B$17,B13) | V13: =IF(U13=1,"OK","DUPLICATE KEY")
... A17: I_T2D_TREATMENT | B17: I_T2D_TREATMENT__C_IHD | C17: Longitudinal treatment of type 2 diabetes | D17: C_IHD | E17: ihd | F17: Ischemic heart disease | G17: sick | H17: dead_ihd | I17: case_fatality | J17: 0.15 | K17: 0.15 | L17: 0.16 | M17: 0.8 | N17: 2025 | O17: 2050 | P17: =IF(OR(J17="",K17="",L17="",M17=""),"",ROUND(K17*(J17*(M17-L17)/(1-J17*L17)),4)) | Q17: I_T2D_TREATMENT__C_T2D | R17: shared-count-once | S17: Review | T17: Provisional | U17: =COUNTIF($B$2:$B$17,B17) | V17: =IF(U17=1,"OK","DUPLICATE KEY")

Sheet Cost_Components
A1: cost_record_id | B1: cost_component_key | C1: cost_option | D1: intervention_id | E1: cause_id | F1: cause_code | G1: cost_join_key | H1: cost_scope | I1: cost_component | J1: population_in_need_measure | K1: population_in_need_fraction | L1: frequency_per_year | M1: c_age_start | N1: c_age_stop | O1: c_sex | P1: unit_cost_usd | Q1: price_year | R1: indonesia_adjusted_flag | S1: cov_baseline | T1: cov_target | U1: cov_start_year | V1: cov_target_year | W1: cost_review | X1: cost_ready
A2: COST_PRIMARY_TX_B | B2: CC_PRIMARY_HTN_STATIN | C2: Option B | D2: I_CVD_PRIMARY | E2: C_SHARED | G2: I_CVD_PRIMARY__C_SHARED | H2: shared-count-once | I2: Antihypertensives and statins for absolute CVD risk >20% | J2: all | K2: 0.3 | L2: 1 | M2: 30 | N2: 95 | O2: Both | P2: 40.487719 | Q2: 2023 | R2: 1 | S2: =IFERROR(INDEX('Selected_Interventions'!$L$2:$L$17,MATCH(G2,'Selected_Interventions'!$Q$2:$Q$17,0)),"") | T2: =IFERROR(INDEX('Selected_Interventions'!$M$2:$M$17,MATCH(G2,'Selected_Interventions'!$Q$2:$Q$17,0)),"") | U2: =IFERROR(INDEX('Selected_Interventions'!$N$2:$N$17,MATCH(G2,'Selected_Interventions'!$Q$2:$Q$17,0)),"") | V2: =IFERROR(INDEX('Selected_Interventions'!$O$2:$O$17,MATCH(G2,'Selected_Interventions'!$Q$2:$Q$17,0)),"") | W2: Alternative | X2: =IF(AND(P2<>"",P2>=0,S2<>"",K2<>"",K2>=0,K2<=1,OR(J2="all",J2="prevalence",J2="incidence")),1,0)
A3: COST_PRIMARY_SCREEN_B | B3: CC_PRIMARY_SCREENING | C3: Option B | D3: I_CVD_PRIMARY | E3: C_SHARED | G3: I_CVD_PRIMARY__C_SHARED | H3: shared-count-once | I3: CVD targeted screening | J3: all | K3: 0.2 | L3: 1 | M3: 30 | N3: 95 | O3: Both | P3: 2.7665219 | Q3: 2023 | R3: 1 | S3: =IFERROR(INDEX('Selected_Interventions'!$L$2:$L$17,MATCH(G3,'Selected_Interventions'!$Q$2:$Q$17,0)),"") | T3: =IFERROR(INDEX('Selected_Interventions'!$M$2:$M$17,MATCH(G3,'Selected_Interventions'!$Q$2:$Q$17,0)),"") | U3: =IFERROR(INDEX('Selected_Interventions'!$N$2:$N$17,MATCH(G3,'Selected_Interventions'!$Q$2:$Q$17,0)),"") | V3: =IFERROR(INDEX('Selected_Interventions'!$O$2:$O$17,MATCH(G3,'Selected_Interventions'!$Q$2:$Q$17,0)),"") | W3: Alternative | X3: =IF(AND(P3<>"",P3>=0,S3<>"",K3<>"",K3>=0,K3<=1,OR(J3="all",J3="prevalence",J3="incidence")),1,0)
A4: COST_HF_ACUTE_C_CMP | B4: CC_HF_ACUTE_C_CMP | C4: Base | D4: I_HF_ACUTE | E4: C_CMP | F4: cmd | G4: I_HF_ACUTE__C_CMP | H4: cause-specific | I4: Acute heart-failure management package | J4: prevalence | K4: 0.5 | L4: 1 | M4: 30 | N4: 95 | O4: Both | P4: 475 | Q4: 2023 | R4: 1 | S4: =IFERROR(INDEX('Selected_Interventions'!$L$2:$L$17,MATCH(G4,'Selected_Interventions'!$Q$2:$Q$17,0)),"") | T4: =IFERROR(INDEX('Selected_Interventions'!$M$2:$M$17,MATCH(G4,'Selected_Interventions'!$Q$2:$Q$17,0)),"") | U4: =IFERROR(INDEX('Selected_Interventions'!$N$2:$N$17,MATCH(G4,'Selected_Interventions'!$Q$2:$Q$17,0)),"") | V4: =IFERROR(INDEX('Selected_Interventions'!$O$2:$O$17,MATCH(G4,'Selected_Interventions'!$Q$2:$Q$17,0)),"") | W4: Provisional | X4: =IF(AND(P4<>"",P4>=0,S4<>"",K4<>"",K4>=0,K4<=1,OR(J4="all",J4="prevalence",J4="incidence")),1,0)
A5: COST_HF_ACUTE_C_HHD | B5: CC_HF_ACUTE_C_HHD | C5: Base | D5: I_HF_ACUTE | E5: C_HHD | F5: hhd | G5: I_HF_ACUTE__C_HHD | H5: cause-specific | I5: Acute heart-failure management package | J5: prevalence | K5: 0.5 | L5: 1 | M5: 30 | N5: 95 | O5: Both | P5: 475 | Q5: 2023 | R5: 1 | S5: =IFERROR(INDEX('Selected_Interventions'!$L$2:$L$17,MATCH(G5,'Selected_Interventions'!$Q$2:$Q$17,0)),"") | T5: =IFERROR(INDEX('Selected_Interventions'!$M$2:$M$17,MATCH(G5,'Selected_Interventions'!$Q$2:$Q$17,0)),"") | U5: =IFERROR(INDEX('Selected_Interventions'!$N$2:$N$17,MATCH(G5,'Selected_Interventions'!$Q$2:$Q$17,0)),"") | V5: =IFERROR(INDEX('Selected_Interventions'!$O$2:$O$17,MATCH(G5,'Selected_Interventions'!$Q$2:$Q$17,0)),"") | W5: Provisional | X5: =IF(AND(P5<>"",P5>=0,S5<>"",K5<>"",K5>=0,K5<=1,OR(J5="all",J5="prevalence",J5="incidence")),1,0)
A6: COST_HF_ACUTE_C_IHD | B6: CC_HF_ACUTE_C_IHD | C6: Base | D6: I_HF_ACUTE | E6: C_IHD | F6: ihd | G6: I_HF_ACUTE__C_IHD | H6: cause-specific | I6: Acute heart-failure management package | J6: prevalence | K6: 0.1 | L6: 1 | M6: 30 | N6: 95 | O6: Both | P6: 475 | Q6: 2023 | R6: 1 | S6: =IFERROR(INDEX('Selected_Interventions'!$L$2:$L$17,MATCH(G6,'Selected_Interventions'!$Q$2:$Q$17,0)),"") | T6: =IFERROR(INDEX('Selected_Interventions'!$M$2:$M$17,MATCH(G6,'Selected_Interventions'!$Q$2:$Q$17,0)),"") | U6: =IFERROR(INDEX('Selected_Interventions'!$N$2:$N$17,MATCH(G6,'Selected_Interventions'!$Q$2:$Q$17,0)),"") | V6: =IFERROR(INDEX('Selected_Interventions'!$O$2:$O$17,MATCH(G6,'Selected_Interventions'!$Q$2:$Q$17,0)),"") | W6: Provisional | X6: =IF(AND(P6<>"",P6>=0,S6<>"",K6<>"",K6>=0,K6<=1,OR(J6="all",J6="prevalence",J6="incidence")),1,0)
A7: COST_HF_CHRONIC_CMP_ECHO | B7: CC_HF_CHRONIC_CMP_ECHO | C7: Base | D7: I_HF_CHRONIC | E7: C_CMP | F7: cmd | G7: I_HF_CHRONIC__C_CMP | H7: cause-specific | I7: One cardiac echo per year | J7: prevalence | K7: 1 | L7: 1 | M7: 0 | N7: 95 | O7: Both | P7: 20 | Q7: 2023 | R7: 1 | S7: =IFERROR(INDEX('Selected_Interventions'!$L$2:$L$17,MATCH(G7,'Selected_Interventions'!$Q$2:$Q$17,0)),"") | T7: =IFERROR(INDEX('Selected_Interventions'!$M$2:$M$17,MATCH(G7,'Selected_Interventions'!$Q$2:$Q$17,0)),"") | U7: =IFERROR(INDEX('Selected_Interventions'!$N$2:$N$17,MATCH(G7,'Selected_Interventions'!$Q$2:$Q$17,0)),"") | V7: =IFERROR(INDEX('Selected_Interventions'!$O$2:$O$17,MATCH(G7,'Selected_Interventions'!$Q$2:$Q$17,0)),"") | W7: Provisional | X7: =IF(AND(P7<>"",P7>=0,S7<>"",K7<>"",K7>=0,K7<=1,OR(J7="all",J7="prevalence",J7="incidence")),1,0)
A8: COST_HF_CHRONIC_CMP_LAB_B | B8: CC_HF_CHRONIC_CMP_FOLLOWUP | C8: Option B | D8: I_HF_CHRONIC | E8: C_CMP | F8: cmd | G8: I_HF_CHRONIC__C_CMP | H8: cause-specific | I8: Lab tests and follow-up visits | J8: prevalence | K8: 1 | L8: 1 | M8: 0 | N8: 95 | O8: Both | P8: 64.943441 | Q8: 2023 | R8: 1 | S8: =IFERROR(INDEX('Selected_Interventions'!$L$2:$L$17,MATCH(G8,'Selected_Interventions'!$Q$2:$Q$17,0)),"") | T8: =IFERROR(INDEX('Selected_Interventions'!$M$2:$M$17,MATCH(G8,'Selected_Interventions'!$Q$2:$Q$17,0)),"") | U8: =IFERROR(INDEX('Selected_Interventions'!$N$2:$N$17,MATCH(G8,'Selected_Interventions'!$Q$2:$Q$17,0)),"") | V8: =IFERROR(INDEX('Selected_Interventions'!$O$2:$O$17,MATCH(G8,'Selected_Interventions'!$Q$2:$Q$17,0)),"") | W8: Alternative | X8: =IF(AND(P8<>"",P8>=0,S8<>"",K8<>"",K8>=0,K8<=1,OR(J8="all",J8="prevalence",J8="incidence")),1,0)
A9: COST_HF_CHRONIC_CMP_TX | B9: CC_HF_CHRONIC_CMP_TREATMENT | C9: Base | D9: I_HF_CHRONIC | E9: C_CMP | F9: cmd | G9: I_HF_CHRONIC__C_CMP | H9: cause-specific | I9: Treatment of heart failure | J9: prevalence | K9: 1 | L9: 1 | M9: 0 | N9: 95 | O9: Both | P9: 115.10623 | Q9: 2023 | R9: 1 | S9: =IFERROR(INDEX('Selected_Interventions'!$L$2:$L$17,MATCH(G9,'Selected_Interventions'!$Q$2:$Q$17,0)),"") | T9: =IFERROR(INDEX('Selected_Interventions'!$M$2:$M$17,MATCH(G9,'Selected_Interventions'!$Q$2:$Q$17,0)),"") | U9: =IFERROR(INDEX('Selected_Interventions'!$N$2:$N$17,MATCH(G9,'Selected_Interventions'!$Q$2:$Q$17,0)),"") | V9: =IFERROR(INDEX('Selected_Interventions'!$O$2:$O$17,MATCH(G9,'Selected_Interventions'!$Q$2:$Q$17,0)),"") | W9: Provisional | X9: =IF(AND(P9<>"",P9>=0,S9<>"",K9<>"",K9>=0,K9<=1,OR(J9="all",J9="prevalence",J9="incidence")),1,0)
A10: COST_HF_CHRONIC_HHD_ECHO | B10: CC_HF_CHRONIC_HHD_ECHO | C10: Base | D10: I_HF_CHRONIC | E10: C_HHD | F10: hhd | G10: I_HF_CHRONIC__C_HHD | H10: cause-specific | I10: One cardiac echo per year | J10: prevalence | K10: 1 | L10: 1 | M10: 30 | N10: 95 | O10: Both | P10: 20 | Q10: 2023 | R10: 1 | S10: =IFERROR(INDEX('Selected_Interventions'!$L$2:$L$17,MATCH(G10,'Selected_Interventions'!$Q$2:$Q$17,0)),"") | T10: =IFERROR(INDEX('Selected_Interventions'!$M$2:$M$17,MATCH(G10,'Selected_Interventions'!$Q$2:$Q$17,0)),"") | U10: =IFERROR(INDEX('Selected_Interventions'!$N$2:$N$17,MATCH(G10,'Selected_Interventions'!$Q$2:$Q$17,0)),"") | V10: =IFERROR(INDEX('Selected_Interventions'!$O$2:$O$17,MATCH(G10,'Selected_Interventions'!$Q$2:$Q$17,0)),"") | W10: Provisional | X10: =IF(AND(P10<>"",P10>=0,S10<>"",K10<>"",K10>=0,K10<=1,OR(J10="all",J10="prevalence",J10="incidence")),1,0)
A11: COST_HF_CHRONIC_HHD_LAB_B | B11: CC_HF_CHRONIC_HHD_FOLLOWUP | C11: Option B | D11: I_HF_CHRONIC | E11: C_HHD | F11: hhd | G11: I_HF_CHRONIC__C_HHD | H11: cause-specific | I11: Lab tests and follow-up visits | J11: prevalence | K11: 1 | L11: 1 | M11: 30 | N11: 95 | O11: Both | P11: 64.943441 | Q11: 2023 | R11: 1 | S11: =IFERROR(INDEX('Selected_Interventions'!$L$2:$L$17,MATCH(G11,'Selected_Interventions'!$Q$2:$Q$17,0)),"") | T11: =IFERROR(INDEX('Selected_Interventions'!$M$2:$M$17,MATCH(G11,'Selected_Interventions'!$Q$2:$Q$17,0)),"") | U11: =IFERROR(INDEX('Selected_Interventions'!$N$2:$N$17,MATCH(G11,'Selected_Interventions'!$Q$2:$Q$17,0)),"") | V11: =IFERROR(INDEX('Selected_Interventions'!$O$2:$O$17,MATCH(G11,'Selected_Interventions'!$Q$2:$Q$17,0)),"") | W11: Alternative | X11: =IF(AND(P11<>"",P11>=0,S11<>"",K11<>"",K11>=0,K11<=1,OR(J11="all",J11="prevalence",J11="incidence")),1,0)
A12: COST_HF_CHRONIC_HHD_TX | B12: CC_HF_CHRONIC_HHD_TREATMENT | C12: Base | D12: I_HF_CHRONIC | E12: C_HHD | F12: hhd | G12: I_HF_CHRONIC__C_HHD | H12: cause-specific | I12: Treatment of heart failure | J12: prevalence | K12: 1 | L12: 1 | M12: 0 | N12: 95 | O12: Both | P12: 115.10623 | Q12: 2023 | R12: 1 | S12: =IFERROR(INDEX('Selected_Interventions'!$L$2:$L$17,MATCH(G12,'Selected_Interventions'!$Q$2:$Q$17,0)),"") | T12: =IFERROR(INDEX('Selected_Interventions'!$M$2:$M$17,MATCH(G12,'Selected_Interventions'!$Q$2:$Q$17,0)),"") | U12: =IFERROR(INDEX('Selected_Interventions'!$N$2:$N$17,MATCH(G12,'Selected_Interventions'!$Q$2:$Q$17,0)),"") | V12: =IFERROR(INDEX('Selected_Interventions'!$O$2:$O$17,MATCH(G12,'Selected_Interventions'!$Q$2:$Q$17,0)),"") | W12: Provisional | X12: =IF(AND(P12<>"",P12>=0,S12<>"",K12<>"",K12>=0,K12<=1,OR(J12="all",J12="prevalence",J12="incidence")),1,0)
A13: COST_HF_CHRONIC_IHD_ECHO | B13: CC_HF_CHRONIC_IHD_ECHO | C13: Base | D13: I_HF_CHRONIC | E13: C_IHD | F13: ihd | G13: I_HF_CHRONIC__C_IHD | H13: cause-specific | I13: One cardiac echo per year | J13: prevalence | K13: 0.2 | L13: 1 | M13: 30 | N13: 95 | O13: Both | P13: 20 | Q13: 2023 | R13: 1 | S13: =IFERROR(INDEX('Selected_Interventions'!$L$2:$L$17,MATCH(G13,'Selected_Interventions'!$Q$2:$Q$17,0)),"") | T13: =IFERROR(INDEX('Selected_Interventions'!$M$2:$M$17,MATCH(G13,'Selected_Interventions'!$Q$2:$Q$17,0)),"") | U13: =IFERROR(INDEX('Selected_Interventions'!$N$2:$N$17,MATCH(G13,'Selected_Interventions'!$Q$2:$Q$17,0)),"") | V13: =IFERROR(INDEX('Selected_Interventions'!$O$2:$O$17,MATCH(G13,'Selected_Interventions'!$Q$2:$Q$17,0)),"") | W13: Provisional | X13: =IF(AND(P13<>"",P13>=0,S13<>"",K13<>"",K13>=0,K13<=1,OR(J13="all",J13="prevalence",J13="incidence")),1,0)
A14: COST_HF_CHRONIC_IHD_LAB | B14: CC_HF_CHRONIC_IHD_FOLLOWUP | C14: Missing | D14: I_HF_CHRONIC | E14: C_IHD | F14: ihd | G14: I_HF_CHRONIC__C_IHD | H14: cause-specific | I14: Lab tests and follow-up visits | J14: prevalence | K14: 0.2 | L14: 1 | M14: 30 | N14: 95 | O14: Both | P14: 7 | Q14: 2023 | R14: 1 | S14: =IFERROR(INDEX('Selected_Interventions'!$L$2:$L$17,MATCH(G14,'Selected_Interventions'!$Q$2:$Q$17,0)),"") | T14: =IFERROR(INDEX('Selected_Interventions'!$M$2:$M$17,MATCH(G14,'Selected_Interventions'!$Q$2:$Q$17,0)),"") | U14: =IFERROR(INDEX('Selected_Interventions'!$N$2:$N$17,MATCH(G14,'Selected_Interventions'!$Q$2:$Q$17,0)),"") | V14: =IFERROR(INDEX('Selected_Interventions'!$O$2:$O$17,MATCH(G14,'Selected_Interventions'!$Q$2:$Q$17,0)),"") | W14: Missing input | X14: =IF(AND(P14<>"",P14>=0,S14<>"",K14<>"",K14>=0,K14<=1,OR(J14="all",J14="prevalence",J14="incidence")),1,0)
A15: COST_HF_CHRONIC_IHD_TX | B15: CC_HF_CHRONIC_IHD_TREATMENT | C15: Base | D15: I_HF_CHRONIC | E15: C_IHD | F15: ihd | G15: I_HF_CHRONIC__C_IHD | H15: cause-specific | I15: Treatment of heart failure | J15: prevalence | K15: 0.2 | L15: 1 | M15: 30 | N15: 95 | O15: Both | P15: 29.216219 | Q15: 2023 | R15: 1 | S15: =IFERROR(INDEX('Selected_Interventions'!$L$2:$L$17,MATCH(G15,'Selected_Interventions'!$Q$2:$Q$17,0)),"") | T15: =IFERROR(INDEX('Selected_Interventions'!$M$2:$M$17,MATCH(G15,'Selected_Interventions'!$Q$2:$Q$17,0)),"") | U15: =IFERROR(INDEX('Selected_Interventions'!$N$2:$N$17,MATCH(G15,'Selected_Interventions'!$Q$2:$Q$17,0)),"") | V15: =IFERROR(INDEX('Selected_Interventions'!$O$2:$O$17,MATCH(G15,'Selected_Interventions'!$Q$2:$Q$17,0)),"") | W15: Provisional | X15: =IF(AND(P15<>"",P15>=0,S15<>"",K15<>"",K15>=0,K15<=1,OR(J15="all",J15="prevalence",J15="incidence")),1,0)
... A28: COST_T2D_SCREENING | B28: CC_T2D_SCREENING | C28: Base | D28: I_T2D_TREATMENT | E28: C_T2D | F28: dm2 | G28: I_T2D_TREATMENT__C_T2D | H28: cause-specific | I28: Diabetes opportunistic screening | J28: all | K28: 1e-05 | L28: 1 | M28: 30 | N28: 95 | O28: Both | P28: 0.70495848 | Q28: 2023 | R28: 1 | S28: =IFERROR(INDEX('Selected_Interventions'!$L$2:$L$17,MATCH(G28,'Selected_Interventions'!$Q$2:$Q$17,0)),"") | T28: =IFERROR(INDEX('Selected_Interventions'!$M$2:$M$17,MATCH(G28,'Selected_Interventions'!$Q$2:$Q$17,0)),"") | U28: =IFERROR(INDEX('Selected_Interventions'!$N$2:$N$17,MATCH(G28,'Selected_Interventions'!$Q$2:$Q$17,0)),"") | V28: =IFERROR(INDEX('Selected_Interventions'!$O$2:$O$17,MATCH(G28,'Selected_Interventions'!$Q$2:$Q$17,0)),"") | W28: Provisional | X28: =IF(AND(P28<>"",P28>=0,S28<>"",K28<>"",K28>=0,K28<=1,OR(J28="all",J28="prevalence",J28="incidence")),1,0)

Sheet Annual_Mortality
A1: scenario | B1: scenario_label | C1: year | D1: cause | E1: cases | F1: cause_deaths | G1: base_deaths | H1: deaths_averted | I1: base_cases | J1: cases_averted
A2: I_CVD_PRIMARY | B2: Primary prevention of CVD | C2: 2025 | D2: cmd | E2: 11293.859 | F2: 8456.0911 | G2: 8456.0911 | H2: =G2-F2 | I2: 11293.859 | J2: =I2-E2
A3: I_CVD_PRIMARY | B3: Primary prevention of CVD | C3: 2025 | D3: dm2 | E3: 796801.79 | F3: 124437.1 | G3: 124437.1 | H3: =G3-F3 | I3: 796801.79 | J3: =I3-E3
A4: I_CVD_PRIMARY | B4: Primary prevention of CVD | C4: 2025 | D4: hhd | E4: 109645.69 | F4: 70978.798 | G4: 70978.798 | H4: =G4-F4 | I4: 110599.34 | J4: =I4-E4
A5: I_CVD_PRIMARY | B5: Primary prevention of CVD | C5: 2025 | D5: hstroke | E5: 267826.2 | F5: 250549.93 | G5: 250549.93 | H5: =G5-F5 | I5: 269908.91 | J5: =I5-E5
A6: I_CVD_PRIMARY | B6: Primary prevention of CVD | C6: 2025 | D6: ihd | E6: 599698.41 | F6: 336235.04 | G6: 336235.04 | H6: =G6-F6 | I6: 605290.56 | J6: =I6-E6
A7: I_CVD_PRIMARY | B7: Primary prevention of CVD | C7: 2025 | D7: istroke | E7: 326007.22 | F7: 165181.23 | G7: 165181.23 | H7: =G7-F7 | I7: 328703.7 | J7: =I7-E7
A8: I_CVD_PRIMARY | B8: Primary prevention of CVD | C8: 2025 | D8: rhd | E8: 12601.519 | F8: 3955.3071 | G8: 3955.3071 | H8: =G8-F8 | I8: 12601.519 | J8: =I8-E8
A9: I_CVD_PRIMARY | B9: Primary prevention of CVD | C9: 2026 | D9: cmd | E9: 11413.94 | F9: 8503.0488 | G9: 8503.0488 | H9: =G9-F9 | I9: 11413.94 | J9: =I9-E9
A10: I_CVD_PRIMARY | B10: Primary prevention of CVD | C10: 2026 | D10: dm2 | E10: 813844.57 | F10: 128333.95 | G10: 128333.95 | H10: =G10-F10 | I10: 813844.57 | J10: =I10-E10
A11: I_CVD_PRIMARY | B11: Primary prevention of CVD | C11: 2026 | D11: hhd | E11: 111300.85 | F11: 72202.279 | G11: 72339.688 | H11: =G11-F11 | I11: 113261.47 | J11: =I11-E11
A12: I_CVD_PRIMARY | B12: Primary prevention of CVD | C12: 2026 | D12: hstroke | E12: 269967.39 | F12: 254049.92 | G12: 254910.75 | H12: =G12-F12 | I12: 274200.58 | J12: =I12-E12
A13: I_CVD_PRIMARY | B13: Primary prevention of CVD | C13: 2026 | D13: ihd | E13: 608641.54 | F13: 344584.48 | G13: 344917.06 | H13: =G13-F13 | I13: 620097.59 | J13: =I13-E13
... A1639: baseline | B1639: Baseline (no new intervention) | C1639: 2050 | D1639: rhd | E1639: 11458.332 | F1639: 1051.1139 | G1639: 1051.1139 | H1639: =G1639-F1639 | I1639: 11458.332 | J1639: =I1639-E1639

Sheet Health_Outcomes
A1: scenario | B1: scenario_label | C1: year | D1: modeled_deaths | E1: baseline_deaths | F1: deaths_averted | G1: modeled_cases | H1: baseline_cases | I1: cases_averted | J1: yll | K1: base_yll | L1: yll_averted | M1: yld | N1: base_yld | O1: yld_averted | P1: daly | Q1: base_daly | R1: dalys_averted | S1: life_years_gained
A2: all | B2: All selected interventions (combined) | C2: 2025 | D2: 956104.48 | E2: 959793.5 | F2: =E2-D2 | G2: 2123874.7 | H2: 2135199.7 | I2: =H2-G2 | J2: 13023884 | K2: 13078631 | L2: =K2-J2 | M2: 2438887.3 | N2: 2439867.8 | O2: =N2-M2 | P2: 15462771 | Q2: 15518499 | R2: =Q2-P2 | S2: =L2
A3: all | B3: All selected interventions (combined) | C3: 2026 | D3: 972035.78 | E3: 980780.31 | F3: =E3-D3 | G3: 2157946 | H3: 2181019.5 | I3: =H3-G3 | J3: 13248926 | K3: 13376482 | L3: =K3-J3 | M3: 2492339.1 | N3: 2495093.1 | O3: =N3-M3 | P3: 15741265 | Q3: 15871576 | R3: =Q3-P3 | S3: =L3
A4: all | B4: All selected interventions (combined) | C4: 2027 | D4: 988622.75 | E4: 1003320.8 | F4: =E4-D4 | G4: 2193121.1 | H4: 2228341.8 | I4: =H4-G4 | J4: 13463760 | K4: 13677395 | L4: =K4-J4 | M4: 2546012 | N4: 2551241 | O4: =N4-M4 | P4: 16009772 | Q4: 16228636 | R4: =Q4-P4 | S4: =L4
A5: all | B5: All selected interventions (combined) | C5: 2028 | D5: 1006065.7 | E5: 1027500.5 | F5: =E5-D5 | G5: 2240047 | H5: 2288120.7 | I5: =H5-G5 | J5: 13662648 | K5: 13973850 | L5: =K5-J5 | M5: 2600748.7 | N5: 2609119.5 | O5: =N5-M5 | P5: 16263397 | Q5: 16582969 | R5: =Q5-P5 | S5: =L5
A6: all | B6: All selected interventions (combined) | C6: 2029 | D6: 1024672.5 | E6: 1053610.4 | F6: =E6-D6 | G6: 2275548.3 | H6: 2336688.1 | I6: =H6-G6 | J6: 13870988 | K6: 14290695 | L6: =K6-J6 | M6: 2655281.6 | N6: 2667387.1 | O6: =N6-M6 | P6: 16526269 | Q6: 16958082 | R6: =Q6-P6 | S6: =L6
A7: all | B7: All selected interventions (combined) | C7: 2030 | D7: 1043719.7 | E7: 1080810.2 | F7: =E7-D7 | G7: 2312077.4 | H7: 2386448.8 | I7: =H7-G7 | J7: 14063696 | K7: 14601429 | L7: =K7-J7 | M7: 2709572.6 | N7: 2725934.8 | O7: =N7-M7 | P7: 16773269 | Q7: 17327364 | R7: =Q7-P7 | S7: =L7
A8: all | B8: All selected interventions (combined) | C8: 2031 | D8: 1061393.7 | E8: 1107157.6 | F8: =E8-D8 | G8: 2347388.5 | H8: 2435295.4 | I8: =H8-G8 | J8: 14246471 | K8: 14910263 | L8: =K8-J8 | M8: 2763634.3 | N8: 2784742.8 | O8: =N8-M8 | P8: 17010106 | Q8: 17695005 | R8: =Q8-P8 | S8: =L8
A9: all | B9: All selected interventions (combined) | C9: 2032 | D9: 1079033.1 | E9: 1133979.8 | F9: =E9-D9 | G9: 2384515.5 | H9: 2486226.9 | I9: =H9-G9 | J9: 14415633 | K9: 15212725 | L9: =K9-J9 | M9: 2817579.3 | N9: 2843886.5 | O9: =N9-M9 | P9: 17233212 | Q9: 18056611 | R9: =Q9-P9 | S9: =L9
A10: all | B10: All selected interventions (combined) | C10: 2033 | D10: 1095945.5 | E10: 1160519 | F10: =E10-D10 | G10: 2428027.3 | H10: 2544179.9 | I10: =H10-G10 | J10: 14561427 | K10: 15498147 | L10: =K10-J10 | M10: 2871971.4 | N10: 2903939 | O10: =N10-M10 | P10: 17433399 | Q10: 18402086 | R10: =Q10-P10 | S10: =L10
A11: all | B11: All selected interventions (combined) | C11: 2034 | D11: 1112752.9 | E11: 1187394.6 | F11: =E11-D11 | G11: 2460942.3 | H11: 2591241.8 | I11: =H11-G11 | J11: 14715676 | K11: 15799428 | L11: =K11-J11 | M11: 2925880 | N11: 2963891.1 | O11: =N11-M11 | P11: 17641556 | Q11: 18763320 | R11: =Q11-P11 | S11: =L11
A12: all | B12: All selected interventions (combined) | C12: 2035 | D12: 1129198.6 | E12: 1214326 | F12: =E12-D12 | G12: 2492871.2 | H12: 2637338.6 | I12: =H12-G12 | J12: 14856644 | K12: 16093446 | L12: =K12-J12 | M12: 2979169.9 | N12: 3023565.8 | O12: =N12-M12 | P12: 17835814 | Q12: 19117012 | R12: =Q12-P12 | S12: =L12
A13: all | B13: All selected interventions (combined) | C13: 2036 | D13: 1145993.2 | E13: 1242005.2 | F13: =E13-D13 | G13: 2528880.9 | H13: 2687815.4 | I13: =H13-G13 | J13: 14991946 | K13: 16387284 | L13: =K13-J13 | M13: 3032101.1 | N13: 3083207.2 | O13: =N13-M13 | P13: 18024047 | Q13: 19470491 | R13: =Q13-P13 | S13: =L13
... A209: I_T2D_TREATMENT | B209: Longitudinal treatment of type 2 diabetes | C209: 2050 | D209: 1563171.1 | E209: 1604008.5 | F209: =E209-D209 | G209: 3268647.8 | H209: 3257199.3 | I209: =H209-G209 | J209: 19040770 | K209: 19570013 | L209: =K209-J209 | M209: 3878765.6 | N209: 3846594.4 | O209: =N209-M209 | P209: 22919536 | Q209: 23416608 | R209: =Q209-P209 | S209: =L209

Sheet CVD_40q30
A1: location | B1: scenario | C1: scenario_label | D1: intervention_family | E1: scenario_role | F1: parent_package_id | G1: htn_target_scenario | H1: year | I1: cvd_40q30 | J1: baseline_cvd_40q30 | K1: absolute_reduction_pp | L1: percent_reduction | M1: cvd_40q30_r | N1: recon_status
A2: Indonesia | B2: I_CVD_PRIMARY | C2: Primary prevention of CVD | D2: clinical | G2: htncov2_aspirational | H2: 2025 | I2: =100*(1-(SUMIFS('CVD_40q30_Age'!$M$2:$M$9361,'CVD_40q30_Age'!$A$2:$A$9361,A2,'CVD_40q30_Age'!$B$2:$B$9361,B2,'CVD_40q30_Age'!$E$2:$E$9361,G2,'CVD_40q30_Age'!$F$2:$F$9361,H2,'CVD_40q30_Age'!$G$2:$G$9361,69))/(SUMIFS('CVD_40q30_Age'!$L$2:$L$9361,'CVD_40q30_Age'!$A$2:$A$9361,A2,'CVD_40q30_Age'!$B$2:$B$9361,B2,'CVD_40q30_Age'!$E$2:$E$9361,G2,'CVD_40q30_Age'!$F$2:$F$9361,H2,'CVD_40q30_Age'!$G$2:$G$9361,30))) | J2: =SUMIFS($I$2:$I$235,$A$2:$A$235,A2,$G$2:$G$235,G2,$H$2:$H$235,H2,$B$2:$B$235,"baseline") | K2: =J2-I2 | L2: =IF(J2=0,"",100*(J2-I2)/J2) | M2: 14.594863 | N2: =IF(ABS(I2-M2)<=0.001,"match","mismatch")
A3: Indonesia | B3: I_CVD_PRIMARY | C3: Primary prevention of CVD | D3: clinical | G3: htncov2_aspirational | H3: 2026 | I3: =100*(1-(SUMIFS('CVD_40q30_Age'!$M$2:$M$9361,'CVD_40q30_Age'!$A$2:$A$9361,A3,'CVD_40q30_Age'!$B$2:$B$9361,B3,'CVD_40q30_Age'!$E$2:$E$9361,G3,'CVD_40q30_Age'!$F$2:$F$9361,H3,'CVD_40q30_Age'!$G$2:$G$9361,69))/(SUMIFS('CVD_40q30_Age'!$L$2:$L$9361,'CVD_40q30_Age'!$A$2:$A$9361,A3,'CVD_40q30_Age'!$B$2:$B$9361,B3,'CVD_40q30_Age'!$E$2:$E$9361,G3,'CVD_40q30_Age'!$F$2:$F$9361,H3,'CVD_40q30_Age'!$G$2:$G$9361,30))) | J3: =SUMIFS($I$2:$I$235,$A$2:$A$235,A3,$G$2:$G$235,G3,$H$2:$H$235,H3,$B$2:$B$235,"baseline") | K3: =J3-I3 | L3: =IF(J3=0,"",100*(J3-I3)/J3) | M3: 14.497404 | N3: =IF(ABS(I3-M3)<=0.001,"match","mismatch")
A4: Indonesia | B4: I_CVD_PRIMARY | C4: Primary prevention of CVD | D4: clinical | G4: htncov2_aspirational | H4: 2027 | I4: =100*(1-(SUMIFS('CVD_40q30_Age'!$M$2:$M$9361,'CVD_40q30_Age'!$A$2:$A$9361,A4,'CVD_40q30_Age'!$B$2:$B$9361,B4,'CVD_40q30_Age'!$E$2:$E$9361,G4,'CVD_40q30_Age'!$F$2:$F$9361,H4,'CVD_40q30_Age'!$G$2:$G$9361,69))/(SUMIFS('CVD_40q30_Age'!$L$2:$L$9361,'CVD_40q30_Age'!$A$2:$A$9361,A4,'CVD_40q30_Age'!$B$2:$B$9361,B4,'CVD_40q30_Age'!$E$2:$E$9361,G4,'CVD_40q30_Age'!$F$2:$F$9361,H4,'CVD_40q30_Age'!$G$2:$G$9361,30))) | J4: =SUMIFS($I$2:$I$235,$A$2:$A$235,A4,$G$2:$G$235,G4,$H$2:$H$235,H4,$B$2:$B$235,"baseline") | K4: =J4-I4 | L4: =IF(J4=0,"",100*(J4-I4)/J4) | M4: 14.37425 | N4: =IF(ABS(I4-M4)<=0.001,"match","mismatch")
A5: Indonesia | B5: I_CVD_PRIMARY | C5: Primary prevention of CVD | D5: clinical | G5: htncov2_aspirational | H5: 2028 | I5: =100*(1-(SUMIFS('CVD_40q30_Age'!$M$2:$M$9361,'CVD_40q30_Age'!$A$2:$A$9361,A5,'CVD_40q30_Age'!$B$2:$B$9361,B5,'CVD_40q30_Age'!$E$2:$E$9361,G5,'CVD_40q30_Age'!$F$2:$F$9361,H5,'CVD_40q30_Age'!$G$2:$G$9361,69))/(SUMIFS('CVD_40q30_Age'!$L$2:$L$9361,'CVD_40q30_Age'!$A$2:$A$9361,A5,'CVD_40q30_Age'!$B$2:$B$9361,B5,'CVD_40q30_Age'!$E$2:$E$9361,G5,'CVD_40q30_Age'!$F$2:$F$9361,H5,'CVD_40q30_Age'!$G$2:$G$9361,30))) | J5: =SUMIFS($I$2:$I$235,$A$2:$A$235,A5,$G$2:$G$235,G5,$H$2:$H$235,H5,$B$2:$B$235,"baseline") | K5: =J5-I5 | L5: =IF(J5=0,"",100*(J5-I5)/J5) | M5: 14.238676 | N5: =IF(ABS(I5-M5)<=0.001,"match","mismatch")
A6: Indonesia | B6: I_CVD_PRIMARY | C6: Primary prevention of CVD | D6: clinical | G6: htncov2_aspirational | H6: 2029 | I6: =100*(1-(SUMIFS('CVD_40q30_Age'!$M$2:$M$9361,'CVD_40q30_Age'!$A$2:$A$9361,A6,'CVD_40q30_Age'!$B$2:$B$9361,B6,'CVD_40q30_Age'!$E$2:$E$9361,G6,'CVD_40q30_Age'!$F$2:$F$9361,H6,'CVD_40q30_Age'!$G$2:$G$9361,69))/(SUMIFS('CVD_40q30_Age'!$L$2:$L$9361,'CVD_40q30_Age'!$A$2:$A$9361,A6,'CVD_40q30_Age'!$B$2:$B$9361,B6,'CVD_40q30_Age'!$E$2:$E$9361,G6,'CVD_40q30_Age'!$F$2:$F$9361,H6,'CVD_40q30_Age'!$G$2:$G$9361,30))) | J6: =SUMIFS($I$2:$I$235,$A$2:$A$235,A6,$G$2:$G$235,G6,$H$2:$H$235,H6,$B$2:$B$235,"baseline") | K6: =J6-I6 | L6: =IF(J6=0,"",100*(J6-I6)/J6) | M6: 14.101328 | N6: =IF(ABS(I6-M6)<=0.001,"match","mismatch")
A7: Indonesia | B7: I_CVD_PRIMARY | C7: Primary prevention of CVD | D7: clinical | G7: htncov2_aspirational | H7: 2030 | I7: =100*(1-(SUMIFS('CVD_40q30_Age'!$M$2:$M$9361,'CVD_40q30_Age'!$A$2:$A$9361,A7,'CVD_40q30_Age'!$B$2:$B$9361,B7,'CVD_40q30_Age'!$E$2:$E$9361,G7,'CVD_40q30_Age'!$F$2:$F$9361,H7,'CVD_40q30_Age'!$G$2:$G$9361,69))/(SUMIFS('CVD_40q30_Age'!$L$2:$L$9361,'CVD_40q30_Age'!$A$2:$A$9361,A7,'CVD_40q30_Age'!$B$2:$B$9361,B7,'CVD_40q30_Age'!$E$2:$E$9361,G7,'CVD_40q30_Age'!$F$2:$F$9361,H7,'CVD_40q30_Age'!$G$2:$G$9361,30))) | J7: =SUMIFS($I$2:$I$235,$A$2:$A$235,A7,$G$2:$G$235,G7,$H$2:$H$235,H7,$B$2:$B$235,"baseline") | K7: =J7-I7 | L7: =IF(J7=0,"",100*(J7-I7)/J7) | M7: 13.948509 | N7: =IF(ABS(I7-M7)<=0.001,"match","mismatch")
A8: Indonesia | B8: I_CVD_PRIMARY | C8: Primary prevention of CVD | D8: clinical | G8: htncov2_aspirational | H8: 2031 | I8: =100*(1-(SUMIFS('CVD_40q30_Age'!$M$2:$M$9361,'CVD_40q30_Age'!$A$2:$A$9361,A8,'CVD_40q30_Age'!$B$2:$B$9361,B8,'CVD_40q30_Age'!$E$2:$E$9361,G8,'CVD_40q30_Age'!$F$2:$F$9361,H8,'CVD_40q30_Age'!$G$2:$G$9361,69))/(SUMIFS('CVD_40q30_Age'!$L$2:$L$9361,'CVD_40q30_Age'!$A$2:$A$9361,A8,'CVD_40q30_Age'!$B$2:$B$9361,B8,'CVD_40q30_Age'!$E$2:$E$9361,G8,'CVD_40q30_Age'!$F$2:$F$9361,H8,'CVD_40q30_Age'!$G$2:$G$9361,30))) | J8: =SUMIFS($I$2:$I$235,$A$2:$A$235,A8,$G$2:$G$235,G8,$H$2:$H$235,H8,$B$2:$B$235,"baseline") | K8: =J8-I8 | L8: =IF(J8=0,"",100*(J8-I8)/J8) | M8: 13.767799 | N8: =IF(ABS(I8-M8)<=0.001,"match","mismatch")
A9: Indonesia | B9: I_CVD_PRIMARY | C9: Primary prevention of CVD | D9: clinical | G9: htncov2_aspirational | H9: 2032 | I9: =100*(1-(SUMIFS('CVD_40q30_Age'!$M$2:$M$9361,'CVD_40q30_Age'!$A$2:$A$9361,A9,'CVD_40q30_Age'!$B$2:$B$9361,B9,'CVD_40q30_Age'!$E$2:$E$9361,G9,'CVD_40q30_Age'!$F$2:$F$9361,H9,'CVD_40q30_Age'!$G$2:$G$9361,69))/(SUMIFS('CVD_40q30_Age'!$L$2:$L$9361,'CVD_40q30_Age'!$A$2:$A$9361,A9,'CVD_40q30_Age'!$B$2:$B$9361,B9,'CVD_40q30_Age'!$E$2:$E$9361,G9,'CVD_40q30_Age'!$F$2:$F$9361,H9,'CVD_40q30_Age'!$G$2:$G$9361,30))) | J9: =SUMIFS($I$2:$I$235,$A$2:$A$235,A9,$G$2:$G$235,G9,$H$2:$H$235,H9,$B$2:$B$235,"baseline") | K9: =J9-I9 | L9: =IF(J9=0,"",100*(J9-I9)/J9) | M9: 13.575472 | N9: =IF(ABS(I9-M9)<=0.001,"match","mismatch")
A10: Indonesia | B10: I_CVD_PRIMARY | C10: Primary prevention of CVD | D10: clinical | G10: htncov2_aspirational | H10: 2033 | I10: =100*(1-(SUMIFS('CVD_40q30_Age'!$M$2:$M$9361,'CVD_40q30_Age'!$A$2:$A$9361,A10,'CVD_40q30_Age'!$B$2:$B$9361,B10,'CVD_40q30_Age'!$E$2:$E$9361,G10,'CVD_40q30_Age'!$F$2:$F$9361,H10,'CVD_40q30_Age'!$G$2:$G$9361,69))/(SUMIFS('CVD_40q30_Age'!$L$2:$L$9361,'CVD_40q30_Age'!$A$2:$A$9361,A10,'CVD_40q30_Age'!$B$2:$B$9361,B10,'CVD_40q30_Age'!$E$2:$E$9361,G10,'CVD_40q30_Age'!$F$2:$F$9361,H10,'CVD_40q30_Age'!$G$2:$G$9361,30))) | J10: =SUMIFS($I$2:$I$235,$A$2:$A$235,A10,$G$2:$G$235,G10,$H$2:$H$235,H10,$B$2:$B$235,"baseline") | K10: =J10-I10 | L10: =IF(J10=0,"",100*(J10-I10)/J10) | M10: 13.368501 | N10: =IF(ABS(I10-M10)<=0.001,"match","mismatch")
A11: Indonesia | B11: I_CVD_PRIMARY | C11: Primary prevention of CVD | D11: clinical | G11: htncov2_aspirational | H11: 2034 | I11: =100*(1-(SUMIFS('CVD_40q30_Age'!$M$2:$M$9361,'CVD_40q30_Age'!$A$2:$A$9361,A11,'CVD_40q30_Age'!$B$2:$B$9361,B11,'CVD_40q30_Age'!$E$2:$E$9361,G11,'CVD_40q30_Age'!$F$2:$F$9361,H11,'CVD_40q30_Age'!$G$2:$G$9361,69))/(SUMIFS('CVD_40q30_Age'!$L$2:$L$9361,'CVD_40q30_Age'!$A$2:$A$9361,A11,'CVD_40q30_Age'!$B$2:$B$9361,B11,'CVD_40q30_Age'!$E$2:$E$9361,G11,'CVD_40q30_Age'!$F$2:$F$9361,H11,'CVD_40q30_Age'!$G$2:$G$9361,30))) | J11: =SUMIFS($I$2:$I$235,$A$2:$A$235,A11,$G$2:$G$235,G11,$H$2:$H$235,H11,$B$2:$B$235,"baseline") | K11: =J11-I11 | L11: =IF(J11=0,"",100*(J11-I11)/J11) | M11: 13.164693 | N11: =IF(ABS(I11-M11)<=0.001,"match","mismatch")
A12: Indonesia | B12: I_CVD_PRIMARY | C12: Primary prevention of CVD | D12: clinical | G12: htncov2_aspirational | H12: 2035 | I12: =100*(1-(SUMIFS('CVD_40q30_Age'!$M$2:$M$9361,'CVD_40q30_Age'!$A$2:$A$9361,A12,'CVD_40q30_Age'!$B$2:$B$9361,B12,'CVD_40q30_Age'!$E$2:$E$9361,G12,'CVD_40q30_Age'!$F$2:$F$9361,H12,'CVD_40q30_Age'!$G$2:$G$9361,69))/(SUMIFS('CVD_40q30_Age'!$L$2:$L$9361,'CVD_40q30_Age'!$A$2:$A$9361,A12,'CVD_40q30_Age'!$B$2:$B$9361,B12,'CVD_40q30_Age'!$E$2:$E$9361,G12,'CVD_40q30_Age'!$F$2:$F$9361,H12,'CVD_40q30_Age'!$G$2:$G$9361,30))) | J12: =SUMIFS($I$2:$I$235,$A$2:$A$235,A12,$G$2:$G$235,G12,$H$2:$H$235,H12,$B$2:$B$235,"baseline") | K12: =J12-I12 | L12: =IF(J12=0,"",100*(J12-I12)/J12) | M12: 12.952108 | N12: =IF(ABS(I12-M12)<=0.001,"match","mismatch")
A13: Indonesia | B13: I_CVD_PRIMARY | C13: Primary prevention of CVD | D13: clinical | G13: htncov2_aspirational | H13: 2036 | I13: =100*(1-(SUMIFS('CVD_40q30_Age'!$M$2:$M$9361,'CVD_40q30_Age'!$A$2:$A$9361,A13,'CVD_40q30_Age'!$B$2:$B$9361,B13,'CVD_40q30_Age'!$E$2:$E$9361,G13,'CVD_40q30_Age'!$F$2:$F$9361,H13,'CVD_40q30_Age'!$G$2:$G$9361,69))/(SUMIFS('CVD_40q30_Age'!$L$2:$L$9361,'CVD_40q30_Age'!$A$2:$A$9361,A13,'CVD_40q30_Age'!$B$2:$B$9361,B13,'CVD_40q30_Age'!$E$2:$E$9361,G13,'CVD_40q30_Age'!$F$2:$F$9361,H13,'CVD_40q30_Age'!$G$2:$G$9361,30))) | J13: =SUMIFS($I$2:$I$235,$A$2:$A$235,A13,$G$2:$G$235,G13,$H$2:$H$235,H13,$B$2:$B$235,"baseline") | K13: =J13-I13 | L13: =IF(J13=0,"",100*(J13-I13)/J13) | M13: 12.744566 | N13: =IF(ABS(I13-M13)<=0.001,"match","mismatch")
... A235: Indonesia | B235: baseline | C235: Baseline (no new intervention) | D235: baseline | G235: htncov2_aspirational | H235: 2050 | I235: =100*(1-(SUMIFS('CVD_40q30_Age'!$M$2:$M$9361,'CVD_40q30_Age'!$A$2:$A$9361,A235,'CVD_40q30_Age'!$B$2:$B$9361,B235,'CVD_40q30_Age'!$E$2:$E$9361,G235,'CVD_40q30_Age'!$F$2:$F$9361,H235,'CVD_40q30_Age'!$G$2:$G$9361,69))/(SUMIFS('CVD_40q30_Age'!$L$2:$L$9361,'CVD_40q30_Age'!$A$2:$A$9361,A235,'CVD_40q30_Age'!$B$2:$B$9361,B235,'CVD_40q30_Age'!$E$2:$E$9361,G235,'CVD_40q30_Age'!$F$2:$F$9361,H235,'CVD_40q30_Age'!$G$2:$G$9361,30))) | J235: =SUMIFS($I$2:$I$235,$A$2:$A$235,A235,$G$2:$G$235,G235,$H$2:$H$235,H235,$B$2:$B$235,"baseline") | K235: =J235-I235 | L235: =IF(J235=0,"",100*(J235-I235)/J235) | M235: 11.686287 | N235: =IF(ABS(I235-M235)<=0.001,"match","mismatch")

Sheet CVD_40q30_Age
A1: location | B1: scenario | C1: scenario_label | D1: intervention_family | E1: htn_target_scenario | F1: year | G1: age | H1: cvd_deaths | I1: population | J1: m_x | K1: q_x | L1: l_x | M1: l_x_next
A2: Indonesia | B2: I_CVD_PRIMARY | C2: Primary prevention of CVD | D2: clinical | E2: htncov2_aspirational | F2: 2025 | G2: 30 | H2: 1282.1481 | I2: 4467259 | J2: =IF(I2>0,H2/I2,0) | K2: =1-EXP(-J2) | L2: =IF(G2=30,1,M1) | M2: =L2*(1-K2)
A3: Indonesia | B3: I_CVD_PRIMARY | C3: Primary prevention of CVD | D3: clinical | E3: htncov2_aspirational | F3: 2025 | G3: 31 | H3: 1315.2391 | I3: 4410712.4 | J3: =IF(I3>0,H3/I3,0) | K3: =1-EXP(-J3) | L3: =IF(G3=30,1,M2) | M3: =L3*(1-K3)
A4: Indonesia | B4: I_CVD_PRIMARY | C4: Primary prevention of CVD | D4: clinical | E4: htncov2_aspirational | F4: 2025 | G4: 32 | H4: 1358.3687 | I4: 4358505.8 | J4: =IF(I4>0,H4/I4,0) | K4: =1-EXP(-J4) | L4: =IF(G4=30,1,M3) | M4: =L4*(1-K4)
A5: Indonesia | B5: I_CVD_PRIMARY | C5: Primary prevention of CVD | D5: clinical | E5: htncov2_aspirational | F5: 2025 | G5: 33 | H5: 1441.8419 | I5: 4398745.9 | J5: =IF(I5>0,H5/I5,0) | K5: =1-EXP(-J5) | L5: =IF(G5=30,1,M4) | M5: =L5*(1-K5)
A6: Indonesia | B6: I_CVD_PRIMARY | C6: Primary prevention of CVD | D6: clinical | E6: htncov2_aspirational | F6: 2025 | G6: 34 | H6: 1533.7871 | I6: 4419468.6 | J6: =IF(I6>0,H6/I6,0) | K6: =1-EXP(-J6) | L6: =IF(G6=30,1,M5) | M6: =L6*(1-K6)
A7: Indonesia | B7: I_CVD_PRIMARY | C7: Primary prevention of CVD | D7: clinical | E7: htncov2_aspirational | F7: 2025 | G7: 35 | H7: 3016.1069 | I7: 6509663.4 | J7: =IF(I7>0,H7/I7,0) | K7: =1-EXP(-J7) | L7: =IF(G7=30,1,M6) | M7: =L7*(1-K7)
A8: Indonesia | B8: I_CVD_PRIMARY | C8: Primary prevention of CVD | D8: clinical | E8: htncov2_aspirational | F8: 2025 | G8: 36 | H8: 2254.7093 | I8: 4383096 | J8: =IF(I8>0,H8/I8,0) | K8: =1-EXP(-J8) | L8: =IF(G8=30,1,M7) | M8: =L8*(1-K8)
A9: Indonesia | B9: I_CVD_PRIMARY | C9: Primary prevention of CVD | D9: clinical | E9: htncov2_aspirational | F9: 2025 | G9: 37 | H9: 2406.7285 | I9: 4369642.3 | J9: =IF(I9>0,H9/I9,0) | K9: =1-EXP(-J9) | L9: =IF(G9=30,1,M8) | M9: =L9*(1-K9)
A10: Indonesia | B10: I_CVD_PRIMARY | C10: Primary prevention of CVD | D10: clinical | E10: htncov2_aspirational | F10: 2025 | G10: 38 | H10: 2504.2649 | I10: 4239505.9 | J10: =IF(I10>0,H10/I10,0) | K10: =1-EXP(-J10) | L10: =IF(G10=30,1,M9) | M10: =L10*(1-K10)
A11: Indonesia | B11: I_CVD_PRIMARY | C11: Primary prevention of CVD | D11: clinical | E11: htncov2_aspirational | F11: 2025 | G11: 39 | H11: 2668.8504 | I11: 4208510.7 | J11: =IF(I11>0,H11/I11,0) | K11: =1-EXP(-J11) | L11: =IF(G11=30,1,M10) | M11: =L11*(1-K11)
A12: Indonesia | B12: I_CVD_PRIMARY | C12: Primary prevention of CVD | D12: clinical | E12: htncov2_aspirational | F12: 2025 | G12: 40 | H12: 3657.3454 | I12: 4272859.9 | J12: =IF(I12>0,H12/I12,0) | K12: =1-EXP(-J12) | L12: =IF(G12=30,1,M11) | M12: =L12*(1-K12)
A13: Indonesia | B13: I_CVD_PRIMARY | C13: Primary prevention of CVD | D13: clinical | E13: htncov2_aspirational | F13: 2025 | G13: 41 | H13: 4027.1377 | I13: 4362484.7 | J13: =IF(I13>0,H13/I13,0) | K13: =1-EXP(-J13) | L13: =IF(G13=30,1,M12) | M13: =L13*(1-K13)
... A9361: Indonesia | B9361: baseline | C9361: Baseline (no new intervention) | D9361: baseline | E9361: htncov2_aspirational | F9361: 2050 | G9361: 69 | H9361: 35334.467 | I9361: 3180308.9 | J9361: =IF(I9361>0,H9361/I9361,0) | K9361: =1-EXP(-J9361) | L9361: =IF(G9361=30,1,M9360) | M9361: =L9361*(1-K9361)

Sheet Annual_Cost
A1: scenario | B1: year | C1: intervention_id | D1: cause_code | E1: cost_record_id | F1: cost_component_key | G1: cost_join_key | H1: cost_scope | I1: population_in_need_measure | J1: population_in_need_fraction | K1: coverage_scenario | L1: coverage_baseline | M1: frequency_per_year | N1: unit_cost_usd | O1: pin_scenario | P1: pin_baseline | Q1: annual_cost_baseline | R1: annual_cost_scenario | S1: annual_cost_incremental | T1: indonesia_adjusted_flag | U1: price_year | V1: discount_factor | W1: disc_cost_baseline | X1: disc_cost_scenario | Y1: disc_cost_incremental | Z1: cov_target | AA1: cov_start_year | AB1: cov_target_year | AC1: c_age_start | AD1: c_age_stop | AE1: c_sex | AF1: r_quantity_scenario | AG1: r_quantity_baseline | AH1: shared_duplicate_count | AI1: national_population | AJ1: annual_cost_baseline_per_capita | AK1: annual_cost_scenario_per_capita | AL1: annual_cost_incremental_per_capita | AM1: disc_cost_incremental_per_capita
A2: I_CVD_PRIMARY | B2: 2025 | C2: I_CVD_PRIMARY | E2: COST_PRIMARY_SCREEN_B | F2: CC_PRIMARY_SCREENING | G2: I_CVD_PRIMARY__C_SHARED | H2: shared-count-once | I2: all | J2: =IFERROR(INDEX('Cost_Components'!$K$2:$K$28,MATCH(E2,'Cost_Components'!$A$2:$A$28,0)),"") | K2: =IF(OR(L2="",Z2="",AA2="",AB2=""),"",IF(B2<AA2,L2,IF(B2>AB2,Z2,L2+(Z2-L2)*MIN(MAX((B2-AA2+1)/MAX(AB2-AA2+1,1),0),1)))) | L2: =IFERROR(INDEX('Cost_Components'!$S$2:$S$28,MATCH(E2,'Cost_Components'!$A$2:$A$28,0)),"") | M2: =IFERROR(INDEX('Cost_Components'!$L$2:$L$28,MATCH(E2,'Cost_Components'!$A$2:$A$28,0)),"") | N2: =IFERROR(INDEX('Cost_Components'!$P$2:$P$28,MATCH(E2,'Cost_Components'!$A$2:$A$28,0)),"") | O2: =AF2*J2 | P2: =AG2*J2 | Q2: =P2*L2*M2*N2 | R2: =O2*K2*M2*N2 | S2: =R2-Q2 | T2: =IFERROR(INDEX('Cost_Components'!$R$2:$R$28,MATCH(E2,'Cost_Components'!$A$2:$A$28,0)),"") | U2: =IFERROR(INDEX('Cost_Components'!$Q$2:$Q$28,MATCH(E2,'Cost_Components'!$A$2:$A$28,0)),"") | V2: =1/(1+'Calculation_Assumptions'!$B$5)^(B2-'Calculation_Assumptions'!$B$2) | W2: =Q2*V2 | X2: =R2*V2 | Y2: =S2*V2 | Z2: =IFERROR(INDEX('Cost_Components'!$T$2:$T$28,MATCH(E2,'Cost_Components'!$A$2:$A$28,0)),"") | AA2: =IFERROR(INDEX('Cost_Components'!$U$2:$U$28,MATCH(E2,'Cost_Components'!$A$2:$A$28,0)),"") | AB2: =IFERROR(INDEX('Cost_Components'!$V$2:$V$28,MATCH(E2,'Cost_Components'!$A$2:$A$28,0)),"") | AC2: =IFERROR(INDEX('Cost_Components'!$M$2:$M$28,MATCH(E2,'Cost_Components'!$A$2:$A$28,0)),"") | AD2: =IFERROR(INDEX('Cost_Components'!$N$2:$N$28,MATCH(E2,'Cost_Components'!$A$2:$A$28,0)),"") | AE2: =IFERROR(INDEX('Cost_Components'!$O$2:$O$28,MATCH(E2,'Cost_Components'!$A$2:$A$28,0)),"") | AF2: 1.5509319e+08 | AG2: 1.5509319e+08 | AH2: =IF(H2="shared-count-once",COUNTIFS($A$2:$A$1405,A2,$B$2:$B$1405,B2,$E$2:$E$1405,E2),1) | AI2: 2.8839191e+08 | AJ2: =IF(AI2=0,"",Q2/AI2) | AK2: =IF(AI2=0,"",R2/AI2) | AL2: =IF(AI2=0,"",S2/AI2) | AM2: =IF(AI2=0,"",Y2/AI2)
A3: I_CVD_PRIMARY | B3: 2026 | C3: I_CVD_PRIMARY | E3: COST_PRIMARY_SCREEN_B | F3: CC_PRIMARY_SCREENING | G3: I_CVD_PRIMARY__C_SHARED | H3: shared-count-once | I3: all | J3: =IFERROR(INDEX('Cost_Components'!$K$2:$K$28,MATCH(E3,'Cost_Components'!$A$2:$A$28,0)),"") | K3: =IF(OR(L3="",Z3="",AA3="",AB3=""),"",IF(B3<AA3,L3,IF(B3>AB3,Z3,L3+(Z3-L3)*MIN(MAX((B3-AA3+1)/MAX(AB3-AA3+1,1),0),1)))) | L3: =IFERROR(INDEX('Cost_Components'!$S$2:$S$28,MATCH(E3,'Cost_Components'!$A$2:$A$28,0)),"") | M3: =IFERROR(INDEX('Cost_Components'!$L$2:$L$28,MATCH(E3,'Cost_Components'!$A$2:$A$28,0)),"") | N3: =IFERROR(INDEX('Cost_Components'!$P$2:$P$28,MATCH(E3,'Cost_Components'!$A$2:$A$28,0)),"") | O3: =AF3*J3 | P3: =AG3*J3 | Q3: =P3*L3*M3*N3 | R3: =O3*K3*M3*N3 | S3: =R3-Q3 | T3: =IFERROR(INDEX('Cost_Components'!$R$2:$R$28,MATCH(E3,'Cost_Components'!$A$2:$A$28,0)),"") | U3: =IFERROR(INDEX('Cost_Components'!$Q$2:$Q$28,MATCH(E3,'Cost_Components'!$A$2:$A$28,0)),"") | V3: =1/(1+'Calculation_Assumptions'!$B$5)^(B3-'Calculation_Assumptions'!$B$2) | W3: =Q3*V3 | X3: =R3*V3 | Y3: =S3*V3 | Z3: =IFERROR(INDEX('Cost_Components'!$T$2:$T$28,MATCH(E3,'Cost_Components'!$A$2:$A$28,0)),"") | AA3: =IFERROR(INDEX('Cost_Components'!$U$2:$U$28,MATCH(E3,'Cost_Components'!$A$2:$A$28,0)),"") | AB3: =IFERROR(INDEX('Cost_Components'!$V$2:$V$28,MATCH(E3,'Cost_Components'!$A$2:$A$28,0)),"") | AC3: =IFERROR(INDEX('Cost_Components'!$M$2:$M$28,MATCH(E3,'Cost_Components'!$A$2:$A$28,0)),"") | AD3: =IFERROR(INDEX('Cost_Components'!$N$2:$N$28,MATCH(E3,'Cost_Components'!$A$2:$A$28,0)),"") | AE3: =IFERROR(INDEX('Cost_Components'!$O$2:$O$28,MATCH(E3,'Cost_Components'!$A$2:$A$28,0)),"") | AF3: 1.5750383e+08 | AG3: 1.5750383e+08 | AH3: =IF(H3="shared-count-once",COUNTIFS($A$2:$A$1405,A3,$B$2:$B$1405,B3,$E$2:$E$1405,E3),1) | AI3: 2.9047213e+08 | AJ3: =IF(AI3=0,"",Q3/AI3) | AK3: =IF(AI3=0,"",R3/AI3) | AL3: =IF(AI3=0,"",S3/AI3) | AM3: =IF(AI3=0,"",Y3/AI3)
A4: I_CVD_PRIMARY | B4: 2027 | C4: I_CVD_PRIMARY | E4: COST_PRIMARY_SCREEN_B | F4: CC_PRIMARY_SCREENING | G4: I_CVD_PRIMARY__C_SHARED | H4: shared-count-once | I4: all | J4: =IFERROR(INDEX('Cost_Components'!$K$2:$K$28,MATCH(E4,'Cost_Components'!$A$2:$A$28,0)),"") | K4: =IF(OR(L4="",Z4="",AA4="",AB4=""),"",IF(B4<AA4,L4,IF(B4>AB4,Z4,L4+(Z4-L4)*MIN(MAX((B4-AA4+1)/MAX(AB4-AA4+1,1),0),1)))) | L4: =IFERROR(INDEX('Cost_Components'!$S$2:$S$28,MATCH(E4,'Cost_Components'!$A$2:$A$28,0)),"") | M4: =IFERROR(INDEX('Cost_Components'!$L$2:$L$28,MATCH(E4,'Cost_Components'!$A$2:$A$28,0)),"") | N4: =IFERROR(INDEX('Cost_Components'!$P$2:$P$28,MATCH(E4,'Cost_Components'!$A$2:$A$28,0)),"") | O4: =AF4*J4 | P4: =AG4*J4 | Q4: =P4*L4*M4*N4 | R4: =O4*K4*M4*N4 | S4: =R4-Q4 | T4: =IFERROR(INDEX('Cost_Components'!$R$2:$R$28,MATCH(E4,'Cost_Components'!$A$2:$A$28,0)),"") | U4: =IFERROR(INDEX('Cost_Components'!$Q$2:$Q$28,MATCH(E4,'Cost_Components'!$A$2:$A$28,0)),"") | V4: =1/(1+'Calculation_Assumptions'!$B$5)^(B4-'Calculation_Assumptions'!$B$2) | W4: =Q4*V4 | X4: =R4*V4 | Y4: =S4*V4 | Z4: =IFERROR(INDEX('Cost_Components'!$T$2:$T$28,MATCH(E4,'Cost_Components'!$A$2:$A$28,0)),"") | AA4: =IFERROR(INDEX('Cost_Components'!$U$2:$U$28,MATCH(E4,'Cost_Components'!$A$2:$A$28,0)),"") | AB4: =IFERROR(INDEX('Cost_Components'!$V$2:$V$28,MATCH(E4,'Cost_Components'!$A$2:$A$28,0)),"") | AC4: =IFERROR(INDEX('Cost_Components'!$M$2:$M$28,MATCH(E4,'Cost_Components'!$A$2:$A$28,0)),"") | AD4: =IFERROR(INDEX('Cost_Components'!$N$2:$N$28,MATCH(E4,'Cost_Components'!$A$2:$A$28,0)),"") | AE4: =IFERROR(INDEX('Cost_Components'!$O$2:$O$28,MATCH(E4,'Cost_Components'!$A$2:$A$28,0)),"") | AF4: 1.5995862e+08 | AG4: 1.5995711e+08 | AH4: =IF(H4="shared-count-once",COUNTIFS($A$2:$A$1405,A4,$B$2:$B$1405,B4,$E$2:$E$1405,E4),1) | AI4: 2.9250508e+08 | AJ4: =IF(AI4=0,"",Q4/AI4) | AK4: =IF(AI4=0,"",R4/AI4) | AL4: =IF(AI4=0,"",S4/AI4) | AM4: =IF(AI4=0,"",Y4/AI4)
A5: I_CVD_PRIMARY | B5: 2028 | C5: I_CVD_PRIMARY | E5: COST_PRIMARY_SCREEN_B | F5: CC_PRIMARY_SCREENING | G5: I_CVD_PRIMARY__C_SHARED | H5: shared-count-once | I5: all | J5: =IFERROR(INDEX('Cost_Components'!$K$2:$K$28,MATCH(E5,'Cost_Components'!$A$2:$A$28,0)),"") | K5: =IF(OR(L5="",Z5="",AA5="",AB5=""),"",IF(B5<AA5,L5,IF(B5>AB5,Z5,L5+(Z5-L5)*MIN(MAX((B5-AA5+1)/MAX(AB5-AA5+1,1),0),1)))) | L5: =IFERROR(INDEX('Cost_Components'!$S$2:$S$28,MATCH(E5,'Cost_Components'!$A$2:$A$28,0)),"") | M5: =IFERROR(INDEX('Cost_Components'!$L$2:$L$28,MATCH(E5,'Cost_Components'!$A$2:$A$28,0)),"") | N5: =IFERROR(INDEX('Cost_Components'!$P$2:$P$28,MATCH(E5,'Cost_Components'!$A$2:$A$28,0)),"") | O5: =AF5*J5 | P5: =AG5*J5 | Q5: =P5*L5*M5*N5 | R5: =O5*K5*M5*N5 | S5: =R5-Q5 | T5: =IFERROR(INDEX('Cost_Components'!$R$2:$R$28,MATCH(E5,'Cost_Components'!$A$2:$A$28,0)),"") | U5: =IFERROR(INDEX('Cost_Components'!$Q$2:$Q$28,MATCH(E5,'Cost_Components'!$A$2:$A$28,0)),"") | V5: =1/(1+'Calculation_Assumptions'!$B$5)^(B5-'Calculation_Assumptions'!$B$2) | W5: =Q5*V5 | X5: =R5*V5 | Y5: =S5*V5 | Z5: =IFERROR(INDEX('Cost_Components'!$T$2:$T$28,MATCH(E5,'Cost_Components'!$A$2:$A$28,0)),"") | AA5: =IFERROR(INDEX('Cost_Components'!$U$2:$U$28,MATCH(E5,'Cost_Components'!$A$2:$A$28,0)),"") | AB5: =IFERROR(INDEX('Cost_Components'!$V$2:$V$28,MATCH(E5,'Cost_Components'!$A$2:$A$28,0)),"") | AC5: =IFERROR(INDEX('Cost_Components'!$M$2:$M$28,MATCH(E5,'Cost_Components'!$A$2:$A$28,0)),"") | AD5: =IFERROR(INDEX('Cost_Components'!$N$2:$N$28,MATCH(E5,'Cost_Components'!$A$2:$A$28,0)),"") | AE5: =IFERROR(INDEX('Cost_Components'!$O$2:$O$28,MATCH(E5,'Cost_Components'!$A$2:$A$28,0)),"") | AF5: 1.6220978e+08 | AG5: 1.6220434e+08 | AH5: =IF(H5="shared-count-once",COUNTIFS($A$2:$A$1405,A5,$B$2:$B$1405,B5,$E$2:$E$1405,E5),1) | AI5: 2.9448471e+08 | AJ5: =IF(AI5=0,"",Q5/AI5) | AK5: =IF(AI5=0,"",R5/AI5) | AL5: =IF(AI5=0,"",S5/AI5) | AM5: =IF(AI5=0,"",Y5/AI5)
A6: I_CVD_PRIMARY | B6: 2029 | C6: I_CVD_PRIMARY | E6: COST_PRIMARY_SCREEN_B | F6: CC_PRIMARY_SCREENING | G6: I_CVD_PRIMARY__C_SHARED | H6: shared-count-once | I6: all | J6: =IFERROR(INDEX('Cost_Components'!$K$2:$K$28,MATCH(E6,'Cost_Components'!$A$2:$A$28,0)),"") | K6: =IF(OR(L6="",Z6="",AA6="",AB6=""),"",IF(B6<AA6,L6,IF(B6>AB6,Z6,L6+(Z6-L6)*MIN(MAX((B6-AA6+1)/MAX(AB6-AA6+1,1),0),1)))) | L6: =IFERROR(INDEX('Cost_Components'!$S$2:$S$28,MATCH(E6,'Cost_Components'!$A$2:$A$28,0)),"") | M6: =IFERROR(INDEX('Cost_Components'!$L$2:$L$28,MATCH(E6,'Cost_Components'!$A$2:$A$28,0)),"") | N6: =IFERROR(INDEX('Cost_Components'!$P$2:$P$28,MATCH(E6,'Cost_Components'!$A$2:$A$28,0)),"") | O6: =AF6*J6 | P6: =AG6*J6 | Q6: =P6*L6*M6*N6 | R6: =O6*K6*M6*N6 | S6: =R6-Q6 | T6: =IFERROR(INDEX('Cost_Components'!$R$2:$R$28,MATCH(E6,'Cost_Components'!$A$2:$A$28,0)),"") | U6: =IFERROR(INDEX('Cost_Components'!$Q$2:$Q$28,MATCH(E6,'Cost_Components'!$A$2:$A$28,0)),"") | V6: =1/(1+'Calculation_Assumptions'!$B$5)^(B6-'Calculation_Assumptions'!$B$2) | W6: =Q6*V6 | X6: =R6*V6 | Y6: =S6*V6 | Z6: =IFERROR(INDEX('Cost_Components'!$T$2:$T$28,MATCH(E6,'Cost_Components'!$A$2:$A$28,0)),"") | AA6: =IFERROR(INDEX('Cost_Components'!$U$2:$U$28,MATCH(E6,'Cost_Components'!$A$2:$A$28,0)),"") | AB6: =IFERROR(INDEX('Cost_Components'!$V$2:$V$28,MATCH(E6,'Cost_Components'!$A$2:$A$28,0)),"") | AC6: =IFERROR(INDEX('Cost_Components'!$M$2:$M$28,MATCH(E6,'Cost_Components'!$A$2:$A$28,0)),"") | AD6: =IFERROR(INDEX('Cost_Components'!$N$2:$N$28,MATCH(E6,'Cost_Components'!$A$2:$A$28,0)),"") | AE6: =IFERROR(INDEX('Cost_Components'!$O$2:$O$28,MATCH(E6,'Cost_Components'!$A$2:$A$28,0)),"") | AF6: 1.6436709e+08 | AG6: 1.6435451e+08 | AH6: =IF(H6="shared-count-once",COUNTIFS($A$2:$A$1405,A6,$B$2:$B$1405,B6,$E$2:$E$1405,E6),1) | AI6: 2.9641403e+08 | AJ6: =IF(AI6=0,"",Q6/AI6) | AK6: =IF(AI6=0,"",R6/AI6) | AL6: =IF(AI6=0,"",S6/AI6) | AM6: =IF(AI6=0,"",Y6/AI6)
A7: I_CVD_PRIMARY | B7: 2030 | C7: I_CVD_PRIMARY | E7: COST_PRIMARY_SCREEN_B | F7: CC_PRIMARY_SCREENING | G7: I_CVD_PRIMARY__C_SHARED | H7: shared-count-once | I7: all | J7: =IFERROR(INDEX('Cost_Components'!$K$2:$K$28,MATCH(E7,'Cost_Components'!$A$2:$A$28,0)),"") | K7: =IF(OR(L7="",Z7="",AA7="",AB7=""),"",IF(B7<AA7,L7,IF(B7>AB7,Z7,L7+(Z7-L7)*MIN(MAX((B7-AA7+1)/MAX(AB7-AA7+1,1),0),1)))) | L7: =IFERROR(INDEX('Cost_Components'!$S$2:$S$28,MATCH(E7,'Cost_Components'!$A$2:$A$28,0)),"") | M7: =IFERROR(INDEX('Cost_Components'!$L$2:$L$28,MATCH(E7,'Cost_Components'!$A$2:$A$28,0)),"") | N7: =IFERROR(INDEX('Cost_Components'!$P$2:$P$28,MATCH(E7,'Cost_Components'!$A$2:$A$28,0)),"") | O7: =AF7*J7 | P7: =AG7*J7 | Q7: =P7*L7*M7*N7 | R7: =O7*K7*M7*N7 | S7: =R7-Q7 | T7: =IFERROR(INDEX('Cost_Components'!$R$2:$R$28,MATCH(E7,'Cost_Components'!$A$2:$A$28,0)),"") | U7: =IFERROR(INDEX('Cost_Components'!$Q$2:$Q$28,MATCH(E7,'Cost_Components'!$A$2:$A$28,0)),"") | V7: =1/(1+'Calculation_Assumptions'!$B$5)^(B7-'Calculation_Assumptions'!$B$2) | W7: =Q7*V7 | X7: =R7*V7 | Y7: =S7*V7 | Z7: =IFERROR(INDEX('Cost_Components'!$T$2:$T$28,MATCH(E7,'Cost_Components'!$A$2:$A$28,0)),"") | AA7: =IFERROR(INDEX('Cost_Components'!$U$2:$U$28,MATCH(E7,'Cost_Components'!$A$2:$A$28,0)),"") | AB7: =IFERROR(INDEX('Cost_Components'!$V$2:$V$28,MATCH(E7,'Cost_Components'!$A$2:$A$28,0)),"") | AC7: =IFERROR(INDEX('Cost_Components'!$M$2:$M$28,MATCH(E7,'Cost_Components'!$A$2:$A$28,0)),"") | AD7: =IFERROR(INDEX('Cost_Components'!$N$2:$N$28,MATCH(E7,'Cost_Components'!$A$2:$A$28,0)),"") | AE7: =IFERROR(INDEX('Cost_Components'!$O$2:$O$28,MATCH(E7,'Cost_Components'!$A$2:$A$28,0)),"") | AF7: 1.6643914e+08 | AG7: 1.6641555e+08 | AH7: =IF(H7="shared-count-once",COUNTIFS($A$2:$A$1405,A7,$B$2:$B$1405,B7,$E$2:$E$1405,E7),1) | AI7: 2.982894e+08 | AJ7: =IF(AI7=0,"",Q7/AI7) | AK7: =IF(AI7=0,"",R7/AI7) | AL7: =IF(AI7=0,"",S7/AI7) | AM7: =IF(AI7=0,"",Y7/AI7)
