Workbook

Sheet Summary
A1: scenario | B1: scenario_label | C1: intervention_family | D1: scenario_level | E1: n_interventions | F1: analysis_start_year | G1: analysis_end_year | H1: cases_averted | I1: deaths_averted | J1: ylls_averted | K1: ylds_averted | L1: dalys_averted | M1: life_years_gained | N1: cvd_40q30_start_pct | O1: cvd_40q30_end_pct | P1: cvd_40q30_abs_reduction_pp_end | Q1: cvd_40q30_pct_reduction_end | R1: incremental_cost | S1: disc_incremental_cost | T1: cost_per_death_averted | U1: cost_per_daly_averted | V1: pv_benefits | W1: pv_costs | X1: pv_net_benefit | Y1: benefit_cost_ratio
A2: baseline | B2: Baseline (no new intervention) | C2: baseline | D2: baseline | E2: 0 | F2: ='Calculation_Assumptions'!$B$2 | G2: ='Calculation_Assumptions'!$B$3 | H2: =SUMIFS('Health_Outcomes'!$I$2:$I$235,'Health_Outcomes'!$A$2:$A$235,A2) | I2: =SUMIFS('Health_Outcomes'!$F$2:$F$235,'Health_Outcomes'!$A$2:$A$235,A2) | J2: =SUMIFS('Health_Outcomes'!$L$2:$L$235,'Health_Outcomes'!$A$2:$A$235,A2) | K2: =SUMIFS('Health_Outcomes'!$O$2:$O$235,'Health_Outcomes'!$A$2:$A$235,A2) | L2: =SUMIFS('Health_Outcomes'!$R$2:$R$235,'Health_Outcomes'!$A$2:$A$235,A2) | M2: =SUMIFS('Health_Outcomes'!$S$2:$S$235,'Health_Outcomes'!$A$2:$A$235,A2) | N2: =SUMIFS('CVD_40q30'!$I$2:$I$261,'CVD_40q30'!$B$2:$B$261,A2,'CVD_40q30'!$H$2:$H$261,F2) | O2: =SUMIFS('CVD_40q30'!$I$2:$I$261,'CVD_40q30'!$B$2:$B$261,A2,'CVD_40q30'!$H$2:$H$261,G2) | P2: =SUMIFS('CVD_40q30'!$K$2:$K$261,'CVD_40q30'!$B$2:$B$261,A2,'CVD_40q30'!$H$2:$H$261,G2) | Q2: =SUMIFS('CVD_40q30'!$L$2:$L$261,'CVD_40q30'!$B$2:$B$261,A2,'CVD_40q30'!$H$2:$H$261,G2) | R2: =SUMIFS('Budget_Impact'!$E$2:$E$235,'Budget_Impact'!$A$2:$A$235,A2) | S2: =SUMIFS('Budget_Impact'!$F$2:$F$235,'Budget_Impact'!$A$2:$A$235,A2) | T2: =IF(I2>0,S2/I2,"") | U2: =IF(L2>0,S2/L2,"") | V2: =SUMIFS('Benefit_Cost'!$G$2:$G$37,'Benefit_Cost'!$A$2:$A$37,A2,'Benefit_Cost'!$F$2:$F$37,"preferred (elasticity 1.5, 20x floor)") | W2: =SUMIFS('Benefit_Cost'!$H$2:$H$37,'Benefit_Cost'!$A$2:$A$37,A2,'Benefit_Cost'!$F$2:$F$37,"preferred (elasticity 1.5, 20x floor)") | X2: =V2-W2 | Y2: =IF(W2>0,V2/W2,"")
A3: S_70_30_30_TO_70_70_70 | B3: 70-30-30 -> 70-70-70 hypertension/cholesterol + diabetes cascade | C3: cascade_70_30_30_to_70_70_70 | D3: combined | E3: 2 | F3: ='Calculation_Assumptions'!$B$2 | G3: ='Calculation_Assumptions'!$B$3 | H3: =SUMIFS('Health_Outcomes'!$I$2:$I$235,'Health_Outcomes'!$A$2:$A$235,A3) | I3: =SUMIFS('Health_Outcomes'!$F$2:$F$235,'Health_Outcomes'!$A$2:$A$235,A3) | J3: =SUMIFS('Health_Outcomes'!$L$2:$L$235,'Health_Outcomes'!$A$2:$A$235,A3) | K3: =SUMIFS('Health_Outcomes'!$O$2:$O$235,'Health_Outcomes'!$A$2:$A$235,A3) | L3: =SUMIFS('Health_Outcomes'!$R$2:$R$235,'Health_Outcomes'!$A$2:$A$235,A3) | M3: =SUMIFS('Health_Outcomes'!$S$2:$S$235,'Health_Outcomes'!$A$2:$A$235,A3) | N3: =SUMIFS('CVD_40q30'!$I$2:$I$261,'CVD_40q30'!$B$2:$B$261,A3,'CVD_40q30'!$H$2:$H$261,F3) | O3: =SUMIFS('CVD_40q30'!$I$2:$I$261,'CVD_40q30'!$B$2:$B$261,A3,'CVD_40q30'!$H$2:$H$261,G3) | P3: =SUMIFS('CVD_40q30'!$K$2:$K$261,'CVD_40q30'!$B$2:$B$261,A3,'CVD_40q30'!$H$2:$H$261,G3) | Q3: =SUMIFS('CVD_40q30'!$L$2:$L$261,'CVD_40q30'!$B$2:$B$261,A3,'CVD_40q30'!$H$2:$H$261,G3) | R3: =SUMIFS('Budget_Impact'!$E$2:$E$235,'Budget_Impact'!$A$2:$A$235,A3) | S3: =SUMIFS('Budget_Impact'!$F$2:$F$235,'Budget_Impact'!$A$2:$A$235,A3) | T3: =IF(I3>0,S3/I3,"") | U3: =IF(L3>0,S3/L3,"") | V3: =SUMIFS('Benefit_Cost'!$G$2:$G$37,'Benefit_Cost'!$A$2:$A$37,A3,'Benefit_Cost'!$F$2:$F$37,"preferred (elasticity 1.5, 20x floor)") | W3: =SUMIFS('Benefit_Cost'!$H$2:$H$37,'Benefit_Cost'!$A$2:$A$37,A3,'Benefit_Cost'!$F$2:$F$37,"preferred (elasticity 1.5, 20x floor)") | X3: =V3-W3 | Y3: =IF(W3>0,V3/W3,"")
A4: I_PH_TOBACCO_TAX | B4: Tobacco tax | C4: public_health | D4: standalone | E4: 1 | F4: ='Calculation_Assumptions'!$B$2 | G4: ='Calculation_Assumptions'!$B$3 | H4: =SUMIFS('Health_Outcomes'!$I$2:$I$235,'Health_Outcomes'!$A$2:$A$235,A4) | I4: =SUMIFS('Health_Outcomes'!$F$2:$F$235,'Health_Outcomes'!$A$2:$A$235,A4) | J4: =SUMIFS('Health_Outcomes'!$L$2:$L$235,'Health_Outcomes'!$A$2:$A$235,A4) | K4: =SUMIFS('Health_Outcomes'!$O$2:$O$235,'Health_Outcomes'!$A$2:$A$235,A4) | L4: =SUMIFS('Health_Outcomes'!$R$2:$R$235,'Health_Outcomes'!$A$2:$A$235,A4) | M4: =SUMIFS('Health_Outcomes'!$S$2:$S$235,'Health_Outcomes'!$A$2:$A$235,A4) | N4: =SUMIFS('CVD_40q30'!$I$2:$I$261,'CVD_40q30'!$B$2:$B$261,A4,'CVD_40q30'!$H$2:$H$261,F4) | O4: =SUMIFS('CVD_40q30'!$I$2:$I$261,'CVD_40q30'!$B$2:$B$261,A4,'CVD_40q30'!$H$2:$H$261,G4) | P4: =SUMIFS('CVD_40q30'!$K$2:$K$261,'CVD_40q30'!$B$2:$B$261,A4,'CVD_40q30'!$H$2:$H$261,G4) | Q4: =SUMIFS('CVD_40q30'!$L$2:$L$261,'CVD_40q30'!$B$2:$B$261,A4,'CVD_40q30'!$H$2:$H$261,G4) | R4: =SUMIFS('Budget_Impact'!$E$2:$E$235,'Budget_Impact'!$A$2:$A$235,A4) | S4: =SUMIFS('Budget_Impact'!$F$2:$F$235,'Budget_Impact'!$A$2:$A$235,A4) | T4: =IF(I4>0,S4/I4,"") | U4: =IF(L4>0,S4/L4,"") | V4: =SUMIFS('Benefit_Cost'!$G$2:$G$37,'Benefit_Cost'!$A$2:$A$37,A4,'Benefit_Cost'!$F$2:$F$37,"preferred (elasticity 1.5, 20x floor)") | W4: =SUMIFS('Benefit_Cost'!$H$2:$H$37,'Benefit_Cost'!$A$2:$A$37,A4,'Benefit_Cost'!$F$2:$F$37,"preferred (elasticity 1.5, 20x floor)") | X4: =V4-W4 | Y4: =IF(W4>0,V4/W4,"")
A5: I_PH_TOB_CLEAN_AIR | B5: Smoke-free / clean-air law | C5: public_health | D5: standalone | E5: 1 | F5: ='Calculation_Assumptions'!$B$2 | G5: ='Calculation_Assumptions'!$B$3 | H5: =SUMIFS('Health_Outcomes'!$I$2:$I$235,'Health_Outcomes'!$A$2:$A$235,A5) | I5: =SUMIFS('Health_Outcomes'!$F$2:$F$235,'Health_Outcomes'!$A$2:$A$235,A5) | J5: =SUMIFS('Health_Outcomes'!$L$2:$L$235,'Health_Outcomes'!$A$2:$A$235,A5) | K5: =SUMIFS('Health_Outcomes'!$O$2:$O$235,'Health_Outcomes'!$A$2:$A$235,A5) | L5: =SUMIFS('Health_Outcomes'!$R$2:$R$235,'Health_Outcomes'!$A$2:$A$235,A5) | M5: =SUMIFS('Health_Outcomes'!$S$2:$S$235,'Health_Outcomes'!$A$2:$A$235,A5) | N5: =SUMIFS('CVD_40q30'!$I$2:$I$261,'CVD_40q30'!$B$2:$B$261,A5,'CVD_40q30'!$H$2:$H$261,F5) | O5: =SUMIFS('CVD_40q30'!$I$2:$I$261,'CVD_40q30'!$B$2:$B$261,A5,'CVD_40q30'!$H$2:$H$261,G5) | P5: =SUMIFS('CVD_40q30'!$K$2:$K$261,'CVD_40q30'!$B$2:$B$261,A5,'CVD_40q30'!$H$2:$H$261,G5) | Q5: =SUMIFS('CVD_40q30'!$L$2:$L$261,'CVD_40q30'!$B$2:$B$261,A5,'CVD_40q30'!$H$2:$H$261,G5) | R5: =SUMIFS('Budget_Impact'!$E$2:$E$235,'Budget_Impact'!$A$2:$A$235,A5) | S5: =SUMIFS('Budget_Impact'!$F$2:$F$235,'Budget_Impact'!$A$2:$A$235,A5) | T5: =IF(I5>0,S5/I5,"") | U5: =IF(L5>0,S5/L5,"") | V5: =SUMIFS('Benefit_Cost'!$G$2:$G$37,'Benefit_Cost'!$A$2:$A$37,A5,'Benefit_Cost'!$F$2:$F$37,"preferred (elasticity 1.5, 20x floor)") | W5: =SUMIFS('Benefit_Cost'!$H$2:$H$37,'Benefit_Cost'!$A$2:$A$37,A5,'Benefit_Cost'!$F$2:$F$37,"preferred (elasticity 1.5, 20x floor)") | X5: =V5-W5 | Y5: =IF(W5>0,V5/W5,"")
A6: I_PH_TOB_MEDIA | B6: Tobacco mass-media campaign | C6: public_health | D6: standalone | E6: 1 | F6: ='Calculation_Assumptions'!$B$2 | G6: ='Calculation_Assumptions'!$B$3 | H6: =SUMIFS('Health_Outcomes'!$I$2:$I$235,'Health_Outcomes'!$A$2:$A$235,A6) | I6: =SUMIFS('Health_Outcomes'!$F$2:$F$235,'Health_Outcomes'!$A$2:$A$235,A6) | J6: =SUMIFS('Health_Outcomes'!$L$2:$L$235,'Health_Outcomes'!$A$2:$A$235,A6) | K6: =SUMIFS('Health_Outcomes'!$O$2:$O$235,'Health_Outcomes'!$A$2:$A$235,A6) | L6: =SUMIFS('Health_Outcomes'!$R$2:$R$235,'Health_Outcomes'!$A$2:$A$235,A6) | M6: =SUMIFS('Health_Outcomes'!$S$2:$S$235,'Health_Outcomes'!$A$2:$A$235,A6) | N6: =SUMIFS('CVD_40q30'!$I$2:$I$261,'CVD_40q30'!$B$2:$B$261,A6,'CVD_40q30'!$H$2:$H$261,F6) | O6: =SUMIFS('CVD_40q30'!$I$2:$I$261,'CVD_40q30'!$B$2:$B$261,A6,'CVD_40q30'!$H$2:$H$261,G6) | P6: =SUMIFS('CVD_40q30'!$K$2:$K$261,'CVD_40q30'!$B$2:$B$261,A6,'CVD_40q30'!$H$2:$H$261,G6) | Q6: =SUMIFS('CVD_40q30'!$L$2:$L$261,'CVD_40q30'!$B$2:$B$261,A6,'CVD_40q30'!$H$2:$H$261,G6) | R6: =SUMIFS('Budget_Impact'!$E$2:$E$235,'Budget_Impact'!$A$2:$A$235,A6) | S6: =SUMIFS('Budget_Impact'!$F$2:$F$235,'Budget_Impact'!$A$2:$A$235,A6) | T6: =IF(I6>0,S6/I6,"") | U6: =IF(L6>0,S6/L6,"") | V6: =SUMIFS('Benefit_Cost'!$G$2:$G$37,'Benefit_Cost'!$A$2:$A$37,A6,'Benefit_Cost'!$F$2:$F$37,"preferred (elasticity 1.5, 20x floor)") | W6: =SUMIFS('Benefit_Cost'!$H$2:$H$37,'Benefit_Cost'!$A$2:$A$37,A6,'Benefit_Cost'!$F$2:$F$37,"preferred (elasticity 1.5, 20x floor)") | X6: =V6-W6 | Y6: =IF(W6>0,V6/W6,"")
A7: I_PH_TOB_AD_BAN | B7: Tobacco advertising ban | C7: public_health | D7: standalone | E7: 1 | F7: ='Calculation_Assumptions'!$B$2 | G7: ='Calculation_Assumptions'!$B$3 | H7: =SUMIFS('Health_Outcomes'!$I$2:$I$235,'Health_Outcomes'!$A$2:$A$235,A7) | I7: =SUMIFS('Health_Outcomes'!$F$2:$F$235,'Health_Outcomes'!$A$2:$A$235,A7) | J7: =SUMIFS('Health_Outcomes'!$L$2:$L$235,'Health_Outcomes'!$A$2:$A$235,A7) | K7: =SUMIFS('Health_Outcomes'!$O$2:$O$235,'Health_Outcomes'!$A$2:$A$235,A7) | L7: =SUMIFS('Health_Outcomes'!$R$2:$R$235,'Health_Outcomes'!$A$2:$A$235,A7) | M7: =SUMIFS('Health_Outcomes'!$S$2:$S$235,'Health_Outcomes'!$A$2:$A$235,A7) | N7: =SUMIFS('CVD_40q30'!$I$2:$I$261,'CVD_40q30'!$B$2:$B$261,A7,'CVD_40q30'!$H$2:$H$261,F7) | O7: =SUMIFS('CVD_40q30'!$I$2:$I$261,'CVD_40q30'!$B$2:$B$261,A7,'CVD_40q30'!$H$2:$H$261,G7) | P7: =SUMIFS('CVD_40q30'!$K$2:$K$261,'CVD_40q30'!$B$2:$B$261,A7,'CVD_40q30'!$H$2:$H$261,G7) | Q7: =SUMIFS('CVD_40q30'!$L$2:$L$261,'CVD_40q30'!$B$2:$B$261,A7,'CVD_40q30'!$H$2:$H$261,G7) | R7: =SUMIFS('Budget_Impact'!$E$2:$E$235,'Budget_Impact'!$A$2:$A$235,A7) | S7: =SUMIFS('Budget_Impact'!$F$2:$F$235,'Budget_Impact'!$A$2:$A$235,A7) | T7: =IF(I7>0,S7/I7,"") | U7: =IF(L7>0,S7/L7,"") | V7: =SUMIFS('Benefit_Cost'!$G$2:$G$37,'Benefit_Cost'!$A$2:$A$37,A7,'Benefit_Cost'!$F$2:$F$37,"preferred (elasticity 1.5, 20x floor)") | W7: =SUMIFS('Benefit_Cost'!$H$2:$H$37,'Benefit_Cost'!$A$2:$A$37,A7,'Benefit_Cost'!$F$2:$F$37,"preferred (elasticity 1.5, 20x floor)") | X7: =V7-W7 | Y7: =IF(W7>0,V7/W7,"")
A8: I_PH_TOBACCO_POLICY | B8: Tobacco policy package | C8: public_health | D8: package | E8: 3 | F8: ='Calculation_Assumptions'!$B$2 | G8: ='Calculation_Assumptions'!$B$3 | H8: =SUMIFS('Health_Outcomes'!$I$2:$I$235,'Health_Outcomes'!$A$2:$A$235,A8) | I8: =SUMIFS('Health_Outcomes'!$F$2:$F$235,'Health_Outcomes'!$A$2:$A$235,A8) | J8: =SUMIFS('Health_Outcomes'!$L$2:$L$235,'Health_Outcomes'!$A$2:$A$235,A8) | K8: =SUMIFS('Health_Outcomes'!$O$2:$O$235,'Health_Outcomes'!$A$2:$A$235,A8) | L8: =SUMIFS('Health_Outcomes'!$R$2:$R$235,'Health_Outcomes'!$A$2:$A$235,A8) | M8: =SUMIFS('Health_Outcomes'!$S$2:$S$235,'Health_Outcomes'!$A$2:$A$235,A8) | N8: =SUMIFS('CVD_40q30'!$I$2:$I$261,'CVD_40q30'!$B$2:$B$261,A8,'CVD_40q30'!$H$2:$H$261,F8) | O8: =SUMIFS('CVD_40q30'!$I$2:$I$261,'CVD_40q30'!$B$2:$B$261,A8,'CVD_40q30'!$H$2:$H$261,G8) | P8: =SUMIFS('CVD_40q30'!$K$2:$K$261,'CVD_40q30'!$B$2:$B$261,A8,'CVD_40q30'!$H$2:$H$261,G8) | Q8: =SUMIFS('CVD_40q30'!$L$2:$L$261,'CVD_40q30'!$B$2:$B$261,A8,'CVD_40q30'!$H$2:$H$261,G8) | R8: =SUMIFS('Budget_Impact'!$E$2:$E$235,'Budget_Impact'!$A$2:$A$235,A8) | S8: =SUMIFS('Budget_Impact'!$F$2:$F$235,'Budget_Impact'!$A$2:$A$235,A8) | T8: =IF(I8>0,S8/I8,"") | U8: =IF(L8>0,S8/L8,"") | V8: =SUMIFS('Benefit_Cost'!$G$2:$G$37,'Benefit_Cost'!$A$2:$A$37,A8,'Benefit_Cost'!$F$2:$F$37,"preferred (elasticity 1.5, 20x floor)") | W8: =SUMIFS('Benefit_Cost'!$H$2:$H$37,'Benefit_Cost'!$A$2:$A$37,A8,'Benefit_Cost'!$F$2:$F$37,"preferred (elasticity 1.5, 20x floor)") | X8: =V8-W8 | Y8: =IF(W8>0,V8/W8,"")
A9: all_public_health | B9: All selected public-health interventions (combined) | C9: public_health | D9: combined | E9: 4 | F9: ='Calculation_Assumptions'!$B$2 | G9: ='Calculation_Assumptions'!$B$3 | H9: =SUMIFS('Health_Outcomes'!$I$2:$I$235,'Health_Outcomes'!$A$2:$A$235,A9) | I9: =SUMIFS('Health_Outcomes'!$F$2:$F$235,'Health_Outcomes'!$A$2:$A$235,A9) | J9: =SUMIFS('Health_Outcomes'!$L$2:$L$235,'Health_Outcomes'!$A$2:$A$235,A9) | K9: =SUMIFS('Health_Outcomes'!$O$2:$O$235,'Health_Outcomes'!$A$2:$A$235,A9) | L9: =SUMIFS('Health_Outcomes'!$R$2:$R$235,'Health_Outcomes'!$A$2:$A$235,A9) | M9: =SUMIFS('Health_Outcomes'!$S$2:$S$235,'Health_Outcomes'!$A$2:$A$235,A9) | N9: =SUMIFS('CVD_40q30'!$I$2:$I$261,'CVD_40q30'!$B$2:$B$261,A9,'CVD_40q30'!$H$2:$H$261,F9) | O9: =SUMIFS('CVD_40q30'!$I$2:$I$261,'CVD_40q30'!$B$2:$B$261,A9,'CVD_40q30'!$H$2:$H$261,G9) | P9: =SUMIFS('CVD_40q30'!$K$2:$K$261,'CVD_40q30'!$B$2:$B$261,A9,'CVD_40q30'!$H$2:$H$261,G9) | Q9: =SUMIFS('CVD_40q30'!$L$2:$L$261,'CVD_40q30'!$B$2:$B$261,A9,'CVD_40q30'!$H$2:$H$261,G9) | R9: =SUMIFS('Budget_Impact'!$E$2:$E$235,'Budget_Impact'!$A$2:$A$235,A9) | S9: =SUMIFS('Budget_Impact'!$F$2:$F$235,'Budget_Impact'!$A$2:$A$235,A9) | T9: =IF(I9>0,S9/I9,"") | U9: =IF(L9>0,S9/L9,"") | V9: =SUMIFS('Benefit_Cost'!$G$2:$G$37,'Benefit_Cost'!$A$2:$A$37,A9,'Benefit_Cost'!$F$2:$F$37,"preferred (elasticity 1.5, 20x floor)") | W9: =SUMIFS('Benefit_Cost'!$H$2:$H$37,'Benefit_Cost'!$A$2:$A$37,A9,'Benefit_Cost'!$F$2:$F$37,"preferred (elasticity 1.5, 20x floor)") | X9: =V9-W9 | Y9: =IF(W9>0,V9/W9,"")
A10: all_cascade_public_health | B10: 70-30-30 -> 70-70-70 cascade + all public-health interventions (combined) | C10: cascade_public_health | D10: combined | E10: 6 | F10: ='Calculation_Assumptions'!$B$2 | G10: ='Calculation_Assumptions'!$B$3 | H10: =SUMIFS('Health_Outcomes'!$I$2:$I$235,'Health_Outcomes'!$A$2:$A$235,A10) | I10: =SUMIFS('Health_Outcomes'!$F$2:$F$235,'Health_Outcomes'!$A$2:$A$235,A10) | J10: =SUMIFS('Health_Outcomes'!$L$2:$L$235,'Health_Outcomes'!$A$2:$A$235,A10) | K10: =SUMIFS('Health_Outcomes'!$O$2:$O$235,'Health_Outcomes'!$A$2:$A$235,A10) | L10: =SUMIFS('Health_Outcomes'!$R$2:$R$235,'Health_Outcomes'!$A$2:$A$235,A10) | M10: =SUMIFS('Health_Outcomes'!$S$2:$S$235,'Health_Outcomes'!$A$2:$A$235,A10) | N10: =SUMIFS('CVD_40q30'!$I$2:$I$261,'CVD_40q30'!$B$2:$B$261,A10,'CVD_40q30'!$H$2:$H$261,F10) | O10: =SUMIFS('CVD_40q30'!$I$2:$I$261,'CVD_40q30'!$B$2:$B$261,A10,'CVD_40q30'!$H$2:$H$261,G10) | P10: =SUMIFS('CVD_40q30'!$K$2:$K$261,'CVD_40q30'!$B$2:$B$261,A10,'CVD_40q30'!$H$2:$H$261,G10) | Q10: =SUMIFS('CVD_40q30'!$L$2:$L$261,'CVD_40q30'!$B$2:$B$261,A10,'CVD_40q30'!$H$2:$H$261,G10) | R10: =SUMIFS('Budget_Impact'!$E$2:$E$235,'Budget_Impact'!$A$2:$A$235,A10) | S10: =SUMIFS('Budget_Impact'!$F$2:$F$235,'Budget_Impact'!$A$2:$A$235,A10) | T10: =IF(I10>0,S10/I10,"") | U10: =IF(L10>0,S10/L10,"") | V10: =SUMIFS('Benefit_Cost'!$G$2:$G$37,'Benefit_Cost'!$A$2:$A$37,A10,'Benefit_Cost'!$F$2:$F$37,"preferred (elasticity 1.5, 20x floor)") | W10: =SUMIFS('Benefit_Cost'!$H$2:$H$37,'Benefit_Cost'!$A$2:$A$37,A10,'Benefit_Cost'!$F$2:$F$37,"preferred (elasticity 1.5, 20x floor)") | X10: =V10-W10 | Y10: =IF(W10>0,V10/W10,"")
A11: S_70_30_30_TO_70_70_70_I_PH_TOBACCO_TAX | B11: 70-30-30 -> 70-70-70 cascade + tobacco tax | C11: cascade_public_health | D11: combined | E11: 3 | F11: ='Calculation_Assumptions'!$B$2 | G11: ='Calculation_Assumptions'!$B$3 | H11: =SUMIFS('Health_Outcomes'!$I$2:$I$235,'Health_Outcomes'!$A$2:$A$235,A11) | I11: =SUMIFS('Health_Outcomes'!$F$2:$F$235,'Health_Outcomes'!$A$2:$A$235,A11) | J11: =SUMIFS('Health_Outcomes'!$L$2:$L$235,'Health_Outcomes'!$A$2:$A$235,A11) | K11: =SUMIFS('Health_Outcomes'!$O$2:$O$235,'Health_Outcomes'!$A$2:$A$235,A11) | L11: =SUMIFS('Health_Outcomes'!$R$2:$R$235,'Health_Outcomes'!$A$2:$A$235,A11) | M11: =SUMIFS('Health_Outcomes'!$S$2:$S$235,'Health_Outcomes'!$A$2:$A$235,A11) | N11: =SUMIFS('CVD_40q30'!$I$2:$I$261,'CVD_40q30'!$B$2:$B$261,A11,'CVD_40q30'!$H$2:$H$261,F11) | O11: =SUMIFS('CVD_40q30'!$I$2:$I$261,'CVD_40q30'!$B$2:$B$261,A11,'CVD_40q30'!$H$2:$H$261,G11) | P11: =SUMIFS('CVD_40q30'!$K$2:$K$261,'CVD_40q30'!$B$2:$B$261,A11,'CVD_40q30'!$H$2:$H$261,G11) | Q11: =SUMIFS('CVD_40q30'!$L$2:$L$261,'CVD_40q30'!$B$2:$B$261,A11,'CVD_40q30'!$H$2:$H$261,G11) | R11: =SUMIFS('Budget_Impact'!$E$2:$E$235,'Budget_Impact'!$A$2:$A$235,A11) | S11: =SUMIFS('Budget_Impact'!$F$2:$F$235,'Budget_Impact'!$A$2:$A$235,A11) | T11: =IF(I11>0,S11/I11,"") | U11: =IF(L11>0,S11/L11,"") | V11: =SUMIFS('Benefit_Cost'!$G$2:$G$37,'Benefit_Cost'!$A$2:$A$37,A11,'Benefit_Cost'!$F$2:$F$37,"preferred (elasticity 1.5, 20x floor)") | W11: =SUMIFS('Benefit_Cost'!$H$2:$H$37,'Benefit_Cost'!$A$2:$A$37,A11,'Benefit_Cost'!$F$2:$F$37,"preferred (elasticity 1.5, 20x floor)") | X11: =V11-W11 | Y11: =IF(W11>0,V11/W11,"")

Sheet README
A1: section | B1: detail
A2: Purpose | B2: Combined 70-30-30 -> 70-70-70 cascade + public-health (fiscal/regulatory) costing, budget impact, cost-effectiveness, CVD 40q30 and Reference-Case benefit-cost analysis in one workbook.
A3: Scope | B3: Baseline (once) + the 70-30-30 -> 70-70-70 cascade scenario + every public-health scenario + the genuine joint 'all_cascade_public_health' scenario. intervention_family tags each scenario baseline / cascade_70_30_30_to_70_70_70 / public_health / cascade_public_health.
A4: How to read | B4: Grey cells are R source values; light-blue cells are LIVE Excel formulas; pale-yellow cells on Calculation_Assumptions are editable controls. The joint scenario is highlighted (orange) on Summary. Calculation_Map lists the dependency chain.
A5: Scenarios | B5: See Summary and Scenario_Catalog. Family-specific input/audit sheets are prefixed CL_ (cascade clinical arm) and PH_ (public-health) where the two source schemas differ.
A6: The joint scenario | B6: 'all_cascade_public_health' is produced by a SINGLE Model 06 projection that applies the clinical (fair_wb) and public-health (ph_wb) engines once each to the same baseline-rate copy -- it is NEVER the arithmetic sum of the separate 'all' and 'all_public_health' outputs.
A7: Costing the joint scenario | B7: Joint cost = clinical components (clinical costing rule) + public-health components (per-capita policy rule), BOTH computed against the joint scenario's own Model 06 population/state. family provenance is retained on every Annual_Cost row and keys are collision-safe (family|cost_record_id). Budget_Impact carries the four *_cost_per_capita columns as LIVE formulae (= that year's cost / national_population); national_population (grey R-source) is each year's national Indonesia population from out_model/model_output_Indonesia_htncov2_aspirational.rds (baseline series, de-duplicated across cause). Annual_Cost carries the matching per-component per-capita formulae, and Cost_Effectiveness carries the scenario mean annual incremental/discounted per-capita (2026-2050).
A8: CVD 40q30 | B8: CVD_40q30 / CVD_40q30_Age give the period probability of dying from the six CVD causes between exact ages 30 and 70 (percent on a 0-100 scale). The life table (m_x, q_x, l_x, l_{x+1}) is live Excel formula; cvd_40q30 reconciles to the Model 07 R value.
A9: Benefit-cost | B9: Reference-Case VSL/VSLY benefit-cost (Robinson et al. 2019) on Health_Outcomes / Economic_Value / Benefit_Cost; PARTIAL mortality-benefit BCA.
A10: Colour legend | B10: header dark-blue; formula light-blue; R-source grey; editable-input pale-yellow; QA green/red/orange.

Sheet Run_Metadata
A1: field | B1: value
A2: workbook | B2: indonesia_model_cost_value_70_30_30_to_70_70_70_public_health_formulae.xlsx
A3: generated_by | B3: Model 09 (09_cost_value.R)
A4: clinical_workbook | B4: indonesia_70_30_30_to_70_70_70_inputs.xlsx
A5: public_health_workbook | B5: indonesia_model_inputs_public_health_updated_mortality.xlsx
A6: baseline_scenario | B6: baseline
A7: joint_scenario | B7: all_cascade_public_health
A8: n_clinical_scenarios | B8: 1
A9: n_public_health_scenarios | B9: 6
A10: analysis_years | B10: 2025-2050
A11: location | B11: Indonesia

Sheet Scenario_Catalog
A1: scenario | B1: scenario_label | C1: intervention_family | D1: scenario_level | E1: scenario_role | F1: parent_package_id | G1: intervention_ids | H1: n_interventions
A2: baseline | B2: Baseline (no new intervention) | C2: baseline | D2: baseline | H2: 0
A3: S_70_30_30_TO_70_70_70 | B3: 70-30-30 -> 70-70-70 hypertension/cholesterol + diabetes cascade | C3: cascade_70_30_30_to_70_70_70 | D3: combined | E3: combined | G3: I_CVD_PRIMARY; I_T2D_TREATMENT | H3: 2
A4: I_PH_TOBACCO_TAX | B4: Tobacco tax | C4: public_health | D4: standalone | E4: standalone | G4: I_PH_TOBACCO_TAX | H4: 1
A5: I_PH_TOB_CLEAN_AIR | B5: Smoke-free / clean-air law | C5: public_health | D5: standalone | E5: child | F5: I_PH_TOBACCO_POLICY | G5: I_PH_TOB_CLEAN_AIR | H5: 1
A6: I_PH_TOB_MEDIA | B6: Tobacco mass-media campaign | C6: public_health | D6: standalone | E6: child | F6: I_PH_TOBACCO_POLICY | G6: I_PH_TOB_MEDIA | H6: 1
A7: I_PH_TOB_AD_BAN | B7: Tobacco advertising ban | C7: public_health | D7: standalone | E7: child | F7: I_PH_TOBACCO_POLICY | G7: I_PH_TOB_AD_BAN | H7: 1
A8: I_PH_TOBACCO_POLICY | B8: Tobacco policy package | C8: public_health | D8: package | E8: package | F8: I_PH_TOBACCO_POLICY | G8: I_PH_TOB_CLEAN_AIR; I_PH_TOB_MEDIA; I_PH_TOB_AD_BAN | H8: 3
A9: all_public_health | B9: All selected public-health interventions (combined) | C9: public_health | D9: combined | E9: combined | G9: I_PH_TOBACCO_TAX; I_PH_TOB_AD_BAN; I_PH_TOB_CLEAN_AIR; I_PH_TOB_MEDIA | H9: 4
A10: all_cascade_public_health | B10: 70-30-30 -> 70-70-70 cascade + all public-health interventions (combined) | C10: cascade_public_health | D10: combined | E10: combined | G10: I_CVD_PRIMARY; I_T2D_TREATMENT; I_PH_TOBACCO_TAX; I_PH_TOB_AD_BAN; I_PH_TOB_CLEAN_AIR; I_PH_TOB_MEDIA | H10: 6
A11: S_70_30_30_TO_70_70_70_I_PH_TOBACCO_TAX | B11: 70-30-30 -> 70-70-70 cascade + tobacco tax | C11: cascade_public_health | D11: combined | E11: combined | G11: I_CVD_PRIMARY; I_T2D_TREATMENT; I_PH_TOBACCO_TAX | H11: 3

Sheet CL_Selected_Interventions
A1: intervention_id | B1: intervention_cause_key | C1: cause_code | D1: model_transition | E1: effect_value | F1: affected_fraction | G1: baseline_coverage | H1: target_coverage | I1: start_year | J1: target_year
A2: I_CVD_PRIMARY | B2: I_CVD_PRIMARY__C_HHD | C2: hhd | D2: incidence | E2: 0.47 | F2: 1 | G2: 0.14506229 | H2: 0.4165 | I2: 2025 | J2: 2040
A3: I_CVD_PRIMARY | B3: I_CVD_PRIMARY__C_ICH | C3: hstroke | D3: incidence | E3: 0.49 | F3: 0.8 | G3: 0.14506229 | H3: 0.4165 | I3: 2025 | J3: 2040
A4: I_CVD_PRIMARY | B4: I_CVD_PRIMARY__C_IHD | C4: ihd | D4: incidence | E4: 0.58 | F4: 0.8 | G4: 0.14506229 | H4: 0.4165 | I4: 2025 | J4: 2040
A5: I_CVD_PRIMARY | B5: I_CVD_PRIMARY__C_IS | C5: istroke | D5: incidence | E5: 0.54 | F5: 0.8 | G5: 0.14506229 | H5: 0.4165 | I5: 2025 | J5: 2040
A6: I_T2D_TREATMENT | B6: I_T2D_TREATMENT__C_IHD | C6: ihd | D6: case_fatality | E6: 0.15 | F6: 0.15 | G6: 0.033768828 | H6: 0.4165 | I6: 2025 | J6: 2040
A7: I_T2D_TREATMENT | B7: I_T2D_TREATMENT__C_T2D | C7: dm2 | D7: case_fatality | E7: 0.28 | F7: 1 | G7: 0.033768828 | H7: 0.4165 | I7: 2025 | J7: 2040

Sheet CL_Cost_Components
A1: cost_record_id | B1: intervention_id | C1: cause_code | D1: cost_component | E1: cost_scope | F1: population_in_need_measure | G1: population_in_need_fraction | H1: frequency_per_year | I1: unit_cost_usd | J1: cov_baseline | K1: cov_target | L1: cost_ready
A2: COST_PRIMARY_SCREEN_A | B2: I_CVD_PRIMARY | D2: CVD targeted screening | E2: shared-count-once | F2: all | G2: 0.2 | H2: 1 | I2: 1.291584 | J2: 0.14506229 | K2: 0.4165 | L2: TRUE
A3: COST_PRIMARY_TX_A | B3: I_CVD_PRIMARY | D3: Antihypertensives and statins for absolute CVD risk >20% | E3: shared-count-once | F3: all | G3: 0.06 | H3: 1 | I3: 69.3 | J3: 0.14506229 | K3: 0.4165 | L3: TRUE
A4: COST_T2D_SCREEN | B4: I_T2D_TREATMENT | C4: dm2 | D4: Diabetes opportunistic screening | E4: cause-specific | F4: all | G4: 1e-05 | H4: 1 | I4: 0.70495848 | J4: 0.033768828 | K4: 0.4165 | L4: TRUE
A5: COST_T2D_NONINSULIN | B5: I_T2D_TREATMENT | C5: dm2 | D5: Diabetes management, non insulin dependent | E5: cause-specific | F5: prevalence | G5: 0.6 | H5: 1 | I5: 82.68 | J5: 0.033768828 | K5: 0.4165 | L5: TRUE
A6: COST_T2D_INSULIN | B6: I_T2D_TREATMENT | C6: dm2 | D6: Diabetes management, insulin dependent | E6: cause-specific | F6: prevalence | G6: 0.2 | H6: 1 | I6: 82.68 | J6: 0.033768828 | K6: 0.4165 | L6: TRUE

Sheet PH_Selected_Interventions
A1: intervention_id | B1: intervention_cause_key | C1: cause_code | D1: model_transition | E1: transition_from | F1: transition_to | G1: effect_model | H1: baseline_exposure | I1: target_exposure | J1: response_value | K1: start_year | L1: target_year
A2: I_PH_TOBACCO_TAX | B2: I_PH_TOBACCO_TAX__C_ICH | C2: hstroke | D2: incidence | E2: well | F2: sick | G2: direct_smoking_prevalence_shift_rr | H2: 0.303 | I2: 0.19722936 | J2: 1.19 | K2: 2026 | L2: 2030
A3: I_PH_TOBACCO_TAX | B3: I_PH_TOBACCO_TAX__C_ICH__SICK_DEAD | C3: hstroke | D3: case_fatality | E3: sick | F3: dead | G3: tobacco_mortality_prevalence_shift_rr | H3: 0.303 | I3: 0.19722936 | J3: 3 | K3: 2026 | L3: 2030
A4: I_PH_TOBACCO_TAX | B4: I_PH_TOBACCO_TAX__C_IHD | C4: ihd | D4: incidence | E4: well | F4: sick | G4: direct_smoking_prevalence_shift_rr | H4: 0.303 | I4: 0.19722936 | J4: 1.6 | K4: 2026 | L4: 2030
A5: I_PH_TOBACCO_TAX | B5: I_PH_TOBACCO_TAX__C_IHD__SICK_DEAD | C5: ihd | D5: case_fatality | E5: sick | F5: dead | G5: tobacco_mortality_prevalence_shift_rr | H5: 0.303 | I5: 0.19722936 | J5: 3 | K5: 2026 | L5: 2030
A6: I_PH_TOBACCO_TAX | B6: I_PH_TOBACCO_TAX__C_IS | C6: istroke | D6: incidence | E6: well | F6: sick | G6: direct_smoking_prevalence_shift_rr | H6: 0.303 | I6: 0.19722936 | J6: 1.38 | K6: 2026 | L6: 2030
A7: I_PH_TOBACCO_TAX | B7: I_PH_TOBACCO_TAX__C_IS__SICK_DEAD | C7: istroke | D7: case_fatality | E7: sick | F7: dead | G7: tobacco_mortality_prevalence_shift_rr | H7: 0.303 | I7: 0.19722936 | J7: 3 | K7: 2026 | L7: 2030
A8: I_PH_TOBACCO_TAX | B8: I_PH_TOBACCO_TAX__C_T2DM | C8: dm2 | D8: incidence | E8: well | F8: sick | G8: direct_smoking_prevalence_shift_rr | H8: 0.303 | I8: 0.19722936 | J8: 1.37 | K8: 2026 | L8: 2030
A9: I_PH_TOB_AD_BAN | B9: I_PH_TOB_AD_BAN__C_ICH | C9: hstroke | D9: incidence | E9: well | F9: sick | G9: direct_smoking_prevalence_shift_rr | H9: 0.303 | I9: 0.29088 | J9: 1.19 | K9: 2026 | L9: 2030
A10: I_PH_TOB_AD_BAN | B10: I_PH_TOB_AD_BAN__C_ICH__SICK_DEAD | C10: hstroke | D10: case_fatality | E10: sick | F10: dead | G10: tobacco_mortality_prevalence_shift_rr | H10: 0.303 | I10: 0.29088 | J10: 3 | K10: 2026 | L10: 2030
A11: I_PH_TOB_AD_BAN | B11: I_PH_TOB_AD_BAN__C_IHD | C11: ihd | D11: incidence | E11: well | F11: sick | G11: direct_smoking_prevalence_shift_rr | H11: 0.303 | I11: 0.29088 | J11: 1.6 | K11: 2026 | L11: 2030
A12: I_PH_TOB_AD_BAN | B12: I_PH_TOB_AD_BAN__C_IHD__SICK_DEAD | C12: ihd | D12: case_fatality | E12: sick | F12: dead | G12: tobacco_mortality_prevalence_shift_rr | H12: 0.303 | I12: 0.29088 | J12: 3 | K12: 2026 | L12: 2030
A13: I_PH_TOB_AD_BAN | B13: I_PH_TOB_AD_BAN__C_IS | C13: istroke | D13: incidence | E13: well | F13: sick | G13: direct_smoking_prevalence_shift_rr | H13: 0.303 | I13: 0.29088 | J13: 1.38 | K13: 2026 | L13: 2030
... A29: I_PH_TOB_MEDIA | B29: I_PH_TOB_MEDIA__C_T2DM | C29: dm2 | D29: incidence | E29: well | F29: sick | G29: direct_smoking_prevalence_shift_rr | H29: 0.303 | I29: 0.283305 | J29: 1.37 | K29: 2026 | L29: 2030

Sheet PH_Cost_Components
A1: cost_record_id | B1: intervention_id | C1: parent_package_id | D1: cost_component | E1: cost_scope | F1: population_in_need_fraction | G1: frequency_per_year | H1: unit_cost_usd | I1: c_age_start | J1: c_age_stop | K1: c_sex | L1: cost_ready
A2: COST_PH_TOB_TAX | B2: I_PH_TOBACCO_TAX | C2: I_PH_TOBACCO_TAX | D2: Annual intersectoral policy implementation | E2: shared-count-once | F2: 1 | G2: 1 | H2: 0.04 | I2: 0 | J2: 95 | K2: Both | L2: TRUE
A3: COST_PH_TOB_AD_BAN | B3: I_PH_TOB_AD_BAN | C3: I_PH_TOBACCO_POLICY | D3: Annual intersectoral policy implementation | E3: component-count-once | F3: 1 | G3: 1 | H3: 0.0077 | I3: 0 | J3: 95 | K3: Both | L3: TRUE
A4: COST_PH_TOB_CLEAN_AIR | B4: I_PH_TOB_CLEAN_AIR | C4: I_PH_TOBACCO_POLICY | D4: Annual intersectoral policy implementation | E4: component-count-once | F4: 1 | G4: 1 | H4: 0.0077 | I4: 0 | J4: 95 | K4: Both | L4: TRUE
A5: COST_PH_TOB_MEDIA | B5: I_PH_TOB_MEDIA | C5: I_PH_TOBACCO_POLICY | D5: Annual intersectoral policy implementation | E5: component-count-once | F5: 1 | G5: 1 | H5: 0.0077 | I5: 0 | J5: 95 | K5: Both | L5: TRUE

Sheet PH_Scenario_Hierarchy
A1: parent_scenario_id | B1: parent_scenario_name | C1: intervention_id | D1: intervention_name | E1: package_group | F1: scenario_role | G1: include_in_parent_scenario | H1: standalone_scenario_id | I1: parent_aggregation_rule | J1: outcome_reporting_rule | K1: cost_reporting_rule | L1: component_order | M1: source_note | N1: is_runnable | O1: is_parent_package
A2: I_PH_TOBACCO_TAX | B2: Tobacco tax | C2: I_PH_TOBACCO_TAX | D2: Tobacco tax | E2: Tobacco | F2: standalone | G2: 1 | H2: I_PH_TOBACCO_TAX | I2: single intervention | J2: report intervention | K2: report intervention cost | L2: 1 | M2: Fiscal | N2: TRUE | O2: FALSE
A3: I_PH_ALCOHOL_TAX | B3: Alcohol tax | C3: I_PH_ALCOHOL_TAX | D3: Alcohol tax | E3: Alcohol | F3: standalone | G3: 1 | H3: I_PH_ALCOHOL_TAX | I3: single intervention | J3: report intervention | K3: report intervention cost | L3: 1 | M3: Fiscal | N3: FALSE | O3: FALSE
A4: I_PH_TOBACCO_POLICY | B4: Tobacco policy package | C4: I_PH_TOB_CLEAN_AIR | D4: Smoke-free / clean-air law | E4: Tobacco | F4: child | G4: 1 | H4: I_PH_TOB_CLEAN_AIR | I4: run children jointly | J4: report child and parent | K4: sum child costs; rerun health jointly | L4: 1 | M4: MPOWER | N4: TRUE | O4: FALSE
A5: I_PH_TOBACCO_POLICY | B5: Tobacco policy package | C5: I_PH_TOB_MEDIA | D5: Tobacco mass-media campaign | E5: Tobacco | F5: child | G5: 1 | H5: I_PH_TOB_MEDIA | I5: run children jointly | J5: report child and parent | K5: sum child costs; rerun health jointly | L5: 2 | M5: MPOWER | N5: TRUE | O5: FALSE
A6: I_PH_TOBACCO_POLICY | B6: Tobacco policy package | C6: I_PH_TOB_AD_BAN | D6: Tobacco advertising ban | E6: Tobacco | F6: child | G6: 1 | H6: I_PH_TOB_AD_BAN | I6: run children jointly | J6: report child and parent | K6: sum child costs; rerun health jointly | L6: 3 | M6: MPOWER | N6: TRUE | O6: FALSE
A7: I_PH_ALCOHOL_POLICY | B7: Alcohol advertising policy | C7: I_PH_ALCOHOL_POLICY | D7: Alcohol advertising ban | E7: Alcohol | F7: standalone | G7: 1 | H7: I_PH_ALCOHOL_POLICY | I7: single intervention | J7: report intervention | K7: report intervention cost | L7: 1 | M7: Alcohol policy | N7: FALSE | O7: FALSE
A8: I_PH_SALT_POLICY | B8: Salt policy package | C8: I_PH_SALT_REFORM | D8: Mandatory sodium reformulation | E8: Diet | F8: child | G8: 1 | H8: I_PH_SALT_REFORM | I8: run children jointly | J8: report child and parent | K8: sum child costs; rerun health jointly | L8: 1 | M8: SHAKE | N8: FALSE | O8: FALSE
A9: I_PH_SALT_POLICY | B9: Salt policy package | C9: I_PH_SALT_FOPL | D9: Sodium front-of-pack labelling | E9: Diet | F9: child | G9: 1 | H9: I_PH_SALT_FOPL | I9: run children jointly | J9: report child and parent | K9: sum child costs; rerun health jointly | L9: 2 | M9: SHAKE | N9: FALSE | O9: FALSE
A10: I_PH_SALT_POLICY | B10: Salt policy package | C10: I_PH_SALT_MEDIA | D10: Sodium mass-media campaign | E10: Diet | F10: child | G10: 1 | H10: I_PH_SALT_MEDIA | I10: run children jointly | J10: report child and parent | K10: sum child costs; rerun health jointly | L10: 3 | M10: SHAKE | N10: FALSE | O10: FALSE
A11: I_PH_SALT_POLICY | B11: Salt policy package | C11: I_PH_SALT_ENV | D11: Supportive public-institution environment | E11: Diet | F11: child | G11: 1 | H11: I_PH_SALT_ENV | I11: run children jointly | J11: report child and parent | K11: sum child costs; rerun health jointly | L11: 4 | M11: SHAKE | N11: FALSE | O11: FALSE
A12: I_PH_TFA_POLICY | B12: Industrial TFA regulation | C12: I_PH_TFA_POLICY | D12: Industrial trans-fat elimination regulation | E12: Diet | F12: standalone | G12: 1 | H12: I_PH_TFA_POLICY | I12: single intervention | J12: report intervention | K12: report intervention cost | L12: 1 | M12: REPLACE | N12: FALSE | O12: FALSE
A13: I_PH_SSB_TAX | B13: SSB tax | C13: I_PH_SSB_TAX | D13: Sugar-sweetened beverage tax | E13: Diet | F13: standalone | G13: 1 | H13: I_PH_SSB_TAX | I13: single intervention | J13: report intervention | K13: report intervention cost | L13: 1 | M13: Fiscal | N13: FALSE | O13: FALSE

Sheet Annual_Mortality
A1: scenario | B1: scenario_label | C1: year | D1: cause | E1: cases | F1: cause_deaths | G1: base_cases | H1: base_deaths | I1: deaths_averted | J1: cases_averted
A2: I_PH_TOBACCO_POLICY | B2: Tobacco policy package | C2: 2025 | D2: cmd | E2: 11293.859 | F2: 8456.0911 | G2: 11293.859 | H2: 8456.0911 | I2: =H2-F2 | J2: =G2-E2
A3: I_PH_TOBACCO_POLICY | B3: Tobacco policy package | C3: 2025 | D3: dm2 | E3: 796801.79 | F3: 124437.1 | G3: 796801.79 | H3: 124437.1 | I3: =H3-F3 | J3: =G3-E3
A4: I_PH_TOBACCO_POLICY | B4: Tobacco policy package | C4: 2025 | D4: hhd | E4: 110599.34 | F4: 70978.798 | G4: 110599.34 | H4: 70978.798 | I4: =H4-F4 | J4: =G4-E4
A5: I_PH_TOBACCO_POLICY | B5: Tobacco policy package | C5: 2025 | D5: hstroke | E5: 269908.91 | F5: 250549.93 | G5: 269908.91 | H5: 250549.93 | I5: =H5-F5 | J5: =G5-E5
A6: I_PH_TOBACCO_POLICY | B6: Tobacco policy package | C6: 2025 | D6: ihd | E6: 605290.56 | F6: 336235.04 | G6: 605290.56 | H6: 336235.04 | I6: =H6-F6 | J6: =G6-E6
A7: I_PH_TOBACCO_POLICY | B7: Tobacco policy package | C7: 2025 | D7: istroke | E7: 328703.7 | F7: 165181.23 | G7: 328703.7 | H7: 165181.23 | I7: =H7-F7 | J7: =G7-E7
A8: I_PH_TOBACCO_POLICY | B8: Tobacco policy package | C8: 2025 | D8: rhd | E8: 12601.519 | F8: 3955.3071 | G8: 12601.519 | H8: 3955.3071 | I8: =H8-F8 | J8: =G8-E8
A9: I_PH_TOBACCO_POLICY | B9: Tobacco policy package | C9: 2026 | D9: cmd | E9: 11413.94 | F9: 8503.0488 | G9: 11413.94 | H9: 8503.0488 | I9: =H9-F9 | J9: =G9-E9
A10: I_PH_TOBACCO_POLICY | B10: Tobacco policy package | C10: 2026 | D10: dm2 | E10: 813844.57 | F10: 128333.95 | G10: 813844.57 | H10: 128333.95 | I10: =H10-F10 | J10: =G10-E10
A11: I_PH_TOBACCO_POLICY | B11: Tobacco policy package | C11: 2026 | D11: hhd | E11: 113261.47 | F11: 72339.688 | G11: 113261.47 | H11: 72339.688 | I11: =H11-F11 | J11: =G11-E11
A12: I_PH_TOBACCO_POLICY | B12: Tobacco policy package | C12: 2026 | D12: hstroke | E12: 273941.16 | F12: 253872.84 | G12: 274200.58 | H12: 254910.75 | I12: =H12-F12 | J12: =G12-E12
A13: I_PH_TOBACCO_POLICY | B13: Tobacco policy package | C13: 2026 | D13: ihd | E13: 618348.3 | F13: 343153.28 | G13: 620097.59 | H13: 344917.06 | I13: =H13-F13 | J13: =G13-E13
... A1639: all_public_health | B1639: All selected public-health interventions (combined) | C1639: 2050 | D1639: rhd | E1639: 11459.37 | F1639: 1051.1546 | G1639: 11458.332 | H1639: 1051.1139 | I1639: =H1639-F1639 | J1639: =G1639-E1639

Sheet Health_Outcomes
A1: scenario | B1: scenario_label | C1: year | D1: modeled_deaths | E1: baseline_deaths | F1: deaths_averted | G1: modeled_cases | H1: baseline_cases | I1: cases_averted | J1: yll | K1: base_yll | L1: yll_averted | M1: yld | N1: base_yld | O1: yld_averted | P1: daly | Q1: base_daly | R1: dalys_averted | S1: life_years_gained
A2: all_cascade_public_health | B2: 70-30-30 -> 70-70-70 cascade + all public-health interventions (combined) | C2: 2025 | D2: 959793.5 | E2: 959793.5 | F2: =E2-D2 | G2: 2135199.7 | H2: 2135199.7 | I2: =H2-G2 | J2: 13078631 | K2: 13078631 | L2: =K2-J2 | M2: 2439867.8 | N2: 2439867.8 | O2: =N2-M2 | P2: 15518499 | Q2: 15518499 | R2: =Q2-P2 | S2: =L2
A3: all_cascade_public_health | B3: 70-30-30 -> 70-70-70 cascade + all public-health interventions (combined) | C3: 2026 | D3: 968627.47 | E3: 980780.31 | F3: =E3-D3 | G3: 2172766.1 | H3: 2181019.5 | I3: =H3-G3 | J3: 13175557 | K3: 13376482 | L3: =K3-J3 | M3: 2495730 | N3: 2495093.1 | O3: =N3-M3 | P3: 15671287 | Q3: 15871576 | R3: =Q3-P3 | S3: =L3
A4: all_cascade_public_health | B4: 70-30-30 -> 70-70-70 cascade + all public-health interventions (combined) | C4: 2027 | D4: 979659.58 | E4: 1003320.8 | F4: =E4-D4 | G4: 2209291.3 | H4: 2228341.8 | I4: =H4-G4 | J4: 13281863 | K4: 13677395 | L4: =K4-J4 | M4: 2552762.7 | N4: 2551241 | O4: =N4-M4 | P4: 15834626 | Q4: 16228636 | R4: =Q4-P4 | S4: =L4
A5: all_cascade_public_health | B5: 70-30-30 -> 70-70-70 cascade + all public-health interventions (combined) | C5: 2028 | D5: 992527.08 | E5: 1027500.5 | F5: =E5-D5 | G5: 2258185.4 | H5: 2288120.7 | I5: =H5-G5 | J5: 13386409 | K5: 13973850 | L5: =K5-J5 | M5: 2611686.6 | N5: 2609119.5 | O5: =N5-M5 | P5: 15998095 | Q5: 16582969 | R5: =Q5-P5 | S5: =L5
A6: all_cascade_public_health | B6: 70-30-30 -> 70-70-70 cascade + all public-health interventions (combined) | C6: 2029 | D6: 1004558.9 | E6: 1053610.4 | F6: =E6-D6 | G6: 2294315.2 | H6: 2336688.1 | I6: =H6-G6 | J6: 13473060 | K6: 14290695 | L6: =K6-J6 | M6: 2671286.5 | N6: 2667387.1 | O6: =N6-M6 | P6: 16144347 | Q6: 16958082 | R6: =Q6-P6 | S6: =L6
A7: all_cascade_public_health | B7: 70-30-30 -> 70-70-70 cascade + all public-health interventions (combined) | C7: 2030 | D7: 1017729.3 | E7: 1080810.2 | F7: =E7-D7 | G7: 2331704.4 | H7: 2386448.8 | I7: =H7-G7 | J7: 13554564 | K7: 14601429 | L7: =K7-J7 | M7: 2731390.7 | N7: 2725934.8 | O7: =N7-M7 | P7: 16285954 | Q7: 17327364 | R7: =Q7-P7 | S7: =L7
A8: all_cascade_public_health | B8: 70-30-30 -> 70-70-70 cascade + all public-health interventions (combined) | C8: 2031 | D8: 1041784.5 | E8: 1107157.6 | F8: =E8-D8 | G8: 2360648.5 | H8: 2435295.4 | I8: =H8-G8 | J8: 13824538 | K8: 14910263 | L8: =K8-J8 | M8: 2789570.4 | N8: 2784742.8 | O8: =N8-M8 | P8: 16614108 | Q8: 17695005 | R8: =Q8-P8 | S8: =L8
A9: all_cascade_public_health | B9: 70-30-30 -> 70-70-70 cascade + all public-health interventions (combined) | C9: 2032 | D9: 1063438.1 | E9: 1133979.8 | F9: =E9-D9 | G9: 2391076.6 | H9: 2486226.9 | I9: =H9-G9 | J9: 14053501 | K9: 15212725 | L9: =K9-J9 | M9: 2846341.8 | N9: 2843886.5 | O9: =N9-M9 | P9: 16899842 | Q9: 18056611 | R9: =Q9-P9 | S9: =L9
A10: all_cascade_public_health | B10: 70-30-30 -> 70-70-70 cascade + all public-health interventions (combined) | C10: 2033 | D10: 1083048.5 | E10: 1160519 | F10: =E10-D10 | G10: 2427671.7 | H10: 2544179.9 | I10: =H10-G10 | J10: 14242624 | K10: 15498147 | L10: =K10-J10 | M10: 2902475.9 | N10: 2903939 | O10: =N10-M10 | P10: 17145100 | Q10: 18402086 | R10: =Q10-P10 | S10: =L10
A11: all_cascade_public_health | B11: 70-30-30 -> 70-70-70 cascade + all public-health interventions (combined) | C11: 2034 | D11: 1104600.1 | E11: 1187394.6 | F11: =E11-D11 | G11: 2455296.5 | H11: 2591241.8 | I11: =H11-G11 | J11: 14467426 | K11: 15799428 | L11: =K11-J11 | M11: 2956997.9 | N11: 2963891.1 | O11: =N11-M11 | P11: 17424424 | Q11: 18763320 | R11: =Q11-P11 | S11: =L11
A12: all_cascade_public_health | B12: 70-30-30 -> 70-70-70 cascade + all public-health interventions (combined) | C12: 2035 | D12: 1124823.9 | E12: 1214326 | F12: =E12-D12 | G12: 2481664.4 | H12: 2637338.6 | I12: =H12-G12 | J12: 14666544 | K12: 16093446 | L12: =K12-J12 | M12: 3009917.3 | N12: 3023565.8 | O12: =N12-M12 | P12: 17676461 | Q12: 19117012 | R12: =Q12-P12 | S12: =L12
A13: all_cascade_public_health | B13: 70-30-30 -> 70-70-70 cascade + all public-health interventions (combined) | C13: 2036 | D13: 1133885.7 | E13: 1242005.2 | F13: =E13-D13 | G13: 2506159.8 | H13: 2687815.4 | I13: =H13-G13 | J13: 14722608 | K13: 16387284 | L13: =K13-J13 | M13: 3062312.6 | N13: 3083207.2 | O13: =N13-M13 | P13: 17784920 | Q13: 19470491 | R13: =Q13-P13 | S13: =L13
... A235: S_70_30_30_TO_70_70_70_I_PH_TOBACCO_TAX | B235: 70-30-30 -> 70-70-70 cascade + tobacco tax | C235: 2050 | D235: 1402000.1 | E235: 1604008.5 | F235: =E235-D235 | G235: 3012341.6 | H235: 3257199.3 | I235: =H235-G235 | J235: 16631506 | K235: 19570013 | L235: =K235-J235 | M235: 3730041.4 | N235: 3846594.4 | O235: =N235-M235 | P235: 20361548 | Q235: 23416608 | R235: =Q235-P235 | S235: =L235

Sheet CVD_40q30
A1: location | B1: scenario | C1: scenario_label | D1: intervention_family | E1: scenario_role | F1: parent_package_id | G1: htn_target_scenario | H1: year | I1: cvd_40q30 | J1: baseline_cvd_40q30 | K1: absolute_reduction_pp | L1: percent_reduction | M1: cvd_40q30_r | N1: recon_status
A2: Indonesia | B2: I_PH_TOBACCO_POLICY | C2: Tobacco policy package | D2: public_health | E2: package | F2: I_PH_TOBACCO_POLICY | G2: htncov2_aspirational | H2: 2025 | I2: =100*(1-(SUMIFS('CVD_40q30_Age'!$M$2:$M$10401,'CVD_40q30_Age'!$A$2:$A$10401,A2,'CVD_40q30_Age'!$B$2:$B$10401,B2,'CVD_40q30_Age'!$E$2:$E$10401,G2,'CVD_40q30_Age'!$F$2:$F$10401,H2,'CVD_40q30_Age'!$G$2:$G$10401,69))/(SUMIFS('CVD_40q30_Age'!$L$2:$L$10401,'CVD_40q30_Age'!$A$2:$A$10401,A2,'CVD_40q30_Age'!$B$2:$B$10401,B2,'CVD_40q30_Age'!$E$2:$E$10401,G2,'CVD_40q30_Age'!$F$2:$F$10401,H2,'CVD_40q30_Age'!$G$2:$G$10401,30))) | J2: =SUMIFS($I$2:$I$261,$A$2:$A$261,A2,$G$2:$G$261,G2,$H$2:$H$261,H2,$B$2:$B$261,"baseline") | K2: =J2-I2 | L2: =IF(J2=0,"",100*(J2-I2)/J2) | M2: 14.594863 | N2: =IF(ABS(I2-M2)<=0.001,"match","mismatch")
A3: Indonesia | B3: I_PH_TOBACCO_POLICY | C3: Tobacco policy package | D3: public_health | E3: package | F3: I_PH_TOBACCO_POLICY | G3: htncov2_aspirational | H3: 2026 | I3: =100*(1-(SUMIFS('CVD_40q30_Age'!$M$2:$M$10401,'CVD_40q30_Age'!$A$2:$A$10401,A3,'CVD_40q30_Age'!$B$2:$B$10401,B3,'CVD_40q30_Age'!$E$2:$E$10401,G3,'CVD_40q30_Age'!$F$2:$F$10401,H3,'CVD_40q30_Age'!$G$2:$G$10401,69))/(SUMIFS('CVD_40q30_Age'!$L$2:$L$10401,'CVD_40q30_Age'!$A$2:$A$10401,A3,'CVD_40q30_Age'!$B$2:$B$10401,B3,'CVD_40q30_Age'!$E$2:$E$10401,G3,'CVD_40q30_Age'!$F$2:$F$10401,H3,'CVD_40q30_Age'!$G$2:$G$10401,30))) | J3: =SUMIFS($I$2:$I$261,$A$2:$A$261,A3,$G$2:$G$261,G3,$H$2:$H$261,H3,$B$2:$B$261,"baseline") | K3: =J3-I3 | L3: =IF(J3=0,"",100*(J3-I3)/J3) | M3: 14.456941 | N3: =IF(ABS(I3-M3)<=0.001,"match","mismatch")
A4: Indonesia | B4: I_PH_TOBACCO_POLICY | C4: Tobacco policy package | D4: public_health | E4: package | F4: I_PH_TOBACCO_POLICY | G4: htncov2_aspirational | H4: 2027 | I4: =100*(1-(SUMIFS('CVD_40q30_Age'!$M$2:$M$10401,'CVD_40q30_Age'!$A$2:$A$10401,A4,'CVD_40q30_Age'!$B$2:$B$10401,B4,'CVD_40q30_Age'!$E$2:$E$10401,G4,'CVD_40q30_Age'!$F$2:$F$10401,H4,'CVD_40q30_Age'!$G$2:$G$10401,69))/(SUMIFS('CVD_40q30_Age'!$L$2:$L$10401,'CVD_40q30_Age'!$A$2:$A$10401,A4,'CVD_40q30_Age'!$B$2:$B$10401,B4,'CVD_40q30_Age'!$E$2:$E$10401,G4,'CVD_40q30_Age'!$F$2:$F$10401,H4,'CVD_40q30_Age'!$G$2:$G$10401,30))) | J4: =SUMIFS($I$2:$I$261,$A$2:$A$261,A4,$G$2:$G$261,G4,$H$2:$H$261,H4,$B$2:$B$261,"baseline") | K4: =J4-I4 | L4: =IF(J4=0,"",100*(J4-I4)/J4) | M4: 14.314466 | N4: =IF(ABS(I4-M4)<=0.001,"match","mismatch")
A5: Indonesia | B5: I_PH_TOBACCO_POLICY | C5: Tobacco policy package | D5: public_health | E5: package | F5: I_PH_TOBACCO_POLICY | G5: htncov2_aspirational | H5: 2028 | I5: =100*(1-(SUMIFS('CVD_40q30_Age'!$M$2:$M$10401,'CVD_40q30_Age'!$A$2:$A$10401,A5,'CVD_40q30_Age'!$B$2:$B$10401,B5,'CVD_40q30_Age'!$E$2:$E$10401,G5,'CVD_40q30_Age'!$F$2:$F$10401,H5,'CVD_40q30_Age'!$G$2:$G$10401,69))/(SUMIFS('CVD_40q30_Age'!$L$2:$L$10401,'CVD_40q30_Age'!$A$2:$A$10401,A5,'CVD_40q30_Age'!$B$2:$B$10401,B5,'CVD_40q30_Age'!$E$2:$E$10401,G5,'CVD_40q30_Age'!$F$2:$F$10401,H5,'CVD_40q30_Age'!$G$2:$G$10401,30))) | J5: =SUMIFS($I$2:$I$261,$A$2:$A$261,A5,$G$2:$G$261,G5,$H$2:$H$261,H5,$B$2:$B$261,"baseline") | K5: =J5-I5 | L5: =IF(J5=0,"",100*(J5-I5)/J5) | M5: 14.175458 | N5: =IF(ABS(I5-M5)<=0.001,"match","mismatch")
A6: Indonesia | B6: I_PH_TOBACCO_POLICY | C6: Tobacco policy package | D6: public_health | E6: package | F6: I_PH_TOBACCO_POLICY | G6: htncov2_aspirational | H6: 2029 | I6: =100*(1-(SUMIFS('CVD_40q30_Age'!$M$2:$M$10401,'CVD_40q30_Age'!$A$2:$A$10401,A6,'CVD_40q30_Age'!$B$2:$B$10401,B6,'CVD_40q30_Age'!$E$2:$E$10401,G6,'CVD_40q30_Age'!$F$2:$F$10401,H6,'CVD_40q30_Age'!$G$2:$G$10401,69))/(SUMIFS('CVD_40q30_Age'!$L$2:$L$10401,'CVD_40q30_Age'!$A$2:$A$10401,A6,'CVD_40q30_Age'!$B$2:$B$10401,B6,'CVD_40q30_Age'!$E$2:$E$10401,G6,'CVD_40q30_Age'!$F$2:$F$10401,H6,'CVD_40q30_Age'!$G$2:$G$10401,30))) | J6: =SUMIFS($I$2:$I$261,$A$2:$A$261,A6,$G$2:$G$261,G6,$H$2:$H$261,H6,$B$2:$B$261,"baseline") | K6: =J6-I6 | L6: =IF(J6=0,"",100*(J6-I6)/J6) | M6: 14.033685 | N6: =IF(ABS(I6-M6)<=0.001,"match","mismatch")
A7: Indonesia | B7: I_PH_TOBACCO_POLICY | C7: Tobacco policy package | D7: public_health | E7: package | F7: I_PH_TOBACCO_POLICY | G7: htncov2_aspirational | H7: 2030 | I7: =100*(1-(SUMIFS('CVD_40q30_Age'!$M$2:$M$10401,'CVD_40q30_Age'!$A$2:$A$10401,A7,'CVD_40q30_Age'!$B$2:$B$10401,B7,'CVD_40q30_Age'!$E$2:$E$10401,G7,'CVD_40q30_Age'!$F$2:$F$10401,H7,'CVD_40q30_Age'!$G$2:$G$10401,69))/(SUMIFS('CVD_40q30_Age'!$L$2:$L$10401,'CVD_40q30_Age'!$A$2:$A$10401,A7,'CVD_40q30_Age'!$B$2:$B$10401,B7,'CVD_40q30_Age'!$E$2:$E$10401,G7,'CVD_40q30_Age'!$F$2:$F$10401,H7,'CVD_40q30_Age'!$G$2:$G$10401,30))) | J7: =SUMIFS($I$2:$I$261,$A$2:$A$261,A7,$G$2:$G$261,G7,$H$2:$H$261,H7,$B$2:$B$261,"baseline") | K7: =J7-I7 | L7: =IF(J7=0,"",100*(J7-I7)/J7) | M7: 13.886552 | N7: =IF(ABS(I7-M7)<=0.001,"match","mismatch")
A8: Indonesia | B8: I_PH_TOBACCO_POLICY | C8: Tobacco policy package | D8: public_health | E8: package | F8: I_PH_TOBACCO_POLICY | G8: htncov2_aspirational | H8: 2031 | I8: =100*(1-(SUMIFS('CVD_40q30_Age'!$M$2:$M$10401,'CVD_40q30_Age'!$A$2:$A$10401,A8,'CVD_40q30_Age'!$B$2:$B$10401,B8,'CVD_40q30_Age'!$E$2:$E$10401,G8,'CVD_40q30_Age'!$F$2:$F$10401,H8,'CVD_40q30_Age'!$G$2:$G$10401,69))/(SUMIFS('CVD_40q30_Age'!$L$2:$L$10401,'CVD_40q30_Age'!$A$2:$A$10401,A8,'CVD_40q30_Age'!$B$2:$B$10401,B8,'CVD_40q30_Age'!$E$2:$E$10401,G8,'CVD_40q30_Age'!$F$2:$F$10401,H8,'CVD_40q30_Age'!$G$2:$G$10401,30))) | J8: =SUMIFS($I$2:$I$261,$A$2:$A$261,A8,$G$2:$G$261,G8,$H$2:$H$261,H8,$B$2:$B$261,"baseline") | K8: =J8-I8 | L8: =IF(J8=0,"",100*(J8-I8)/J8) | M8: 13.779364 | N8: =IF(ABS(I8-M8)<=0.001,"match","mismatch")
A9: Indonesia | B9: I_PH_TOBACCO_POLICY | C9: Tobacco policy package | D9: public_health | E9: package | F9: I_PH_TOBACCO_POLICY | G9: htncov2_aspirational | H9: 2032 | I9: =100*(1-(SUMIFS('CVD_40q30_Age'!$M$2:$M$10401,'CVD_40q30_Age'!$A$2:$A$10401,A9,'CVD_40q30_Age'!$B$2:$B$10401,B9,'CVD_40q30_Age'!$E$2:$E$10401,G9,'CVD_40q30_Age'!$F$2:$F$10401,H9,'CVD_40q30_Age'!$G$2:$G$10401,69))/(SUMIFS('CVD_40q30_Age'!$L$2:$L$10401,'CVD_40q30_Age'!$A$2:$A$10401,A9,'CVD_40q30_Age'!$B$2:$B$10401,B9,'CVD_40q30_Age'!$E$2:$E$10401,G9,'CVD_40q30_Age'!$F$2:$F$10401,H9,'CVD_40q30_Age'!$G$2:$G$10401,30))) | J9: =SUMIFS($I$2:$I$261,$A$2:$A$261,A9,$G$2:$G$261,G9,$H$2:$H$261,H9,$B$2:$B$261,"baseline") | K9: =J9-I9 | L9: =IF(J9=0,"",100*(J9-I9)/J9) | M9: 13.661763 | N9: =IF(ABS(I9-M9)<=0.001,"match","mismatch")
A10: Indonesia | B10: I_PH_TOBACCO_POLICY | C10: Tobacco policy package | D10: public_health | E10: package | F10: I_PH_TOBACCO_POLICY | G10: htncov2_aspirational | H10: 2033 | I10: =100*(1-(SUMIFS('CVD_40q30_Age'!$M$2:$M$10401,'CVD_40q30_Age'!$A$2:$A$10401,A10,'CVD_40q30_Age'!$B$2:$B$10401,B10,'CVD_40q30_Age'!$E$2:$E$10401,G10,'CVD_40q30_Age'!$F$2:$F$10401,H10,'CVD_40q30_Age'!$G$2:$G$10401,69))/(SUMIFS('CVD_40q30_Age'!$L$2:$L$10401,'CVD_40q30_Age'!$A$2:$A$10401,A10,'CVD_40q30_Age'!$B$2:$B$10401,B10,'CVD_40q30_Age'!$E$2:$E$10401,G10,'CVD_40q30_Age'!$F$2:$F$10401,H10,'CVD_40q30_Age'!$G$2:$G$10401,30))) | J10: =SUMIFS($I$2:$I$261,$A$2:$A$261,A10,$G$2:$G$261,G10,$H$2:$H$261,H10,$B$2:$B$261,"baseline") | K10: =J10-I10 | L10: =IF(J10=0,"",100*(J10-I10)/J10) | M10: 13.531395 | N10: =IF(ABS(I10-M10)<=0.001,"match","mismatch")
A11: Indonesia | B11: I_PH_TOBACCO_POLICY | C11: Tobacco policy package | D11: public_health | E11: package | F11: I_PH_TOBACCO_POLICY | G11: htncov2_aspirational | H11: 2034 | I11: =100*(1-(SUMIFS('CVD_40q30_Age'!$M$2:$M$10401,'CVD_40q30_Age'!$A$2:$A$10401,A11,'CVD_40q30_Age'!$B$2:$B$10401,B11,'CVD_40q30_Age'!$E$2:$E$10401,G11,'CVD_40q30_Age'!$F$2:$F$10401,H11,'CVD_40q30_Age'!$G$2:$G$10401,69))/(SUMIFS('CVD_40q30_Age'!$L$2:$L$10401,'CVD_40q30_Age'!$A$2:$A$10401,A11,'CVD_40q30_Age'!$B$2:$B$10401,B11,'CVD_40q30_Age'!$E$2:$E$10401,G11,'CVD_40q30_Age'!$F$2:$F$10401,H11,'CVD_40q30_Age'!$G$2:$G$10401,30))) | J11: =SUMIFS($I$2:$I$261,$A$2:$A$261,A11,$G$2:$G$261,G11,$H$2:$H$261,H11,$B$2:$B$261,"baseline") | K11: =J11-I11 | L11: =IF(J11=0,"",100*(J11-I11)/J11) | M11: 13.419038 | N11: =IF(ABS(I11-M11)<=0.001,"match","mismatch")
A12: Indonesia | B12: I_PH_TOBACCO_POLICY | C12: Tobacco policy package | D12: public_health | E12: package | F12: I_PH_TOBACCO_POLICY | G12: htncov2_aspirational | H12: 2035 | I12: =100*(1-(SUMIFS('CVD_40q30_Age'!$M$2:$M$10401,'CVD_40q30_Age'!$A$2:$A$10401,A12,'CVD_40q30_Age'!$B$2:$B$10401,B12,'CVD_40q30_Age'!$E$2:$E$10401,G12,'CVD_40q30_Age'!$F$2:$F$10401,H12,'CVD_40q30_Age'!$G$2:$G$10401,69))/(SUMIFS('CVD_40q30_Age'!$L$2:$L$10401,'CVD_40q30_Age'!$A$2:$A$10401,A12,'CVD_40q30_Age'!$B$2:$B$10401,B12,'CVD_40q30_Age'!$E$2:$E$10401,G12,'CVD_40q30_Age'!$F$2:$F$10401,H12,'CVD_40q30_Age'!$G$2:$G$10401,30))) | J12: =SUMIFS($I$2:$I$261,$A$2:$A$261,A12,$G$2:$G$261,G12,$H$2:$H$261,H12,$B$2:$B$261,"baseline") | K12: =J12-I12 | L12: =IF(J12=0,"",100*(J12-I12)/J12) | M12: 13.29789 | N12: =IF(ABS(I12-M12)<=0.001,"match","mismatch")
A13: Indonesia | B13: I_PH_TOBACCO_POLICY | C13: Tobacco policy package | D13: public_health | E13: package | F13: I_PH_TOBACCO_POLICY | G13: htncov2_aspirational | H13: 2036 | I13: =100*(1-(SUMIFS('CVD_40q30_Age'!$M$2:$M$10401,'CVD_40q30_Age'!$A$2:$A$10401,A13,'CVD_40q30_Age'!$B$2:$B$10401,B13,'CVD_40q30_Age'!$E$2:$E$10401,G13,'CVD_40q30_Age'!$F$2:$F$10401,H13,'CVD_40q30_Age'!$G$2:$G$10401,69))/(SUMIFS('CVD_40q30_Age'!$L$2:$L$10401,'CVD_40q30_Age'!$A$2:$A$10401,A13,'CVD_40q30_Age'!$B$2:$B$10401,B13,'CVD_40q30_Age'!$E$2:$E$10401,G13,'CVD_40q30_Age'!$F$2:$F$10401,H13,'CVD_40q30_Age'!$G$2:$G$10401,30))) | J13: =SUMIFS($I$2:$I$261,$A$2:$A$261,A13,$G$2:$G$261,G13,$H$2:$H$261,H13,$B$2:$B$261,"baseline") | K13: =J13-I13 | L13: =IF(J13=0,"",100*(J13-I13)/J13) | M13: 13.14275 | N13: =IF(ABS(I13-M13)<=0.001,"match","mismatch")
... A27: Indonesia | B27: I_PH_TOBACCO_POLICY | C27: Tobacco policy package | D27: public_health | E27: package | F27: I_PH_TOBACCO_POLICY | G27: htncov2_aspirational | H27: 2050 | I27: =100*(1-(SUMIFS('CVD_40q30_Age'!$M$2:$M$10401,'CVD_40q30_Age'!$A$2:$A$10401,A27,'CVD_40q30_Age'!$B$2:$B$10401,B27,'CVD_40q30_Age'!$E$2:$E$10401,G27,'CVD_40q30_Age'!$F$2:$F$10401,H27,'CVD_40q30_Age'!$G$2:$G$10401,69))/(SUMIFS('CVD_40q30_Age'!$L$2:$L$10401,'CVD_40q30_Age'!$A$2:$A$10401,A27,'CVD_40q30_Age'!$B$2:$B$10401,B27,'CVD_40q30_Age'!$E$2:$E$10401,G27,'CVD_40q30_Age'!$F$2:$F$10401,H27,'CVD_40q30_Age'!$G$2:$G$10401,30))) | J27: =SUMIFS($I$2:$I$261,$A$2:$A$261,A27,$G$2:$G$261,G27,$H$2:$H$261,H27,$B$2:$B$261,"baseline") | K27: =J27-I27 | L27: =IF(J27=0,"",100*(J27-I27)/J27) | M27: 11.26863 | N27: =IF(ABS(I27-M27)<=0.001,"match","mismatch")
A28: Indonesia | B28: I_PH_TOBACCO_TAX | C28: Tobacco tax | D28: public_health | E28: standalone | G28: htncov2_aspirational | H28: 2025 | I28: =100*(1-(SUMIFS('CVD_40q30_Age'!$M$2:$M$10401,'CVD_40q30_Age'!$A$2:$A$10401,A28,'CVD_40q30_Age'!$B$2:$B$10401,B28,'CVD_40q30_Age'!$E$2:$E$10401,G28,'CVD_40q30_Age'!$F$2:$F$10401,H28,'CVD_40q30_Age'!$G$2:$G$10401,69))/(SUMIFS('CVD_40q30_Age'!$L$2:$L$10401,'CVD_40q30_Age'!$A$2:$A$10401,A28,'CVD_40q30_Age'!$B$2:$B$10401,B28,'CVD_40q30_Age'!$E$2:$E$10401,G28,'CVD_40q30_Age'!$F$2:$F$10401,H28,'CVD_40q30_Age'!$G$2:$G$10401,30))) | J28: =SUMIFS($I$2:$I$261,$A$2:$A$261,A28,$G$2:$G$261,G28,$H$2:$H$261,H28,$B$2:$B$261,"baseline") | K28: =J28-I28 | L28: =IF(J28=0,"",100*(J28-I28)/J28) | M28: 14.594863 | N28: =IF(ABS(I28-M28)<=0.001,"match","mismatch")
A29: Indonesia | B29: I_PH_TOBACCO_TAX | C29: Tobacco tax | D29: public_health | E29: standalone | G29: htncov2_aspirational | H29: 2026 | I29: =100*(1-(SUMIFS('CVD_40q30_Age'!$M$2:$M$10401,'CVD_40q30_Age'!$A$2:$A$10401,A29,'CVD_40q30_Age'!$B$2:$B$10401,B29,'CVD_40q30_Age'!$E$2:$E$10401,G29,'CVD_40q30_Age'!$F$2:$F$10401,H29,'CVD_40q30_Age'!$G$2:$G$10401,69))/(SUMIFS('CVD_40q30_Age'!$L$2:$L$10401,'CVD_40q30_Age'!$A$2:$A$10401,A29,'CVD_40q30_Age'!$B$2:$B$10401,B29,'CVD_40q30_Age'!$E$2:$E$10401,G29,'CVD_40q30_Age'!$F$2:$F$10401,H29,'CVD_40q30_Age'!$G$2:$G$10401,30))) | J29: =SUMIFS($I$2:$I$261,$A$2:$A$261,A29,$G$2:$G$261,G29,$H$2:$H$261,H29,$B$2:$B$261,"baseline") | K29: =J29-I29 | L29: =IF(J29=0,"",100*(J29-I29)/J29) | M29: 14.381953 | N29: =IF(ABS(I29-M29)<=0.001,"match","mismatch")
A30: Indonesia | B30: I_PH_TOBACCO_TAX | C30: Tobacco tax | D30: public_health | E30: standalone | G30: htncov2_aspirational | H30: 2027 | I30: =100*(1-(SUMIFS('CVD_40q30_Age'!$M$2:$M$10401,'CVD_40q30_Age'!$A$2:$A$10401,A30,'CVD_40q30_Age'!$B$2:$B$10401,B30,'CVD_40q30_Age'!$E$2:$E$10401,G30,'CVD_40q30_Age'!$F$2:$F$10401,H30,'CVD_40q30_Age'!$G$2:$G$10401,69))/(SUMIFS('CVD_40q30_Age'!$L$2:$L$10401,'CVD_40q30_Age'!$A$2:$A$10401,A30,'CVD_40q30_Age'!$B$2:$B$10401,B30,'CVD_40q30_Age'!$E$2:$E$10401,G30,'CVD_40q30_Age'!$F$2:$F$10401,H30,'CVD_40q30_Age'!$G$2:$G$10401,30))) | J30: =SUMIFS($I$2:$I$261,$A$2:$A$261,A30,$G$2:$G$261,G30,$H$2:$H$261,H30,$B$2:$B$261,"baseline") | K30: =J30-I30 | L30: =IF(J30=0,"",100*(J30-I30)/J30) | M30: 14.169602 | N30: =IF(ABS(I30-M30)<=0.001,"match","mismatch")
A31: Indonesia | B31: I_PH_TOBACCO_TAX | C31: Tobacco tax | D31: public_health | E31: standalone | G31: htncov2_aspirational | H31: 2028 | I31: =100*(1-(SUMIFS('CVD_40q30_Age'!$M$2:$M$10401,'CVD_40q30_Age'!$A$2:$A$10401,A31,'CVD_40q30_Age'!$B$2:$B$10401,B31,'CVD_40q30_Age'!$E$2:$E$10401,G31,'CVD_40q30_Age'!$F$2:$F$10401,H31,'CVD_40q30_Age'!$G$2:$G$10401,69))/(SUMIFS('CVD_40q30_Age'!$L$2:$L$10401,'CVD_40q30_Age'!$A$2:$A$10401,A31,'CVD_40q30_Age'!$B$2:$B$10401,B31,'CVD_40q30_Age'!$E$2:$E$10401,G31,'CVD_40q30_Age'!$F$2:$F$10401,H31,'CVD_40q30_Age'!$G$2:$G$10401,30))) | J31: =SUMIFS($I$2:$I$261,$A$2:$A$261,A31,$G$2:$G$261,G31,$H$2:$H$261,H31,$B$2:$B$261,"baseline") | K31: =J31-I31 | L31: =IF(J31=0,"",100*(J31-I31)/J31) | M31: 13.963807 | N31: =IF(ABS(I31-M31)<=0.001,"match","mismatch")
A32: Indonesia | B32: I_PH_TOBACCO_TAX | C32: Tobacco tax | D32: public_health | E32: standalone | G32: htncov2_aspirational | H32: 2029 | I32: =100*(1-(SUMIFS('CVD_40q30_Age'!$M$2:$M$10401,'CVD_40q30_Age'!$A$2:$A$10401,A32,'CVD_40q30_Age'!$B$2:$B$10401,B32,'CVD_40q30_Age'!$E$2:$E$10401,G32,'CVD_40q30_Age'!$F$2:$F$10401,H32,'CVD_40q30_Age'!$G$2:$G$10401,69))/(SUMIFS('CVD_40q30_Age'!$L$2:$L$10401,'CVD_40q30_Age'!$A$2:$A$10401,A32,'CVD_40q30_Age'!$B$2:$B$10401,B32,'CVD_40q30_Age'!$E$2:$E$10401,G32,'CVD_40q30_Age'!$F$2:$F$10401,H32,'CVD_40q30_Age'!$G$2:$G$10401,30))) | J32: =SUMIFS($I$2:$I$261,$A$2:$A$261,A32,$G$2:$G$261,G32,$H$2:$H$261,H32,$B$2:$B$261,"baseline") | K32: =J32-I32 | L32: =IF(J32=0,"",100*(J32-I32)/J32) | M32: 13.740179 | N32: =IF(ABS(I32-M32)<=0.001,"match","mismatch")
A33: Indonesia | B33: I_PH_TOBACCO_TAX | C33: Tobacco tax | D33: public_health | E33: standalone | G33: htncov2_aspirational | H33: 2030 | I33: =100*(1-(SUMIFS('CVD_40q30_Age'!$M$2:$M$10401,'CVD_40q30_Age'!$A$2:$A$10401,A33,'CVD_40q30_Age'!$B$2:$B$10401,B33,'CVD_40q30_Age'!$E$2:$E$10401,G33,'CVD_40q30_Age'!$F$2:$F$10401,H33,'CVD_40q30_Age'!$G$2:$G$10401,69))/(SUMIFS('CVD_40q30_Age'!$L$2:$L$10401,'CVD_40q30_Age'!$A$2:$A$10401,A33,'CVD_40q30_Age'!$B$2:$B$10401,B33,'CVD_40q30_Age'!$E$2:$E$10401,G33,'CVD_40q30_Age'!$F$2:$F$10401,H33,'CVD_40q30_Age'!$G$2:$G$10401,30))) | J33: =SUMIFS($I$2:$I$261,$A$2:$A$261,A33,$G$2:$G$261,G33,$H$2:$H$261,H33,$B$2:$B$261,"baseline") | K33: =J33-I33 | L33: =IF(J33=0,"",100*(J33-I33)/J33) | M33: 13.513396 | N33: =IF(ABS(I33-M33)<=0.001,"match","mismatch")
A34: Indonesia | B34: I_PH_TOBACCO_TAX | C34: Tobacco tax | D34: public_health | E34: standalone | G34: htncov2_aspirational | H34: 2031 | I34: =100*(1-(SUMIFS('CVD_40q30_Age'!$M$2:$M$10401,'CVD_40q30_Age'!$A$2:$A$10401,A34,'CVD_40q30_Age'!$B$2:$B$10401,B34,'CVD_40q30_Age'!$E$2:$E$10401,G34,'CVD_40q30_Age'!$F$2:$F$10401,H34,'CVD_40q30_Age'!$G$2:$G$10401,69))/(SUMIFS('CVD_40q30_Age'!$L$2:$L$10401,'CVD_40q30_Age'!$A$2:$A$10401,A34,'CVD_40q30_Age'!$B$2:$B$10401,B34,'CVD_40q30_Age'!$E$2:$E$10401,G34,'CVD_40q30_Age'!$F$2:$F$10401,H34,'CVD_40q30_Age'!$G$2:$G$10401,30))) | J34: =SUMIFS($I$2:$I$261,$A$2:$A$261,A34,$G$2:$G$261,G34,$H$2:$H$261,H34,$B$2:$B$261,"baseline") | K34: =J34-I34 | L34: =IF(J34=0,"",100*(J34-I34)/J34) | M34: 13.405571 | N34: =IF(ABS(I34-M34)<=0.001,"match","mismatch")
A35: Indonesia | B35: I_PH_TOBACCO_TAX | C35: Tobacco tax | D35: public_health | E35: standalone | G35: htncov2_aspirational | H35: 2032 | I35: =100*(1-(SUMIFS('CVD_40q30_Age'!$M$2:$M$10401,'CVD_40q30_Age'!$A$2:$A$10401,A35,'CVD_40q30_Age'!$B$2:$B$10401,B35,'CVD_40q30_Age'!$E$2:$E$10401,G35,'CVD_40q30_Age'!$F$2:$F$10401,H35,'CVD_40q30_Age'!$G$2:$G$10401,69))/(SUMIFS('CVD_40q30_Age'!$L$2:$L$10401,'CVD_40q30_Age'!$A$2:$A$10401,A35,'CVD_40q30_Age'!$B$2:$B$10401,B35,'CVD_40q30_Age'!$E$2:$E$10401,G35,'CVD_40q30_Age'!$F$2:$F$10401,H35,'CVD_40q30_Age'!$G$2:$G$10401,30))) | J35: =SUMIFS($I$2:$I$261,$A$2:$A$261,A35,$G$2:$G$261,G35,$H$2:$H$261,H35,$B$2:$B$261,"baseline") | K35: =J35-I35 | L35: =IF(J35=0,"",100*(J35-I35)/J35) | M35: 13.283934 | N35: =IF(ABS(I35-M35)<=0.001,"match","mismatch")
A36: Indonesia | B36: I_PH_TOBACCO_TAX | C36: Tobacco tax | D36: public_health | E36: standalone | G36: htncov2_aspirational | H36: 2033 | I36: =100*(1-(SUMIFS('CVD_40q30_Age'!$M$2:$M$10401,'CVD_40q30_Age'!$A$2:$A$10401,A36,'CVD_40q30_Age'!$B$2:$B$10401,B36,'CVD_40q30_Age'!$E$2:$E$10401,G36,'CVD_40q30_Age'!$F$2:$F$10401,H36,'CVD_40q30_Age'!$G$2:$G$10401,69))/(SUMIFS('CVD_40q30_Age'!$L$2:$L$10401,'CVD_40q30_Age'!$A$2:$A$10401,A36,'CVD_40q30_Age'!$B$2:$B$10401,B36,'CVD_40q30_Age'!$E$2:$E$10401,G36,'CVD_40q30_Age'!$F$2:$F$10401,H36,'CVD_40q30_Age'!$G$2:$G$10401,30))) | J36: =SUMIFS($I$2:$I$261,$A$2:$A$261,A36,$G$2:$G$261,G36,$H$2:$H$261,H36,$B$2:$B$261,"baseline") | K36: =J36-I36 | L36: =IF(J36=0,"",100*(J36-I36)/J36) | M36: 13.14763 | N36: =IF(ABS(I36-M36)<=0.001,"match","mismatch")
A37: Indonesia | B37: I_PH_TOBACCO_TAX | C37: Tobacco tax | D37: public_health | E37: standalone | G37: htncov2_aspirational | H37: 2034 | I37: =100*(1-(SUMIFS('CVD_40q30_Age'!$M$2:$M$10401,'CVD_40q30_Age'!$A$2:$A$10401,A37,'CVD_40q30_Age'!$B$2:$B$10401,B37,'CVD_40q30_Age'!$E$2:$E$10401,G37,'CVD_40q30_Age'!$F$2:$F$10401,H37,'CVD_40q30_Age'!$G$2:$G$10401,69))/(SUMIFS('CVD_40q30_Age'!$L$2:$L$10401,'CVD_40q30_Age'!$A$2:$A$10401,A37,'CVD_40q30_Age'!$B$2:$B$10401,B37,'CVD_40q30_Age'!$E$2:$E$10401,G37,'CVD_40q30_Age'!$F$2:$F$10401,H37,'CVD_40q30_Age'!$G$2:$G$10401,30))) | J37: =SUMIFS($I$2:$I$261,$A$2:$A$261,A37,$G$2:$G$261,G37,$H$2:$H$261,H37,$B$2:$B$261,"baseline") | K37: =J37-I37 | L37: =IF(J37=0,"",100*(J37-I37)/J37) | M37: 13.044187 | N37: =IF(ABS(I37-M37)<=0.001,"match","mismatch")
A38: Indonesia | B38: I_PH_TOBACCO_TAX | C38: Tobacco tax | D38: public_health | E38: standalone | G38: htncov2_aspirational | H38: 2035 | I38: =100*(1-(SUMIFS('CVD_40q30_Age'!$M$2:$M$10401,'CVD_40q30_Age'!$A$2:$A$10401,A38,'CVD_40q30_Age'!$B$2:$B$10401,B38,'CVD_40q30_Age'!$E$2:$E$10401,G38,'CVD_40q30_Age'!$F$2:$F$10401,H38,'CVD_40q30_Age'!$G$2:$G$10401,69))/(SUMIFS('CVD_40q30_Age'!$L$2:$L$10401,'CVD_40q30_Age'!$A$2:$A$10401,A38,'CVD_40q30_Age'!$B$2:$B$10401,B38,'CVD_40q30_Age'!$E$2:$E$10401,G38,'CVD_40q30_Age'!$F$2:$F$10401,H38,'CVD_40q30_Age'!$G$2:$G$10401,30))) | J38: =SUMIFS($I$2:$I$261,$A$2:$A$261,A38,$G$2:$G$261,G38,$H$2:$H$261,H38,$B$2:$B$261,"baseline") | K38: =J38-I38 | L38: =IF(J38=0,"",100*(J38-I38)/J38) | M38: 12.929814 | N38: =IF(ABS(I38-M38)<=0.001,"match","mismatch")
A39: Indonesia | B39: I_PH_TOBACCO_TAX | C39: Tobacco tax | D39: public_health | E39: standalone | G39: htncov2_aspirational | H39: 2036 | I39: =100*(1-(SUMIFS('CVD_40q30_Age'!$M$2:$M$10401,'CVD_40q30_Age'!$A$2:$A$10401,A39,'CVD_40q30_Age'!$B$2:$B$10401,B39,'CVD_40q30_Age'!$E$2:$E$10401,G39,'CVD_40q30_Age'!$F$2:$F$10401,H39,'CVD_40q30_Age'!$G$2:$G$10401,69))/(SUMIFS('CVD_40q30_Age'!$L$2:$L$10401,'CVD_40q30_Age'!$A$2:$A$10401,A39,'CVD_40q30_Age'!$B$2:$B$10401,B39,'CVD_40q30_Age'!$E$2:$E$10401,G39,'CVD_40q30_Age'!$F$2:$F$10401,H39,'CVD_40q30_Age'!$G$2:$G$10401,30))) | J39: =SUMIFS($I$2:$I$261,$A$2:$A$261,A39,$G$2:$G$261,G39,$H$2:$H$261,H39,$B$2:$B$261,"baseline") | K39: =J39-I39 | L39: =IF(J39=0,"",100*(J39-I39)/J39) | M39: 12.730235 | N39: =IF(ABS(I39-M39)<=0.001,"match","mismatch")
