Workbook

Sheet README
A1: Indonesia NCD FAIR Choices - cost & value workbook (formula edition)
A3: section | B3: detail
A4: Purpose | B4: Costing, budget impact and mortality-based cost-effectiveness for the FAIR Choices CVD interventions selected in indonesia_model_inputs.xlsx.
A5: How to read | B5: Grey cells are R-generated source values; light-blue cells are LIVE Excel formulas; pale-yellow cells on Calculation_Assumptions are editable controls. Change a yellow control and the blue results recompute. Calculation_Map lists every dependency.
A6: Scenarios | B6: Baseline + one scenario per selected valid intervention + a combined 'all' scenario. Membership derives only from the workbook selections (Model 04).
A7: Baseline pairing | B7: Deaths averted = baseline deaths - scenario deaths, matched at location x year x age x sex x cause (aggregated to year x cause here).
A8: Model aggregates | B8: Annual_Mortality carries the R health aggregates (cases, deaths, baseline); Annual_Cost carries the full-precision R population quantity before the PIN fraction. The 157k-row state trace stays in the companion R workbook.
A9: Costing | B9: annual_cost = population_in_need x coverage(t) x frequency x unit_cost. PIN measure maps 'all'->eligible population, 'prevalence'->sick stock, 'incidence'->new cases.
A10: Shared costs | B10: Components flagged 'shared-count-once' (cost_join_key ...__C_SHARED) are counted once at intervention level, never once per affected cause (see Annual_Cost shared_duplicate_count and QA).
A11: Budget impact | B11: Budget impact reports UNDISCOUNTED baseline, scenario, incremental and cumulative incremental cost. Discounted costs are separate columns.
A12: Cost-effectiveness | B12: USD per death averted = cumulative discounted incremental cost / cumulative (undiscounted) deaths averted over the horizon. Not a DALY-based ICER.
A13: Economic value | B13: Value of statistical life (VSL/VSLY) is reused from Model 08 as R source values; only the cost link, supplementary benefit-cost ratio and net benefit are recalculated here.
A14: QA & reconciliation | B14: QA_Checks recomputes each invariant in Excel and reconciles the Excel cost-effectiveness headline against the R engine values stored on Calculation_Assumptions. PASS/FAIL/REVIEW are conditionally formatted.
... A17: Deferred | B17: DALYs, YLL, YLD, disability weights and life-expectancy outcomes are deferred to later work and are NOT in this workbook.

Sheet Run_Metadata
A1: item | B1: value
A2: Workbook title | B2: Indonesia NCD FAIR Choices - cost & value
A3: Run date | B3: 2026-08-21
A4: Model / pipeline | B4: CVD FAIR Choices (Models 00-06 -> 09)
A5: Input workbook | B5: C:/Users/wrgar/OneDrive - UW/02Work/WorldBank-Indonesia/uw-wb-indonesia-ncd/data/indonesia_model_inputs.xlsx
A6: Model output source | B6: output/out_model/model_output_*.rds (Model 06)
A7: Location | B7: Indonesia
A8: Analysis years | B8: ='Calculation_Assumptions'!B2&"-"&'Calculation_Assumptions'!B3
A9: Baseline scenario | B9: ='Calculation_Assumptions'!B4
A10: Scenarios costed | B10: I_CVD_PRIMARY, I_HF_ACUTE, I_HF_CHRONIC, I_IHD_SECONDARY, I_RHD_SECONDARY, I_RHD_SURGERY, I_STROKE_SECONDARY, I_T2D_TREATMENT, all
A11: Cost discount rate | B11: ='Calculation_Assumptions'!B5
A12: Cost price year | B12: ='Calculation_Assumptions'!B6
A13: Currency | B13: ='Calculation_Assumptions'!B7
A14: Economic perspective | B14: ='Calculation_Assumptions'!B8
A15: Coverage scale-up shape | B15: ='Calculation_Assumptions'!B9
A16: Downstream cost offsets | B16: ='Calculation_Assumptions'!B10
A17: Health outcomes (DALYs/YLL/YLD) | B17: Out of scope in this stage (deferred)
A18: R version | B18: R version 4.5.1 (2025-06-13 ucrt)
A19: openxlsx / data.table | B19: 4.2.8 / 1.17.8

Sheet Selected_Interventions
A1: intervention_id | B1: intervention_cause_key | C1: intervention_name | D1: cause_id | E1: cause_code | F1: model_name | G1: transition_from | H1: transition_to | I1: model_transition | J1: effect_value | K1: affected_fraction | L1: baseline_coverage | M1: target_coverage | N1: start_year | O1: target_year | P1: adjusted_effect_at_target | Q1: cost_join_key | R1: cost_scope | S1: effect_review | T1: coverage_review | U1: key_count | V1: formula_status
A2: I_CVD_PRIMARY | B2: I_CVD_PRIMARY__C_HHD | C2: Primary prevention of CVD | D2: C_HHD | E2: hhd | F2: Hypertensive heart disease | G2: well | H2: sick | I2: incidence | J2: 0.47 | K2: 1 | L2: 0.31 | M2: 0.8 | N2: 2025 | O2: 2050 | P2: =IF(OR(J2="",K2="",L2="",M2=""),"",ROUND(K2*(J2*(M2-L2)/(1-J2*L2)),4)) | Q2: I_CVD_PRIMARY__C_SHARED | R2: shared-count-once | S2: Provisional | T2: Provisional | U2: =COUNTIF($B$2:$B$18,B2) | V2: =IF(U2=1,"OK","DUPLICATE KEY")
A3: I_CVD_PRIMARY | B3: I_CVD_PRIMARY__C_ICH | C3: Primary prevention of CVD | D3: C_ICH | E3: hstroke | F3: Intracerebral hemorrhage | G3: well | H3: sick | I3: incidence | J3: 0.49 | K3: 0.8 | L3: 0.31 | M3: 0.8 | N3: 2025 | O3: 2050 | P3: =IF(OR(J3="",K3="",L3="",M3=""),"",ROUND(K3*(J3*(M3-L3)/(1-J3*L3)),4)) | Q3: I_CVD_PRIMARY__C_SHARED | R3: shared-count-once | S3: Provisional | T3: Provisional | U3: =COUNTIF($B$2:$B$18,B3) | V3: =IF(U3=1,"OK","DUPLICATE KEY")
A4: I_CVD_PRIMARY | B4: I_CVD_PRIMARY__C_IHD | C4: Primary prevention of CVD | D4: C_IHD | E4: ihd | F4: Ischemic heart disease | G4: well | H4: sick | I4: incidence | J4: 0.58 | K4: 0.8 | L4: 0.31 | M4: 0.8 | N4: 2025 | O4: 2050 | P4: =IF(OR(J4="",K4="",L4="",M4=""),"",ROUND(K4*(J4*(M4-L4)/(1-J4*L4)),4)) | Q4: I_CVD_PRIMARY__C_SHARED | R4: shared-count-once | S4: Provisional | T4: Provisional | U4: =COUNTIF($B$2:$B$18,B4) | V4: =IF(U4=1,"OK","DUPLICATE KEY")
A5: I_CVD_PRIMARY | B5: I_CVD_PRIMARY__C_IS | C5: Primary prevention of CVD | D5: C_IS | E5: istroke | F5: Ischemic stroke | G5: well | H5: sick | I5: incidence | J5: 0.54 | K5: 0.8 | L5: 0.31 | M5: 0.8 | N5: 2025 | O5: 2050 | P5: =IF(OR(J5="",K5="",L5="",M5=""),"",ROUND(K5*(J5*(M5-L5)/(1-J5*L5)),4)) | Q5: I_CVD_PRIMARY__C_SHARED | R5: shared-count-once | S5: Provisional | T5: Provisional | U5: =COUNTIF($B$2:$B$18,B5) | V5: =IF(U5=1,"OK","DUPLICATE KEY")
A6: I_HF_ACUTE | B6: I_HF_ACUTE__C_CMP | C6: Acute heart-failure management | D6: C_CMP | E6: cmd | F6: Cardiomyopathy and myocarditis | G6: sick_hf | H6: dead_cmp | I6: case_fatality | J6: 0.74 | K6: 0.2 | L6: 0.31 | M6: 0.8 | N6: 2025 | O6: 2050 | P6: =IF(OR(J6="",K6="",L6="",M6=""),"",ROUND(K6*(J6*(M6-L6)/(1-J6*L6)),4)) | Q6: I_HF_ACUTE__C_CMP | R6: cause-specific | S6: Provisional | T6: Provisional | U6: =COUNTIF($B$2:$B$18,B6) | V6: =IF(U6=1,"OK","DUPLICATE KEY")
A7: I_HF_ACUTE | B7: I_HF_ACUTE__C_HHD | C7: Acute heart-failure management | D7: C_HHD | E7: hhd | F7: Hypertensive heart disease | G7: sick_hf | H7: dead_hhd | I7: case_fatality | J7: 0.74 | K7: 0.2 | L7: 0.31 | M7: 0.8 | N7: 2025 | O7: 2050 | P7: =IF(OR(J7="",K7="",L7="",M7=""),"",ROUND(K7*(J7*(M7-L7)/(1-J7*L7)),4)) | Q7: I_HF_ACUTE__C_HHD | R7: cause-specific | S7: Provisional | T7: Provisional | U7: =COUNTIF($B$2:$B$18,B7) | V7: =IF(U7=1,"OK","DUPLICATE KEY")
A8: I_HF_ACUTE | B8: I_HF_ACUTE__C_IHD | C8: Acute heart-failure management | D8: C_IHD | E8: ihd | F8: Ischemic heart disease | G8: sick_hf | H8: dead_ihd | I8: case_fatality | J8: 0.18 | K8: 0.05 | L8: 0.31 | M8: 0.8 | N8: 2025 | O8: 2050 | P8: =IF(OR(J8="",K8="",L8="",M8=""),"",ROUND(K8*(J8*(M8-L8)/(1-J8*L8)),4)) | Q8: I_HF_ACUTE__C_IHD | R8: cause-specific | S8: Provisional | T8: Provisional | U8: =COUNTIF($B$2:$B$18,B8) | V8: =IF(U8=1,"OK","DUPLICATE KEY")
A9: I_HF_CHRONIC | B9: I_HF_CHRONIC__C_CMP | C9: Chronic heart-failure management | D9: C_CMP | E9: cmd | F9: Cardiomyopathy and myocarditis | G9: sick_hf | H9: dead_cmp | I9: case_fatality | J9: 0.536 | K9: 0.8 | L9: 0.31 | M9: 0.8 | N9: 2025 | O9: 2050 | P9: =IF(OR(J9="",K9="",L9="",M9=""),"",ROUND(K9*(J9*(M9-L9)/(1-J9*L9)),4)) | Q9: I_HF_CHRONIC__C_CMP | R9: cause-specific | S9: Provisional | T9: Provisional | U9: =COUNTIF($B$2:$B$18,B9) | V9: =IF(U9=1,"OK","DUPLICATE KEY")
A10: I_HF_CHRONIC | B10: I_HF_CHRONIC__C_HHD | C10: Chronic heart-failure management | D10: C_HHD | E10: hhd | F10: Hypertensive heart disease | G10: sick_hf | H10: dead_hhd | I10: case_fatality | J10: 0.275 | K10: 0.8 | L10: 0.31 | M10: 0.8 | N10: 2025 | O10: 2050 | P10: =IF(OR(J10="",K10="",L10="",M10=""),"",ROUND(K10*(J10*(M10-L10)/(1-J10*L10)),4)) | Q10: I_HF_CHRONIC__C_HHD | R10: cause-specific | S10: Provisional | T10: Provisional | U10: =COUNTIF($B$2:$B$18,B10) | V10: =IF(U10=1,"OK","DUPLICATE KEY")
A11: I_HF_CHRONIC | B11: I_HF_CHRONIC__C_IHD | C11: Chronic heart-failure management | D11: C_IHD | E11: ihd | F11: Ischemic heart disease | G11: sick_hf | H11: dead_ihd | I11: case_fatality | J11: 0.093 | K11: 0.2 | L11: 0.31 | M11: 0.8 | N11: 2025 | O11: 2050 | P11: =IF(OR(J11="",K11="",L11="",M11=""),"",ROUND(K11*(J11*(M11-L11)/(1-J11*L11)),4)) | Q11: I_HF_CHRONIC__C_IHD | R11: cause-specific | S11: Provisional | T11: Provisional | U11: =COUNTIF($B$2:$B$18,B11) | V11: =IF(U11=1,"OK","DUPLICATE KEY")
A12: I_IHD_SECONDARY | B12: I_IHD_SECONDARY__C_IHD | C12: Secondary prevention of ischemic heart disease | D12: C_IHD | E12: ihd | F12: Ischemic heart disease | G12: sick | H12: dead_ihd | I12: case_fatality | J12: 0.5822 | K12: 0.2 | L12: 0.31 | M12: 0.8 | N12: 2025 | O12: 2050 | P12: =IF(OR(J12="",K12="",L12="",M12=""),"",ROUND(K12*(J12*(M12-L12)/(1-J12*L12)),4)) | Q12: I_IHD_SECONDARY__C_IHD | R12: cause-specific | S12: Provisional | T12: Provisional | U12: =COUNTIF($B$2:$B$18,B12) | V12: =IF(U12=1,"OK","DUPLICATE KEY")
A13: I_RHD_SECONDARY | B13: I_RHD_SECONDARY__C_RHD | C13: RHD secondary prevention | D13: C_RHD | E13: rhd | F13: Rheumatic heart disease | G13: sick | H13: dead_rhd | I13: case_fatality | J13: 0.55 | K13: 1 | L13: 0.31 | M13: 0.8 | N13: 2025 | O13: 2050 | P13: =IF(OR(J13="",K13="",L13="",M13=""),"",ROUND(K13*(J13*(M13-L13)/(1-J13*L13)),4)) | Q13: I_RHD_SECONDARY__C_RHD | R13: cause-specific | S13: Provisional | T13: Provisional | U13: =COUNTIF($B$2:$B$18,B13) | V13: =IF(U13=1,"OK","DUPLICATE KEY")
... A18: I_T2D_TREATMENT | B18: I_T2D_TREATMENT__C_IHD | C18: Longitudinal treatment of type 2 diabetes | D18: C_IHD | E18: ihd | F18: Ischemic heart disease | G18: sick | H18: dead_ihd | I18: case_fatality | J18: 0.15 | K18: 0.15 | L18: 0.31 | M18: 0.8 | N18: 2025 | O18: 2050 | P18: =IF(OR(J18="",K18="",L18="",M18=""),"",ROUND(K18*(J18*(M18-L18)/(1-J18*L18)),4)) | Q18: I_T2D_TREATMENT__C_T2D | R18: shared-count-once | S18: Review | T18: Missing input | U18: =COUNTIF($B$2:$B$18,B18) | V18: =IF(U18=1,"OK","DUPLICATE KEY")

Sheet Cost_Components
A1: cost_record_id | B1: cost_component_key | C1: cost_option | D1: intervention_id | E1: cause_id | F1: cause_code | G1: cost_join_key | H1: cost_scope | I1: cost_component | J1: population_in_need_measure | K1: population_in_need_fraction | L1: frequency_per_year | M1: c_age_start | N1: c_age_stop | O1: c_sex | P1: unit_cost_usd | Q1: price_year | R1: indonesia_adjusted_flag | S1: cov_baseline | T1: cov_target | U1: cov_start_year | V1: cov_target_year | W1: cost_review | X1: cost_ready
A2: COST_PRIMARY_TX_A | B2: CC_PRIMARY_HTN_STATIN | C2: Option A (selected) | D2: I_CVD_PRIMARY | E2: C_SHARED | G2: I_CVD_PRIMARY__C_SHARED | H2: shared-count-once | I2: Antihypertensives and statins for absolute CVD risk >20% | J2: all | K2: 0.06 | L2: 1 | M2: 30 | N2: 95 | O2: Both | P2: 22.2296 | Q2: 2023 | R2: 1 | S2: =IFERROR(INDEX('Selected_Interventions'!$L$2:$L$18,MATCH(G2,'Selected_Interventions'!$Q$2:$Q$18,0)),"") | T2: =IFERROR(INDEX('Selected_Interventions'!$M$2:$M$18,MATCH(G2,'Selected_Interventions'!$Q$2:$Q$18,0)),"") | U2: =IFERROR(INDEX('Selected_Interventions'!$N$2:$N$18,MATCH(G2,'Selected_Interventions'!$Q$2:$Q$18,0)),"") | V2: =IFERROR(INDEX('Selected_Interventions'!$O$2:$O$18,MATCH(G2,'Selected_Interventions'!$Q$2:$Q$18,0)),"") | W2: Review | X2: =IF(AND(P2<>"",P2>=0,S2<>"",K2<>"",K2>=0,K2<=1,OR(J2="all",J2="prevalence",J2="incidence")),1,0)
A3: COST_PRIMARY_SCREEN_A | B3: CC_PRIMARY_SCREENING | C3: Option A (selected) | D3: I_CVD_PRIMARY | E3: C_SHARED | G3: I_CVD_PRIMARY__C_SHARED | H3: shared-count-once | I3: CVD targeted screening | J3: all | K3: 0.2 | L3: 1 | M3: 30 | N3: 95 | O3: Both | P3: 1.291584 | Q3: 2023 | R3: 1 | S3: =IFERROR(INDEX('Selected_Interventions'!$L$2:$L$18,MATCH(G3,'Selected_Interventions'!$Q$2:$Q$18,0)),"") | T3: =IFERROR(INDEX('Selected_Interventions'!$M$2:$M$18,MATCH(G3,'Selected_Interventions'!$Q$2:$Q$18,0)),"") | U3: =IFERROR(INDEX('Selected_Interventions'!$N$2:$N$18,MATCH(G3,'Selected_Interventions'!$Q$2:$Q$18,0)),"") | V3: =IFERROR(INDEX('Selected_Interventions'!$O$2:$O$18,MATCH(G3,'Selected_Interventions'!$Q$2:$Q$18,0)),"") | W3: Review | X3: =IF(AND(P3<>"",P3>=0,S3<>"",K3<>"",K3>=0,K3<=1,OR(J3="all",J3="prevalence",J3="incidence")),1,0)
A4: COST_HF_ACUTE_C_CMP | B4: CC_HF_ACUTE_C_CMP | C4: Base | D4: I_HF_ACUTE | E4: C_CMP | F4: cmd | G4: I_HF_ACUTE__C_CMP | H4: cause-specific | I4: Acute heart-failure management package | J4: prevalence | K4: 0.5 | L4: 1 | M4: 30 | N4: 95 | O4: Both | P4: 282.51284 | Q4: 2023 | R4: 1 | S4: =IFERROR(INDEX('Selected_Interventions'!$L$2:$L$18,MATCH(G4,'Selected_Interventions'!$Q$2:$Q$18,0)),"") | T4: =IFERROR(INDEX('Selected_Interventions'!$M$2:$M$18,MATCH(G4,'Selected_Interventions'!$Q$2:$Q$18,0)),"") | U4: =IFERROR(INDEX('Selected_Interventions'!$N$2:$N$18,MATCH(G4,'Selected_Interventions'!$Q$2:$Q$18,0)),"") | V4: =IFERROR(INDEX('Selected_Interventions'!$O$2:$O$18,MATCH(G4,'Selected_Interventions'!$Q$2:$Q$18,0)),"") | W4: Provisional | X4: =IF(AND(P4<>"",P4>=0,S4<>"",K4<>"",K4>=0,K4<=1,OR(J4="all",J4="prevalence",J4="incidence")),1,0)
A5: COST_HF_ACUTE_C_HHD | B5: CC_HF_ACUTE_C_HHD | C5: Base | D5: I_HF_ACUTE | E5: C_HHD | F5: hhd | G5: I_HF_ACUTE__C_HHD | H5: cause-specific | I5: Acute heart-failure management package | J5: prevalence | K5: 0.5 | L5: 1 | M5: 30 | N5: 95 | O5: Both | P5: 282.51284 | Q5: 2023 | R5: 1 | S5: =IFERROR(INDEX('Selected_Interventions'!$L$2:$L$18,MATCH(G5,'Selected_Interventions'!$Q$2:$Q$18,0)),"") | T5: =IFERROR(INDEX('Selected_Interventions'!$M$2:$M$18,MATCH(G5,'Selected_Interventions'!$Q$2:$Q$18,0)),"") | U5: =IFERROR(INDEX('Selected_Interventions'!$N$2:$N$18,MATCH(G5,'Selected_Interventions'!$Q$2:$Q$18,0)),"") | V5: =IFERROR(INDEX('Selected_Interventions'!$O$2:$O$18,MATCH(G5,'Selected_Interventions'!$Q$2:$Q$18,0)),"") | W5: Provisional | X5: =IF(AND(P5<>"",P5>=0,S5<>"",K5<>"",K5>=0,K5<=1,OR(J5="all",J5="prevalence",J5="incidence")),1,0)
A6: COST_HF_ACUTE_C_IHD | B6: CC_HF_ACUTE_C_IHD | C6: Base | D6: I_HF_ACUTE | E6: C_IHD | F6: ihd | G6: I_HF_ACUTE__C_IHD | H6: cause-specific | I6: Acute heart-failure management package | J6: prevalence | K6: 0.1 | L6: 1 | M6: 30 | N6: 95 | O6: Both | P6: 282.51284 | Q6: 2023 | R6: 1 | S6: =IFERROR(INDEX('Selected_Interventions'!$L$2:$L$18,MATCH(G6,'Selected_Interventions'!$Q$2:$Q$18,0)),"") | T6: =IFERROR(INDEX('Selected_Interventions'!$M$2:$M$18,MATCH(G6,'Selected_Interventions'!$Q$2:$Q$18,0)),"") | U6: =IFERROR(INDEX('Selected_Interventions'!$N$2:$N$18,MATCH(G6,'Selected_Interventions'!$Q$2:$Q$18,0)),"") | V6: =IFERROR(INDEX('Selected_Interventions'!$O$2:$O$18,MATCH(G6,'Selected_Interventions'!$Q$2:$Q$18,0)),"") | W6: Provisional | X6: =IF(AND(P6<>"",P6>=0,S6<>"",K6<>"",K6>=0,K6<=1,OR(J6="all",J6="prevalence",J6="incidence")),1,0)
A7: COST_HF_CHRONIC_CMP_ECHO | B7: CC_HF_CHRONIC_CMP_ECHO | C7: Base | D7: I_HF_CHRONIC | E7: C_CMP | F7: cmd | G7: I_HF_CHRONIC__C_CMP | H7: cause-specific | I7: One cardiac echo per year | J7: prevalence | K7: 1 | L7: 1 | M7: 0 | N7: 95 | O7: Both | P7: 5.133311 | Q7: 2023 | R7: 1 | S7: =IFERROR(INDEX('Selected_Interventions'!$L$2:$L$18,MATCH(G7,'Selected_Interventions'!$Q$2:$Q$18,0)),"") | T7: =IFERROR(INDEX('Selected_Interventions'!$M$2:$M$18,MATCH(G7,'Selected_Interventions'!$Q$2:$Q$18,0)),"") | U7: =IFERROR(INDEX('Selected_Interventions'!$N$2:$N$18,MATCH(G7,'Selected_Interventions'!$Q$2:$Q$18,0)),"") | V7: =IFERROR(INDEX('Selected_Interventions'!$O$2:$O$18,MATCH(G7,'Selected_Interventions'!$Q$2:$Q$18,0)),"") | W7: Provisional | X7: =IF(AND(P7<>"",P7>=0,S7<>"",K7<>"",K7>=0,K7<=1,OR(J7="all",J7="prevalence",J7="incidence")),1,0)
A8: COST_HF_CHRONIC_CMP_LAB_A | B8: CC_HF_CHRONIC_CMP_FOLLOWUP | C8: Option A (selected) | D8: I_HF_CHRONIC | E8: C_CMP | F8: cmd | G8: I_HF_CHRONIC__C_CMP | H8: cause-specific | I8: Lab tests and follow-up visits | J8: prevalence | K8: 1 | L8: 1 | M8: 0 | N8: 95 | O8: Both | P8: 35.362649 | Q8: 2023 | R8: 1 | S8: =IFERROR(INDEX('Selected_Interventions'!$L$2:$L$18,MATCH(G8,'Selected_Interventions'!$Q$2:$Q$18,0)),"") | T8: =IFERROR(INDEX('Selected_Interventions'!$M$2:$M$18,MATCH(G8,'Selected_Interventions'!$Q$2:$Q$18,0)),"") | U8: =IFERROR(INDEX('Selected_Interventions'!$N$2:$N$18,MATCH(G8,'Selected_Interventions'!$Q$2:$Q$18,0)),"") | V8: =IFERROR(INDEX('Selected_Interventions'!$O$2:$O$18,MATCH(G8,'Selected_Interventions'!$Q$2:$Q$18,0)),"") | W8: Review | X8: =IF(AND(P8<>"",P8>=0,S8<>"",K8<>"",K8>=0,K8<=1,OR(J8="all",J8="prevalence",J8="incidence")),1,0)
A9: COST_HF_CHRONIC_CMP_TX | B9: CC_HF_CHRONIC_CMP_TREATMENT | C9: Base | D9: I_HF_CHRONIC | E9: C_CMP | F9: cmd | G9: I_HF_CHRONIC__C_CMP | H9: cause-specific | I9: Treatment of heart failure | J9: prevalence | K9: 1 | L9: 1 | M9: 0 | N9: 95 | O9: Both | P9: 115.10623 | Q9: 2023 | R9: 1 | S9: =IFERROR(INDEX('Selected_Interventions'!$L$2:$L$18,MATCH(G9,'Selected_Interventions'!$Q$2:$Q$18,0)),"") | T9: =IFERROR(INDEX('Selected_Interventions'!$M$2:$M$18,MATCH(G9,'Selected_Interventions'!$Q$2:$Q$18,0)),"") | U9: =IFERROR(INDEX('Selected_Interventions'!$N$2:$N$18,MATCH(G9,'Selected_Interventions'!$Q$2:$Q$18,0)),"") | V9: =IFERROR(INDEX('Selected_Interventions'!$O$2:$O$18,MATCH(G9,'Selected_Interventions'!$Q$2:$Q$18,0)),"") | W9: Provisional | X9: =IF(AND(P9<>"",P9>=0,S9<>"",K9<>"",K9>=0,K9<=1,OR(J9="all",J9="prevalence",J9="incidence")),1,0)
A10: COST_HF_CHRONIC_HHD_ECHO | B10: CC_HF_CHRONIC_HHD_ECHO | C10: Base | D10: I_HF_CHRONIC | E10: C_HHD | F10: hhd | G10: I_HF_CHRONIC__C_HHD | H10: cause-specific | I10: One cardiac echo per year | J10: prevalence | K10: 1 | L10: 1 | M10: 30 | N10: 95 | O10: Both | P10: 5.133311 | Q10: 2023 | R10: 1 | S10: =IFERROR(INDEX('Selected_Interventions'!$L$2:$L$18,MATCH(G10,'Selected_Interventions'!$Q$2:$Q$18,0)),"") | T10: =IFERROR(INDEX('Selected_Interventions'!$M$2:$M$18,MATCH(G10,'Selected_Interventions'!$Q$2:$Q$18,0)),"") | U10: =IFERROR(INDEX('Selected_Interventions'!$N$2:$N$18,MATCH(G10,'Selected_Interventions'!$Q$2:$Q$18,0)),"") | V10: =IFERROR(INDEX('Selected_Interventions'!$O$2:$O$18,MATCH(G10,'Selected_Interventions'!$Q$2:$Q$18,0)),"") | W10: Provisional | X10: =IF(AND(P10<>"",P10>=0,S10<>"",K10<>"",K10>=0,K10<=1,OR(J10="all",J10="prevalence",J10="incidence")),1,0)
A11: COST_HF_CHRONIC_HHD_LAB_A | B11: CC_HF_CHRONIC_HHD_FOLLOWUP | C11: Option A (selected) | D11: I_HF_CHRONIC | E11: C_HHD | F11: hhd | G11: I_HF_CHRONIC__C_HHD | H11: cause-specific | I11: Lab tests and follow-up visits | J11: prevalence | K11: 1 | L11: 1 | M11: 30 | N11: 95 | O11: Both | P11: 35.362649 | Q11: 2023 | R11: 1 | S11: =IFERROR(INDEX('Selected_Interventions'!$L$2:$L$18,MATCH(G11,'Selected_Interventions'!$Q$2:$Q$18,0)),"") | T11: =IFERROR(INDEX('Selected_Interventions'!$M$2:$M$18,MATCH(G11,'Selected_Interventions'!$Q$2:$Q$18,0)),"") | U11: =IFERROR(INDEX('Selected_Interventions'!$N$2:$N$18,MATCH(G11,'Selected_Interventions'!$Q$2:$Q$18,0)),"") | V11: =IFERROR(INDEX('Selected_Interventions'!$O$2:$O$18,MATCH(G11,'Selected_Interventions'!$Q$2:$Q$18,0)),"") | W11: Review | X11: =IF(AND(P11<>"",P11>=0,S11<>"",K11<>"",K11>=0,K11<=1,OR(J11="all",J11="prevalence",J11="incidence")),1,0)
A12: COST_HF_CHRONIC_HHD_TX | B12: CC_HF_CHRONIC_HHD_TREATMENT | C12: Base | D12: I_HF_CHRONIC | E12: C_HHD | F12: hhd | G12: I_HF_CHRONIC__C_HHD | H12: cause-specific | I12: Treatment of heart failure | J12: prevalence | K12: 1 | L12: 1 | M12: 0 | N12: 95 | O12: Both | P12: 115.10623 | Q12: 2023 | R12: 1 | S12: =IFERROR(INDEX('Selected_Interventions'!$L$2:$L$18,MATCH(G12,'Selected_Interventions'!$Q$2:$Q$18,0)),"") | T12: =IFERROR(INDEX('Selected_Interventions'!$M$2:$M$18,MATCH(G12,'Selected_Interventions'!$Q$2:$Q$18,0)),"") | U12: =IFERROR(INDEX('Selected_Interventions'!$N$2:$N$18,MATCH(G12,'Selected_Interventions'!$Q$2:$Q$18,0)),"") | V12: =IFERROR(INDEX('Selected_Interventions'!$O$2:$O$18,MATCH(G12,'Selected_Interventions'!$Q$2:$Q$18,0)),"") | W12: Provisional | X12: =IF(AND(P12<>"",P12>=0,S12<>"",K12<>"",K12>=0,K12<=1,OR(J12="all",J12="prevalence",J12="incidence")),1,0)
A13: COST_HF_CHRONIC_IHD_ECHO | B13: CC_HF_CHRONIC_IHD_ECHO | C13: Base | D13: I_HF_CHRONIC | E13: C_IHD | F13: ihd | G13: I_HF_CHRONIC__C_IHD | H13: cause-specific | I13: One cardiac echo per year | J13: prevalence | K13: 0.2 | L13: 1 | M13: 30 | N13: 95 | O13: Both | P13: 5.133311 | Q13: 2023 | R13: 1 | S13: =IFERROR(INDEX('Selected_Interventions'!$L$2:$L$18,MATCH(G13,'Selected_Interventions'!$Q$2:$Q$18,0)),"") | T13: =IFERROR(INDEX('Selected_Interventions'!$M$2:$M$18,MATCH(G13,'Selected_Interventions'!$Q$2:$Q$18,0)),"") | U13: =IFERROR(INDEX('Selected_Interventions'!$N$2:$N$18,MATCH(G13,'Selected_Interventions'!$Q$2:$Q$18,0)),"") | V13: =IFERROR(INDEX('Selected_Interventions'!$O$2:$O$18,MATCH(G13,'Selected_Interventions'!$Q$2:$Q$18,0)),"") | W13: Provisional | X13: =IF(AND(P13<>"",P13>=0,S13<>"",K13<>"",K13>=0,K13<=1,OR(J13="all",J13="prevalence",J13="incidence")),1,0)
A14: COST_HF_CHRONIC_IHD_LAB | B14: CC_HF_CHRONIC_IHD_FOLLOWUP | C14: Missing | D14: I_HF_CHRONIC | E14: C_IHD | F14: ihd | G14: I_HF_CHRONIC__C_IHD | H14: cause-specific | I14: Lab tests and follow-up visits | J14: prevalence | K14: 0.2 | L14: 1 | M14: 30 | N14: 95 | O14: Both | P14: 7 | Q14: 2023 | R14: 1 | S14: =IFERROR(INDEX('Selected_Interventions'!$L$2:$L$18,MATCH(G14,'Selected_Interventions'!$Q$2:$Q$18,0)),"") | T14: =IFERROR(INDEX('Selected_Interventions'!$M$2:$M$18,MATCH(G14,'Selected_Interventions'!$Q$2:$Q$18,0)),"") | U14: =IFERROR(INDEX('Selected_Interventions'!$N$2:$N$18,MATCH(G14,'Selected_Interventions'!$Q$2:$Q$18,0)),"") | V14: =IFERROR(INDEX('Selected_Interventions'!$O$2:$O$18,MATCH(G14,'Selected_Interventions'!$Q$2:$Q$18,0)),"") | W14: Missing input | X14: =IF(AND(P14<>"",P14>=0,S14<>"",K14<>"",K14>=0,K14<=1,OR(J14="all",J14="prevalence",J14="incidence")),1,0)
A15: COST_HF_CHRONIC_IHD_TX | B15: CC_HF_CHRONIC_IHD_TREATMENT | C15: Base | D15: I_HF_CHRONIC | E15: C_IHD | F15: ihd | G15: I_HF_CHRONIC__C_IHD | H15: cause-specific | I15: Treatment of heart failure | J15: prevalence | K15: 0.2 | L15: 1 | M15: 30 | N15: 95 | O15: Both | P15: 29.216219 | Q15: 2023 | R15: 1 | S15: =IFERROR(INDEX('Selected_Interventions'!$L$2:$L$18,MATCH(G15,'Selected_Interventions'!$Q$2:$Q$18,0)),"") | T15: =IFERROR(INDEX('Selected_Interventions'!$M$2:$M$18,MATCH(G15,'Selected_Interventions'!$Q$2:$Q$18,0)),"") | U15: =IFERROR(INDEX('Selected_Interventions'!$N$2:$N$18,MATCH(G15,'Selected_Interventions'!$Q$2:$Q$18,0)),"") | V15: =IFERROR(INDEX('Selected_Interventions'!$O$2:$O$18,MATCH(G15,'Selected_Interventions'!$Q$2:$Q$18,0)),"") | W15: Provisional | X15: =IF(AND(P15<>"",P15>=0,S15<>"",K15<>"",K15>=0,K15<=1,OR(J15="all",J15="prevalence",J15="incidence")),1,0)
... A27: COST_T2D_TREATMENT | B27: CC_T2D_TREATMENT | C27: Base | D27: I_T2D_TREATMENT | E27: C_T2D | F27: dm2 | G27: I_T2D_TREATMENT__C_T2D | H27: cause-specific | I27: Diabetes screening and treatment | J27: prevalence | K27: 0.8 | L27: 1 | M27: 0 | N27: 95 | O27: Both | P27: 176.67 | Q27: 2014 | R27: 0 | S27: =IFERROR(INDEX('Selected_Interventions'!$L$2:$L$18,MATCH(G27,'Selected_Interventions'!$Q$2:$Q$18,0)),"") | T27: =IFERROR(INDEX('Selected_Interventions'!$M$2:$M$18,MATCH(G27,'Selected_Interventions'!$Q$2:$Q$18,0)),"") | U27: =IFERROR(INDEX('Selected_Interventions'!$N$2:$N$18,MATCH(G27,'Selected_Interventions'!$Q$2:$Q$18,0)),"") | V27: =IFERROR(INDEX('Selected_Interventions'!$O$2:$O$18,MATCH(G27,'Selected_Interventions'!$Q$2:$Q$18,0)),"") | W27: Review | X27: =IF(AND(P27<>"",P27>=0,S27<>"",K27<>"",K27>=0,K27<=1,OR(J27="all",J27="prevalence",J27="incidence")),1,0)

Sheet Annual_Mortality
A1: scenario | B1: scenario_label | C1: year | D1: cause | E1: cases | F1: cause_deaths | G1: base_deaths | H1: deaths_averted | I1: base_cases | J1: cases_averted
A2: I_CVD_PRIMARY | B2: Primary prevention of CVD | C2: 2025 | D2: cmd | E2: 12176.171 | F2: 8959.2701 | G2: 8959.2701 | H2: =G2-F2 | I2: 12176.171 | J2: =I2-E2
A3: I_CVD_PRIMARY | B3: Primary prevention of CVD | C3: 2025 | D3: dm2 | E3: 1026758.6 | F3: 129383.32 | G3: 129383.32 | H3: =G3-F3 | I3: 1026758.6 | J3: =I3-E3
A4: I_CVD_PRIMARY | B4: Primary prevention of CVD | C4: 2025 | D4: hhd | E4: 114347.21 | F4: 67656.559 | G4: 67656.559 | H4: =G4-F4 | I4: 115291.16 | J4: =I4-E4
A5: I_CVD_PRIMARY | B5: Primary prevention of CVD | C5: 2025 | D5: hstroke | E5: 279608.74 | F5: 263295.7 | G5: 263295.7 | H5: =G5-F5 | I5: 281662.55 | J5: =I5-E5
A6: I_CVD_PRIMARY | B6: Primary prevention of CVD | C6: 2025 | D6: ihd | E6: 606792.13 | F6: 335724.87 | G6: 335724.87 | H6: =G6-F6 | I6: 612171.63 | J6: =I6-E6
A7: I_CVD_PRIMARY | B7: Primary prevention of CVD | C7: 2025 | D7: istroke | E7: 337040.93 | F7: 190841.88 | G7: 190841.88 | H7: =G7-F7 | I7: 339642.13 | J7: =I7-E7
A8: I_CVD_PRIMARY | B8: Primary prevention of CVD | C8: 2025 | D8: rhd | E8: 39660.837 | F8: 5303.4223 | G8: 5303.4223 | H8: =G8-F8 | I8: 39660.837 | J8: =I8-E8
A9: I_CVD_PRIMARY | B9: Primary prevention of CVD | C9: 2026 | D9: cmd | E9: 12568.939 | F9: 9271.1334 | G9: 9271.1334 | H9: =G9-F9 | I9: 12568.939 | J9: =I9-E9
A10: I_CVD_PRIMARY | B10: Primary prevention of CVD | C10: 2026 | D10: dm2 | E10: 1042135.2 | F10: 137145.83 | G10: 137145.83 | H10: =G10-F10 | I10: 1042135.2 | J10: =I10-E10
A11: I_CVD_PRIMARY | B11: Primary prevention of CVD | C11: 2026 | D11: hhd | E11: 112796.49 | F11: 70191.013 | G11: 70326.603 | H11: =G11-F11 | I11: 114707.99 | J11: =I11-E11
A12: I_CVD_PRIMARY | B12: Primary prevention of CVD | C12: 2026 | D12: hstroke | E12: 278609.32 | F12: 258660.04 | G12: 259504.47 | H12: =G12-F12 | I12: 282722.54 | J12: =I12-E12
A13: I_CVD_PRIMARY | B13: Primary prevention of CVD | C13: 2026 | D13: ihd | E13: 605871.29 | F13: 342642.48 | G13: 342960.14 | H13: =G13-F13 | I13: 616790.03 | J13: =I13-E13
... A1821: baseline | B1821: Baseline (no new intervention) | C1821: 2050 | D1821: rhd | E1821: 33926.479 | F1821: 1888.515 | G1821: 1888.515 | H1821: =G1821-F1821 | I1821: 33926.479 | J1821: =I1821-E1821

Sheet Annual_Cost
A1: scenario | B1: year | C1: intervention_id | D1: cause_code | E1: cost_record_id | F1: cost_component_key | G1: cost_join_key | H1: cost_scope | I1: population_in_need_measure | J1: population_in_need_fraction | K1: coverage_scenario | L1: coverage_baseline | M1: frequency_per_year | N1: unit_cost_usd | O1: pin_scenario | P1: pin_baseline | Q1: annual_cost_baseline | R1: annual_cost_scenario | S1: annual_cost_incremental | T1: indonesia_adjusted_flag | U1: price_year | V1: discount_factor | W1: disc_cost_baseline | X1: disc_cost_scenario | Y1: disc_cost_incremental | Z1: cov_target | AA1: cov_start_year | AB1: cov_target_year | AC1: c_age_start | AD1: c_age_stop | AE1: c_sex | AF1: r_quantity_scenario | AG1: r_quantity_baseline | AH1: shared_duplicate_count
A2: I_CVD_PRIMARY | B2: 2025 | C2: I_CVD_PRIMARY | E2: COST_PRIMARY_SCREEN_A | F2: CC_PRIMARY_SCREENING | G2: I_CVD_PRIMARY__C_SHARED | H2: shared-count-once | I2: all | J2: =IFERROR(INDEX('Cost_Components'!$K$2:$K$27,MATCH(E2,'Cost_Components'!$A$2:$A$27,0)),"") | K2: =IF(OR(L2="",Z2="",AA2="",AB2=""),"",IF(B2<AA2,L2,IF(B2>AB2,Z2,L2+(Z2-L2)*MIN(MAX((B2-AA2+1)/MAX(AB2-AA2+1,1),0),1)))) | L2: =IFERROR(INDEX('Cost_Components'!$S$2:$S$27,MATCH(E2,'Cost_Components'!$A$2:$A$27,0)),"") | M2: =IFERROR(INDEX('Cost_Components'!$L$2:$L$27,MATCH(E2,'Cost_Components'!$A$2:$A$27,0)),"") | N2: =IFERROR(INDEX('Cost_Components'!$P$2:$P$27,MATCH(E2,'Cost_Components'!$A$2:$A$27,0)),"") | O2: =AF2*J2 | P2: =AG2*J2 | Q2: =P2*L2*M2*N2 | R2: =O2*K2*M2*N2 | S2: =R2-Q2 | T2: =IFERROR(INDEX('Cost_Components'!$R$2:$R$27,MATCH(E2,'Cost_Components'!$A$2:$A$27,0)),"") | U2: =IFERROR(INDEX('Cost_Components'!$Q$2:$Q$27,MATCH(E2,'Cost_Components'!$A$2:$A$27,0)),"") | V2: =1/(1+'Calculation_Assumptions'!$B$5)^(B2-'Calculation_Assumptions'!$B$2) | W2: =Q2*V2 | X2: =R2*V2 | Y2: =S2*V2 | Z2: =IFERROR(INDEX('Cost_Components'!$T$2:$T$27,MATCH(E2,'Cost_Components'!$A$2:$A$27,0)),"") | AA2: =IFERROR(INDEX('Cost_Components'!$U$2:$U$27,MATCH(E2,'Cost_Components'!$A$2:$A$27,0)),"") | AB2: =IFERROR(INDEX('Cost_Components'!$V$2:$V$27,MATCH(E2,'Cost_Components'!$A$2:$A$27,0)),"") | AC2: =IFERROR(INDEX('Cost_Components'!$M$2:$M$27,MATCH(E2,'Cost_Components'!$A$2:$A$27,0)),"") | AD2: =IFERROR(INDEX('Cost_Components'!$N$2:$N$27,MATCH(E2,'Cost_Components'!$A$2:$A$27,0)),"") | AE2: =IFERROR(INDEX('Cost_Components'!$O$2:$O$27,MATCH(E2,'Cost_Components'!$A$2:$A$27,0)),"") | AF2: 3.03073e+08 | AG2: 3.03073e+08 | AH2: =IF(H2="shared-count-once",COUNTIFS($A$2:$A$1353,A2,$B$2:$B$1353,B2,$E$2:$E$1353,E2),1)
A3: I_CVD_PRIMARY | B3: 2026 | C3: I_CVD_PRIMARY | E3: COST_PRIMARY_SCREEN_A | F3: CC_PRIMARY_SCREENING | G3: I_CVD_PRIMARY__C_SHARED | H3: shared-count-once | I3: all | J3: =IFERROR(INDEX('Cost_Components'!$K$2:$K$27,MATCH(E3,'Cost_Components'!$A$2:$A$27,0)),"") | K3: =IF(OR(L3="",Z3="",AA3="",AB3=""),"",IF(B3<AA3,L3,IF(B3>AB3,Z3,L3+(Z3-L3)*MIN(MAX((B3-AA3+1)/MAX(AB3-AA3+1,1),0),1)))) | L3: =IFERROR(INDEX('Cost_Components'!$S$2:$S$27,MATCH(E3,'Cost_Components'!$A$2:$A$27,0)),"") | M3: =IFERROR(INDEX('Cost_Components'!$L$2:$L$27,MATCH(E3,'Cost_Components'!$A$2:$A$27,0)),"") | N3: =IFERROR(INDEX('Cost_Components'!$P$2:$P$27,MATCH(E3,'Cost_Components'!$A$2:$A$27,0)),"") | O3: =AF3*J3 | P3: =AG3*J3 | Q3: =P3*L3*M3*N3 | R3: =O3*K3*M3*N3 | S3: =R3-Q3 | T3: =IFERROR(INDEX('Cost_Components'!$R$2:$R$27,MATCH(E3,'Cost_Components'!$A$2:$A$27,0)),"") | U3: =IFERROR(INDEX('Cost_Components'!$Q$2:$Q$27,MATCH(E3,'Cost_Components'!$A$2:$A$27,0)),"") | V3: =1/(1+'Calculation_Assumptions'!$B$5)^(B3-'Calculation_Assumptions'!$B$2) | W3: =Q3*V3 | X3: =R3*V3 | Y3: =S3*V3 | Z3: =IFERROR(INDEX('Cost_Components'!$T$2:$T$27,MATCH(E3,'Cost_Components'!$A$2:$A$27,0)),"") | AA3: =IFERROR(INDEX('Cost_Components'!$U$2:$U$27,MATCH(E3,'Cost_Components'!$A$2:$A$27,0)),"") | AB3: =IFERROR(INDEX('Cost_Components'!$V$2:$V$27,MATCH(E3,'Cost_Components'!$A$2:$A$27,0)),"") | AC3: =IFERROR(INDEX('Cost_Components'!$M$2:$M$27,MATCH(E3,'Cost_Components'!$A$2:$A$27,0)),"") | AD3: =IFERROR(INDEX('Cost_Components'!$N$2:$N$27,MATCH(E3,'Cost_Components'!$A$2:$A$27,0)),"") | AE3: =IFERROR(INDEX('Cost_Components'!$O$2:$O$27,MATCH(E3,'Cost_Components'!$A$2:$A$27,0)),"") | AF3: 3.0764667e+08 | AG3: 3.0764667e+08 | AH3: =IF(H3="shared-count-once",COUNTIFS($A$2:$A$1353,A3,$B$2:$B$1353,B3,$E$2:$E$1353,E3),1)
A4: I_CVD_PRIMARY | B4: 2027 | C4: I_CVD_PRIMARY | E4: COST_PRIMARY_SCREEN_A | F4: CC_PRIMARY_SCREENING | G4: I_CVD_PRIMARY__C_SHARED | H4: shared-count-once | I4: all | J4: =IFERROR(INDEX('Cost_Components'!$K$2:$K$27,MATCH(E4,'Cost_Components'!$A$2:$A$27,0)),"") | K4: =IF(OR(L4="",Z4="",AA4="",AB4=""),"",IF(B4<AA4,L4,IF(B4>AB4,Z4,L4+(Z4-L4)*MIN(MAX((B4-AA4+1)/MAX(AB4-AA4+1,1),0),1)))) | L4: =IFERROR(INDEX('Cost_Components'!$S$2:$S$27,MATCH(E4,'Cost_Components'!$A$2:$A$27,0)),"") | M4: =IFERROR(INDEX('Cost_Components'!$L$2:$L$27,MATCH(E4,'Cost_Components'!$A$2:$A$27,0)),"") | N4: =IFERROR(INDEX('Cost_Components'!$P$2:$P$27,MATCH(E4,'Cost_Components'!$A$2:$A$27,0)),"") | O4: =AF4*J4 | P4: =AG4*J4 | Q4: =P4*L4*M4*N4 | R4: =O4*K4*M4*N4 | S4: =R4-Q4 | T4: =IFERROR(INDEX('Cost_Components'!$R$2:$R$27,MATCH(E4,'Cost_Components'!$A$2:$A$27,0)),"") | U4: =IFERROR(INDEX('Cost_Components'!$Q$2:$Q$27,MATCH(E4,'Cost_Components'!$A$2:$A$27,0)),"") | V4: =1/(1+'Calculation_Assumptions'!$B$5)^(B4-'Calculation_Assumptions'!$B$2) | W4: =Q4*V4 | X4: =R4*V4 | Y4: =S4*V4 | Z4: =IFERROR(INDEX('Cost_Components'!$T$2:$T$27,MATCH(E4,'Cost_Components'!$A$2:$A$27,0)),"") | AA4: =IFERROR(INDEX('Cost_Components'!$U$2:$U$27,MATCH(E4,'Cost_Components'!$A$2:$A$27,0)),"") | AB4: =IFERROR(INDEX('Cost_Components'!$V$2:$V$27,MATCH(E4,'Cost_Components'!$A$2:$A$27,0)),"") | AC4: =IFERROR(INDEX('Cost_Components'!$M$2:$M$27,MATCH(E4,'Cost_Components'!$A$2:$A$27,0)),"") | AD4: =IFERROR(INDEX('Cost_Components'!$N$2:$N$27,MATCH(E4,'Cost_Components'!$A$2:$A$27,0)),"") | AE4: =IFERROR(INDEX('Cost_Components'!$O$2:$O$27,MATCH(E4,'Cost_Components'!$A$2:$A$27,0)),"") | AF4: 3.1226697e+08 | AG4: 3.119751e+08 | AH4: =IF(H4="shared-count-once",COUNTIFS($A$2:$A$1353,A4,$B$2:$B$1353,B4,$E$2:$E$1353,E4),1)
A5: I_CVD_PRIMARY | B5: 2028 | C5: I_CVD_PRIMARY | E5: COST_PRIMARY_SCREEN_A | F5: CC_PRIMARY_SCREENING | G5: I_CVD_PRIMARY__C_SHARED | H5: shared-count-once | I5: all | J5: =IFERROR(INDEX('Cost_Components'!$K$2:$K$27,MATCH(E5,'Cost_Components'!$A$2:$A$27,0)),"") | K5: =IF(OR(L5="",Z5="",AA5="",AB5=""),"",IF(B5<AA5,L5,IF(B5>AB5,Z5,L5+(Z5-L5)*MIN(MAX((B5-AA5+1)/MAX(AB5-AA5+1,1),0),1)))) | L5: =IFERROR(INDEX('Cost_Components'!$S$2:$S$27,MATCH(E5,'Cost_Components'!$A$2:$A$27,0)),"") | M5: =IFERROR(INDEX('Cost_Components'!$L$2:$L$27,MATCH(E5,'Cost_Components'!$A$2:$A$27,0)),"") | N5: =IFERROR(INDEX('Cost_Components'!$P$2:$P$27,MATCH(E5,'Cost_Components'!$A$2:$A$27,0)),"") | O5: =AF5*J5 | P5: =AG5*J5 | Q5: =P5*L5*M5*N5 | R5: =O5*K5*M5*N5 | S5: =R5-Q5 | T5: =IFERROR(INDEX('Cost_Components'!$R$2:$R$27,MATCH(E5,'Cost_Components'!$A$2:$A$27,0)),"") | U5: =IFERROR(INDEX('Cost_Components'!$Q$2:$Q$27,MATCH(E5,'Cost_Components'!$A$2:$A$27,0)),"") | V5: =1/(1+'Calculation_Assumptions'!$B$5)^(B5-'Calculation_Assumptions'!$B$2) | W5: =Q5*V5 | X5: =R5*V5 | Y5: =S5*V5 | Z5: =IFERROR(INDEX('Cost_Components'!$T$2:$T$27,MATCH(E5,'Cost_Components'!$A$2:$A$27,0)),"") | AA5: =IFERROR(INDEX('Cost_Components'!$U$2:$U$27,MATCH(E5,'Cost_Components'!$A$2:$A$27,0)),"") | AB5: =IFERROR(INDEX('Cost_Components'!$V$2:$V$27,MATCH(E5,'Cost_Components'!$A$2:$A$27,0)),"") | AC5: =IFERROR(INDEX('Cost_Components'!$M$2:$M$27,MATCH(E5,'Cost_Components'!$A$2:$A$27,0)),"") | AD5: =IFERROR(INDEX('Cost_Components'!$N$2:$N$27,MATCH(E5,'Cost_Components'!$A$2:$A$27,0)),"") | AE5: =IFERROR(INDEX('Cost_Components'!$O$2:$O$27,MATCH(E5,'Cost_Components'!$A$2:$A$27,0)),"") | AF5: 3.168103e+08 | AG5: 3.1653136e+08 | AH5: =IF(H5="shared-count-once",COUNTIFS($A$2:$A$1353,A5,$B$2:$B$1353,B5,$E$2:$E$1353,E5),1)
A6: I_CVD_PRIMARY | B6: 2029 | C6: I_CVD_PRIMARY | E6: COST_PRIMARY_SCREEN_A | F6: CC_PRIMARY_SCREENING | G6: I_CVD_PRIMARY__C_SHARED | H6: shared-count-once | I6: all | J6: =IFERROR(INDEX('Cost_Components'!$K$2:$K$27,MATCH(E6,'Cost_Components'!$A$2:$A$27,0)),"") | K6: =IF(OR(L6="",Z6="",AA6="",AB6=""),"",IF(B6<AA6,L6,IF(B6>AB6,Z6,L6+(Z6-L6)*MIN(MAX((B6-AA6+1)/MAX(AB6-AA6+1,1),0),1)))) | L6: =IFERROR(INDEX('Cost_Components'!$S$2:$S$27,MATCH(E6,'Cost_Components'!$A$2:$A$27,0)),"") | M6: =IFERROR(INDEX('Cost_Components'!$L$2:$L$27,MATCH(E6,'Cost_Components'!$A$2:$A$27,0)),"") | N6: =IFERROR(INDEX('Cost_Components'!$P$2:$P$27,MATCH(E6,'Cost_Components'!$A$2:$A$27,0)),"") | O6: =AF6*J6 | P6: =AG6*J6 | Q6: =P6*L6*M6*N6 | R6: =O6*K6*M6*N6 | S6: =R6-Q6 | T6: =IFERROR(INDEX('Cost_Components'!$R$2:$R$27,MATCH(E6,'Cost_Components'!$A$2:$A$27,0)),"") | U6: =IFERROR(INDEX('Cost_Components'!$Q$2:$Q$27,MATCH(E6,'Cost_Components'!$A$2:$A$27,0)),"") | V6: =1/(1+'Calculation_Assumptions'!$B$5)^(B6-'Calculation_Assumptions'!$B$2) | W6: =Q6*V6 | X6: =R6*V6 | Y6: =S6*V6 | Z6: =IFERROR(INDEX('Cost_Components'!$T$2:$T$27,MATCH(E6,'Cost_Components'!$A$2:$A$27,0)),"") | AA6: =IFERROR(INDEX('Cost_Components'!$U$2:$U$27,MATCH(E6,'Cost_Components'!$A$2:$A$27,0)),"") | AB6: =IFERROR(INDEX('Cost_Components'!$V$2:$V$27,MATCH(E6,'Cost_Components'!$A$2:$A$27,0)),"") | AC6: =IFERROR(INDEX('Cost_Components'!$M$2:$M$27,MATCH(E6,'Cost_Components'!$A$2:$A$27,0)),"") | AD6: =IFERROR(INDEX('Cost_Components'!$N$2:$N$27,MATCH(E6,'Cost_Components'!$A$2:$A$27,0)),"") | AE6: =IFERROR(INDEX('Cost_Components'!$O$2:$O$27,MATCH(E6,'Cost_Components'!$A$2:$A$27,0)),"") | AF6: 3.2119755e+08 | AG6: 3.2092558e+08 | AH6: =IF(H6="shared-count-once",COUNTIFS($A$2:$A$1353,A6,$B$2:$B$1353,B6,$E$2:$E$1353,E6),1)
A7: I_CVD_PRIMARY | B7: 2030 | C7: I_CVD_PRIMARY | E7: COST_PRIMARY_SCREEN_A | F7: CC_PRIMARY_SCREENING | G7: I_CVD_PRIMARY__C_SHARED | H7: shared-count-once | I7: all | J7: =IFERROR(INDEX('Cost_Components'!$K$2:$K$27,MATCH(E7,'Cost_Components'!$A$2:$A$27,0)),"") | K7: =IF(OR(L7="",Z7="",AA7="",AB7=""),"",IF(B7<AA7,L7,IF(B7>AB7,Z7,L7+(Z7-L7)*MIN(MAX((B7-AA7+1)/MAX(AB7-AA7+1,1),0),1)))) | L7: =IFERROR(INDEX('Cost_Components'!$S$2:$S$27,MATCH(E7,'Cost_Components'!$A$2:$A$27,0)),"") | M7: =IFERROR(INDEX('Cost_Components'!$L$2:$L$27,MATCH(E7,'Cost_Components'!$A$2:$A$27,0)),"") | N7: =IFERROR(INDEX('Cost_Components'!$P$2:$P$27,MATCH(E7,'Cost_Components'!$A$2:$A$27,0)),"") | O7: =AF7*J7 | P7: =AG7*J7 | Q7: =P7*L7*M7*N7 | R7: =O7*K7*M7*N7 | S7: =R7-Q7 | T7: =IFERROR(INDEX('Cost_Components'!$R$2:$R$27,MATCH(E7,'Cost_Components'!$A$2:$A$27,0)),"") | U7: =IFERROR(INDEX('Cost_Components'!$Q$2:$Q$27,MATCH(E7,'Cost_Components'!$A$2:$A$27,0)),"") | V7: =1/(1+'Calculation_Assumptions'!$B$5)^(B7-'Calculation_Assumptions'!$B$2) | W7: =Q7*V7 | X7: =R7*V7 | Y7: =S7*V7 | Z7: =IFERROR(INDEX('Cost_Components'!$T$2:$T$27,MATCH(E7,'Cost_Components'!$A$2:$A$27,0)),"") | AA7: =IFERROR(INDEX('Cost_Components'!$U$2:$U$27,MATCH(E7,'Cost_Components'!$A$2:$A$27,0)),"") | AB7: =IFERROR(INDEX('Cost_Components'!$V$2:$V$27,MATCH(E7,'Cost_Components'!$A$2:$A$27,0)),"") | AC7: =IFERROR(INDEX('Cost_Components'!$M$2:$M$27,MATCH(E7,'Cost_Components'!$A$2:$A$27,0)),"") | AD7: =IFERROR(INDEX('Cost_Components'!$N$2:$N$27,MATCH(E7,'Cost_Components'!$A$2:$A$27,0)),"") | AE7: =IFERROR(INDEX('Cost_Components'!$O$2:$O$27,MATCH(E7,'Cost_Components'!$A$2:$A$27,0)),"") | AF7: 3.2541001e+08 | AG7: 3.2513696e+08 | AH7: =IF(H7="shared-count-once",COUNTIFS($A$2:$A$1353,A7,$B$2:$B$1353,B7,$E$2:$E$1353,E7),1)
A8: I_CVD_PRIMARY | B8: 2031 | C8: I_CVD_PRIMARY | E8: COST_PRIMARY_SCREEN_A | F8: CC_PRIMARY_SCREENING | G8: I_CVD_PRIMARY__C_SHARED | H8: shared-count-once | I8: all | J8: =IFERROR(INDEX('Cost_Components'!$K$2:$K$27,MATCH(E8,'Cost_Components'!$A$2:$A$27,0)),"") | K8: =IF(OR(L8="",Z8="",AA8="",AB8=""),"",IF(B8<AA8,L8,IF(B8>AB8,Z8,L8+(Z8-L8)*MIN(MAX((B8-AA8+1)/MAX(AB8-AA8+1,1),0),1)))) | L8: =IFERROR(INDEX('Cost_Components'!$S$2:$S$27,MATCH(E8,'Cost_Components'!$A$2:$A$27,0)),"") | M8: =IFERROR(INDEX('Cost_Components'!$L$2:$L$27,MATCH(E8,'Cost_Components'!$A$2:$A$27,0)),"") | N8: =IFERROR(INDEX('Cost_Components'!$P$2:$P$27,MATCH(E8,'Cost_Components'!$A$2:$A$27,0)),"") | O8: =AF8*J8 | P8: =AG8*J8 | Q8: =P8*L8*M8*N8 | R8: =O8*K8*M8*N8 | S8: =R8-Q8 | T8: =IFERROR(INDEX('Cost_Components'!$R$2:$R$27,MATCH(E8,'Cost_Components'!$A$2:$A$27,0)),"") | U8: =IFERROR(INDEX('Cost_Components'!$Q$2:$Q$27,MATCH(E8,'Cost_Components'!$A$2:$A$27,0)),"") | V8: =1/(1+'Calculation_Assumptions'!$B$5)^(B8-'Calculation_Assumptions'!$B$2) | W8: =Q8*V8 | X8: =R8*V8 | Y8: =S8*V8 | Z8: =IFERROR(INDEX('Cost_Components'!$T$2:$T$27,MATCH(E8,'Cost_Components'!$A$2:$A$27,0)),"") | AA8: =IFERROR(INDEX('Cost_Components'!$U$2:$U$27,MATCH(E8,'Cost_Components'!$A$2:$A$27,0)),"") | AB8: =IFERROR(INDEX('Cost_Components'!$V$2:$V$27,MATCH(E8,'Cost_Components'!$A$2:$A$27,0)),"") | AC8: =IFERROR(INDEX('Cost_Components'!$M$2:$M$27,MATCH(E8,'Cost_Components'!$A$2:$A$27,0)),"") | AD8: =IFERROR(INDEX('Cost_Components'!$N$2:$N$27,MATCH(E8,'Cost_Components'!$A$2:$A$27,0)),"") | AE8: =IFERROR(INDEX('Cost_Components'!$O$2:$O$27,MATCH(E8,'Cost_Components'!$A$2:$A$27,0)),"") | AF8: 3.2937128e+08 | AG8: 3.2925981e+08 | AH8: =IF(H8="shared-count-once",COUNTIFS($A$2:$A$1353,A8,$B$2:$B$1353,B8,$E$2:$E$1353,E8),1)
A9: I_CVD_PRIMARY | B9: 2032 | C9: I_CVD_PRIMARY | E9: COST_PRIMARY_SCREEN_A | F9: CC_PRIMARY_SCREENING | G9: I_CVD_PRIMARY__C_SHARED | H9: shared-count-once | I9: all | J9: =IFERROR(INDEX('Cost_Components'!$K$2:$K$27,MATCH(E9,'Cost_Components'!$A$2:$A$27,0)),"") | K9: =IF(OR(L9="",Z9="",AA9="",AB9=""),"",IF(B9<AA9,L9,IF(B9>AB9,Z9,L9+(Z9-L9)*MIN(MAX((B9-AA9+1)/MAX(AB9-AA9+1,1),0),1)))) | L9: =IFERROR(INDEX('Cost_Components'!$S$2:$S$27,MATCH(E9,'Cost_Components'!$A$2:$A$27,0)),"") | M9: =IFERROR(INDEX('Cost_Components'!$L$2:$L$27,MATCH(E9,'Cost_Components'!$A$2:$A$27,0)),"") | N9: =IFERROR(INDEX('Cost_Components'!$P$2:$P$27,MATCH(E9,'Cost_Components'!$A$2:$A$27,0)),"") | O9: =AF9*J9 | P9: =AG9*J9 | Q9: =P9*L9*M9*N9 | R9: =O9*K9*M9*N9 | S9: =R9-Q9 | T9: =IFERROR(INDEX('Cost_Components'!$R$2:$R$27,MATCH(E9,'Cost_Components'!$A$2:$A$27,0)),"") | U9: =IFERROR(INDEX('Cost_Components'!$Q$2:$Q$27,MATCH(E9,'Cost_Components'!$A$2:$A$27,0)),"") | V9: =1/(1+'Calculation_Assumptions'!$B$5)^(B9-'Calculation_Assumptions'!$B$2) | W9: =Q9*V9 | X9: =R9*V9 | Y9: =S9*V9 | Z9: =IFERROR(INDEX('Cost_Components'!$T$2:$T$27,MATCH(E9,'Cost_Components'!$A$2:$A$27,0)),"") | AA9: =IFERROR(INDEX('Cost_Components'!$U$2:$U$27,MATCH(E9,'Cost_Components'!$A$2:$A$27,0)),"") | AB9: =IFERROR(INDEX('Cost_Components'!$V$2:$V$27,MATCH(E9,'Cost_Components'!$A$2:$A$27,0)),"") | AC9: =IFERROR(INDEX('Cost_Components'!$M$2:$M$27,MATCH(E9,'Cost_Components'!$A$2:$A$27,0)),"") | AD9: =IFERROR(INDEX('Cost_Components'!$N$2:$N$27,MATCH(E9,'Cost_Components'!$A$2:$A$27,0)),"") | AE9: =IFERROR(INDEX('Cost_Components'!$O$2:$O$27,MATCH(E9,'Cost_Components'!$A$2:$A$27,0)),"") | AF9: 3.3348393e+08 | AG9: 3.3333154e+08 | AH9: =IF(H9="shared-count-once",COUNTIFS($A$2:$A$1353,A9,$B$2:$B$1353,B9,$E$2:$E$1353,E9),1)
A10: I_CVD_PRIMARY | B10: 2033 | C10: I_CVD_PRIMARY | E10: COST_PRIMARY_SCREEN_A | F10: CC_PRIMARY_SCREENING | G10: I_CVD_PRIMARY__C_SHARED | H10: shared-count-once | I10: all | J10: =IFERROR(INDEX('Cost_Components'!$K$2:$K$27,MATCH(E10,'Cost_Components'!$A$2:$A$27,0)),"") | K10: =IF(OR(L10="",Z10="",AA10="",AB10=""),"",IF(B10<AA10,L10,IF(B10>AB10,Z10,L10+(Z10-L10)*MIN(MAX((B10-AA10+1)/MAX(AB10-AA10+1,1),0),1)))) | L10: =IFERROR(INDEX('Cost_Components'!$S$2:$S$27,MATCH(E10,'Cost_Components'!$A$2:$A$27,0)),"") | M10: =IFERROR(INDEX('Cost_Components'!$L$2:$L$27,MATCH(E10,'Cost_Components'!$A$2:$A$27,0)),"") | N10: =IFERROR(INDEX('Cost_Components'!$P$2:$P$27,MATCH(E10,'Cost_Components'!$A$2:$A$27,0)),"") | O10: =AF10*J10 | P10: =AG10*J10 | Q10: =P10*L10*M10*N10 | R10: =O10*K10*M10*N10 | S10: =R10-Q10 | T10: =IFERROR(INDEX('Cost_Components'!$R$2:$R$27,MATCH(E10,'Cost_Components'!$A$2:$A$27,0)),"") | U10: =IFERROR(INDEX('Cost_Components'!$Q$2:$Q$27,MATCH(E10,'Cost_Components'!$A$2:$A$27,0)),"") | V10: =1/(1+'Calculation_Assumptions'!$B$5)^(B10-'Calculation_Assumptions'!$B$2) | W10: =Q10*V10 | X10: =R10*V10 | Y10: =S10*V10 | Z10: =IFERROR(INDEX('Cost_Components'!$T$2:$T$27,MATCH(E10,'Cost_Components'!$A$2:$A$27,0)),"") | AA10: =IFERROR(INDEX('Cost_Components'!$U$2:$U$27,MATCH(E10,'Cost_Components'!$A$2:$A$27,0)),"") | AB10: =IFERROR(INDEX('Cost_Components'!$V$2:$V$27,MATCH(E10,'Cost_Components'!$A$2:$A$27,0)),"") | AC10: =IFERROR(INDEX('Cost_Components'!$M$2:$M$27,MATCH(E10,'Cost_Components'!$A$2:$A$27,0)),"") | AD10: =IFERROR(INDEX('Cost_Components'!$N$2:$N$27,MATCH(E10,'Cost_Components'!$A$2:$A$27,0)),"") | AE10: =IFERROR(INDEX('Cost_Components'!$O$2:$O$27,MATCH(E10,'Cost_Components'!$A$2:$A$27,0)),"") | AF10: 3.3755155e+08 | AG10: 3.373496e+08 | AH10: =IF(H10="shared-count-once",COUNTIFS($A$2:$A$1353,A10,$B$2:$B$1353,B10,$E$2:$E$1353,E10),1)
A11: I_CVD_PRIMARY | B11: 2034 | C11: I_CVD_PRIMARY | E11: COST_PRIMARY_SCREEN_A | F11: CC_PRIMARY_SCREENING | G11: I_CVD_PRIMARY__C_SHARED | H11: shared-count-once | I11: all | J11: =IFERROR(INDEX('Cost_Components'!$K$2:$K$27,MATCH(E11,'Cost_Components'!$A$2:$A$27,0)),"") | K11: =IF(OR(L11="",Z11="",AA11="",AB11=""),"",IF(B11<AA11,L11,IF(B11>AB11,Z11,L11+(Z11-L11)*MIN(MAX((B11-AA11+1)/MAX(AB11-AA11+1,1),0),1)))) | L11: =IFERROR(INDEX('Cost_Components'!$S$2:$S$27,MATCH(E11,'Cost_Components'!$A$2:$A$27,0)),"") | M11: =IFERROR(INDEX('Cost_Components'!$L$2:$L$27,MATCH(E11,'Cost_Components'!$A$2:$A$27,0)),"") | N11: =IFERROR(INDEX('Cost_Components'!$P$2:$P$27,MATCH(E11,'Cost_Components'!$A$2:$A$27,0)),"") | O11: =AF11*J11 | P11: =AG11*J11 | Q11: =P11*L11*M11*N11 | R11: =O11*K11*M11*N11 | S11: =R11-Q11 | T11: =IFERROR(INDEX('Cost_Components'!$R$2:$R$27,MATCH(E11,'Cost_Components'!$A$2:$A$27,0)),"") | U11: =IFERROR(INDEX('Cost_Components'!$Q$2:$Q$27,MATCH(E11,'Cost_Components'!$A$2:$A$27,0)),"") | V11: =1/(1+'Calculation_Assumptions'!$B$5)^(B11-'Calculation_Assumptions'!$B$2) | W11: =Q11*V11 | X11: =R11*V11 | Y11: =S11*V11 | Z11: =IFERROR(INDEX('Cost_Components'!$T$2:$T$27,MATCH(E11,'Cost_Components'!$A$2:$A$27,0)),"") | AA11: =IFERROR(INDEX('Cost_Components'!$U$2:$U$27,MATCH(E11,'Cost_Components'!$A$2:$A$27,0)),"") | AB11: =IFERROR(INDEX('Cost_Components'!$V$2:$V$27,MATCH(E11,'Cost_Components'!$A$2:$A$27,0)),"") | AC11: =IFERROR(INDEX('Cost_Components'!$M$2:$M$27,MATCH(E11,'Cost_Components'!$A$2:$A$27,0)),"") | AD11: =IFERROR(INDEX('Cost_Components'!$N$2:$N$27,MATCH(E11,'Cost_Components'!$A$2:$A$27,0)),"") | AE11: =IFERROR(INDEX('Cost_Components'!$O$2:$O$27,MATCH(E11,'Cost_Components'!$A$2:$A$27,0)),"") | AF11: 3.4161345e+08 | AG11: 3.4135282e+08 | AH11: =IF(H11="shared-count-once",COUNTIFS($A$2:$A$1353,A11,$B$2:$B$1353,B11,$E$2:$E$1353,E11),1)
A12: I_CVD_PRIMARY | B12: 2035 | C12: I_CVD_PRIMARY | E12: COST_PRIMARY_SCREEN_A | F12: CC_PRIMARY_SCREENING | G12: I_CVD_PRIMARY__C_SHARED | H12: shared-count-once | I12: all | J12: =IFERROR(INDEX('Cost_Components'!$K$2:$K$27,MATCH(E12,'Cost_Components'!$A$2:$A$27,0)),"") | K12: =IF(OR(L12="",Z12="",AA12="",AB12=""),"",IF(B12<AA12,L12,IF(B12>AB12,Z12,L12+(Z12-L12)*MIN(MAX((B12-AA12+1)/MAX(AB12-AA12+1,1),0),1)))) | L12: =IFERROR(INDEX('Cost_Components'!$S$2:$S$27,MATCH(E12,'Cost_Components'!$A$2:$A$27,0)),"") | M12: =IFERROR(INDEX('Cost_Components'!$L$2:$L$27,MATCH(E12,'Cost_Components'!$A$2:$A$27,0)),"") | N12: =IFERROR(INDEX('Cost_Components'!$P$2:$P$27,MATCH(E12,'Cost_Components'!$A$2:$A$27,0)),"") | O12: =AF12*J12 | P12: =AG12*J12 | Q12: =P12*L12*M12*N12 | R12: =O12*K12*M12*N12 | S12: =R12-Q12 | T12: =IFERROR(INDEX('Cost_Components'!$R$2:$R$27,MATCH(E12,'Cost_Components'!$A$2:$A$27,0)),"") | U12: =IFERROR(INDEX('Cost_Components'!$Q$2:$Q$27,MATCH(E12,'Cost_Components'!$A$2:$A$27,0)),"") | V12: =1/(1+'Calculation_Assumptions'!$B$5)^(B12-'Calculation_Assumptions'!$B$2) | W12: =Q12*V12 | X12: =R12*V12 | Y12: =S12*V12 | Z12: =IFERROR(INDEX('Cost_Components'!$T$2:$T$27,MATCH(E12,'Cost_Components'!$A$2:$A$27,0)),"") | AA12: =IFERROR(INDEX('Cost_Components'!$U$2:$U$27,MATCH(E12,'Cost_Components'!$A$2:$A$27,0)),"") | AB12: =IFERROR(INDEX('Cost_Components'!$V$2:$V$27,MATCH(E12,'Cost_Components'!$A$2:$A$27,0)),"") | AC12: =IFERROR(INDEX('Cost_Components'!$M$2:$M$27,MATCH(E12,'Cost_Components'!$A$2:$A$27,0)),"") | AD12: =IFERROR(INDEX('Cost_Components'!$N$2:$N$27,MATCH(E12,'Cost_Components'!$A$2:$A$27,0)),"") | AE12: =IFERROR(INDEX('Cost_Components'!$O$2:$O$27,MATCH(E12,'Cost_Components'!$A$2:$A$27,0)),"") | AF12: 3.4575846e+08 | AG12: 3.4542926e+08 | AH12: =IF(H12="shared-count-once",COUNTIFS($A$2:$A$1353,A12,$B$2:$B$1353,B12,$E$2:$E$1353,E12),1)
A13: I_CVD_PRIMARY | B13: 2036 | C13: I_CVD_PRIMARY | E13: COST_PRIMARY_SCREEN_A | F13: CC_PRIMARY_SCREENING | G13: I_CVD_PRIMARY__C_SHARED | H13: shared-count-once | I13: all | J13: =IFERROR(INDEX('Cost_Components'!$K$2:$K$27,MATCH(E13,'Cost_Components'!$A$2:$A$27,0)),"") | K13: =IF(OR(L13="",Z13="",AA13="",AB13=""),"",IF(B13<AA13,L13,IF(B13>AB13,Z13,L13+(Z13-L13)*MIN(MAX((B13-AA13+1)/MAX(AB13-AA13+1,1),0),1)))) | L13: =IFERROR(INDEX('Cost_Components'!$S$2:$S$27,MATCH(E13,'Cost_Components'!$A$2:$A$27,0)),"") | M13: =IFERROR(INDEX('Cost_Components'!$L$2:$L$27,MATCH(E13,'Cost_Components'!$A$2:$A$27,0)),"") | N13: =IFERROR(INDEX('Cost_Components'!$P$2:$P$27,MATCH(E13,'Cost_Components'!$A$2:$A$27,0)),"") | O13: =AF13*J13 | P13: =AG13*J13 | Q13: =P13*L13*M13*N13 | R13: =O13*K13*M13*N13 | S13: =R13-Q13 | T13: =IFERROR(INDEX('Cost_Components'!$R$2:$R$27,MATCH(E13,'Cost_Components'!$A$2:$A$27,0)),"") | U13: =IFERROR(INDEX('Cost_Components'!$Q$2:$Q$27,MATCH(E13,'Cost_Components'!$A$2:$A$27,0)),"") | V13: =1/(1+'Calculation_Assumptions'!$B$5)^(B13-'Calculation_Assumptions'!$B$2) | W13: =Q13*V13 | X13: =R13*V13 | Y13: =S13*V13 | Z13: =IFERROR(INDEX('Cost_Components'!$T$2:$T$27,MATCH(E13,'Cost_Components'!$A$2:$A$27,0)),"") | AA13: =IFERROR(INDEX('Cost_Components'!$U$2:$U$27,MATCH(E13,'Cost_Components'!$A$2:$A$27,0)),"") | AB13: =IFERROR(INDEX('Cost_Components'!$V$2:$V$27,MATCH(E13,'Cost_Components'!$A$2:$A$27,0)),"") | AC13: =IFERROR(INDEX('Cost_Components'!$M$2:$M$27,MATCH(E13,'Cost_Components'!$A$2:$A$27,0)),"") | AD13: =IFERROR(INDEX('Cost_Components'!$N$2:$N$27,MATCH(E13,'Cost_Components'!$A$2:$A$27,0)),"") | AE13: =IFERROR(INDEX('Cost_Components'!$O$2:$O$27,MATCH(E13,'Cost_Components'!$A$2:$A$27,0)),"") | AF13: 3.5004097e+08 | AG13: 3.4963346e+08 | AH13: =IF(H13="shared-count-once",COUNTIFS($A$2:$A$1353,A13,$B$2:$B$1353,B13,$E$2:$E$1353,E13),1)
... A53: I_CVD_PRIMARY | B53: 2050 | C53: I_CVD_PRIMARY | E53: COST_PRIMARY_TX_A | F53: CC_PRIMARY_HTN_STATIN | G53: I_CVD_PRIMARY__C_SHARED | H53: shared-count-once | I53: all | J53: =IFERROR(INDEX('Cost_Components'!$K$2:$K$27,MATCH(E53,'Cost_Components'!$A$2:$A$27,0)),"") | K53: =IF(OR(L53="",Z53="",AA53="",AB53=""),"",IF(B53<AA53,L53,IF(B53>AB53,Z53,L53+(Z53-L53)*MIN(MAX((B53-AA53+1)/MAX(AB53-AA53+1,1),0),1)))) | L53: =IFERROR(INDEX('Cost_Components'!$S$2:$S$27,MATCH(E53,'Cost_Components'!$A$2:$A$27,0)),"") | M53: =IFERROR(INDEX('Cost_Components'!$L$2:$L$27,MATCH(E53,'Cost_Components'!$A$2:$A$27,0)),"") | N53: =IFERROR(INDEX('Cost_Components'!$P$2:$P$27,MATCH(E53,'Cost_Components'!$A$2:$A$27,0)),"") | O53: =AF53*J53 | P53: =AG53*J53 | Q53: =P53*L53*M53*N53 | R53: =O53*K53*M53*N53 | S53: =R53-Q53 | T53: =IFERROR(INDEX('Cost_Components'!$R$2:$R$27,MATCH(E53,'Cost_Components'!$A$2:$A$27,0)),"") | U53: =IFERROR(INDEX('Cost_Components'!$Q$2:$Q$27,MATCH(E53,'Cost_Components'!$A$2:$A$27,0)),"") | V53: =1/(1+'Calculation_Assumptions'!$B$5)^(B53-'Calculation_Assumptions'!$B$2) | W53: =Q53*V53 | X53: =R53*V53 | Y53: =S53*V53 | Z53: =IFERROR(INDEX('Cost_Components'!$T$2:$T$27,MATCH(E53,'Cost_Components'!$A$2:$A$27,0)),"") | AA53: =IFERROR(INDEX('Cost_Components'!$U$2:$U$27,MATCH(E53,'Cost_Components'!$A$2:$A$27,0)),"") | AB53: =IFERROR(INDEX('Cost_Components'!$V$2:$V$27,MATCH(E53,'Cost_Components'!$A$2:$A$27,0)),"") | AC53: =IFERROR(INDEX('Cost_Components'!$M$2:$M$27,MATCH(E53,'Cost_Components'!$A$2:$A$27,0)),"") | AD53: =IFERROR(INDEX('Cost_Components'!$N$2:$N$27,MATCH(E53,'Cost_Components'!$A$2:$A$27,0)),"") | AE53: =IFERROR(INDEX('Cost_Components'!$O$2:$O$27,MATCH(E53,'Cost_Components'!$A$2:$A$27,0)),"") | AF53: 4.0071109e+08 | AG53: 3.9813254e+08 | AH53: =IF(H53="shared-count-once",COUNTIFS($A$2:$A$1353,A53,$B$2:$B$1353,B53,$E$2:$E$1353,E53),1)
A54: I_HF_ACUTE | B54: 2025 | C54: I_HF_ACUTE | D54: cmd | E54: COST_HF_ACUTE_C_CMP | F54: CC_HF_ACUTE_C_CMP | G54: I_HF_ACUTE__C_CMP | H54: cause-specific | I54: prevalence | J54: =IFERROR(INDEX('Cost_Components'!$K$2:$K$27,MATCH(E54,'Cost_Components'!$A$2:$A$27,0)),"") | K54: =IF(OR(L54="",Z54="",AA54="",AB54=""),"",IF(B54<AA54,L54,IF(B54>AB54,Z54,L54+(Z54-L54)*MIN(MAX((B54-AA54+1)/MAX(AB54-AA54+1,1),0),1)))) | L54: =IFERROR(INDEX('Cost_Components'!$S$2:$S$27,MATCH(E54,'Cost_Components'!$A$2:$A$27,0)),"") | M54: =IFERROR(INDEX('Cost_Components'!$L$2:$L$27,MATCH(E54,'Cost_Components'!$A$2:$A$27,0)),"") | N54: =IFERROR(INDEX('Cost_Components'!$P$2:$P$27,MATCH(E54,'Cost_Components'!$A$2:$A$27,0)),"") | O54: =AF54*J54 | P54: =AG54*J54 | Q54: =P54*L54*M54*N54 | R54: =O54*K54*M54*N54 | S54: =R54-Q54 | T54: =IFERROR(INDEX('Cost_Components'!$R$2:$R$27,MATCH(E54,'Cost_Components'!$A$2:$A$27,0)),"") | U54: =IFERROR(INDEX('Cost_Components'!$Q$2:$Q$27,MATCH(E54,'Cost_Components'!$A$2:$A$27,0)),"") | V54: =1/(1+'Calculation_Assumptions'!$B$5)^(B54-'Calculation_Assumptions'!$B$2) | W54: =Q54*V54 | X54: =R54*V54 | Y54: =S54*V54 | Z54: =IFERROR(INDEX('Cost_Components'!$T$2:$T$27,MATCH(E54,'Cost_Components'!$A$2:$A$27,0)),"") | AA54: =IFERROR(INDEX('Cost_Components'!$U$2:$U$27,MATCH(E54,'Cost_Components'!$A$2:$A$27,0)),"") | AB54: =IFERROR(INDEX('Cost_Components'!$V$2:$V$27,MATCH(E54,'Cost_Components'!$A$2:$A$27,0)),"") | AC54: =IFERROR(INDEX('Cost_Components'!$M$2:$M$27,MATCH(E54,'Cost_Components'!$A$2:$A$27,0)),"") | AD54: =IFERROR(INDEX('Cost_Components'!$N$2:$N$27,MATCH(E54,'Cost_Components'!$A$2:$A$27,0)),"") | AE54: =IFERROR(INDEX('Cost_Components'!$O$2:$O$27,MATCH(E54,'Cost_Components'!$A$2:$A$27,0)),"") | AF54: 53324.494 | AG54: 53296.123 | AH54: =IF(H54="shared-count-once",COUNTIFS($A$2:$A$1353,A54,$B$2:$B$1353,B54,$E$2:$E$1353,E54),1)
A55: I_HF_ACUTE | B55: 2026 | C55: I_HF_ACUTE | D55: cmd | E55: COST_HF_ACUTE_C_CMP | F55: CC_HF_ACUTE_C_CMP | G55: I_HF_ACUTE__C_CMP | H55: cause-specific | I55: prevalence | J55: =IFERROR(INDEX('Cost_Components'!$K$2:$K$27,MATCH(E55,'Cost_Components'!$A$2:$A$27,0)),"") | K55: =IF(OR(L55="",Z55="",AA55="",AB55=""),"",IF(B55<AA55,L55,IF(B55>AB55,Z55,L55+(Z55-L55)*MIN(MAX((B55-AA55+1)/MAX(AB55-AA55+1,1),0),1)))) | L55: =IFERROR(INDEX('Cost_Components'!$S$2:$S$27,MATCH(E55,'Cost_Components'!$A$2:$A$27,0)),"") | M55: =IFERROR(INDEX('Cost_Components'!$L$2:$L$27,MATCH(E55,'Cost_Components'!$A$2:$A$27,0)),"") | N55: =IFERROR(INDEX('Cost_Components'!$P$2:$P$27,MATCH(E55,'Cost_Components'!$A$2:$A$27,0)),"") | O55: =AF55*J55 | P55: =AG55*J55 | Q55: =P55*L55*M55*N55 | R55: =O55*K55*M55*N55 | S55: =R55-Q55 | T55: =IFERROR(INDEX('Cost_Components'!$R$2:$R$27,MATCH(E55,'Cost_Components'!$A$2:$A$27,0)),"") | U55: =IFERROR(INDEX('Cost_Components'!$Q$2:$Q$27,MATCH(E55,'Cost_Components'!$A$2:$A$27,0)),"") | V55: =1/(1+'Calculation_Assumptions'!$B$5)^(B55-'Calculation_Assumptions'!$B$2) | W55: =Q55*V55 | X55: =R55*V55 | Y55: =S55*V55 | Z55: =IFERROR(INDEX('Cost_Components'!$T$2:$T$27,MATCH(E55,'Cost_Components'!$A$2:$A$27,0)),"") | AA55: =IFERROR(INDEX('Cost_Components'!$U$2:$U$27,MATCH(E55,'Cost_Components'!$A$2:$A$27,0)),"") | AB55: =IFERROR(INDEX('Cost_Components'!$V$2:$V$27,MATCH(E55,'Cost_Components'!$A$2:$A$27,0)),"") | AC55: =IFERROR(INDEX('Cost_Components'!$M$2:$M$27,MATCH(E55,'Cost_Components'!$A$2:$A$27,0)),"") | AD55: =IFERROR(INDEX('Cost_Components'!$N$2:$N$27,MATCH(E55,'Cost_Components'!$A$2:$A$27,0)),"") | AE55: =IFERROR(INDEX('Cost_Components'!$O$2:$O$27,MATCH(E55,'Cost_Components'!$A$2:$A$27,0)),"") | AF55: 55224.558 | AG55: 55143.657 | AH55: =IF(H55="shared-count-once",COUNTIFS($A$2:$A$1353,A55,$B$2:$B$1353,B55,$E$2:$E$1353,E55),1)
A56: I_HF_ACUTE | B56: 2027 | C56: I_HF_ACUTE | D56: cmd | E56: COST_HF_ACUTE_C_CMP | F56: CC_HF_ACUTE_C_CMP | G56: I_HF_ACUTE__C_CMP | H56: cause-specific | I56: prevalence | J56: =IFERROR(INDEX('Cost_Components'!$K$2:$K$27,MATCH(E56,'Cost_Components'!$A$2:$A$27,0)),"") | K56: =IF(OR(L56="",Z56="",AA56="",AB56=""),"",IF(B56<AA56,L56,IF(B56>AB56,Z56,L56+(Z56-L56)*MIN(MAX((B56-AA56+1)/MAX(AB56-AA56+1,1),0),1)))) | L56: =IFERROR(INDEX('Cost_Components'!$S$2:$S$27,MATCH(E56,'Cost_Components'!$A$2:$A$27,0)),"") | M56: =IFERROR(INDEX('Cost_Components'!$L$2:$L$27,MATCH(E56,'Cost_Components'!$A$2:$A$27,0)),"") | N56: =IFERROR(INDEX('Cost_Components'!$P$2:$P$27,MATCH(E56,'Cost_Components'!$A$2:$A$27,0)),"") | O56: =AF56*J56 | P56: =AG56*J56 | Q56: =P56*L56*M56*N56 | R56: =O56*K56*M56*N56 | S56: =R56-Q56 | T56: =IFERROR(INDEX('Cost_Components'!$R$2:$R$27,MATCH(E56,'Cost_Components'!$A$2:$A$27,0)),"") | U56: =IFERROR(INDEX('Cost_Components'!$Q$2:$Q$27,MATCH(E56,'Cost_Components'!$A$2:$A$27,0)),"") | V56: =1/(1+'Calculation_Assumptions'!$B$5)^(B56-'Calculation_Assumptions'!$B$2) | W56: =Q56*V56 | X56: =R56*V56 | Y56: =S56*V56 | Z56: =IFERROR(INDEX('Cost_Components'!$T$2:$T$27,MATCH(E56,'Cost_Components'!$A$2:$A$27,0)),"") | AA56: =IFERROR(INDEX('Cost_Components'!$U$2:$U$27,MATCH(E56,'Cost_Components'!$A$2:$A$27,0)),"") | AB56: =IFERROR(INDEX('Cost_Components'!$V$2:$V$27,MATCH(E56,'Cost_Components'!$A$2:$A$27,0)),"") | AC56: =IFERROR(INDEX('Cost_Components'!$M$2:$M$27,MATCH(E56,'Cost_Components'!$A$2:$A$27,0)),"") | AD56: =IFERROR(INDEX('Cost_Components'!$N$2:$N$27,MATCH(E56,'Cost_Components'!$A$2:$A$27,0)),"") | AE56: =IFERROR(INDEX('Cost_Components'!$O$2:$O$27,MATCH(E56,'Cost_Components'!$A$2:$A$27,0)),"") | AF56: 57117.016 | AG56: 56962.574 | AH56: =IF(H56="shared-count-once",COUNTIFS($A$2:$A$1353,A56,$B$2:$B$1353,B56,$E$2:$E$1353,E56),1)
A57: I_HF_ACUTE | B57: 2028 | C57: I_HF_ACUTE | D57: cmd | E57: COST_HF_ACUTE_C_CMP | F57: CC_HF_ACUTE_C_CMP | G57: I_HF_ACUTE__C_CMP | H57: cause-specific | I57: prevalence | J57: =IFERROR(INDEX('Cost_Components'!$K$2:$K$27,MATCH(E57,'Cost_Components'!$A$2:$A$27,0)),"") | K57: =IF(OR(L57="",Z57="",AA57="",AB57=""),"",IF(B57<AA57,L57,IF(B57>AB57,Z57,L57+(Z57-L57)*MIN(MAX((B57-AA57+1)/MAX(AB57-AA57+1,1),0),1)))) | L57: =IFERROR(INDEX('Cost_Components'!$S$2:$S$27,MATCH(E57,'Cost_Components'!$A$2:$A$27,0)),"") | M57: =IFERROR(INDEX('Cost_Components'!$L$2:$L$27,MATCH(E57,'Cost_Components'!$A$2:$A$27,0)),"") | N57: =IFERROR(INDEX('Cost_Components'!$P$2:$P$27,MATCH(E57,'Cost_Components'!$A$2:$A$27,0)),"") | O57: =AF57*J57 | P57: =AG57*J57 | Q57: =P57*L57*M57*N57 | R57: =O57*K57*M57*N57 | S57: =R57-Q57 | T57: =IFERROR(INDEX('Cost_Components'!$R$2:$R$27,MATCH(E57,'Cost_Components'!$A$2:$A$27,0)),"") | U57: =IFERROR(INDEX('Cost_Components'!$Q$2:$Q$27,MATCH(E57,'Cost_Components'!$A$2:$A$27,0)),"") | V57: =1/(1+'Calculation_Assumptions'!$B$5)^(B57-'Calculation_Assumptions'!$B$2) | W57: =Q57*V57 | X57: =R57*V57 | Y57: =S57*V57 | Z57: =IFERROR(INDEX('Cost_Components'!$T$2:$T$27,MATCH(E57,'Cost_Components'!$A$2:$A$27,0)),"") | AA57: =IFERROR(INDEX('Cost_Components'!$U$2:$U$27,MATCH(E57,'Cost_Components'!$A$2:$A$27,0)),"") | AB57: =IFERROR(INDEX('Cost_Components'!$V$2:$V$27,MATCH(E57,'Cost_Components'!$A$2:$A$27,0)),"") | AC57: =IFERROR(INDEX('Cost_Components'!$M$2:$M$27,MATCH(E57,'Cost_Components'!$A$2:$A$27,0)),"") | AD57: =IFERROR(INDEX('Cost_Components'!$N$2:$N$27,MATCH(E57,'Cost_Components'!$A$2:$A$27,0)),"") | AE57: =IFERROR(INDEX('Cost_Components'!$O$2:$O$27,MATCH(E57,'Cost_Components'!$A$2:$A$27,0)),"") | AF57: 58991.035 | AG57: 58744.418 | AH57: =IF(H57="shared-count-once",COUNTIFS($A$2:$A$1353,A57,$B$2:$B$1353,B57,$E$2:$E$1353,E57),1)
