Workbook

Sheet README
A1: Indonesia NCD model — user input workbook
A3: Draft for review • August 14, 2026 meeting decisions + supplied Fair Choices, coverage/PIN, and cost files
A5: Readiness | C5: Interventions | E5: Model causes | G5: Intervention–cause links
A6: =IF(COUNTIF(QA_Checks!$E$2:$E$9,"FAIL")=0,"READY TO RUN","REVIEW REQUIRED") -> READY TO RUN | C6: =COUNTA(Dictionaries!$A$2:$A$9) -> 8 | E6: =COUNTIF(Dictionaries!$I$2:$I$9,1) -> 7 | G6: =COUNTA(Intervention_Cause_Map!$A$2:$A$18) -> 17
A9: How to use the workbook
A10: 1 | B10: Edit yellow cells only.
A11: 2 | B11: Use Model_Input_View to audit the joined transition, effect, coverage, and cost key for each intervention–cause pair.
A12: 3 | B12: Costs join through cost_join_key. C_SHARED means count the cost once at intervention level, not once per affected cause.
A13: 4 | B13: For costing, keep exactly one selected_for_base_case = 1 within each cost_component_key.
A14: 5 | B14: Resolve QA failures and red review items before running the full economic evaluation.
A16: Known review items retained explicitly
A17: Resolved | B17: Type 2 diabetes baseline coverage set from SKI 2023 (treated among laboratory-confirmed diabetics aged 30+)
A18: Resolved | B18: Type 2 diabetes unit cost replaced with observed JKN FKRTL outpatient spend per patient-year, 2023
A19: Resolved | B19: Filled from JKN heart-failure outpatient spend per patient-year, 2023
A20: Superseded | B20: Salary-adjustment options no longer drive the base case; selected rows now carry observed Indonesian JKN values
A21: Review | B21: Confirm RHD surgery transition if the final model has explicit severe-RHD or surgery states
A23: Color legend: yellow = user input • light blue = formula/derived • green = valid • red/orange = missing or review

Sheet Assumptions
A1: parameter_id | B1: value | C1: unit | D1: base_case | E1: lower_bound | F1: upper_bound | G1: description | H1: source
A2: analysis_start_year | B2: 2025 | C2: year | D2: 2025 | E2: 2025 | F2: 2025 | G2: First modeled year | H2: input_file.xlsx and meeting scope
A3: analysis_end_year | B3: 2050 | C3: year | D3: 2050 | E3: 2050 | F3: 2100 | G3: Last year for the Jakarta-oriented analysis | H3: Meeting target year
A4: intervention_start_year | B4: 2025 | C4: year | D4: 2025 | E4: 2025 | F4: 2030 | G4: First year of intervention scale-up | H4: input_file.xlsx
A5: target_coverage_default | B5: 0.8 | C5: proportion | D5: 0.8 | E5: 0.7 | F5: 0.9 | G5: Default intervention coverage target; row-level override is available | H5: August 14 meeting
A6: coverage_target_year | B6: 2050 | C6: year | D6: 2050 | E6: 2030 | F6: 2050 | G6: Year in which target coverage is reached | H6: August 14 meeting
A7: cost_discount_rate | B7: 0.03 | C7: proportion/year | D7: 0.03 | E7: 0 | F7: 0.05 | G7: Annual discount rate for costs | H7: input_file.xlsx
A8: health_discount_rate | B8: 0.03 | C8: proportion/year | D8: 0.03 | E8: 0 | F8: 0.05 | G8: Annual discount rate for health outcomes | H8: input_file.xlsx
A9: cost_price_year | B9: 2023 | C9: USD year | D9: 2023 | E9: 2023 | F9: 2024 | G9: Price year for Indonesia-adjusted CVD unit costs | H9: cvd_unit_cost_indonesia_1(1).xlsx
A10: currency | B10: USD | C10: currency | D10: USD | E10: USD | F10: USD | G10: Reporting currency | H10: input_file.xlsx
A11: scale_up_shape | B11: linear | C11: text | D11: linear | E11: linear | F11: linear | G11: Coverage increases linearly from start year to target year | H11: August 14 meeting
A12: downstream_cost_offsets | B12: 0 | C12: 0/1 flag | D12: 0 | E12: 0 | F12: 1 | G12: Include downstream disease-cost offsets | H12: input_file.xlsx
A13: rhd_surgery_frequency | B13: 1 | C13: procedure/patient-year | D13: 1 | E13: 0 | F13: 1 | G13: Provisional surgery frequency used for costing | H13: input_file.xlsx
A14: economic_perspective | B14: health_system | C14: text | D14: health_system | E14: health_system | F14: societal | G14: Economic evaluation perspective | H14: Working assumption
A15: usd_idr_exchange_rate | B15: 15237 | C15: IDR per USD | D15: 15237 | E15: 15000 | F15: 15600 | G15: Conversion applied to all JKN-derived unit costs (2023 period average) | H15: World Bank official exchange rate, Indonesia 2023

Sheet Dictionaries
A1: intervention_id | B1: intervention_name | C1: package_group | D1: definition | F1: cause_id | G1: cause_name | H1: model_name | I1: is_model_cause
A2: I_RHD_SECONDARY | B2: RHD secondary prevention | C2: Rheumatic heart disease | D2: Secondary prophylaxis for rheumatic fever or established RHD | F2: C_RHD | G2: Rheumatic heart disease | H2: Rheumatic heart disease | I2: 1
A3: I_RHD_SURGERY | B3: RHD cardiac surgery | C3: Rheumatic heart disease | D3: Cardiac surgery for severe rheumatic heart disease | F3: C_IHD | G3: Ischemic heart disease | H3: Ischemic heart disease | I3: 1
A4: I_CVD_PRIMARY | B4: Primary prevention of CVD | C4: Primary CVD prevention | D4: Combined hypertension-treatment/statin intervention using average Fair Choices effects | F4: C_IS | G4: Ischemic stroke | H4: Ischemic stroke | I4: 1
A5: I_IHD_SECONDARY | B5: Secondary prevention of ischemic heart disease | C5: Secondary CVD prevention | D5: Longitudinal secondary prevention after ischemic heart disease | F5: C_ICH | G5: Intracerebral hemorrhage | H5: Intracerebral hemorrhage | I5: 1
A6: I_STROKE_SECONDARY | B6: Secondary prevention of stroke | C6: Secondary CVD prevention | D6: Longitudinal secondary prevention after ischemic or intracerebral hemorrhagic stroke | F6: C_HHD | G6: Hypertensive heart disease | H6: Hypertensive heart disease | I6: 1
A7: I_HF_ACUTE | B7: Acute heart-failure management | C7: Heart-failure treatment | D7: Acute management of heart failure arising from IHD, HHD, or cardiomyopathy/myocarditis | F7: C_CMP | G7: Cardiomyopathy and myocarditis | H7: Cardiomyopathy and myocarditis | I7: 1
A8: I_HF_CHRONIC | B8: Chronic heart-failure management | C8: Heart-failure treatment | D8: Longitudinal management of chronic heart failure arising from IHD, HHD, or cardiomyopathy/myocarditis | F8: C_T2D | G8: Diabetes mellitus type 2 | H8: Type 2 diabetes | I8: 1
A9: I_T2D_TREATMENT | B9: Longitudinal treatment of type 2 diabetes | C9: Diabetes treatment | D9: Treatment affecting direct diabetes deaths and IHD deaths attributable to high blood glucose | F9: C_SHARED | G9: Shared intervention cost | H9: Not a disease model; count cost once | I9: 0

Sheet Intervention_Cause_Map
A1: intervention_cause_key | B1: intervention_id | C1: intervention_name | D1: cause_id | E1: cause_name | F1: model_name | G1: effect_key | H1: coverage_key | I1: cost_join_key | J1: cost_scope | K1: include_flag | L1: notes | M1: duplicate_count
A2: I_RHD_SECONDARY__C_RHD | B2: I_RHD_SECONDARY | C2: RHD secondary prevention | D2: C_RHD | E2: Rheumatic heart disease | F2: Rheumatic heart disease | G2: I_RHD_SECONDARY__C_RHD | H2: I_RHD_SECONDARY__C_RHD | I2: I_RHD_SECONDARY__C_RHD | J2: cause-specific | K2: 1 | L2: Apply to the RHD model | M2: =COUNTIF($A$2:$A$18,A2) -> 1
A3: I_RHD_SURGERY__C_RHD | B3: I_RHD_SURGERY | C3: RHD cardiac surgery | D3: C_RHD | E3: Rheumatic heart disease | F3: Rheumatic heart disease | G3: I_RHD_SURGERY__C_RHD | H3: I_RHD_SURGERY__C_RHD | I3: I_RHD_SURGERY__C_RHD | J3: cause-specific | K3: 1 | L3: SRHD has been replaced with RHD | M3: =COUNTIF($A$2:$A$18,A3) -> 1
A4: I_CVD_PRIMARY__C_IHD | B4: I_CVD_PRIMARY | C4: Primary prevention of CVD | D4: C_IHD | E4: Ischemic heart disease | F4: Ischemic heart disease | G4: I_CVD_PRIMARY__C_IHD | H4: I_CVD_PRIMARY__C_IHD | I4: I_CVD_PRIMARY__C_SHARED | J4: shared-count-once | K4: 1 | L4: Shared screening/treatment costs must be counted once | M4: =COUNTIF($A$2:$A$18,A4) -> 1
A5: I_CVD_PRIMARY__C_IS | B5: I_CVD_PRIMARY | C5: Primary prevention of CVD | D5: C_IS | E5: Ischemic stroke | F5: Ischemic stroke | G5: I_CVD_PRIMARY__C_IS | H5: I_CVD_PRIMARY__C_IS | I5: I_CVD_PRIMARY__C_SHARED | J5: shared-count-once | K5: 1 | L5: Shared screening/treatment costs must be counted once | M5: =COUNTIF($A$2:$A$18,A5) -> 1
A6: I_CVD_PRIMARY__C_ICH | B6: I_CVD_PRIMARY | C6: Primary prevention of CVD | D6: C_ICH | E6: Intracerebral hemorrhage | F6: Intracerebral hemorrhage | G6: I_CVD_PRIMARY__C_ICH | H6: I_CVD_PRIMARY__C_ICH | I6: I_CVD_PRIMARY__C_SHARED | J6: shared-count-once | K6: 1 | L6: Shared screening/treatment costs must be counted once | M6: =COUNTIF($A$2:$A$18,A6) -> 1
A7: I_CVD_PRIMARY__C_HHD | B7: I_CVD_PRIMARY | C7: Primary prevention of CVD | D7: C_HHD | E7: Hypertensive heart disease | F7: Hypertensive heart disease | G7: I_CVD_PRIMARY__C_HHD | H7: I_CVD_PRIMARY__C_HHD | I7: I_CVD_PRIMARY__C_SHARED | J7: shared-count-once | K7: 1 | L7: Shared screening/treatment costs must be counted once | M7: =COUNTIF($A$2:$A$18,A7) -> 1
A8: I_IHD_SECONDARY__C_IHD | B8: I_IHD_SECONDARY | C8: Secondary prevention of ischemic heart disease | D8: C_IHD | E8: Ischemic heart disease | F8: Ischemic heart disease | G8: I_IHD_SECONDARY__C_IHD | H8: I_IHD_SECONDARY__C_IHD | I8: I_IHD_SECONDARY__C_IHD | J8: cause-specific | K8: 1 | L8: Apply to sick-to-dead transition | M8: =COUNTIF($A$2:$A$18,A8) -> 1
A9: I_STROKE_SECONDARY__C_IS | B9: I_STROKE_SECONDARY | C9: Secondary prevention of stroke | D9: C_IS | E9: Ischemic stroke | F9: Ischemic stroke | G9: I_STROKE_SECONDARY__C_IS | H9: I_STROKE_SECONDARY__C_IS | I9: I_STROKE_SECONDARY__C_IS | J9: cause-specific | K9: 1 | L9: Cause-specific effect and cost components | M9: =COUNTIF($A$2:$A$18,A9) -> 1
A10: I_STROKE_SECONDARY__C_ICH | B10: I_STROKE_SECONDARY | C10: Secondary prevention of stroke | D10: C_ICH | E10: Intracerebral hemorrhage | F10: Intracerebral hemorrhage | G10: I_STROKE_SECONDARY__C_ICH | H10: I_STROKE_SECONDARY__C_ICH | I10: I_STROKE_SECONDARY__C_ICH | J10: cause-specific | K10: 1 | L10: Cause-specific effect and cost components | M10: =COUNTIF($A$2:$A$18,A10) -> 1
A11: I_HF_ACUTE__C_IHD | B11: I_HF_ACUTE | C11: Acute heart-failure management | D11: C_IHD | E11: Ischemic heart disease | F11: Ischemic heart disease | G11: I_HF_ACUTE__C_IHD | H11: I_HF_ACUTE__C_IHD | I11: I_HF_ACUTE__C_IHD | J11: cause-specific | K11: 1 | L11: Heart failure arising from IHD | M11: =COUNTIF($A$2:$A$18,A11) -> 1
A12: I_HF_ACUTE__C_HHD | B12: I_HF_ACUTE | C12: Acute heart-failure management | D12: C_HHD | E12: Hypertensive heart disease | F12: Hypertensive heart disease | G12: I_HF_ACUTE__C_HHD | H12: I_HF_ACUTE__C_HHD | I12: I_HF_ACUTE__C_HHD | J12: cause-specific | K12: 1 | L12: Heart failure arising from HHD | M12: =COUNTIF($A$2:$A$18,A12) -> 1
A13: I_HF_ACUTE__C_CMP | B13: I_HF_ACUTE | C13: Acute heart-failure management | D13: C_CMP | E13: Cardiomyopathy and myocarditis | F13: Cardiomyopathy and myocarditis | G13: I_HF_ACUTE__C_CMP | H13: I_HF_ACUTE__C_CMP | I13: I_HF_ACUTE__C_CMP | J13: cause-specific | K13: 1 | L13: Heart failure arising from cardiomyopathy/myocarditis | M13: =COUNTIF($A$2:$A$18,A13) -> 1
... A18: I_T2D_TREATMENT__C_IHD | B18: I_T2D_TREATMENT | C18: Longitudinal treatment of type 2 diabetes | D18: C_IHD | E18: Ischemic heart disease attributable to high blood glucose | F18: Ischemic heart disease | G18: I_T2D_TREATMENT__C_IHD | H18: I_T2D_TREATMENT__C_IHD | I18: I_T2D_TREATMENT__C_T2D | J18: shared-count-once | K18: 1 | L18: Count diabetes treatment cost once on the T2D population | M18: =COUNTIF($A$2:$A$18,A18) -> 1

Sheet Effect_Sizes
A1: effect_id | B1: intervention_cause_key | C1: intervention_id | D1: cause_id | E1: intervention_name | F1: cause_name | G1: transition_from | H1: transition_to | I1: effect_measure | J1: effect_value | K1: affected_fraction | L1: age_start | M1: age_stop | N1: sex | O1: duration_years | P1: source_variable | Q1: source_file | R1: source_row | S1: review_status | T1: notes | U1: map_match_count | V1: qa_status
A2: E_RHD_SECONDARY | B2: I_RHD_SECONDARY__C_RHD | C2: I_RHD_SECONDARY | D2: C_RHD | E2: RHD secondary prevention | F2: Rheumatic heart disease | G2: sick | H2: dead_rhd | I2: relative_risk_reduction | J2: 0.55 | K2: 1 | L2: 5 | M2: 39 | N2: Both | O2: 1 | P2: Prevalence (reclassified to mortality transition) | Q2: taxonomy_effect_size.xlsx | R2: Sheet 1, row 146 | S2: Provisional | T2: Meeting decision maps secondary prevention to sick → dead | U2: =COUNTIF(Intervention_Cause_Map!$A$2:$A$18,B2) -> 1 | V2: =IF(U2<>1,"BAD KEY",IF(OR(J2<0,J2>1,K2<0,K2>1),"BAD VALUE","OK")) -> OK
A3: E_RHD_SURGERY | B3: I_RHD_SURGERY__C_RHD | C3: I_RHD_SURGERY | D3: C_RHD | E3: RHD cardiac surgery | F3: Rheumatic heart disease | G3: sick_severe | H3: dead_rhd | I3: relative_risk_reduction | J3: 0.75 | K3: 1 | L3: 5 | M3: 40 | N3: Both | O3: 15 | P3: Mortality | Q3: taxonomy_effect_size.xlsx | R3: Sheet 1, row 148 | S3: Review | T3: Confirm model state if surgery is represented explicitly | U3: =COUNTIF(Intervention_Cause_Map!$A$2:$A$18,B3) -> 1 | V3: =IF(U3<>1,"BAD KEY",IF(OR(J3<0,J3>1,K3<0,K3>1),"BAD VALUE","OK")) -> OK
A4: E_PRIMARY_IHD | B4: I_CVD_PRIMARY__C_IHD | C4: I_CVD_PRIMARY | D4: C_IHD | E4: Primary prevention of CVD | F4: Ischemic heart disease | G4: well | H4: sick | I4: relative_risk_reduction | J4: 0.58 | K4: 0.8 | L4: 30 | M4: 80 | N4: Both | O4: 1 | P4: Mortality (reclassified to incidence transition) | Q4: taxonomy_effect_size.xlsx | R4: Sheet 1, row 136 | S4: Provisional | T4: Average Fair Choices hypertension/statin effect applied to incidence | U4: =COUNTIF(Intervention_Cause_Map!$A$2:$A$18,B4) -> 1 | V4: =IF(U4<>1,"BAD KEY",IF(OR(J4<0,J4>1,K4<0,K4>1),"BAD VALUE","OK")) -> OK
A5: E_PRIMARY_IS | B5: I_CVD_PRIMARY__C_IS | C5: I_CVD_PRIMARY | D5: C_IS | E5: Primary prevention of CVD | F5: Ischemic stroke | G5: well | H5: sick | I5: relative_risk_reduction | J5: 0.54 | K5: 0.8 | L5: 30 | M5: 80 | N5: Both | O5: 1 | P5: Mortality (reclassified to incidence transition) | Q5: taxonomy_effect_size.xlsx | R5: Sheet 1, row 133 | S5: Provisional | T5: Average Fair Choices hypertension/statin effect applied to incidence | U5: =COUNTIF(Intervention_Cause_Map!$A$2:$A$18,B5) -> 1 | V5: =IF(U5<>1,"BAD KEY",IF(OR(J5<0,J5>1,K5<0,K5>1),"BAD VALUE","OK")) -> OK
A6: E_PRIMARY_ICH | B6: I_CVD_PRIMARY__C_ICH | C6: I_CVD_PRIMARY | D6: C_ICH | E6: Primary prevention of CVD | F6: Intracerebral hemorrhage | G6: well | H6: sick | I6: relative_risk_reduction | J6: 0.49 | K6: 0.8 | L6: 30 | M6: 80 | N6: Both | O6: 1 | P6: Mortality (reclassified to incidence transition) | Q6: taxonomy_effect_size.xlsx | R6: Sheet 1, row 134 | S6: Provisional | T6: Average Fair Choices hypertension/statin effect applied to incidence | U6: =COUNTIF(Intervention_Cause_Map!$A$2:$A$18,B6) -> 1 | V6: =IF(U6<>1,"BAD KEY",IF(OR(J6<0,J6>1,K6<0,K6>1),"BAD VALUE","OK")) -> OK
A7: E_PRIMARY_HHD | B7: I_CVD_PRIMARY__C_HHD | C7: I_CVD_PRIMARY | D7: C_HHD | E7: Primary prevention of CVD | F7: Hypertensive heart disease | G7: well | H7: sick | I7: relative_risk_reduction | J7: 0.47 | K7: 1 | L7: 30 | M7: 80 | N7: Both | O7: 1 | P7: Mortality (reclassified to incidence transition) | Q7: taxonomy_effect_size.xlsx | R7: Sheet 1, row 135 | S7: Provisional | T7: Average Fair Choices hypertension/statin effect applied to incidence | U7: =COUNTIF(Intervention_Cause_Map!$A$2:$A$18,B7) -> 1 | V7: =IF(U7<>1,"BAD KEY",IF(OR(J7<0,J7>1,K7<0,K7>1),"BAD VALUE","OK")) -> OK
A8: E_IHD_SECONDARY | B8: I_IHD_SECONDARY__C_IHD | C8: I_IHD_SECONDARY | D8: C_IHD | E8: Secondary prevention of ischemic heart disease | F8: Ischemic heart disease | G8: sick | H8: dead_ihd | I8: relative_risk_reduction | J8: 0.5822 | K8: 0.2 | L8: 30 | M8: 80 | N8: Both | O8: 1 | P8: Mortality | Q8: taxonomy_effect_size.xlsx | R8: Sheet 1, row 139 | S8: Provisional | T8: Cause-specific disease-management effect | U8: =COUNTIF(Intervention_Cause_Map!$A$2:$A$18,B8) -> 1 | V8: =IF(U8<>1,"BAD KEY",IF(OR(J8<0,J8>1,K8<0,K8>1),"BAD VALUE","OK")) -> OK
A9: E_STROKE_SECONDARY_IS | B9: I_STROKE_SECONDARY__C_IS | C9: I_STROKE_SECONDARY | D9: C_IS | E9: Secondary prevention of stroke | F9: Ischemic stroke | G9: sick | H9: dead_is | I9: relative_risk_reduction | J9: 0.23 | K9: 0.2 | L9: 30 | M9: 80 | N9: Both | O9: 1 | P9: Mortality | Q9: taxonomy_effect_size.xlsx | R9: Sheet 1, row 152 | S9: Provisional | T9: Cause-specific disease-management effect | U9: =COUNTIF(Intervention_Cause_Map!$A$2:$A$18,B9) -> 1 | V9: =IF(U9<>1,"BAD KEY",IF(OR(J9<0,J9>1,K9<0,K9>1),"BAD VALUE","OK")) -> OK
A10: E_STROKE_SECONDARY_ICH | B10: I_STROKE_SECONDARY__C_ICH | C10: I_STROKE_SECONDARY | D10: C_ICH | E10: Secondary prevention of stroke | F10: Intracerebral hemorrhage | G10: sick | H10: dead_ich | I10: relative_risk_reduction | J10: 0.08 | K10: 0.2 | L10: 30 | M10: 80 | N10: Both | O10: 1 | P10: Mortality | Q10: taxonomy_effect_size.xlsx | R10: Sheet 1, row 153 | S10: Provisional | T10: Cause-specific disease-management effect | U10: =COUNTIF(Intervention_Cause_Map!$A$2:$A$18,B10) -> 1 | V10: =IF(U10<>1,"BAD KEY",IF(OR(J10<0,J10>1,K10<0,K10>1),"BAD VALUE","OK")) -> OK
A11: E_HF_ACUTE_IHD | B11: I_HF_ACUTE__C_IHD | C11: I_HF_ACUTE | D11: C_IHD | E11: Acute heart-failure management | F11: Ischemic heart disease | G11: sick_hf | H11: dead_ihd | I11: relative_risk_reduction | J11: 0.18 | K11: 0.05 | L11: 30 | M11: 99 | N11: Both | O11: 1 | P11: Mortality | Q11: taxonomy_effect_size.xlsx | R11: Sheet 1, row 143 | S11: Provisional | T11: Apply only to heart failure arising from IHD | U11: =COUNTIF(Intervention_Cause_Map!$A$2:$A$18,B11) -> 1 | V11: =IF(U11<>1,"BAD KEY",IF(OR(J11<0,J11>1,K11<0,K11>1),"BAD VALUE","OK")) -> OK
A12: E_HF_ACUTE_HHD | B12: I_HF_ACUTE__C_HHD | C12: I_HF_ACUTE | D12: C_HHD | E12: Acute heart-failure management | F12: Hypertensive heart disease | G12: sick_hf | H12: dead_hhd | I12: relative_risk_reduction | J12: 0.74 | K12: 0.2 | L12: 30 | M12: 99 | N12: Both | O12: 1 | P12: Mortality | Q12: taxonomy_effect_size.xlsx | R12: Sheet 1, row 144 | S12: Provisional | T12: Apply only to heart failure arising from HHD | U12: =COUNTIF(Intervention_Cause_Map!$A$2:$A$18,B12) -> 1 | V12: =IF(U12<>1,"BAD KEY",IF(OR(J12<0,J12>1,K12<0,K12>1),"BAD VALUE","OK")) -> OK
A13: E_HF_ACUTE_CMP | B13: I_HF_ACUTE__C_CMP | C13: I_HF_ACUTE | D13: C_CMP | E13: Acute heart-failure management | F13: Cardiomyopathy and myocarditis | G13: sick_hf | H13: dead_cmp | I13: relative_risk_reduction | J13: 0.74 | K13: 0.2 | L13: 30 | M13: 99 | N13: Both | O13: 1 | P13: Mortality | Q13: taxonomy_effect_size.xlsx | R13: Sheet 1, row 145 | S13: Provisional | T13: Apply only to heart failure arising from cardiomyopathy/myocarditis | U13: =COUNTIF(Intervention_Cause_Map!$A$2:$A$18,B13) -> 1 | V13: =IF(U13<>1,"BAD KEY",IF(OR(J13<0,J13>1,K13<0,K13>1),"BAD VALUE","OK")) -> OK
... A18: E_T2D_IHD_HBG | B18: I_T2D_TREATMENT__C_IHD | C18: I_T2D_TREATMENT | D18: C_IHD | E18: Longitudinal treatment of type 2 diabetes | F18: Ischemic heart disease attributable to high blood glucose | G18: sick | H18: dead_ihd | I18: relative_risk_reduction | J18: 0.15 | K18: 0.15 | L18: 0 | M18: 95 | N18: Both | O18: 1 | P18: Mortality | Q18: taxonomy_effect_size.xlsx | R18: Sheet 1, row 174 | S18: Review | T18: Confirm NCD Countdown attributable-fraction implementation | U18: =COUNTIF(Intervention_Cause_Map!$A$2:$A$18,B18) -> 1 | V18: =IF(U18<>1,"BAD KEY",IF(OR(J18<0,J18>1,K18<0,K18>1),"BAD VALUE","OK")) -> OK

Sheet Coverage
A1: coverage_id | B1: intervention_cause_key | C1: intervention_id | D1: cause_id | E1: intervention_name | F1: cause_name | G1: baseline_coverage | H1: target_override | I1: target_coverage | J1: start_year | K1: target_year | L1: scale_up_shape | M1: baseline_source_file | N1: baseline_source_row | O1: proxy_note | P1: review_status | Q1: absolute_increase | R1: map_match_count | S1: qa_status | T1: baseline_coverage_previous | U1: jkn_basis | V1: jkn_n_insample
A2: CVG_01 | B2: I_RHD_SECONDARY__C_RHD | C2: I_RHD_SECONDARY | D2: C_RHD | E2: RHD secondary prevention | F2: Rheumatic heart disease | G2: 0.4011 | I2: =IF(H2="",Assumptions!$B$5,H2) -> 0.8 | J2: =Assumptions!$B$4 -> 2025 | K2: =Assumptions!$B$6 -> 2050 | L2: linear | M2: Data Sampel JKN 2022-2023 (reguler), I05-I09 | N2: analysis/outputs/jkn_retention_by_group.csv | ski2023_coverage.csv | O2: Indonesian value; replaces the FairChoices regional/platform proxy | P2: Indonesia JKN | Q2: =IF(G2="","",I2-G2) -> 0.3989 | R2: =COUNTIF(Intervention_Cause_Map!$A$2:$A$18,B2) -> 1 | S2: =IF(R2<>1,"BAD KEY",IF(G2="","MISSING BASELINE",IF(OR(G2<0,G2>1,I2<0,I2>1,I2<G2),"BAD COVERAGE","OK"))) -> OK | T2: 0.31 | U2: Share of JKN patients with a 2022 claim (excluding those recorded as died in 2022) who had a further claim for the same condition in 2023; effective continuation of care among diagnosed patients | V2: 698
A3: CVG_02 | B3: I_RHD_SURGERY__C_RHD | C3: I_RHD_SURGERY | D3: C_RHD | E3: RHD cardiac surgery | F3: Rheumatic heart disease | G3: 0.0664 | I3: =IF(H3="",Assumptions!$B$5,H3) -> 0.8 | J3: =Assumptions!$B$4 -> 2025 | K3: =Assumptions!$B$6 -> 2050 | L3: linear | M3: Data Sampel JKN 2023 (reguler), I05-I09 | N3: analysis/outputs/jkn_retention_by_group.csv | ski2023_coverage.csv | O3: Indonesian value; replaces the FairChoices regional/platform proxy | P3: Indonesia JKN | Q3: =IF(G3="","",I3-G3) -> 0.7336 | R3: =COUNTIF(Intervention_Cause_Map!$A$2:$A$18,B3) -> 1 | S3: =IF(R3<>1,"BAD KEY",IF(G3="","MISSING BASELINE",IF(OR(G3<0,G3>1,I3<0,I3>1,I3<G3),"BAD COVERAGE","OK"))) -> OK | T3: 0.1 | U3: Share of prevalent JKN RHD patients who received an inpatient surgical-procedure episode in 2023 | V3: 919
A4: CVG_03 | B4: I_CVD_PRIMARY__C_IHD | C4: I_CVD_PRIMARY | D4: C_IHD | E4: Primary prevention of CVD | F4: Ischemic heart disease | G4: 0.2466 | I4: =IF(H4="",Assumptions!$B$5,H4) -> 0.8 | J4: =Assumptions!$B$4 -> 2025 | K4: =Assumptions!$B$6 -> 2050 | L4: linear | M4: SKI 2023 (harmonized), final_hypertension_status + ht_ever_treated | N4: analysis/outputs/jkn_retention_by_group.csv | ski2023_coverage.csv | O4: Indonesian value; replaces the FairChoices regional/platform proxy | P4: Indonesia SKI 2023 | Q4: =IF(G4="","",I4-G4) -> 0.5534 | R4: =COUNTIF(Intervention_Cause_Map!$A$2:$A$18,B4) -> 1 | S4: =IF(R4<>1,"BAD KEY",IF(G4="","MISSING BASELINE",IF(OR(G4<0,G4>1,I4<0,I4>1,I4<G4),"BAD COVERAGE","OK"))) -> OK | T4: 0.31 | U4: Share of measured hypertensives aged 30+ ever treated for hypertension, weight_total
A5: CVG_04 | B5: I_CVD_PRIMARY__C_IS | C5: I_CVD_PRIMARY | D5: C_IS | E5: Primary prevention of CVD | F5: Ischemic stroke | G5: 0.2466 | I5: =IF(H5="",Assumptions!$B$5,H5) -> 0.8 | J5: =Assumptions!$B$4 -> 2025 | K5: =Assumptions!$B$6 -> 2050 | L5: linear | M5: SKI 2023 (harmonized), final_hypertension_status + ht_ever_treated | N5: analysis/outputs/jkn_retention_by_group.csv | ski2023_coverage.csv | O5: Indonesian value; replaces the FairChoices regional/platform proxy | P5: Indonesia SKI 2023 | Q5: =IF(G5="","",I5-G5) -> 0.5534 | R5: =COUNTIF(Intervention_Cause_Map!$A$2:$A$18,B5) -> 1 | S5: =IF(R5<>1,"BAD KEY",IF(G5="","MISSING BASELINE",IF(OR(G5<0,G5>1,I5<0,I5>1,I5<G5),"BAD COVERAGE","OK"))) -> OK | T5: 0.31 | U5: Share of measured hypertensives aged 30+ ever treated for hypertension, weight_total
A6: CVG_05 | B6: I_CVD_PRIMARY__C_ICH | C6: I_CVD_PRIMARY | D6: C_ICH | E6: Primary prevention of CVD | F6: Intracerebral hemorrhage | G6: 0.2466 | I6: =IF(H6="",Assumptions!$B$5,H6) -> 0.8 | J6: =Assumptions!$B$4 -> 2025 | K6: =Assumptions!$B$6 -> 2050 | L6: linear | M6: SKI 2023 (harmonized), final_hypertension_status + ht_ever_treated | N6: analysis/outputs/jkn_retention_by_group.csv | ski2023_coverage.csv | O6: Indonesian value; replaces the FairChoices regional/platform proxy | P6: Indonesia SKI 2023 | Q6: =IF(G6="","",I6-G6) -> 0.5534 | R6: =COUNTIF(Intervention_Cause_Map!$A$2:$A$18,B6) -> 1 | S6: =IF(R6<>1,"BAD KEY",IF(G6="","MISSING BASELINE",IF(OR(G6<0,G6>1,I6<0,I6>1,I6<G6),"BAD COVERAGE","OK"))) -> OK | T6: 0.31 | U6: Share of measured hypertensives aged 30+ ever treated for hypertension, weight_total
A7: CVG_06 | B7: I_CVD_PRIMARY__C_HHD | C7: I_CVD_PRIMARY | D7: C_HHD | E7: Primary prevention of CVD | F7: Hypertensive heart disease | G7: 0.2466 | I7: =IF(H7="",Assumptions!$B$5,H7) -> 0.8 | J7: =Assumptions!$B$4 -> 2025 | K7: =Assumptions!$B$6 -> 2050 | L7: linear | M7: SKI 2023 (harmonized), final_hypertension_status + ht_ever_treated | N7: analysis/outputs/jkn_retention_by_group.csv | ski2023_coverage.csv | O7: Indonesian value; replaces the FairChoices regional/platform proxy | P7: Indonesia SKI 2023 | Q7: =IF(G7="","",I7-G7) -> 0.5534 | R7: =COUNTIF(Intervention_Cause_Map!$A$2:$A$18,B7) -> 1 | S7: =IF(R7<>1,"BAD KEY",IF(G7="","MISSING BASELINE",IF(OR(G7<0,G7>1,I7<0,I7>1,I7<G7),"BAD COVERAGE","OK"))) -> OK | T7: 0.31 | U7: Share of measured hypertensives aged 30+ ever treated for hypertension, weight_total
A8: CVG_07 | B8: I_IHD_SECONDARY__C_IHD | C8: I_IHD_SECONDARY | D8: C_IHD | E8: Secondary prevention of ischemic heart disease | F8: Ischemic heart disease | G8: 0.5301 | I8: =IF(H8="",Assumptions!$B$5,H8) -> 0.8 | J8: =Assumptions!$B$4 -> 2025 | K8: =Assumptions!$B$6 -> 2050 | L8: linear | M8: Data Sampel JKN 2022-2023 (reguler), I20-I25 | N8: analysis/outputs/jkn_retention_by_group.csv | ski2023_coverage.csv | O8: Indonesian value; replaces the FairChoices regional/platform proxy | P8: Indonesia JKN | Q8: =IF(G8="","",I8-G8) -> 0.2699 | R8: =COUNTIF(Intervention_Cause_Map!$A$2:$A$18,B8) -> 1 | S8: =IF(R8<>1,"BAD KEY",IF(G8="","MISSING BASELINE",IF(OR(G8<0,G8>1,I8<0,I8>1,I8<G8),"BAD COVERAGE","OK"))) -> OK | T8: 0.31 | U8: Share of JKN patients with a 2022 claim (excluding those recorded as died in 2022) who had a further claim for the same condition in 2023; effective continuation of care among diagnosed patients | V8: 11920
A9: CVG_08 | B9: I_STROKE_SECONDARY__C_IS | C9: I_STROKE_SECONDARY | D9: C_IS | E9: Secondary prevention of stroke | F9: Ischemic stroke | G9: 0.3822 | I9: =IF(H9="",Assumptions!$B$5,H9) -> 0.8 | J9: =Assumptions!$B$4 -> 2025 | K9: =Assumptions!$B$6 -> 2050 | L9: linear | M9: Data Sampel JKN 2022-2023 (reguler), I63 | N9: analysis/outputs/jkn_retention_by_group.csv | ski2023_coverage.csv | O9: Indonesian value; replaces the FairChoices regional/platform proxy | P9: Indonesia JKN | Q9: =IF(G9="","",I9-G9) -> 0.4178 | R9: =COUNTIF(Intervention_Cause_Map!$A$2:$A$18,B9) -> 1 | S9: =IF(R9<>1,"BAD KEY",IF(G9="","MISSING BASELINE",IF(OR(G9<0,G9>1,I9<0,I9>1,I9<G9),"BAD COVERAGE","OK"))) -> OK | T9: 0.31 | U9: Share of JKN patients with a 2022 claim (excluding those recorded as died in 2022) who had a further claim for the same condition in 2023; effective continuation of care among diagnosed patients | V9: 4506
A10: CVG_09 | B10: I_STROKE_SECONDARY__C_ICH | C10: I_STROKE_SECONDARY | D10: C_ICH | E10: Secondary prevention of stroke | F10: Intracerebral hemorrhage | G10: 0.2124 | I10: =IF(H10="",Assumptions!$B$5,H10) -> 0.8 | J10: =Assumptions!$B$4 -> 2025 | K10: =Assumptions!$B$6 -> 2050 | L10: linear | M10: Data Sampel JKN 2022-2023 (reguler), I61 | N10: analysis/outputs/jkn_retention_by_group.csv | ski2023_coverage.csv | O10: Indonesian value; replaces the FairChoices regional/platform proxy | P10: Indonesia JKN | Q10: =IF(G10="","",I10-G10) -> 0.5876 | R10: =COUNTIF(Intervention_Cause_Map!$A$2:$A$18,B10) -> 1 | S10: =IF(R10<>1,"BAD KEY",IF(G10="","MISSING BASELINE",IF(OR(G10<0,G10>1,I10<0,I10>1,I10<G10),"BAD COVERAGE","OK"))) -> OK | T10: 0.31 | U10: Share of JKN patients with a 2022 claim (excluding those recorded as died in 2022) who had a further claim for the same condition in 2023; effective continuation of care among diagnosed patients | V10: 739
A11: CVG_10 | B11: I_HF_ACUTE__C_IHD | C11: I_HF_ACUTE | D11: C_IHD | E11: Acute heart-failure management | F11: Ischemic heart disease | G11: 0.2684 | I11: =IF(H11="",Assumptions!$B$5,H11) -> 0.8 | J11: =Assumptions!$B$4 -> 2025 | K11: =Assumptions!$B$6 -> 2050 | L11: linear | M11: Data Sampel JKN 2023 (reguler), I50 | N11: analysis/outputs/jkn_retention_by_group.csv | ski2023_coverage.csv | O11: Indonesian value; replaces the FairChoices regional/platform proxy | P11: Indonesia JKN | Q11: =IF(G11="","",I11-G11) -> 0.5316 | R11: =COUNTIF(Intervention_Cause_Map!$A$2:$A$18,B11) -> 1 | S11: =IF(R11<>1,"BAD KEY",IF(G11="","MISSING BASELINE",IF(OR(G11<0,G11>1,I11<0,I11>1,I11<G11),"BAD COVERAGE","OK"))) -> OK | T11: 0.31 | U11: Share of prevalent JKN heart-failure patients with at least one hospital admission in 2023; baseline coverage of facility-based acute management | V11: 11183
A12: CVG_11 | B12: I_HF_ACUTE__C_HHD | C12: I_HF_ACUTE | D12: C_HHD | E12: Acute heart-failure management | F12: Hypertensive heart disease | G12: 0.2684 | I12: =IF(H12="",Assumptions!$B$5,H12) -> 0.8 | J12: =Assumptions!$B$4 -> 2025 | K12: =Assumptions!$B$6 -> 2050 | L12: linear | M12: Data Sampel JKN 2023 (reguler), I50 | N12: analysis/outputs/jkn_retention_by_group.csv | ski2023_coverage.csv | O12: Indonesian value; replaces the FairChoices regional/platform proxy | P12: Indonesia JKN | Q12: =IF(G12="","",I12-G12) -> 0.5316 | R12: =COUNTIF(Intervention_Cause_Map!$A$2:$A$18,B12) -> 1 | S12: =IF(R12<>1,"BAD KEY",IF(G12="","MISSING BASELINE",IF(OR(G12<0,G12>1,I12<0,I12>1,I12<G12),"BAD COVERAGE","OK"))) -> OK | T12: 0.31 | U12: Share of prevalent JKN heart-failure patients with at least one hospital admission in 2023; baseline coverage of facility-based acute management | V12: 11183
A13: CVG_12 | B13: I_HF_ACUTE__C_CMP | C13: I_HF_ACUTE | D13: C_CMP | E13: Acute heart-failure management | F13: Cardiomyopathy and myocarditis | G13: 0.2684 | I13: =IF(H13="",Assumptions!$B$5,H13) -> 0.8 | J13: =Assumptions!$B$4 -> 2025 | K13: =Assumptions!$B$6 -> 2050 | L13: linear | M13: Data Sampel JKN 2023 (reguler), I50 | N13: analysis/outputs/jkn_retention_by_group.csv | ski2023_coverage.csv | O13: Indonesian value; replaces the FairChoices regional/platform proxy | P13: Indonesia JKN | Q13: =IF(G13="","",I13-G13) -> 0.5316 | R13: =COUNTIF(Intervention_Cause_Map!$A$2:$A$18,B13) -> 1 | S13: =IF(R13<>1,"BAD KEY",IF(G13="","MISSING BASELINE",IF(OR(G13<0,G13>1,I13<0,I13>1,I13<G13),"BAD COVERAGE","OK"))) -> OK | T13: 0.31 | U13: Share of prevalent JKN heart-failure patients with at least one hospital admission in 2023; baseline coverage of facility-based acute management | V13: 11183
A14: CVG_13 | B14: I_HF_CHRONIC__C_IHD | C14: I_HF_CHRONIC | D14: C_IHD | E14: Chronic heart-failure management | F14: Ischemic heart disease | G14: 0.5025 | I14: =IF(H14="",Assumptions!$B$5,H14) -> 0.8 | J14: =Assumptions!$B$4 -> 2025 | K14: =Assumptions!$B$6 -> 2050 | L14: linear | M14: Data Sampel JKN 2022-2023 (reguler), I50 | N14: analysis/outputs/jkn_retention_by_group.csv | ski2023_coverage.csv | O14: Indonesian value; replaces the FairChoices regional/platform proxy | P14: Indonesia JKN | Q14: =IF(G14="","",I14-G14) -> 0.2975 | R14: =COUNTIF(Intervention_Cause_Map!$A$2:$A$18,B14) -> 1 | S14: =IF(R14<>1,"BAD KEY",IF(G14="","MISSING BASELINE",IF(OR(G14<0,G14>1,I14<0,I14>1,I14<G14),"BAD COVERAGE","OK"))) -> OK | T14: 0.31 | U14: Share of JKN patients with a 2022 claim (excluding those recorded as died in 2022) who had a further claim for the same condition in 2023; effective continuation of care among diagnosed patients | V14: 9442
A15: CVG_14 | B15: I_HF_CHRONIC__C_HHD | C15: I_HF_CHRONIC | D15: C_HHD | E15: Chronic heart-failure management | F15: Hypertensive heart disease | G15: 0.5025 | I15: =IF(H15="",Assumptions!$B$5,H15) -> 0.8 | J15: =Assumptions!$B$4 -> 2025 | K15: =Assumptions!$B$6 -> 2050 | L15: linear | M15: Data Sampel JKN 2022-2023 (reguler), I50 | N15: analysis/outputs/jkn_retention_by_group.csv | ski2023_coverage.csv | O15: Indonesian value; replaces the FairChoices regional/platform proxy | P15: Indonesia JKN | Q15: =IF(G15="","",I15-G15) -> 0.2975 | R15: =COUNTIF(Intervention_Cause_Map!$A$2:$A$18,B15) -> 1 | S15: =IF(R15<>1,"BAD KEY",IF(G15="","MISSING BASELINE",IF(OR(G15<0,G15>1,I15<0,I15>1,I15<G15),"BAD COVERAGE","OK"))) -> OK | T15: 0.31 | U15: Share of JKN patients with a 2022 claim (excluding those recorded as died in 2022) who had a further claim for the same condition in 2023; effective continuation of care among diagnosed patients | V15: 9442
A16: CVG_15 | B16: I_HF_CHRONIC__C_CMP | C16: I_HF_CHRONIC | D16: C_CMP | E16: Chronic heart-failure management | F16: Cardiomyopathy and myocarditis | G16: 0.5025 | I16: =IF(H16="",Assumptions!$B$5,H16) -> 0.8 | J16: =Assumptions!$B$4 -> 2025 | K16: =Assumptions!$B$6 -> 2050 | L16: linear | M16: Data Sampel JKN 2022-2023 (reguler), I50 | N16: analysis/outputs/jkn_retention_by_group.csv | ski2023_coverage.csv | O16: Indonesian value; replaces the FairChoices regional/platform proxy | P16: Indonesia JKN | Q16: =IF(G16="","",I16-G16) -> 0.2975 | R16: =COUNTIF(Intervention_Cause_Map!$A$2:$A$18,B16) -> 1 | S16: =IF(R16<>1,"BAD KEY",IF(G16="","MISSING BASELINE",IF(OR(G16<0,G16>1,I16<0,I16>1,I16<G16),"BAD COVERAGE","OK"))) -> OK | T16: 0.31 | U16: Share of JKN patients with a 2022 claim (excluding those recorded as died in 2022) who had a further claim for the same condition in 2023; effective continuation of care among diagnosed patients | V16: 9442
A17: CVG_16 | B17: I_T2D_TREATMENT__C_T2D | C17: I_T2D_TREATMENT | D17: C_T2D | E17: Longitudinal treatment of type 2 diabetes | F17: Diabetes mellitus type 2 | G17: 0.213 | I17: =IF(H17="",Assumptions!$B$5,H17) -> 0.8 | J17: =Assumptions!$B$4 -> 2025 | K17: =Assumptions!$B$6 -> 2050 | L17: linear | M17: SKI 2023 (harmonized), dm_final_status + dm_ever_treated | N17: analysis/outputs/jkn_retention_by_group.csv | ski2023_coverage.csv | O17: Indonesian value; replaces the FairChoices regional/platform proxy | P17: Indonesia SKI 2023 | Q17: =IF(G17="","",I17-G17) -> 0.587 | R17: =COUNTIF(Intervention_Cause_Map!$A$2:$A$18,B17) -> 1 | S17: =IF(R17<>1,"BAD KEY",IF(G17="","MISSING BASELINE",IF(OR(G17<0,G17>1,I17<0,I17>1,I17<G17),"BAD COVERAGE","OK"))) -> OK | U17: Share of laboratory-confirmed diabetics aged 30+ ever treated for diabetes, weight_diabetes
A18: CVG_17 | B18: I_T2D_TREATMENT__C_IHD | C18: I_T2D_TREATMENT | D18: C_IHD | E18: Longitudinal treatment of type 2 diabetes | F18: Ischemic heart disease attributable to high blood glucose | G18: 0.213 | I18: =IF(H18="",Assumptions!$B$5,H18) -> 0.8 | J18: =Assumptions!$B$4 -> 2025 | K18: =Assumptions!$B$6 -> 2050 | L18: linear | M18: SKI 2023 (harmonized), dm_final_status + dm_ever_treated | N18: analysis/outputs/jkn_retention_by_group.csv | ski2023_coverage.csv | O18: Indonesian value; replaces the FairChoices regional/platform proxy | P18: Indonesia SKI 2023 | Q18: =IF(G18="","",I18-G18) -> 0.587 | R18: =COUNTIF(Intervention_Cause_Map!$A$2:$A$18,B18) -> 1 | S18: =IF(R18<>1,"BAD KEY",IF(G18="","MISSING BASELINE",IF(OR(G18<0,G18>1,I18<0,I18>1,I18<G18),"BAD COVERAGE","OK"))) -> OK | U18: Share of laboratory-confirmed diabetics aged 30+ ever treated for diabetes, weight_diabetes

Sheet Cost_Components
A1: cost_record_id | B1: cost_component_key | C1: cost_option | D1: selected_for_base_case | E1: intervention_id | F1: cause_id | G1: cost_join_key | H1: intervention_name | I1: cause_name | J1: cost_component | K1: population_in_need_measure | L1: population_in_need_fraction | M1: cost_unit | N1: frequency_per_year | O1: age_start | P1: age_stop | Q1: sex | R1: platform | S1: unit_cost_usd | T1: price_year | U1: indonesia_adjusted_flag | V1: source_country | W1: source_file | X1: source_row | Y1: review_status | Z1: notes | AA1: map_match_count | AB1: selection_count | AC1: qa_status | AD1: unit_cost_idr_2023 | AE1: unit_cost_usd_previous | AF1: jkn_basis | AG1: jkn_n_insample
A2: COST_RHD_SEC_01 | B2: CC_RHD_SECONDARY_PENICILLIN | C2: Indonesia JKN 2023 (selected) | D2: 1 | E2: I_RHD_SECONDARY | F2: C_RHD | G2: I_RHD_SECONDARY__C_RHD | H2: RHD secondary prevention | I2: Rheumatic heart disease | J2: Secondary prophylaxis with penicillin | K2: prevalence | L2: 1 | M2: USD per patient-year | N2: 1 | O2: 5 | P2: 39 | Q2: Both | R2: Health center | S2: 68.174793 | T2: 2023 | U2: 1 | V2: Indonesia | W2: Data Sampel JKN (bpjs_data.reguler.fkrtl), claim year 2023 | X2: analysis/outputs/jkn_cost_by_group.csv | Y2: Indonesia JKN | Z2: Replaces the FairChoices transferred cost with an observed Indonesian JKN value. Converted at Rp 15,237/USD (2023 period average). NCD-E-12 revision 2026-09-01. | AA2: =COUNTIF(Intervention_Cause_Map!$I$2:$I$18,G2) -> 1 | AB2: =SUMIF($B$2:$B$35,B2,$D$2:$D$35) -> 1 | AC2: =IF(AA2<1,"BAD KEY",IF(S2="","MISSING COST",IF(U2=0,"REVIEW ADJUSTMENT",IF(AB2<>1,"CHECK SELECTION","OK")))) -> OK | AD2: 1038779 | AE2: 50.857354 | AF2: FKRTL outpatient spend per RHD patient in outpatient care, 2023 [ICD-10 I05-I09] | AG2: 769
A3: COST_RHD_SURG_01 | B3: CC_RHD_SURGERY | C3: Indonesia JKN 2023 (selected) | D3: 1 | E3: I_RHD_SURGERY | F3: C_RHD | G3: I_RHD_SURGERY__C_RHD | H3: RHD cardiac surgery | I3: Rheumatic heart disease | J3: Rheumatic heart disease cardiac surgery | K3: prevalence | L3: 1 | M3: USD per procedure | N3: =Assumptions!$B$13 -> 1 | O3: 5 | P3: 40 | Q3: Both | R3: Hospital | S3: 3766.311 | T3: 2023 | U3: 1 | V3: Indonesia | W3: Data Sampel JKN (bpjs_data.reguler.fkrtl), claim year 2023 | X3: analysis/outputs/jkn_cost_by_group.csv | Y3: Indonesia JKN | Z3: Replaces the FairChoices transferred cost with an observed Indonesian JKN value. Converted at Rp 15,237/USD (2023 period average). NCD-E-12 revision 2026-09-01. Small in-sample base (n=65); treat as indicative and widen the PSA range. | AA3: =COUNTIF(Intervention_Cause_Map!$I$2:$I$18,G3) -> 1 | AB3: =SUMIF($B$2:$B$35,B3,$D$2:$D$35) -> 1 | AC3: =IF(AA3<1,"BAD KEY",IF(S3="","MISSING COST",IF(U3=0,"REVIEW ADJUSTMENT",IF(AB3<>1,"CHECK SELECTION","OK")))) -> OK | AD3: 57387280 | AE3: 12488.386 | AF3: Mean INA-CBG paid amount per RHD inpatient episode with an inpatient procedure group, 2023 [ICD-10 I05-I09] | AG3: 65
A4: COST_PRIMARY_SCREEN_A | B4: CC_PRIMARY_SCREENING | C4: Option A (selected) | D4: 1 | E4: I_CVD_PRIMARY | F4: C_SHARED | G4: I_CVD_PRIMARY__C_SHARED | H4: Primary prevention of CVD | I4: Shared primary CVD cost | J4: CVD targeted screening | K4: all | L4: 0.2 | M4: USD per eligible person-year | N4: 1 | O4: 30 | P4: 95 | Q4: Both | R4: Health center | S4: 1.291584 | T4: 2023 | U4: 1 | V4: Tanzania | W4: cvd_unit_cost_indonesia_1(1).xlsx | X4: row 15 | Y4: Review - no JKN equivalent | Z4: Population screening is delivered at FKTP/Posbindu under capitation, so it generates no fee-for-service claim in the JKN sample. FairChoices Indonesia-adjusted value retained. JKN reference for a specialist outpatient contact: Rp 248,443 per visit (hypertension, 2023). | AA4: =COUNTIF(Intervention_Cause_Map!$I$2:$I$18,G4) -> 4 | AB4: =SUMIF($B$2:$B$35,B4,$D$2:$D$35) -> 1 | AC4: =IF(AA4<1,"BAD KEY",IF(S4="","MISSING COST",IF(U4=0,"REVIEW ADJUSTMENT",IF(AB4<>1,"CHECK SELECTION","OK")))) -> OK | AF4: No JKN claims equivalent
A5: COST_PRIMARY_SCREEN_B | B5: CC_PRIMARY_SCREENING | C5: Option B | D5: 0 | E5: I_CVD_PRIMARY | F5: C_SHARED | G5: I_CVD_PRIMARY__C_SHARED | H5: Primary prevention of CVD | I5: Shared primary CVD cost | J5: CVD targeted screening | K5: all | L5: 0.2 | M5: USD per eligible person-year | N5: 1 | O5: 30 | P5: 95 | Q5: Both | R5: Health center | S5: 2.766522 | T5: 2023 | U5: 1 | V5: Tanzania | W5: cvd_unit_cost_indonesia_1(1).xlsx | X5: row 16 | Y5: Alternative | Z5: Alternative salary-adjustment option | AA5: =COUNTIF(Intervention_Cause_Map!$I$2:$I$18,G5) -> 4 | AB5: =SUMIF($B$2:$B$35,B5,$D$2:$D$35) -> 1 | AC5: =IF(AA5<1,"BAD KEY",IF(S5="","MISSING COST",IF(U5=0,"REVIEW ADJUSTMENT",IF(AB5<>1,"CHECK SELECTION","OK")))) -> OK
A6: COST_PRIMARY_TX_A | B6: CC_PRIMARY_HTN_STATIN | C6: Indonesia JKN 2023 (selected) | D6: 1 | E6: I_CVD_PRIMARY | F6: C_SHARED | G6: I_CVD_PRIMARY__C_SHARED | H6: Primary prevention of CVD | I6: Shared primary CVD cost | J6: Antihypertensives and statins for absolute CVD risk >20% | K6: all | L6: 0.06 | M6: USD per eligible person-year | N6: 1 | O6: 30 | P6: 95 | Q6: Both | R6: Health center | S6: 69.304995 | T6: 2023 | U6: 1 | V6: Indonesia | W6: Data Sampel JKN (bpjs_data.reguler.fkrtl), claim year 2023 | X6: analysis/outputs/jkn_cost_by_group.csv | Y6: Indonesia JKN | Z6: Replaces the FairChoices transferred cost with an observed Indonesian JKN value. Converted at Rp 15,237/USD (2023 period average). NCD-E-12 revision 2026-09-01. | AA6: =COUNTIF(Intervention_Cause_Map!$I$2:$I$18,G6) -> 4 | AB6: =SUMIF($B$2:$B$35,B6,$D$2:$D$35) -> 1 | AC6: =IF(AA6<1,"BAD KEY",IF(S6="","MISSING COST",IF(U6=0,"REVIEW ADJUSTMENT",IF(AB6<>1,"CHECK SELECTION","OK")))) -> OK | AD6: 1056000 | AE6: 22.2296 | AF6: FKRTL outpatient spend per hypertension patient in outpatient care, 2023 [ICD-10 I10-I15] | AG6: 32889
A7: COST_PRIMARY_TX_B | B7: CC_PRIMARY_HTN_STATIN | C7: Option B | D7: 0 | E7: I_CVD_PRIMARY | F7: C_SHARED | G7: I_CVD_PRIMARY__C_SHARED | H7: Primary prevention of CVD | I7: Shared primary CVD cost | J7: Antihypertensives and statins for absolute CVD risk >20% | K7: all | L7: 0.06 | M7: USD per eligible person-year | N7: 1 | O7: 30 | P7: 95 | Q7: Both | R7: Health center | S7: 40.487719 | T7: 2023 | U7: 1 | V7: Tanzania | W7: cvd_unit_cost_indonesia_1(1).xlsx | X7: row 18 | Y7: Alternative | Z7: Alternative salary-adjustment option | AA7: =COUNTIF(Intervention_Cause_Map!$I$2:$I$18,G7) -> 4 | AB7: =SUMIF($B$2:$B$35,B7,$D$2:$D$35) -> 1 | AC7: =IF(AA7<1,"BAD KEY",IF(S7="","MISSING COST",IF(U7=0,"REVIEW ADJUSTMENT",IF(AB7<>1,"CHECK SELECTION","OK")))) -> OK
A8: COST_IHD_SEC_CF_A | B8: CC_IHD_SECONDARY_CASE_FINDING | C8: Indonesia JKN 2023 (selected) | D8: 1 | E8: I_IHD_SECONDARY | F8: C_IHD | G8: I_IHD_SECONDARY__C_IHD | H8: Secondary prevention of ischemic heart disease | I8: Ischemic heart disease | J8: Case finding and diagnosis | K8: incidence | L8: 0.52 | M8: USD per incident case | N8: 1 | O8: 0 | P8: 95 | Q8: Both | R8: Hospital | S8: 677.26935 | T8: 2023 | U8: 1 | V8: Indonesia | W8: Data Sampel JKN (bpjs_data.reguler.fkrtl), claim year 2023 | X8: analysis/outputs/jkn_cost_by_group.csv | Y8: Indonesia JKN | Z8: Replaces the FairChoices transferred cost with an observed Indonesian JKN value. Converted at Rp 15,237/USD (2023 period average). NCD-E-12 revision 2026-09-01. Scope differs from the FairChoices component: an INA-CBG episode is paid as one all-inclusive package, so this is the full first-ever admission (diagnosis plus acute treatment), not diagnostic work-up alone. Check for overlap with the paired TREATMENT component before summing. | AA8: =COUNTIF(Intervention_Cause_Map!$I$2:$I$18,G8) -> 1 | AB8: =SUMIF($B$2:$B$35,B8,$D$2:$D$35) -> 1 | AC8: =IF(AA8<1,"BAD KEY",IF(S8="","MISSING COST",IF(U8=0,"REVIEW ADJUSTMENT",IF(AB8<>1,"CHECK SELECTION","OK")))) -> OK | AD8: 10319553 | AE8: 35.362649 | AF8: Mean INA-CBG paid amount for the first-ever IHD inpatient episode (no IHD claim 2015-2022), 2023 [ICD-10 I20-I25] | AG8: 4061
A9: COST_IHD_SEC_CF_B | B9: CC_IHD_SECONDARY_CASE_FINDING | C9: Option B | D9: 0 | E9: I_IHD_SECONDARY | F9: C_IHD | G9: I_IHD_SECONDARY__C_IHD | H9: Secondary prevention of ischemic heart disease | I9: Ischemic heart disease | J9: Case finding and diagnosis | K9: incidence | L9: 0.52 | M9: USD per incident case | N9: 1 | O9: 0 | P9: 95 | Q9: Both | R9: Hospital | S9: 64.943441 | T9: 2023 | U9: 1 | V9: Tanzania | W9: cvd_unit_cost_indonesia_1(1).xlsx | X9: row 44 | Y9: Alternative | Z9: Alternative salary-adjustment option | AA9: =COUNTIF(Intervention_Cause_Map!$I$2:$I$18,G9) -> 1 | AB9: =SUMIF($B$2:$B$35,B9,$D$2:$D$35) -> 1 | AC9: =IF(AA9<1,"BAD KEY",IF(S9="","MISSING COST",IF(U9=0,"REVIEW ADJUSTMENT",IF(AB9<>1,"CHECK SELECTION","OK")))) -> OK
A10: COST_IHD_SEC_FU | B10: CC_IHD_SECONDARY_FOLLOWUP | C10: Indonesia JKN 2023 (selected) | D10: 1 | E10: I_IHD_SECONDARY | F10: C_IHD | G10: I_IHD_SECONDARY__C_IHD | H10: Secondary prevention of ischemic heart disease | I10: Ischemic heart disease | J10: Lab tests and follow-up visits for IHD patients | K10: prevalence | L10: 1 | M10: USD per patient-year | N10: 1 | O10: 0 | P10: 95 | Q10: Both | R10: Hospital | S10: 77.628668 | T10: 2023 | U10: 1 | V10: Indonesia | W10: Data Sampel JKN (bpjs_data.reguler.fkrtl), claim year 2023 | X10: analysis/outputs/jkn_cost_by_group.csv | Y10: Indonesia JKN | Z10: Replaces the FairChoices transferred cost with an observed Indonesian JKN value. Converted at Rp 15,237/USD (2023 period average). NCD-E-12 revision 2026-09-01. | AA10: =COUNTIF(Intervention_Cause_Map!$I$2:$I$18,G10) -> 1 | AB10: =SUMIF($B$2:$B$35,B10,$D$2:$D$35) -> 1 | AC10: =IF(AA10<1,"BAD KEY",IF(S10="","MISSING COST",IF(U10=0,"REVIEW ADJUSTMENT",IF(AB10<>1,"CHECK SELECTION","OK")))) -> OK | AD10: 1182828 | AE10: 119.72149 | AF10: FKRTL outpatient spend per IHD patient in outpatient care, 2023 [ICD-10 I20-I25] | AG10: 13330
A11: COST_IHD_SEC_TX | B11: CC_IHD_SECONDARY_TREATMENT | C11: Indonesia JKN 2023 (selected) | D11: 1 | E11: I_IHD_SECONDARY | F11: C_IHD | G11: I_IHD_SECONDARY__C_IHD | H11: Secondary prevention of ischemic heart disease | I11: Ischemic heart disease | J11: Treatment cost for IHD patients | K11: prevalence | L11: 1 | M11: USD per patient-year | N11: 1 | O11: 0 | P11: 95 | Q11: Both | R11: Hospital | S11: 213.29057 | T11: 2023 | U11: 1 | V11: Indonesia | W11: Data Sampel JKN (bpjs_data.reguler.fkrtl), claim year 2023 | X11: analysis/outputs/jkn_cost_by_group.csv | Y11: Indonesia JKN | Z11: Replaces the FairChoices transferred cost with an observed Indonesian JKN value. Converted at Rp 15,237/USD (2023 period average). NCD-E-12 revision 2026-09-01. | AA11: =COUNTIF(Intervention_Cause_Map!$I$2:$I$18,G11) -> 1 | AB11: =SUMIF($B$2:$B$35,B11,$D$2:$D$35) -> 1 | AC11: =IF(AA11<1,"BAD KEY",IF(S11="","MISSING COST",IF(U11=0,"REVIEW ADJUSTMENT",IF(AB11<>1,"CHECK SELECTION","OK")))) -> OK | AD11: 3249908 | AE11: 36.463998 | AF11: Recurrent (non-first-ever) inpatient spend per prevalent IHD patient, 2023 [ICD-10 I20-I25] | AG11: 7700
A12: COST_STROKE_IS_CF | B12: CC_STROKE_IS_CASE_FINDING | C12: Indonesia JKN 2023 (selected) | D12: 1 | E12: I_STROKE_SECONDARY | F12: C_IS | G12: I_STROKE_SECONDARY__C_IS | H12: Secondary prevention of stroke | I12: Ischemic stroke | J12: Case finding and diagnosis | K12: incidence | L12: 0.52 | M12: USD per incident case | N12: 1 | O12: 30 | P12: 95 | Q12: Both | R12: Hospital | S12: 574.50204 | T12: 2023 | U12: 1 | V12: Indonesia | W12: Data Sampel JKN (bpjs_data.reguler.fkrtl), claim year 2023 | X12: analysis/outputs/jkn_cost_by_group.csv | Y12: Indonesia JKN | Z12: Replaces the FairChoices transferred cost with an observed Indonesian JKN value. Converted at Rp 15,237/USD (2023 period average). NCD-E-12 revision 2026-09-01. Scope differs from the FairChoices component: an INA-CBG episode is paid as one all-inclusive package, so this is the full first-ever admission (diagnosis plus acute treatment), not diagnostic work-up alone. Check for overlap with the paired TREATMENT component before summing. | AA12: =COUNTIF(Intervention_Cause_Map!$I$2:$I$18,G12) -> 1 | AB12: =SUMIF($B$2:$B$35,B12,$D$2:$D$35) -> 1 | AC12: =IF(AA12<1,"BAD KEY",IF(S12="","MISSING COST",IF(U12=0,"REVIEW ADJUSTMENT",IF(AB12<>1,"CHECK SELECTION","OK")))) -> OK | AD12: 8753688 | AE12: 186.47979 | AF12: Mean INA-CBG paid amount for the first-ever ischaemic-stroke inpatient episode, 2023 [ICD-10 I63] | AG12: 2947
A13: COST_STROKE_IS_LAB_A | B13: CC_STROKE_IS_FOLLOWUP | C13: Indonesia JKN 2023 (selected) | D13: 1 | E13: I_STROKE_SECONDARY | F13: C_IS | G13: I_STROKE_SECONDARY__C_IS | H13: Secondary prevention of stroke | I13: Ischemic stroke | J13: Lab tests and follow-up visits | K13: prevalence | L13: 0.5 | M13: USD per patient-year | N13: 1 | O13: 30 | P13: 95 | Q13: Both | R13: Hospital | S13: 71.302158 | T13: 2023 | U13: 1 | V13: Indonesia | W13: Data Sampel JKN (bpjs_data.reguler.fkrtl), claim year 2023 | X13: analysis/outputs/jkn_cost_by_group.csv | Y13: Indonesia JKN | Z13: Replaces the FairChoices transferred cost with an observed Indonesian JKN value. Converted at Rp 15,237/USD (2023 period average). NCD-E-12 revision 2026-09-01. | AA13: =COUNTIF(Intervention_Cause_Map!$I$2:$I$18,G13) -> 1 | AB13: =SUMIF($B$2:$B$35,B13,$D$2:$D$35) -> 1 | AC13: =IF(AA13<1,"BAD KEY",IF(S13="","MISSING COST",IF(U13=0,"REVIEW ADJUSTMENT",IF(AB13<>1,"CHECK SELECTION","OK")))) -> OK | AD13: 1086431 | AE13: 35.362649 | AF13: FKRTL outpatient spend per ischaemic-stroke patient in outpatient care, 2023 [ICD-10 I63] | AG13: 4819
A14: COST_STROKE_IS_LAB_B | B14: CC_STROKE_IS_FOLLOWUP | C14: Option B | D14: 0 | E14: I_STROKE_SECONDARY | F14: C_IS | G14: I_STROKE_SECONDARY__C_IS | H14: Secondary prevention of stroke | I14: Ischemic stroke | J14: Lab tests and follow-up visits | K14: prevalence | L14: 0.5 | M14: USD per patient-year | N14: 1 | O14: 30 | P14: 95 | Q14: Both | R14: Hospital | S14: 64.943441 | T14: 2023 | U14: 1 | V14: Tanzania | W14: cvd_unit_cost_indonesia_1(1).xlsx | X14: row 38 | Y14: Alternative | Z14: Alternative salary-adjustment option | AA14: =COUNTIF(Intervention_Cause_Map!$I$2:$I$18,G14) -> 1 | AB14: =SUMIF($B$2:$B$35,B14,$D$2:$D$35) -> 1 | AC14: =IF(AA14<1,"BAD KEY",IF(S14="","MISSING COST",IF(U14=0,"REVIEW ADJUSTMENT",IF(AB14<>1,"CHECK SELECTION","OK")))) -> OK
A15: COST_STROKE_IS_TX | B15: CC_STROKE_IS_TREATMENT | C15: Indonesia JKN 2023 (selected) | D15: 1 | E15: I_STROKE_SECONDARY | F15: C_IS | G15: I_STROKE_SECONDARY__C_IS | H15: Secondary prevention of stroke | I15: Ischemic stroke | J15: Treatment cost for stroke patients | K15: prevalence | L15: 0.5 | M15: USD per patient-year | N15: 1 | O15: 30 | P15: 95 | Q15: Both | R15: Hospital | S15: 172.27746 | T15: 2023 | U15: 1 | V15: Indonesia | W15: Data Sampel JKN (bpjs_data.reguler.fkrtl), claim year 2023 | X15: analysis/outputs/jkn_cost_by_group.csv | Y15: Indonesia JKN | Z15: Replaces the FairChoices transferred cost with an observed Indonesian JKN value. Converted at Rp 15,237/USD (2023 period average). NCD-E-12 revision 2026-09-01. | AA15: =COUNTIF(Intervention_Cause_Map!$I$2:$I$18,G15) -> 1 | AB15: =SUMIF($B$2:$B$35,B15,$D$2:$D$35) -> 1 | AC15: =IF(AA15<1,"BAD KEY",IF(S15="","MISSING COST",IF(U15=0,"REVIEW ADJUSTMENT",IF(AB15<>1,"CHECK SELECTION","OK")))) -> OK | AD15: 2624992 | AE15: 119.72149 | AF15: Recurrent (non-first-ever) inpatient spend per prevalent ischaemic-stroke patient, 2023 [ICD-10 I63] | AG15: 2196
A16: COST_STROKE_ICH_CF_A | B16: CC_STROKE_ICH_CASE_FINDING | C16: Indonesia JKN 2023 (selected) | D16: 1 | E16: I_STROKE_SECONDARY | F16: C_ICH | G16: I_STROKE_SECONDARY__C_ICH | H16: Secondary prevention of stroke | I16: Intracerebral hemorrhage | J16: Case finding and diagnosis | K16: incidence | L16: 0.52 | M16: USD per incident case | N16: 1 | O16: 30 | P16: 95 | Q16: Both | R16: Hospital | S16: 1035.0049 | T16: 2023 | U16: 1 | V16: Indonesia | W16: Data Sampel JKN (bpjs_data.reguler.fkrtl), claim year 2023 | X16: analysis/outputs/jkn_cost_by_group.csv | Y16: Indonesia JKN | Z16: Replaces the FairChoices transferred cost with an observed Indonesian JKN value. Converted at Rp 15,237/USD (2023 period average). NCD-E-12 revision 2026-09-01. Scope differs from the FairChoices component: an INA-CBG episode is paid as one all-inclusive package, so this is the full first-ever admission (diagnosis plus acute treatment), not diagnostic work-up alone. Check for overlap with the paired TREATMENT component before summing. | AA16: =COUNTIF(Intervention_Cause_Map!$I$2:$I$18,G16) -> 1 | AB16: =SUMIF($B$2:$B$35,B16,$D$2:$D$35) -> 1 | AC16: =IF(AA16<1,"BAD KEY",IF(S16="","MISSING COST",IF(U16=0,"REVIEW ADJUSTMENT",IF(AB16<>1,"CHECK SELECTION","OK")))) -> OK | AD16: 15770369 | AE16: 550.94829 | AF16: Mean INA-CBG paid amount for the first-ever intracerebral-haemorrhage inpatient episode, 2023 [ICD-10 I61] | AG16: 745
A17: COST_STROKE_ICH_CF_B | B17: CC_STROKE_ICH_CASE_FINDING | C17: Option B | D17: 0 | E17: I_STROKE_SECONDARY | F17: C_ICH | G17: I_STROKE_SECONDARY__C_ICH | H17: Secondary prevention of stroke | I17: Intracerebral hemorrhage | J17: Case finding and diagnosis | K17: incidence | L17: 0.52 | M17: USD per incident case | N17: 1 | O17: 30 | P17: 95 | Q17: Both | R17: Hospital | S17: 900.25859 | T17: 2023 | U17: 1 | V17: Tanzania | W17: cvd_unit_cost_indonesia_1(1).xlsx | X17: row 34 | Y17: Alternative | Z17: Alternative salary-adjustment option | AA17: =COUNTIF(Intervention_Cause_Map!$I$2:$I$18,G17) -> 1 | AB17: =SUMIF($B$2:$B$35,B17,$D$2:$D$35) -> 1 | AC17: =IF(AA17<1,"BAD KEY",IF(S17="","MISSING COST",IF(U17=0,"REVIEW ADJUSTMENT",IF(AB17<>1,"CHECK SELECTION","OK")))) -> OK
A18: COST_STROKE_ICH_LAB_A | B18: CC_STROKE_ICH_FOLLOWUP | C18: Indonesia JKN 2023 (selected) | D18: 1 | E18: I_STROKE_SECONDARY | F18: C_ICH | G18: I_STROKE_SECONDARY__C_ICH | H18: Secondary prevention of stroke | I18: Intracerebral hemorrhage | J18: Lab tests and follow-up visits | K18: prevalence | L18: 0.5 | M18: USD per patient-year | N18: 1 | O18: 30 | P18: 95 | Q18: Both | R18: Hospital | S18: 56.227229 | T18: 2023 | U18: 1 | V18: Indonesia | W18: Data Sampel JKN (bpjs_data.reguler.fkrtl), claim year 2023 | X18: analysis/outputs/jkn_cost_by_group.csv | Y18: Indonesia JKN | Z18: Replaces the FairChoices transferred cost with an observed Indonesian JKN value. Converted at Rp 15,237/USD (2023 period average). NCD-E-12 revision 2026-09-01. | AA18: =COUNTIF(Intervention_Cause_Map!$I$2:$I$18,G18) -> 1 | AB18: =SUMIF($B$2:$B$35,B18,$D$2:$D$35) -> 1 | AC18: =IF(AA18<1,"BAD KEY",IF(S18="","MISSING COST",IF(U18=0,"REVIEW ADJUSTMENT",IF(AB18<>1,"CHECK SELECTION","OK")))) -> OK | AD18: 856734 | AE18: 35.362649 | AF18: FKRTL outpatient spend per intracerebral-haemorrhage patient in outpatient care, 2023 [ICD-10 I61] | AG18: 738
A19: COST_STROKE_ICH_LAB_B | B19: CC_STROKE_ICH_FOLLOWUP | C19: Option B | D19: 0 | E19: I_STROKE_SECONDARY | F19: C_ICH | G19: I_STROKE_SECONDARY__C_ICH | H19: Secondary prevention of stroke | I19: Intracerebral hemorrhage | J19: Lab tests and follow-up visits | K19: prevalence | L19: 0.5 | M19: USD per patient-year | N19: 1 | O19: 30 | P19: 95 | Q19: Both | R19: Hospital | S19: 64.943441 | T19: 2023 | U19: 1 | V19: Tanzania | W19: cvd_unit_cost_indonesia_1(1).xlsx | X19: row 36 | Y19: Alternative | Z19: Alternative salary-adjustment option | AA19: =COUNTIF(Intervention_Cause_Map!$I$2:$I$18,G19) -> 1 | AB19: =SUMIF($B$2:$B$35,B19,$D$2:$D$35) -> 1 | AC19: =IF(AA19<1,"BAD KEY",IF(S19="","MISSING COST",IF(U19=0,"REVIEW ADJUSTMENT",IF(AB19<>1,"CHECK SELECTION","OK")))) -> OK
A20: COST_STROKE_ICH_TX | B20: CC_STROKE_ICH_TREATMENT | C20: Indonesia JKN 2023 (selected) | D20: 1 | E20: I_STROKE_SECONDARY | F20: C_ICH | G20: I_STROKE_SECONDARY__C_ICH | H20: Secondary prevention of stroke | I20: Intracerebral hemorrhage | J20: Treatment cost for stroke patients | K20: prevalence | L20: 0.5 | M20: USD per patient-year | N20: 1 | O20: 30 | P20: 95 | Q20: Both | R20: Hospital | S20: 272.7886 | T20: 2023 | U20: 1 | V20: Indonesia | W20: Data Sampel JKN (bpjs_data.reguler.fkrtl), claim year 2023 | X20: analysis/outputs/jkn_cost_by_group.csv | Y20: Indonesia JKN | Z20: Replaces the FairChoices transferred cost with an observed Indonesian JKN value. Converted at Rp 15,237/USD (2023 period average). NCD-E-12 revision 2026-09-01. Small in-sample base (n=214); treat as indicative and widen the PSA range. | AA20: =COUNTIF(Intervention_Cause_Map!$I$2:$I$18,G20) -> 1 | AB20: =SUMIF($B$2:$B$35,B20,$D$2:$D$35) -> 1 | AC20: =IF(AA20<1,"BAD KEY",IF(S20="","MISSING COST",IF(U20=0,"REVIEW ADJUSTMENT",IF(AB20<>1,"CHECK SELECTION","OK")))) -> OK | AD20: 4156480 | AE20: 119.72149 | AF20: Recurrent (non-first-ever) inpatient spend per prevalent intracerebral-haemorrhage patient, 2023 [ICD-10 I61] | AG20: 214
A21: COST_HF_ACUTE_C_IHD | B21: CC_HF_ACUTE_C_IHD | C21: Indonesia JKN 2023 (selected) | D21: 1 | E21: I_HF_ACUTE | F21: C_IHD | G21: I_HF_ACUTE__C_IHD | H21: Acute heart-failure management | I21: Ischemic heart disease | J21: Acute heart-failure management package | K21: prevalence | L21: 0.1 | M21: USD per acute episode | N21: 1 | O21: 30 | P21: 95 | Q21: Both | R21: Hospital | S21: 575.48695 | T21: 2023 | U21: 1 | V21: Indonesia | W21: Data Sampel JKN (bpjs_data.reguler.fkrtl), claim year 2023 | X21: analysis/outputs/jkn_cost_by_group.csv | Y21: Indonesia JKN | Z21: Replaces the FairChoices transferred cost with an observed Indonesian JKN value. Converted at Rp 15,237/USD (2023 period average). NCD-E-12 revision 2026-09-01. | AA21: =COUNTIF(Intervention_Cause_Map!$I$2:$I$18,G21) -> 1 | AB21: =SUMIF($B$2:$B$35,B21,$D$2:$D$35) -> 1 | AC21: =IF(AA21<1,"BAD KEY",IF(S21="","MISSING COST",IF(U21=0,"REVIEW ADJUSTMENT",IF(AB21<>1,"CHECK SELECTION","OK")))) -> OK | AD21: 8768695 | AE21: 282.51284 | AF21: Mean INA-CBG paid amount per heart-failure inpatient episode, 2023 [ICD-10 I50] | AG21: 3813
A22: COST_HF_ACUTE_C_HHD | B22: CC_HF_ACUTE_C_HHD | C22: Indonesia JKN 2023 (selected) | D22: 1 | E22: I_HF_ACUTE | F22: C_HHD | G22: I_HF_ACUTE__C_HHD | H22: Acute heart-failure management | I22: Hypertensive heart disease | J22: Acute heart-failure management package | K22: prevalence | L22: 0.5 | M22: USD per acute episode | N22: 1 | O22: 30 | P22: 95 | Q22: Both | R22: Hospital | S22: 575.48695 | T22: 2023 | U22: 1 | V22: Indonesia | W22: Data Sampel JKN (bpjs_data.reguler.fkrtl), claim year 2023 | X22: analysis/outputs/jkn_cost_by_group.csv | Y22: Indonesia JKN | Z22: Replaces the FairChoices transferred cost with an observed Indonesian JKN value. Converted at Rp 15,237/USD (2023 period average). NCD-E-12 revision 2026-09-01. | AA22: =COUNTIF(Intervention_Cause_Map!$I$2:$I$18,G22) -> 1 | AB22: =SUMIF($B$2:$B$35,B22,$D$2:$D$35) -> 1 | AC22: =IF(AA22<1,"BAD KEY",IF(S22="","MISSING COST",IF(U22=0,"REVIEW ADJUSTMENT",IF(AB22<>1,"CHECK SELECTION","OK")))) -> OK | AD22: 8768695 | AE22: 282.51284 | AF22: Mean INA-CBG paid amount per heart-failure inpatient episode, 2023 [ICD-10 I50] | AG22: 3813
A23: COST_HF_ACUTE_C_CMP | B23: CC_HF_ACUTE_C_CMP | C23: Indonesia JKN 2023 (selected) | D23: 1 | E23: I_HF_ACUTE | F23: C_CMP | G23: I_HF_ACUTE__C_CMP | H23: Acute heart-failure management | I23: Cardiomyopathy and myocarditis | J23: Acute heart-failure management package | K23: prevalence | L23: 0.5 | M23: USD per acute episode | N23: 1 | O23: 30 | P23: 95 | Q23: Both | R23: Hospital | S23: 575.48695 | T23: 2023 | U23: 1 | V23: Indonesia | W23: Data Sampel JKN (bpjs_data.reguler.fkrtl), claim year 2023 | X23: analysis/outputs/jkn_cost_by_group.csv | Y23: Indonesia JKN | Z23: Replaces the FairChoices transferred cost with an observed Indonesian JKN value. Converted at Rp 15,237/USD (2023 period average). NCD-E-12 revision 2026-09-01. | AA23: =COUNTIF(Intervention_Cause_Map!$I$2:$I$18,G23) -> 1 | AB23: =SUMIF($B$2:$B$35,B23,$D$2:$D$35) -> 1 | AC23: =IF(AA23<1,"BAD KEY",IF(S23="","MISSING COST",IF(U23=0,"REVIEW ADJUSTMENT",IF(AB23<>1,"CHECK SELECTION","OK")))) -> OK | AD23: 8768695 | AE23: 282.51284 | AF23: Mean INA-CBG paid amount per heart-failure inpatient episode, 2023 [ICD-10 I50] | AG23: 3813
A24: COST_HF_CHRONIC_CMP_ECHO | B24: CC_HF_CHRONIC_CMP_ECHO | C24: Base | D24: 1 | E24: I_HF_CHRONIC | F24: C_CMP | G24: I_HF_CHRONIC__C_CMP | H24: Chronic heart-failure management | I24: Cardiomyopathy and myocarditis | J24: One cardiac echo per year | K24: prevalence | L24: 1 | M24: USD per patient-year | N24: 1 | O24: 0 | P24: 95 | Q24: Both | R24: Hospital | S24: 5.133311 | T24: 2023 | U24: 1 | V24: Brazil | W24: cvd_unit_cost_indonesia_1(1).xlsx | X24: row 19 | Y24: Review - no JKN equivalent | Z24: Echocardiography is bundled inside the INA-CBG package and cannot be priced separately from claims. FairChoices Indonesia-adjusted value retained. | AA24: =COUNTIF(Intervention_Cause_Map!$I$2:$I$18,G24) -> 1 | AB24: =SUMIF($B$2:$B$35,B24,$D$2:$D$35) -> 1 | AC24: =IF(AA24<1,"BAD KEY",IF(S24="","MISSING COST",IF(U24=0,"REVIEW ADJUSTMENT",IF(AB24<>1,"CHECK SELECTION","OK")))) -> OK | AF24: No JKN claims equivalent
