Workbook

Sheet README
A1: Indonesia NCD model - public-health policy inputs
A3: Individual intervention inputs with nested tobacco and salt packages; TFA RR base case with optional PAF sensitivity
A5: Readiness | C5: Executable interventions | E5: Risk exposures | G5: Intervention-cause links
A6: =IF(COUNTIF(QA_Checks!$E$2:$E$25,"FAIL")=0,"READY","REVIEW REQUIRED") -> REVIEW REQUIRED | C6: =COUNTA(Exposure_Targets!$B$2:$B$13) -> 12 | E6: =COUNTA(Dictionaries!$F$2:$F$6) -> 5 | G6: =COUNTA(Intervention_Cause_Map!$A$2:$A$62) -> 61
A9: How to use the workbook
A10: 1 | B10: Policy_Levers contains separate fiscal baseline/target tax levels and regulatory none/partial/full fields; derived gaps and reductions are formulas.
A11: 2 | B11: Scenario_Hierarchy preserves I_PH_TOBACCO_POLICY and I_PH_SALT_POLICY while every component has its own intervention_id.
A12: 3 | B12: Exposure, cause links, effects and costs trace each intervention into modeling and cost effectiveness.
A13: 4 | B13: Run parent bundles jointly in the integrated model; do not add standalone child cases or deaths.
A14: 5 | B14: TFA defaults to RR: RR per 1 percentage-point energy = sqrt(1.21). Change Assumptions.tfa_effect_method only for optional PAF sensitivity.
A15: 6 | B15: Tobacco and salt child costs use provisional equal allocations that preserve package totals.
A17: Key interpretation and review items
A18: Resolved | B18: TFA RR no longer requires a PAF
A19: Resolved | B19: Tobacco and salt components have independent effect and cost keys
A20: Resolved | B20: Taxes use baseline-to-target changes and elasticity
A21: Resolved | B21: Regulations use none/partial/full with formula-derived effects
A22: Review | B22: Source costs require Indonesia and price-year adjustment
A23: Review | B23: Replace equal child cost shares when component-specific costs are available
A24: Caution | B24: Parent health outcomes require joint scenario runs
A25: New / Caution | B25: Tobacco CVD now includes uniquely keyed sick-to-dead proxy rows with Jha age-sex piecewise base timing. The exploratory SSB/T2DM mortality row remains disabled, and the attached R code still requires transition and lag-model support.

Sheet Assumptions
A1: parameter_id | B1: value | C1: unit | D1: base_case | E1: lower_bound | F1: upper_bound | G1: description | H1: source
A2: analysis_start_year | B2: 2025 | C2: year | D2: 2025 | E2: 2025 | F2: 2026 | G2: First modeled year | H2: Indonesia model scope
A3: analysis_end_year | B3: 2050 | C3: year | D3: 2050 | E3: 2030 | F3: 2050 | G3: Last modeled year | H3: Indonesia model scope
A4: policy_start_year | B4: 2026 | C4: year | D4: 2026 | E4: 2025 | F4: 2030 | G4: First implementation year | H4: Working scenario
A5: exposure_target_year | B5: 2030 | C5: year | D5: 2030 | E5: 2028 | F5: 2050 | G5: Year full exposure reduction is reached | H5: Working scenario
A6: policy_cost_ramp_years | B6: 3 | C6: years | D6: 3 | E6: 1 | F6: 5 | G6: Years to full policy implementation cost | H6: NCD Countdown supplement p 34
A7: cost_discount_rate | B7: 0.03 | C7: proportion/year | D7: 0.03 | E7: 0 | F7: 0.05 | G7: Annual discount rate for costs | H7: Match clinical workbook
A8: health_discount_rate | B8: 0.03 | C8: proportion/year | D8: 0.03 | E8: 0 | F8: 0.05 | G8: Annual discount rate for health outcomes | H8: Match clinical workbook
A9: reporting_price_year | B9: 2023 | C9: USD year | D9: 2023 | E9: 2020 | F9: 2024 | G9: Target reporting price year | H9: Match clinical workbook
A10: source_cost_price_year | B10: 2017 | C10: USD year | D10: 2017 | E10: 2017 | F10: 2017 | G10: Price year in source cost file | H10: PINandCosts0625(1).csv
A11: currency | B11: USD | C11: currency | D11: USD | E11: USD | F11: USD | G11: Reporting currency | H11: Working assumption
A12: scale_up_shape | B12: linear | C12: text | D12: linear | E12: linear | F12: linear | G12: Full reduction is phased in evenly | H12: NCD Countdown supplement p 34
A13: economic_perspective | B13: health_system | C13: text | D13: health_system | E13: health_system | F13: societal | G13: Economic evaluation perspective | H13: NCD Countdown
A14: tobacco_cvd_lag_rate | B14: 0.0616 | C14: annual fraction | D14: 0.0616 | E14: 0.04 | F14: 0.08 | G14: Sensitivity-only normalized exponential annual fraction; base case uses Jha age-sex piecewise scalars | H14: Cho et al. 2024; user-specified sensitivity
A15: sodium_exposure_floor | B15: 3 | C15: g sodium/day | D15: 3 | E15: 3 | F15: 3 | G15: No additional benefit below this exposure | H15: NCD Countdown p 33
A16: tfa_target_exposure | B16: 0.00317 | C16: % energy from industrial TFA | D16: 0 | E16: 0 | F16: 0.5 | G16: Target under full industrial-TFA elimination | H16: WHO REPLACE; editable
A17: constant_marginal_policy_cost | B17: 1 | C17: 0/1 flag | D17: 1 | E17: 0 | F17: 1 | G17: Policy cost proportional to implementation | H17: NCD Countdown limitation
A18: grams_pure_alcohol_per_litre | B18: 789 | C18: g/L | D18: 789 | E18: 789 | F18: 789 | G18: Alcohol dose-response conversion | H18: Standard conversion
A19: weeks_per_year | B19: 52 | C19: weeks/year | D19: 52 | E19: 52 | F19: 52.1775 | G19: Alcohol dose-response conversion | H19: Model convention
A20: ssb_tax_price_increase | B20: 0.2 | C20: relative price change | D20: 0.2 | E20: 0.1 | F20: 0.5 | G20: Target SSB retail-price increase | H20: https://www.who.int/publications/i/item/9789240091016/
A21: ssb_price_elasticity_indonesia | B21: -0.875 | C21: own-price elasticity | D21: -0.875 | E21: -0.93 | F21: -0.715 | G21: 20% price increase reduces mean demand 17.5% | H21: https://doi.org/10.1371/journal.pone.0293913
A22: ssb_tax_pass_through_global | B22: 0.82 | C22: proportion | D22: 0.82 | E22: 0.66 | F22: 0.98 | G22: Sensitivity parameter | H22: https://doi.org/10.1001/jamanetworkopen.2022.15276
A23: ssb_price_elasticity_global | B23: -1.59 | C23: own-price elasticity | D23: -1.59 | E23: -2.11 | F23: -1.08 | G23: Sensitivity parameter | H23: https://doi.org/10.1001/jamanetworkopen.2022.15276
A24: regulatory_none_score | B24: 0 | C24: implementation score | D24: 0 | E24: 0 | F24: 0 | G24: Numeric value for none | H24: User-requested convention
A25: regulatory_partial_score | B25: 0.5 | C25: implementation score | D25: 0.5 | E25: 0.5 | F25: 0.5 | G25: Partial to full applies half effect | H25: User-requested convention
A26: regulatory_full_score | B26: 1 | C26: implementation score | D26: 1 | E26: 1 | F26: 1 | G26: Numeric value for full | H26: User-requested convention
A27: tfa_effect_method | B27: RR | C27: RR/PAF switch | D27: RR | E27: RR | F27: PAF | G27: RR is base case; PAF is optional sensitivity | H27: User request
A28: tfa_optional_ihd_paf | C28: proportion | E28: 0 | F28: 1 | G28: Used only when TFA method is PAF | H28: Optional user input
A29: tobacco_cvd_lag_model_base | B29: jha_piecewise_shared_scalar | C29: text | D29: jha_piecewise_shared_scalar | E29: jha_piecewise_shared_scalar | F29: jha_piecewise_shared_scalar | G29: Base timing model for tobacco-CVD incidence and mortality | H29: https://doi.org/10.1056/EVIDoa2300272
A30: tobacco_cvd_lag_model_sensitivity | B30: normalized_exponential_lag | C30: text | D30: normalized_exponential_lag | E30: normalized_exponential_lag | F30: normalized_exponential_lag | G30: Sensitivity timing model; normalized to full effect at year 10 | H30: User-specified sensitivity
A31: tobacco_cvd_full_effect_year | B31: 10 | C31: years since cessation | D31: 10 | E31: 10 | F31: 10 | G31: Year at which the normalized exponential sensitivity reaches full effect | H31: Model convention
A32: tobacco_vascular_mortality_rr_male | B32: 2.9 | C32: HR current vs never smoker | D32: 2.9 | E32: 2.9 | F32: 2.9 | G32: Male vascular-mortality hazard ratio | H32: https://doi.org/10.1056/EVIDoa2300272
A33: tobacco_vascular_mortality_rr_female | B33: 3.1 | C33: HR current vs never smoker | D33: 3.1 | E33: 3.1 | F33: 3.1 | G33: Female vascular-mortality hazard ratio | H33: https://doi.org/10.1056/EVIDoa2300272
A34: tobacco_vascular_mortality_rr_pooled | B34: =AVERAGE(B32:B33) -> 3 | C34: HR current vs never smoker | D34: 3 | E34: 2.9 | F34: 3.1 | G34: Backward-compatible pooled value; R should use sex-specific values | H34: Average of Jha male and female HRs
A35: tobacco_vascular_erd_ge10_pooled | B35: 0.90125 | C35: proportion | D35: 0.90125 | E35: 0.90125 | F35: 0.90125 | G35: Mean age-sex ERD at 10+ years; used only for the illustrative pooled workbook formula | H35: Derived from Cho et al. 2024 Figure 2
A36: tobacco_age80_scalar_extrapolation | B36: use_age_60_79 | C36: text | D36: use_age_60_79 | E36: use_age_60_79 | F36: use_age_60_79 | G36: Apply 60-79 Jha scalars to ages 80+ | H36: Conservative extrapolation
A37: transition_probability_rr_method | B37: 1-(1-p0)^RR | C37: text | D37: 1-(1-p0)^RR | E37: 1-(1-p0)^RR | F37: 1-(1-p0)^RR | G37: Convert rate ratios to annual Markov probabilities through the continuous-rate scale | H37: Standard rate-to-probability conversion
A38: bca_base_year | B38: 2025 | C38: year | D38: 2025 | E38: 2025 | F38: 2026 | G38: Base year to which BCA benefits and costs are both discounted (single shared base year) | H38: Robinson et al. 2019 Reference Case Guidelines for BCA in Global Health & Development (CHDS/Harvard); = analysis_start_year
A39: bca_discount_rate_primary | B39: 0.03 | C39: proportion/year | D39: 0.03 | E39: 0.03 | F39: 0.05 | G39: Primary real discount rate applied to BOTH benefits and costs in the BCA | H39: Robinson et al. 2019 Reference Case Guidelines for BCA in Global Health & Development (CHDS/Harvard); context-specific primary rate
A40: bca_discount_rate_sensitivity_3pct | B40: 0.03 | C40: proportion/year | D40: 0.03 | E40: 0.03 | F40: 0.03 | G40: Standardized sensitivity discount rate (3%) | H40: Robinson et al. 2019 Reference Case Guidelines for BCA in Global Health & Development (CHDS/Harvard); standardized sensitivity
...

Sheet Dictionaries
A1: intervention_id | B1: intervention_name | C1: package_group | D1: definition | F1: risk_id | G1: risk_name | H1: exposure_measure | I1: exposure_unit | K1: cause_id | L1: cause_name | M1: model_name | N1: is_model_cause | O1: mapping_note
A2: I_PH_TOBACCO_TAX | B2: Tobacco tax | C2: Tobacco | D2: Tax share -> price -> smoking exposure | F2: R_SMOKING | G2: Smoking | H2: Smoking prevalence | I2: proportion | K2: C_RHD | L2: Rheumatic heart disease | M2: Rheumatic heart disease | N2: 1 | O2: No direct mapping
A3: I_PH_ALCOHOL_TAX | B3: Alcohol tax | C3: Alcohol | D3: Incremental retail-price change | F3: R_ALCOHOL | G3: Alcohol use | H3: Alcohol consumption per adult | I3: litres pure alcohol/adult/year | K3: C_IHD | L3: Ischemic heart disease | M3: Ischemic heart disease | N3: 1 | O3: Direct mapped effects
A4: I_PH_TOB_CLEAN_AIR | B4: Smoke-free / clean-air law | C4: Tobacco | D4: Child of I_PH_TOBACCO_POLICY | F4: R_SODIUM | G4: High sodium intake | H4: Mean sodium intake | I4: g sodium/day | K4: C_IS | L4: Ischemic stroke | M4: Ischemic stroke | N4: 1 | O4: Direct mapped effects
A5: I_PH_TOB_MEDIA | B5: Tobacco mass-media campaign | C5: Tobacco | D5: Child of I_PH_TOBACCO_POLICY | F5: R_TFA | G5: Trans-fat intake | H5: Mean industrial trans-fat intake | I5: % energy | K5: C_ICH | L5: Intracerebral hemorrhage | M5: Intracerebral hemorrhage | N5: 1 | O5: SSB uses proxy
A6: I_PH_TOB_AD_BAN | B6: Tobacco advertising ban | C6: Tobacco | D6: Child of I_PH_TOBACCO_POLICY | F6: R_SSB | G6: Sugar-sweetened beverage intake | H6: Mean SSB intake | I6: 8 oz servings/adult/day | K6: C_HHD | L6: Hypertensive heart disease | M6: Hypertensive heart disease | N6: 1 | O6: SSB uses proxy
A7: I_PH_ALCOHOL_POLICY | B7: Alcohol advertising ban | C7: Alcohol | D7: Individual regulatory intervention | K7: C_CMYO | L7: Cardiomyopathy and myocarditis | M7: Cardiomyopathy and myocarditis | N7: 1 | O7: Alcohol mapping
A8: I_PH_SALT_REFORM | B8: Mandatory sodium reformulation | C8: Diet | D8: Child of I_PH_SALT_POLICY | K8: C_T2DM | L8: Diabetes mellitus type 2 | M8: Diabetes mellitus type 2 | N8: 1 | O8: Smoking and SSB
A9: I_PH_SALT_FOPL | B9: Sodium front-of-pack labelling | C9: Diet | D9: Child of I_PH_SALT_POLICY | K9: C_IHD_HBG | L9: IHD attributable to high blood glucose | M9: IHD attributable to high blood glucose | N9: 1 | O9: Do not link separately
A10: I_PH_SALT_MEDIA | B10: Sodium mass-media campaign | C10: Diet | D10: Child of I_PH_SALT_POLICY | K10: C_SHARED | L10: Shared policy cost | M10: Not a disease model | N10: 0 | O10: Cost-only key
A11: I_PH_SALT_ENV | B11: Supportive public-institution environment | C11: Diet | D11: Child of I_PH_SALT_POLICY
A12: I_PH_TFA_POLICY | B12: Industrial trans-fat elimination regulation | C12: Diet | D12: RR base case; optional PAF
A13: I_PH_SSB_TAX | B13: Sugar-sweetened beverage tax | C13: Diet | D13: 20% retail-price target

Sheet Intervention_Cause_Map
A1: intervention_cause_key | B1: intervention_id | C1: risk_id | D1: intervention_name | E1: risk_name | F1: cause_id | G1: cause_name | H1: effect_key | I1: exposure_key | J1: cost_join_key | K1: cost_scope | L1: transition_from | M1: transition_to | N1: include_flag | O1: requires_cause_expansion | P1: notes | Q1: duplicate_count
A2: I_PH_TOBACCO_TAX__C_IHD | B2: I_PH_TOBACCO_TAX | C2: R_SMOKING | D2: Tobacco tax | E2: Smoking | F2: C_IHD | G2: Ischemic heart disease | H2: I_PH_TOBACCO_TAX__C_IHD | I2: I_PH_TOBACCO_TAX | J2: I_PH_TOBACCO_TAX__C_SHARED | K2: shared-count-once | L2: well | M2: sick | N2: 1 | O2: 0 | P2: Direct exposure-response incidence effect; report by intervention_id. | Q2: =COUNTIF($A$2:$A$62,A2) -> 1
A3: I_PH_TOBACCO_TAX__C_IS | B3: I_PH_TOBACCO_TAX | C3: R_SMOKING | D3: Tobacco tax | E3: Smoking | F3: C_IS | G3: Ischemic stroke | H3: I_PH_TOBACCO_TAX__C_IS | I3: I_PH_TOBACCO_TAX | J3: I_PH_TOBACCO_TAX__C_SHARED | K3: shared-count-once | L3: well | M3: sick | N3: 1 | O3: 0 | P3: Direct exposure-response incidence effect; report by intervention_id. | Q3: =COUNTIF($A$2:$A$62,A3) -> 1
A4: I_PH_TOBACCO_TAX__C_ICH | B4: I_PH_TOBACCO_TAX | C4: R_SMOKING | D4: Tobacco tax | E4: Smoking | F4: C_ICH | G4: Intracerebral hemorrhage | H4: I_PH_TOBACCO_TAX__C_ICH | I4: I_PH_TOBACCO_TAX | J4: I_PH_TOBACCO_TAX__C_SHARED | K4: shared-count-once | L4: well | M4: sick | N4: 1 | O4: 0 | P4: Direct exposure-response incidence effect; report by intervention_id. | Q4: =COUNTIF($A$2:$A$62,A4) -> 1
A5: I_PH_TOBACCO_TAX__C_T2DM | B5: I_PH_TOBACCO_TAX | C5: R_SMOKING | D5: Tobacco tax | E5: Smoking | F5: C_T2DM | G5: Diabetes mellitus type 2 | H5: I_PH_TOBACCO_TAX__C_T2DM | I5: I_PH_TOBACCO_TAX | J5: I_PH_TOBACCO_TAX__C_SHARED | K5: shared-count-once | L5: well | M5: sick | N5: 1 | O5: 0 | P5: Direct exposure-response incidence effect; report by intervention_id. | Q5: =COUNTIF($A$2:$A$62,A5) -> 1
A6: I_PH_ALCOHOL_TAX__C_IHD | B6: I_PH_ALCOHOL_TAX | C6: R_ALCOHOL | D6: Alcohol tax | E6: Alcohol use | F6: C_IHD | G6: Ischemic heart disease | H6: I_PH_ALCOHOL_TAX__C_IHD | I6: I_PH_ALCOHOL_TAX | J6: I_PH_ALCOHOL_TAX__C_SHARED | K6: shared-count-once | L6: well | M6: sick | N6: 0 | O6: 0 | P6: Direct exposure-response incidence effect; report by intervention_id. | Q6: =COUNTIF($A$2:$A$62,A6) -> 1
A7: I_PH_ALCOHOL_TAX__C_IS | B7: I_PH_ALCOHOL_TAX | C7: R_ALCOHOL | D7: Alcohol tax | E7: Alcohol use | F7: C_IS | G7: Ischemic stroke | H7: I_PH_ALCOHOL_TAX__C_IS | I7: I_PH_ALCOHOL_TAX | J7: I_PH_ALCOHOL_TAX__C_SHARED | K7: shared-count-once | L7: well | M7: sick | N7: 0 | O7: 0 | P7: Direct exposure-response incidence effect; report by intervention_id. | Q7: =COUNTIF($A$2:$A$62,A7) -> 1
A8: I_PH_ALCOHOL_TAX__C_ICH | B8: I_PH_ALCOHOL_TAX | C8: R_ALCOHOL | D8: Alcohol tax | E8: Alcohol use | F8: C_ICH | G8: Intracerebral hemorrhage | H8: I_PH_ALCOHOL_TAX__C_ICH | I8: I_PH_ALCOHOL_TAX | J8: I_PH_ALCOHOL_TAX__C_SHARED | K8: shared-count-once | L8: well | M8: sick | N8: 0 | O8: 0 | P8: Direct exposure-response incidence effect; report by intervention_id. | Q8: =COUNTIF($A$2:$A$62,A8) -> 1
A9: I_PH_ALCOHOL_TAX__C_HHD | B9: I_PH_ALCOHOL_TAX | C9: R_ALCOHOL | D9: Alcohol tax | E9: Alcohol use | F9: C_HHD | G9: Hypertensive heart disease | H9: I_PH_ALCOHOL_TAX__C_HHD | I9: I_PH_ALCOHOL_TAX | J9: I_PH_ALCOHOL_TAX__C_SHARED | K9: shared-count-once | L9: well | M9: sick | N9: 0 | O9: 0 | P9: Direct exposure-response incidence effect; report by intervention_id. | Q9: =COUNTIF($A$2:$A$62,A9) -> 1
A10: I_PH_ALCOHOL_TAX__C_CMYO | B10: I_PH_ALCOHOL_TAX | C10: R_ALCOHOL | D10: Alcohol tax | E10: Alcohol use | F10: C_CMYO | G10: Cardiomyopathy and myocarditis | H10: I_PH_ALCOHOL_TAX__C_CMYO | I10: I_PH_ALCOHOL_TAX | J10: I_PH_ALCOHOL_TAX__C_SHARED | K10: shared-count-once | L10: well | M10: sick | N10: 0 | O10: 0 | P10: Direct exposure-response incidence effect; report by intervention_id. | Q10: =COUNTIF($A$2:$A$62,A10) -> 1
A11: I_PH_TOB_CLEAN_AIR__C_IHD | B11: I_PH_TOB_CLEAN_AIR | C11: R_SMOKING | D11: Smoke-free / clean-air law | E11: Smoking | F11: C_IHD | G11: Ischemic heart disease | H11: I_PH_TOB_CLEAN_AIR__C_IHD | I11: I_PH_TOB_CLEAN_AIR | J11: I_PH_TOB_CLEAN_AIR__C_SHARED | K11: component-count-once | L11: well | M11: sick | N11: 1 | O11: 0 | P11: Direct exposure-response incidence effect; report by intervention_id. | Q11: =COUNTIF($A$2:$A$62,A11) -> 1
A12: I_PH_TOB_CLEAN_AIR__C_IS | B12: I_PH_TOB_CLEAN_AIR | C12: R_SMOKING | D12: Smoke-free / clean-air law | E12: Smoking | F12: C_IS | G12: Ischemic stroke | H12: I_PH_TOB_CLEAN_AIR__C_IS | I12: I_PH_TOB_CLEAN_AIR | J12: I_PH_TOB_CLEAN_AIR__C_SHARED | K12: component-count-once | L12: well | M12: sick | N12: 1 | O12: 0 | P12: Direct exposure-response incidence effect; report by intervention_id. | Q12: =COUNTIF($A$2:$A$62,A12) -> 1
A13: I_PH_TOB_CLEAN_AIR__C_ICH | B13: I_PH_TOB_CLEAN_AIR | C13: R_SMOKING | D13: Smoke-free / clean-air law | E13: Smoking | F13: C_ICH | G13: Intracerebral hemorrhage | H13: I_PH_TOB_CLEAN_AIR__C_ICH | I13: I_PH_TOB_CLEAN_AIR | J13: I_PH_TOB_CLEAN_AIR__C_SHARED | K13: component-count-once | L13: well | M13: sick | N13: 1 | O13: 0 | P13: Direct exposure-response incidence effect; report by intervention_id. | Q13: =COUNTIF($A$2:$A$62,A13) -> 1
... A62: I_PH_SSB_TAX__C_T2DM__SICK_DEAD | B62: I_PH_SSB_TAX | C62: R_SSB | D62: Sugar-sweetened beverage tax | E62: Sugar-sweetened beverage intake | F62: C_T2DM | G62: Diabetes mellitus type 2 | H62: I_PH_SSB_TAX__C_T2DM__SICK_DEAD | I62: I_PH_SSB_TAX | J62: I_PH_SSB_TAX__C_SHARED | K62: shared-count-once | L62: sick | M62: dead | N62: 0 | O62: 0 | P62: Exploratory and disabled: BMJ outcome is all-cause mortality among adults with T2DM, not diabetes-specific death. | Q62: =COUNTIF($A$2:$A$62,A62) -> 1

Sheet Policy_Levers
A1: lever_id | B1: intervention_id | C1: intervention_name | D1: component | E1: lever_method | F1: baseline_value | G1: target_value | H1: lever_unit | I1: effect_parameter | J1: effect_parameter_unit | K1: estimated_risk_reduction | L1: source | M1: review_status | N1: notes | O1: qa_status | P1: parent_package_id | Q1: parent_package_name | R1: intervention_role | S1: fiscal_baseline_tax_level | T1: fiscal_target_tax_level | U1: fiscal_tax_level_unit | V1: regulatory_baseline_level | W1: regulatory_target_level | X1: regulatory_baseline_score | Y1: regulatory_target_score | Z1: implementation_gap | AA1: implied_price_change | AB1: fiscal_tax_delta
A2: PL_TOB_TAX_SHARE | B2: I_PH_TOBACCO_TAX | C2: Tobacco tax | D2: Tax share of final retail price | E2: tax_share_to_price_elasticity | F2: =IF(OR(E2="tax_share_to_price_elasticity",E2="price_elasticity"),S2,X2) -> 0.65921 | G2: =IF(OR(E2="tax_share_to_price_elasticity",E2="price_elasticity"),T2,Y2) -> 0.75 | H2: =IF(OR(E2="tax_share_to_price_elasticity",E2="price_elasticity"),U2,"implementation score 0-1") -> tax share of retail price | I2: -0.48 | J2: price elasticity | K2: =IF(E2="tax_share_to_price_elasticity",MIN(1,ABS(I2)*AA2),IF(E2="price_elasticity",MIN(1,ABS(I2)*AA2),IF(E2="regulatory_gap_multiplicative",MIN(1,Z2*I2),""))) -> 0.1743168 | L2: WHO tobacco report 2025; Countdown p 32 | M2: Ready | N2: WHO reports Indonesia in >=75% group; baseline equals target. | O2: =IF(OR(E2="tax_share_to_price_elasticity",E2="price_elasticity"),IF(COUNT(S2,T2)<2,"MISSING FISCAL INPUT",IF(OR(K2<0,K2>1),"BAD REDUCTION","OK")),IF(OR(V2="",W2="",COUNT(X2,Y2)<2),"MISSING REGULATORY INPUT",IF(OR(K2<0,K2>1),"BAD REDUCTION","OK"))) -> OK | P2: I_PH_TOBACCO_TAX | Q2: Tobacco tax | R2: standalone | S2: 0.65921 | T2: 0.75 | U2: tax share of retail price | V2: partial | W2: partial | X2: =IF(V2="none",Assumptions!$B$24,IF(V2="partial",Assumptions!$B$25,IF(V2="full",Assumptions!$B$26,""))) -> 0.5 | Y2: =IF(W2="none",Assumptions!$B$24,IF(W2="partial",Assumptions!$B$25,IF(W2="full",Assumptions!$B$26,""))) -> 0.5 | Z2: =IF(COUNT(X2,Y2)<2,"",MAX(0,Y2-X2)) -> 0 | AA2: =IF(E2="tax_share_to_price_elasticity",IF(OR(COUNT(S2,T2)<2,T2>=1),"",MAX(0,(1-S2)/(1-T2)-1)),IF(E2="price_elasticity",IF(COUNT(S2,T2)<2,"",MAX(0,T2-S2)),0)) -> 0.36316 | AB2: =IF(OR(E2="tax_share_to_price_elasticity",E2="price_elasticity"),IF(COUNT(S2,T2)<2,"",T2-S2),0) -> 0.09079
A3: PL_ALC_PRICE | B3: I_PH_ALCOHOL_TAX | C3: Alcohol tax | D3: Incremental retail-price increase versus current law | E3: price_elasticity | F3: =IF(OR(E3="tax_share_to_price_elasticity",E3="price_elasticity"),S3,X3) -> 0 | G3: =IF(OR(E3="tax_share_to_price_elasticity",E3="price_elasticity"),T3,Y3) -> 0.25 | H3: =IF(OR(E3="tax_share_to_price_elasticity",E3="price_elasticity"),U3,"implementation score 0-1") -> relative price change vs current law | I3: -0.49 | J3: price elasticity | K3: =IF(E3="tax_share_to_price_elasticity",MIN(1,ABS(I3)*AA3),IF(E3="price_elasticity",MIN(1,ABS(I3)*AA3),IF(E3="regulatory_gap_multiplicative",MIN(1,Z3*I3),""))) -> 0.1225 | L3: Countdown p 31 | M3: Ready | N3: Baseline zero incremental change; target +25%. | O3: =IF(OR(E3="tax_share_to_price_elasticity",E3="price_elasticity"),IF(COUNT(S3,T3)<2,"MISSING FISCAL INPUT",IF(OR(K3<0,K3>1),"BAD REDUCTION","OK")),IF(OR(V3="",W3="",COUNT(X3,Y3)<2),"MISSING REGULATORY INPUT",IF(OR(K3<0,K3>1),"BAD REDUCTION","OK"))) -> OK | P3: I_PH_ALCOHOL_TAX | Q3: Alcohol tax | R3: standalone | S3: 0 | T3: 0.25 | U3: relative price change vs current law | V3: none | W3: none | X3: =IF(V3="none",Assumptions!$B$24,IF(V3="partial",Assumptions!$B$25,IF(V3="full",Assumptions!$B$26,""))) -> 0 | Y3: =IF(W3="none",Assumptions!$B$24,IF(W3="partial",Assumptions!$B$25,IF(W3="full",Assumptions!$B$26,""))) -> 0 | Z3: =IF(COUNT(X3,Y3)<2,"",MAX(0,Y3-X3)) -> 0 | AA3: =IF(E3="tax_share_to_price_elasticity",IF(OR(COUNT(S3,T3)<2,T3>=1),"",MAX(0,(1-S3)/(1-T3)-1)),IF(E3="price_elasticity",IF(COUNT(S3,T3)<2,"",MAX(0,T3-S3)),0)) -> 0.25 | AB3: =IF(OR(E3="tax_share_to_price_elasticity",E3="price_elasticity"),IF(COUNT(S3,T3)<2,"",T3-S3),0) -> 0.25
A4: PL_TOB_CLEAN_AIR | B4: I_PH_TOB_CLEAN_AIR | C4: Smoke-free / clean-air law | D4: Smoking ban / clean-air law | E4: regulatory_gap_multiplicative | F4: =IF(OR(E4="tax_share_to_price_elasticity",E4="price_elasticity"),S4,X4) -> 0.5 | G4: =IF(OR(E4="tax_share_to_price_elasticity",E4="price_elasticity"),T4,Y4) -> 1 | H4: =IF(OR(E4="tax_share_to_price_elasticity",E4="price_elasticity"),U4,"implementation score 0-1") -> implementation score 0-1 | I4: 0.11 | J4: full-policy relative smoking reduction | K4: =IF(E4="tax_share_to_price_elasticity",MIN(1,ABS(I4)*AA4),IF(E4="price_elasticity",MIN(1,ABS(I4)*AA4),IF(E4="regulatory_gap_multiplicative",MIN(1,Z4*I4),""))) -> 0.055 | L4: WHO NCD Progress Monitor 2025; Countdown p 32 | M4: Ready | N4: Baseline partial. | O4: =IF(OR(E4="tax_share_to_price_elasticity",E4="price_elasticity"),IF(COUNT(S4,T4)<2,"MISSING FISCAL INPUT",IF(OR(K4<0,K4>1),"BAD REDUCTION","OK")),IF(OR(V4="",W4="",COUNT(X4,Y4)<2),"MISSING REGULATORY INPUT",IF(OR(K4<0,K4>1),"BAD REDUCTION","OK"))) -> OK | P4: I_PH_TOBACCO_POLICY | Q4: Tobacco policy package | R4: child | V4: partial | W4: full | X4: =IF(V4="none",Assumptions!$B$24,IF(V4="partial",Assumptions!$B$25,IF(V4="full",Assumptions!$B$26,""))) -> 0.5 | Y4: =IF(W4="none",Assumptions!$B$24,IF(W4="partial",Assumptions!$B$25,IF(W4="full",Assumptions!$B$26,""))) -> 1 | Z4: =IF(COUNT(X4,Y4)<2,"",MAX(0,Y4-X4)) -> 0.5 | AA4: =IF(E4="tax_share_to_price_elasticity",IF(OR(COUNT(S4,T4)<2,T4>=1),"",MAX(0,(1-S4)/(1-T4)-1)),IF(E4="price_elasticity",IF(COUNT(S4,T4)<2,"",MAX(0,T4-S4)),0)) -> 0 | AB4: =IF(OR(E4="tax_share_to_price_elasticity",E4="price_elasticity"),IF(COUNT(S4,T4)<2,"",T4-S4),0) -> 0
A5: PL_TOB_MEDIA | B5: I_PH_TOB_MEDIA | C5: Tobacco mass-media campaign | D5: Highly publicised mass-media campaign | E5: regulatory_gap_multiplicative | F5: =IF(OR(E5="tax_share_to_price_elasticity",E5="price_elasticity"),S5,X5) -> 0 | G5: =IF(OR(E5="tax_share_to_price_elasticity",E5="price_elasticity"),T5,Y5) -> 1 | H5: =IF(OR(E5="tax_share_to_price_elasticity",E5="price_elasticity"),U5,"implementation score 0-1") -> implementation score 0-1 | I5: 0.065 | J5: full-policy relative smoking reduction | K5: =IF(E5="tax_share_to_price_elasticity",MIN(1,ABS(I5)*AA5),IF(E5="price_elasticity",MIN(1,ABS(I5)*AA5),IF(E5="regulatory_gap_multiplicative",MIN(1,Z5*I5),""))) -> 0.065 | L5: WHO NCD Progress Monitor 2025; Countdown p 32 | M5: Ready | N5: Baseline none. | O5: =IF(OR(E5="tax_share_to_price_elasticity",E5="price_elasticity"),IF(COUNT(S5,T5)<2,"MISSING FISCAL INPUT",IF(OR(K5<0,K5>1),"BAD REDUCTION","OK")),IF(OR(V5="",W5="",COUNT(X5,Y5)<2),"MISSING REGULATORY INPUT",IF(OR(K5<0,K5>1),"BAD REDUCTION","OK"))) -> OK | P5: I_PH_TOBACCO_POLICY | Q5: Tobacco policy package | R5: child | V5: none | W5: full | X5: =IF(V5="none",Assumptions!$B$24,IF(V5="partial",Assumptions!$B$25,IF(V5="full",Assumptions!$B$26,""))) -> 0 | Y5: =IF(W5="none",Assumptions!$B$24,IF(W5="partial",Assumptions!$B$25,IF(W5="full",Assumptions!$B$26,""))) -> 1 | Z5: =IF(COUNT(X5,Y5)<2,"",MAX(0,Y5-X5)) -> 1 | AA5: =IF(E5="tax_share_to_price_elasticity",IF(OR(COUNT(S5,T5)<2,T5>=1),"",MAX(0,(1-S5)/(1-T5)-1)),IF(E5="price_elasticity",IF(COUNT(S5,T5)<2,"",MAX(0,T5-S5)),0)) -> 0 | AB5: =IF(OR(E5="tax_share_to_price_elasticity",E5="price_elasticity"),IF(COUNT(S5,T5)<2,"",T5-S5),0) -> 0
A6: PL_TOB_AD_BAN | B6: I_PH_TOB_AD_BAN | C6: Tobacco advertising ban | D6: Advertising, promotion and sponsorship ban | E6: regulatory_gap_multiplicative | F6: =IF(OR(E6="tax_share_to_price_elasticity",E6="price_elasticity"),S6,X6) -> 0 | G6: =IF(OR(E6="tax_share_to_price_elasticity",E6="price_elasticity"),T6,Y6) -> 1 | H6: =IF(OR(E6="tax_share_to_price_elasticity",E6="price_elasticity"),U6,"implementation score 0-1") -> implementation score 0-1 | I6: 0.04 | J6: full-policy relative smoking reduction | K6: =IF(E6="tax_share_to_price_elasticity",MIN(1,ABS(I6)*AA6),IF(E6="price_elasticity",MIN(1,ABS(I6)*AA6),IF(E6="regulatory_gap_multiplicative",MIN(1,Z6*I6),""))) -> 0.04 | L6: WHO NCD Progress Monitor 2025; Countdown p 32 | M6: Ready | N6: Baseline none. | O6: =IF(OR(E6="tax_share_to_price_elasticity",E6="price_elasticity"),IF(COUNT(S6,T6)<2,"MISSING FISCAL INPUT",IF(OR(K6<0,K6>1),"BAD REDUCTION","OK")),IF(OR(V6="",W6="",COUNT(X6,Y6)<2),"MISSING REGULATORY INPUT",IF(OR(K6<0,K6>1),"BAD REDUCTION","OK"))) -> OK | P6: I_PH_TOBACCO_POLICY | Q6: Tobacco policy package | R6: child | V6: none | W6: full | X6: =IF(V6="none",Assumptions!$B$24,IF(V6="partial",Assumptions!$B$25,IF(V6="full",Assumptions!$B$26,""))) -> 0 | Y6: =IF(W6="none",Assumptions!$B$24,IF(W6="partial",Assumptions!$B$25,IF(W6="full",Assumptions!$B$26,""))) -> 1 | Z6: =IF(COUNT(X6,Y6)<2,"",MAX(0,Y6-X6)) -> 1 | AA6: =IF(E6="tax_share_to_price_elasticity",IF(OR(COUNT(S6,T6)<2,T6>=1),"",MAX(0,(1-S6)/(1-T6)-1)),IF(E6="price_elasticity",IF(COUNT(S6,T6)<2,"",MAX(0,T6-S6)),0)) -> 0 | AB6: =IF(OR(E6="tax_share_to_price_elasticity",E6="price_elasticity"),IF(COUNT(S6,T6)<2,"",T6-S6),0) -> 0
A7: PL_ALC_AD_BAN | B7: I_PH_ALCOHOL_POLICY | C7: Alcohol advertising ban | D7: Alcohol advertising ban | E7: regulatory_gap_multiplicative | F7: =IF(OR(E7="tax_share_to_price_elasticity",E7="price_elasticity"),S7,X7) -> 0.5 | G7: =IF(OR(E7="tax_share_to_price_elasticity",E7="price_elasticity"),T7,Y7) -> 1 | H7: =IF(OR(E7="tax_share_to_price_elasticity",E7="price_elasticity"),U7,"implementation score 0-1") -> implementation score 0-1 | I7: 0.269 | J7: full-policy relative alcohol reduction | K7: =IF(E7="tax_share_to_price_elasticity",MIN(1,ABS(I7)*AA7),IF(E7="price_elasticity",MIN(1,ABS(I7)*AA7),IF(E7="regulatory_gap_multiplicative",MIN(1,Z7*I7),""))) -> 0.1345 | L7: WHO NCD Progress Monitor 2025; Countdown p 31 | M7: Ready | N7: Full to full gives zero additional effect. | O7: =IF(OR(E7="tax_share_to_price_elasticity",E7="price_elasticity"),IF(COUNT(S7,T7)<2,"MISSING FISCAL INPUT",IF(OR(K7<0,K7>1),"BAD REDUCTION","OK")),IF(OR(V7="",W7="",COUNT(X7,Y7)<2),"MISSING REGULATORY INPUT",IF(OR(K7<0,K7>1),"BAD REDUCTION","OK"))) -> OK | P7: I_PH_ALCOHOL_POLICY | Q7: Alcohol advertising policy | R7: standalone | V7: partial | W7: full | X7: =IF(V7="none",Assumptions!$B$24,IF(V7="partial",Assumptions!$B$25,IF(V7="full",Assumptions!$B$26,""))) -> 0.5 | Y7: =IF(W7="none",Assumptions!$B$24,IF(W7="partial",Assumptions!$B$25,IF(W7="full",Assumptions!$B$26,""))) -> 1 | Z7: =IF(COUNT(X7,Y7)<2,"",MAX(0,Y7-X7)) -> 0.5 | AA7: =IF(E7="tax_share_to_price_elasticity",IF(OR(COUNT(S7,T7)<2,T7>=1),"",MAX(0,(1-S7)/(1-T7)-1)),IF(E7="price_elasticity",IF(COUNT(S7,T7)<2,"",MAX(0,T7-S7)),0)) -> 0 | AB7: =IF(OR(E7="tax_share_to_price_elasticity",E7="price_elasticity"),IF(COUNT(S7,T7)<2,"",T7-S7),0) -> 0
A8: PL_SALT_REFORM | B8: I_PH_SALT_REFORM | C8: Mandatory sodium reformulation | D8: Mandatory product reformulation | E8: regulatory_gap_multiplicative | F8: =IF(OR(E8="tax_share_to_price_elasticity",E8="price_elasticity"),S8,X8) -> 0.5 | G8: =IF(OR(E8="tax_share_to_price_elasticity",E8="price_elasticity"),T8,Y8) -> 1 | H8: =IF(OR(E8="tax_share_to_price_elasticity",E8="price_elasticity"),U8,"implementation score 0-1") -> implementation score 0-1 | I8: 0.2 | J8: full-policy relative sodium reduction | K8: =IF(E8="tax_share_to_price_elasticity",MIN(1,ABS(I8)*AA8),IF(E8="price_elasticity",MIN(1,ABS(I8)*AA8),IF(E8="regulatory_gap_multiplicative",MIN(1,Z8*I8),""))) -> 0.1 | L8: WHO Indonesia 2026; Countdown p 33 | M8: Ready | N8: Law adopted; technical benchmarks pending: partial. | O8: =IF(OR(E8="tax_share_to_price_elasticity",E8="price_elasticity"),IF(COUNT(S8,T8)<2,"MISSING FISCAL INPUT",IF(OR(K8<0,K8>1),"BAD REDUCTION","OK")),IF(OR(V8="",W8="",COUNT(X8,Y8)<2),"MISSING REGULATORY INPUT",IF(OR(K8<0,K8>1),"BAD REDUCTION","OK"))) -> OK | P8: I_PH_SALT_POLICY | Q8: Salt policy package | R8: child | V8: partial | W8: full | X8: =IF(V8="none",Assumptions!$B$24,IF(V8="partial",Assumptions!$B$25,IF(V8="full",Assumptions!$B$26,""))) -> 0.5 | Y8: =IF(W8="none",Assumptions!$B$24,IF(W8="partial",Assumptions!$B$25,IF(W8="full",Assumptions!$B$26,""))) -> 1 | Z8: =IF(COUNT(X8,Y8)<2,"",MAX(0,Y8-X8)) -> 0.5 | AA8: =IF(E8="tax_share_to_price_elasticity",IF(OR(COUNT(S8,T8)<2,T8>=1),"",MAX(0,(1-S8)/(1-T8)-1)),IF(E8="price_elasticity",IF(COUNT(S8,T8)<2,"",MAX(0,T8-S8)),0)) -> 0 | AB8: =IF(OR(E8="tax_share_to_price_elasticity",E8="price_elasticity"),IF(COUNT(S8,T8)<2,"",T8-S8),0) -> 0
A9: PL_SALT_FOPL | B9: I_PH_SALT_FOPL | C9: Sodium front-of-pack labelling | D9: Front-of-pack labelling | E9: regulatory_gap_multiplicative | F9: =IF(OR(E9="tax_share_to_price_elasticity",E9="price_elasticity"),S9,X9) -> 0.5 | G9: =IF(OR(E9="tax_share_to_price_elasticity",E9="price_elasticity"),T9,Y9) -> 1 | H9: =IF(OR(E9="tax_share_to_price_elasticity",E9="price_elasticity"),U9,"implementation score 0-1") -> implementation score 0-1 | I9: 0.1 | J9: full-policy relative sodium reduction | K9: =IF(E9="tax_share_to_price_elasticity",MIN(1,ABS(I9)*AA9),IF(E9="price_elasticity",MIN(1,ABS(I9)*AA9),IF(E9="regulatory_gap_multiplicative",MIN(1,Z9*I9),""))) -> 0.05 | L9: WHO Indonesia 2026; Countdown p 33 | M9: Ready | N9: Mandatory framework adopted; implementation ongoing: partial. | O9: =IF(OR(E9="tax_share_to_price_elasticity",E9="price_elasticity"),IF(COUNT(S9,T9)<2,"MISSING FISCAL INPUT",IF(OR(K9<0,K9>1),"BAD REDUCTION","OK")),IF(OR(V9="",W9="",COUNT(X9,Y9)<2),"MISSING REGULATORY INPUT",IF(OR(K9<0,K9>1),"BAD REDUCTION","OK"))) -> OK | P9: I_PH_SALT_POLICY | Q9: Salt policy package | R9: child | V9: partial | W9: full | X9: =IF(V9="none",Assumptions!$B$24,IF(V9="partial",Assumptions!$B$25,IF(V9="full",Assumptions!$B$26,""))) -> 0.5 | Y9: =IF(W9="none",Assumptions!$B$24,IF(W9="partial",Assumptions!$B$25,IF(W9="full",Assumptions!$B$26,""))) -> 1 | Z9: =IF(COUNT(X9,Y9)<2,"",MAX(0,Y9-X9)) -> 0.5 | AA9: =IF(E9="tax_share_to_price_elasticity",IF(OR(COUNT(S9,T9)<2,T9>=1),"",MAX(0,(1-S9)/(1-T9)-1)),IF(E9="price_elasticity",IF(COUNT(S9,T9)<2,"",MAX(0,T9-S9)),0)) -> 0 | AB9: =IF(OR(E9="tax_share_to_price_elasticity",E9="price_elasticity"),IF(COUNT(S9,T9)<2,"",T9-S9),0) -> 0
A10: PL_SALT_MEDIA | B10: I_PH_SALT_MEDIA | C10: Sodium mass-media campaign | D10: Mass-media campaign | E10: regulatory_gap_multiplicative | F10: =IF(OR(E10="tax_share_to_price_elasticity",E10="price_elasticity"),S10,X10) -> 0.5 | G10: =IF(OR(E10="tax_share_to_price_elasticity",E10="price_elasticity"),T10,Y10) -> 0.5 | H10: =IF(OR(E10="tax_share_to_price_elasticity",E10="price_elasticity"),U10,"implementation score 0-1") -> implementation score 0-1 | I10: 0.05 | J10: full-policy relative sodium reduction | K10: =IF(E10="tax_share_to_price_elasticity",MIN(1,ABS(I10)*AA10),IF(E10="price_elasticity",MIN(1,ABS(I10)*AA10),IF(E10="regulatory_gap_multiplicative",MIN(1,Z10*I10),""))) -> 0 | L10: WHO NCD Progress Monitor 2025; Countdown p 33 | M10: Ready | N10: Full to full gives zero additional effect. | O10: =IF(OR(E10="tax_share_to_price_elasticity",E10="price_elasticity"),IF(COUNT(S10,T10)<2,"MISSING FISCAL INPUT",IF(OR(K10<0,K10>1),"BAD REDUCTION","OK")),IF(OR(V10="",W10="",COUNT(X10,Y10)<2),"MISSING REGULATORY INPUT",IF(OR(K10<0,K10>1),"BAD REDUCTION","OK"))) -> OK | P10: I_PH_SALT_POLICY | Q10: Salt policy package | R10: child | V10: partial | W10: partial | X10: =IF(V10="none",Assumptions!$B$24,IF(V10="partial",Assumptions!$B$25,IF(V10="full",Assumptions!$B$26,""))) -> 0.5 | Y10: =IF(W10="none",Assumptions!$B$24,IF(W10="partial",Assumptions!$B$25,IF(W10="full",Assumptions!$B$26,""))) -> 0.5 | Z10: =IF(COUNT(X10,Y10)<2,"",MAX(0,Y10-X10)) -> 0 | AA10: =IF(E10="tax_share_to_price_elasticity",IF(OR(COUNT(S10,T10)<2,T10>=1),"",MAX(0,(1-S10)/(1-T10)-1)),IF(E10="price_elasticity",IF(COUNT(S10,T10)<2,"",MAX(0,T10-S10)),0)) -> 0 | AB10: =IF(OR(E10="tax_share_to_price_elasticity",E10="price_elasticity"),IF(COUNT(S10,T10)<2,"",T10-S10),0) -> 0
A11: PL_SALT_ENV | B11: I_PH_SALT_ENV | C11: Supportive public-institution environment | D11: Public food procurement and supportive institutions | E11: regulatory_gap_multiplicative | F11: =IF(OR(E11="tax_share_to_price_elasticity",E11="price_elasticity"),S11,X11) -> 0.5 | G11: =IF(OR(E11="tax_share_to_price_elasticity",E11="price_elasticity"),T11,Y11) -> 1 | H11: =IF(OR(E11="tax_share_to_price_elasticity",E11="price_elasticity"),U11,"implementation score 0-1") -> implementation score 0-1 | I11: 0.07 | J11: full-policy relative sodium reduction | K11: =IF(E11="tax_share_to_price_elasticity",MIN(1,ABS(I11)*AA11),IF(E11="price_elasticity",MIN(1,ABS(I11)*AA11),IF(E11="regulatory_gap_multiplicative",MIN(1,Z11*I11),""))) -> 0.035 | L11: WHO Indonesia 2026; Countdown p 33 | M11: Ready | N11: Healthy-zone implementation incomplete: partial. | O11: =IF(OR(E11="tax_share_to_price_elasticity",E11="price_elasticity"),IF(COUNT(S11,T11)<2,"MISSING FISCAL INPUT",IF(OR(K11<0,K11>1),"BAD REDUCTION","OK")),IF(OR(V11="",W11="",COUNT(X11,Y11)<2),"MISSING REGULATORY INPUT",IF(OR(K11<0,K11>1),"BAD REDUCTION","OK"))) -> OK | P11: I_PH_SALT_POLICY | Q11: Salt policy package | R11: child | V11: partial | W11: full | X11: =IF(V11="none",Assumptions!$B$24,IF(V11="partial",Assumptions!$B$25,IF(V11="full",Assumptions!$B$26,""))) -> 0.5 | Y11: =IF(W11="none",Assumptions!$B$24,IF(W11="partial",Assumptions!$B$25,IF(W11="full",Assumptions!$B$26,""))) -> 1 | Z11: =IF(COUNT(X11,Y11)<2,"",MAX(0,Y11-X11)) -> 0.5 | AA11: =IF(E11="tax_share_to_price_elasticity",IF(OR(COUNT(S11,T11)<2,T11>=1),"",MAX(0,(1-S11)/(1-T11)-1)),IF(E11="price_elasticity",IF(COUNT(S11,T11)<2,"",MAX(0,T11-S11)),0)) -> 0 | AB11: =IF(OR(E11="tax_share_to_price_elasticity",E11="price_elasticity"),IF(COUNT(S11,T11)<2,"",T11-S11),0) -> 0
A12: PL_TFA_REG | B12: I_PH_TFA_POLICY | C12: Industrial trans-fat elimination regulation | D12: Best-practice industrial TFA regulation | E12: regulatory_gap_multiplicative | F12: =IF(OR(E12="tax_share_to_price_elasticity",E12="price_elasticity"),S12,X12) -> 0.5 | G12: =IF(OR(E12="tax_share_to_price_elasticity",E12="price_elasticity"),T12,Y12) -> 1 | H12: =IF(OR(E12="tax_share_to_price_elasticity",E12="price_elasticity"),U12,"implementation score 0-1") -> implementation score 0-1 | I12: 1 | J12: full-policy relative industrial-TFA reduction | K12: =IF(E12="tax_share_to_price_elasticity",MIN(1,ABS(I12)*AA12),IF(E12="price_elasticity",MIN(1,ABS(I12)*AA12),IF(E12="regulatory_gap_multiplicative",MIN(1,Z12*I12),""))) -> 0.5 | L12: WHO Indonesia 2024/2026; REPLACE | M12: Ready | N12: Framework adopted but not fully implemented: partial. | O12: =IF(OR(E12="tax_share_to_price_elasticity",E12="price_elasticity"),IF(COUNT(S12,T12)<2,"MISSING FISCAL INPUT",IF(OR(K12<0,K12>1),"BAD REDUCTION","OK")),IF(OR(V12="",W12="",COUNT(X12,Y12)<2),"MISSING REGULATORY INPUT",IF(OR(K12<0,K12>1),"BAD REDUCTION","OK"))) -> OK | P12: I_PH_TFA_POLICY | Q12: Industrial TFA regulation | R12: standalone | V12: partial | W12: full | X12: =IF(V12="none",Assumptions!$B$24,IF(V12="partial",Assumptions!$B$25,IF(V12="full",Assumptions!$B$26,""))) -> 0.5 | Y12: =IF(W12="none",Assumptions!$B$24,IF(W12="partial",Assumptions!$B$25,IF(W12="full",Assumptions!$B$26,""))) -> 1 | Z12: =IF(COUNT(X12,Y12)<2,"",MAX(0,Y12-X12)) -> 0.5 | AA12: =IF(E12="tax_share_to_price_elasticity",IF(OR(COUNT(S12,T12)<2,T12>=1),"",MAX(0,(1-S12)/(1-T12)-1)),IF(E12="price_elasticity",IF(COUNT(S12,T12)<2,"",MAX(0,T12-S12)),0)) -> 0 | AB12: =IF(OR(E12="tax_share_to_price_elasticity",E12="price_elasticity"),IF(COUNT(S12,T12)<2,"",T12-S12),0) -> 0
A13: PL_SSB_PRICE | B13: I_PH_SSB_TAX | C13: Sugar-sweetened beverage tax | D13: Incremental retail-price increase | E13: price_elasticity | F13: =IF(OR(E13="tax_share_to_price_elasticity",E13="price_elasticity"),S13,X13) -> 0 | G13: =IF(OR(E13="tax_share_to_price_elasticity",E13="price_elasticity"),T13,Y13) -> 0.2 | H13: =IF(OR(E13="tax_share_to_price_elasticity",E13="price_elasticity"),U13,"implementation score 0-1") -> relative price change vs baseline | I13: =Assumptions!$B$21 -> -0.875 | J13: own-price elasticity | K13: =IF(E13="tax_share_to_price_elasticity",MIN(1,ABS(I13)*AA13),IF(E13="price_elasticity",MIN(1,ABS(I13)*AA13),IF(E13="regulatory_gap_multiplicative",MIN(1,Z13*I13),""))) -> 0.175 | L13: https://doi.org/10.1371/journal.pone.0293913; WHO 2024 | M13: Ready | N13: Baseline no national excise; target +20% consumer price. | O13: =IF(OR(E13="tax_share_to_price_elasticity",E13="price_elasticity"),IF(COUNT(S13,T13)<2,"MISSING FISCAL INPUT",IF(OR(K13<0,K13>1),"BAD REDUCTION","OK")),IF(OR(V13="",W13="",COUNT(X13,Y13)<2),"MISSING REGULATORY INPUT",IF(OR(K13<0,K13>1),"BAD REDUCTION","OK"))) -> OK | P13: I_PH_SSB_TAX | Q13: SSB tax | R13: standalone | S13: 0 | T13: =Assumptions!$B$20 -> 0.2 | U13: relative price change vs baseline | V13: none | W13: full | X13: =IF(V13="none",Assumptions!$B$24,IF(V13="partial",Assumptions!$B$25,IF(V13="full",Assumptions!$B$26,""))) -> 0 | Y13: =IF(W13="none",Assumptions!$B$24,IF(W13="partial",Assumptions!$B$25,IF(W13="full",Assumptions!$B$26,""))) -> 1 | Z13: =IF(COUNT(X13,Y13)<2,"",MAX(0,Y13-X13)) -> 1 | AA13: =IF(E13="tax_share_to_price_elasticity",IF(OR(COUNT(S13,T13)<2,T13>=1),"",MAX(0,(1-S13)/(1-T13)-1)),IF(E13="price_elasticity",IF(COUNT(S13,T13)<2,"",MAX(0,T13-S13)),0)) -> 0.2 | AB13: =IF(OR(E13="tax_share_to_price_elasticity",E13="price_elasticity"),IF(COUNT(S13,T13)<2,"",T13-S13),0) -> 0.2

Sheet Exposure_Targets
A1: exposure_input_id | B1: intervention_id | C1: risk_id | D1: intervention_name | E1: risk_exposure_measure | F1: exposure_unit | G1: baseline_exposure | H1: reduction_method | I1: desired_reduction_override | J1: recommended_reduction_or_target | K1: applied_reduction_or_target | L1: exposure_floor | M1: target_exposure | N1: absolute_reduction | O1: relative_reduction | P1: start_year | Q1: target_year | R1: scale_up_shape | S1: source | T1: review_status | U1: qa_status
A2: EXP_TOB_TAX | B2: I_PH_TOBACCO_TAX | C2: R_SMOKING | D2: Tobacco tax | E2: Smoking prevalence | F2: proportion | G2: 0.303 | H2: relative | J2: =SUMIF(Policy_Levers!$B$2:$B$13,B2,Policy_Levers!$K$2:$K$13) -> 0.1743168 | K2: =IF(ISBLANK(I2),J2,I2) -> 0.1743168 | L2: 0 | M2: =IF(OR(ISBLANK(G2),ISBLANK(K2)),"",IF(H2="relative",MAX(L2,G2*(1-K2)),IF(H2="absolute",MAX(L2,G2-K2),IF(H2="target",MAX(L2,K2),"")))) -> 0.25018201 | N2: =IF(ISBLANK(M2),"",G2-M2) -> 0.05281799 | O2: =IF(OR(ISBLANK(G2),G2=0,ISBLANK(N2)),"",N2/G2) -> 0.1743168 | P2: =Assumptions!$B$4 -> 2026 | Q2: =Assumptions!$B$5 -> 2030 | R2: =Assumptions!$B$12 -> linear | S2: WHO/GATS; fiscal method | T2: Baseline retained | U2: =IF(ISBLANK(G2),"MISSING EXPOSURE",IF(ISBLANK(K2),"MISSING REDUCTION",IF(OR(M2<L2,M2>G2,Q2<P2),"BAD INPUT","OK"))) -> OK
A3: EXP_ALC_TAX | B3: I_PH_ALCOHOL_TAX | C3: R_ALCOHOL | D3: Alcohol tax | E3: Alcohol consumption per adult | F3: litres pure alcohol/adult/year | G3: 0.1 | H3: relative | J3: =SUMIF(Policy_Levers!$B$2:$B$13,B3,Policy_Levers!$K$2:$K$13) -> 0.1225 | K3: =IF(ISBLANK(I3),J3,I3) -> 0.1225 | L3: 0 | M3: =IF(OR(ISBLANK(G3),ISBLANK(K3)),"",IF(H3="relative",MAX(L3,G3*(1-K3)),IF(H3="absolute",MAX(L3,G3-K3),IF(H3="target",MAX(L3,K3),"")))) -> 0.08775 | N3: =IF(ISBLANK(M3),"",G3-M3) -> 0.01225 | O3: =IF(OR(ISBLANK(G3),G3=0,ISBLANK(N3)),"",N3/G3) -> 0.1225 | P3: =Assumptions!$B$4 -> 2026 | Q3: =Assumptions!$B$5 -> 2030 | R3: =Assumptions!$B$12 -> linear | S3: Countdown elasticity | T3: Baseline retained | U3: =IF(ISBLANK(G3),"MISSING EXPOSURE",IF(ISBLANK(K3),"MISSING REDUCTION",IF(OR(M3<L3,M3>G3,Q3<P3),"BAD INPUT","OK"))) -> OK
A4: EXP_TOB_CLEAN_AIR | B4: I_PH_TOB_CLEAN_AIR | C4: R_SMOKING | D4: Smoke-free / clean-air law | E4: Smoking prevalence | F4: proportion | G4: 0.303 | H4: relative | J4: =SUMIF(Policy_Levers!$B$2:$B$13,B4,Policy_Levers!$K$2:$K$13) -> 0.055 | K4: =IF(ISBLANK(I4),J4,I4) -> 0.055 | L4: 0 | M4: =IF(OR(ISBLANK(G4),ISBLANK(K4)),"",IF(H4="relative",MAX(L4,G4*(1-K4)),IF(H4="absolute",MAX(L4,G4-K4),IF(H4="target",MAX(L4,K4),"")))) -> 0.286335 | N4: =IF(ISBLANK(M4),"",G4-M4) -> 0.016665 | O4: =IF(OR(ISBLANK(G4),G4=0,ISBLANK(N4)),"",N4/G4) -> 0.055 | P4: =Assumptions!$B$4 -> 2026 | Q4: =Assumptions!$B$5 -> 2030 | R4: =Assumptions!$B$12 -> linear | S4: WHO category + Countdown effect | T4: Ready | U4: =IF(ISBLANK(G4),"MISSING EXPOSURE",IF(ISBLANK(K4),"MISSING REDUCTION",IF(OR(M4<L4,M4>G4,Q4<P4),"BAD INPUT","OK"))) -> OK
A5: EXP_TOB_MEDIA | B5: I_PH_TOB_MEDIA | C5: R_SMOKING | D5: Tobacco mass-media campaign | E5: Smoking prevalence | F5: proportion | G5: 0.303 | H5: relative | J5: =SUMIF(Policy_Levers!$B$2:$B$13,B5,Policy_Levers!$K$2:$K$13) -> 0.065 | K5: =IF(ISBLANK(I5),J5,I5) -> 0.065 | L5: 0 | M5: =IF(OR(ISBLANK(G5),ISBLANK(K5)),"",IF(H5="relative",MAX(L5,G5*(1-K5)),IF(H5="absolute",MAX(L5,G5-K5),IF(H5="target",MAX(L5,K5),"")))) -> 0.283305 | N5: =IF(ISBLANK(M5),"",G5-M5) -> 0.019695 | O5: =IF(OR(ISBLANK(G5),G5=0,ISBLANK(N5)),"",N5/G5) -> 0.065 | P5: =Assumptions!$B$4 -> 2026 | Q5: =Assumptions!$B$5 -> 2030 | R5: =Assumptions!$B$12 -> linear | S5: WHO category + Countdown effect | T5: Ready | U5: =IF(ISBLANK(G5),"MISSING EXPOSURE",IF(ISBLANK(K5),"MISSING REDUCTION",IF(OR(M5<L5,M5>G5,Q5<P5),"BAD INPUT","OK"))) -> OK
A6: EXP_TOB_AD_BAN | B6: I_PH_TOB_AD_BAN | C6: R_SMOKING | D6: Tobacco advertising ban | E6: Smoking prevalence | F6: proportion | G6: 0.303 | H6: relative | J6: =SUMIF(Policy_Levers!$B$2:$B$13,B6,Policy_Levers!$K$2:$K$13) -> 0.04 | K6: =IF(ISBLANK(I6),J6,I6) -> 0.04 | L6: 0 | M6: =IF(OR(ISBLANK(G6),ISBLANK(K6)),"",IF(H6="relative",MAX(L6,G6*(1-K6)),IF(H6="absolute",MAX(L6,G6-K6),IF(H6="target",MAX(L6,K6),"")))) -> 0.29088 | N6: =IF(ISBLANK(M6),"",G6-M6) -> 0.01212 | O6: =IF(OR(ISBLANK(G6),G6=0,ISBLANK(N6)),"",N6/G6) -> 0.04 | P6: =Assumptions!$B$4 -> 2026 | Q6: =Assumptions!$B$5 -> 2030 | R6: =Assumptions!$B$12 -> linear | S6: WHO category + Countdown effect | T6: Ready | U6: =IF(ISBLANK(G6),"MISSING EXPOSURE",IF(ISBLANK(K6),"MISSING REDUCTION",IF(OR(M6<L6,M6>G6,Q6<P6),"BAD INPUT","OK"))) -> OK
A7: EXP_ALC_POLICY | B7: I_PH_ALCOHOL_POLICY | C7: R_ALCOHOL | D7: Alcohol advertising ban | E7: Alcohol consumption per adult | F7: litres pure alcohol/adult/year | G7: 0.1 | H7: relative | J7: =SUMIF(Policy_Levers!$B$2:$B$13,B7,Policy_Levers!$K$2:$K$13) -> 0.1345 | K7: =IF(ISBLANK(I7),J7,I7) -> 0.1345 | L7: 0 | M7: =IF(OR(ISBLANK(G7),ISBLANK(K7)),"",IF(H7="relative",MAX(L7,G7*(1-K7)),IF(H7="absolute",MAX(L7,G7-K7),IF(H7="target",MAX(L7,K7),"")))) -> 0.08655 | N7: =IF(ISBLANK(M7),"",G7-M7) -> 0.01345 | O7: =IF(OR(ISBLANK(G7),G7=0,ISBLANK(N7)),"",N7/G7) -> 0.1345 | P7: =Assumptions!$B$4 -> 2026 | Q7: =Assumptions!$B$5 -> 2030 | R7: =Assumptions!$B$12 -> linear | S7: WHO category + Countdown effect | T7: Ready | U7: =IF(ISBLANK(G7),"MISSING EXPOSURE",IF(ISBLANK(K7),"MISSING REDUCTION",IF(OR(M7<L7,M7>G7,Q7<P7),"BAD INPUT","OK"))) -> OK
A8: EXP_SALT_REFORM | B8: I_PH_SALT_REFORM | C8: R_SODIUM | D8: Mandatory sodium reformulation | E8: Mean sodium intake | F8: g sodium/day | G8: 4.4 | H8: relative | J8: =SUMIF(Policy_Levers!$B$2:$B$13,B8,Policy_Levers!$K$2:$K$13) -> 0.1 | K8: =IF(ISBLANK(I8),J8,I8) -> 0.1 | L8: 3 | M8: =IF(OR(ISBLANK(G8),ISBLANK(K8)),"",IF(H8="relative",MAX(L8,G8*(1-K8)),IF(H8="absolute",MAX(L8,G8-K8),IF(H8="target",MAX(L8,K8),"")))) -> 3.96 | N8: =IF(ISBLANK(M8),"",G8-M8) -> 0.44 | O8: =IF(OR(ISBLANK(G8),G8=0,ISBLANK(N8)),"",N8/G8) -> 0.1 | P8: =Assumptions!$B$4 -> 2026 | Q8: =Assumptions!$B$5 -> 2030 | R8: =Assumptions!$B$12 -> linear | S8: WHO category + Countdown effect | T8: Ready | U8: =IF(ISBLANK(G8),"MISSING EXPOSURE",IF(ISBLANK(K8),"MISSING REDUCTION",IF(OR(M8<L8,M8>G8,Q8<P8),"BAD INPUT","OK"))) -> OK
A9: EXP_SALT_FOPL | B9: I_PH_SALT_FOPL | C9: R_SODIUM | D9: Sodium front-of-pack labelling | E9: Mean sodium intake | F9: g sodium/day | G9: 4.4 | H9: relative | J9: =SUMIF(Policy_Levers!$B$2:$B$13,B9,Policy_Levers!$K$2:$K$13) -> 0.05 | K9: =IF(ISBLANK(I9),J9,I9) -> 0.05 | L9: 3 | M9: =IF(OR(ISBLANK(G9),ISBLANK(K9)),"",IF(H9="relative",MAX(L9,G9*(1-K9)),IF(H9="absolute",MAX(L9,G9-K9),IF(H9="target",MAX(L9,K9),"")))) -> 4.18 | N9: =IF(ISBLANK(M9),"",G9-M9) -> 0.22 | O9: =IF(OR(ISBLANK(G9),G9=0,ISBLANK(N9)),"",N9/G9) -> 0.05 | P9: =Assumptions!$B$4 -> 2026 | Q9: =Assumptions!$B$5 -> 2030 | R9: =Assumptions!$B$12 -> linear | S9: WHO category + Countdown effect | T9: Ready | U9: =IF(ISBLANK(G9),"MISSING EXPOSURE",IF(ISBLANK(K9),"MISSING REDUCTION",IF(OR(M9<L9,M9>G9,Q9<P9),"BAD INPUT","OK"))) -> OK
A10: EXP_SALT_MEDIA | B10: I_PH_SALT_MEDIA | C10: R_SODIUM | D10: Sodium mass-media campaign | E10: Mean sodium intake | F10: g sodium/day | G10: 4.4 | H10: relative | J10: =SUMIF(Policy_Levers!$B$2:$B$13,B10,Policy_Levers!$K$2:$K$13) -> 0 | K10: =IF(ISBLANK(I10),J10,I10) -> 0 | L10: 3 | M10: =IF(OR(ISBLANK(G10),ISBLANK(K10)),"",IF(H10="relative",MAX(L10,G10*(1-K10)),IF(H10="absolute",MAX(L10,G10-K10),IF(H10="target",MAX(L10,K10),"")))) -> 4.4 | N10: =IF(ISBLANK(M10),"",G10-M10) -> 0 | O10: =IF(OR(ISBLANK(G10),G10=0,ISBLANK(N10)),"",N10/G10) -> 0 | P10: =Assumptions!$B$4 -> 2026 | Q10: =Assumptions!$B$5 -> 2030 | R10: =Assumptions!$B$12 -> linear | S10: WHO category + Countdown effect | T10: Ready | U10: =IF(ISBLANK(G10),"MISSING EXPOSURE",IF(ISBLANK(K10),"MISSING REDUCTION",IF(OR(M10<L10,M10>G10,Q10<P10),"BAD INPUT","OK"))) -> OK
A11: EXP_SALT_ENV | B11: I_PH_SALT_ENV | C11: R_SODIUM | D11: Supportive public-institution environment | E11: Mean sodium intake | F11: g sodium/day | G11: 4.4 | H11: relative | J11: =SUMIF(Policy_Levers!$B$2:$B$13,B11,Policy_Levers!$K$2:$K$13) -> 0.035 | K11: =IF(ISBLANK(I11),J11,I11) -> 0.035 | L11: 3 | M11: =IF(OR(ISBLANK(G11),ISBLANK(K11)),"",IF(H11="relative",MAX(L11,G11*(1-K11)),IF(H11="absolute",MAX(L11,G11-K11),IF(H11="target",MAX(L11,K11),"")))) -> 4.246 | N11: =IF(ISBLANK(M11),"",G11-M11) -> 0.154 | O11: =IF(OR(ISBLANK(G11),G11=0,ISBLANK(N11)),"",N11/G11) -> 0.035 | P11: =Assumptions!$B$4 -> 2026 | Q11: =Assumptions!$B$5 -> 2030 | R11: =Assumptions!$B$12 -> linear | S11: WHO category + Countdown effect | T11: Ready | U11: =IF(ISBLANK(G11),"MISSING EXPOSURE",IF(ISBLANK(K11),"MISSING REDUCTION",IF(OR(M11<L11,M11>G11,Q11<P11),"BAD INPUT","OK"))) -> OK
A12: EXP_TFA_POLICY | B12: I_PH_TFA_POLICY | C12: R_TFA | D12: Industrial trans-fat elimination regulation | E12: Mean industrial trans-fat intake | F12: % energy | G12: 0.0317 | H12: relative | J12: =SUMIF(Policy_Levers!$B$2:$B$13,B12,Policy_Levers!$K$2:$K$13) -> 0.5 | K12: =IF(ISBLANK(I12),J12,I12) -> 0.5 | L12: 0 | M12: =IF(OR(ISBLANK(G12),ISBLANK(K12)),"",IF(H12="relative",MAX(L12,G12*(1-K12)),IF(H12="absolute",MAX(L12,G12-K12),IF(H12="target",MAX(L12,K12),"")))) -> 0.01585 | N12: =IF(ISBLANK(M12),"",G12-M12) -> 0.01585 | O12: =IF(OR(ISBLANK(G12),G12=0,ISBLANK(N12)),"",N12/G12) -> 0.5 | P12: =Assumptions!$B$4 -> 2026 | Q12: =Assumptions!$B$5 -> 2030 | R12: =Assumptions!$B$12 -> linear | S12: WHO regulatory gap + RR | T12: RR base case; PAF optional | U12: =IF(ISBLANK(G12),"MISSING EXPOSURE",IF(ISBLANK(K12),"MISSING REDUCTION",IF(OR(M12<L12,M12>G12,Q12<P12),"BAD INPUT","OK"))) -> OK
A13: EXP_SSB_TAX | B13: I_PH_SSB_TAX | C13: R_SSB | D13: Sugar-sweetened beverage tax | E13: Mean SSB intake | F13: 8 oz servings/adult/day | G13: 0.11428571 | H13: relative | J13: =SUMIF(Policy_Levers!$B$2:$B$13,B13,Policy_Levers!$K$2:$K$13) -> 0.175 | K13: =IF(ISBLANK(I13),J13,I13) -> 0.175 | L13: 0 | M13: =IF(OR(ISBLANK(G13),ISBLANK(K13)),"",IF(H13="relative",MAX(L13,G13*(1-K13)),IF(H13="absolute",MAX(L13,G13-K13),IF(H13="target",MAX(L13,K13),"")))) -> 0.094285714 | N13: =IF(ISBLANK(M13),"",G13-M13) -> 0.02 | O13: =IF(OR(ISBLANK(G13),G13=0,ISBLANK(N13)),"",N13/G13) -> 0.175 | P13: =Assumptions!$B$4 -> 2026 | Q13: =Assumptions!$B$5 -> 2030 | R13: =Assumptions!$B$12 -> linear | S13: Lara-Castor; Widarjono | T13: GDD 2020 mean | U13: =IF(ISBLANK(G13),"MISSING EXPOSURE",IF(ISBLANK(K13),"MISSING REDUCTION",IF(OR(M13<L13,M13>G13,Q13<P13),"BAD INPUT","OK"))) -> OK

Sheet Effect_Parameters
A1: effect_id | B1: intervention_cause_key | C1: intervention_id | D1: risk_id | E1: cause_id | F1: effect_model | G1: response_key | H1: response_parameter | I1: response_value | J1: response_unit | K1: paf_value | L1: paf_required_flag | M1: paf_threshold | N1: lag_model | O1: lag_parameter | P1: transition_from | Q1: transition_to | R1: source_file | S1: source_location | T1: review_status | U1: notes | V1: map_match_count | W1: qa_status
A2: EFF_001 | B2: I_PH_TOBACCO_TAX__C_IHD | C2: I_PH_TOBACCO_TAX | D2: R_SMOKING | E2: C_IHD | F2: direct_smoking_prevalence_shift_rr | G2: RR_SMOKING_IHD | H2: RR current smoker vs non-smoker | I2: =INDEX(Risk_Response!$L$2:$L$63,MATCH(G2,Risk_Response!$A$2:$A$63,0)) -> 1.6 | J2: relative risk | L2: 0 | N2: jha_piecewise_shared_scalar | O2: =SUMIF(Assumptions!$A$2:$A$37,"tobacco_cvd_lag_rate",Assumptions!$B$2:$B$37) -> 0.0616 | P2: well | Q2: sick | R2: APCSC; Cho et al. 2024 | S2: https://doi.org/10.1093/ije/dyi104; https://doi.org/10.1056/EVIDoa2300272 | T2: Ready | U2: Direct well-to-sick incidence effect. Base timing: Jha age-sex piecewise shared scalar; lag_parameter is sensitivity-only. | V2: =COUNTIF(Intervention_Cause_Map!$A$2:$A$62,B2) -> 1 | W2: =IF(V2<>1,"MAP ERROR",IF(NOT(OR(AND(P2="well",Q2="sick"),AND(P2="sick",Q2="dead"))),"REVIEW TRANSITION",IF(AND(L2=1,OR(ISBLANK(K2),K2<0,K2>1)),"MISSING PAF",IF(R2="","MISSING SOURCE",IF(OR(T2="Ready",T2=""),"OK","REVIEW"))))) -> OK
A3: EFF_002 | B3: I_PH_TOBACCO_TAX__C_IS | C3: I_PH_TOBACCO_TAX | D3: R_SMOKING | E3: C_IS | F3: direct_smoking_prevalence_shift_rr | G3: RR_SMOKING_IS | H3: RR current smoker vs non-smoker | I3: =INDEX(Risk_Response!$L$2:$L$63,MATCH(G3,Risk_Response!$A$2:$A$63,0)) -> 1.38 | J3: relative risk | L3: 0 | N3: jha_piecewise_shared_scalar | O3: =SUMIF(Assumptions!$A$2:$A$37,"tobacco_cvd_lag_rate",Assumptions!$B$2:$B$37) -> 0.0616 | P3: well | Q3: sick | R3: APCSC; Cho et al. 2024 | S3: https://doi.org/10.1093/ije/dyi104; https://doi.org/10.1056/EVIDoa2300272 | T3: Ready | U3: Direct well-to-sick incidence effect. Base timing: Jha age-sex piecewise shared scalar; lag_parameter is sensitivity-only. | V3: =COUNTIF(Intervention_Cause_Map!$A$2:$A$62,B3) -> 1 | W3: =IF(V3<>1,"MAP ERROR",IF(NOT(OR(AND(P3="well",Q3="sick"),AND(P3="sick",Q3="dead"))),"REVIEW TRANSITION",IF(AND(L3=1,OR(ISBLANK(K3),K3<0,K3>1)),"MISSING PAF",IF(R3="","MISSING SOURCE",IF(OR(T3="Ready",T3=""),"OK","REVIEW"))))) -> OK
A4: EFF_003 | B4: I_PH_TOBACCO_TAX__C_ICH | C4: I_PH_TOBACCO_TAX | D4: R_SMOKING | E4: C_ICH | F4: direct_smoking_prevalence_shift_rr | G4: RR_SMOKING_ICH | H4: RR current smoker vs non-smoker | I4: =INDEX(Risk_Response!$L$2:$L$63,MATCH(G4,Risk_Response!$A$2:$A$63,0)) -> 1.19 | J4: relative risk | L4: 0 | N4: jha_piecewise_shared_scalar | O4: =SUMIF(Assumptions!$A$2:$A$37,"tobacco_cvd_lag_rate",Assumptions!$B$2:$B$37) -> 0.0616 | P4: well | Q4: sick | R4: APCSC; Cho et al. 2024 | S4: https://doi.org/10.1093/ije/dyi104; https://doi.org/10.1056/EVIDoa2300272 | T4: Ready | U4: Direct well-to-sick incidence effect. Base timing: Jha age-sex piecewise shared scalar; lag_parameter is sensitivity-only. | V4: =COUNTIF(Intervention_Cause_Map!$A$2:$A$62,B4) -> 1 | W4: =IF(V4<>1,"MAP ERROR",IF(NOT(OR(AND(P4="well",Q4="sick"),AND(P4="sick",Q4="dead"))),"REVIEW TRANSITION",IF(AND(L4=1,OR(ISBLANK(K4),K4<0,K4>1)),"MISSING PAF",IF(R4="","MISSING SOURCE",IF(OR(T4="Ready",T4=""),"OK","REVIEW"))))) -> OK
A5: EFF_004 | B5: I_PH_TOBACCO_TAX__C_T2DM | C5: I_PH_TOBACCO_TAX | D5: R_SMOKING | E5: C_T2DM | F5: direct_smoking_prevalence_shift_rr | G5: RR_SMOKING_T2DM | H5: RR current smoker vs non-smoker | I5: =INDEX(Risk_Response!$L$2:$L$63,MATCH(G5,Risk_Response!$A$2:$A$63,0)) -> 1.37 | J5: relative risk | L5: 0 | N5: delayed_exponential_remaining_effect | O5: =Risk_Response!$L$12 -> 0.061514457 | P5: well | Q5: sick | R5: APCSC; Pan et al. | S5: https://doi.org/10.1016/S2213-8587(15)00316-2 | T5: Ready | U5: Direct well-to-sick incidence effect. | V5: =COUNTIF(Intervention_Cause_Map!$A$2:$A$62,B5) -> 1 | W5: =IF(V5<>1,"MAP ERROR",IF(NOT(OR(AND(P5="well",Q5="sick"),AND(P5="sick",Q5="dead"))),"REVIEW TRANSITION",IF(AND(L5=1,OR(ISBLANK(K5),K5<0,K5>1)),"MISSING PAF",IF(R5="","MISSING SOURCE",IF(OR(T5="Ready",T5=""),"OK","REVIEW"))))) -> OK
A6: EFF_005 | B6: I_PH_ALCOHOL_TAX__C_IHD | C6: I_PH_ALCOHOL_TAX | D6: R_ALCOHOL | E6: C_IHD | F6: direct_loglinear_rr_per_unit_reduction | G6: RR_ALCOHOL_IHD_1L | H6: RR per 1 L/year | I6: =INDEX(Risk_Response!$L$2:$L$63,MATCH(G6,Risk_Response!$A$2:$A$63,0)) -> 1.0088804 | J6: relative risk | L6: 0 | N6: immediate_after_full_implementation | O6: 1 | P6: well | Q6: sick | R6: Wood et al. 2018 | S6: https://doi.org/10.1016/S0140-6736(18)30134-X | T6: Ready | U6: Direct well-to-sick incidence effect. | V6: =COUNTIF(Intervention_Cause_Map!$A$2:$A$62,B6) -> 1 | W6: =IF(V6<>1,"MAP ERROR",IF(NOT(OR(AND(P6="well",Q6="sick"),AND(P6="sick",Q6="dead"))),"REVIEW TRANSITION",IF(AND(L6=1,OR(ISBLANK(K6),K6<0,K6>1)),"MISSING PAF",IF(R6="","MISSING SOURCE",IF(OR(T6="Ready",T6=""),"OK","REVIEW"))))) -> OK
A7: EFF_006 | B7: I_PH_ALCOHOL_TAX__C_IS | C7: I_PH_ALCOHOL_TAX | D7: R_ALCOHOL | E7: C_IS | F7: direct_loglinear_rr_per_unit_reduction | G7: RR_ALCOHOL_IS_1L | H7: RR per 1 L/year | I7: =INDEX(Risk_Response!$L$2:$L$63,MATCH(G7,Risk_Response!$A$2:$A$63,0)) -> 1.02008 | J7: relative risk | L7: 0 | N7: immediate_after_full_implementation | O7: 1 | P7: well | Q7: sick | R7: Wood et al. 2018 | S7: https://doi.org/10.1016/S0140-6736(18)30134-X | T7: Ready | U7: Direct well-to-sick incidence effect. | V7: =COUNTIF(Intervention_Cause_Map!$A$2:$A$62,B7) -> 1 | W7: =IF(V7<>1,"MAP ERROR",IF(NOT(OR(AND(P7="well",Q7="sick"),AND(P7="sick",Q7="dead"))),"REVIEW TRANSITION",IF(AND(L7=1,OR(ISBLANK(K7),K7<0,K7>1)),"MISSING PAF",IF(R7="","MISSING SOURCE",IF(OR(T7="Ready",T7=""),"OK","REVIEW"))))) -> OK
A8: EFF_007 | B8: I_PH_ALCOHOL_TAX__C_ICH | C8: I_PH_ALCOHOL_TAX | D8: R_ALCOHOL | E8: C_ICH | F8: direct_loglinear_rr_per_unit_reduction | G8: RR_ALCOHOL_ICH_1L | H8: RR per 1 L/year | I8: =INDEX(Risk_Response!$L$2:$L$63,MATCH(G8,Risk_Response!$A$2:$A$63,0)) -> 1.02008 | J8: relative risk | L8: 0 | N8: immediate_after_full_implementation | O8: 1 | P8: well | Q8: sick | R8: Wood et al. 2018 | S8: https://doi.org/10.1016/S0140-6736(18)30134-X | T8: Ready | U8: Direct well-to-sick incidence effect. | V8: =COUNTIF(Intervention_Cause_Map!$A$2:$A$62,B8) -> 1 | W8: =IF(V8<>1,"MAP ERROR",IF(NOT(OR(AND(P8="well",Q8="sick"),AND(P8="sick",Q8="dead"))),"REVIEW TRANSITION",IF(AND(L8=1,OR(ISBLANK(K8),K8<0,K8>1)),"MISSING PAF",IF(R8="","MISSING SOURCE",IF(OR(T8="Ready",T8=""),"OK","REVIEW"))))) -> OK
A9: EFF_008 | B9: I_PH_ALCOHOL_TAX__C_HHD | C9: I_PH_ALCOHOL_TAX | D9: R_ALCOHOL | E9: C_HHD | F9: direct_loglinear_rr_per_unit_reduction | G9: RR_ALCOHOL_HHD_1L | H9: RR per 1 L/year | I9: =INDEX(Risk_Response!$L$2:$L$63,MATCH(G9,Risk_Response!$A$2:$A$63,0)) -> 1.0331775 | J9: relative risk | L9: 0 | N9: immediate_after_full_implementation | O9: 1 | P9: well | Q9: sick | R9: Wood et al. 2018 | S9: https://doi.org/10.1016/S0140-6736(18)30134-X | T9: Ready | U9: Direct well-to-sick incidence effect. | V9: =COUNTIF(Intervention_Cause_Map!$A$2:$A$62,B9) -> 1 | W9: =IF(V9<>1,"MAP ERROR",IF(NOT(OR(AND(P9="well",Q9="sick"),AND(P9="sick",Q9="dead"))),"REVIEW TRANSITION",IF(AND(L9=1,OR(ISBLANK(K9),K9<0,K9>1)),"MISSING PAF",IF(R9="","MISSING SOURCE",IF(OR(T9="Ready",T9=""),"OK","REVIEW"))))) -> OK
A10: EFF_009 | B10: I_PH_ALCOHOL_TAX__C_CMYO | C10: I_PH_ALCOHOL_TAX | D10: R_ALCOHOL | E10: C_CMYO | F10: direct_loglinear_rr_per_unit_reduction | G10: RR_ALCOHOL_CMYO_1L | H10: RR per 1 L/year | I10: =INDEX(Risk_Response!$L$2:$L$63,MATCH(G10,Risk_Response!$A$2:$A$63,0)) -> 1.0131617 | J10: relative risk | L10: 0 | N10: immediate_after_full_implementation | O10: 1 | P10: well | Q10: sick | R10: Wood et al. 2018 | S10: https://doi.org/10.1016/S0140-6736(18)30134-X | T10: Ready | U10: Direct well-to-sick incidence effect. | V10: =COUNTIF(Intervention_Cause_Map!$A$2:$A$62,B10) -> 1 | W10: =IF(V10<>1,"MAP ERROR",IF(NOT(OR(AND(P10="well",Q10="sick"),AND(P10="sick",Q10="dead"))),"REVIEW TRANSITION",IF(AND(L10=1,OR(ISBLANK(K10),K10<0,K10>1)),"MISSING PAF",IF(R10="","MISSING SOURCE",IF(OR(T10="Ready",T10=""),"OK","REVIEW"))))) -> OK
