Workbook

Sheet README
A1: Indonesia 70-30-30 to 70-70-70 — stand-alone input workbook
A3: Formula-driven cascade inputs • NCD-RisC hypertension and diabetes • cholesterol coverage follows hypertension
A5: Readiness | C5: Interventions | E5: Model causes | G5: Intervention-cause links
A6: =QA_Checks!E14 -> MODEL INTEGRATION REQUIRED | C6: =COUNTA(Dictionaries!A2:A3) -> 2 | E6: =COUNTIF(Dictionaries!H2:H6,1) -> 5 | G6: =COUNTA(Intervention_Cause_Map!A2:A7) -> 6
A9: How to use the workbook
A10: 1 | B10: Edit yellow cells only; light-blue cells are formulas or derived values.
A11: 2 | B11: Review Coverage to audit baseline and target cascade arithmetic; 13.65% and 41.65% are used exactly.
A12: 3 | B12: Use Coverage_Trajectory for annual intervention coverage and Model_Input_View for model-ready transition multipliers.
A13: 4 | B13: Run the accompanying R script to create CSV/RDS handoff files; it recomputes formulas from raw inputs.
A14: 5 | B14: Health outcomes require the calibrated Markov baseline and scenario runner; national cost formulae are supplied in the companion results workbook.
A16: Key review items retained explicitly
A17: Missing | B17: Calibrated national Markov baseline RDS and scenario runner were not supplied; deaths, cases, and life-years cannot yet be recalculated.
A18: Review | B18: Diabetes control is an editable 34.21% among-treated baseline derived from the 2023 national care cascade and cross-checked against a peer-reviewed 32.0% estimate.
A19: Ready | B19: Exact effective coverage is 13.65% in 2030 and 41.65% in 2040; no rounded override is applied.
A20: Missing | B20: Provincial cascade and calibrated disease-burden inputs are absent; the provincial sheet is illustrative only.
A21: Ready | B21: Updated diabetes screening, non-insulin management, and insulin-management costs are Indonesia-adjusted 2023 USD inputs.
A23: Color legend: yellow = editable input • light blue = formula/derived • green = valid • orange/red = review or missing

Sheet Assumptions
A1: parameter_id | B1: value | C1: unit | D1: base_case | E1: lower_bound | F1: upper_bound | G1: description | H1: source
A2: analysis_start_year | B2: 2025 | C2: year | D2: 2025 | E2: 2025 | F2: 2025 | G2: First modeled year | H2: Agreed analysis horizon
A3: analysis_end_year | B3: 2050 | C3: year | D3: 2050 | E3: 2050 | F3: 2050 | G3: Last modeled year | H3: Agreed analysis horizon
A4: first_target_year | B4: 2030 | C4: year | D4: 2030 | E4: 2030 | F4: 2030 | G4: Year to achieve 70-30-30 | H4: World Bank/UW request, 27 Aug 2026
A5: final_target_year | B5: 2040 | C5: year | D5: 2040 | E5: 2040 | F5: 2040 | G5: Year to achieve 70-70-70 | H5: World Bank/UW request, 27 Aug 2026
A6: target_diagnosis_share | B6: 0.7 | C6: proportion | D6: 0.7 | E6: 0.7 | F6: 0.7 | G6: Diagnosis step for both targets | H6: World Bank/UW request
A7: first_target_treatment_conditional | B7: 0.3 | C7: proportion | D7: 0.3 | E7: 0.3 | F7: 0.3 | G7: Treated among diagnosed in 2030 | H7: 70-30-30 definition
A8: first_target_control_conditional | B8: 0.3 | C8: proportion | D8: 0.3 | E8: 0.3 | F8: 0.3 | G8: Controlled among treated in 2030 | H8: 70-30-30 definition
A9: final_target_treatment_conditional | B9: 0.7 | C9: proportion | D9: 0.7 | E9: 0.7 | F9: 0.7 | G9: Treated among diagnosed in 2040 | H9: 70-70-70 definition
A10: final_target_control_conditional | B10: 0.7 | C10: proportion | D10: 0.7 | E10: 0.7 | F10: 0.7 | G10: Controlled among treated in 2040 | H10: 70-70-70 definition
A11: treated_uncontrolled_effect_fraction | B11: 0.5 | C11: share of full effect | D11: 0.5 | E11: 0.5 | F11: 0.5 | G11: Effect received when treated but uncontrolled | H11: World Bank/UW request
A12: first_target_effective_coverage_exact | B12: =B6*B7*(B8+(1-B8)*B11) -> 0.1365 | C12: proportion | D12: 0.1365 | E12: 0.1365 | F12: 0.1365 | G12: Exact 70-30-30 effective coverage; no rounding override | H12: World Bank/UW cascade specification
A13: final_target_effective_coverage_exact | B13: =B6*B9*(B10+(1-B10)*B11) -> 0.4165 | C13: proportion | D13: 0.4165 | E13: 0.4165 | F13: 0.4165 | G13: Exact 70-70-70 effective coverage; no rounding override | H13: World Bank/UW cascade specification
A14: diabetes_baseline_control_among_treated | B14: 0.34210526 | C14: proportion | D14: 0.34210526 | E14: 0.32 | F14: 0.363 | G14: Derived as 6.5% controlled / 19.0% treated in the 2023 national diabetes cascade; editable | H14: Muharram et al. medRxiv 2026; peer-reviewed national estimate 32.0% HbA1c<7%
A15: diabetes_baseline_diagnosis_conditioning | B15: 1 | C15: proportion | D15: 1 | E15: 1 | F15: 1 | G15: Conditions directly on all people with diabetes so reported treatment is reproduced | H15: Explicit modeling assumption
A16: cholesterol_coverage_proxy | B16: hypertension | C16: text | D16: hypertension | E16: hypertension | F16: hypertension | G16: Cholesterol coverage follows hypertension coverage | H16: World Bank/UW request
A17: scale_up_shape | B17: piecewise_linear | C17: text | D17: piecewise_linear | E17: piecewise_linear | F17: piecewise_linear | G17: Linear to 2030, then linear to 2040 | H17: World Bank/UW request
A18: post_target_rule | B18: hold | C18: text | D18: hold | E18: hold | F18: hold | G18: Maintain achieved level after 2040 | H18: World Bank/UW request
A19: prevent_coverage_backsliding | B19: 1 | C19: 0/1 | D19: 1 | E19: 0 | F19: 1 | G19: When a measured baseline already exceeds a milestone, retain baseline rather than scale down | H19: Scale-up interpretation
A20: scenario_id | B20: S_70_30_30_TO_70_70_70 | C20: text | D20: S_70_30_30_TO_70_70_70 | G20: Stable scenario identifier | H20: This analysis
A21: model_baseline_rds | C21: path | G21: Calibrated national baseline RDS; required for health outcomes | H21: Not supplied
A22: model_runner_script | C22: path | G22: Existing Markov scenario runner; required for health outcomes | H22: Not supplied
A23: model_output_directory | B23: output/70_30_30_to_70_70_70 | C23: path | D23: output/70_30_30_to_70_70_70 | G23: Dedicated output directory | H23: This analysis
A24: cost_discount_rate | B24: 0.03 | C24: proportion/year | D24: 0.03 | E24: 0 | F24: 0.05 | G24: Annual cost discount rate | H24: Supplied Indonesia input workbook
A25: health_discount_rate | B25: 0.03 | C25: proportion/year | D25: 0.03 | E25: 0 | F25: 0.05 | G25: Annual health discount rate | H25: Supplied Indonesia input workbook
A26: cost_price_year | B26: 2023 | C26: USD year | D26: 2023 | E26: 2023 | F26: 2023 | G26: Reporting price year | H26: Supplied Indonesia input workbook
A27: currency | B27: USD | C27: currency | D27: USD | E27: USD | F27: USD | G27: Reporting currency | H27: Supplied Indonesia input workbook
A28: downstream_cost_offsets | B28: 0 | C28: 0/1 flag | D28: 0 | E28: 0 | F28: 1 | G28: Include downstream disease-cost offsets | H28: input_file.xlsx
A29: economic_perspective | B29: health_system | C29: text | D29: health_system | E29: health_system | F29: societal | G29: Economic evaluation perspective | H29: Working assumption
A30: bca_base_year | B30: 2025 | C30: year | D30: 2025 | E30: 2025 | F30: 2026 | G30: Base year to which BCA benefits and costs are both discounted (single shared base year) | H30: Robinson et al. 2019 Reference Case Guidelines for BCA in Global Health & Development (CHDS/Harvard); = analysis_start_year
A31: bca_discount_rate_primary | B31: 0.03 | C31: proportion/year | D31: 0.03 | E31: 0.03 | F31: 0.05 | G31: Primary real discount rate applied to BOTH benefits and costs in the BCA | H31: Robinson et al. 2019 Reference Case Guidelines for BCA in Global Health & Development (CHDS/Harvard); context-specific primary rate
A32: bca_discount_rate_sensitivity_3pct | B32: 0.03 | C32: proportion/year | D32: 0.03 | E32: 0.03 | F32: 0.03 | G32: Standardized sensitivity discount rate (3%) | H32: Robinson et al. 2019 Reference Case Guidelines for BCA in Global Health & Development (CHDS/Harvard); standardized sensitivity
A33: bca_discount_rate_sensitivity_2x_gdp_pc_growth | B33: 0.08 | C33: proportion/year | D33: 0.08 | E33: 0.06 | F33: 0.1 | G33: Standardized sensitivity = 2x projected near-term real GDP per-capita growth; Model 08 recomputes from SSP2 | H33: Robinson et al. 2019 Reference Case Guidelines for BCA in Global Health & Development (CHDS/Harvard); IIASA SSP 3.1 (SSP2)
A34: vsl_us_gni_ratio | B34: 160 | C34: ratio (VSL/GNI per capita) | D34: 160 | E34: 100 | F34: 230 | G34: U.S. reference VSL-to-GNI-per-capita ratio used for the income transfer | H34: Robinson et al. 2019 Reference Case Guidelines for BCA in Global Health & Development (CHDS/Harvard)
A35: vsl_income_elasticity_preferred | B35: 1.5 | C35: elasticity | D35: 1.5 | E35: 1 | F35: 1.5 | G35: Income elasticity of VSL for LMIC extrapolation (preferred / reference case) | H35: Robinson et al. 2019 Reference Case Guidelines for BCA in Global Health & Development (CHDS/Harvard)
A36: vsl_floor_gni_multiple | B36: 20 | C36: ratio (VSL/GNI per capita) | D36: 20 | E36: 20 | F36: 20 | G36: Lower bound: transferred VSL not below this multiple of target-country GNI per capita | H36: Robinson et al. 2019 Reference Case Guidelines for BCA in Global Health & Development (CHDS/Harvard)
A37: vsl_sensitivity_gni_multiple_100 | B37: 100 | C37: ratio (VSL/GNI per capita) | D37: 100 | E37: 100 | F37: 100 | G37: Standardized sensitivity 1: VSL = 100 x target GNI per capita | H37: Robinson et al. 2019 Reference Case Guidelines for BCA in Global Health & Development (CHDS/Harvard)
A38: vsl_sensitivity_gni_multiple_160 | B38: 160 | C38: ratio (VSL/GNI per capita) | D38: 160 | E38: 160 | F38: 160 | G38: Standardized sensitivity 2: VSL = 160 x target GNI per capita | H38: Robinson et al. 2019 Reference Case Guidelines for BCA in Global Health & Development (CHDS/Harvard)
... A40: vsly_adult_max_age | B40: 64 | C40: age (years) | D40: 64 | E40: 64 | F40: 95 | G40: Upper bound of adult (working-age) population for the VSLY average-adult-age denominator | H40: ILO / World Bank working-age population 15-64
A41: bca_currency_basis | B41: PPP_international_dollars | C41: text | D41: PPP_international_dollars | G41: Common monetary basis for BCA benefits and costs; VSL is transferred using GNI per capita at PPP | H41: Robinson et al. 2019 Reference Case Guidelines for BCA in Global Health & Development (CHDS/Harvard)
...

Sheet Dictionaries
A1: intervention_id | B1: intervention_name | C1: package_group | D1: definition | E1: cause_id | F1: cause_name | G1: model_name | H1: is_model_cause
A2: I_CVD_PRIMARY | B2: Primary prevention of CVD | C2: Primary CVD prevention | D2: Hypertension treatment plus statin coverage, using the agreed cascade | E2: C_IHD | F2: Ischemic heart disease | G2: Ischemic heart disease | H2: 1
A3: I_T2D_TREATMENT | B3: Longitudinal treatment of type 2 diabetes | C3: Diabetes treatment | D3: Treatment affects direct diabetes deaths and IHD attributable to high blood glucose | E3: C_IS | F3: Ischemic stroke | G3: Ischemic stroke | H3: 1
E4: C_ICH | F4: Intracerebral hemorrhage | G4: Intracerebral hemorrhage | H4: 1
E5: C_HHD | F5: Hypertensive heart disease | G5: Hypertensive heart disease | H5: 1
E6: C_T2D | F6: Diabetes mellitus type 2 | G6: Type 2 diabetes | H6: 1
E7: C_SHARED | F7: Shared intervention cost | G7: Not a disease model | H7: 0

Sheet Intervention_Cause_Map
A1: intervention_cause_key | B1: intervention_id | C1: intervention_name | D1: cause_id | E1: cause_name | F1: model_name | G1: transition_from | H1: transition_to | I1: effect_key | J1: cost_join_key | K1: cost_scope | L1: include_flag | M1: notes
A2: I_CVD_PRIMARY__C_IHD | B2: I_CVD_PRIMARY | C2: Primary prevention of CVD | D2: C_IHD | E2: Ischemic heart disease | F2: Ischemic heart disease | G2: well | H2: sick | I2: I_CVD_PRIMARY__C_IHD | J2: I_CVD_PRIMARY__C_SHARED | K2: shared-count-once | L2: 1 | M2: Hypertension and statin coverage follow the same cascade
A3: I_CVD_PRIMARY__C_IS | B3: I_CVD_PRIMARY | C3: Primary prevention of CVD | D3: C_IS | E3: Ischemic stroke | F3: Ischemic stroke | G3: well | H3: sick | I3: I_CVD_PRIMARY__C_IS | J3: I_CVD_PRIMARY__C_SHARED | K3: shared-count-once | L3: 1 | M3: Hypertension and statin coverage follow the same cascade
A4: I_CVD_PRIMARY__C_ICH | B4: I_CVD_PRIMARY | C4: Primary prevention of CVD | D4: C_ICH | E4: Intracerebral hemorrhage | F4: Intracerebral hemorrhage | G4: well | H4: sick | I4: I_CVD_PRIMARY__C_ICH | J4: I_CVD_PRIMARY__C_SHARED | K4: shared-count-once | L4: 1 | M4: Hypertension and statin coverage follow the same cascade
A5: I_CVD_PRIMARY__C_HHD | B5: I_CVD_PRIMARY | C5: Primary prevention of CVD | D5: C_HHD | E5: Hypertensive heart disease | F5: Hypertensive heart disease | G5: well | H5: sick | I5: I_CVD_PRIMARY__C_HHD | J5: I_CVD_PRIMARY__C_SHARED | K5: shared-count-once | L5: 1 | M5: Hypertension coverage drives this link
A6: I_T2D_TREATMENT__C_T2D | B6: I_T2D_TREATMENT | C6: Longitudinal treatment of type 2 diabetes | D6: C_T2D | E6: Diabetes mellitus type 2 | F6: Type 2 diabetes | G6: sick | H6: dead_t2d | I6: I_T2D_TREATMENT__C_T2D | J6: I_T2D_TREATMENT__C_T2D | K6: cause-specific | L6: 1 | M6: Direct diabetes mortality effect
A7: I_T2D_TREATMENT__C_IHD | B7: I_T2D_TREATMENT | C7: Longitudinal treatment of type 2 diabetes | D7: C_IHD | E7: IHD attributable to high blood glucose | F7: Ischemic heart disease | G7: sick | H7: dead_ihd | I7: I_T2D_TREATMENT__C_IHD | J7: I_T2D_TREATMENT__C_T2D | K7: shared-count-once | L7: 1 | M7: Count diabetes treatment cost once

Sheet Effect_Sizes
A1: effect_id | B1: intervention_cause_key | C1: intervention_id | D1: cause_id | E1: intervention_name | F1: cause_name | G1: transition_from | H1: transition_to | I1: effect_measure | J1: effect_value | K1: affected_fraction | L1: age_start | M1: age_stop | N1: sex | O1: source_file | P1: source_row | Q1: review_status | R1: notes | S1: map_match_count | T1: qa_status
A2: E_PRIMARY_IHD | B2: I_CVD_PRIMARY__C_IHD | C2: I_CVD_PRIMARY | D2: C_IHD | E2: Primary prevention of CVD | F2: Ischemic heart disease | G2: well | H2: sick | I2: relative_risk_reduction | J2: 0.58 | K2: 0.8 | L2: 30 | M2: 80 | N2: Both | O2: taxonomy_effect_size.xlsx | P2: Sheet 1, row 136 | Q2: Provisional | R2: Average Fair Choices hypertension/statin effect | S2: =COUNTIF(Intervention_Cause_Map!$A$2:$A$7,B2) -> 1 | T2: =IF(S2<>1,"BAD KEY",IF(OR(J2<0,J2>1,K2<0,K2>1),"BAD VALUE","OK")) -> OK
A3: E_PRIMARY_IS | B3: I_CVD_PRIMARY__C_IS | C3: I_CVD_PRIMARY | D3: C_IS | E3: Primary prevention of CVD | F3: Ischemic stroke | G3: well | H3: sick | I3: relative_risk_reduction | J3: 0.54 | K3: 0.8 | L3: 30 | M3: 80 | N3: Both | O3: taxonomy_effect_size.xlsx | P3: Sheet 1, row 133 | Q3: Provisional | R3: Average Fair Choices hypertension/statin effect | S3: =COUNTIF(Intervention_Cause_Map!$A$2:$A$7,B3) -> 1 | T3: =IF(S3<>1,"BAD KEY",IF(OR(J3<0,J3>1,K3<0,K3>1),"BAD VALUE","OK")) -> OK
A4: E_PRIMARY_ICH | B4: I_CVD_PRIMARY__C_ICH | C4: I_CVD_PRIMARY | D4: C_ICH | E4: Primary prevention of CVD | F4: Intracerebral hemorrhage | G4: well | H4: sick | I4: relative_risk_reduction | J4: 0.49 | K4: 0.8 | L4: 30 | M4: 80 | N4: Both | O4: taxonomy_effect_size.xlsx | P4: Sheet 1, row 134 | Q4: Provisional | R4: Average Fair Choices hypertension/statin effect | S4: =COUNTIF(Intervention_Cause_Map!$A$2:$A$7,B4) -> 1 | T4: =IF(S4<>1,"BAD KEY",IF(OR(J4<0,J4>1,K4<0,K4>1),"BAD VALUE","OK")) -> OK
A5: E_PRIMARY_HHD | B5: I_CVD_PRIMARY__C_HHD | C5: I_CVD_PRIMARY | D5: C_HHD | E5: Primary prevention of CVD | F5: Hypertensive heart disease | G5: well | H5: sick | I5: relative_risk_reduction | J5: 0.47 | K5: 1 | L5: 30 | M5: 80 | N5: Both | O5: taxonomy_effect_size.xlsx | P5: Sheet 1, row 135 | Q5: Provisional | R5: Average Fair Choices hypertension/statin effect | S5: =COUNTIF(Intervention_Cause_Map!$A$2:$A$7,B5) -> 1 | T5: =IF(S5<>1,"BAD KEY",IF(OR(J5<0,J5>1,K5<0,K5>1),"BAD VALUE","OK")) -> OK
A6: E_T2D_DIRECT | B6: I_T2D_TREATMENT__C_T2D | C6: I_T2D_TREATMENT | D6: C_T2D | E6: Longitudinal treatment of type 2 diabetes | F6: Diabetes mellitus type 2 | G6: sick | H6: dead_t2d | I6: relative_risk_reduction | J6: 0.28 | K6: 1 | L6: 0 | M6: 95 | N6: Both | O6: taxonomy_effect_size.xlsx | P6: Sheet 1, row 173 | Q6: Provisional | R6: Direct diabetes mortality effect | S6: =COUNTIF(Intervention_Cause_Map!$A$2:$A$7,B6) -> 1 | T6: =IF(S6<>1,"BAD KEY",IF(OR(J6<0,J6>1,K6<0,K6>1),"BAD VALUE","OK")) -> OK
A7: E_T2D_IHD_HBG | B7: I_T2D_TREATMENT__C_IHD | C7: I_T2D_TREATMENT | D7: C_IHD | E7: Longitudinal treatment of type 2 diabetes | F7: IHD attributable to high blood glucose | G7: sick | H7: dead_ihd | I7: relative_risk_reduction | J7: 0.15 | K7: 0.15 | L7: 0 | M7: 95 | N7: Both | O7: taxonomy_effect_size.xlsx | P7: Sheet 1, row 174 | Q7: Review | R7: Confirm attributable-fraction implementation | S7: =COUNTIF(Intervention_Cause_Map!$A$2:$A$7,B7) -> 1 | T7: =IF(S7<>1,"BAD KEY",IF(OR(J7<0,J7>1,K7<0,K7>1),"BAD VALUE","OK")) -> OK

Sheet Coverage
A1: coverage_id | B1: risk_factor_id | C1: risk_factor_name | D1: sex | E1: milestone | F1: year | G1: diagnosis_step | H1: treatment_step_conditional | I1: control_step_conditional | J1: diagnosed_share_all_condition | K1: treated_share_all_condition | L1: controlled_share_all_condition | M1: treated_uncontrolled_share | N1: partial_effect_fraction | O1: exact_effective_coverage | P1: policy_effective_coverage_override | Q1: model_effective_coverage | R1: source | S1: assumption_note | T1: qa_status
A2: CVG_RF_HTN_Men_BASE | B2: RF_HTN | C2: Hypertension | D2: Men | E2: Baseline | F2: 2025 | G2: =Raw_NCDRisC!H2 -> 0.29011104 | H2: =Raw_NCDRisC!I2/Raw_NCDRisC!H2 -> 0.53038727 | I2: =Raw_NCDRisC!J2/Raw_NCDRisC!I2 -> 0.23288796 | J2: =G2 -> 0.29011104 | K2: =G2*H2 -> 0.1538712 | L2: =K2*I2 -> 0.035834751 | M2: =K2-L2 -> 0.11803645 | N2: =Assumptions!$B$11 -> 0.5 | O2: =L2+N2*M2 -> 0.094852977 | Q2: =IF(P2="",O2,P2) -> 0.094852977 | R2: NCD-RisC 2019 hypertension cascade | S2: Observed diagnosed, treated, and controlled shares. | T2: =IF(OR(G2<0,G2>1,H2<0,H2>1,I2<0,I2>1,Q2<0,Q2>1),"BAD","OK") -> OK
A3: CVG_RF_HTN_Men_2030 | B3: RF_HTN | C3: Hypertension | D3: Men | E3: 70-30-30 | F3: 2030 | G3: =Assumptions!$B$6 -> 0.7 | H3: =Assumptions!$B$7 -> 0.3 | I3: =Assumptions!$B$8 -> 0.3 | J3: =G3 -> 0.7 | K3: =G3*H3 -> 0.21 | L3: =K3*I3 -> 0.063 | M3: =K3-L3 -> 0.147 | N3: =Assumptions!$B$11 -> 0.5 | O3: =L3+N3*M3 -> 0.1365 | Q3: =O3 -> 0.1365 | R3: World Bank/UW policy target | S3: Exact cascade arithmetic is used without a rounded override. | T3: =IF(OR(G3<0,G3>1,H3<0,H3>1,I3<0,I3>1,Q3<0,Q3>1),"BAD","OK") -> OK
A4: CVG_RF_HTN_Men_2040 | B4: RF_HTN | C4: Hypertension | D4: Men | E4: 70-70-70 | F4: 2040 | G4: =Assumptions!$B$6 -> 0.7 | H4: =Assumptions!$B$9 -> 0.7 | I4: =Assumptions!$B$10 -> 0.7 | J4: =G4 -> 0.7 | K4: =G4*H4 -> 0.49 | L4: =K4*I4 -> 0.343 | M4: =K4-L4 -> 0.147 | N4: =Assumptions!$B$11 -> 0.5 | O4: =L4+N4*M4 -> 0.4165 | Q4: =O4 -> 0.4165 | R4: World Bank/UW policy target | S4: Exact cascade arithmetic is used without a rounded override. | T4: =IF(OR(G4<0,G4>1,H4<0,H4>1,I4<0,I4>1,Q4<0,Q4>1),"BAD","OK") -> OK
A5: CVG_RF_HTN_Women_BASE | B5: RF_HTN | C5: Hypertension | D5: Women | E5: Baseline | F5: 2025 | G5: =Raw_NCDRisC!H3 -> 0.40958943 | H5: =Raw_NCDRisC!I3/Raw_NCDRisC!H3 -> 0.52283352 | I5: =Raw_NCDRisC!J3/Raw_NCDRisC!I3 -> 0.23915523 | J5: =G5 -> 0.40958943 | K5: =G5*H5 -> 0.21414708 | L5: =K5*I5 -> 0.051214394 | M5: =K5-L5 -> 0.16293269 | N5: =Assumptions!$B$11 -> 0.5 | O5: =L5+N5*M5 -> 0.13268074 | Q5: =IF(P5="",O5,P5) -> 0.13268074 | R5: NCD-RisC 2019 hypertension cascade | S5: Observed diagnosed, treated, and controlled shares. | T5: =IF(OR(G5<0,G5>1,H5<0,H5>1,I5<0,I5>1,Q5<0,Q5>1),"BAD","OK") -> OK
A6: CVG_RF_HTN_Women_2030 | B6: RF_HTN | C6: Hypertension | D6: Women | E6: 70-30-30 | F6: 2030 | G6: =Assumptions!$B$6 -> 0.7 | H6: =Assumptions!$B$7 -> 0.3 | I6: =Assumptions!$B$8 -> 0.3 | J6: =G6 -> 0.7 | K6: =G6*H6 -> 0.21 | L6: =K6*I6 -> 0.063 | M6: =K6-L6 -> 0.147 | N6: =Assumptions!$B$11 -> 0.5 | O6: =L6+N6*M6 -> 0.1365 | Q6: =O6 -> 0.1365 | R6: World Bank/UW policy target | S6: Exact cascade arithmetic is used without a rounded override. | T6: =IF(OR(G6<0,G6>1,H6<0,H6>1,I6<0,I6>1,Q6<0,Q6>1),"BAD","OK") -> OK
A7: CVG_RF_HTN_Women_2040 | B7: RF_HTN | C7: Hypertension | D7: Women | E7: 70-70-70 | F7: 2040 | G7: =Assumptions!$B$6 -> 0.7 | H7: =Assumptions!$B$9 -> 0.7 | I7: =Assumptions!$B$10 -> 0.7 | J7: =G7 -> 0.7 | K7: =G7*H7 -> 0.49 | L7: =K7*I7 -> 0.343 | M7: =K7-L7 -> 0.147 | N7: =Assumptions!$B$11 -> 0.5 | O7: =L7+N7*M7 -> 0.4165 | Q7: =O7 -> 0.4165 | R7: World Bank/UW policy target | S7: Exact cascade arithmetic is used without a rounded override. | T7: =IF(OR(G7<0,G7>1,H7<0,H7>1,I7<0,I7>1,Q7<0,Q7>1),"BAD","OK") -> OK
A8: CVG_RF_T2D_Men_BASE | B8: RF_T2D | C8: Type 2 diabetes | D8: Men | E8: Baseline | F8: 2025 | G8: =Assumptions!$B$15 -> 1 | H8: =Raw_NCDRisC!I4 -> 0.19418973 | I8: =Assumptions!$B$14 -> 0.34210526 | J8: =G8 -> 1 | K8: =G8*H8 -> 0.19418973 | L8: =K8*I8 -> 0.066433328 | M8: =K8-L8 -> 0.1277564 | N8: =Assumptions!$B$11 -> 0.5 | O8: =L8+N8*M8 -> 0.13031153 | Q8: =IF(P8="",O8,P8) -> 0.13031153 | R8: NCD-RisC 2022 diabetes treatment | S8: Control among treated is the editable national baseline in Assumptions; NCD-RisC supplies treatment. | T8: =IF(OR(G8<0,G8>1,H8<0,H8>1,I8<0,I8>1,Q8<0,Q8>1),"BAD","OK") -> OK
A9: CVG_RF_T2D_Men_2030 | B9: RF_T2D | C9: Type 2 diabetes | D9: Men | E9: 70-30-30 | F9: 2030 | G9: =Assumptions!$B$6 -> 0.7 | H9: =Assumptions!$B$7 -> 0.3 | I9: =Assumptions!$B$8 -> 0.3 | J9: =G9 -> 0.7 | K9: =G9*H9 -> 0.21 | L9: =K9*I9 -> 0.063 | M9: =K9-L9 -> 0.147 | N9: =Assumptions!$B$11 -> 0.5 | O9: =L9+N9*M9 -> 0.1365 | Q9: =O9 -> 0.1365 | R9: World Bank/UW policy target | S9: Exact cascade arithmetic is used without a rounded override. | T9: =IF(OR(G9<0,G9>1,H9<0,H9>1,I9<0,I9>1,Q9<0,Q9>1),"BAD","OK") -> OK
A10: CVG_RF_T2D_Men_2040 | B10: RF_T2D | C10: Type 2 diabetes | D10: Men | E10: 70-70-70 | F10: 2040 | G10: =Assumptions!$B$6 -> 0.7 | H10: =Assumptions!$B$9 -> 0.7 | I10: =Assumptions!$B$10 -> 0.7 | J10: =G10 -> 0.7 | K10: =G10*H10 -> 0.49 | L10: =K10*I10 -> 0.343 | M10: =K10-L10 -> 0.147 | N10: =Assumptions!$B$11 -> 0.5 | O10: =L10+N10*M10 -> 0.4165 | Q10: =O10 -> 0.4165 | R10: World Bank/UW policy target | S10: Exact cascade arithmetic is used without a rounded override. | T10: =IF(OR(G10<0,G10>1,H10<0,H10>1,I10<0,I10>1,Q10<0,Q10>1),"BAD","OK") -> OK
A11: CVG_RF_T2D_Women_BASE | B11: RF_T2D | C11: Type 2 diabetes | D11: Women | E11: Baseline | F11: 2025 | G11: =Assumptions!$B$15 -> 1 | H11: =Raw_NCDRisC!I5 -> 0.24665382 | I11: =Assumptions!$B$14 -> 0.34210526 | J11: =G11 -> 1 | K11: =G11*H11 -> 0.24665382 | L11: =K11*I11 -> 0.084381571 | M11: =K11-L11 -> 0.16227225 | N11: =Assumptions!$B$11 -> 0.5 | O11: =L11+N11*M11 -> 0.1655177 | Q11: =IF(P11="",O11,P11) -> 0.1655177 | R11: NCD-RisC 2022 diabetes treatment | S11: Control among treated is the editable national baseline in Assumptions; NCD-RisC supplies treatment. | T11: =IF(OR(G11<0,G11>1,H11<0,H11>1,I11<0,I11>1,Q11<0,Q11>1),"BAD","OK") -> OK
A12: CVG_RF_T2D_Women_2030 | B12: RF_T2D | C12: Type 2 diabetes | D12: Women | E12: 70-30-30 | F12: 2030 | G12: =Assumptions!$B$6 -> 0.7 | H12: =Assumptions!$B$7 -> 0.3 | I12: =Assumptions!$B$8 -> 0.3 | J12: =G12 -> 0.7 | K12: =G12*H12 -> 0.21 | L12: =K12*I12 -> 0.063 | M12: =K12-L12 -> 0.147 | N12: =Assumptions!$B$11 -> 0.5 | O12: =L12+N12*M12 -> 0.1365 | Q12: =O12 -> 0.1365 | R12: World Bank/UW policy target | S12: Exact cascade arithmetic is used without a rounded override. | T12: =IF(OR(G12<0,G12>1,H12<0,H12>1,I12<0,I12>1,Q12<0,Q12>1),"BAD","OK") -> OK
A13: CVG_RF_T2D_Women_2040 | B13: RF_T2D | C13: Type 2 diabetes | D13: Women | E13: 70-70-70 | F13: 2040 | G13: =Assumptions!$B$6 -> 0.7 | H13: =Assumptions!$B$9 -> 0.7 | I13: =Assumptions!$B$10 -> 0.7 | J13: =G13 -> 0.7 | K13: =G13*H13 -> 0.49 | L13: =K13*I13 -> 0.343 | M13: =K13-L13 -> 0.147 | N13: =Assumptions!$B$11 -> 0.5 | O13: =L13+N13*M13 -> 0.4165 | Q13: =O13 -> 0.4165 | R13: World Bank/UW policy target | S13: Exact cascade arithmetic is used without a rounded override. | T13: =IF(OR(G13<0,G13>1,H13<0,H13>1,I13<0,I13>1,Q13<0,Q13>1),"BAD","OK") -> OK
A14: CVG_RF_CHOL_Men_BASE | B14: RF_CHOL | C14: Cholesterol | D14: Men | E14: Baseline | F14: 2025 | G14: =G2 -> 0.29011104 | H14: =H2 -> 0.53038727 | I14: =I2 -> 0.23288796 | J14: =G14 -> 0.29011104 | K14: =G14*H14 -> 0.1538712 | L14: =K14*I14 -> 0.035834751 | M14: =K14-L14 -> 0.11803645 | N14: =Assumptions!$B$11 -> 0.5 | O14: =L14+N14*M14 -> 0.094852977 | Q14: =IF(P14="",O14,P14) -> 0.094852977 | R14: Proxy from hypertension coverage | S14: Cholesterol treatment coverage follows hypertension coverage. | T14: =IF(OR(G14<0,G14>1,H14<0,H14>1,I14<0,I14>1,Q14<0,Q14>1),"BAD","OK") -> OK
A15: CVG_RF_CHOL_Men_2030 | B15: RF_CHOL | C15: Cholesterol | D15: Men | E15: 70-30-30 | F15: 2030 | G15: =Assumptions!$B$6 -> 0.7 | H15: =Assumptions!$B$7 -> 0.3 | I15: =Assumptions!$B$8 -> 0.3 | J15: =G15 -> 0.7 | K15: =G15*H15 -> 0.21 | L15: =K15*I15 -> 0.063 | M15: =K15-L15 -> 0.147 | N15: =Assumptions!$B$11 -> 0.5 | O15: =L15+N15*M15 -> 0.1365 | Q15: =O15 -> 0.1365 | R15: World Bank/UW policy target | S15: Exact cascade arithmetic is used without a rounded override. | T15: =IF(OR(G15<0,G15>1,H15<0,H15>1,I15<0,I15>1,Q15<0,Q15>1),"BAD","OK") -> OK
A16: CVG_RF_CHOL_Men_2040 | B16: RF_CHOL | C16: Cholesterol | D16: Men | E16: 70-70-70 | F16: 2040 | G16: =Assumptions!$B$6 -> 0.7 | H16: =Assumptions!$B$9 -> 0.7 | I16: =Assumptions!$B$10 -> 0.7 | J16: =G16 -> 0.7 | K16: =G16*H16 -> 0.49 | L16: =K16*I16 -> 0.343 | M16: =K16-L16 -> 0.147 | N16: =Assumptions!$B$11 -> 0.5 | O16: =L16+N16*M16 -> 0.4165 | Q16: =O16 -> 0.4165 | R16: World Bank/UW policy target | S16: Exact cascade arithmetic is used without a rounded override. | T16: =IF(OR(G16<0,G16>1,H16<0,H16>1,I16<0,I16>1,Q16<0,Q16>1),"BAD","OK") -> OK
A17: CVG_RF_CHOL_Women_BASE | B17: RF_CHOL | C17: Cholesterol | D17: Women | E17: Baseline | F17: 2025 | G17: =G5 -> 0.40958943 | H17: =H5 -> 0.52283352 | I17: =I5 -> 0.23915523 | J17: =G17 -> 0.40958943 | K17: =G17*H17 -> 0.21414708 | L17: =K17*I17 -> 0.051214394 | M17: =K17-L17 -> 0.16293269 | N17: =Assumptions!$B$11 -> 0.5 | O17: =L17+N17*M17 -> 0.13268074 | Q17: =IF(P17="",O17,P17) -> 0.13268074 | R17: Proxy from hypertension coverage | S17: Cholesterol treatment coverage follows hypertension coverage. | T17: =IF(OR(G17<0,G17>1,H17<0,H17>1,I17<0,I17>1,Q17<0,Q17>1),"BAD","OK") -> OK
A18: CVG_RF_CHOL_Women_2030 | B18: RF_CHOL | C18: Cholesterol | D18: Women | E18: 70-30-30 | F18: 2030 | G18: =Assumptions!$B$6 -> 0.7 | H18: =Assumptions!$B$7 -> 0.3 | I18: =Assumptions!$B$8 -> 0.3 | J18: =G18 -> 0.7 | K18: =G18*H18 -> 0.21 | L18: =K18*I18 -> 0.063 | M18: =K18-L18 -> 0.147 | N18: =Assumptions!$B$11 -> 0.5 | O18: =L18+N18*M18 -> 0.1365 | Q18: =O18 -> 0.1365 | R18: World Bank/UW policy target | S18: Exact cascade arithmetic is used without a rounded override. | T18: =IF(OR(G18<0,G18>1,H18<0,H18>1,I18<0,I18>1,Q18<0,Q18>1),"BAD","OK") -> OK
A19: CVG_RF_CHOL_Women_2040 | B19: RF_CHOL | C19: Cholesterol | D19: Women | E19: 70-70-70 | F19: 2040 | G19: =Assumptions!$B$6 -> 0.7 | H19: =Assumptions!$B$9 -> 0.7 | I19: =Assumptions!$B$10 -> 0.7 | J19: =G19 -> 0.7 | K19: =G19*H19 -> 0.49 | L19: =K19*I19 -> 0.343 | M19: =K19-L19 -> 0.147 | N19: =Assumptions!$B$11 -> 0.5 | O19: =L19+N19*M19 -> 0.4165 | Q19: =O19 -> 0.4165 | R19: World Bank/UW policy target | S19: Exact cascade arithmetic is used without a rounded override. | T19: =IF(OR(G19<0,G19>1,H19<0,H19>1,I19<0,I19>1,Q19<0,Q19>1),"BAD","OK") -> OK

Sheet Coverage_Trajectory
A1: trajectory_id | B1: scenario_id | C1: intervention_id | D1: intervention_name | E1: risk_factor_id | F1: sex | G1: year | H1: baseline_effective_coverage | I1: target_2030 | J1: target_2040 | K1: scenario_effective_coverage | L1: status_quo_effective_coverage | M1: annual_change | N1: phase | O1: source_note | P1: qa_status
A2: I_CVD_PRIMARY_Men_2025 | B2: S_70_30_30_TO_70_70_70 | C2: I_CVD_PRIMARY | D2: Primary prevention of CVD | E2: RF_HTN | F2: Men | G2: 2025 | H2: =Coverage!Q2 -> 0.094852977 | I2: =IF(Assumptions!$B$19=1,MAX(H2,Coverage!Q3),Coverage!Q3) -> 0.1365 | J2: =IF(Assumptions!$B$19=1,MAX(H2,Coverage!Q4),Coverage!Q4) -> 0.4165 | K2: =IF(G2<=Assumptions!$B$4,H2+(I2-H2)*(G2-Assumptions!$B$2)/(Assumptions!$B$4-Assumptions!$B$2),IF(G2<=Assumptions!$B$5,I2+(J2-I2)*(G2-Assumptions!$B$4)/(Assumptions!$B$5-Assumptions!$B$4),J2)) -> 0.094852977 | L2: =H2 -> 0.094852977 | M2: 0 | N2: Scale to 70-30-30 | O2: Piecewise linear scale-up; hold after 2040 | P2: =IF(OR(K2<0,K2>1,M2<0),"BAD","OK") -> OK
A3: I_CVD_PRIMARY_Men_2026 | B3: S_70_30_30_TO_70_70_70 | C3: I_CVD_PRIMARY | D3: Primary prevention of CVD | E3: RF_HTN | F3: Men | G3: 2026 | H3: =Coverage!Q2 -> 0.094852977 | I3: =IF(Assumptions!$B$19=1,MAX(H3,Coverage!Q3),Coverage!Q3) -> 0.1365 | J3: =IF(Assumptions!$B$19=1,MAX(H3,Coverage!Q4),Coverage!Q4) -> 0.4165 | K3: =IF(G3<=Assumptions!$B$4,H3+(I3-H3)*(G3-Assumptions!$B$2)/(Assumptions!$B$4-Assumptions!$B$2),IF(G3<=Assumptions!$B$5,I3+(J3-I3)*(G3-Assumptions!$B$4)/(Assumptions!$B$5-Assumptions!$B$4),J3)) -> 0.10318238 | L3: =H3 -> 0.094852977 | M3: =K3-K2 -> 0.0083294046 | N3: Scale to 70-30-30 | O3: Piecewise linear scale-up; hold after 2040 | P3: =IF(OR(K3<0,K3>1,M3<0),"BAD","OK") -> OK
A4: I_CVD_PRIMARY_Men_2027 | B4: S_70_30_30_TO_70_70_70 | C4: I_CVD_PRIMARY | D4: Primary prevention of CVD | E4: RF_HTN | F4: Men | G4: 2027 | H4: =Coverage!Q2 -> 0.094852977 | I4: =IF(Assumptions!$B$19=1,MAX(H4,Coverage!Q3),Coverage!Q3) -> 0.1365 | J4: =IF(Assumptions!$B$19=1,MAX(H4,Coverage!Q4),Coverage!Q4) -> 0.4165 | K4: =IF(G4<=Assumptions!$B$4,H4+(I4-H4)*(G4-Assumptions!$B$2)/(Assumptions!$B$4-Assumptions!$B$2),IF(G4<=Assumptions!$B$5,I4+(J4-I4)*(G4-Assumptions!$B$4)/(Assumptions!$B$5-Assumptions!$B$4),J4)) -> 0.11151179 | L4: =H4 -> 0.094852977 | M4: =K4-K3 -> 0.0083294046 | N4: Scale to 70-30-30 | O4: Piecewise linear scale-up; hold after 2040 | P4: =IF(OR(K4<0,K4>1,M4<0),"BAD","OK") -> OK
A5: I_CVD_PRIMARY_Men_2028 | B5: S_70_30_30_TO_70_70_70 | C5: I_CVD_PRIMARY | D5: Primary prevention of CVD | E5: RF_HTN | F5: Men | G5: 2028 | H5: =Coverage!Q2 -> 0.094852977 | I5: =IF(Assumptions!$B$19=1,MAX(H5,Coverage!Q3),Coverage!Q3) -> 0.1365 | J5: =IF(Assumptions!$B$19=1,MAX(H5,Coverage!Q4),Coverage!Q4) -> 0.4165 | K5: =IF(G5<=Assumptions!$B$4,H5+(I5-H5)*(G5-Assumptions!$B$2)/(Assumptions!$B$4-Assumptions!$B$2),IF(G5<=Assumptions!$B$5,I5+(J5-I5)*(G5-Assumptions!$B$4)/(Assumptions!$B$5-Assumptions!$B$4),J5)) -> 0.11984119 | L5: =H5 -> 0.094852977 | M5: =K5-K4 -> 0.0083294046 | N5: Scale to 70-30-30 | O5: Piecewise linear scale-up; hold after 2040 | P5: =IF(OR(K5<0,K5>1,M5<0),"BAD","OK") -> OK
A6: I_CVD_PRIMARY_Men_2029 | B6: S_70_30_30_TO_70_70_70 | C6: I_CVD_PRIMARY | D6: Primary prevention of CVD | E6: RF_HTN | F6: Men | G6: 2029 | H6: =Coverage!Q2 -> 0.094852977 | I6: =IF(Assumptions!$B$19=1,MAX(H6,Coverage!Q3),Coverage!Q3) -> 0.1365 | J6: =IF(Assumptions!$B$19=1,MAX(H6,Coverage!Q4),Coverage!Q4) -> 0.4165 | K6: =IF(G6<=Assumptions!$B$4,H6+(I6-H6)*(G6-Assumptions!$B$2)/(Assumptions!$B$4-Assumptions!$B$2),IF(G6<=Assumptions!$B$5,I6+(J6-I6)*(G6-Assumptions!$B$4)/(Assumptions!$B$5-Assumptions!$B$4),J6)) -> 0.1281706 | L6: =H6 -> 0.094852977 | M6: =K6-K5 -> 0.0083294046 | N6: Scale to 70-30-30 | O6: Piecewise linear scale-up; hold after 2040 | P6: =IF(OR(K6<0,K6>1,M6<0),"BAD","OK") -> OK
A7: I_CVD_PRIMARY_Men_2030 | B7: S_70_30_30_TO_70_70_70 | C7: I_CVD_PRIMARY | D7: Primary prevention of CVD | E7: RF_HTN | F7: Men | G7: 2030 | H7: =Coverage!Q2 -> 0.094852977 | I7: =IF(Assumptions!$B$19=1,MAX(H7,Coverage!Q3),Coverage!Q3) -> 0.1365 | J7: =IF(Assumptions!$B$19=1,MAX(H7,Coverage!Q4),Coverage!Q4) -> 0.4165 | K7: =IF(G7<=Assumptions!$B$4,H7+(I7-H7)*(G7-Assumptions!$B$2)/(Assumptions!$B$4-Assumptions!$B$2),IF(G7<=Assumptions!$B$5,I7+(J7-I7)*(G7-Assumptions!$B$4)/(Assumptions!$B$5-Assumptions!$B$4),J7)) -> 0.1365 | L7: =H7 -> 0.094852977 | M7: =K7-K6 -> 0.0083294046 | N7: Scale to 70-30-30 | O7: Piecewise linear scale-up; hold after 2040 | P7: =IF(OR(K7<0,K7>1,M7<0),"BAD","OK") -> OK
A8: I_CVD_PRIMARY_Men_2031 | B8: S_70_30_30_TO_70_70_70 | C8: I_CVD_PRIMARY | D8: Primary prevention of CVD | E8: RF_HTN | F8: Men | G8: 2031 | H8: =Coverage!Q2 -> 0.094852977 | I8: =IF(Assumptions!$B$19=1,MAX(H8,Coverage!Q3),Coverage!Q3) -> 0.1365 | J8: =IF(Assumptions!$B$19=1,MAX(H8,Coverage!Q4),Coverage!Q4) -> 0.4165 | K8: =IF(G8<=Assumptions!$B$4,H8+(I8-H8)*(G8-Assumptions!$B$2)/(Assumptions!$B$4-Assumptions!$B$2),IF(G8<=Assumptions!$B$5,I8+(J8-I8)*(G8-Assumptions!$B$4)/(Assumptions!$B$5-Assumptions!$B$4),J8)) -> 0.1645 | L8: =H8 -> 0.094852977 | M8: =K8-K7 -> 0.028 | N8: Scale to 70-70-70 | O8: Piecewise linear scale-up; hold after 2040 | P8: =IF(OR(K8<0,K8>1,M8<0),"BAD","OK") -> OK
A9: I_CVD_PRIMARY_Men_2032 | B9: S_70_30_30_TO_70_70_70 | C9: I_CVD_PRIMARY | D9: Primary prevention of CVD | E9: RF_HTN | F9: Men | G9: 2032 | H9: =Coverage!Q2 -> 0.094852977 | I9: =IF(Assumptions!$B$19=1,MAX(H9,Coverage!Q3),Coverage!Q3) -> 0.1365 | J9: =IF(Assumptions!$B$19=1,MAX(H9,Coverage!Q4),Coverage!Q4) -> 0.4165 | K9: =IF(G9<=Assumptions!$B$4,H9+(I9-H9)*(G9-Assumptions!$B$2)/(Assumptions!$B$4-Assumptions!$B$2),IF(G9<=Assumptions!$B$5,I9+(J9-I9)*(G9-Assumptions!$B$4)/(Assumptions!$B$5-Assumptions!$B$4),J9)) -> 0.1925 | L9: =H9 -> 0.094852977 | M9: =K9-K8 -> 0.028 | N9: Scale to 70-70-70 | O9: Piecewise linear scale-up; hold after 2040 | P9: =IF(OR(K9<0,K9>1,M9<0),"BAD","OK") -> OK
A10: I_CVD_PRIMARY_Men_2033 | B10: S_70_30_30_TO_70_70_70 | C10: I_CVD_PRIMARY | D10: Primary prevention of CVD | E10: RF_HTN | F10: Men | G10: 2033 | H10: =Coverage!Q2 -> 0.094852977 | I10: =IF(Assumptions!$B$19=1,MAX(H10,Coverage!Q3),Coverage!Q3) -> 0.1365 | J10: =IF(Assumptions!$B$19=1,MAX(H10,Coverage!Q4),Coverage!Q4) -> 0.4165 | K10: =IF(G10<=Assumptions!$B$4,H10+(I10-H10)*(G10-Assumptions!$B$2)/(Assumptions!$B$4-Assumptions!$B$2),IF(G10<=Assumptions!$B$5,I10+(J10-I10)*(G10-Assumptions!$B$4)/(Assumptions!$B$5-Assumptions!$B$4),J10)) -> 0.2205 | L10: =H10 -> 0.094852977 | M10: =K10-K9 -> 0.028 | N10: Scale to 70-70-70 | O10: Piecewise linear scale-up; hold after 2040 | P10: =IF(OR(K10<0,K10>1,M10<0),"BAD","OK") -> OK
A11: I_CVD_PRIMARY_Men_2034 | B11: S_70_30_30_TO_70_70_70 | C11: I_CVD_PRIMARY | D11: Primary prevention of CVD | E11: RF_HTN | F11: Men | G11: 2034 | H11: =Coverage!Q2 -> 0.094852977 | I11: =IF(Assumptions!$B$19=1,MAX(H11,Coverage!Q3),Coverage!Q3) -> 0.1365 | J11: =IF(Assumptions!$B$19=1,MAX(H11,Coverage!Q4),Coverage!Q4) -> 0.4165 | K11: =IF(G11<=Assumptions!$B$4,H11+(I11-H11)*(G11-Assumptions!$B$2)/(Assumptions!$B$4-Assumptions!$B$2),IF(G11<=Assumptions!$B$5,I11+(J11-I11)*(G11-Assumptions!$B$4)/(Assumptions!$B$5-Assumptions!$B$4),J11)) -> 0.2485 | L11: =H11 -> 0.094852977 | M11: =K11-K10 -> 0.028 | N11: Scale to 70-70-70 | O11: Piecewise linear scale-up; hold after 2040 | P11: =IF(OR(K11<0,K11>1,M11<0),"BAD","OK") -> OK
A12: I_CVD_PRIMARY_Men_2035 | B12: S_70_30_30_TO_70_70_70 | C12: I_CVD_PRIMARY | D12: Primary prevention of CVD | E12: RF_HTN | F12: Men | G12: 2035 | H12: =Coverage!Q2 -> 0.094852977 | I12: =IF(Assumptions!$B$19=1,MAX(H12,Coverage!Q3),Coverage!Q3) -> 0.1365 | J12: =IF(Assumptions!$B$19=1,MAX(H12,Coverage!Q4),Coverage!Q4) -> 0.4165 | K12: =IF(G12<=Assumptions!$B$4,H12+(I12-H12)*(G12-Assumptions!$B$2)/(Assumptions!$B$4-Assumptions!$B$2),IF(G12<=Assumptions!$B$5,I12+(J12-I12)*(G12-Assumptions!$B$4)/(Assumptions!$B$5-Assumptions!$B$4),J12)) -> 0.2765 | L12: =H12 -> 0.094852977 | M12: =K12-K11 -> 0.028 | N12: Scale to 70-70-70 | O12: Piecewise linear scale-up; hold after 2040 | P12: =IF(OR(K12<0,K12>1,M12<0),"BAD","OK") -> OK
A13: I_CVD_PRIMARY_Men_2036 | B13: S_70_30_30_TO_70_70_70 | C13: I_CVD_PRIMARY | D13: Primary prevention of CVD | E13: RF_HTN | F13: Men | G13: 2036 | H13: =Coverage!Q2 -> 0.094852977 | I13: =IF(Assumptions!$B$19=1,MAX(H13,Coverage!Q3),Coverage!Q3) -> 0.1365 | J13: =IF(Assumptions!$B$19=1,MAX(H13,Coverage!Q4),Coverage!Q4) -> 0.4165 | K13: =IF(G13<=Assumptions!$B$4,H13+(I13-H13)*(G13-Assumptions!$B$2)/(Assumptions!$B$4-Assumptions!$B$2),IF(G13<=Assumptions!$B$5,I13+(J13-I13)*(G13-Assumptions!$B$4)/(Assumptions!$B$5-Assumptions!$B$4),J13)) -> 0.3045 | L13: =H13 -> 0.094852977 | M13: =K13-K12 -> 0.028 | N13: Scale to 70-70-70 | O13: Piecewise linear scale-up; hold after 2040 | P13: =IF(OR(K13<0,K13>1,M13<0),"BAD","OK") -> OK
A14: I_CVD_PRIMARY_Men_2037 | B14: S_70_30_30_TO_70_70_70 | C14: I_CVD_PRIMARY | D14: Primary prevention of CVD | E14: RF_HTN | F14: Men | G14: 2037 | H14: =Coverage!Q2 -> 0.094852977 | I14: =IF(Assumptions!$B$19=1,MAX(H14,Coverage!Q3),Coverage!Q3) -> 0.1365 | J14: =IF(Assumptions!$B$19=1,MAX(H14,Coverage!Q4),Coverage!Q4) -> 0.4165 | K14: =IF(G14<=Assumptions!$B$4,H14+(I14-H14)*(G14-Assumptions!$B$2)/(Assumptions!$B$4-Assumptions!$B$2),IF(G14<=Assumptions!$B$5,I14+(J14-I14)*(G14-Assumptions!$B$4)/(Assumptions!$B$5-Assumptions!$B$4),J14)) -> 0.3325 | L14: =H14 -> 0.094852977 | M14: =K14-K13 -> 0.028 | N14: Scale to 70-70-70 | O14: Piecewise linear scale-up; hold after 2040 | P14: =IF(OR(K14<0,K14>1,M14<0),"BAD","OK") -> OK
A15: I_CVD_PRIMARY_Men_2038 | B15: S_70_30_30_TO_70_70_70 | C15: I_CVD_PRIMARY | D15: Primary prevention of CVD | E15: RF_HTN | F15: Men | G15: 2038 | H15: =Coverage!Q2 -> 0.094852977 | I15: =IF(Assumptions!$B$19=1,MAX(H15,Coverage!Q3),Coverage!Q3) -> 0.1365 | J15: =IF(Assumptions!$B$19=1,MAX(H15,Coverage!Q4),Coverage!Q4) -> 0.4165 | K15: =IF(G15<=Assumptions!$B$4,H15+(I15-H15)*(G15-Assumptions!$B$2)/(Assumptions!$B$4-Assumptions!$B$2),IF(G15<=Assumptions!$B$5,I15+(J15-I15)*(G15-Assumptions!$B$4)/(Assumptions!$B$5-Assumptions!$B$4),J15)) -> 0.3605 | L15: =H15 -> 0.094852977 | M15: =K15-K14 -> 0.028 | N15: Scale to 70-70-70 | O15: Piecewise linear scale-up; hold after 2040 | P15: =IF(OR(K15<0,K15>1,M15<0),"BAD","OK") -> OK
A16: I_CVD_PRIMARY_Men_2039 | B16: S_70_30_30_TO_70_70_70 | C16: I_CVD_PRIMARY | D16: Primary prevention of CVD | E16: RF_HTN | F16: Men | G16: 2039 | H16: =Coverage!Q2 -> 0.094852977 | I16: =IF(Assumptions!$B$19=1,MAX(H16,Coverage!Q3),Coverage!Q3) -> 0.1365 | J16: =IF(Assumptions!$B$19=1,MAX(H16,Coverage!Q4),Coverage!Q4) -> 0.4165 | K16: =IF(G16<=Assumptions!$B$4,H16+(I16-H16)*(G16-Assumptions!$B$2)/(Assumptions!$B$4-Assumptions!$B$2),IF(G16<=Assumptions!$B$5,I16+(J16-I16)*(G16-Assumptions!$B$4)/(Assumptions!$B$5-Assumptions!$B$4),J16)) -> 0.3885 | L16: =H16 -> 0.094852977 | M16: =K16-K15 -> 0.028 | N16: Scale to 70-70-70 | O16: Piecewise linear scale-up; hold after 2040 | P16: =IF(OR(K16<0,K16>1,M16<0),"BAD","OK") -> OK
A17: I_CVD_PRIMARY_Men_2040 | B17: S_70_30_30_TO_70_70_70 | C17: I_CVD_PRIMARY | D17: Primary prevention of CVD | E17: RF_HTN | F17: Men | G17: 2040 | H17: =Coverage!Q2 -> 0.094852977 | I17: =IF(Assumptions!$B$19=1,MAX(H17,Coverage!Q3),Coverage!Q3) -> 0.1365 | J17: =IF(Assumptions!$B$19=1,MAX(H17,Coverage!Q4),Coverage!Q4) -> 0.4165 | K17: =IF(G17<=Assumptions!$B$4,H17+(I17-H17)*(G17-Assumptions!$B$2)/(Assumptions!$B$4-Assumptions!$B$2),IF(G17<=Assumptions!$B$5,I17+(J17-I17)*(G17-Assumptions!$B$4)/(Assumptions!$B$5-Assumptions!$B$4),J17)) -> 0.4165 | L17: =H17 -> 0.094852977 | M17: =K17-K16 -> 0.028 | N17: Scale to 70-70-70 | O17: Piecewise linear scale-up; hold after 2040 | P17: =IF(OR(K17<0,K17>1,M17<0),"BAD","OK") -> OK
A18: I_CVD_PRIMARY_Men_2041 | B18: S_70_30_30_TO_70_70_70 | C18: I_CVD_PRIMARY | D18: Primary prevention of CVD | E18: RF_HTN | F18: Men | G18: 2041 | H18: =Coverage!Q2 -> 0.094852977 | I18: =IF(Assumptions!$B$19=1,MAX(H18,Coverage!Q3),Coverage!Q3) -> 0.1365 | J18: =IF(Assumptions!$B$19=1,MAX(H18,Coverage!Q4),Coverage!Q4) -> 0.4165 | K18: =IF(G18<=Assumptions!$B$4,H18+(I18-H18)*(G18-Assumptions!$B$2)/(Assumptions!$B$4-Assumptions!$B$2),IF(G18<=Assumptions!$B$5,I18+(J18-I18)*(G18-Assumptions!$B$4)/(Assumptions!$B$5-Assumptions!$B$4),J18)) -> 0.4165 | L18: =H18 -> 0.094852977 | M18: =K18-K17 -> 0 | N18: Maintain 70-70-70 | O18: Piecewise linear scale-up; hold after 2040 | P18: =IF(OR(K18<0,K18>1,M18<0),"BAD","OK") -> OK
A19: I_CVD_PRIMARY_Men_2042 | B19: S_70_30_30_TO_70_70_70 | C19: I_CVD_PRIMARY | D19: Primary prevention of CVD | E19: RF_HTN | F19: Men | G19: 2042 | H19: =Coverage!Q2 -> 0.094852977 | I19: =IF(Assumptions!$B$19=1,MAX(H19,Coverage!Q3),Coverage!Q3) -> 0.1365 | J19: =IF(Assumptions!$B$19=1,MAX(H19,Coverage!Q4),Coverage!Q4) -> 0.4165 | K19: =IF(G19<=Assumptions!$B$4,H19+(I19-H19)*(G19-Assumptions!$B$2)/(Assumptions!$B$4-Assumptions!$B$2),IF(G19<=Assumptions!$B$5,I19+(J19-I19)*(G19-Assumptions!$B$4)/(Assumptions!$B$5-Assumptions!$B$4),J19)) -> 0.4165 | L19: =H19 -> 0.094852977 | M19: =K19-K18 -> 0 | N19: Maintain 70-70-70 | O19: Piecewise linear scale-up; hold after 2040 | P19: =IF(OR(K19<0,K19>1,M19<0),"BAD","OK") -> OK
A20: I_CVD_PRIMARY_Men_2043 | B20: S_70_30_30_TO_70_70_70 | C20: I_CVD_PRIMARY | D20: Primary prevention of CVD | E20: RF_HTN | F20: Men | G20: 2043 | H20: =Coverage!Q2 -> 0.094852977 | I20: =IF(Assumptions!$B$19=1,MAX(H20,Coverage!Q3),Coverage!Q3) -> 0.1365 | J20: =IF(Assumptions!$B$19=1,MAX(H20,Coverage!Q4),Coverage!Q4) -> 0.4165 | K20: =IF(G20<=Assumptions!$B$4,H20+(I20-H20)*(G20-Assumptions!$B$2)/(Assumptions!$B$4-Assumptions!$B$2),IF(G20<=Assumptions!$B$5,I20+(J20-I20)*(G20-Assumptions!$B$4)/(Assumptions!$B$5-Assumptions!$B$4),J20)) -> 0.4165 | L20: =H20 -> 0.094852977 | M20: =K20-K19 -> 0 | N20: Maintain 70-70-70 | O20: Piecewise linear scale-up; hold after 2040 | P20: =IF(OR(K20<0,K20>1,M20<0),"BAD","OK") -> OK
A21: I_CVD_PRIMARY_Men_2044 | B21: S_70_30_30_TO_70_70_70 | C21: I_CVD_PRIMARY | D21: Primary prevention of CVD | E21: RF_HTN | F21: Men | G21: 2044 | H21: =Coverage!Q2 -> 0.094852977 | I21: =IF(Assumptions!$B$19=1,MAX(H21,Coverage!Q3),Coverage!Q3) -> 0.1365 | J21: =IF(Assumptions!$B$19=1,MAX(H21,Coverage!Q4),Coverage!Q4) -> 0.4165 | K21: =IF(G21<=Assumptions!$B$4,H21+(I21-H21)*(G21-Assumptions!$B$2)/(Assumptions!$B$4-Assumptions!$B$2),IF(G21<=Assumptions!$B$5,I21+(J21-I21)*(G21-Assumptions!$B$4)/(Assumptions!$B$5-Assumptions!$B$4),J21)) -> 0.4165 | L21: =H21 -> 0.094852977 | M21: =K21-K20 -> 0 | N21: Maintain 70-70-70 | O21: Piecewise linear scale-up; hold after 2040 | P21: =IF(OR(K21<0,K21>1,M21<0),"BAD","OK") -> OK
A22: I_CVD_PRIMARY_Men_2045 | B22: S_70_30_30_TO_70_70_70 | C22: I_CVD_PRIMARY | D22: Primary prevention of CVD | E22: RF_HTN | F22: Men | G22: 2045 | H22: =Coverage!Q2 -> 0.094852977 | I22: =IF(Assumptions!$B$19=1,MAX(H22,Coverage!Q3),Coverage!Q3) -> 0.1365 | J22: =IF(Assumptions!$B$19=1,MAX(H22,Coverage!Q4),Coverage!Q4) -> 0.4165 | K22: =IF(G22<=Assumptions!$B$4,H22+(I22-H22)*(G22-Assumptions!$B$2)/(Assumptions!$B$4-Assumptions!$B$2),IF(G22<=Assumptions!$B$5,I22+(J22-I22)*(G22-Assumptions!$B$4)/(Assumptions!$B$5-Assumptions!$B$4),J22)) -> 0.4165 | L22: =H22 -> 0.094852977 | M22: =K22-K21 -> 0 | N22: Maintain 70-70-70 | O22: Piecewise linear scale-up; hold after 2040 | P22: =IF(OR(K22<0,K22>1,M22<0),"BAD","OK") -> OK
A23: I_CVD_PRIMARY_Men_2046 | B23: S_70_30_30_TO_70_70_70 | C23: I_CVD_PRIMARY | D23: Primary prevention of CVD | E23: RF_HTN | F23: Men | G23: 2046 | H23: =Coverage!Q2 -> 0.094852977 | I23: =IF(Assumptions!$B$19=1,MAX(H23,Coverage!Q3),Coverage!Q3) -> 0.1365 | J23: =IF(Assumptions!$B$19=1,MAX(H23,Coverage!Q4),Coverage!Q4) -> 0.4165 | K23: =IF(G23<=Assumptions!$B$4,H23+(I23-H23)*(G23-Assumptions!$B$2)/(Assumptions!$B$4-Assumptions!$B$2),IF(G23<=Assumptions!$B$5,I23+(J23-I23)*(G23-Assumptions!$B$4)/(Assumptions!$B$5-Assumptions!$B$4),J23)) -> 0.4165 | L23: =H23 -> 0.094852977 | M23: =K23-K22 -> 0 | N23: Maintain 70-70-70 | O23: Piecewise linear scale-up; hold after 2040 | P23: =IF(OR(K23<0,K23>1,M23<0),"BAD","OK") -> OK
A24: I_CVD_PRIMARY_Men_2047 | B24: S_70_30_30_TO_70_70_70 | C24: I_CVD_PRIMARY | D24: Primary prevention of CVD | E24: RF_HTN | F24: Men | G24: 2047 | H24: =Coverage!Q2 -> 0.094852977 | I24: =IF(Assumptions!$B$19=1,MAX(H24,Coverage!Q3),Coverage!Q3) -> 0.1365 | J24: =IF(Assumptions!$B$19=1,MAX(H24,Coverage!Q4),Coverage!Q4) -> 0.4165 | K24: =IF(G24<=Assumptions!$B$4,H24+(I24-H24)*(G24-Assumptions!$B$2)/(Assumptions!$B$4-Assumptions!$B$2),IF(G24<=Assumptions!$B$5,I24+(J24-I24)*(G24-Assumptions!$B$4)/(Assumptions!$B$5-Assumptions!$B$4),J24)) -> 0.4165 | L24: =H24 -> 0.094852977 | M24: =K24-K23 -> 0 | N24: Maintain 70-70-70 | O24: Piecewise linear scale-up; hold after 2040 | P24: =IF(OR(K24<0,K24>1,M24<0),"BAD","OK") -> OK
A25: I_CVD_PRIMARY_Men_2048 | B25: S_70_30_30_TO_70_70_70 | C25: I_CVD_PRIMARY | D25: Primary prevention of CVD | E25: RF_HTN | F25: Men | G25: 2048 | H25: =Coverage!Q2 -> 0.094852977 | I25: =IF(Assumptions!$B$19=1,MAX(H25,Coverage!Q3),Coverage!Q3) -> 0.1365 | J25: =IF(Assumptions!$B$19=1,MAX(H25,Coverage!Q4),Coverage!Q4) -> 0.4165 | K25: =IF(G25<=Assumptions!$B$4,H25+(I25-H25)*(G25-Assumptions!$B$2)/(Assumptions!$B$4-Assumptions!$B$2),IF(G25<=Assumptions!$B$5,I25+(J25-I25)*(G25-Assumptions!$B$4)/(Assumptions!$B$5-Assumptions!$B$4),J25)) -> 0.4165 | L25: =H25 -> 0.094852977 | M25: =K25-K24 -> 0 | N25: Maintain 70-70-70 | O25: Piecewise linear scale-up; hold after 2040 | P25: =IF(OR(K25<0,K25>1,M25<0),"BAD","OK") -> OK
A26: I_CVD_PRIMARY_Men_2049 | B26: S_70_30_30_TO_70_70_70 | C26: I_CVD_PRIMARY | D26: Primary prevention of CVD | E26: RF_HTN | F26: Men | G26: 2049 | H26: =Coverage!Q2 -> 0.094852977 | I26: =IF(Assumptions!$B$19=1,MAX(H26,Coverage!Q3),Coverage!Q3) -> 0.1365 | J26: =IF(Assumptions!$B$19=1,MAX(H26,Coverage!Q4),Coverage!Q4) -> 0.4165 | K26: =IF(G26<=Assumptions!$B$4,H26+(I26-H26)*(G26-Assumptions!$B$2)/(Assumptions!$B$4-Assumptions!$B$2),IF(G26<=Assumptions!$B$5,I26+(J26-I26)*(G26-Assumptions!$B$4)/(Assumptions!$B$5-Assumptions!$B$4),J26)) -> 0.4165 | L26: =H26 -> 0.094852977 | M26: =K26-K25 -> 0 | N26: Maintain 70-70-70 | O26: Piecewise linear scale-up; hold after 2040 | P26: =IF(OR(K26<0,K26>1,M26<0),"BAD","OK") -> OK
A27: I_CVD_PRIMARY_Men_2050 | B27: S_70_30_30_TO_70_70_70 | C27: I_CVD_PRIMARY | D27: Primary prevention of CVD | E27: RF_HTN | F27: Men | G27: 2050 | H27: =Coverage!Q2 -> 0.094852977 | I27: =IF(Assumptions!$B$19=1,MAX(H27,Coverage!Q3),Coverage!Q3) -> 0.1365 | J27: =IF(Assumptions!$B$19=1,MAX(H27,Coverage!Q4),Coverage!Q4) -> 0.4165 | K27: =IF(G27<=Assumptions!$B$4,H27+(I27-H27)*(G27-Assumptions!$B$2)/(Assumptions!$B$4-Assumptions!$B$2),IF(G27<=Assumptions!$B$5,I27+(J27-I27)*(G27-Assumptions!$B$4)/(Assumptions!$B$5-Assumptions!$B$4),J27)) -> 0.4165 | L27: =H27 -> 0.094852977 | M27: =K27-K26 -> 0 | N27: Maintain 70-70-70 | O27: Piecewise linear scale-up; hold after 2040 | P27: =IF(OR(K27<0,K27>1,M27<0),"BAD","OK") -> OK
A28: I_CVD_PRIMARY_Women_2025 | B28: S_70_30_30_TO_70_70_70 | C28: I_CVD_PRIMARY | D28: Primary prevention of CVD | E28: RF_HTN | F28: Women | G28: 2025 | H28: =Coverage!Q5 -> 0.13268074 | I28: =IF(Assumptions!$B$19=1,MAX(H28,Coverage!Q6),Coverage!Q6) -> 0.1365 | J28: =IF(Assumptions!$B$19=1,MAX(H28,Coverage!Q7),Coverage!Q7) -> 0.4165 | K28: =IF(G28<=Assumptions!$B$4,H28+(I28-H28)*(G28-Assumptions!$B$2)/(Assumptions!$B$4-Assumptions!$B$2),IF(G28<=Assumptions!$B$5,I28+(J28-I28)*(G28-Assumptions!$B$4)/(Assumptions!$B$5-Assumptions!$B$4),J28)) -> 0.13268074 | L28: =H28 -> 0.13268074 | M28: 0 | N28: Scale to 70-30-30 | O28: Piecewise linear scale-up; hold after 2040 | P28: =IF(OR(K28<0,K28>1,M28<0),"BAD","OK") -> OK
A29: I_CVD_PRIMARY_Women_2026 | B29: S_70_30_30_TO_70_70_70 | C29: I_CVD_PRIMARY | D29: Primary prevention of CVD | E29: RF_HTN | F29: Women | G29: 2026 | H29: =Coverage!Q5 -> 0.13268074 | I29: =IF(Assumptions!$B$19=1,MAX(H29,Coverage!Q6),Coverage!Q6) -> 0.1365 | J29: =IF(Assumptions!$B$19=1,MAX(H29,Coverage!Q7),Coverage!Q7) -> 0.4165 | K29: =IF(G29<=Assumptions!$B$4,H29+(I29-H29)*(G29-Assumptions!$B$2)/(Assumptions!$B$4-Assumptions!$B$2),IF(G29<=Assumptions!$B$5,I29+(J29-I29)*(G29-Assumptions!$B$4)/(Assumptions!$B$5-Assumptions!$B$4),J29)) -> 0.13344459 | L29: =H29 -> 0.13268074 | M29: =K29-K28 -> 0.00076385241 | N29: Scale to 70-30-30 | O29: Piecewise linear scale-up; hold after 2040 | P29: =IF(OR(K29<0,K29>1,M29<0),"BAD","OK") -> OK
A30: I_CVD_PRIMARY_Women_2027 | B30: S_70_30_30_TO_70_70_70 | C30: I_CVD_PRIMARY | D30: Primary prevention of CVD | E30: RF_HTN | F30: Women | G30: 2027 | H30: =Coverage!Q5 -> 0.13268074 | I30: =IF(Assumptions!$B$19=1,MAX(H30,Coverage!Q6),Coverage!Q6) -> 0.1365 | J30: =IF(Assumptions!$B$19=1,MAX(H30,Coverage!Q7),Coverage!Q7) -> 0.4165 | K30: =IF(G30<=Assumptions!$B$4,H30+(I30-H30)*(G30-Assumptions!$B$2)/(Assumptions!$B$4-Assumptions!$B$2),IF(G30<=Assumptions!$B$5,I30+(J30-I30)*(G30-Assumptions!$B$4)/(Assumptions!$B$5-Assumptions!$B$4),J30)) -> 0.13420844 | L30: =H30 -> 0.13268074 | M30: =K30-K29 -> 0.00076385241 | N30: Scale to 70-30-30 | O30: Piecewise linear scale-up; hold after 2040 | P30: =IF(OR(K30<0,K30>1,M30<0),"BAD","OK") -> OK
A31: I_CVD_PRIMARY_Women_2028 | B31: S_70_30_30_TO_70_70_70 | C31: I_CVD_PRIMARY | D31: Primary prevention of CVD | E31: RF_HTN | F31: Women | G31: 2028 | H31: =Coverage!Q5 -> 0.13268074 | I31: =IF(Assumptions!$B$19=1,MAX(H31,Coverage!Q6),Coverage!Q6) -> 0.1365 | J31: =IF(Assumptions!$B$19=1,MAX(H31,Coverage!Q7),Coverage!Q7) -> 0.4165 | K31: =IF(G31<=Assumptions!$B$4,H31+(I31-H31)*(G31-Assumptions!$B$2)/(Assumptions!$B$4-Assumptions!$B$2),IF(G31<=Assumptions!$B$5,I31+(J31-I31)*(G31-Assumptions!$B$4)/(Assumptions!$B$5-Assumptions!$B$4),J31)) -> 0.1349723 | L31: =H31 -> 0.13268074 | M31: =K31-K30 -> 0.00076385241 | N31: Scale to 70-30-30 | O31: Piecewise linear scale-up; hold after 2040 | P31: =IF(OR(K31<0,K31>1,M31<0),"BAD","OK") -> OK
A32: I_CVD_PRIMARY_Women_2029 | B32: S_70_30_30_TO_70_70_70 | C32: I_CVD_PRIMARY | D32: Primary prevention of CVD | E32: RF_HTN | F32: Women | G32: 2029 | H32: =Coverage!Q5 -> 0.13268074 | I32: =IF(Assumptions!$B$19=1,MAX(H32,Coverage!Q6),Coverage!Q6) -> 0.1365 | J32: =IF(Assumptions!$B$19=1,MAX(H32,Coverage!Q7),Coverage!Q7) -> 0.4165 | K32: =IF(G32<=Assumptions!$B$4,H32+(I32-H32)*(G32-Assumptions!$B$2)/(Assumptions!$B$4-Assumptions!$B$2),IF(G32<=Assumptions!$B$5,I32+(J32-I32)*(G32-Assumptions!$B$4)/(Assumptions!$B$5-Assumptions!$B$4),J32)) -> 0.13573615 | L32: =H32 -> 0.13268074 | M32: =K32-K31 -> 0.00076385241 | N32: Scale to 70-30-30 | O32: Piecewise linear scale-up; hold after 2040 | P32: =IF(OR(K32<0,K32>1,M32<0),"BAD","OK") -> OK
A33: I_CVD_PRIMARY_Women_2030 | B33: S_70_30_30_TO_70_70_70 | C33: I_CVD_PRIMARY | D33: Primary prevention of CVD | E33: RF_HTN | F33: Women | G33: 2030 | H33: =Coverage!Q5 -> 0.13268074 | I33: =IF(Assumptions!$B$19=1,MAX(H33,Coverage!Q6),Coverage!Q6) -> 0.1365 | J33: =IF(Assumptions!$B$19=1,MAX(H33,Coverage!Q7),Coverage!Q7) -> 0.4165 | K33: =IF(G33<=Assumptions!$B$4,H33+(I33-H33)*(G33-Assumptions!$B$2)/(Assumptions!$B$4-Assumptions!$B$2),IF(G33<=Assumptions!$B$5,I33+(J33-I33)*(G33-Assumptions!$B$4)/(Assumptions!$B$5-Assumptions!$B$4),J33)) -> 0.1365 | L33: =H33 -> 0.13268074 | M33: =K33-K32 -> 0.00076385241 | N33: Scale to 70-30-30 | O33: Piecewise linear scale-up; hold after 2040 | P33: =IF(OR(K33<0,K33>1,M33<0),"BAD","OK") -> OK
A34: I_CVD_PRIMARY_Women_2031 | B34: S_70_30_30_TO_70_70_70 | C34: I_CVD_PRIMARY | D34: Primary prevention of CVD | E34: RF_HTN | F34: Women | G34: 2031 | H34: =Coverage!Q5 -> 0.13268074 | I34: =IF(Assumptions!$B$19=1,MAX(H34,Coverage!Q6),Coverage!Q6) -> 0.1365 | J34: =IF(Assumptions!$B$19=1,MAX(H34,Coverage!Q7),Coverage!Q7) -> 0.4165 | K34: =IF(G34<=Assumptions!$B$4,H34+(I34-H34)*(G34-Assumptions!$B$2)/(Assumptions!$B$4-Assumptions!$B$2),IF(G34<=Assumptions!$B$5,I34+(J34-I34)*(G34-Assumptions!$B$4)/(Assumptions!$B$5-Assumptions!$B$4),J34)) -> 0.1645 | L34: =H34 -> 0.13268074 | M34: =K34-K33 -> 0.028 | N34: Scale to 70-70-70 | O34: Piecewise linear scale-up; hold after 2040 | P34: =IF(OR(K34<0,K34>1,M34<0),"BAD","OK") -> OK
A35: I_CVD_PRIMARY_Women_2032 | B35: S_70_30_30_TO_70_70_70 | C35: I_CVD_PRIMARY | D35: Primary prevention of CVD | E35: RF_HTN | F35: Women | G35: 2032 | H35: =Coverage!Q5 -> 0.13268074 | I35: =IF(Assumptions!$B$19=1,MAX(H35,Coverage!Q6),Coverage!Q6) -> 0.1365 | J35: =IF(Assumptions!$B$19=1,MAX(H35,Coverage!Q7),Coverage!Q7) -> 0.4165 | K35: =IF(G35<=Assumptions!$B$4,H35+(I35-H35)*(G35-Assumptions!$B$2)/(Assumptions!$B$4-Assumptions!$B$2),IF(G35<=Assumptions!$B$5,I35+(J35-I35)*(G35-Assumptions!$B$4)/(Assumptions!$B$5-Assumptions!$B$4),J35)) -> 0.1925 | L35: =H35 -> 0.13268074 | M35: =K35-K34 -> 0.028 | N35: Scale to 70-70-70 | O35: Piecewise linear scale-up; hold after 2040 | P35: =IF(OR(K35<0,K35>1,M35<0),"BAD","OK") -> OK
A36: I_CVD_PRIMARY_Women_2033 | B36: S_70_30_30_TO_70_70_70 | C36: I_CVD_PRIMARY | D36: Primary prevention of CVD | E36: RF_HTN | F36: Women | G36: 2033 | H36: =Coverage!Q5 -> 0.13268074 | I36: =IF(Assumptions!$B$19=1,MAX(H36,Coverage!Q6),Coverage!Q6) -> 0.1365 | J36: =IF(Assumptions!$B$19=1,MAX(H36,Coverage!Q7),Coverage!Q7) -> 0.4165 | K36: =IF(G36<=Assumptions!$B$4,H36+(I36-H36)*(G36-Assumptions!$B$2)/(Assumptions!$B$4-Assumptions!$B$2),IF(G36<=Assumptions!$B$5,I36+(J36-I36)*(G36-Assumptions!$B$4)/(Assumptions!$B$5-Assumptions!$B$4),J36)) -> 0.2205 | L36: =H36 -> 0.13268074 | M36: =K36-K35 -> 0.028 | N36: Scale to 70-70-70 | O36: Piecewise linear scale-up; hold after 2040 | P36: =IF(OR(K36<0,K36>1,M36<0),"BAD","OK") -> OK
A37: I_CVD_PRIMARY_Women_2034 | B37: S_70_30_30_TO_70_70_70 | C37: I_CVD_PRIMARY | D37: Primary prevention of CVD | E37: RF_HTN | F37: Women | G37: 2034 | H37: =Coverage!Q5 -> 0.13268074 | I37: =IF(Assumptions!$B$19=1,MAX(H37,Coverage!Q6),Coverage!Q6) -> 0.1365 | J37: =IF(Assumptions!$B$19=1,MAX(H37,Coverage!Q7),Coverage!Q7) -> 0.4165 | K37: =IF(G37<=Assumptions!$B$4,H37+(I37-H37)*(G37-Assumptions!$B$2)/(Assumptions!$B$4-Assumptions!$B$2),IF(G37<=Assumptions!$B$5,I37+(J37-I37)*(G37-Assumptions!$B$4)/(Assumptions!$B$5-Assumptions!$B$4),J37)) -> 0.2485 | L37: =H37 -> 0.13268074 | M37: =K37-K36 -> 0.028 | N37: Scale to 70-70-70 | O37: Piecewise linear scale-up; hold after 2040 | P37: =IF(OR(K37<0,K37>1,M37<0),"BAD","OK") -> OK
A38: I_CVD_PRIMARY_Women_2035 | B38: S_70_30_30_TO_70_70_70 | C38: I_CVD_PRIMARY | D38: Primary prevention of CVD | E38: RF_HTN | F38: Women | G38: 2035 | H38: =Coverage!Q5 -> 0.13268074 | I38: =IF(Assumptions!$B$19=1,MAX(H38,Coverage!Q6),Coverage!Q6) -> 0.1365 | J38: =IF(Assumptions!$B$19=1,MAX(H38,Coverage!Q7),Coverage!Q7) -> 0.4165 | K38: =IF(G38<=Assumptions!$B$4,H38+(I38-H38)*(G38-Assumptions!$B$2)/(Assumptions!$B$4-Assumptions!$B$2),IF(G38<=Assumptions!$B$5,I38+(J38-I38)*(G38-Assumptions!$B$4)/(Assumptions!$B$5-Assumptions!$B$4),J38)) -> 0.2765 | L38: =H38 -> 0.13268074 | M38: =K38-K37 -> 0.028 | N38: Scale to 70-70-70 | O38: Piecewise linear scale-up; hold after 2040 | P38: =IF(OR(K38<0,K38>1,M38<0),"BAD","OK") -> OK
A39: I_CVD_PRIMARY_Women_2036 | B39: S_70_30_30_TO_70_70_70 | C39: I_CVD_PRIMARY | D39: Primary prevention of CVD | E39: RF_HTN | F39: Women | G39: 2036 | H39: =Coverage!Q5 -> 0.13268074 | I39: =IF(Assumptions!$B$19=1,MAX(H39,Coverage!Q6),Coverage!Q6) -> 0.1365 | J39: =IF(Assumptions!$B$19=1,MAX(H39,Coverage!Q7),Coverage!Q7) -> 0.4165 | K39: =IF(G39<=Assumptions!$B$4,H39+(I39-H39)*(G39-Assumptions!$B$2)/(Assumptions!$B$4-Assumptions!$B$2),IF(G39<=Assumptions!$B$5,I39+(J39-I39)*(G39-Assumptions!$B$4)/(Assumptions!$B$5-Assumptions!$B$4),J39)) -> 0.3045 | L39: =H39 -> 0.13268074 | M39: =K39-K38 -> 0.028 | N39: Scale to 70-70-70 | O39: Piecewise linear scale-up; hold after 2040 | P39: =IF(OR(K39<0,K39>1,M39<0),"BAD","OK") -> OK
A40: I_CVD_PRIMARY_Women_2037 | B40: S_70_30_30_TO_70_70_70 | C40: I_CVD_PRIMARY | D40: Primary prevention of CVD | E40: RF_HTN | F40: Women | G40: 2037 | H40: =Coverage!Q5 -> 0.13268074 | I40: =IF(Assumptions!$B$19=1,MAX(H40,Coverage!Q6),Coverage!Q6) -> 0.1365 | J40: =IF(Assumptions!$B$19=1,MAX(H40,Coverage!Q7),Coverage!Q7) -> 0.4165 | K40: =IF(G40<=Assumptions!$B$4,H40+(I40-H40)*(G40-Assumptions!$B$2)/(Assumptions!$B$4-Assumptions!$B$2),IF(G40<=Assumptions!$B$5,I40+(J40-I40)*(G40-Assumptions!$B$4)/(Assumptions!$B$5-Assumptions!$B$4),J40)) -> 0.3325 | L40: =H40 -> 0.13268074 | M40: =K40-K39 -> 0.028 | N40: Scale to 70-70-70 | O40: Piecewise linear scale-up; hold after 2040 | P40: =IF(OR(K40<0,K40>1,M40<0),"BAD","OK") -> OK
...

Sheet Cost_Components
A1: cost_record_id | B1: cost_component_key | C1: cost_option | D1: selected_for_base_case | E1: intervention_id | F1: cause_id | G1: cost_join_key | H1: intervention_name | I1: cause_name | J1: cost_component | K1: population_in_need_measure | L1: population_in_need_fraction | M1: cost_unit | N1: frequency_per_year | O1: age_start | P1: age_stop | Q1: sex | R1: platform | S1: unit_cost_usd | T1: price_year | U1: indonesia_adjusted_flag | V1: source_country | W1: source_file | X1: source_row | Y1: review_status | Z1: notes | AA1: map_match_count | AB1: selection_count | AC1: qa_status
A2: COST_PRIMARY_SCREEN_A | B2: CC_PRIMARY_SCREENING | C2: Option A (selected) | D2: 0 | E2: I_CVD_PRIMARY | F2: C_SHARED | G2: I_CVD_PRIMARY__C_SHARED | H2: Primary prevention of CVD | I2: Shared primary CVD cost | J2: CVD targeted screening | K2: all | L2: 0.2 | M2: USD per eligible person-year | N2: 1 | O2: 30 | P2: 95 | Q2: Both | R2: Health center | S2: 1.291584 | T2: 2023 | U2: 1 | V2: Tanzania | W2: indonesia_model_inputs(7).xlsx | X2: Cost_Components row 4 | Y2: Review | Z2: Lower salary-adjustment option; confirm selection | AA2: =COUNTIF(Intervention_Cause_Map!$J$2:$J$7,G2) -> 4 | AB2: =SUMIF($B$2:$B$8,B2,$D$2:$D$8) -> 1 | AC2: =IF(AA2<1,"BAD KEY",IF(S2="","MISSING COST",IF(U2=0,"REVIEW ADJUSTMENT",IF(AB2<>1,"CHECK SELECTION","OK")))) -> OK
A3: COST_PRIMARY_SCREEN_B | B3: CC_PRIMARY_SCREENING | C3: Option B | D3: 1 | E3: I_CVD_PRIMARY | F3: C_SHARED | G3: I_CVD_PRIMARY__C_SHARED | H3: Primary prevention of CVD | I3: Shared primary CVD cost | J3: CVD targeted screening | K3: all | L3: 0.2 | M3: USD per eligible person-year | N3: 1 | O3: 30 | P3: 95 | Q3: Both | R3: Health center | S3: 2.766522 | T3: 2023 | U3: 1 | V3: Tanzania | W3: indonesia_model_inputs(7).xlsx | X3: Cost_Components row 5 | Y3: Alternative | Z3: Alternative salary-adjustment option | AA3: =COUNTIF(Intervention_Cause_Map!$J$2:$J$7,G3) -> 4 | AB3: =SUMIF($B$2:$B$8,B3,$D$2:$D$8) -> 1 | AC3: =IF(AA3<1,"BAD KEY",IF(S3="","MISSING COST",IF(U3=0,"REVIEW ADJUSTMENT",IF(AB3<>1,"CHECK SELECTION","OK")))) -> OK
A4: COST_PRIMARY_TX_A | B4: CC_PRIMARY_HTN_STATIN | C4: Option A (selected) | D4: 0 | E4: I_CVD_PRIMARY | F4: C_SHARED | G4: I_CVD_PRIMARY__C_SHARED | H4: Primary prevention of CVD | I4: Shared primary CVD cost | J4: Antihypertensives and statins for absolute CVD risk >20% | K4: all | L4: 0.06 | M4: USD per eligible person-year | N4: 1 | O4: 30 | P4: 95 | Q4: Both | R4: Health center | S4: 22.2296 | T4: 2023 | U4: 1 | V4: Tanzania | W4: indonesia_model_inputs(7).xlsx | X4: Cost_Components row 6 | Y4: Review | Z4: Lower salary-adjustment option; confirm selection | AA4: =COUNTIF(Intervention_Cause_Map!$J$2:$J$7,G4) -> 4 | AB4: =SUMIF($B$2:$B$8,B4,$D$2:$D$8) -> 1 | AC4: =IF(AA4<1,"BAD KEY",IF(S4="","MISSING COST",IF(U4=0,"REVIEW ADJUSTMENT",IF(AB4<>1,"CHECK SELECTION","OK")))) -> OK
