Workbook

Sheet README
A1: Indonesia NCD model — user input workbook
A3: Draft for review • August 14, 2026 meeting decisions + supplied Fair Choices, coverage/PIN, and cost files
A5: Readiness | C5: Interventions | E5: Model causes | G5: Intervention–cause links
A6: =IF(COUNTIF(QA_Checks!$E$2:$E$9,"FAIL")=0,"READY TO RUN","REVIEW REQUIRED") -> READY TO RUN | C6: =COUNTA(Dictionaries!$A$2:$A$10) -> 9 | E6: =COUNTIF(Dictionaries!$I$2:$I$9,1) -> 7 | G6: =COUNTA(Intervention_Cause_Map!$A$2:$A$19) -> 18
A9: How to use the workbook
A10: 1 | B10: Edit yellow cells only.
A11: 2 | B11: Use Model_Input_View to audit the joined transition, effect, coverage, and cost key for each intervention–cause pair.
A12: 3 | B12: Costs join through cost_join_key. C_SHARED means count the cost once at intervention level, not once per affected cause.
A13: 4 | B13: For costing, keep exactly one selected_for_base_case = 1 within each cost_component_key.
A14: 5 | B14: Resolve QA failures and red review items before running the full economic evaluation.
A16: Known review items retained explicitly
A17: Resolved | B17: Type 2 diabetes baseline coverage updated to 16% from the revised PIN file
A18: Resolved | B18: Type 2 diabetes unit costs updated with Indonesia-adjusted 2023 USD values
A19: Missing | B19: IHD-specific chronic heart-failure lab/follow-up unit cost
A20: Review | B20: Lower cost option is provisionally selected when the adjusted cost file contains two salary options
A21: Review | B21: Confirm RHD surgery transition if the final model has explicit severe-RHD or surgery states
A23: Color legend: yellow = user input • light blue = formula/derived • green = valid • red/orange = missing or review

Sheet Assumptions
A1: parameter_id | B1: value | C1: unit | D1: base_case | E1: lower_bound | F1: upper_bound | G1: description | H1: source
A2: analysis_start_year | B2: 2025 | C2: year | D2: 2025 | E2: 2025 | F2: 2025 | G2: First modeled year | H2: input_file.xlsx and meeting scope
A3: analysis_end_year | B3: 2050 | C3: year | D3: 2050 | E3: 2050 | F3: 2100 | G3: Last year for the Jakarta-oriented analysis | H3: Meeting target year
A4: intervention_start_year | B4: 2025 | C4: year | D4: 2025 | E4: 2025 | F4: 2030 | G4: First year of intervention scale-up | H4: input_file.xlsx
A5: target_coverage_default | B5: 0.8 | C5: proportion | D5: 0.8 | E5: 0.7 | F5: 0.9 | G5: Default intervention coverage target; row-level override is available | H5: August 14 meeting
A6: coverage_target_year | B6: 2050 | C6: year | D6: 2050 | E6: 2030 | F6: 2050 | G6: Year in which target coverage is reached | H6: August 14 meeting
A7: cost_discount_rate | B7: 0.03 | C7: proportion/year | D7: 0.03 | E7: 0 | F7: 0.05 | G7: Annual discount rate for costs | H7: input_file.xlsx
A8: health_discount_rate | B8: 0.03 | C8: proportion/year | D8: 0.03 | E8: 0 | F8: 0.05 | G8: Annual discount rate for health outcomes | H8: input_file.xlsx
A9: cost_price_year | B9: 2023 | C9: USD year | D9: 2023 | E9: 2023 | F9: 2024 | G9: Price year for Indonesia-adjusted CVD unit costs | H9: cvd_unit_cost_indonesia_1_dm(2).xlsx
A10: currency | B10: USD | C10: currency | D10: USD | E10: USD | F10: USD | G10: Reporting currency | H10: input_file.xlsx
A11: scale_up_shape | B11: linear | C11: text | D11: linear | E11: linear | F11: linear | G11: Coverage increases linearly from start year to target year | H11: August 14 meeting
A12: downstream_cost_offsets | B12: 0 | C12: 0/1 flag | D12: 0 | E12: 0 | F12: 1 | G12: Include downstream disease-cost offsets | H12: input_file.xlsx
A13: rhd_surgery_frequency | B13: 1 | C13: procedure/patient-year | D13: 1 | E13: 0 | F13: 1 | G13: Provisional surgery frequency used for costing | H13: input_file.xlsx
A14: economic_perspective | B14: health_system | C14: text | D14: health_system | E14: health_system | F14: societal | G14: Economic evaluation perspective | H14: Working assumption
A15: bca_base_year | B15: 2025 | C15: year | D15: 2025 | E15: 2025 | F15: 2026 | G15: Base year to which BCA benefits and costs are both discounted (single shared base year) | H15: Robinson et al. 2019 Reference Case Guidelines for BCA in Global Health & Development (CHDS/Harvard); = analysis_start_year
A16: bca_discount_rate_primary | B16: 0.03 | C16: proportion/year | D16: 0.03 | E16: 0.03 | F16: 0.05 | G16: Primary real discount rate applied to BOTH benefits and costs in the BCA | H16: Robinson et al. 2019 Reference Case Guidelines for BCA in Global Health & Development (CHDS/Harvard); context-specific primary rate
A17: bca_discount_rate_sensitivity_3pct | B17: 0.03 | C17: proportion/year | D17: 0.03 | E17: 0.03 | F17: 0.03 | G17: Standardized sensitivity discount rate (3%) | H17: Robinson et al. 2019 Reference Case Guidelines for BCA in Global Health & Development (CHDS/Harvard); standardized sensitivity
A18: bca_discount_rate_sensitivity_2x_gdp_pc_growth | B18: 0.08 | C18: proportion/year | D18: 0.08 | E18: 0.06 | F18: 0.1 | G18: Standardized sensitivity = 2x projected near-term real GDP per-capita growth; Model 08 recomputes from SSP2 | H18: Robinson et al. 2019 Reference Case Guidelines for BCA in Global Health & Development (CHDS/Harvard); IIASA SSP 3.1 (SSP2)
A19: vsl_us_gni_ratio | B19: 160 | C19: ratio (VSL/GNI per capita) | D19: 160 | E19: 100 | F19: 230 | G19: U.S. reference VSL-to-GNI-per-capita ratio used for the income transfer | H19: Robinson et al. 2019 Reference Case Guidelines for BCA in Global Health & Development (CHDS/Harvard)
A20: vsl_income_elasticity_preferred | B20: 1.5 | C20: elasticity | D20: 1.5 | E20: 1 | F20: 1.5 | G20: Income elasticity of VSL for LMIC extrapolation (preferred / reference case) | H20: Robinson et al. 2019 Reference Case Guidelines for BCA in Global Health & Development (CHDS/Harvard)
A21: vsl_floor_gni_multiple | B21: 20 | C21: ratio (VSL/GNI per capita) | D21: 20 | E21: 20 | F21: 20 | G21: Lower bound: transferred VSL not below this multiple of target-country GNI per capita | H21: Robinson et al. 2019 Reference Case Guidelines for BCA in Global Health & Development (CHDS/Harvard)
A22: vsl_sensitivity_gni_multiple_100 | B22: 100 | C22: ratio (VSL/GNI per capita) | D22: 100 | E22: 100 | F22: 100 | G22: Standardized sensitivity 1: VSL = 100 x target GNI per capita | H22: Robinson et al. 2019 Reference Case Guidelines for BCA in Global Health & Development (CHDS/Harvard)
A23: vsl_sensitivity_gni_multiple_160 | B23: 160 | C23: ratio (VSL/GNI per capita) | D23: 160 | E23: 160 | F23: 160 | G23: Standardized sensitivity 2: VSL = 160 x target GNI per capita | H23: Robinson et al. 2019 Reference Case Guidelines for BCA in Global Health & Development (CHDS/Harvard)
A24: vsly_adult_min_age | B24: 15 | C24: age (years) | D24: 15 | E24: 15 | F24: 20 | G24: Lower bound of adult (working-age) population for the VSLY average-adult-age denominator | H24: Robinson et al. 2019 Reference Case Guidelines for BCA in Global Health & Development (CHDS/Harvard); ILO/World Bank working age 15-64
A25: vsly_adult_max_age | B25: 64 | C25: age (years) | D25: 64 | E25: 64 | F25: 95 | G25: Upper bound of adult (working-age) population for the VSLY average-adult-age denominator | H25: ILO / World Bank working-age population 15-64
A26: bca_currency_basis | B26: PPP_international_dollars | C26: text | D26: PPP_international_dollars | E26: 631 | F26: 631 | G26: Common monetary basis for BCA benefits and costs; VSL is transferred using GNI per capita at PPP | H26: Robinson et al. 2019 Reference Case Guidelines for BCA in Global Health & Development (CHDS/Harvard)
A27: bca_price_year | B27: 2023 | C27: year | D27: 2023 | E27: 2020 | F27: 2024 | G27: Real price year for BCA benefits and costs (must match the cost price year) | H27: = cost_price_year / reporting_price_year
A28: cost_to_bca_currency_factor | B28: 3 | C28: int$ per market US$ | D28: 3 | E28: 2.7 | F28: 3.3 | G28: Multiplier converting market-exchange-rate USD costs to PPP international dollars (benefit basis); = 1 / WB ICP price-level ratio | H28: World Bank ICP PA.NUS.PPPC.RF (Indonesia price-level ratio ~0.33)
A29: bca_standing | B29: societal | C29: text | D29: societal | E29: 631 | F29: 631 | G29: Standing/perspective for the BCA (whose benefits and costs count) | H29: Robinson et al. 2019 Reference Case Guidelines for BCA in Global Health & Development (CHDS/Harvard)
A30: bca_scope | B30: partial_mortality_benefit | C30: text | D30: partial_mortality_benefit | E30: 631 | F30: 631 | G30: Scope: benefits limited to averted mortality (VSL/VSLY); costs limited to implementation/health-system. NOT a full societal BCA | H30: Model scope limitation

Sheet Dictionaries
A1: intervention_id | B1: intervention_name | C1: package_group | D1: definition | F1: cause_id | G1: cause_name | H1: model_name | I1: is_model_cause
A2: I_RHD_SECONDARY | B2: RHD secondary prevention | C2: Rheumatic heart disease | D2: Secondary prophylaxis for rheumatic fever or established RHD | F2: C_RHD | G2: Rheumatic heart disease | H2: Rheumatic heart disease | I2: 1
A3: I_RHD_SURGERY | B3: RHD cardiac surgery | C3: Rheumatic heart disease | D3: Cardiac surgery for severe rheumatic heart disease | F3: C_IHD | G3: Ischemic heart disease | H3: Ischemic heart disease | I3: 1
A4: I_CVD_PRIMARY | B4: Primary prevention of CVD | C4: Primary CVD prevention | D4: Combined hypertension-treatment/statin intervention using average Fair Choices effects | F4: C_IS | G4: Ischemic stroke | H4: Ischemic stroke | I4: 1
A5: I_IHD_SECONDARY | B5: Secondary prevention of ischemic heart disease | C5: Secondary CVD prevention | D5: Longitudinal secondary prevention after ischemic heart disease | F5: C_ICH | G5: Intracerebral hemorrhage | H5: Intracerebral hemorrhage | I5: 1
A6: I_STROKE_SECONDARY | B6: Secondary prevention of stroke | C6: Secondary CVD prevention | D6: Longitudinal secondary prevention after ischemic or intracerebral hemorrhagic stroke | F6: C_HHD | G6: Hypertensive heart disease | H6: Hypertensive heart disease | I6: 1
A7: I_HF_ACUTE | B7: Acute heart-failure management | C7: Heart-failure treatment | D7: Acute management of heart failure arising from IHD, HHD, or cardiomyopathy/myocarditis | F7: C_CMP | G7: Cardiomyopathy and myocarditis | H7: Cardiomyopathy and myocarditis | I7: 1
A8: I_HF_CHRONIC | B8: Chronic heart-failure management | C8: Heart-failure treatment | D8: Longitudinal management of chronic heart failure arising from IHD, HHD, or cardiomyopathy/myocarditis | F8: C_T2D | G8: Diabetes mellitus type 2 | H8: Type 2 diabetes | I8: 1
A9: I_T2D_TREATMENT | B9: Longitudinal treatment of type 2 diabetes | C9: Diabetes treatment | D9: Treatment affecting direct diabetes deaths and IHD deaths attributable to high blood glucose | F9: C_SHARED | G9: Shared intervention cost | H9: Not a disease model; count cost once | I9: 0
A10: I_IHD_ACUTE | B10: Treatment of acute coronary syndromes | C10: Acute ischemic heart disease treatment | D10: Acute hospital management of ischemic heart disease with aspirin, unfractionated heparin, and generic thrombolytics when indicated

Sheet Intervention_Cause_Map
A1: intervention_cause_key | B1: intervention_id | C1: intervention_name | D1: cause_id | E1: cause_name | F1: model_name | G1: effect_key | H1: coverage_key | I1: cost_join_key | J1: cost_scope | K1: include_flag | L1: notes | M1: duplicate_count
A2: I_RHD_SECONDARY__C_RHD | B2: I_RHD_SECONDARY | C2: RHD secondary prevention | D2: C_RHD | E2: Rheumatic heart disease | F2: Rheumatic heart disease | G2: I_RHD_SECONDARY__C_RHD | H2: I_RHD_SECONDARY__C_RHD | I2: I_RHD_SECONDARY__C_RHD | J2: cause-specific | K2: 0 | L2: Apply to the RHD model | M2: =COUNTIF($A$2:$A$19,A2) -> 1
A3: I_RHD_SURGERY__C_RHD | B3: I_RHD_SURGERY | C3: RHD cardiac surgery | D3: C_RHD | E3: Rheumatic heart disease | F3: Rheumatic heart disease | G3: I_RHD_SURGERY__C_RHD | H3: I_RHD_SURGERY__C_RHD | I3: I_RHD_SURGERY__C_RHD | J3: cause-specific | K3: 0 | L3: SRHD has been replaced with RHD | M3: =COUNTIF($A$2:$A$19,A3) -> 1
A4: I_CVD_PRIMARY__C_IHD | B4: I_CVD_PRIMARY | C4: Primary prevention of CVD | D4: C_IHD | E4: Ischemic heart disease | F4: Ischemic heart disease | G4: I_CVD_PRIMARY__C_IHD | H4: I_CVD_PRIMARY__C_IHD | I4: I_CVD_PRIMARY__C_SHARED | J4: shared-count-once | K4: 1 | L4: Shared screening/treatment costs must be counted once | M4: =COUNTIF($A$2:$A$19,A4) -> 1
A5: I_CVD_PRIMARY__C_IS | B5: I_CVD_PRIMARY | C5: Primary prevention of CVD | D5: C_IS | E5: Ischemic stroke | F5: Ischemic stroke | G5: I_CVD_PRIMARY__C_IS | H5: I_CVD_PRIMARY__C_IS | I5: I_CVD_PRIMARY__C_SHARED | J5: shared-count-once | K5: 1 | L5: Shared screening/treatment costs must be counted once | M5: =COUNTIF($A$2:$A$19,A5) -> 1
A6: I_CVD_PRIMARY__C_ICH | B6: I_CVD_PRIMARY | C6: Primary prevention of CVD | D6: C_ICH | E6: Intracerebral hemorrhage | F6: Intracerebral hemorrhage | G6: I_CVD_PRIMARY__C_ICH | H6: I_CVD_PRIMARY__C_ICH | I6: I_CVD_PRIMARY__C_SHARED | J6: shared-count-once | K6: 1 | L6: Shared screening/treatment costs must be counted once | M6: =COUNTIF($A$2:$A$19,A6) -> 1
A7: I_CVD_PRIMARY__C_HHD | B7: I_CVD_PRIMARY | C7: Primary prevention of CVD | D7: C_HHD | E7: Hypertensive heart disease | F7: Hypertensive heart disease | G7: I_CVD_PRIMARY__C_HHD | H7: I_CVD_PRIMARY__C_HHD | I7: I_CVD_PRIMARY__C_SHARED | J7: shared-count-once | K7: 1 | L7: Shared screening/treatment costs must be counted once | M7: =COUNTIF($A$2:$A$19,A7) -> 1
A8: I_IHD_SECONDARY__C_IHD | B8: I_IHD_SECONDARY | C8: Secondary prevention of ischemic heart disease | D8: C_IHD | E8: Ischemic heart disease | F8: Ischemic heart disease | G8: I_IHD_SECONDARY__C_IHD | H8: I_IHD_SECONDARY__C_IHD | I8: I_IHD_SECONDARY__C_IHD | J8: cause-specific | K8: 1 | L8: Apply to sick-to-dead transition | M8: =COUNTIF($A$2:$A$19,A8) -> 1
A9: I_STROKE_SECONDARY__C_IS | B9: I_STROKE_SECONDARY | C9: Secondary prevention of stroke | D9: C_IS | E9: Ischemic stroke | F9: Ischemic stroke | G9: I_STROKE_SECONDARY__C_IS | H9: I_STROKE_SECONDARY__C_IS | I9: I_STROKE_SECONDARY__C_IS | J9: cause-specific | K9: 1 | L9: Cause-specific effect and cost components | M9: =COUNTIF($A$2:$A$19,A9) -> 1
A10: I_STROKE_SECONDARY__C_ICH | B10: I_STROKE_SECONDARY | C10: Secondary prevention of stroke | D10: C_ICH | E10: Intracerebral hemorrhage | F10: Intracerebral hemorrhage | G10: I_STROKE_SECONDARY__C_ICH | H10: I_STROKE_SECONDARY__C_ICH | I10: I_STROKE_SECONDARY__C_ICH | J10: cause-specific | K10: 1 | L10: Cause-specific effect and cost components | M10: =COUNTIF($A$2:$A$19,A10) -> 1
A11: I_HF_ACUTE__C_IHD | B11: I_HF_ACUTE | C11: Acute heart-failure management | D11: C_IHD | E11: Ischemic heart disease | F11: Ischemic heart disease | G11: I_HF_ACUTE__C_IHD | H11: I_HF_ACUTE__C_IHD | I11: I_HF_ACUTE__C_IHD | J11: cause-specific | K11: 1 | L11: Heart failure arising from IHD | M11: =COUNTIF($A$2:$A$19,A11) -> 1
A12: I_HF_ACUTE__C_HHD | B12: I_HF_ACUTE | C12: Acute heart-failure management | D12: C_HHD | E12: Hypertensive heart disease | F12: Hypertensive heart disease | G12: I_HF_ACUTE__C_HHD | H12: I_HF_ACUTE__C_HHD | I12: I_HF_ACUTE__C_HHD | J12: cause-specific | K12: 1 | L12: Heart failure arising from HHD | M12: =COUNTIF($A$2:$A$19,A12) -> 1
A13: I_HF_ACUTE__C_CMP | B13: I_HF_ACUTE | C13: Acute heart-failure management | D13: C_CMP | E13: Cardiomyopathy and myocarditis | F13: Cardiomyopathy and myocarditis | G13: I_HF_ACUTE__C_CMP | H13: I_HF_ACUTE__C_CMP | I13: I_HF_ACUTE__C_CMP | J13: cause-specific | K13: 1 | L13: Heart failure arising from cardiomyopathy/myocarditis | M13: =COUNTIF($A$2:$A$19,A13) -> 1
... A19: I_IHD_ACUTE__C_IHD | B19: I_IHD_ACUTE | C19: Treatment of acute coronary syndromes | D19: C_IHD | E19: Ischemic heart disease | F19: Ischemic heart disease | G19: I_IHD_ACUTE__C_IHD | H19: I_IHD_ACUTE__C_IHD | I19: I_IHD_ACUTE__C_IHD | J19: cause-specific | K19: 1 | L19: Apply to the acute IHD case-fatality (sick-to-dead) transition | M19: =COUNTIF($A$2:$A$19,A19) -> 1

Sheet Effect_Sizes
A1: effect_id | B1: intervention_cause_key | C1: intervention_id | D1: cause_id | E1: intervention_name | F1: cause_name | G1: transition_from | H1: transition_to | I1: effect_measure | J1: effect_value | K1: affected_fraction | L1: age_start | M1: age_stop | N1: sex | O1: duration_years | P1: source_variable | Q1: source_file | R1: source_row | S1: review_status | T1: notes | U1: map_match_count | V1: qa_status
A2: E_RHD_SECONDARY | B2: I_RHD_SECONDARY__C_RHD | C2: I_RHD_SECONDARY | D2: C_RHD | E2: RHD secondary prevention | F2: Rheumatic heart disease | G2: sick | H2: dead_rhd | I2: relative_risk_reduction | J2: 0.55 | K2: 1 | L2: 5 | M2: 39 | N2: Both | O2: 1 | P2: Prevalence (reclassified to mortality transition) | Q2: taxonomy_effect_size.xlsx | R2: Sheet 1, row 146 | S2: Provisional | T2: Meeting decision maps secondary prevention to sick → dead | U2: =COUNTIF(Intervention_Cause_Map!$A$2:$A$19,B2) -> 1 | V2: =IF(U2<>1,"BAD KEY",IF(OR(J2<0,J2>1,K2<0,K2>1),"BAD VALUE","OK")) -> OK
A3: E_RHD_SURGERY | B3: I_RHD_SURGERY__C_RHD | C3: I_RHD_SURGERY | D3: C_RHD | E3: RHD cardiac surgery | F3: Rheumatic heart disease | G3: sick_severe | H3: dead_rhd | I3: relative_risk_reduction | J3: 0.75 | K3: 0.1 | L3: 5 | M3: 40 | N3: Both | O3: 15 | P3: Mortality | Q3: taxonomy_effect_size.xlsx | R3: Sheet 1, row 148 | S3: Review | T3: Confirm model state if surgery is represented explicitly | U3: =COUNTIF(Intervention_Cause_Map!$A$2:$A$19,B3) -> 1 | V3: =IF(U3<>1,"BAD KEY",IF(OR(J3<0,J3>1,K3<0,K3>1),"BAD VALUE","OK")) -> OK
A4: E_PRIMARY_IHD | B4: I_CVD_PRIMARY__C_IHD | C4: I_CVD_PRIMARY | D4: C_IHD | E4: Primary prevention of CVD | F4: Ischemic heart disease | G4: well | H4: sick | I4: relative_risk_reduction | J4: 0.58 | K4: 0.8 | L4: 30 | M4: 80 | N4: Both | O4: 1 | P4: Mortality (reclassified to incidence transition) | Q4: taxonomy_effect_size.xlsx | R4: Sheet 1, row 136 | S4: Provisional | T4: Average Fair Choices hypertension/statin effect applied to incidence | U4: =COUNTIF(Intervention_Cause_Map!$A$2:$A$19,B4) -> 1 | V4: =IF(U4<>1,"BAD KEY",IF(OR(J4<0,J4>1,K4<0,K4>1),"BAD VALUE","OK")) -> OK
A5: E_PRIMARY_IS | B5: I_CVD_PRIMARY__C_IS | C5: I_CVD_PRIMARY | D5: C_IS | E5: Primary prevention of CVD | F5: Ischemic stroke | G5: well | H5: sick | I5: relative_risk_reduction | J5: 0.54 | K5: 0.8 | L5: 30 | M5: 80 | N5: Both | O5: 1 | P5: Mortality (reclassified to incidence transition) | Q5: taxonomy_effect_size.xlsx | R5: Sheet 1, row 133 | S5: Provisional | T5: Average Fair Choices hypertension/statin effect applied to incidence | U5: =COUNTIF(Intervention_Cause_Map!$A$2:$A$19,B5) -> 1 | V5: =IF(U5<>1,"BAD KEY",IF(OR(J5<0,J5>1,K5<0,K5>1),"BAD VALUE","OK")) -> OK
A6: E_PRIMARY_ICH | B6: I_CVD_PRIMARY__C_ICH | C6: I_CVD_PRIMARY | D6: C_ICH | E6: Primary prevention of CVD | F6: Intracerebral hemorrhage | G6: well | H6: sick | I6: relative_risk_reduction | J6: 0.49 | K6: 0.8 | L6: 30 | M6: 80 | N6: Both | O6: 1 | P6: Mortality (reclassified to incidence transition) | Q6: taxonomy_effect_size.xlsx | R6: Sheet 1, row 134 | S6: Provisional | T6: Average Fair Choices hypertension/statin effect applied to incidence | U6: =COUNTIF(Intervention_Cause_Map!$A$2:$A$19,B6) -> 1 | V6: =IF(U6<>1,"BAD KEY",IF(OR(J6<0,J6>1,K6<0,K6>1),"BAD VALUE","OK")) -> OK
A7: E_PRIMARY_HHD | B7: I_CVD_PRIMARY__C_HHD | C7: I_CVD_PRIMARY | D7: C_HHD | E7: Primary prevention of CVD | F7: Hypertensive heart disease | G7: well | H7: sick | I7: relative_risk_reduction | J7: 0.47 | K7: 1 | L7: 30 | M7: 80 | N7: Both | O7: 1 | P7: Mortality (reclassified to incidence transition) | Q7: taxonomy_effect_size.xlsx | R7: Sheet 1, row 135 | S7: Provisional | T7: Average Fair Choices hypertension/statin effect applied to incidence | U7: =COUNTIF(Intervention_Cause_Map!$A$2:$A$19,B7) -> 1 | V7: =IF(U7<>1,"BAD KEY",IF(OR(J7<0,J7>1,K7<0,K7>1),"BAD VALUE","OK")) -> OK
A8: E_IHD_SECONDARY | B8: I_IHD_SECONDARY__C_IHD | C8: I_IHD_SECONDARY | D8: C_IHD | E8: Secondary prevention of ischemic heart disease | F8: Ischemic heart disease | G8: sick | H8: dead_ihd | I8: relative_risk_reduction | J8: 0.5822 | K8: 0.2 | L8: 30 | M8: 80 | N8: Both | O8: 1 | P8: Mortality | Q8: taxonomy_effect_size.xlsx | R8: Sheet 1, row 139 | S8: Provisional | T8: Cause-specific disease-management effect | U8: =COUNTIF(Intervention_Cause_Map!$A$2:$A$19,B8) -> 1 | V8: =IF(U8<>1,"BAD KEY",IF(OR(J8<0,J8>1,K8<0,K8>1),"BAD VALUE","OK")) -> OK
A9: E_STROKE_SECONDARY_IS | B9: I_STROKE_SECONDARY__C_IS | C9: I_STROKE_SECONDARY | D9: C_IS | E9: Secondary prevention of stroke | F9: Ischemic stroke | G9: sick | H9: dead_is | I9: relative_risk_reduction | J9: 0.23 | K9: 0.2 | L9: 30 | M9: 80 | N9: Both | O9: 1 | P9: Mortality | Q9: taxonomy_effect_size.xlsx | R9: Sheet 1, row 152 | S9: Provisional | T9: Cause-specific disease-management effect | U9: =COUNTIF(Intervention_Cause_Map!$A$2:$A$19,B9) -> 1 | V9: =IF(U9<>1,"BAD KEY",IF(OR(J9<0,J9>1,K9<0,K9>1),"BAD VALUE","OK")) -> OK
A10: E_STROKE_SECONDARY_ICH | B10: I_STROKE_SECONDARY__C_ICH | C10: I_STROKE_SECONDARY | D10: C_ICH | E10: Secondary prevention of stroke | F10: Intracerebral hemorrhage | G10: sick | H10: dead_ich | I10: relative_risk_reduction | J10: 0.08 | K10: 0.2 | L10: 30 | M10: 80 | N10: Both | O10: 1 | P10: Mortality | Q10: taxonomy_effect_size.xlsx | R10: Sheet 1, row 153 | S10: Provisional | T10: Cause-specific disease-management effect | U10: =COUNTIF(Intervention_Cause_Map!$A$2:$A$19,B10) -> 1 | V10: =IF(U10<>1,"BAD KEY",IF(OR(J10<0,J10>1,K10<0,K10>1),"BAD VALUE","OK")) -> OK
A11: E_HF_ACUTE_IHD | B11: I_HF_ACUTE__C_IHD | C11: I_HF_ACUTE | D11: C_IHD | E11: Acute heart-failure management | F11: Ischemic heart disease | G11: sick_hf | H11: dead_ihd | I11: relative_risk_reduction | J11: 0.18 | K11: 0.05 | L11: 30 | M11: 99 | N11: Both | O11: 1 | P11: Mortality | Q11: taxonomy_effect_size.xlsx | R11: Sheet 1, row 143 | S11: Provisional | T11: Apply only to heart failure arising from IHD | U11: =COUNTIF(Intervention_Cause_Map!$A$2:$A$19,B11) -> 1 | V11: =IF(U11<>1,"BAD KEY",IF(OR(J11<0,J11>1,K11<0,K11>1),"BAD VALUE","OK")) -> OK
A12: E_HF_ACUTE_HHD | B12: I_HF_ACUTE__C_HHD | C12: I_HF_ACUTE | D12: C_HHD | E12: Acute heart-failure management | F12: Hypertensive heart disease | G12: sick_hf | H12: dead_hhd | I12: relative_risk_reduction | J12: 0.74 | K12: 0.2 | L12: 30 | M12: 99 | N12: Both | O12: 1 | P12: Mortality | Q12: taxonomy_effect_size.xlsx | R12: Sheet 1, row 144 | S12: Provisional | T12: Apply only to heart failure arising from HHD | U12: =COUNTIF(Intervention_Cause_Map!$A$2:$A$19,B12) -> 1 | V12: =IF(U12<>1,"BAD KEY",IF(OR(J12<0,J12>1,K12<0,K12>1),"BAD VALUE","OK")) -> OK
A13: E_HF_ACUTE_CMP | B13: I_HF_ACUTE__C_CMP | C13: I_HF_ACUTE | D13: C_CMP | E13: Acute heart-failure management | F13: Cardiomyopathy and myocarditis | G13: sick_hf | H13: dead_cmp | I13: relative_risk_reduction | J13: 0.74 | K13: 0.2 | L13: 30 | M13: 99 | N13: Both | O13: 1 | P13: Mortality | Q13: taxonomy_effect_size.xlsx | R13: Sheet 1, row 145 | S13: Provisional | T13: Apply only to heart failure arising from cardiomyopathy/myocarditis | U13: =COUNTIF(Intervention_Cause_Map!$A$2:$A$19,B13) -> 1 | V13: =IF(U13<>1,"BAD KEY",IF(OR(J13<0,J13>1,K13<0,K13>1),"BAD VALUE","OK")) -> OK
... A19: E_IHD_ACUTE | B19: I_IHD_ACUTE__C_IHD | C19: I_IHD_ACUTE | D19: C_IHD | E19: Treatment of acute coronary syndromes | F19: Ischemic heart disease | G19: sick | H19: dead_ihd | I19: relative_risk_reduction | J19: 0.2812 | K19: 0.5 | L19: 30 | M19: 80 | N19: Both | O19: 1 | P19: Mortality | Q19: taxonomy_effect_size(1).xlsx | R19: Sheet 1, row 138 | S19: Provisional | T19: Fair Choices acute coronary syndrome mortality effect; apply to acute IHD case fatality | U19: =COUNTIF(Intervention_Cause_Map!$A$2:$A$19,B19) -> 1 | V19: =IF(U19<>1,"BAD KEY",IF(OR(J19<0,J19>1,K19<0,K19>1),"BAD VALUE","OK")) -> OK

Sheet Coverage
A1: coverage_id | B1: intervention_cause_key | C1: intervention_id | D1: cause_id | E1: intervention_name | F1: cause_name | G1: baseline_coverage | H1: target_override | I1: target_coverage | J1: start_year | K1: target_year | L1: scale_up_shape | M1: baseline_source_file | N1: baseline_source_row | O1: proxy_note | P1: review_status | Q1: absolute_increase | R1: map_match_count | S1: qa_status
A2: CVG_01 | B2: I_RHD_SECONDARY__C_RHD | C2: I_RHD_SECONDARY | D2: C_RHD | E2: RHD secondary prevention | F2: Rheumatic heart disease | G2: 0.4011 | I2: =IF(H2="",Assumptions!$B$5,H2) -> 0.8 | J2: =Assumptions!$B$4 -> 2025 | K2: =Assumptions!$B$6 -> 2050 | L2: linear | M2: cvd_input_file_PIN_dm(2).csv | N2: row 29 | O2: Regional/platform proxy; validate with Indonesian collaborators | P2: Provisional | Q2: =IF(G2="","",I2-G2) -> 0.3989 | R2: =COUNTIF(Intervention_Cause_Map!$A$2:$A$19,B2) -> 1 | S2: =IF(R2<>1,"BAD KEY",IF(G2="","MISSING BASELINE",IF(OR(G2<0,G2>1,I2<0,I2>1,I2<G2),"BAD COVERAGE","OK"))) -> OK
A3: CVG_02 | B3: I_RHD_SURGERY__C_RHD | C3: I_RHD_SURGERY | D3: C_RHD | E3: RHD cardiac surgery | F3: Rheumatic heart disease | G3: 0.0664 | I3: =IF(H3="",Assumptions!$B$5,H3) -> 0.8 | J3: =Assumptions!$B$4 -> 2025 | K3: =Assumptions!$B$6 -> 2050 | L3: linear | M3: cvd_input_file_PIN_dm(2).csv | N3: row 31 | O3: Regional/platform proxy; SRHD relabeled as RHD | P3: Provisional | Q3: =IF(G3="","",I3-G3) -> 0.7336 | R3: =COUNTIF(Intervention_Cause_Map!$A$2:$A$19,B3) -> 1 | S3: =IF(R3<>1,"BAD KEY",IF(G3="","MISSING BASELINE",IF(OR(G3<0,G3>1,I3<0,I3>1,I3<G3),"BAD COVERAGE","OK"))) -> OK
A4: CVG_03 | B4: I_CVD_PRIMARY__C_IHD | C4: I_CVD_PRIMARY | D4: C_IHD | E4: Primary prevention of CVD | F4: Ischemic heart disease | G4: 0.2466 | I4: =IF(H4="",Assumptions!$B$5,H4) -> 0.8 | J4: =Assumptions!$B$4 -> 2025 | K4: =Assumptions!$B$6 -> 2050 | L4: linear | M4: cvd_input_file_PIN_dm(2).csv | N4: rows 2–3 | O4: Country-context value supplied with the PIN file | P4: Provisional | Q4: =IF(G4="","",I4-G4) -> 0.5534 | R4: =COUNTIF(Intervention_Cause_Map!$A$2:$A$19,B4) -> 1 | S4: =IF(R4<>1,"BAD KEY",IF(G4="","MISSING BASELINE",IF(OR(G4<0,G4>1,I4<0,I4>1,I4<G4),"BAD COVERAGE","OK"))) -> OK
A5: CVG_04 | B5: I_CVD_PRIMARY__C_IS | C5: I_CVD_PRIMARY | D5: C_IS | E5: Primary prevention of CVD | F5: Ischemic stroke | G5: 0.2466 | I5: =IF(H5="",Assumptions!$B$5,H5) -> 0.8 | J5: =Assumptions!$B$4 -> 2025 | K5: =Assumptions!$B$6 -> 2050 | L5: linear | M5: cvd_input_file_PIN_dm(2).csv | N5: rows 2–3 | O5: Country-context value supplied with the PIN file | P5: Provisional | Q5: =IF(G5="","",I5-G5) -> 0.5534 | R5: =COUNTIF(Intervention_Cause_Map!$A$2:$A$19,B5) -> 1 | S5: =IF(R5<>1,"BAD KEY",IF(G5="","MISSING BASELINE",IF(OR(G5<0,G5>1,I5<0,I5>1,I5<G5),"BAD COVERAGE","OK"))) -> OK
A6: CVG_05 | B6: I_CVD_PRIMARY__C_ICH | C6: I_CVD_PRIMARY | D6: C_ICH | E6: Primary prevention of CVD | F6: Intracerebral hemorrhage | G6: 0.2466 | I6: =IF(H6="",Assumptions!$B$5,H6) -> 0.8 | J6: =Assumptions!$B$4 -> 2025 | K6: =Assumptions!$B$6 -> 2050 | L6: linear | M6: cvd_input_file_PIN_dm(2).csv | N6: rows 2–3 | O6: Country-context value supplied with the PIN file | P6: Provisional | Q6: =IF(G6="","",I6-G6) -> 0.5534 | R6: =COUNTIF(Intervention_Cause_Map!$A$2:$A$19,B6) -> 1 | S6: =IF(R6<>1,"BAD KEY",IF(G6="","MISSING BASELINE",IF(OR(G6<0,G6>1,I6<0,I6>1,I6<G6),"BAD COVERAGE","OK"))) -> OK
A7: CVG_06 | B7: I_CVD_PRIMARY__C_HHD | C7: I_CVD_PRIMARY | D7: C_HHD | E7: Primary prevention of CVD | F7: Hypertensive heart disease | G7: 0.2466 | I7: =IF(H7="",Assumptions!$B$5,H7) -> 0.8 | J7: =Assumptions!$B$4 -> 2025 | K7: =Assumptions!$B$6 -> 2050 | L7: linear | M7: cvd_input_file_PIN_dm(2).csv | N7: rows 2–3 | O7: Country-context value supplied with the PIN file | P7: Provisional | Q7: =IF(G7="","",I7-G7) -> 0.5534 | R7: =COUNTIF(Intervention_Cause_Map!$A$2:$A$19,B7) -> 1 | S7: =IF(R7<>1,"BAD KEY",IF(G7="","MISSING BASELINE",IF(OR(G7<0,G7>1,I7<0,I7>1,I7<G7),"BAD COVERAGE","OK"))) -> OK
A8: CVG_07 | B8: I_IHD_SECONDARY__C_IHD | C8: I_IHD_SECONDARY | D8: C_IHD | E8: Secondary prevention of ischemic heart disease | F8: Ischemic heart disease | G8: 0.5301 | I8: =IF(H8="",Assumptions!$B$5,H8) -> 0.8 | J8: =Assumptions!$B$4 -> 2025 | K8: =Assumptions!$B$6 -> 2050 | L8: linear | M8: cvd_input_file_PIN_dm(2).csv | N8: rows 5–7 | O8: Higher-capacity/platform proxy | P8: Provisional | Q8: =IF(G8="","",I8-G8) -> 0.2699 | R8: =COUNTIF(Intervention_Cause_Map!$A$2:$A$19,B8) -> 1 | S8: =IF(R8<>1,"BAD KEY",IF(G8="","MISSING BASELINE",IF(OR(G8<0,G8>1,I8<0,I8>1,I8<G8),"BAD COVERAGE","OK"))) -> OK
A9: CVG_08 | B9: I_STROKE_SECONDARY__C_IS | C9: I_STROKE_SECONDARY | D9: C_IS | E9: Secondary prevention of stroke | F9: Ischemic stroke | G9: 0.3822 | I9: =IF(H9="",Assumptions!$B$5,H9) -> 0.8 | J9: =Assumptions!$B$4 -> 2025 | K9: =Assumptions!$B$6 -> 2050 | L9: linear | M9: cvd_input_file_PIN_dm(2).csv | N9: rows 9–14 | O9: Higher-capacity/platform proxy | P9: Provisional | Q9: =IF(G9="","",I9-G9) -> 0.4178 | R9: =COUNTIF(Intervention_Cause_Map!$A$2:$A$19,B9) -> 1 | S9: =IF(R9<>1,"BAD KEY",IF(G9="","MISSING BASELINE",IF(OR(G9<0,G9>1,I9<0,I9>1,I9<G9),"BAD COVERAGE","OK"))) -> OK
A10: CVG_09 | B10: I_STROKE_SECONDARY__C_ICH | C10: I_STROKE_SECONDARY | D10: C_ICH | E10: Secondary prevention of stroke | F10: Intracerebral hemorrhage | G10: 0.2124 | I10: =IF(H10="",Assumptions!$B$5,H10) -> 0.8 | J10: =Assumptions!$B$4 -> 2025 | K10: =Assumptions!$B$6 -> 2050 | L10: linear | M10: cvd_input_file_PIN_dm(2).csv | N10: rows 9–14 | O10: Higher-capacity/platform proxy | P10: Provisional | Q10: =IF(G10="","",I10-G10) -> 0.5876 | R10: =COUNTIF(Intervention_Cause_Map!$A$2:$A$19,B10) -> 1 | S10: =IF(R10<>1,"BAD KEY",IF(G10="","MISSING BASELINE",IF(OR(G10<0,G10>1,I10<0,I10>1,I10<G10),"BAD COVERAGE","OK"))) -> OK
A11: CVG_10 | B11: I_HF_ACUTE__C_IHD | C11: I_HF_ACUTE | D11: C_IHD | E11: Acute heart-failure management | F11: Ischemic heart disease | G11: 0.2684 | I11: =IF(H11="",Assumptions!$B$5,H11) -> 0.8 | J11: =Assumptions!$B$4 -> 2025 | K11: =Assumptions!$B$6 -> 2050 | L11: linear | M11: cvd_input_file_PIN_dm(2).csv | N11: rows 26–28 | O11: Hospital/platform proxy | P11: Provisional | Q11: =IF(G11="","",I11-G11) -> 0.5316 | R11: =COUNTIF(Intervention_Cause_Map!$A$2:$A$19,B11) -> 1 | S11: =IF(R11<>1,"BAD KEY",IF(G11="","MISSING BASELINE",IF(OR(G11<0,G11>1,I11<0,I11>1,I11<G11),"BAD COVERAGE","OK"))) -> OK
A12: CVG_11 | B12: I_HF_ACUTE__C_HHD | C12: I_HF_ACUTE | D12: C_HHD | E12: Acute heart-failure management | F12: Hypertensive heart disease | G12: 0.2684 | I12: =IF(H12="",Assumptions!$B$5,H12) -> 0.8 | J12: =Assumptions!$B$4 -> 2025 | K12: =Assumptions!$B$6 -> 2050 | L12: linear | M12: cvd_input_file_PIN_dm(2).csv | N12: rows 26–28 | O12: Hospital/platform proxy | P12: Provisional | Q12: =IF(G12="","",I12-G12) -> 0.5316 | R12: =COUNTIF(Intervention_Cause_Map!$A$2:$A$19,B12) -> 1 | S12: =IF(R12<>1,"BAD KEY",IF(G12="","MISSING BASELINE",IF(OR(G12<0,G12>1,I12<0,I12>1,I12<G12),"BAD COVERAGE","OK"))) -> OK
A13: CVG_12 | B13: I_HF_ACUTE__C_CMP | C13: I_HF_ACUTE | D13: C_CMP | E13: Acute heart-failure management | F13: Cardiomyopathy and myocarditis | G13: 0.2684 | I13: =IF(H13="",Assumptions!$B$5,H13) -> 0.8 | J13: =Assumptions!$B$4 -> 2025 | K13: =Assumptions!$B$6 -> 2050 | L13: linear | M13: cvd_input_file_PIN_dm(2).csv | N13: rows 26–28 | O13: Hospital/platform proxy | P13: Provisional | Q13: =IF(G13="","",I13-G13) -> 0.5316 | R13: =COUNTIF(Intervention_Cause_Map!$A$2:$A$19,B13) -> 1 | S13: =IF(R13<>1,"BAD KEY",IF(G13="","MISSING BASELINE",IF(OR(G13<0,G13>1,I13<0,I13>1,I13<G13),"BAD COVERAGE","OK"))) -> OK
... A19: CVG_18 | B19: I_IHD_ACUTE__C_IHD | C19: I_IHD_ACUTE | D19: C_IHD | E19: Treatment of acute coronary syndromes | F19: Ischemic heart disease | G19: 0.2 | I19: =IF(H19="",Assumptions!$B$5,H19) -> 0.8 | J19: =Assumptions!$B$4 -> 2025 | K19: =Assumptions!$B$6 -> 2050 | L19: linear | M19: cvd_input_file_PIN_dm(4).csv | N19: row 4 | O19: Hospital/platform baseline coverage supplied in the PIN file | P19: Provisional | Q19: =IF(G19="","",I19-G19) -> 0.6 | R19: =COUNTIF(Intervention_Cause_Map!$A$2:$A$19,B19) -> 1 | S19: =IF(R19<>1,"BAD KEY",IF(G19="","MISSING BASELINE",IF(OR(G19<0,G19>1,I19<0,I19>1,I19<G19),"BAD COVERAGE","OK"))) -> OK

Sheet Cost_Components
A1: cost_record_id | B1: cost_component_key | C1: cost_option | D1: selected_for_base_case | E1: intervention_id | F1: cause_id | G1: cost_join_key | H1: intervention_name | I1: cause_name | J1: cost_component | K1: population_in_need_measure | L1: population_in_need_fraction | M1: cost_unit | N1: frequency_per_year | O1: age_start | P1: age_stop | Q1: sex | R1: platform | S1: unit_cost_usd | T1: price_year | U1: indonesia_adjusted_flag | V1: source_country | W1: source_file | X1: source_row | Y1: review_status | Z1: notes | AA1: map_match_count | AB1: selection_count | AC1: qa_status
A2: COST_RHD_SEC_01 | B2: CC_RHD_SECONDARY_PENICILLIN | C2: Base | D2: 1 | E2: I_RHD_SECONDARY | F2: C_RHD | G2: I_RHD_SECONDARY__C_RHD | H2: RHD secondary prevention | I2: Rheumatic heart disease | J2: Secondary prophylaxis with penicillin | K2: prevalence | L2: 1 | M2: USD per patient-year | N2: 1 | O2: 5 | P2: 39 | Q2: Both | R2: Health center | S2: 68.174793 | T2: 2023 | U2: 1 | V2: Kenya | W2: cvd_unit_cost_indonesia_1_dm(2).xlsx | X2: row 13 | Y2: Provisional | Z2: Indonesia-adjusted Fair Choices unit cost | AA2: =COUNTIF(Intervention_Cause_Map!$I$2:$I$19,G2) -> 1 | AB2: =SUMIF($B$2:$B$38,B2,$D$2:$D$38) -> 1 | AC2: =IF(AA2<1,"BAD KEY",IF(S2="","MISSING COST",IF(U2=0,"REVIEW ADJUSTMENT",IF(AB2<>1,"CHECK SELECTION","OK")))) -> OK
A3: COST_RHD_SURG_01 | B3: CC_RHD_SURGERY | C3: Base | D3: 1 | E3: I_RHD_SURGERY | F3: C_RHD | G3: I_RHD_SURGERY__C_RHD | H3: RHD cardiac surgery | I3: Rheumatic heart disease | J3: Rheumatic heart disease cardiac surgery | K3: prevalence | L3: =10%*0.41 -> 0.041 | M3: USD per procedure | N3: =Assumptions!$B$13 -> 1 | O3: 5 | P3: 40 | Q3: Both | R3: Hospital | S3: 3766.311 | T3: 2023 | U3: 1 | V3: Kenya | W3: cvd_unit_cost_indonesia_1_dm(2).xlsx | X3: row 14 | Y3: Review | Z3: SRHD corrected to RHD; frequency linked to assumption | AA3: =COUNTIF(Intervention_Cause_Map!$I$2:$I$19,G3) -> 1 | AB3: =SUMIF($B$2:$B$38,B3,$D$2:$D$38) -> 1 | AC3: =IF(AA3<1,"BAD KEY",IF(S3="","MISSING COST",IF(U3=0,"REVIEW ADJUSTMENT",IF(AB3<>1,"CHECK SELECTION","OK")))) -> OK
A4: COST_PRIMARY_SCREEN_A | B4: CC_PRIMARY_SCREENING | C4: Option A (selected) | D4: 1 | E4: I_CVD_PRIMARY | F4: C_SHARED | G4: I_CVD_PRIMARY__C_SHARED | H4: Primary prevention of CVD | I4: Shared primary CVD cost | J4: CVD targeted screening | K4: all | L4: 0.2 | M4: USD per eligible person-year | N4: 1 | O4: 30 | P4: 95 | Q4: Both | R4: Health center | S4: 1.291584 | T4: 2023 | U4: 1 | V4: Tanzania | W4: cvd_unit_cost_indonesia_1_dm(2).xlsx | X4: row 15 | Y4: Review | Z4: Lower of two salary-adjustment options; confirm selection | AA4: =COUNTIF(Intervention_Cause_Map!$I$2:$I$19,G4) -> 4 | AB4: =SUMIF($B$2:$B$38,B4,$D$2:$D$38) -> 1 | AC4: =IF(AA4<1,"BAD KEY",IF(S4="","MISSING COST",IF(U4=0,"REVIEW ADJUSTMENT",IF(AB4<>1,"CHECK SELECTION","OK")))) -> OK
A5: COST_PRIMARY_SCREEN_B | B5: CC_PRIMARY_SCREENING | C5: Option B | D5: 0 | E5: I_CVD_PRIMARY | F5: C_SHARED | G5: I_CVD_PRIMARY__C_SHARED | H5: Primary prevention of CVD | I5: Shared primary CVD cost | J5: CVD targeted screening | K5: all | L5: 0.2 | M5: USD per eligible person-year | N5: 1 | O5: 30 | P5: 95 | Q5: Both | R5: Health center | S5: 2.766522 | T5: 2023 | U5: 1 | V5: Tanzania | W5: cvd_unit_cost_indonesia_1_dm(2).xlsx | X5: row 16 | Y5: Alternative | Z5: Alternative salary-adjustment option | AA5: =COUNTIF(Intervention_Cause_Map!$I$2:$I$19,G5) -> 4 | AB5: =SUMIF($B$2:$B$38,B5,$D$2:$D$38) -> 1 | AC5: =IF(AA5<1,"BAD KEY",IF(S5="","MISSING COST",IF(U5=0,"REVIEW ADJUSTMENT",IF(AB5<>1,"CHECK SELECTION","OK")))) -> OK
A6: COST_PRIMARY_TX_A | B6: CC_PRIMARY_HTN_STATIN | C6: Option A (selected) | D6: 1 | E6: I_CVD_PRIMARY | F6: C_SHARED | G6: I_CVD_PRIMARY__C_SHARED | H6: Primary prevention of CVD | I6: Shared primary CVD cost | J6: Antihypertensives and statins for absolute CVD risk >20% | K6: all | L6: 0.3 | M6: USD per eligible person-year | N6: 1 | O6: 30 | P6: 95 | Q6: Both | R6: Health center | S6: 69.304995 | T6: 2023 | U6: 1 | V6: Tanzania | W6: cvd_unit_cost_indonesia_1_dm(2).xlsx | X6: row 17 | Y6: Review | Z6: Lower of two salary-adjustment options; confirm selection | AA6: =COUNTIF(Intervention_Cause_Map!$I$2:$I$19,G6) -> 4 | AB6: =SUMIF($B$2:$B$38,B6,$D$2:$D$38) -> 1 | AC6: =IF(AA6<1,"BAD KEY",IF(S6="","MISSING COST",IF(U6=0,"REVIEW ADJUSTMENT",IF(AB6<>1,"CHECK SELECTION","OK")))) -> OK
A7: COST_PRIMARY_TX_B | B7: CC_PRIMARY_HTN_STATIN | C7: Option B | D7: 0 | E7: I_CVD_PRIMARY | F7: C_SHARED | G7: I_CVD_PRIMARY__C_SHARED | H7: Primary prevention of CVD | I7: Shared primary CVD cost | J7: Antihypertensives and statins for absolute CVD risk >20% | K7: all | L7: 0.3 | M7: USD per eligible person-year | N7: 1 | O7: 30 | P7: 95 | Q7: Both | R7: Health center | S7: 40.487719 | T7: 2023 | U7: 1 | V7: Tanzania | W7: cvd_unit_cost_indonesia_1_dm(2).xlsx | X7: row 18 | Y7: Alternative | Z7: Alternative salary-adjustment option | AA7: =COUNTIF(Intervention_Cause_Map!$I$2:$I$19,G7) -> 4 | AB7: =SUMIF($B$2:$B$38,B7,$D$2:$D$38) -> 1 | AC7: =IF(AA7<1,"BAD KEY",IF(S7="","MISSING COST",IF(U7=0,"REVIEW ADJUSTMENT",IF(AB7<>1,"CHECK SELECTION","OK")))) -> OK
A8: COST_IHD_SEC_CF_A | B8: CC_IHD_SECONDARY_CASE_FINDING | C8: Option A (selected) | D8: 1 | E8: I_IHD_SECONDARY | F8: C_IHD | G8: I_IHD_SECONDARY__C_IHD | H8: Secondary prevention of ischemic heart disease | I8: Ischemic heart disease | J8: Case finding and diagnosis | K8: incidence | L8: 0.52 | M8: USD per incident case | N8: 1 | O8: 30 | P8: 95 | Q8: Both | R8: Hospital | S8: 1e-07 | T8: 2023 | U8: 1 | V8: Tanzania | W8: cvd_unit_cost_indonesia_1_dm(2).xlsx | X8: row 43 | Y8: Review | Z8: Lower of two salary-adjustment options | AA8: =COUNTIF(Intervention_Cause_Map!$I$2:$I$19,G8) -> 1 | AB8: =SUMIF($B$2:$B$38,B8,$D$2:$D$38) -> 1 | AC8: =IF(AA8<1,"BAD KEY",IF(S8="","MISSING COST",IF(U8=0,"REVIEW ADJUSTMENT",IF(AB8<>1,"CHECK SELECTION","OK")))) -> OK
A9: COST_IHD_SEC_CF_B | B9: CC_IHD_SECONDARY_CASE_FINDING | C9: Option B | D9: 0 | E9: I_IHD_SECONDARY | F9: C_IHD | G9: I_IHD_SECONDARY__C_IHD | H9: Secondary prevention of ischemic heart disease | I9: Ischemic heart disease | J9: Case finding and diagnosis | K9: incidence | L9: 0.52 | M9: USD per incident case | N9: 1 | O9: 30 | P9: 95 | Q9: Both | R9: Hospital | S9: 1e-07 | T9: 2023 | U9: 1 | V9: Tanzania | W9: cvd_unit_cost_indonesia_1_dm(2).xlsx | X9: row 44 | Y9: Alternative | Z9: Alternative salary-adjustment option | AA9: =COUNTIF(Intervention_Cause_Map!$I$2:$I$19,G9) -> 1 | AB9: =SUMIF($B$2:$B$38,B9,$D$2:$D$38) -> 1 | AC9: =IF(AA9<1,"BAD KEY",IF(S9="","MISSING COST",IF(U9=0,"REVIEW ADJUSTMENT",IF(AB9<>1,"CHECK SELECTION","OK")))) -> OK
A10: COST_IHD_SEC_FU | B10: CC_IHD_SECONDARY_FOLLOWUP | C10: Base | D10: 1 | E10: I_IHD_SECONDARY | F10: C_IHD | G10: I_IHD_SECONDARY__C_IHD | H10: Secondary prevention of ischemic heart disease | I10: Ischemic heart disease | J10: Lab tests and follow-up visits for IHD patients | K10: prevalence | L10: 1 | M10: USD per patient-year | N10: 1 | O10: 30 | P10: 95 | Q10: Both | R10: Hospital | S10: 77.628668 | T10: 2023 | U10: 1 | V10: Tanzania | W10: cvd_unit_cost_indonesia_1_dm(2).xlsx | X10: rows 45–46 | Y10: Provisional | Z10: Source label referred to stroke; corrected to IHD for this mapping | AA10: =COUNTIF(Intervention_Cause_Map!$I$2:$I$19,G10) -> 1 | AB10: =SUMIF($B$2:$B$38,B10,$D$2:$D$38) -> 1 | AC10: =IF(AA10<1,"BAD KEY",IF(S10="","MISSING COST",IF(U10=0,"REVIEW ADJUSTMENT",IF(AB10<>1,"CHECK SELECTION","OK")))) -> OK
A11: COST_IHD_SEC_TX | B11: CC_IHD_SECONDARY_TREATMENT | C11: Base | D11: 1 | E11: I_IHD_SECONDARY | F11: C_IHD | G11: I_IHD_SECONDARY__C_IHD | H11: Secondary prevention of ischemic heart disease | I11: Ischemic heart disease | J11: Treatment cost for IHD patients | K11: prevalence | L11: 1 | M11: USD per patient-year | N11: 1 | O11: 30 | P11: 95 | Q11: Both | R11: Hospital | S11: 213.29057 | T11: 2023 | U11: 1 | V11: Brazil | W11: cvd_unit_cost_indonesia_1_dm(2).xlsx | X11: row 47 | Y11: Provisional | AA11: =COUNTIF(Intervention_Cause_Map!$I$2:$I$19,G11) -> 1 | AB11: =SUMIF($B$2:$B$38,B11,$D$2:$D$38) -> 1 | AC11: =IF(AA11<1,"BAD KEY",IF(S11="","MISSING COST",IF(U11=0,"REVIEW ADJUSTMENT",IF(AB11<>1,"CHECK SELECTION","OK")))) -> OK
A12: COST_STROKE_IS_CF | B12: CC_STROKE_IS_CASE_FINDING | C12: Base | D12: 1 | E12: I_STROKE_SECONDARY | F12: C_IS | G12: I_STROKE_SECONDARY__C_IS | H12: Secondary prevention of stroke | I12: Ischemic stroke | J12: Case finding and diagnosis | K12: incidence | L12: 0.52 | M12: USD per incident case | N12: 1 | O12: 30 | P12: 95 | Q12: Both | R12: Hospital | S12: 574.50204 | T12: 2023 | U12: 1 | V12: Brazil | W12: cvd_unit_cost_indonesia_1_dm(2).xlsx | X12: row 32 | Y12: Provisional | AA12: =COUNTIF(Intervention_Cause_Map!$I$2:$I$19,G12) -> 1 | AB12: =SUMIF($B$2:$B$38,B12,$D$2:$D$38) -> 1 | AC12: =IF(AA12<1,"BAD KEY",IF(S12="","MISSING COST",IF(U12=0,"REVIEW ADJUSTMENT",IF(AB12<>1,"CHECK SELECTION","OK")))) -> OK
A13: COST_STROKE_IS_LAB_A | B13: CC_STROKE_IS_FOLLOWUP | C13: Option A (selected) | D13: 1 | E13: I_STROKE_SECONDARY | F13: C_IS | G13: I_STROKE_SECONDARY__C_IS | H13: Secondary prevention of stroke | I13: Ischemic stroke | J13: Lab tests and follow-up visits | K13: prevalence | L13: 0.5 | M13: USD per patient-year | N13: 1 | O13: 30 | P13: 95 | Q13: Both | R13: Hospital | S13: 71.302158 | T13: 2023 | U13: 1 | V13: Tanzania | W13: cvd_unit_cost_indonesia_1_dm(2).xlsx | X13: row 37 | Y13: Review | Z13: Lower of two salary-adjustment options | AA13: =COUNTIF(Intervention_Cause_Map!$I$2:$I$19,G13) -> 1 | AB13: =SUMIF($B$2:$B$38,B13,$D$2:$D$38) -> 1 | AC13: =IF(AA13<1,"BAD KEY",IF(S13="","MISSING COST",IF(U13=0,"REVIEW ADJUSTMENT",IF(AB13<>1,"CHECK SELECTION","OK")))) -> OK
A14: COST_STROKE_IS_LAB_B | B14: CC_STROKE_IS_FOLLOWUP | C14: Option B | D14: 0 | E14: I_STROKE_SECONDARY | F14: C_IS | G14: I_STROKE_SECONDARY__C_IS | H14: Secondary prevention of stroke | I14: Ischemic stroke | J14: Lab tests and follow-up visits | K14: prevalence | L14: 0.5 | M14: USD per patient-year | N14: 1 | O14: 30 | P14: 95 | Q14: Both | R14: Hospital | S14: 64.943441 | T14: 2023 | U14: 1 | V14: Tanzania | W14: cvd_unit_cost_indonesia_1_dm(2).xlsx | X14: row 38 | Y14: Alternative | Z14: Alternative salary-adjustment option | AA14: =COUNTIF(Intervention_Cause_Map!$I$2:$I$19,G14) -> 1 | AB14: =SUMIF($B$2:$B$38,B14,$D$2:$D$38) -> 1 | AC14: =IF(AA14<1,"BAD KEY",IF(S14="","MISSING COST",IF(U14=0,"REVIEW ADJUSTMENT",IF(AB14<>1,"CHECK SELECTION","OK")))) -> OK
A15: COST_STROKE_IS_TX | B15: CC_STROKE_IS_TREATMENT | C15: Base | D15: 1 | E15: I_STROKE_SECONDARY | F15: C_IS | G15: I_STROKE_SECONDARY__C_IS | H15: Secondary prevention of stroke | I15: Ischemic stroke | J15: Treatment cost for stroke patients | K15: prevalence | L15: 0.5 | M15: USD per patient-year | N15: 1 | O15: 30 | P15: 95 | Q15: Both | R15: Hospital | S15: 172.27746 | T15: 2023 | U15: 1 | V15: Tanzania | W15: cvd_unit_cost_indonesia_1_dm(2).xlsx | X15: rows 41–42 | Y15: Provisional | AA15: =COUNTIF(Intervention_Cause_Map!$I$2:$I$19,G15) -> 1 | AB15: =SUMIF($B$2:$B$38,B15,$D$2:$D$38) -> 1 | AC15: =IF(AA15<1,"BAD KEY",IF(S15="","MISSING COST",IF(U15=0,"REVIEW ADJUSTMENT",IF(AB15<>1,"CHECK SELECTION","OK")))) -> OK
A16: COST_STROKE_ICH_CF_A | B16: CC_STROKE_ICH_CASE_FINDING | C16: Option A (selected) | D16: 1 | E16: I_STROKE_SECONDARY | F16: C_ICH | G16: I_STROKE_SECONDARY__C_ICH | H16: Secondary prevention of stroke | I16: Intracerebral hemorrhage | J16: Case finding and diagnosis | K16: incidence | L16: 0.52 | M16: USD per incident case | N16: 1 | O16: 30 | P16: 95 | Q16: Both | R16: Hospital | S16: 1035.0049 | T16: 2023 | U16: 1 | V16: Tanzania | W16: cvd_unit_cost_indonesia_1_dm(2).xlsx | X16: row 33 | Y16: Review | Z16: Lower of two salary-adjustment options | AA16: =COUNTIF(Intervention_Cause_Map!$I$2:$I$19,G16) -> 1 | AB16: =SUMIF($B$2:$B$38,B16,$D$2:$D$38) -> 1 | AC16: =IF(AA16<1,"BAD KEY",IF(S16="","MISSING COST",IF(U16=0,"REVIEW ADJUSTMENT",IF(AB16<>1,"CHECK SELECTION","OK")))) -> OK
A17: COST_STROKE_ICH_CF_B | B17: CC_STROKE_ICH_CASE_FINDING | C17: Option B | D17: 0 | E17: I_STROKE_SECONDARY | F17: C_ICH | G17: I_STROKE_SECONDARY__C_ICH | H17: Secondary prevention of stroke | I17: Intracerebral hemorrhage | J17: Case finding and diagnosis | K17: incidence | L17: 0.52 | M17: USD per incident case | N17: 1 | O17: 30 | P17: 95 | Q17: Both | R17: Hospital | S17: 900.25859 | T17: 2023 | U17: 1 | V17: Tanzania | W17: cvd_unit_cost_indonesia_1_dm(2).xlsx | X17: row 34 | Y17: Alternative | Z17: Alternative salary-adjustment option | AA17: =COUNTIF(Intervention_Cause_Map!$I$2:$I$19,G17) -> 1 | AB17: =SUMIF($B$2:$B$38,B17,$D$2:$D$38) -> 1 | AC17: =IF(AA17<1,"BAD KEY",IF(S17="","MISSING COST",IF(U17=0,"REVIEW ADJUSTMENT",IF(AB17<>1,"CHECK SELECTION","OK")))) -> OK
A18: COST_STROKE_ICH_LAB_A | B18: CC_STROKE_ICH_FOLLOWUP | C18: Option A (selected) | D18: 1 | E18: I_STROKE_SECONDARY | F18: C_ICH | G18: I_STROKE_SECONDARY__C_ICH | H18: Secondary prevention of stroke | I18: Intracerebral hemorrhage | J18: Lab tests and follow-up visits | K18: prevalence | L18: 0.5 | M18: USD per patient-year | N18: 1 | O18: 30 | P18: 95 | Q18: Both | R18: Hospital | S18: 56.227229 | T18: 2023 | U18: 1 | V18: Tanzania | W18: cvd_unit_cost_indonesia_1_dm(2).xlsx | X18: row 35 | Y18: Review | Z18: Lower of two salary-adjustment options | AA18: =COUNTIF(Intervention_Cause_Map!$I$2:$I$19,G18) -> 1 | AB18: =SUMIF($B$2:$B$38,B18,$D$2:$D$38) -> 1 | AC18: =IF(AA18<1,"BAD KEY",IF(S18="","MISSING COST",IF(U18=0,"REVIEW ADJUSTMENT",IF(AB18<>1,"CHECK SELECTION","OK")))) -> OK
A19: COST_STROKE_ICH_LAB_B | B19: CC_STROKE_ICH_FOLLOWUP | C19: Option B | D19: 0 | E19: I_STROKE_SECONDARY | F19: C_ICH | G19: I_STROKE_SECONDARY__C_ICH | H19: Secondary prevention of stroke | I19: Intracerebral hemorrhage | J19: Lab tests and follow-up visits | K19: prevalence | L19: 0.5 | M19: USD per patient-year | N19: 1 | O19: 30 | P19: 95 | Q19: Both | R19: Hospital | S19: 64.943441 | T19: 2023 | U19: 1 | V19: Tanzania | W19: cvd_unit_cost_indonesia_1_dm(2).xlsx | X19: row 36 | Y19: Alternative | Z19: Alternative salary-adjustment option | AA19: =COUNTIF(Intervention_Cause_Map!$I$2:$I$19,G19) -> 1 | AB19: =SUMIF($B$2:$B$38,B19,$D$2:$D$38) -> 1 | AC19: =IF(AA19<1,"BAD KEY",IF(S19="","MISSING COST",IF(U19=0,"REVIEW ADJUSTMENT",IF(AB19<>1,"CHECK SELECTION","OK")))) -> OK
A20: COST_STROKE_ICH_TX | B20: CC_STROKE_ICH_TREATMENT | C20: Base | D20: 1 | E20: I_STROKE_SECONDARY | F20: C_ICH | G20: I_STROKE_SECONDARY__C_ICH | H20: Secondary prevention of stroke | I20: Intracerebral hemorrhage | J20: Treatment cost for stroke patients | K20: prevalence | L20: 0.5 | M20: USD per patient-year | N20: 1 | O20: 30 | P20: 95 | Q20: Both | R20: Hospital | S20: 272.7886 | T20: 2023 | U20: 1 | V20: Tanzania | W20: cvd_unit_cost_indonesia_1_dm(2).xlsx | X20: rows 39–40 | Y20: Provisional | AA20: =COUNTIF(Intervention_Cause_Map!$I$2:$I$19,G20) -> 1 | AB20: =SUMIF($B$2:$B$38,B20,$D$2:$D$38) -> 1 | AC20: =IF(AA20<1,"BAD KEY",IF(S20="","MISSING COST",IF(U20=0,"REVIEW ADJUSTMENT",IF(AB20<>1,"CHECK SELECTION","OK")))) -> OK
A21: COST_HF_ACUTE_C_IHD | B21: CC_HF_ACUTE_C_IHD | C21: Base | D21: 1 | E21: I_HF_ACUTE | F21: C_IHD | G21: I_HF_ACUTE__C_IHD | H21: Acute heart-failure management | I21: Ischemic heart disease | J21: Acute heart-failure management package | K21: prevalence | L21: 0.1 | M21: USD per acute episode | N21: 1 | O21: 30 | P21: 95 | Q21: Both | R21: Hospital | S21: 575.48695 | T21: 2023 | U21: 1 | V21: Ghana | W21: cvd_unit_cost_indonesia_1_dm(2).xlsx | X21: row 4 | Y21: Provisional | AA21: =COUNTIF(Intervention_Cause_Map!$I$2:$I$19,G21) -> 1 | AB21: =SUMIF($B$2:$B$38,B21,$D$2:$D$38) -> 1 | AC21: =IF(AA21<1,"BAD KEY",IF(S21="","MISSING COST",IF(U21=0,"REVIEW ADJUSTMENT",IF(AB21<>1,"CHECK SELECTION","OK")))) -> OK
A22: COST_HF_ACUTE_C_HHD | B22: CC_HF_ACUTE_C_HHD | C22: Base | D22: 1 | E22: I_HF_ACUTE | F22: C_HHD | G22: I_HF_ACUTE__C_HHD | H22: Acute heart-failure management | I22: Hypertensive heart disease | J22: Acute heart-failure management package | K22: prevalence | L22: 0.5 | M22: USD per acute episode | N22: 1 | O22: 30 | P22: 95 | Q22: Both | R22: Hospital | S22: 575.48695 | T22: 2023 | U22: 1 | V22: Ghana | W22: cvd_unit_cost_indonesia_1_dm(2).xlsx | X22: row 3 | Y22: Provisional | AA22: =COUNTIF(Intervention_Cause_Map!$I$2:$I$19,G22) -> 1 | AB22: =SUMIF($B$2:$B$38,B22,$D$2:$D$38) -> 1 | AC22: =IF(AA22<1,"BAD KEY",IF(S22="","MISSING COST",IF(U22=0,"REVIEW ADJUSTMENT",IF(AB22<>1,"CHECK SELECTION","OK")))) -> OK
A23: COST_HF_ACUTE_C_CMP | B23: CC_HF_ACUTE_C_CMP | C23: Base | D23: 1 | E23: I_HF_ACUTE | F23: C_CMP | G23: I_HF_ACUTE__C_CMP | H23: Acute heart-failure management | I23: Cardiomyopathy and myocarditis | J23: Acute heart-failure management package | K23: prevalence | L23: 0.5 | M23: USD per acute episode | N23: 1 | O23: 30 | P23: 95 | Q23: Both | R23: Hospital | S23: 575.48695 | T23: 2023 | U23: 1 | V23: Ghana | W23: cvd_unit_cost_indonesia_1_dm(2).xlsx | X23: row 2 | Y23: Provisional | AA23: =COUNTIF(Intervention_Cause_Map!$I$2:$I$19,G23) -> 1 | AB23: =SUMIF($B$2:$B$38,B23,$D$2:$D$38) -> 1 | AC23: =IF(AA23<1,"BAD KEY",IF(S23="","MISSING COST",IF(U23=0,"REVIEW ADJUSTMENT",IF(AB23<>1,"CHECK SELECTION","OK")))) -> OK
A24: COST_HF_CHRONIC_CMP_ECHO | B24: CC_HF_CHRONIC_CMP_ECHO | C24: Base | D24: 1 | E24: I_HF_CHRONIC | F24: C_CMP | G24: I_HF_CHRONIC__C_CMP | H24: Chronic heart-failure management | I24: Cardiomyopathy and myocarditis | J24: One cardiac echo per year | K24: prevalence | L24: 1 | M24: USD per patient-year | N24: 1 | O24: 0 | P24: 95 | Q24: Both | R24: Hospital | S24: 5.133311 | T24: 2023 | U24: 1 | V24: Brazil | W24: cvd_unit_cost_indonesia_1_dm(2).xlsx | X24: row 19 | Y24: Provisional | AA24: =COUNTIF(Intervention_Cause_Map!$I$2:$I$19,G24) -> 1 | AB24: =SUMIF($B$2:$B$38,B24,$D$2:$D$38) -> 1 | AC24: =IF(AA24<1,"BAD KEY",IF(S24="","MISSING COST",IF(U24=0,"REVIEW ADJUSTMENT",IF(AB24<>1,"CHECK SELECTION","OK")))) -> OK
A25: COST_HF_CHRONIC_CMP_LAB_A | B25: CC_HF_CHRONIC_CMP_FOLLOWUP | C25: Option A (selected) | D25: 1 | E25: I_HF_CHRONIC | F25: C_CMP | G25: I_HF_CHRONIC__C_CMP | H25: Chronic heart-failure management | I25: Cardiomyopathy and myocarditis | J25: Lab tests and follow-up visits | K25: prevalence | L25: 1 | M25: USD per patient-year | N25: 1 | O25: 0 | P25: 95 | Q25: Both | R25: Hospital | S25: 69.384409 | T25: 2023 | U25: 1 | V25: Tanzania | W25: cvd_unit_cost_indonesia_1_dm(2).xlsx | X25: row 22 | Y25: Review | Z25: Lower of two salary-adjustment options | AA25: =COUNTIF(Intervention_Cause_Map!$I$2:$I$19,G25) -> 1 | AB25: =SUMIF($B$2:$B$38,B25,$D$2:$D$38) -> 1 | AC25: =IF(AA25<1,"BAD KEY",IF(S25="","MISSING COST",IF(U25=0,"REVIEW ADJUSTMENT",IF(AB25<>1,"CHECK SELECTION","OK")))) -> OK
A26: COST_HF_CHRONIC_CMP_LAB_B | B26: CC_HF_CHRONIC_CMP_FOLLOWUP | C26: Option B | D26: 0 | E26: I_HF_CHRONIC | F26: C_CMP | G26: I_HF_CHRONIC__C_CMP | H26: Chronic heart-failure management | I26: Cardiomyopathy and myocarditis | J26: Lab tests and follow-up visits | K26: prevalence | L26: 1 | M26: USD per patient-year | N26: 1 | O26: 0 | P26: 95 | Q26: Both | R26: Hospital | S26: 64.943441 | T26: 2023 | U26: 1 | V26: Tanzania | W26: cvd_unit_cost_indonesia_1_dm(2).xlsx | X26: row 23 | Y26: Alternative | Z26: Alternative salary-adjustment option | AA26: =COUNTIF(Intervention_Cause_Map!$I$2:$I$19,G26) -> 1 | AB26: =SUMIF($B$2:$B$38,B26,$D$2:$D$38) -> 1 | AC26: =IF(AA26<1,"BAD KEY",IF(S26="","MISSING COST",IF(U26=0,"REVIEW ADJUSTMENT",IF(AB26<>1,"CHECK SELECTION","OK")))) -> OK
A27: COST_HF_CHRONIC_CMP_TX | B27: CC_HF_CHRONIC_CMP_TREATMENT | C27: Base | D27: 1 | E27: I_HF_CHRONIC | F27: C_CMP | G27: I_HF_CHRONIC__C_CMP | H27: Chronic heart-failure management | I27: Cardiomyopathy and myocarditis | J27: Treatment of heart failure | K27: prevalence | L27: 1 | M27: USD per patient-year | N27: 1 | O27: 0 | P27: 95 | Q27: Both | R27: Hospital | S27: 152.88988 | T27: 2023 | U27: 1 | V27: Tanzania | W27: cvd_unit_cost_indonesia_1_dm(2).xlsx | X27: rows 26–27 | Y27: Provisional | AA27: =COUNTIF(Intervention_Cause_Map!$I$2:$I$19,G27) -> 1 | AB27: =SUMIF($B$2:$B$38,B27,$D$2:$D$38) -> 1 | AC27: =IF(AA27<1,"BAD KEY",IF(S27="","MISSING COST",IF(U27=0,"REVIEW ADJUSTMENT",IF(AB27<>1,"CHECK SELECTION","OK")))) -> OK
A28: COST_HF_CHRONIC_HHD_ECHO | B28: CC_HF_CHRONIC_HHD_ECHO | C28: Base | D28: 1 | E28: I_HF_CHRONIC | F28: C_HHD | G28: I_HF_CHRONIC__C_HHD | H28: Chronic heart-failure management | I28: Hypertensive heart disease | J28: One cardiac echo per year | K28: prevalence | L28: 1 | M28: USD per patient-year | N28: 1 | O28: 30 | P28: 95 | Q28: Both | R28: Hospital | S28: 5.133311 | T28: 2023 | U28: 1 | V28: Brazil | W28: cvd_unit_cost_indonesia_1_dm(2).xlsx | X28: row 20 | Y28: Provisional | AA28: =COUNTIF(Intervention_Cause_Map!$I$2:$I$19,G28) -> 1 | AB28: =SUMIF($B$2:$B$38,B28,$D$2:$D$38) -> 1 | AC28: =IF(AA28<1,"BAD KEY",IF(S28="","MISSING COST",IF(U28=0,"REVIEW ADJUSTMENT",IF(AB28<>1,"CHECK SELECTION","OK")))) -> OK
A29: COST_HF_CHRONIC_HHD_LAB_A | B29: CC_HF_CHRONIC_HHD_FOLLOWUP | C29: Option A (selected) | D29: 1 | E29: I_HF_CHRONIC | F29: C_HHD | G29: I_HF_CHRONIC__C_HHD | H29: Chronic heart-failure management | I29: Hypertensive heart disease | J29: Lab tests and follow-up visits | K29: prevalence | L29: 1 | M29: USD per patient-year | N29: 1 | O29: 30 | P29: 95 | Q29: Both | R29: Hospital | S29: 69.384409 | T29: 2023 | U29: 1 | V29: Tanzania | W29: cvd_unit_cost_indonesia_1_dm(2).xlsx | X29: row 24 | Y29: Review | Z29: Lower of two salary-adjustment options | AA29: =COUNTIF(Intervention_Cause_Map!$I$2:$I$19,G29) -> 1 | AB29: =SUMIF($B$2:$B$38,B29,$D$2:$D$38) -> 1 | AC29: =IF(AA29<1,"BAD KEY",IF(S29="","MISSING COST",IF(U29=0,"REVIEW ADJUSTMENT",IF(AB29<>1,"CHECK SELECTION","OK")))) -> OK
A30: COST_HF_CHRONIC_HHD_LAB_B | B30: CC_HF_CHRONIC_HHD_FOLLOWUP | C30: Option B | D30: 0 | E30: I_HF_CHRONIC | F30: C_HHD | G30: I_HF_CHRONIC__C_HHD | H30: Chronic heart-failure management | I30: Hypertensive heart disease | J30: Lab tests and follow-up visits | K30: prevalence | L30: 1 | M30: USD per patient-year | N30: 1 | O30: 30 | P30: 95 | Q30: Both | R30: Hospital | S30: 64.943441 | T30: 2023 | U30: 1 | V30: Tanzania | W30: cvd_unit_cost_indonesia_1_dm(2).xlsx | X30: row 25 | Y30: Alternative | Z30: Alternative salary-adjustment option | AA30: =COUNTIF(Intervention_Cause_Map!$I$2:$I$19,G30) -> 1 | AB30: =SUMIF($B$2:$B$38,B30,$D$2:$D$38) -> 1 | AC30: =IF(AA30<1,"BAD KEY",IF(S30="","MISSING COST",IF(U30=0,"REVIEW ADJUSTMENT",IF(AB30<>1,"CHECK SELECTION","OK")))) -> OK
A31: COST_HF_CHRONIC_HHD_TX | B31: CC_HF_CHRONIC_HHD_TREATMENT | C31: Base | D31: 1 | E31: I_HF_CHRONIC | F31: C_HHD | G31: I_HF_CHRONIC__C_HHD | H31: Chronic heart-failure management | I31: Hypertensive heart disease | J31: Treatment of heart failure | K31: prevalence | L31: 1 | M31: USD per patient-year | N31: 1 | O31: 0 | P31: 95 | Q31: Both | R31: Hospital | S31: 152.88988 | T31: 2023 | U31: 1 | V31: Tanzania | W31: cvd_unit_cost_indonesia_1_dm(2).xlsx | X31: rows 28–29 | Y31: Provisional | Z31: Source age starts at 0; verify against model eligibility | AA31: =COUNTIF(Intervention_Cause_Map!$I$2:$I$19,G31) -> 1 | AB31: =SUMIF($B$2:$B$38,B31,$D$2:$D$38) -> 1 | AC31: =IF(AA31<1,"BAD KEY",IF(S31="","MISSING COST",IF(U31=0,"REVIEW ADJUSTMENT",IF(AB31<>1,"CHECK SELECTION","OK")))) -> OK
A32: COST_HF_CHRONIC_IHD_ECHO | B32: CC_HF_CHRONIC_IHD_ECHO | C32: Base | D32: 1 | E32: I_HF_CHRONIC | F32: C_IHD | G32: I_HF_CHRONIC__C_IHD | H32: Chronic heart-failure management | I32: Ischemic heart disease | J32: One cardiac echo per year | K32: prevalence | L32: 0.2 | M32: USD per patient-year | N32: 1 | O32: 30 | P32: 95 | Q32: Both | R32: Hospital | S32: 5.133311 | T32: 2023 | U32: 1 | V32: Brazil | W32: cvd_unit_cost_indonesia_1_dm(2).xlsx | X32: row 21 | Y32: Provisional | AA32: =COUNTIF(Intervention_Cause_Map!$I$2:$I$19,G32) -> 1 | AB32: =SUMIF($B$2:$B$38,B32,$D$2:$D$38) -> 1 | AC32: =IF(AA32<1,"BAD KEY",IF(S32="","MISSING COST",IF(U32=0,"REVIEW ADJUSTMENT",IF(AB32<>1,"CHECK SELECTION","OK")))) -> OK
A33: COST_HF_CHRONIC_IHD_LAB | B33: CC_HF_CHRONIC_IHD_FOLLOWUP | C33: Missing | D33: 1 | E33: I_HF_CHRONIC | F33: C_IHD | G33: I_HF_CHRONIC__C_IHD | H33: Chronic heart-failure management | I33: Ischemic heart disease | J33: Lab tests and follow-up visits | K33: prevalence | L33: 0.2 | M33: USD per patient-year | N33: 1 | O33: 30 | P33: 95 | Q33: Both | R33: Hospital | S33: 69.384409 | T33: 2023 | U33: 1 | W33: cvd_unit_cost_indonesia_1_dm(2).xlsx | X33: not found | Y33: Missing input | Z33: No IHD-specific chronic HF follow-up cost identified in supplied adjusted cost file | AA33: =COUNTIF(Intervention_Cause_Map!$I$2:$I$19,G33) -> 1 | AB33: =SUMIF($B$2:$B$38,B33,$D$2:$D$38) -> 1 | AC33: =IF(AA33<1,"BAD KEY",IF(S33="","MISSING COST",IF(U33=0,"REVIEW ADJUSTMENT",IF(AB33<>1,"CHECK SELECTION","OK")))) -> OK
A34: COST_HF_CHRONIC_IHD_TX | B34: CC_HF_CHRONIC_IHD_TREATMENT | C34: Base | D34: 1 | E34: I_HF_CHRONIC | F34: C_IHD | G34: I_HF_CHRONIC__C_IHD | H34: Chronic heart-failure management | I34: Ischemic heart disease | J34: Treatment of heart failure | K34: prevalence | L34: 0.2 | M34: USD per patient-year | N34: 1 | O34: 30 | P34: 95 | Q34: Both | R34: Hospital | S34: 152.88988 | T34: 2023 | U34: 1 | V34: Tanzania | W34: cvd_unit_cost_indonesia_1_dm(2).xlsx | X34: rows 30–31 | Y34: Provisional | AA34: =COUNTIF(Intervention_Cause_Map!$I$2:$I$19,G34) -> 1 | AB34: =SUMIF($B$2:$B$38,B34,$D$2:$D$38) -> 1 | AC34: =IF(AA34<1,"BAD KEY",IF(S34="","MISSING COST",IF(U34=0,"REVIEW ADJUSTMENT",IF(AB34<>1,"CHECK SELECTION","OK")))) -> OK
A35: COST_T2D_SCREENING | B35: CC_T2D_SCREENING | C35: Base | D35: 1 | E35: I_T2D_TREATMENT | F35: C_T2D | G35: I_T2D_TREATMENT__C_T2D | H35: Longitudinal treatment of type 2 diabetes | I35: Diabetes mellitus type 2 | J35: Diabetes opportunistic screening | K35: all | L35: 1e-05 | M35: USD per eligible person-year | N35: 1 | O35: 30 | P35: 95 | Q35: Both | R35: Health center | S35: 0.70495848 | T35: 2023 | U35: 1 | V35: India | W35: cvd_unit_cost_indonesia_1_dm(2).xlsx | X35: row 50 | Y35: Provisional | Z35: Indonesia-adjusted Fair Choices unit cost; mapped to the updated PIN screening component | AA35: =COUNTIF(Intervention_Cause_Map!$I$2:$I$19,G35) -> 2 | AB35: =SUMIF($B$2:$B$38,B35,$D$2:$D$38) -> 1 | AC35: =IF(AA35<1,"BAD KEY",IF(S35="","MISSING COST",IF(U35=0,"REVIEW ADJUSTMENT",IF(AB35<>1,"CHECK SELECTION","OK")))) -> OK
A36: COST_T2D_NON_INSULIN | B36: CC_T2D_NON_INSULIN | C36: Base | D36: 1 | E36: I_T2D_TREATMENT | F36: C_T2D | G36: I_T2D_TREATMENT__C_T2D | H36: Longitudinal treatment of type 2 diabetes | I36: Diabetes mellitus type 2 | J36: Diabetes management, non-insulin dependent | K36: prevalence | L36: 0.6 | M36: USD per patient-year | N36: 1 | O36: 30 | P36: 95 | Q36: Both | R36: Health center | S36: 82.68 | T36: 2023 | U36: 1 | V36: Bangladesh | W36: cvd_unit_cost_indonesia_1_dm(2).xlsx | X36: row 51 | Y36: Provisional | Z36: Indonesia-adjusted Fair Choices unit cost; mapped to the updated PIN non-insulin component | AA36: =COUNTIF(Intervention_Cause_Map!$I$2:$I$19,G36) -> 2 | AB36: =SUMIF($B$2:$B$38,B36,$D$2:$D$38) -> 1 | AC36: =IF(AA36<1,"BAD KEY",IF(S36="","MISSING COST",IF(U36=0,"REVIEW ADJUSTMENT",IF(AB36<>1,"CHECK SELECTION","OK")))) -> OK
