Workbook

Sheet README
A1: Indonesia NCD model - public-health policy inputs
A3: Draft for review - tobacco and alcohol now use direct condition-specific risk responses; no cause-specific tobacco/alcohol PAF inputs
A5: Readiness | C5: Policies | E5: Risk exposures | G5: Policy-cause links
A6: =IF(COUNTIF(QA_Checks!$E$2:$E$16,"FAIL")=0,"READY TO RUN","REVIEW REQUIRED") -> REVIEW REQUIRED | C6: =COUNTA(Dictionaries!$A$2:$A$8) -> 7 | E6: =COUNTA(Dictionaries!$F$2:$F$6) -> 5 | G6: =COUNTA(Intervention_Cause_Map!$A$2:$A$29) -> 28
A9: How to use the workbook
A10: 1 | B10: Enter or update Indonesia baseline smoking prevalence, alcohol consumption, sodium intake, and TFA exposure. The SSB baseline is prefilled from GDD 2020 and remains editable.
A11: 2 | B11: Optionally override recommended exposure reductions or targets; otherwise the documented policy defaults are used. The SSB base case applies a 20% price increase and 17.5% demand reduction.
A12: 3 | B12: Policy_Levers shows how tax and component-policy parameters generate recommended exposure reductions, including Indonesia-specific SSB demand response.
A13: 4 | B13: Effects join through intervention_cause_key. Tobacco, alcohol, sodium, TFA, and SSB condition effects are assigned to well -> sick transitions; SSB direct RRs do not require a model PAF input.
A14: 5 | B14: Resolve remaining baseline-exposure, TFA PAF, tax-input, and cost-adjustment QA failures before model execution.
A17: Known review items retained explicitly
A18: Missing | B18: Indonesia baseline exposure for smoking, alcohol, sodium, and TFA
A19: Missing | B19: Indonesia tobacco tax share and WHO TFA policy score
A20: Resolved | B20: Tobacco/alcohol PAF placeholders replaced with direct intervention-condition links
A21: Resolved | B21: Sodium and TFA transitions assigned to well -> sick as requested
A22: Added | B22: SSB tax mapped to IHD, ischemic stroke, intracerebral hemorrhage, HHD, and type 2 diabetes
A23: Review | B23: SSB ICH and HHD mappings use transparent stroke and hypertension evidence proxies
A24: Caution | B24: IHD attributable to high blood glucose overlaps total IHD and is not linked separately to avoid double counting

Sheet Assumptions
A1: parameter_id | B1: value | C1: unit | D1: base_case | E1: lower_bound | F1: upper_bound | G1: description | H1: source
A2: analysis_start_year | B2: 2025 | C2: year | D2: 2025 | E2: 2025 | F2: 2026 | G2: First modeled year | H2: Indonesia model scope
A3: analysis_end_year | B3: 2050 | C3: year | D3: 2050 | E3: 2030 | F3: 2050 | G3: Last modeled year | H3: Indonesia model scope
A4: policy_start_year | B4: 2026 | C4: year | D4: 2026 | E4: 2025 | F4: 2030 | G4: First implementation year | H4: Working Countdown scenario; editable
A5: exposure_target_year | B5: 2030 | C5: year | D5: 2030 | E5: 2028 | F5: 2050 | G5: Year full exposure reduction is reached | H5: Working scenario; editable
A6: policy_cost_ramp_years | B6: 3 | C6: years | D6: 3 | E6: 1 | F6: 5 | G6: Years to full policy implementation cost | H6: NCD Countdown supplement p 34
A7: cost_discount_rate | B7: 0.03 | C7: proportion/year | D7: 0.03 | E7: 0 | F7: 0.05 | G7: Annual discount rate for costs | H7: Match clinical workbook
A8: health_discount_rate | B8: 0.03 | C8: proportion/year | D8: 0.03 | E8: 0 | F8: 0.05 | G8: Annual discount rate for health outcomes | H8: Match clinical workbook
A9: reporting_price_year | B9: 2023 | C9: USD year | D9: 2023 | E9: 2020 | F9: 2024 | G9: Target reporting price year | H9: Match clinical workbook
A10: source_cost_price_year | B10: 2017 | C10: USD year | D10: 2017 | E10: 2017 | F10: 2017 | G10: Price year in PINandCosts0625 | H10: PINandCosts0625(1).csv
A11: currency | B11: USD | C11: currency | D11: USD | E11: USD | F11: USD | G11: Reporting currency | H11: Working assumption
A12: scale_up_shape | B12: linear | C12: text | D12: linear | E12: linear | F12: linear | G12: Full reduction is phased in evenly from start through target year | H12: NCD Countdown supplement p 34
A13: economic_perspective | B13: health_system | C13: text | D13: health_system | E13: health_system | F13: societal | G13: Economic evaluation perspective | H13: NCD Countdown costing perspective
A14: tobacco_cvd_lag_rate | B14: 0.0616 | C14: annual fraction of remaining effect | D14: 0.0616 | E14: 0.04 | F14: 0.08 | G14: Exponential effect-realization rate reproducing approximately 47% of the full tobacco-CVD effect by year 10 | H14: Watkins 2022 supplement Figure A1; Duncan et al. 2019
A15: sodium_exposure_floor | B15: 3 | C15: g sodium/day | D15: 3 | E15: 3 | F15: 3 | G15: No additional benefit below this exposure | H15: NCD Countdown supplement p 33
A16: tfa_target_exposure | B16: 0 | C16: % energy | D16: 0 | E16: 0 | F16: 0.5 | G16: Target exposure under industrial trans-fat elimination | H16: NCD Countdown supplement pp 33-34
A17: constant_marginal_policy_cost | B17: 1 | C17: 0/1 flag | D17: 1 | E17: 0 | F17: 1 | G17: Assume policy cost is proportional to implementation | H17: NCD Countdown limitation
A18: grams_pure_alcohol_per_litre | B18: 789 | C18: g/L | D18: 789 | E18: 789 | F18: 789 | G18: Density conversion used for alcohol dose-response parameters | H18: Standard pure-ethanol conversion
A19: weeks_per_year | B19: 52 | C19: weeks/year | D19: 52 | E19: 52 | F19: 52.1775 | G19: Annualization factor for alcohol dose-response parameters | H19: Model convention
A20: ssb_tax_price_increase | B20: 0.2 | C20: relative price change | D20: 0.2 | E20: 0.1 | F20: 0.5 | G20: Counterfactual SSB retail-price increase under excise tax | H20: Attached: inline-supplementary-material-1.pdf; https://www.who.int/publications/i/item/9789240091016/
A21: ssb_price_elasticity_indonesia | B21: -0.875 | C21: own-price elasticity | D21: -0.875 | E21: -0.93 | F21: -0.715 | G21: Implied mean Indonesia elasticity: a 20% price increase reduces SSB demand 17.5%; group range 14.3%-18.6% | H21: https://doi.org/10.1371/journal.pone.0293913
A22: ssb_tax_pass_through_global | B22: 0.82 | C22: proportion | D22: 0.82 | E22: 0.66 | F22: 0.98 | G22: Implemented-tax meta-analysis reference; not multiplied into the Indonesia base case because the lever is parameterized as a retail-price increase | H22: https://doi.org/10.1001/jamanetworkopen.2022.15276
A23: ssb_price_elasticity_global | B23: -1.59 | C23: own-price elasticity | D23: -1.59 | E23: -2.11 | F23: -1.08 | G23: Global implemented-tax sales elasticity for sensitivity analysis | H23: https://doi.org/10.1001/jamanetworkopen.2022.15276

Sheet Dictionaries
A1: intervention_id | B1: intervention_name | C1: package_group | D1: definition | F1: risk_id | G1: risk_name | H1: exposure_measure | I1: exposure_unit | K1: cause_id | L1: cause_name | M1: model_name | N1: is_model_cause | O1: mapping_note
A2: I_PH_TOBACCO_TAX | B2: Tobacco tax | C2: Tobacco | D2: Excise and other tobacco taxes targeting at least 75% of final retail price | F2: R_SMOKING | G2: Smoking | H2: Smoking prevalence | I2: proportion | K2: C_RHD | L2: Rheumatic heart disease | M2: Rheumatic heart disease | N2: 1 | O2: No SSB mapping selected
A3: I_PH_ALCOHOL_TAX | B3: Alcohol tax | C3: Alcohol | D3: Excise tax producing a 25% total alcohol price increase | F3: R_ALCOHOL | G3: Alcohol use | H3: Alcohol consumption per adult | I3: litres pure alcohol/adult/year | K3: C_IHD | L3: Ischemic heart disease | M3: Ischemic heart disease | N3: 1 | O3: Direct tobacco, alcohol, sodium, and SSB mapping
A4: I_PH_TOBACCO_POLICY | B4: Tobacco policy | C4: Tobacco | D4: Clean-air law, mass media, and advertising bans | F4: R_SODIUM | G4: High sodium intake | H4: Mean sodium intake | I4: g sodium/day | K4: C_IS | L4: Ischemic stroke | M4: Ischemic stroke | N4: 1 | O4: Direct tobacco, alcohol, sodium, and SSB mapping
A5: I_PH_ALCOHOL_POLICY | B5: Alcohol policy | C5: Alcohol | D5: Alcohol advertising restrictions | F5: R_TFA | G5: Trans-fat intake | H5: Mean trans-fat intake | I5: % energy | K5: C_ICH | L5: Intracerebral hemorrhage | M5: Intracerebral hemorrhage | N5: 1 | O5: Direct tobacco/alcohol/sodium mapping; SSB uses total-stroke RR proxy
A6: I_PH_SALT_POLICY | B6: Salt policy | C6: Diet | D6: Reformulation, front-of-pack labelling, mass media, and enabling environments | F6: R_SSB | G6: Sugar-sweetened beverage intake | H6: Mean SSB intake | I6: 8 oz (248 g) servings/adult/day | K6: C_HHD | L6: Hypertensive heart disease | M6: Hypertensive heart disease | N6: 1 | O6: Direct alcohol/sodium mapping; SSB uses hypertension RR proxy
A7: I_PH_TFA_POLICY | B7: Trans fat policy | C7: Diet | D7: Best-practice policy to eliminate industrial trans fat | K7: C_CMYO | L7: Cardiomyopathy and myocarditis | M7: Cardiomyopathy and myocarditis | N7: 1 | O7: Direct alcohol mapping; no SSB mapping in Watkins raised-BMI cause set
A8: I_PH_SSB_TAX | B8: Sugar-sweetened beverage tax | C8: Diet | D8: Excise tax designed to increase the retail price of non-milk SSBs by 20% | K8: C_T2DM | L8: Diabetes mellitus type 2 | M8: Diabetes mellitus type 2 | N8: 1 | O8: Direct tobacco and SSB mapping
K9: C_IHD_HBG | L9: Ischemic heart disease attributable to high blood glucose | M9: Ischemic heart disease attributable to high blood glucose | N9: 1 | O9: Overlapping attributable component; do not add to total IHD without subtraction
K10: C_SHARED | L10: Shared policy cost | M10: Not a disease model; count cost once | N10: 0 | O10: Cost-only key

Sheet Intervention_Cause_Map
A1: intervention_cause_key | B1: intervention_id | C1: risk_id | D1: intervention_name | E1: risk_name | F1: cause_id | G1: cause_name | H1: effect_key | I1: exposure_key | J1: cost_join_key | K1: cost_scope | L1: transition_from | M1: transition_to | N1: include_flag | O1: requires_cause_expansion | P1: notes | Q1: duplicate_count
A2: I_PH_TOBACCO_TAX__C_IHD | B2: I_PH_TOBACCO_TAX | C2: R_SMOKING | D2: Tobacco tax | E2: Smoking | F2: C_IHD | G2: Ischemic heart disease | H2: I_PH_TOBACCO_TAX__C_IHD | I2: I_PH_TOBACCO_TAX | J2: I_PH_TOBACCO_TAX__C_SHARED | K2: shared-count-once | L2: well | M2: sick | N2: 1 | O2: 0 | P2: Direct prevalence-shift RR model; no cause PAF input | Q2: =COUNTIF($A$2:$A$29,A2) -> 1
A3: I_PH_TOBACCO_TAX__C_IS | B3: I_PH_TOBACCO_TAX | C3: R_SMOKING | D3: Tobacco tax | E3: Smoking | F3: C_IS | G3: Ischemic stroke | H3: I_PH_TOBACCO_TAX__C_IS | I3: I_PH_TOBACCO_TAX | J3: I_PH_TOBACCO_TAX__C_SHARED | K3: shared-count-once | L3: well | M3: sick | N3: 1 | O3: 0 | P3: Direct prevalence-shift RR model; no cause PAF input | Q3: =COUNTIF($A$2:$A$29,A3) -> 1
A4: I_PH_TOBACCO_TAX__C_ICH | B4: I_PH_TOBACCO_TAX | C4: R_SMOKING | D4: Tobacco tax | E4: Smoking | F4: C_ICH | G4: Intracerebral hemorrhage | H4: I_PH_TOBACCO_TAX__C_ICH | I4: I_PH_TOBACCO_TAX | J4: I_PH_TOBACCO_TAX__C_SHARED | K4: shared-count-once | L4: well | M4: sick | N4: 1 | O4: 0 | P4: Direct prevalence-shift RR model; no cause PAF input | Q4: =COUNTIF($A$2:$A$29,A4) -> 1
A5: I_PH_TOBACCO_TAX__C_T2DM | B5: I_PH_TOBACCO_TAX | C5: R_SMOKING | D5: Tobacco tax | E5: Smoking | F5: C_T2DM | G5: Diabetes mellitus type 2 | H5: I_PH_TOBACCO_TAX__C_T2DM | I5: I_PH_TOBACCO_TAX | J5: I_PH_TOBACCO_TAX__C_SHARED | K5: shared-count-once | L5: well | M5: sick | N5: 1 | O5: 0 | P5: Direct prevalence-shift RR model; no cause PAF input | Q5: =COUNTIF($A$2:$A$29,A5) -> 1
A6: I_PH_ALCOHOL_TAX__C_IHD | B6: I_PH_ALCOHOL_TAX | C6: R_ALCOHOL | D6: Alcohol tax | E6: Alcohol use | F6: C_IHD | G6: Ischemic heart disease | H6: I_PH_ALCOHOL_TAX__C_IHD | I6: I_PH_ALCOHOL_TAX | J6: I_PH_ALCOHOL_TAX__C_SHARED | K6: shared-count-once | L6: well | M6: sick | N6: 1 | O6: 0 | P6: Direct dose-response RR per litre/year; no cause PAF input | Q6: =COUNTIF($A$2:$A$29,A6) -> 1
A7: I_PH_ALCOHOL_TAX__C_IS | B7: I_PH_ALCOHOL_TAX | C7: R_ALCOHOL | D7: Alcohol tax | E7: Alcohol use | F7: C_IS | G7: Ischemic stroke | H7: I_PH_ALCOHOL_TAX__C_IS | I7: I_PH_ALCOHOL_TAX | J7: I_PH_ALCOHOL_TAX__C_SHARED | K7: shared-count-once | L7: well | M7: sick | N7: 1 | O7: 0 | P7: Direct dose-response RR per litre/year; no cause PAF input | Q7: =COUNTIF($A$2:$A$29,A7) -> 1
A8: I_PH_ALCOHOL_TAX__C_ICH | B8: I_PH_ALCOHOL_TAX | C8: R_ALCOHOL | D8: Alcohol tax | E8: Alcohol use | F8: C_ICH | G8: Intracerebral hemorrhage | H8: I_PH_ALCOHOL_TAX__C_ICH | I8: I_PH_ALCOHOL_TAX | J8: I_PH_ALCOHOL_TAX__C_SHARED | K8: shared-count-once | L8: well | M8: sick | N8: 1 | O8: 0 | P8: Direct dose-response RR per litre/year; no cause PAF input | Q8: =COUNTIF($A$2:$A$29,A8) -> 1
A9: I_PH_ALCOHOL_TAX__C_HHD | B9: I_PH_ALCOHOL_TAX | C9: R_ALCOHOL | D9: Alcohol tax | E9: Alcohol use | F9: C_HHD | G9: Hypertensive heart disease | H9: I_PH_ALCOHOL_TAX__C_HHD | I9: I_PH_ALCOHOL_TAX | J9: I_PH_ALCOHOL_TAX__C_SHARED | K9: shared-count-once | L9: well | M9: sick | N9: 1 | O9: 0 | P9: Direct dose-response RR per litre/year; no cause PAF input | Q9: =COUNTIF($A$2:$A$29,A9) -> 1
A10: I_PH_ALCOHOL_TAX__C_CMYO | B10: I_PH_ALCOHOL_TAX | C10: R_ALCOHOL | D10: Alcohol tax | E10: Alcohol use | F10: C_CMYO | G10: Cardiomyopathy and myocarditis | H10: I_PH_ALCOHOL_TAX__C_CMYO | I10: I_PH_ALCOHOL_TAX | J10: I_PH_ALCOHOL_TAX__C_SHARED | K10: shared-count-once | L10: well | M10: sick | N10: 1 | O10: 0 | P10: Direct dose-response RR per litre/year; no cause PAF input | Q10: =COUNTIF($A$2:$A$29,A10) -> 1
A11: I_PH_TOBACCO_POLICY__C_IHD | B11: I_PH_TOBACCO_POLICY | C11: R_SMOKING | D11: Tobacco policy | E11: Smoking | F11: C_IHD | G11: Ischemic heart disease | H11: I_PH_TOBACCO_POLICY__C_IHD | I11: I_PH_TOBACCO_POLICY | J11: I_PH_TOBACCO_POLICY__C_SHARED | K11: shared-count-once | L11: well | M11: sick | N11: 1 | O11: 0 | P11: Direct prevalence-shift RR model; no cause PAF input | Q11: =COUNTIF($A$2:$A$29,A11) -> 1
A12: I_PH_TOBACCO_POLICY__C_IS | B12: I_PH_TOBACCO_POLICY | C12: R_SMOKING | D12: Tobacco policy | E12: Smoking | F12: C_IS | G12: Ischemic stroke | H12: I_PH_TOBACCO_POLICY__C_IS | I12: I_PH_TOBACCO_POLICY | J12: I_PH_TOBACCO_POLICY__C_SHARED | K12: shared-count-once | L12: well | M12: sick | N12: 1 | O12: 0 | P12: Direct prevalence-shift RR model; no cause PAF input | Q12: =COUNTIF($A$2:$A$29,A12) -> 1
A13: I_PH_TOBACCO_POLICY__C_ICH | B13: I_PH_TOBACCO_POLICY | C13: R_SMOKING | D13: Tobacco policy | E13: Smoking | F13: C_ICH | G13: Intracerebral hemorrhage | H13: I_PH_TOBACCO_POLICY__C_ICH | I13: I_PH_TOBACCO_POLICY | J13: I_PH_TOBACCO_POLICY__C_SHARED | K13: shared-count-once | L13: well | M13: sick | N13: 1 | O13: 0 | P13: Direct prevalence-shift RR model; no cause PAF input | Q13: =COUNTIF($A$2:$A$29,A13) -> 1
... A29: I_PH_SSB_TAX__C_T2DM | B29: I_PH_SSB_TAX | C29: R_SSB | D29: Sugar-sweetened beverage tax | E29: Sugar-sweetened beverage intake | F29: C_T2DM | G29: Diabetes mellitus type 2 | H29: I_PH_SSB_TAX__C_T2DM | I29: I_PH_SSB_TAX | J29: I_PH_SSB_TAX__C_SHARED | K29: shared-count-once | L29: well | M29: sick | N29: 1 | O29: 0 | P29: Direct SSB RR per daily serving from Lara-Castor 2025; no model PAF required | Q29: =COUNTIF($A$2:$A$29,A29) -> 1

Sheet Policy_Levers
A1: lever_id | B1: intervention_id | C1: intervention_name | D1: component | E1: lever_method | F1: baseline_value | G1: target_value | H1: lever_unit | I1: effect_parameter | J1: effect_parameter_unit | K1: estimated_risk_reduction | L1: source | M1: review_status | N1: notes | O1: qa_status
A2: PL_TOB_TAX_SHARE | B2: I_PH_TOBACCO_TAX | C2: Tobacco tax | D2: Tax share of final retail price | E2: tax_share_to_price_elasticity | F2: 0.11 | G2: 0.75 | H2: proportion | I2: -0.48 | J2: price elasticity | K2: =IF(ISBLANK(F2),"",IF(E2="tax_share_to_price_elasticity",MIN(1,ABS(I2)*MAX(0,(1-F2)/(1-G2)-1)),IF(E2="price_elasticity",MIN(1,ABS(I2)*MAX(0,G2-F2)),IF(E2="coverage_gap_multiplicative",MIN(1,I2*MAX(0,G2-F2)),IF(E2="score_lookup",IF(F2<=2,1,IF(F2=3,0.297,0)),""))))) -> 1 | L2: NCD Countdown supplement p 32 | M2: Missing | N2: Enter Indonesia current tax share; target is the MPOWER 75% benchmark | O2: =IF(OR(ISBLANK(F2),ISBLANK(G2)),"MISSING INPUT",IF(G2<F2,"BAD TARGET","OK")) -> OK
A3: PL_ALC_PRICE | B3: I_PH_ALCOHOL_TAX | C3: Alcohol tax | D3: Total price increase | E3: price_elasticity | F3: 0.249 | G3: 0.25 | H3: relative price change | I3: -0.49 | J3: price elasticity | K3: =IF(ISBLANK(F3),"",IF(E3="tax_share_to_price_elasticity",MIN(1,ABS(I3)*MAX(0,(1-F3)/(1-G3)-1)),IF(E3="price_elasticity",MIN(1,ABS(I3)*MAX(0,G3-F3)),IF(E3="coverage_gap_multiplicative",MIN(1,I3*MAX(0,G3-F3)),IF(E3="score_lookup",IF(F3<=2,1,IF(F3=3,0.297,0)),""))))) -> 0.00049 | L3: NCD Countdown supplement p 31 | M3: Provisional | N3: Produces a 12.25% consumption reduction under constant elasticity | O3: =IF(OR(ISBLANK(F3),ISBLANK(G3)),"MISSING INPUT",IF(G3<F3,"BAD TARGET","OK")) -> OK
A4: PL_TOB_CLEAN_AIR | B4: I_PH_TOBACCO_POLICY | C4: Tobacco policy | D4: Smoking ban / clean-air law | E4: coverage_gap_multiplicative | F4: 0 | G4: 1 | H4: implementation proportion | I4: 0.11 | J4: relative exposure reduction | K4: =IF(ISBLANK(F4),"",IF(E4="tax_share_to_price_elasticity",MIN(1,ABS(I4)*MAX(0,(1-F4)/(1-G4)-1)),IF(E4="price_elasticity",MIN(1,ABS(I4)*MAX(0,G4-F4)),IF(E4="coverage_gap_multiplicative",MIN(1,I4*MAX(0,G4-F4)),IF(E4="score_lookup",IF(F4<=2,1,IF(F4=3,0.297,0)),""))))) -> 0.11 | L4: NCD Countdown supplement p 32 | M4: Review | N4: Replace provisional zero with Indonesia implementation level | O4: =IF(OR(ISBLANK(F4),ISBLANK(G4)),"MISSING INPUT",IF(G4<F4,"BAD TARGET","OK")) -> OK
A5: PL_TOB_MEDIA | B5: I_PH_TOBACCO_POLICY | C5: Tobacco policy | D5: Highly publicised mass media | E5: coverage_gap_multiplicative | F5: 0 | G5: 1 | H5: implementation proportion | I5: 0.065 | J5: relative exposure reduction | K5: =IF(ISBLANK(F5),"",IF(E5="tax_share_to_price_elasticity",MIN(1,ABS(I5)*MAX(0,(1-F5)/(1-G5)-1)),IF(E5="price_elasticity",MIN(1,ABS(I5)*MAX(0,G5-F5)),IF(E5="coverage_gap_multiplicative",MIN(1,I5*MAX(0,G5-F5)),IF(E5="score_lookup",IF(F5<=2,1,IF(F5=3,0.297,0)),""))))) -> 0.065 | L5: NCD Countdown supplement p 32 | M5: Review | N5: Replace provisional zero with Indonesia implementation level | O5: =IF(OR(ISBLANK(F5),ISBLANK(G5)),"MISSING INPUT",IF(G5<F5,"BAD TARGET","OK")) -> OK
A6: PL_TOB_AD_BAN | B6: I_PH_TOBACCO_POLICY | C6: Tobacco policy | D6: Advertising bans | E6: coverage_gap_multiplicative | F6: 0 | G6: 1 | H6: implementation proportion | I6: 0.04 | J6: relative exposure reduction | K6: =IF(ISBLANK(F6),"",IF(E6="tax_share_to_price_elasticity",MIN(1,ABS(I6)*MAX(0,(1-F6)/(1-G6)-1)),IF(E6="price_elasticity",MIN(1,ABS(I6)*MAX(0,G6-F6)),IF(E6="coverage_gap_multiplicative",MIN(1,I6*MAX(0,G6-F6)),IF(E6="score_lookup",IF(F6<=2,1,IF(F6=3,0.297,0)),""))))) -> 0.04 | L6: NCD Countdown supplement p 32 | M6: Review | N6: Replace provisional zero with Indonesia implementation level | O6: =IF(OR(ISBLANK(F6),ISBLANK(G6)),"MISSING INPUT",IF(G6<F6,"BAD TARGET","OK")) -> OK
A7: PL_ALC_AD_BAN | B7: I_PH_ALCOHOL_POLICY | C7: Alcohol policy | D7: Alcohol advertising ban | E7: coverage_gap_multiplicative | F7: 0.999 | G7: 1 | H7: implementation proportion | I7: 0.269 | J7: relative exposure reduction | K7: =IF(ISBLANK(F7),"",IF(E7="tax_share_to_price_elasticity",MIN(1,ABS(I7)*MAX(0,(1-F7)/(1-G7)-1)),IF(E7="price_elasticity",MIN(1,ABS(I7)*MAX(0,G7-F7)),IF(E7="coverage_gap_multiplicative",MIN(1,I7*MAX(0,G7-F7)),IF(E7="score_lookup",IF(F7<=2,1,IF(F7=3,0.297,0)),""))))) -> 0.000269 | L7: NCD Countdown supplement p 31 | M7: Review | N7: Replace provisional zero with Indonesia implementation level | O7: =IF(OR(ISBLANK(F7),ISBLANK(G7)),"MISSING INPUT",IF(G7<F7,"BAD TARGET","OK")) -> OK
A8: PL_SALT_REFORM | B8: I_PH_SALT_POLICY | C8: Salt policy | D8: Mandatory product reformulation | E8: coverage_gap_multiplicative | F8: 0 | G8: 1 | H8: implementation proportion | I8: 0.2 | J8: relative sodium reduction | K8: =IF(ISBLANK(F8),"",IF(E8="tax_share_to_price_elasticity",MIN(1,ABS(I8)*MAX(0,(1-F8)/(1-G8)-1)),IF(E8="price_elasticity",MIN(1,ABS(I8)*MAX(0,G8-F8)),IF(E8="coverage_gap_multiplicative",MIN(1,I8*MAX(0,G8-F8)),IF(E8="score_lookup",IF(F8<=2,1,IF(F8=3,0.297,0)),""))))) -> 0.2 | L8: NCD Countdown supplement p 33 | M8: Review | N8: Voluntary reformulation alternative is 15% | O8: =IF(OR(ISBLANK(F8),ISBLANK(G8)),"MISSING INPUT",IF(G8<F8,"BAD TARGET","OK")) -> OK
A9: PL_SALT_FOPL | B9: I_PH_SALT_POLICY | C9: Salt policy | D9: Front-of-pack labelling | E9: coverage_gap_multiplicative | F9: 0 | G9: 1 | H9: implementation proportion | I9: 0.1 | J9: relative sodium reduction | K9: =IF(ISBLANK(F9),"",IF(E9="tax_share_to_price_elasticity",MIN(1,ABS(I9)*MAX(0,(1-F9)/(1-G9)-1)),IF(E9="price_elasticity",MIN(1,ABS(I9)*MAX(0,G9-F9)),IF(E9="coverage_gap_multiplicative",MIN(1,I9*MAX(0,G9-F9)),IF(E9="score_lookup",IF(F9<=2,1,IF(F9=3,0.297,0)),""))))) -> 0.1 | L9: NCD Countdown supplement p 33 | M9: Review | N9: Replace provisional zero with Indonesia implementation level | O9: =IF(OR(ISBLANK(F9),ISBLANK(G9)),"MISSING INPUT",IF(G9<F9,"BAD TARGET","OK")) -> OK
A10: PL_SALT_MEDIA | B10: I_PH_SALT_POLICY | C10: Salt policy | D10: Mass-media campaign | E10: coverage_gap_multiplicative | F10: 0 | G10: 1 | H10: implementation proportion | I10: 0.05 | J10: relative sodium reduction | K10: =IF(ISBLANK(F10),"",IF(E10="tax_share_to_price_elasticity",MIN(1,ABS(I10)*MAX(0,(1-F10)/(1-G10)-1)),IF(E10="price_elasticity",MIN(1,ABS(I10)*MAX(0,G10-F10)),IF(E10="coverage_gap_multiplicative",MIN(1,I10*MAX(0,G10-F10)),IF(E10="score_lookup",IF(F10<=2,1,IF(F10=3,0.297,0)),""))))) -> 0.05 | L10: NCD Countdown supplement p 33 | M10: Review | N10: Replace provisional zero with Indonesia implementation level | O10: =IF(OR(ISBLANK(F10),ISBLANK(G10)),"MISSING INPUT",IF(G10<F10,"BAD TARGET","OK")) -> OK
A11: PL_SALT_ENV | B11: I_PH_SALT_POLICY | C11: Salt policy | D11: Supportive public-institution environment | E11: coverage_gap_multiplicative | F11: 0 | G11: 1 | H11: implementation proportion | I11: 0.07 | J11: relative sodium reduction | K11: =IF(ISBLANK(F11),"",IF(E11="tax_share_to_price_elasticity",MIN(1,ABS(I11)*MAX(0,(1-F11)/(1-G11)-1)),IF(E11="price_elasticity",MIN(1,ABS(I11)*MAX(0,G11-F11)),IF(E11="coverage_gap_multiplicative",MIN(1,I11*MAX(0,G11-F11)),IF(E11="score_lookup",IF(F11<=2,1,IF(F11=3,0.297,0)),""))))) -> 0.07 | L11: NCD Countdown supplement p 33 | M11: Review | N11: Replace provisional zero with Indonesia implementation level | O11: =IF(OR(ISBLANK(F11),ISBLANK(G11)),"MISSING INPUT",IF(G11<F11,"BAD TARGET","OK")) -> OK
A12: PL_TFA_SCORE | B12: I_PH_TFA_POLICY | C12: Trans fat policy | D12: WHO TFA policy score | E12: score_lookup | F12: 0 | G12: 4 | H12: score 0-4 | J12: TFA-attributable IHD death reduction | K12: =IF(ISBLANK(F12),"",IF(E12="tax_share_to_price_elasticity",MIN(1,ABS(I12)*MAX(0,(1-F12)/(1-G12)-1)),IF(E12="price_elasticity",MIN(1,ABS(I12)*MAX(0,G12-F12)),IF(E12="coverage_gap_multiplicative",MIN(1,I12*MAX(0,G12-F12)),IF(E12="score_lookup",IF(F12<=2,1,IF(F12=3,0.297,0)),""))))) -> 1 | L12: NCD Countdown supplement pp 33-34 | M12: Missing | N12: Enter current score: 0-2 => 100%, 3 => 29.7%, 4 => 0 additional effect | O12: =IF(OR(ISBLANK(F12),ISBLANK(G12)),"MISSING INPUT",IF(G12<F12,"BAD TARGET","OK")) -> OK
A13: PL_SSB_PRICE | B13: I_PH_SSB_TAX | C13: Sugar-sweetened beverage tax | D13: Retail price increase | E13: price_elasticity | F13: 0 | G13: =Assumptions!$B$20 -> 0.2 | H13: relative price change | I13: =Assumptions!$B$21 -> -0.875 | J13: own-price elasticity | K13: =IF(ISBLANK(F13),"",MIN(1,ABS(I13)*MAX(0,G13-F13))) -> 0.175 | L13: https://doi.org/10.1371/journal.pone.0293913; https://doi.org/10.1001/jamanetworkopen.2022.15276 | M13: Ready | N13: Indonesia 2021 SUSENAS demand model: a 20% price increase reduces mean SSB demand 17.5% (14.3%-18.6% by group). Global implemented-tax meta-analysis: 82% pass-through and sales elasticity -1.59 retained in Assumptions for sensitivity. | O13: =IF(OR(ISBLANK(F13),ISBLANK(G13)),"MISSING INPUT",IF(G13<F13,"BAD TARGET","OK")) -> OK

Sheet Exposure_Targets
A1: exposure_input_id | B1: intervention_id | C1: risk_id | D1: intervention_name | E1: risk_exposure_measure | F1: exposure_unit | G1: baseline_exposure | H1: reduction_method | I1: desired_reduction_override | J1: recommended_reduction_or_target | K1: applied_reduction_or_target | L1: exposure_floor | M1: target_exposure | N1: absolute_reduction | O1: relative_reduction | P1: start_year | Q1: target_year | R1: scale_up_shape | S1: source | T1: review_status | U1: qa_status
A2: EXP_TOB_TAX | B2: I_PH_TOBACCO_TAX | C2: R_SMOKING | D2: Tobacco tax | E2: Smoking prevalence | F2: proportion | G2: 0.303 | H2: relative | J2: =Policy_Levers!$K$2 -> 1 | K2: =IF(ISBLANK(I2),J2,I2) -> 1 | L2: 0 | M2: =IF(OR(ISBLANK(G2),ISBLANK(K2)),"",IF(H2="relative",MAX(L2,G2*(1-K2)),IF(H2="absolute",MAX(L2,G2-K2),IF(H2="target",MAX(L2,K2),"")))) -> 0 | N2: =IF(M2="","",G2-M2) -> 0.303 | O2: =IF(OR(G2="",G2=0,N2=""),"",N2/G2) -> 1 | P2: =Assumptions!$B$4 -> 2026 | Q2: =Assumptions!$B$5 -> 2030 | R2: linear | S2: User input + Countdown tax method | T2: Missing input | U2: =IF(ISBLANK(G2),"MISSING EXPOSURE",IF(ISBLANK(K2),"MISSING REDUCTION",IF(OR(M2<L2,M2>G2,Q2<P2),"BAD INPUT","OK"))) -> OK
A3: EXP_ALC_TAX | B3: I_PH_ALCOHOL_TAX | C3: R_ALCOHOL | D3: Alcohol tax | E3: Alcohol consumption per adult | F3: litres pure alcohol/adult/year | G3: 0.1 | H3: relative | J3: =Policy_Levers!$K$3 -> 0.00049 | K3: =IF(ISBLANK(I3),J3,I3) -> 0.00049 | L3: 0 | M3: =IF(OR(ISBLANK(G3),ISBLANK(K3)),"",IF(H3="relative",MAX(L3,G3*(1-K3)),IF(H3="absolute",MAX(L3,G3-K3),IF(H3="target",MAX(L3,K3),"")))) -> 0.099951 | N3: =IF(M3="","",G3-M3) -> 4.9e-05 | O3: =IF(OR(G3="",G3=0,N3=""),"",N3/G3) -> 0.00049 | P3: =Assumptions!$B$4 -> 2026 | Q3: =Assumptions!$B$5 -> 2030 | R3: linear | S3: User input + Countdown price elasticity | T3: Missing input | U3: =IF(ISBLANK(G3),"MISSING EXPOSURE",IF(ISBLANK(K3),"MISSING REDUCTION",IF(OR(M3<L3,M3>G3,Q3<P3),"BAD INPUT","OK"))) -> OK
A4: EXP_TOB_POLICY | B4: I_PH_TOBACCO_POLICY | C4: R_SMOKING | D4: Tobacco policy | E4: Smoking prevalence | F4: proportion | G4: 0.303 | H4: relative | J4: =1-(1-Policy_Levers!$K$4)*(1-Policy_Levers!$K$5)*(1-Policy_Levers!$K$6) -> 0.201136 | K4: =IF(ISBLANK(I4),J4,I4) -> 0.201136 | L4: 0 | M4: =IF(OR(ISBLANK(G4),ISBLANK(K4)),"",IF(H4="relative",MAX(L4,G4*(1-K4)),IF(H4="absolute",MAX(L4,G4-K4),IF(H4="target",MAX(L4,K4),"")))) -> 0.24205579 | N4: =IF(M4="","",G4-M4) -> 0.060944208 | O4: =IF(OR(G4="",G4=0,N4=""),"",N4/G4) -> 0.201136 | P4: =Assumptions!$B$4 -> 2026 | Q4: =Assumptions!$B$5 -> 2030 | R4: linear | S4: User input + Countdown SimSmoke effects | T4: Missing input | U4: =IF(ISBLANK(G4),"MISSING EXPOSURE",IF(ISBLANK(K4),"MISSING REDUCTION",IF(OR(M4<L4,M4>G4,Q4<P4),"BAD INPUT","OK"))) -> OK
A5: EXP_ALC_POLICY | B5: I_PH_ALCOHOL_POLICY | C5: R_ALCOHOL | D5: Alcohol policy | E5: Alcohol consumption per adult | F5: litres pure alcohol/adult/year | G5: 0.1 | H5: relative | J5: =Policy_Levers!$K$7 -> 0.000269 | K5: =IF(ISBLANK(I5),J5,I5) -> 0.000269 | L5: 0 | M5: =IF(OR(ISBLANK(G5),ISBLANK(K5)),"",IF(H5="relative",MAX(L5,G5*(1-K5)),IF(H5="absolute",MAX(L5,G5-K5),IF(H5="target",MAX(L5,K5),"")))) -> 0.0999731 | N5: =IF(M5="","",G5-M5) -> 2.69e-05 | O5: =IF(OR(G5="",G5=0,N5=""),"",N5/G5) -> 0.000269 | P5: =Assumptions!$B$4 -> 2026 | Q5: =Assumptions!$B$5 -> 2030 | R5: linear | S5: User input + Countdown Sheffield-model effect | T5: Missing input | U5: =IF(ISBLANK(G5),"MISSING EXPOSURE",IF(ISBLANK(K5),"MISSING REDUCTION",IF(OR(M5<L5,M5>G5,Q5<P5),"BAD INPUT","OK"))) -> OK
A6: EXP_SALT_POLICY | B6: I_PH_SALT_POLICY | C6: R_SODIUM | D6: Salt policy | E6: Mean sodium intake | F6: g sodium/day | G6: 4.4 | H6: relative | J6: =1-(1-Policy_Levers!$K$8)*(1-Policy_Levers!$K$9)*(1-Policy_Levers!$K$10)*(1-Policy_Levers!$K$11) -> 0.36388 | K6: =IF(ISBLANK(I6),J6,I6) -> 0.36388 | L6: =Assumptions!$B$15 -> 3 | M6: =IF(OR(ISBLANK(G6),ISBLANK(K6)),"",IF(H6="relative",MAX(L6,G6*(1-K6)),IF(H6="absolute",MAX(L6,G6-K6),IF(H6="target",MAX(L6,K6),"")))) -> 3 | N6: =IF(M6="","",G6-M6) -> 1.4 | O6: =IF(OR(G6="",G6=0,N6=""),"",N6/G6) -> 0.31818182 | P6: =Assumptions!$B$4 -> 2026 | Q6: =Assumptions!$B$5 -> 2030 | R6: linear | S6: User input + NCD Countdown supplement p 33 | T6: Missing input | U6: =IF(ISBLANK(G6),"MISSING EXPOSURE",IF(ISBLANK(K6),"MISSING REDUCTION",IF(OR(M6<L6,M6>G6,Q6<P6),"BAD INPUT","OK"))) -> OK
A7: EXP_TFA_POLICY | B7: I_PH_TFA_POLICY | C7: R_TFA | D7: Trans fat policy | E7: Mean trans-fat intake | F7: % energy | G7: 0.48 | H7: target | J7: =Assumptions!$B$16 -> 0 | K7: =IF(ISBLANK(I7),J7,I7) -> 0 | L7: 0 | M7: =IF(OR(ISBLANK(G7),ISBLANK(K7)),"",IF(H7="relative",MAX(L7,G7*(1-K7)),IF(H7="absolute",MAX(L7,G7-K7),IF(H7="target",MAX(L7,K7),"")))) -> 0 | N7: =IF(M7="","",G7-M7) -> 0.48 | O7: =IF(OR(G7="",G7=0,N7=""),"",N7/G7) -> 1 | P7: =Assumptions!$B$4 -> 2026 | Q7: =Assumptions!$B$5 -> 2030 | R7: linear | S7: User input + NCD Countdown supplement pp 33-34 | T7: Missing input | U7: =IF(ISBLANK(G7),"MISSING EXPOSURE",IF(ISBLANK(K7),"MISSING REDUCTION",IF(OR(M7<L7,M7>G7,Q7<P7),"BAD INPUT","OK"))) -> OK
A8: EXP_SSB_TAX | B8: I_PH_SSB_TAX | C8: R_SSB | D8: Sugar-sweetened beverage tax | E8: Mean SSB intake | F8: 8 oz (248 g) servings/adult/day | G8: 0.11428571 | H8: relative | J8: =Policy_Levers!$K$13 -> 0.175 | K8: =IF(ISBLANK(I8),J8,I8) -> 0.175 | L8: 0 | M8: =IF(OR(ISBLANK(G8),ISBLANK(K8)),"",IF(H8="relative",MAX(L8,G8*(1-K8)),IF(H8="absolute",MAX(L8,G8-K8),IF(H8="target",MAX(L8,K8),"")))) -> 0.094285714 | N8: =IF(M8="","",G8-M8) -> 0.02 | O8: =IF(OR(G8="",G8=0,N8=""),"",N8/G8) -> 0.175 | P8: =Assumptions!$B$4 -> 2026 | Q8: =Assumptions!$B$5 -> 2030 | R8: linear | S8: Lara-Castor et al. 2025 Supplementary Table 4 (https://doi.org/10.1038/s41591-024-03345-4); Widarjono et al. 2023 (https://doi.org/10.1371/journal.pone.0293913) | T8: Base exposure is GDD 2020 adult mean (0.8 servings/week); tax response is Indonesia-specific. Replace baseline if a newer comparable intake series is selected. | U8: =IF(ISBLANK(G8),"MISSING EXPOSURE",IF(ISBLANK(K8),"MISSING REDUCTION",IF(OR(M8<L8,M8>G8,Q8<P8),"BAD INPUT","OK"))) -> OK

Sheet Effect_Parameters
A1: effect_id | B1: intervention_cause_key | C1: intervention_id | D1: risk_id | E1: cause_id | F1: effect_model | G1: response_key | H1: response_parameter | I1: response_value | J1: response_unit | K1: paf_value | L1: paf_required_flag | M1: paf_threshold | N1: lag_model | O1: lag_parameter | P1: transition_from | Q1: transition_to | R1: source_file | S1: source_location | T1: review_status | U1: notes | V1: map_match_count | W1: qa_status
A2: EFF_01 | B2: I_PH_TOBACCO_TAX__C_IHD | C2: I_PH_TOBACCO_TAX | D2: R_SMOKING | E2: C_IHD | F2: direct_smoking_prevalence_shift_rr | G2: RR_SMOKING_IHD | H2: RR current smoker vs non-smoker | I2: =INDEX(Risk_Response!$L$2:$L$18,MATCH(G2,Risk_Response!$A$2:$A$18,0)) -> 1.6 | J2: relative risk | L2: 0 | N2: delayed_exponential_remaining_effect | O2: =Risk_Response!$L$11 -> 0.061514457 | P2: well | Q2: sick | R2: Asia Pacific Cohort Studies Collaboration 2005 | S2: https://doi.org/10.1093/ije/dyi104 | T2: Ready | U2: Direct incidence effect from smoking prevalence and cause-specific RR; no PAF input. Tobacco lag follows the Countdown delayed-effect structure. | V2: =COUNTIF(Intervention_Cause_Map!$A$2:$A$29,B2) -> 1 | W2: =IF(V2<>1,"MAP ERROR",IF(P2<>"well","REVIEW TRANSITION",IF(Q2<>"sick","REVIEW TRANSITION",IF(AND(L2=1,OR(K2="",K2<0,K2>1)),"MISSING PAF",IF(R2="","MISSING SOURCE","OK"))))) -> OK
A3: EFF_02 | B3: I_PH_TOBACCO_TAX__C_IS | C3: I_PH_TOBACCO_TAX | D3: R_SMOKING | E3: C_IS | F3: direct_smoking_prevalence_shift_rr | G3: RR_SMOKING_IS | H3: RR current smoker vs non-smoker | I3: =INDEX(Risk_Response!$L$2:$L$18,MATCH(G3,Risk_Response!$A$2:$A$18,0)) -> 1.38 | J3: relative risk | L3: 0 | N3: delayed_exponential_remaining_effect | O3: =Risk_Response!$L$11 -> 0.061514457 | P3: well | Q3: sick | R3: Asia Pacific Cohort Studies Collaboration 2005 | S3: https://doi.org/10.1093/ije/dyi104 | T3: Ready | U3: Direct incidence effect from smoking prevalence and cause-specific RR; no PAF input. Tobacco lag follows the Countdown delayed-effect structure. | V3: =COUNTIF(Intervention_Cause_Map!$A$2:$A$29,B3) -> 1 | W3: =IF(V3<>1,"MAP ERROR",IF(P3<>"well","REVIEW TRANSITION",IF(Q3<>"sick","REVIEW TRANSITION",IF(AND(L3=1,OR(K3="",K3<0,K3>1)),"MISSING PAF",IF(R3="","MISSING SOURCE","OK"))))) -> OK
A4: EFF_03 | B4: I_PH_TOBACCO_TAX__C_ICH | C4: I_PH_TOBACCO_TAX | D4: R_SMOKING | E4: C_ICH | F4: direct_smoking_prevalence_shift_rr | G4: RR_SMOKING_ICH | H4: RR current smoker vs non-smoker | I4: =INDEX(Risk_Response!$L$2:$L$18,MATCH(G4,Risk_Response!$A$2:$A$18,0)) -> 1.19 | J4: relative risk | L4: 0 | N4: delayed_exponential_remaining_effect | O4: =Risk_Response!$L$11 -> 0.061514457 | P4: well | Q4: sick | R4: Asia Pacific Cohort Studies Collaboration 2005 | S4: https://doi.org/10.1093/ije/dyi104 | T4: Ready | U4: Direct incidence effect from smoking prevalence and cause-specific RR; no PAF input. Tobacco lag follows the Countdown delayed-effect structure. | V4: =COUNTIF(Intervention_Cause_Map!$A$2:$A$29,B4) -> 1 | W4: =IF(V4<>1,"MAP ERROR",IF(P4<>"well","REVIEW TRANSITION",IF(Q4<>"sick","REVIEW TRANSITION",IF(AND(L4=1,OR(K4="",K4<0,K4>1)),"MISSING PAF",IF(R4="","MISSING SOURCE","OK"))))) -> OK
A5: EFF_04 | B5: I_PH_TOBACCO_TAX__C_T2DM | C5: I_PH_TOBACCO_TAX | D5: R_SMOKING | E5: C_T2DM | F5: direct_smoking_prevalence_shift_rr | G5: RR_SMOKING_T2DM | H5: RR current smoker vs non-smoker | I5: =INDEX(Risk_Response!$L$2:$L$18,MATCH(G5,Risk_Response!$A$2:$A$18,0)) -> 1.37 | J5: relative risk | L5: 0 | N5: delayed_exponential_remaining_effect | O5: =Risk_Response!$L$12 -> 0.061514457 | P5: well | Q5: sick | R5: Pan et al. 2015 | S5: https://doi.org/10.1016/S2213-8587(15)00316-2 | T5: Provisional lag proxy | U5: Direct incidence effect from smoking prevalence and cause-specific RR; no PAF input. Tobacco lag follows the Countdown delayed-effect structure. | V5: =COUNTIF(Intervention_Cause_Map!$A$2:$A$29,B5) -> 1 | W5: =IF(V5<>1,"MAP ERROR",IF(P5<>"well","REVIEW TRANSITION",IF(Q5<>"sick","REVIEW TRANSITION",IF(AND(L5=1,OR(K5="",K5<0,K5>1)),"MISSING PAF",IF(R5="","MISSING SOURCE","OK"))))) -> OK
A6: EFF_05 | B6: I_PH_ALCOHOL_TAX__C_IHD | C6: I_PH_ALCOHOL_TAX | D6: R_ALCOHOL | E6: C_IHD | F6: direct_loglinear_rr_per_unit_reduction | G6: RR_ALCOHOL_IHD_1L | H6: RR per 1 L pure alcohol/adult/year | I6: =INDEX(Risk_Response!$L$2:$L$18,MATCH(G6,Risk_Response!$A$2:$A$18,0)) -> 1.0088804 | J6: relative risk | L6: 0 | N6: immediate_after_full_implementation | O6: 1 | P6: well | Q6: sick | R6: Wood et al. 2018 | S6: https://doi.org/10.1016/S0140-6736(18)30134-X | T6: Provisional proxy | U6: Direct incidence effect from alcohol reduction and cause-specific dose-response RR; no PAF input. See Risk_Response for source-to-model conversion and proxy notes. | V6: =COUNTIF(Intervention_Cause_Map!$A$2:$A$29,B6) -> 1 | W6: =IF(V6<>1,"MAP ERROR",IF(P6<>"well","REVIEW TRANSITION",IF(Q6<>"sick","REVIEW TRANSITION",IF(AND(L6=1,OR(K6="",K6<0,K6>1)),"MISSING PAF",IF(R6="","MISSING SOURCE","OK"))))) -> OK
A7: EFF_06 | B7: I_PH_ALCOHOL_TAX__C_IS | C7: I_PH_ALCOHOL_TAX | D7: R_ALCOHOL | E7: C_IS | F7: direct_loglinear_rr_per_unit_reduction | G7: RR_ALCOHOL_IS_1L | H7: RR per 1 L pure alcohol/adult/year | I7: =INDEX(Risk_Response!$L$2:$L$18,MATCH(G7,Risk_Response!$A$2:$A$18,0)) -> 1.02008 | J7: relative risk | L7: 0 | N7: immediate_after_full_implementation | O7: 1 | P7: well | Q7: sick | R7: Wood et al. 2018 | S7: https://doi.org/10.1016/S0140-6736(18)30134-X | T7: Provisional proxy | U7: Direct incidence effect from alcohol reduction and cause-specific dose-response RR; no PAF input. See Risk_Response for source-to-model conversion and proxy notes. | V7: =COUNTIF(Intervention_Cause_Map!$A$2:$A$29,B7) -> 1 | W7: =IF(V7<>1,"MAP ERROR",IF(P7<>"well","REVIEW TRANSITION",IF(Q7<>"sick","REVIEW TRANSITION",IF(AND(L7=1,OR(K7="",K7<0,K7>1)),"MISSING PAF",IF(R7="","MISSING SOURCE","OK"))))) -> OK
A8: EFF_07 | B8: I_PH_ALCOHOL_TAX__C_ICH | C8: I_PH_ALCOHOL_TAX | D8: R_ALCOHOL | E8: C_ICH | F8: direct_loglinear_rr_per_unit_reduction | G8: RR_ALCOHOL_ICH_1L | H8: RR per 1 L pure alcohol/adult/year | I8: =INDEX(Risk_Response!$L$2:$L$18,MATCH(G8,Risk_Response!$A$2:$A$18,0)) -> 1.02008 | J8: relative risk | L8: 0 | N8: immediate_after_full_implementation | O8: 1 | P8: well | Q8: sick | R8: Wood et al. 2018 | S8: https://doi.org/10.1016/S0140-6736(18)30134-X | T8: Provisional proxy | U8: Direct incidence effect from alcohol reduction and cause-specific dose-response RR; no PAF input. See Risk_Response for source-to-model conversion and proxy notes. | V8: =COUNTIF(Intervention_Cause_Map!$A$2:$A$29,B8) -> 1 | W8: =IF(V8<>1,"MAP ERROR",IF(P8<>"well","REVIEW TRANSITION",IF(Q8<>"sick","REVIEW TRANSITION",IF(AND(L8=1,OR(K8="",K8<0,K8>1)),"MISSING PAF",IF(R8="","MISSING SOURCE","OK"))))) -> OK
A9: EFF_08 | B9: I_PH_ALCOHOL_TAX__C_HHD | C9: I_PH_ALCOHOL_TAX | D9: R_ALCOHOL | E9: C_HHD | F9: direct_loglinear_rr_per_unit_reduction | G9: RR_ALCOHOL_HHD_1L | H9: RR per 1 L pure alcohol/adult/year | I9: =INDEX(Risk_Response!$L$2:$L$18,MATCH(G9,Risk_Response!$A$2:$A$18,0)) -> 1.0331775 | J9: relative risk | L9: 0 | N9: immediate_after_full_implementation | O9: 1 | P9: well | Q9: sick | R9: Wood et al. 2018 | S9: https://doi.org/10.1016/S0140-6736(18)30134-X | T9: Ready | U9: Direct incidence effect from alcohol reduction and cause-specific dose-response RR; no PAF input. See Risk_Response for source-to-model conversion and proxy notes. | V9: =COUNTIF(Intervention_Cause_Map!$A$2:$A$29,B9) -> 1 | W9: =IF(V9<>1,"MAP ERROR",IF(P9<>"well","REVIEW TRANSITION",IF(Q9<>"sick","REVIEW TRANSITION",IF(AND(L9=1,OR(K9="",K9<0,K9>1)),"MISSING PAF",IF(R9="","MISSING SOURCE","OK"))))) -> OK
A10: EFF_09 | B10: I_PH_ALCOHOL_TAX__C_CMYO | C10: I_PH_ALCOHOL_TAX | D10: R_ALCOHOL | E10: C_CMYO | F10: direct_loglinear_rr_per_unit_reduction | G10: RR_ALCOHOL_CMYO_1L | H10: RR per 1 L pure alcohol/adult/year | I10: =INDEX(Risk_Response!$L$2:$L$18,MATCH(G10,Risk_Response!$A$2:$A$18,0)) -> 1.0131617 | J10: relative risk | L10: 0 | N10: immediate_after_full_implementation | O10: 1 | P10: well | Q10: sick | R10: Wood et al. 2018 | S10: https://doi.org/10.1016/S0140-6736(18)30134-X | T10: Provisional proxy | U10: Direct incidence effect from alcohol reduction and cause-specific dose-response RR; no PAF input. See Risk_Response for source-to-model conversion and proxy notes. | V10: =COUNTIF(Intervention_Cause_Map!$A$2:$A$29,B10) -> 1 | W10: =IF(V10<>1,"MAP ERROR",IF(P10<>"well","REVIEW TRANSITION",IF(Q10<>"sick","REVIEW TRANSITION",IF(AND(L10=1,OR(K10="",K10<0,K10>1)),"MISSING PAF",IF(R10="","MISSING SOURCE","OK"))))) -> OK
A11: EFF_10 | B11: I_PH_TOBACCO_POLICY__C_IHD | C11: I_PH_TOBACCO_POLICY | D11: R_SMOKING | E11: C_IHD | F11: direct_smoking_prevalence_shift_rr | G11: RR_SMOKING_IHD | H11: RR current smoker vs non-smoker | I11: =INDEX(Risk_Response!$L$2:$L$18,MATCH(G11,Risk_Response!$A$2:$A$18,0)) -> 1.6 | J11: relative risk | L11: 0 | N11: delayed_exponential_remaining_effect | O11: =Risk_Response!$L$11 -> 0.061514457 | P11: well | Q11: sick | R11: Asia Pacific Cohort Studies Collaboration 2005 | S11: https://doi.org/10.1093/ije/dyi104 | T11: Ready | U11: Direct incidence effect from smoking prevalence and cause-specific RR; no PAF input. Tobacco lag follows the Countdown delayed-effect structure. | V11: =COUNTIF(Intervention_Cause_Map!$A$2:$A$29,B11) -> 1 | W11: =IF(V11<>1,"MAP ERROR",IF(P11<>"well","REVIEW TRANSITION",IF(Q11<>"sick","REVIEW TRANSITION",IF(AND(L11=1,OR(K11="",K11<0,K11>1)),"MISSING PAF",IF(R11="","MISSING SOURCE","OK"))))) -> OK
A12: EFF_11 | B12: I_PH_TOBACCO_POLICY__C_IS | C12: I_PH_TOBACCO_POLICY | D12: R_SMOKING | E12: C_IS | F12: direct_smoking_prevalence_shift_rr | G12: RR_SMOKING_IS | H12: RR current smoker vs non-smoker | I12: =INDEX(Risk_Response!$L$2:$L$18,MATCH(G12,Risk_Response!$A$2:$A$18,0)) -> 1.38 | J12: relative risk | L12: 0 | N12: delayed_exponential_remaining_effect | O12: =Risk_Response!$L$11 -> 0.061514457 | P12: well | Q12: sick | R12: Asia Pacific Cohort Studies Collaboration 2005 | S12: https://doi.org/10.1093/ije/dyi104 | T12: Ready | U12: Direct incidence effect from smoking prevalence and cause-specific RR; no PAF input. Tobacco lag follows the Countdown delayed-effect structure. | V12: =COUNTIF(Intervention_Cause_Map!$A$2:$A$29,B12) -> 1 | W12: =IF(V12<>1,"MAP ERROR",IF(P12<>"well","REVIEW TRANSITION",IF(Q12<>"sick","REVIEW TRANSITION",IF(AND(L12=1,OR(K12="",K12<0,K12>1)),"MISSING PAF",IF(R12="","MISSING SOURCE","OK"))))) -> OK
A13: EFF_12 | B13: I_PH_TOBACCO_POLICY__C_ICH | C13: I_PH_TOBACCO_POLICY | D13: R_SMOKING | E13: C_ICH | F13: direct_smoking_prevalence_shift_rr | G13: RR_SMOKING_ICH | H13: RR current smoker vs non-smoker | I13: =INDEX(Risk_Response!$L$2:$L$18,MATCH(G13,Risk_Response!$A$2:$A$18,0)) -> 1.19 | J13: relative risk | L13: 0 | N13: delayed_exponential_remaining_effect | O13: =Risk_Response!$L$11 -> 0.061514457 | P13: well | Q13: sick | R13: Asia Pacific Cohort Studies Collaboration 2005 | S13: https://doi.org/10.1093/ije/dyi104 | T13: Ready | U13: Direct incidence effect from smoking prevalence and cause-specific RR; no PAF input. Tobacco lag follows the Countdown delayed-effect structure. | V13: =COUNTIF(Intervention_Cause_Map!$A$2:$A$29,B13) -> 1 | W13: =IF(V13<>1,"MAP ERROR",IF(P13<>"well","REVIEW TRANSITION",IF(Q13<>"sick","REVIEW TRANSITION",IF(AND(L13=1,OR(K13="",K13<0,K13>1)),"MISSING PAF",IF(R13="","MISSING SOURCE","OK"))))) -> OK
A14: EFF_13 | B14: I_PH_TOBACCO_POLICY__C_T2DM | C14: I_PH_TOBACCO_POLICY | D14: R_SMOKING | E14: C_T2DM | F14: direct_smoking_prevalence_shift_rr | G14: RR_SMOKING_T2DM | H14: RR current smoker vs non-smoker | I14: =INDEX(Risk_Response!$L$2:$L$18,MATCH(G14,Risk_Response!$A$2:$A$18,0)) -> 1.37 | J14: relative risk | L14: 0 | N14: delayed_exponential_remaining_effect | O14: =Risk_Response!$L$12 -> 0.061514457 | P14: well | Q14: sick | R14: Pan et al. 2015 | S14: https://doi.org/10.1016/S2213-8587(15)00316-2 | T14: Provisional lag proxy | U14: Direct incidence effect from smoking prevalence and cause-specific RR; no PAF input. Tobacco lag follows the Countdown delayed-effect structure. | V14: =COUNTIF(Intervention_Cause_Map!$A$2:$A$29,B14) -> 1 | W14: =IF(V14<>1,"MAP ERROR",IF(P14<>"well","REVIEW TRANSITION",IF(Q14<>"sick","REVIEW TRANSITION",IF(AND(L14=1,OR(K14="",K14<0,K14>1)),"MISSING PAF",IF(R14="","MISSING SOURCE","OK"))))) -> OK
A15: EFF_14 | B15: I_PH_ALCOHOL_POLICY__C_IHD | C15: I_PH_ALCOHOL_POLICY | D15: R_ALCOHOL | E15: C_IHD | F15: direct_loglinear_rr_per_unit_reduction | G15: RR_ALCOHOL_IHD_1L | H15: RR per 1 L pure alcohol/adult/year | I15: =INDEX(Risk_Response!$L$2:$L$18,MATCH(G15,Risk_Response!$A$2:$A$18,0)) -> 1.0088804 | J15: relative risk | L15: 0 | N15: immediate_after_full_implementation | O15: 1 | P15: well | Q15: sick | R15: Wood et al. 2018 | S15: https://doi.org/10.1016/S0140-6736(18)30134-X | T15: Provisional proxy | U15: Direct incidence effect from alcohol reduction and cause-specific dose-response RR; no PAF input. See Risk_Response for source-to-model conversion and proxy notes. | V15: =COUNTIF(Intervention_Cause_Map!$A$2:$A$29,B15) -> 1 | W15: =IF(V15<>1,"MAP ERROR",IF(P15<>"well","REVIEW TRANSITION",IF(Q15<>"sick","REVIEW TRANSITION",IF(AND(L15=1,OR(K15="",K15<0,K15>1)),"MISSING PAF",IF(R15="","MISSING SOURCE","OK"))))) -> OK
A16: EFF_15 | B16: I_PH_ALCOHOL_POLICY__C_IS | C16: I_PH_ALCOHOL_POLICY | D16: R_ALCOHOL | E16: C_IS | F16: direct_loglinear_rr_per_unit_reduction | G16: RR_ALCOHOL_IS_1L | H16: RR per 1 L pure alcohol/adult/year | I16: =INDEX(Risk_Response!$L$2:$L$18,MATCH(G16,Risk_Response!$A$2:$A$18,0)) -> 1.02008 | J16: relative risk | L16: 0 | N16: immediate_after_full_implementation | O16: 1 | P16: well | Q16: sick | R16: Wood et al. 2018 | S16: https://doi.org/10.1016/S0140-6736(18)30134-X | T16: Provisional proxy | U16: Direct incidence effect from alcohol reduction and cause-specific dose-response RR; no PAF input. See Risk_Response for source-to-model conversion and proxy notes. | V16: =COUNTIF(Intervention_Cause_Map!$A$2:$A$29,B16) -> 1 | W16: =IF(V16<>1,"MAP ERROR",IF(P16<>"well","REVIEW TRANSITION",IF(Q16<>"sick","REVIEW TRANSITION",IF(AND(L16=1,OR(K16="",K16<0,K16>1)),"MISSING PAF",IF(R16="","MISSING SOURCE","OK"))))) -> OK
A17: EFF_16 | B17: I_PH_ALCOHOL_POLICY__C_ICH | C17: I_PH_ALCOHOL_POLICY | D17: R_ALCOHOL | E17: C_ICH | F17: direct_loglinear_rr_per_unit_reduction | G17: RR_ALCOHOL_ICH_1L | H17: RR per 1 L pure alcohol/adult/year | I17: =INDEX(Risk_Response!$L$2:$L$18,MATCH(G17,Risk_Response!$A$2:$A$18,0)) -> 1.02008 | J17: relative risk | L17: 0 | N17: immediate_after_full_implementation | O17: 1 | P17: well | Q17: sick | R17: Wood et al. 2018 | S17: https://doi.org/10.1016/S0140-6736(18)30134-X | T17: Provisional proxy | U17: Direct incidence effect from alcohol reduction and cause-specific dose-response RR; no PAF input. See Risk_Response for source-to-model conversion and proxy notes. | V17: =COUNTIF(Intervention_Cause_Map!$A$2:$A$29,B17) -> 1 | W17: =IF(V17<>1,"MAP ERROR",IF(P17<>"well","REVIEW TRANSITION",IF(Q17<>"sick","REVIEW TRANSITION",IF(AND(L17=1,OR(K17="",K17<0,K17>1)),"MISSING PAF",IF(R17="","MISSING SOURCE","OK"))))) -> OK
A18: EFF_17 | B18: I_PH_ALCOHOL_POLICY__C_HHD | C18: I_PH_ALCOHOL_POLICY | D18: R_ALCOHOL | E18: C_HHD | F18: direct_loglinear_rr_per_unit_reduction | G18: RR_ALCOHOL_HHD_1L | H18: RR per 1 L pure alcohol/adult/year | I18: =INDEX(Risk_Response!$L$2:$L$18,MATCH(G18,Risk_Response!$A$2:$A$18,0)) -> 1.0331775 | J18: relative risk | L18: 0 | N18: immediate_after_full_implementation | O18: 1 | P18: well | Q18: sick | R18: Wood et al. 2018 | S18: https://doi.org/10.1016/S0140-6736(18)30134-X | T18: Ready | U18: Direct incidence effect from alcohol reduction and cause-specific dose-response RR; no PAF input. See Risk_Response for source-to-model conversion and proxy notes. | V18: =COUNTIF(Intervention_Cause_Map!$A$2:$A$29,B18) -> 1 | W18: =IF(V18<>1,"MAP ERROR",IF(P18<>"well","REVIEW TRANSITION",IF(Q18<>"sick","REVIEW TRANSITION",IF(AND(L18=1,OR(K18="",K18<0,K18>1)),"MISSING PAF",IF(R18="","MISSING SOURCE","OK"))))) -> OK
A19: EFF_18 | B19: I_PH_ALCOHOL_POLICY__C_CMYO | C19: I_PH_ALCOHOL_POLICY | D19: R_ALCOHOL | E19: C_CMYO | F19: direct_loglinear_rr_per_unit_reduction | G19: RR_ALCOHOL_CMYO_1L | H19: RR per 1 L pure alcohol/adult/year | I19: =INDEX(Risk_Response!$L$2:$L$18,MATCH(G19,Risk_Response!$A$2:$A$18,0)) -> 1.0131617 | J19: relative risk | L19: 0 | N19: immediate_after_full_implementation | O19: 1 | P19: well | Q19: sick | R19: Wood et al. 2018 | S19: https://doi.org/10.1016/S0140-6736(18)30134-X | T19: Provisional proxy | U19: Direct incidence effect from alcohol reduction and cause-specific dose-response RR; no PAF input. See Risk_Response for source-to-model conversion and proxy notes. | V19: =COUNTIF(Intervention_Cause_Map!$A$2:$A$29,B19) -> 1 | W19: =IF(V19<>1,"MAP ERROR",IF(P19<>"well","REVIEW TRANSITION",IF(Q19<>"sick","REVIEW TRANSITION",IF(AND(L19=1,OR(K19="",K19<0,K19>1)),"MISSING PAF",IF(R19="","MISSING SOURCE","OK"))))) -> OK
A20: EFF_19 | B20: I_PH_SALT_POLICY__C_IHD | C20: I_PH_SALT_POLICY | D20: R_SODIUM | E20: C_IHD | F20: direct_loglinear_rr_per_unit_reduction | G20: RR_SODIUM_1G | H20: RR per 1 g sodium | I20: =INDEX(Risk_Response!$L$2:$L$18,MATCH(G20,Risk_Response!$A$2:$A$18,0)) -> 1.06 | J20: relative risk | L20: 0 | N20: immediate_after_full_implementation | O20: 1 | P20: well | Q20: sick | R20: Watkins 2022 - Supplement to NCD Countdown 2030 efficient pathways and strategic.pdf | S20: p 33 | T20: Ready | U20: User-directed well-to-sick transition. Countdown cause-specific effect is applied to the corresponding incidence transition during integration. | V20: =COUNTIF(Intervention_Cause_Map!$A$2:$A$29,B20) -> 1 | W20: =IF(V20<>1,"MAP ERROR",IF(P20<>"well","REVIEW TRANSITION",IF(Q20<>"sick","REVIEW TRANSITION",IF(AND(L20=1,OR(K20="",K20<0,K20>1)),"MISSING PAF",IF(R20="","MISSING SOURCE","OK"))))) -> OK
A21: EFF_20 | B21: I_PH_SALT_POLICY__C_IS | C21: I_PH_SALT_POLICY | D21: R_SODIUM | E21: C_IS | F21: direct_loglinear_rr_per_unit_reduction | G21: RR_SODIUM_1G | H21: RR per 1 g sodium | I21: =INDEX(Risk_Response!$L$2:$L$18,MATCH(G21,Risk_Response!$A$2:$A$18,0)) -> 1.06 | J21: relative risk | L21: 0 | N21: immediate_after_full_implementation | O21: 1 | P21: well | Q21: sick | R21: Watkins 2022 - Supplement to NCD Countdown 2030 efficient pathways and strategic.pdf | S21: p 33 | T21: Ready | U21: User-directed well-to-sick transition. Countdown cause-specific effect is applied to the corresponding incidence transition during integration. | V21: =COUNTIF(Intervention_Cause_Map!$A$2:$A$29,B21) -> 1 | W21: =IF(V21<>1,"MAP ERROR",IF(P21<>"well","REVIEW TRANSITION",IF(Q21<>"sick","REVIEW TRANSITION",IF(AND(L21=1,OR(K21="",K21<0,K21>1)),"MISSING PAF",IF(R21="","MISSING SOURCE","OK"))))) -> OK
A22: EFF_21 | B22: I_PH_SALT_POLICY__C_ICH | C22: I_PH_SALT_POLICY | D22: R_SODIUM | E22: C_ICH | F22: direct_loglinear_rr_per_unit_reduction | G22: RR_SODIUM_1G | H22: RR per 1 g sodium | I22: =INDEX(Risk_Response!$L$2:$L$18,MATCH(G22,Risk_Response!$A$2:$A$18,0)) -> 1.06 | J22: relative risk | L22: 0 | N22: immediate_after_full_implementation | O22: 1 | P22: well | Q22: sick | R22: Watkins 2022 - Supplement to NCD Countdown 2030 efficient pathways and strategic.pdf | S22: p 33 | T22: Ready | U22: User-directed well-to-sick transition. Countdown cause-specific effect is applied to the corresponding incidence transition during integration. | V22: =COUNTIF(Intervention_Cause_Map!$A$2:$A$29,B22) -> 1 | W22: =IF(V22<>1,"MAP ERROR",IF(P22<>"well","REVIEW TRANSITION",IF(Q22<>"sick","REVIEW TRANSITION",IF(AND(L22=1,OR(K22="",K22<0,K22>1)),"MISSING PAF",IF(R22="","MISSING SOURCE","OK"))))) -> OK
A23: EFF_22 | B23: I_PH_SALT_POLICY__C_HHD | C23: I_PH_SALT_POLICY | D23: R_SODIUM | E23: C_HHD | F23: direct_loglinear_rr_per_unit_reduction | G23: RR_SODIUM_1G | H23: RR per 1 g sodium | I23: =INDEX(Risk_Response!$L$2:$L$18,MATCH(G23,Risk_Response!$A$2:$A$18,0)) -> 1.06 | J23: relative risk | L23: 0 | N23: immediate_after_full_implementation | O23: 1 | P23: well | Q23: sick | R23: Watkins 2022 - Supplement to NCD Countdown 2030 efficient pathways and strategic.pdf | S23: p 33 | T23: Ready | U23: User-directed well-to-sick transition. Countdown cause-specific effect is applied to the corresponding incidence transition during integration. | V23: =COUNTIF(Intervention_Cause_Map!$A$2:$A$29,B23) -> 1 | W23: =IF(V23<>1,"MAP ERROR",IF(P23<>"well","REVIEW TRANSITION",IF(Q23<>"sick","REVIEW TRANSITION",IF(AND(L23=1,OR(K23="",K23<0,K23>1)),"MISSING PAF",IF(R23="","MISSING SOURCE","OK"))))) -> OK
A24: EFF_23 | B24: I_PH_TFA_POLICY__C_IHD | C24: I_PH_TFA_POLICY | D24: R_TFA | E24: C_IHD | F24: tfa_attributable_ihd_PAF_x_policy_score | G24: TFA_SCORE_EFFECT | H24: policy-score effect on TFA-attributable IHD deaths | J24: proportion | L24: 1 | N24: immediate_after_full_implementation | O24: 1 | P24: well | Q24: sick | R24: Watkins 2022 - Supplement to NCD Countdown 2030 efficient pathways and strategic.pdf | S24: pp 33-34 | T24: Missing input | U24: User-directed well-to-sick transition. Enter Indonesia TFA-attributable IHD PAF and WHO policy score before execution. | V24: =COUNTIF(Intervention_Cause_Map!$A$2:$A$29,B24) -> 1 | W24: =IF(V24<>1,"MAP ERROR",IF(P24<>"well","REVIEW TRANSITION",IF(Q24<>"sick","REVIEW TRANSITION",IF(AND(L24=1,OR(K24="",K24<0,K24>1)),"MISSING PAF",IF(R24="","MISSING SOURCE","OK"))))) -> MISSING PAF
A25: EFF_24 | B25: I_PH_SSB_TAX__C_IHD | C25: I_PH_SSB_TAX | D25: R_SSB | E25: C_IHD | F25: direct_loglinear_rr_per_unit_reduction | G25: RR_SSB_IHD_1SERV | H25: RR per 1 daily 8 oz (248 g) SSB serving | I25: 1.14 | J25: relative risk | L25: 0 | N25: immediate_after_full_implementation | O25: 1 | P25: well | Q25: sick | R25: Lara-Castor et al. 2025 | S25: https://doi.org/10.1038/s41591-024-03345-4 | T25: Ready | U25: Direct BMI-independent RR, standardized to one 8 oz (248 g) serving/day; no model PAF input. | V25: =COUNTIF(Intervention_Cause_Map!$A$2:$A$29,B25) -> 1 | W25: =IF(V25<>1,"MAP ERROR",IF(P25<>"well","REVIEW TRANSITION",IF(Q25<>"sick","REVIEW TRANSITION",IF(AND(L25=1,OR(K25="",K25<0,K25>1)),"MISSING PAF",IF(R25="","MISSING SOURCE","OK"))))) -> OK
A26: EFF_25 | B26: I_PH_SSB_TAX__C_IS | C26: I_PH_SSB_TAX | D26: R_SSB | E26: C_IS | F26: direct_loglinear_rr_per_unit_reduction | G26: RR_SSB_IS_1SERV | H26: RR per 1 daily 8 oz (248 g) SSB serving | I26: 1.07 | J26: relative risk | L26: 0 | N26: immediate_after_full_implementation | O26: 1 | P26: well | Q26: sick | R26: Lara-Castor et al. 2025 | S26: https://doi.org/10.1038/s41591-024-03345-4 | T26: Ready | U26: Direct BMI-independent RR, standardized to one 8 oz (248 g) serving/day; no model PAF input. | V26: =COUNTIF(Intervention_Cause_Map!$A$2:$A$29,B26) -> 1 | W26: =IF(V26<>1,"MAP ERROR",IF(P26<>"well","REVIEW TRANSITION",IF(Q26<>"sick","REVIEW TRANSITION",IF(AND(L26=1,OR(K26="",K26<0,K26>1)),"MISSING PAF",IF(R26="","MISSING SOURCE","OK"))))) -> OK
A27: EFF_26 | B27: I_PH_SSB_TAX__C_ICH | C27: I_PH_SSB_TAX | D27: R_SSB | E27: C_ICH | F27: direct_loglinear_rr_per_unit_reduction | G27: RR_SSB_ICH_1SERV_PROXY | H27: RR per 1 daily 8 oz (248 g) SSB serving | I27: 1.08 | J27: relative risk | L27: 0 | N27: immediate_after_full_implementation | O27: 1 | P27: well | Q27: sick | R27: Sun et al. 2023 | S27: https://doi.org/10.1016/j.advnut.2022.12.002 | T27: Provisional proxy | U27: Total-stroke morbidity RR per 250 mL/day used for intracerebral hemorrhage; retain sensitivity or exclude if subtype-specific evidence is required. | V27: =COUNTIF(Intervention_Cause_Map!$A$2:$A$29,B27) -> 1 | W27: =IF(V27<>1,"MAP ERROR",IF(P27<>"well","REVIEW TRANSITION",IF(Q27<>"sick","REVIEW TRANSITION",IF(AND(L27=1,OR(K27="",K27<0,K27>1)),"MISSING PAF",IF(R27="","MISSING SOURCE","OK"))))) -> OK
A28: EFF_27 | B28: I_PH_SSB_TAX__C_HHD | C28: I_PH_SSB_TAX | D28: R_SSB | E28: C_HHD | F28: direct_loglinear_rr_per_unit_reduction | G28: RR_SSB_HHD_1SERV_PROXY | H28: RR per 1 daily 8 oz (248 g) SSB serving | I28: 1.1 | J28: relative risk | L28: 0 | N28: immediate_after_full_implementation | O28: 1 | P28: well | Q28: sick | R28: Qin et al. 2020 | S28: https://doi.org/10.1007/s10654-020-00655-y | T28: Provisional proxy | U28: Hypertension incidence RR per 250 mL/day used as an HHD incidence proxy, consistent with the Watkins raised-BMI cause set. | V28: =COUNTIF(Intervention_Cause_Map!$A$2:$A$29,B28) -> 1 | W28: =IF(V28<>1,"MAP ERROR",IF(P28<>"well","REVIEW TRANSITION",IF(Q28<>"sick","REVIEW TRANSITION",IF(AND(L28=1,OR(K28="",K28<0,K28>1)),"MISSING PAF",IF(R28="","MISSING SOURCE","OK"))))) -> OK
A29: EFF_28 | B29: I_PH_SSB_TAX__C_T2DM | C29: I_PH_SSB_TAX | D29: R_SSB | E29: C_T2DM | F29: direct_loglinear_rr_per_unit_reduction | G29: RR_SSB_T2DM_1SERV | H29: RR per 1 daily 8 oz (248 g) SSB serving | I29: 1.18 | J29: relative risk | L29: 0 | N29: immediate_after_full_implementation | O29: 1 | P29: well | Q29: sick | R29: Lara-Castor et al. 2025 | S29: https://doi.org/10.1038/s41591-024-03345-4 | T29: Ready | U29: Direct BMI-independent RR, standardized to one 8 oz (248 g) serving/day; no model PAF input. | V29: =COUNTIF(Intervention_Cause_Map!$A$2:$A$29,B29) -> 1 | W29: =IF(V29<>1,"MAP ERROR",IF(P29<>"well","REVIEW TRANSITION",IF(Q29<>"sick","REVIEW TRANSITION",IF(AND(L29=1,OR(K29="",K29<0,K29>1)),"MISSING PAF",IF(R29="","MISSING SOURCE","OK"))))) -> OK

Sheet Risk_Response
A1: response_key | B1: risk_id | C1: selection_status | D1: response_name | E1: age_start | F1: age_stop | G1: sex | H1: cause_id | I1: cause_scope | J1: source_effect_value | K1: source_effect_unit | L1: model_response_value | M1: model_response_unit | N1: derivation | O1: source | P1: selected_for_base_case | Q1: notes
A2: RR_SMOKING_IHD | B2: R_SMOKING | C2: Selected | D2: Current smoking RR - ischemic heart disease | E2: 20 | F2: 95 | G2: Both | H2: C_IHD | I2: Ischemic heart disease | J2: 1.6 | K2: RR current vs non-smoker | L2: =J2 -> 1.6 | M2: RR current vs non-smoker | N2: model RR = source RR | O2: Asia Pacific Cohort Studies Collaboration. Int J Epidemiol. 2005. https://doi.org/10.1093/ije/dyi104 | P2: 1 | Q2: Pooled CHD estimate; directly applied to IHD incidence
A3: RR_SMOKING_IS | B3: R_SMOKING | C3: Selected | D3: Current smoking RR - ischemic stroke | E3: 20 | F3: 95 | G3: Both | H3: C_IS | I3: Ischemic stroke | J3: 1.38 | K3: RR current vs non-smoker | L3: =J3 -> 1.38 | M3: RR current vs non-smoker | N3: model RR = source RR | O3: Asia Pacific Cohort Studies Collaboration. Int J Epidemiol. 2005. https://doi.org/10.1093/ije/dyi104 | P3: 1 | Q3: Direct ischemic-stroke estimate
A4: RR_SMOKING_ICH | B4: R_SMOKING | C4: Selected | D4: Current smoking RR - intracerebral hemorrhage | E4: 20 | F4: 95 | G4: Both | H4: C_ICH | I4: Intracerebral hemorrhage | J4: 1.19 | K4: RR current vs non-smoker | L4: =J4 -> 1.19 | M4: RR current vs non-smoker | N4: model RR = source RR | O4: Asia Pacific Cohort Studies Collaboration. Int J Epidemiol. 2005. https://doi.org/10.1093/ije/dyi104 | P4: 1 | Q4: Hemorrhagic-stroke estimate used for intracerebral hemorrhage
A5: RR_SMOKING_T2DM | B5: R_SMOKING | C5: Selected | D5: Current smoking RR - type 2 diabetes | E5: 20 | F5: 95 | G5: Both | H5: C_T2DM | I5: Diabetes mellitus type 2 | J5: 1.37 | K5: RR current vs non-smoker | L5: =J5 -> 1.37 | M5: RR current vs non-smoker | N5: model RR = source RR | O5: Pan et al. Lancet Diabetes Endocrinol. 2015. https://doi.org/10.1016/S2213-8587(15)00316-2 | P5: 1 | Q5: Pooled RR 1.37 (95% CI 1.33-1.42); early post-cessation risk requires sensitivity analysis
A6: RR_ALCOHOL_IHD_1L | B6: R_ALCOHOL | C6: Selected | D6: Alcohol dose-response RR - ischemic heart disease | E6: 20 | F6: 95 | G6: Both | H6: C_IHD | I6: Ischemic heart disease | J6: 1.06 | K6: HR per 100 g ethanol/week | L6: =J6^(1/(100*Assumptions!$B$19/Assumptions!$B$18)) -> 1.0088804 | M6: RR per 1 L pure alcohol/adult/year | N6: source HR converted using 789 g/L and 52 weeks/year | O6: Wood et al. Lancet. 2018. https://doi.org/10.1016/S0140-6736(18)30134-X | P6: 1 | Q6: Coronary disease excluding myocardial infarction used as conservative IHD proxy
A7: RR_ALCOHOL_IS_1L | B7: R_ALCOHOL | C7: Selected | D7: Alcohol dose-response RR - ischemic stroke | E7: 20 | F7: 95 | G7: Both | H7: C_IS | I7: Ischemic stroke | J7: 1.14 | K7: HR per 100 g ethanol/week | L7: =J7^(1/(100*Assumptions!$B$19/Assumptions!$B$18)) -> 1.02008 | M7: RR per 1 L pure alcohol/adult/year | N7: source HR converted using 789 g/L and 52 weeks/year | O7: Wood et al. Lancet. 2018. https://doi.org/10.1016/S0140-6736(18)30134-X | P7: 1 | Q7: All-stroke estimate used as subtype proxy
A8: RR_ALCOHOL_ICH_1L | B8: R_ALCOHOL | C8: Selected | D8: Alcohol dose-response RR - intracerebral hemorrhage | E8: 20 | F8: 95 | G8: Both | H8: C_ICH | I8: Intracerebral hemorrhage | J8: 1.14 | K8: HR per 100 g ethanol/week | L8: =J8^(1/(100*Assumptions!$B$19/Assumptions!$B$18)) -> 1.02008 | M8: RR per 1 L pure alcohol/adult/year | N8: source HR converted using 789 g/L and 52 weeks/year | O8: Wood et al. Lancet. 2018. https://doi.org/10.1016/S0140-6736(18)30134-X | P8: 1 | Q8: All-stroke estimate used as subtype proxy
A9: RR_ALCOHOL_HHD_1L | B9: R_ALCOHOL | C9: Selected | D9: Alcohol dose-response RR - hypertensive heart disease | E9: 20 | F9: 95 | G9: Both | H9: C_HHD | I9: Hypertensive heart disease | J9: 1.24 | K9: HR per 100 g ethanol/week | L9: =J9^(1/(100*Assumptions!$B$19/Assumptions!$B$18)) -> 1.0331775 | M9: RR per 1 L pure alcohol/adult/year | N9: source HR converted using 789 g/L and 52 weeks/year | O9: Wood et al. Lancet. 2018. https://doi.org/10.1016/S0140-6736(18)30134-X | P9: 1 | Q9: Fatal hypertensive-disease estimate directly mapped to HHD
